Workbook

Sheet Overview
A1: BENTLEY | B1: Total in £ | C1: Error | D1: Note
A2: CASH ACCOUNT
A3: RECEIPTS
A4: Arrears total
A5: Rents of assize total
A6: Quittances total
A7: Defaults of rent total
A8: Defaults of rent through the pestilence total
A9: Cotlands defaults total
A10: Cotlands total
A11: Total of quittances and defaults of rent total
A12: Total of rents remaining clear total
A13: Farms total
... A22: Farm of the demesne land total
A23: Total of all receipts (calculated here) | B23: =Receipts!F114 -> 55.02
A24: Total of all receipts (calculated here) incl arrears | B24: =Receipts!F115 -> 64.96
A25: Total recorded in the accounts excl. arrears | B25: =Receipts!F113 -> 54.97 | C25: =B25-B23 -> -0.05
A26: Total recorded in the accounts incl. arrears
A29: EXPENSES
A30: Cost of ploughs total
A31: Purchase of corn total
A32: Cost of carts and wagons total
A33: Cost of dairy total
A34: Purchase of stock total
A35: Sheepcote total
A36: Cost of buildings total
A37: Threshing total
A38: Barley expenses
A39: Expenses of the harvest total
... A43: Annual fees
A44: Total of all expenses per account | B44: =Expenses!F88 -> 14.59
A45: Total of all expenses (calculated here) | B45: =Expenses!F89 -> 14.66875
A46: Total fixed investment | B46: =Expenses!F90 -> 1.72375
A47: Total Demesne fixed investment | B47: =Expenses!F91 -> 1.72375
A49: Owed by the reeve | B49: =B23-B45 -> 40.35125
A50: From accounts | B50: =Expenses!F81 -> 40.38 | C50: =B50-B49 -> 0.02875
A52: Allowances
A53: Cash deliveries | B53: =Expenses!F83 -> 23.5
A54: Sum of the above | B54: =SUM(B52:B53) -> 23.5
A55: Total of all allowances and cash deliveries in accounts
...

Sheet Receipts
A1: BENTLEY RECEIPTS
A2: Heading | B2: £ | C2: s | D2: d | F2: Total in £ | G2: Error | H2: Notes
A3: Arrears | B3: 9 | C3: 18 | D3: 9.5 | F3: 9.94 | H3: James de Northon', bailiff, and William le Stynt', reeve, render account for £9 18 shilling 9.5pence of arrears from the previous year.
A4: Arrears | B4: 0 | C4: 0 | D4: 0 | F4: 0 | H4: All delivered to Sir Geoffrey, treasurer of Wolvesey, and they are quit.
A5: Arrears | F5: 9.94 | G5: =F5-F3 -> 0 | H5: Total
A7: Rents of assize | B7: 8 | C7: 16 | D7: 10.25 | F7: 8.84 | H7: The same render account for £8 16 shilling 10.25pence for all rents of assize at Easter (22 April).
A8: Rents of assize | B8: 8 | C8: 16 | D8: 10.25 | F8: 8.84 | H8: £8 16 shilling 10.25pence at Michaelmas (29 September).
A9: Rents of assize | B9: 17 | C9: 13 | D9: 9 | F9: 17.69 | H9: Total, £17 13 shilling 9pence
A10: Rents of assize | F10: 17.68 | G10: -0.01 | H10: Total
A12: Quittances | B12: 0 | C12: 5 | D12: 0 | F12: 0.25 | H12: In quittance of 1 reeve for the year 5 shilling.
A13: Quittances | B13: 0 | C13: 3 | D13: 0 | F13: 0.15 | H13: 1 shepherd for the year 3 shilling.
A14: Quittances | B14: 0 | C14: 6 | D14: 0 | F14: 0.3 | H14: 3 ploughmen for the year 6 shilling.
A15: Quittances | B15: 0 | C15: 2 | D15: 0 | F15: 0.1 | H15: 1 smith for the year 2 shilling
A16: Quittances | B16: 0 | C16: 16 | D16: 0 | F16: =B16+C16/20+D16/240 -> 0.8 | H16: Total, 16 shilling
A17: Quittances | F17: 0.8 | G17: =F17-F16 -> 0 | H17: Total
A19: Defaults of rent | B19: 0 | C19: 1 | D19: 3 | F19: 0.06 | H19: In default of 2 acres of Sampson drawn into demesne 1 shilling 3pence.
A20: Defaults of rent | B20: 0 | C20: 4 | D20: 9 | F20: 0.24 | H20: 2.5 acres in Costouue 4 shilling 9pence.
A21: Defaults of rent | B21: 0 | C21: 0 | D21: 6 | F21: 0.03 | H21: certain land of Gundevyl' drawn into demesne 6pence.
A22: Defaults of rent | B22: 0 | C22: 0 | D22: 10 | F22: 0.04 | H22: 1.5 acres and 1 perch which belonged to John Edward drawn into demesne 10pence.
A23: Defaults of rent | B23: 0 | C23: 2 | D23: 0 | F23: 0.1 | H23: 2 acres of land of Thomas de Camera drawn into demesne 2 shilling.
A24: Defaults of rent | B24: 1 | C24: 5 | D24: 5 | F24: 1.27 | H24: 1 house of Joan de la Forde which was pulled down on account of the king's highway 1pence Total of defaults of rent, 9 shilling 5pence Total of quittances and defaults of rent, £1 5 shilling 5pence
A25: Defaults of rent | F25: =SUM(F19:F24) -> 1.74 | H25: Total
A27: Rents remaining | B27: 16 | C27: 8 | D27: 4 | F27: 16.42 | H27: Total of rents remaining, £16 8 shilling 4pence
A29: Annual recognizance | B29: 0 | C29: 0 | D29: 6 | F29: 0.03 | H29: The same render account for 6pence from the annual recognizance of the relict of Thomas de Badely, for the term of 13 years which John le Commongare granted her to hold the land of Richard Vassal.
A30: Annual recognizance | B30: 0 | C30: 0 | D30: 6 | F30: 0.03 | H30: She thus pays 6pence yearly, and this will be the second year.
A31: Annual recognizance | B31: 0 | C31: 0 | D31: 6 | F31: 0.03 | H31: Total, 6pence
A32: Annual recognizance | F32: 0.06 | G32: 0.03 | H32: Total
A34: Issues of the manor | B34: 0 | C34: 14 | D34: 1 | F34: 0.7 | H34: The same render account for 14 shilling 1pence from common pannage of 114 pigs and 106 piglets, at 1pence a pig over a year old, 0.5pence a piglet.
A35: Issues of the manor | B35: 0 | C35: 6 | D35: 2 | F35: 0.31 | H35: 6 shilling from pannage of Luxegrove and Woodgarston, of 36 pigs of Robert Archyr, Richard atte Ford', William Duk' and other men of Bentley, at 2pence a pig.
A36: Issues of the manor | B36: 0 | C36: 1 | D36: 6 | F36: 0.08 | H36: 1 shilling 6pence from the pasturage of la Rygg' sold to the men of Crondall.
A37: Issues of the manor | B37: 0 | C37: 1 | D37: 0 | F37: 0.05 | H37: 1 shilling from the pasturage of Woodgarston sold.
A38: Issues of the manor | B38: 0 | C38: 2 | D38: 0 | F38: 0.1 | H38: 2 shilling from the pasturage of Coleford'.
A39: Issues of the manor | B39: 0 | C39: 1 | D39: 0 | F39: 0.05 | H39: 1 shilling from the pasturage of la Brodemed' sold.
A40: Issues of the manor | B40: 0 | C40: 4 | D40: 0 | F40: 0.2 | H40: 4 shilling from the pasturage of Midelfeld' sold.
A41: Issues of the manor | B41: 0 | C41: 0 | D41: 0 | F41: 0 | H41: nothing from the pasturage of la Den' and Westssend' because it was reserved for the lord's oxen.
A42: Issues of the manor | B42: 0 | C42: 0 | D42: 0 | F42: 0 | H42: nothing from the pasturage of Luxegrove this year for the lord's oxen.
A43: Issues of the manor | B43: 1 | C43: 10 | D43: 0 | F43: 1.5 | H43: £1 10 shilling from 3 oxen sold, at 10 shilling each.
A44: Issues of the manor | B44: 0 | C44: 4 | D44: 6 | F44: 0.23 | H44: 4 shilling 6pence from an old feeble ox sold.
A45: Issues of the manor | B45: 0 | C45: 6 | D45: 0 | F45: 0.3 | H45: 6 shilling from 1 cow from the heriot of John ate Pull' sold.
... A52: Issues of the manor | B52: 1 | C52: 6 | D52: 8 | F52: 1.33 | H52: £1 6 shilling 8pence from 2 casks of cider remaining from the previous year sold without the wood.
...

Sheet Expenses
A1: BEAUWORTH EXPENSES
A2: Heading | B2: £ | C2: s | D2: d | F2: Total in £ | G2: Error | H2: Notes | J2: Fixed investment | K2: Demesne fixed investment
A3: Expenses of ploughs | B3: 0 | C3: 11 | D3: 5 | F3: 0.57 | H3: In steel bought for 3 ploughs for the year 11 shilling 5pence. | J3: =F3 -> 0.57 | K3: =F3 -> 0.57
A4: Expenses of ploughs | B4: 0 | C4: 2 | D4: 6 | F4: 0.12 | H4: 3 ploughshares bought 2 shilling 6pence. | J4: =F4 -> 0.12 | K4: =F4 -> 0.12
A5: Expenses of ploughs | B5: 0 | C5: 1 | D5: 0 | F5: 0.05 | H5: 3 pairs of wheels bought 1 shilling. | J5: =F5 -> 0.05 | K5: =F5 -> 0.05
A6: Expenses of ploughs | B6: 0 | C6: 0 | D6: 6 | F6: 0.03 | H6: 2 ploughs made anew 6pence. | J6: =F6 -> 0.03 | K6: =F6 -> 0.03
A7: Expenses of ploughs | B7: 0 | C7: 0 | D7: 7.5 | F7: 0.03 | H7: 3 ploughs fitted with iron tyres 7.5pence. | J7: =F7 -> 0.03 | K7: =F7 -> 0.03
A8: Expenses of ploughs | B8: 4 | C8: 5 | D8: 11 | F8: 4.3 | H8: 8 oxen bought £4 5 shilling 11pence, at 11 shilling 5pence each for 3, 10 shilling 7pence each for 2, 10 shilling 6pence for 1, and 10 shilling each for 2..
A9: Expenses of ploughs | B9: 0 | C9: 9 | D9: 0 | F9: 0.45 | H9: stipend of 3 drovers for the year 9 shilling.
A10: Expenses of ploughs | B10: 0 | C10: 8 | D10: 0 | F10: =B10+C10/20+D10/240 -> 0.4 | H10: forage' bought for oxen 8 shilling
A11: Expenses of ploughs | B11: 5 | C11: 18 | D11: 11.5 | F11: 5.95 | H11: Total, £5 18 shilling 11.5pence
A12: Expenses of ploughs | F12: =SUM(F3:F10) -> 5.95 | G12: =F12-F11 -> 0 | H12: Total
A14: Purchase of seed and liveries | B14: 2 | C14: 16 | D14: 4 | F14: 2.82 | H14: In 20.5 quarters of barley bought for the liveries of the manorial servants £2 16 shilling 4pence, at 3 shilling 4pence a qr for 7 quarters, 2 shilling 8pence a qr for 4.5 quarters, and 2 shilling 4pence a qr for 9 quarters.
A15: Purchase of seed and liveries | B15: 2 | C15: 16 | D15: 4 | F15: 2.82 | H15: Total, £2 16 shilling 4pence
A16: Purchase of seed and liveries | F16: 2.82 | G16: 0 | H16: Total
A18: Carts | B18: 0 | C18: 2 | D18: 5 | F18: 0.12 | H18: In 1 pair of wheels bought 2 shilling .5pence. | J18: =F18 -> 0.12 | K18: =J18 -> 0.12
A19: Carts | B19: 0 | C19: 0 | D19: 8 | F19: 0.03 | H19: clouts with nails bought 8pence. | J19: =F19 -> 0.03 | K19: =J19 -> 0.03
A20: Carts | B20: 0 | C20: 0 | D20: 3.5 | F20: 0.01 | H20: grease bought 3.5pence. | J20: =F20 -> 0.01 | K20: =J20 -> 0.01
A21: Carts | B21: 0 | C21: 0 | D21: 8.25 | F21: 0.03 | H21: 2 new collars 8.25pence. | J21: =F21 -> 0.03 | K21: =J21 -> 0.03
A22: Carts | B22: 0 | C22: 0 | D22: 4.5 | F22: 0.02 | H22: 1 pair of saddle-pads bought 4.5pence. | J22: =F22 -> 0.02 | K22: =J22 -> 0.02
A23: Carts | B23: 0 | C23: 0 | D23: 3 | F23: 0.01 | H23: 1 pair of traces bought 3pence. | J23: =F23 -> 0.01 | K23: =J23 -> 0.01
A24: Carts | B24: 0 | C24: 0 | D24: 1.5 | F24: 0.01 | H24: girths and cruppers bought 1.5pence. | J24: =F24 -> 0.01 | K24: =J24 -> 0.01
A25: Carts | B25: 0 | C25: 0 | D25: 2 | F25: 0.01 | H25: white leather bought for mending harnesses 2pence. | J25: =F25 -> 0.01 | K25: =J25 -> 0.01
A26: Carts | B26: 0 | C26: 0 | D26: 6 | F26: 0.03 | H26: a cart made anew and another mended for dung 6pence. | J26: =F26 -> 0.03 | K26: =J26 -> 0.03
A27: Carts | B27: 0 | C27: 0 | D27: 2 | F27: 0.01 | H27: fitting the said carts with axles 2pence. | J27: =F27 -> 0.01 | K27: =J27 -> 0.01
A28: Carts | B28: 0 | C28: 2 | D28: 6 | F28: 0.12 | H28: shoeing 2 cart-horses for the year 2 shilling 6pence. | J28: =F28 -> 0.12 | K28: =J28 -> 0.12
A29: Carts | B29: 0 | C29: 3 | D29: 0 | F29: =B29+C29/20+D29/240 -> 0.15 | H29: stipend of 1 carter for the year 3 shilling
A30: Carts | B30: 0 | C30: 10 | D30: 9.25 | F30: =B30+C30/20+D30/240 -> 0.53854167 | H30: Total, 10 shilling 9.25pence
A31: Carts | F31: 0.59 | G31: =F31-F30 -> 0.051458333 | H31: Total
A33: Cost of buildings | B33: 0 | C33: 2 | D33: 4 | F33: 0.12 | H33: In roofing the great barn and hay-barn in places 2 shilling 4pence. | J33: =F33 -> 0.12 | K33: =J33 -> 0.12
A34: Cost of buildings | B34: 0 | C34: 1 | D34: 8.5 | F34: 0.09 | H34: mending the granary with tiles and lime bought for the same 1 shilling 8.5pence. | J34: =F34 -> 0.09 | K34: =J34 -> 0.09
A35: Cost of buildings | B35: 0 | C35: 0 | D35: 4.5 | F35: 0.02 | H35: 1 barrow bought 4.5pence. | J35: =F35 -> 0.02 | K35: =J35 -> 0.02
A36: Cost of buildings | B36: 0 | C36: 0 | D36: 4.5 | F36: 0.02 | H36: making 1 gate for the enclosure between the king's highway and the lord's field 4.5pence. | J36: =F36 -> 0.02 | K36: =J36 -> 0.02
A37: Cost of buildings | B37: 0 | C37: 0 | D37: 10.5 | F37: =B37+C37/20+D37/240 -> 0.04375 | H37: sawing boards 10.5pence | J37: =F37 -> 0.04375 | K37: =J37 -> 0.04375
A38: Cost of buildings | B38: 0 | C38: 5 | D38: 8 | F38: =B38+C38/20+D38/240 -> 0.28333333 | H38: Total, 5 shilling 8pence
A39: Cost of buildings | F39: =SUM(F33:F37) -> 0.29375 | G39: =F39-F38 -> 0.010416667 | H39: Total
A41: Threshing and winnowing | H41: {henceforth 1.75pence should always be owed for threshing and winnowing 10 struck bushels of barley and the same for vetches and .75pence for threshing 10 bushels of oats, 1pence for winnowing 8 quarters}
A42: Threshing and winnowing | B42: 1 | C42: 1 | D42: 8.25 | F42: 1.08 | H42: In threshing and winnowing 118 quarters 2 bushels of wheat by piece-work £1 1 shilling 8.25pence, at 2pence a qr threshed and 1pence per 5 quarters winnowepence.
A43: Threshing and winnowing | B43: 0 | C43: 1 | D43: 9.75 | F43: 0.09 | H43: threshing and winnowing 7.5 quarters 2 bushels of winter barley and 4 quarters 2 bushels of barley by piece-work 1 shilling 9.75pence, at 1.75pence a qr.
A44: Threshing and winnowing | B44: 0 | C44: 3 | D44: 2.5 | F44: 0.16 | H44: threshing and winnowing 61.5 quarters 1 bushels of oats by piece-work 3 shilling 2.5pence, at 0.75pence a qr threshed and 1 pence per 8 quarters winnowepence.
...

Sheet Issues of the Grange
A1: Gross Output | B1: Total Quantity | C1: Account Total Quarters | D1: Bought in Total Quarters | E1: Received | F1: Sold Total Quarters | G1: Difference Produced+Bought-Sold | H1: Weighted Average Price per Quarter | I1: Value of Total Production weighted
A2: wheat | B2: =118+2/8 -> 118.25 | C2: 118.25 | D2: 0 | F2: 84 | G2: =B2-F2 -> 34.25 | H2: 0.3 | I2: =H2*B2 -> 35.475
A3: barley (incl. winter barley) | B3: =C3+D3+E3 -> 33.25 | C3: =4.75 -> 4.75 | D3: 20.5 | E3: =6.5+1.5 -> 8 | F3: 3.375 | G3: =B3-F3 -> 29.875 | H3: 0.11666667 | I3: =H3*B3 -> 3.8791667
A4: oats | B4: 74.625 | C4: 61.625 | D4: 0 | F4: 12 | G4: =B4-F4 -> 62.625 | H4: 0.15 | I4: =H4*B4 -> 11.19375
A5: vetches | B5: 2.25 | C5: 2.25 | D5: 0 | F5: 0 | G5: =B5-F5 -> 2.25 | H5: 0.11666667 | I5: =H5*B5 -> 0.2625
A7: Total Production | B7: =SUM(B2:B5) -> 228.375
A8: Sales of corn (as recorded in accounts)
A11: Net output | B11: Gross output | C11: Seed quarters | D11: Seed bushels | E11: Seed total quarters | F11: tithe quarters | G11: tithe bushels | H11: tithe total | I11: manorial servants quarters | J11: manorial servants bushels | K11: manorial servants total quarters | L11: output net of tithe, seed, liveries | M11: in stock from last year | N11: Price in £ | O11: Value of net output in £ | P11: Value of sales (in "Sale of Corn") in £
A12: wheat | B12: =B2 -> 118.25 | C12: 23.5 | D12: 1 | E12: =C12+D12/8 -> 23.625 | I12: =4+1+3 -> 8 | J12: =2 -> 2 | K12: =I12+J12/8 -> 8.25 | L12: =B12-E12-H12-K12 -> 86.375 | N12: =H2 -> 0.3 | O12: =N12*L12 -> 25.9125
A13: barley (incl. winter barley) | B13: =B3 -> 33.25 | C13: =1+3 -> 4 | D13: =2 -> 2 | E13: =C13+D13/8 -> 4.25 | I13: =3+26 -> 29 | J13: =2 -> 2 | K13: =I13+J13/8 -> 29.25 | L13: =B13-E13-H13-K13 -> -0.25 | N13: =H3 -> 0.11666667 | Q13: must be a mistake in the accounts
A14: oats | B14: =B4 -> 74.625 | C14: 40.5 | D14: 2 | E14: =C14+D14/8 -> 40.75 | I14: =7.5+1+13 -> 21.5 | J14: =3 -> 3 | K14: =I14+J14/8 -> 21.875 | L14: =B14-E14-H14-K14 -> 12 | N14: =H4 -> 0.15 | O14: =N14*L14 -> 1.8
A15: vetches | B15: =B5 -> 2.25 | D15: 6 | E15: =C15+D15/8 -> 0.75 | I15: 1.5 | K15: =I15+J15/8 -> 1.5 | L15: =B15-E15-H15-K15 -> 0 | N15: =H5 -> 0.11666667 | O15: =N15*L15 -> 0
A17: Total

Sheet Issues of the Mills

Sheet Stock
A1: BENTLEY STOCK ACCOUNT
C3: added | G3: subtracted
A4: Livestock | B4: Inherited stock | C4: added | D4: strays | E4: herbage | F4: churchscot | G4: of which in default | H4: sold | I4: in murrain | J4: accounted for elsewhere | K4: End-period stock | L4: cross-check | M4: stock building | N4: raw production | O4: Unit price (£) | P4: Value of stock (£) at given value | Q4: Value of stock (£) at sales prices | R4: Sales in (£) | S4: Value of stock building (£) | T4: Value of production (£) at sales prices | U4: Details
A5: Cart-horses | B5: 2 | K5: 2 | L5: =B5+C5+D5+E5+F5-G5-H5-I5-J5 -> 2 | M5: =K5-B5 -> 0
A6: Mares | L6: =B6+C6+D6+E6+F6-G6-H6-I6-J6 -> 0 | M6: =K6-B6 -> 0
A7: Plough horses | L7: =B7+C7+D7+E7+F7-G7-H7-I7-J7 -> 0 | M7: =K7-B7 -> 0
A8: Colts (unspecified years) | L8: =B8+C8+D8+E8+F8-G8-H8-I8-J8 -> 0 | M8: =K8-B8 -> 0
A9: Colts (2 years) | L9: =B9+C9+D9+E9+F9-G9-H9-I9-J9 -> 0 | M9: =K9-B9 -> 0
A10: Colts (1 year) | L10: =B10+C10+D10+E10+F10-G10-H10-I10-J10 -> 0 | M10: =K10-B10 -> 0
A11: Foals | L11: =B11+C11+D11+E11+F11-G11-H11-I11-J11 -> 0 | M11: =K11-B11 -> 0
A12: Oxen | B12: 34 | C12: 8 | H12: 3 | I12: 1 | J12: 1 | K12: 37 | L12: =B12+C12+D12+E12+F12-G12-H12-I12-J12 -> 37 | M12: =K12-B12 -> 3 | O12: =R12/H12 -> 0.5 | R12: =Receipts!F43 -> 1.5 | S12: =O12*M12 -> 1.5 | U12: issues of manor record the sale of an additional old oxen, not recorded here
A13: Bulls | L13: =B13+C13+D13+E13+F13-G13-H13-I13-J13 -> 0 | M13: =K13-B13 -> 0 | S13: =O13*M13 -> 0
A14: Cows | C14: 1 | H14: 1 | K14: 0 | L14: =B14+C14+D14+E14+F14-G14-H14-I14-J14 -> 0 | M14: =K14-B14 -> 0 | O14: =R14/H14 -> 0.3 | R14: =Receipts!F45 -> 0.3 | S14: =O14*M14 -> 0
A15: Steers | L15: =B15+C15+D15+E15+F15-G15-H15-I15-J15 -> 0 | M15: =K15-B15 -> 0 | S15: =O15*M15 -> 0
A16: Bullocks | B16: 1 | H16: 1 | K16: 0 | L16: =B16+C16+D16+E16+F16-G16-H16-I16-J16 -> 0 | M16: =K16-B16 -> -1 | O16: =R16/H16 -> 0.2 | R16: =Receipts!F46 -> 0.2 | S16: =O16*M16 -> -0.2
A17: Yearlings | L17: =B17+C17+D17+E17+F17-G17-H17-I17-J17 -> 0 | M17: =K17-B17 -> 0
A18: Calves | L18: =B18+C18+D18+E18+F18-G18-H18-I18-J18 -> 0 | M18: =K18-B18 -> 0
A19: Wethers | L19: =B19+C19+D19+E19+F19-G19-H19-I19-J19 -> 0 | M19: =K19-B19 -> 0
A20: Rams | L20: =B20+C20+D20+E20+F20-G20-H20-I20-J20 -> 0 | M20: =K20-B20 -> 0
A21: Ewes | L21: =B21+C21+D21+E21+F21-G21-H21-I21-J21 -> 0 | M21: =K21-B21 -> 0
A22: Hoggs | L22: =B22+C22+D22+E22+F22-G22-H22-I22-J22 -> 0 | M22: =K22-B22 -> 0
A23: Lambs | L23: =B23+C23+D23+E23+F23-G23-H23-I23-J23 -> 0 | M23: =K23-B23 -> 0
A24: Boars | L24: =B24+C24+D24+E24+F24-G24-H24-I24-J24 -> 0 | M24: =K24-B24 -> 0
A25: Sows | L25: =B25+C25+D25+E25+F25-G25-H25-I25-J25 -> 0 | M25: =K25-B25 -> 0
A26: Pigs | L26: =B26+C26+D26+E26+F26-G26-H26-I26-J26 -> 0 | M26: =K26-B26 -> 0
A27: Hoggets | L27: =B27+C27+D27+E27+F27-G27-H27-I27-J27 -> 0 | M27: =K27-B27 -> 0
A28: Piglets | C28: 1 | H28: 1 | K28: 0 | L28: =B28+C28+D28+E28+F28-G28-H28-I28-J28 -> 0 | M28: =K28-B28 -> 0 | O28: =R28/H28 -> 0.03 | R28: =Receipts!F48 -> 0.03 | S28: =O28*M28 -> 0
A29: Swans
A30: Peacocks
A31: Total Value | R31: =SUM(R5:R30) -> 2.03
A34: Wool
A35: Coarse wool
A36: Lamb's wool
A37: Wool locks
A38: Wool sold at shearing
A39: Total wool
A42: Hides
A43: Ox hides | H43: 1 | O43: =R43/H43 -> 0.11 | R43: =Receipts!F47 -> 0.11 | T43: =O43*H43 -> 0.11 | U43: only recoded in issues of the manor, not stock
A44: Mare
A45: Steer
...

Sheet Issues of the Grange raw
A1: Heading | B1: Sentence | C1: Quarters 1_x | D1: Bushels 1_x | E1: Sown Quarters | F1: Sown Bushels | G1: Sown Total Quarters | H1: Bought in Quarters | I1: Bought in Bushels | J1: Bought in Total Quarters | K1: Tithe Quarters | L1: Tithe Bushels | M1: Tithe Total Quarters | N1: Manorial servants & livestock Quarters | O1: Manorial servants & livestock Bushels | P1: Manorial servants & livestock Total Quarters | Q1: Sold Quarters | R1: Sold Bushels | S1: Sold Total Quarters | T1: Account Quarters | U1: Account Bushels | V1: Account Total Quarters | W1: bought only | X1: Total Quarters Except 1 | Y1: Total Bushels Except 1 | Z1: Total Corn Cross-Check | AA1: Total Corn Manorial Account | AB1: Corn Quantity Error | AC1: Quarters 1_y | AD1: Bushels 1_y | AE1: Quarters 2 | AF1: Bushels 2 | AG1: Quarters 3 | AH1: Bushels 3 | AI1: Quarters 4 | AJ1: Bushels 4
A2: And thus he owes clear | B2: Total | C2: 0 | D2: 0 | E2: 0 | F2: 0 | G2: 0 | H2: 0 | I2: 0 | J2: 0 | K2: 0 | L2: 0 | M2: 0 | N2: 0 | O2: 0 | P2: 0 | Q2: 0 | R2: 0 | S2: 0 | T2: 0 | U2: 0 | V2: 0 | W2: 0
A3: Wheat | B3: {yield: 4.5-fold plus 3.5 quarters} | C3: 0 | D3: 0 | E3: 0 | F3: 0 | G3: 0 | H3: 0 | I3: 0 | J3: 0 | K3: 0 | L3: 0 | M3: 0 | N3: 0 | O3: 0 | P3: 0 | Q3: 0 | R3: 0 | S3: 0 | T3: 0 | U3: 0 | V3: 0 | W3: 0 | X3: 3.5 | Y3: 0 | Z3: 3.5 | AA3: 3.5 | AB3: 0 | AC3: 3.5 | AD3: 0
A4: Wheat | B4: The same render account for 118 quarters 2 bushels from the whole issue of wheat and curall from the grange with the increment of the granary. | C4: 0 | D4: 0 | E4: 0 | F4: 0 | G4: 0 | H4: 0 | I4: 0 | J4: 0 | K4: 0 | L4: 0 | M4: 0 | N4: 0 | O4: 0 | P4: 0 | Q4: 0 | R4: 0 | S4: 0 | T4: 118 | U4: 2 | V4: 118.25 | W4: 0 | X4: 118 | Y4: 2 | Z4: 118.25 | AA4: 118.25 | AB4: 0 | AC4: 118 | AD4: 2
A5: Wheat | B5: Sown over 75 acres measured by the perch which lie in the fields of Quidacr' and la Estdon', 23.5 quarters 1 bushels. | C5: 0 | D5: 0 | E5: 23.5 | F5: 1 | G5: 23.625 | H5: 0 | I5: 0 | J5: 0 | K5: 0 | L5: 0 | M5: 0 | N5: 0 | O5: 0 | P5: 0 | Q5: 0 | R5: 0 | S5: 0 | T5: 0 | U5: 0 | V5: 0 | W5: 0 | X5: 23.5 | Y5: 1 | Z5: 23.625 | AA5: 23.625 | AB5: 0 | AC5: 23.5 | AD5: 1
A6: Wheat | B6: that is, 2.5 bushels an acre, plus 7 bushels in all. | C6: 0 | D6: 0 | E6: 0 | F6: 0 | G6: 0 | H6: 0 | I6: 0 | J6: 0 | K6: 0 | L6: 0 | M6: 0 | N6: 0 | O6: 0 | P6: 0 | Q6: 0 | R6: 0 | S6: 0 | T6: 0 | U6: 0 | V6: 0 | W6: 0 | X6: 0 | Y6: 7 | Z6: 0.875 | AA6: 0.3125 | AB6: 0.5625 | AC6: 0 | AD6: 2.5 | AE6: 0 | AF6: 7
A7: Wheat | B7: Delivered to 1 sergeant for the year, 4 quarters 2 bushels, because he takes the rest in barley. | C7: 0 | D7: 0 | E7: 0 | F7: 0 | G7: 0 | H7: 0 | I7: 0 | J7: 0 | K7: 0 | L7: 0 | M7: 0 | N7: 0 | O7: 0 | P7: 0 | Q7: 0 | R7: 0 | S7: 0 | T7: 0 | U7: 0 | V7: 0 | W7: 0 | X7: 4 | Y7: 2 | Z7: 4.25 | AA7: 4.25 | AB7: 0 | AC7: 4 | AD7: 2
A8: Wheat | B8: . | C8: 0 | D8: 0 | E8: 0 | F8: 0 | G8: 0 | H8: 0 | I8: 0 | J8: 0 | K8: 0 | L8: 0 | M8: 0 | N8: 0 | O8: 0 | P8: 0 | Q8: 0 | R8: 0 | S8: 0 | T8: 0 | U8: 0 | V8: 0 | W8: 0 | X8: 0 | Y8: 0 | Z8: 0 | AA8: 0 | AB8: 0 | AC8: 0 | AD8: 0
A9: Wheat | B9: . | C9: 0 | D9: 0 | E9: 0 | F9: 0 | G9: 0 | H9: 0 | I9: 0 | J9: 0 | K9: 0 | L9: 0 | M9: 0 | N9: 0 | O9: 0 | P9: 0 | Q9: 0 | R9: 0 | S9: 0 | T9: 0 | U9: 0 | V9: 0 | W9: 0 | X9: 0 | Y9: 0 | Z9: 0 | AA9: 0 | AB9: 0 | AC9: 0 | AD9: 0
A10: Wheat | B10: bread made for the weeders and carriers of hay, 1 qr. | C10: 0 | D10: 0 | E10: 0 | F10: 0 | G10: 0 | H10: 0 | I10: 0 | J10: 0 | K10: 0 | L10: 0 | M10: 0 | N10: 0 | O10: 0 | P10: 0 | Q10: 0 | R10: 0 | S10: 0 | T10: 0 | U10: 0 | V10: 0 | W10: 0
A11: Wheat | B11: . | C11: 0 | D11: 0 | E11: 0 | F11: 0 | G11: 0 | H11: 0 | I11: 0 | J11: 0 | K11: 0 | L11: 0 | M11: 0 | N11: 0 | O11: 0 | P11: 0 | Q11: 0 | R11: 0 | S11: 0 | T11: 0 | U11: 0 | V11: 0 | W11: 0 | X11: 0 | Y11: 0 | Z11: 0 | AA11: 0 | AB11: 0 | AC11: 0 | AD11: 0
A12: Wheat | B12: . | C12: 0 | D12: 0 | E12: 0 | F12: 0 | G12: 0 | H12: 0 | I12: 0 | J12: 0 | K12: 0 | L12: 0 | M12: 0 | N12: 0 | O12: 0 | P12: 0 | Q12: 0 | R12: 0 | S12: 0 | T12: 0 | U12: 0 | V12: 0 | W12: 0 | X12: 0 | Y12: 0 | Z12: 0 | AA12: 0 | AB12: 0 | AC12: 0 | AD12: 0
A13: Wheat | B13: provision of 4 harvest boon-works, 3 quarters. | C13: 0 | D13: 0 | E13: 0 | F13: 0 | G13: 0 | H13: 0 | I13: 0 | J13: 0 | K13: 0 | L13: 0 | M13: 0 | N13: 0 | O13: 0 | P13: 0 | Q13: 0 | R13: 0 | S13: 0 | T13: 0 | U13: 0 | V13: 0 | W13: 0 | X13: 3 | Y13: 0 | Z13: 3 | AA13: 3 | AB13: 0 | AC13: 3 | AD13: 0
A14: Wheat | B14: Sold, 87 quarters 3 bushels, of which 3 quarters 3 bushels are curall. | C14: 0 | D14: 0 | E14: 0 | F14: 0 | G14: 0 | H14: 0 | I14: 0 | J14: 0 | K14: 0 | L14: 0 | M14: 0 | N14: 0 | O14: 0 | P14: 0 | Q14: 90 | R14: 6 | S14: 90.75 | T14: 0 | U14: 0 | V14: 0 | W14: 0 | X14: 3 | Y14: 3 | Z14: 3.375 | AA14: 87.375 | AB14: -84 | AC14: 87 | AD14: 3 | AE14: 3 | AF14: 3
A15: Wheat | B15: Total | C15: 0 | D15: 0 | E15: 0 | F15: 0 | G15: 0 | H15: 0 | I15: 0 | J15: 0 | K15: 0 | L15: 0 | M15: 0 | N15: 0 | O15: 0 | P15: 0 | Q15: 0 | R15: 0 | S15: 0 | T15: 0 | U15: 0 | V15: 0 | W15: 0
A16: Winter barley | B16: {yield: 4-fold plus 2 bushels} | C16: 0 | D16: 0 | E16: 0 | F16: 0 | G16: 0 | H16: 0 | I16: 0 | J16: 0 | K16: 0 | L16: 0 | M16: 0 | N16: 0 | O16: 0 | P16: 0 | Q16: 0 | R16: 0 | S16: 0 | T16: 0 | U16: 0 | V16: 0 | W16: 0 | X16: 0 | Y16: 2 | Z16: 0.25 | AA16: 0.25 | AB16: 0 | AC16: 0 | AD16: 2
A17: Winter barley | B17: The same render account for 7.5 quarters 2 bushels from the whole issue of winter barley from the grange with the increment of the granary. | C17: 0 | D17: 0 | E17: 0 | F17: 0 | G17: 0 | H17: 0 | I17: 0 | J17: 0 | K17: 0 | L17: 0 | M17: 0 | N17: 0 | O17: 0 | P17: 0 | Q17: 0 | R17: 0 | S17: 0 | T17: 7.5 | U17: 2 | V17: 7.75 | W17: 0 | X17: 7.5 | Y17: 2 | Z17: 7.75 | AA17: 7.75 | AB17: 0 | AC17: 7.5 | AD17: 2
A18: Winter barley | B18: Sown over 4 acres measured by the perch which lie in the field of ..., 1 qr 2 bushels Mixed below with barley for the liveries of the manorial servants, 6.5 quarters. | C18: 0 | D18: 0 | E18: 6.5 | F18: 0 | G18: 6.5 | H18: 0 | I18: 0 | J18: 0 | K18: 0 | L18: 0 | M18: 0 | N18: 6.5 | O18: 0 | P18: 6.5 | Q18: 0 | R18: 0 | S18: 0 | T18: 0 | U18: 0 | V18: 0 | W18: 0
A19: Winter barley | B19: Total | C19: 0 | D19: 0 | E19: 0 | F19: 0 | G19: 0 | H19: 0 | I19: 0 | J19: 0 | K19: 0 | L19: 0 | M19: 0 | N19: 0 | O19: 0 | P19: 0 | Q19: 0 | R19: 0 | S19: 0 | T19: 0 | U19: 0 | V19: 0 | W19: 0
A20: Barley | B20: (yield: three-fold plus 2 bushels) | C20: 0 | D20: 0 | E20: 0 | F20: 0 | G20: 0 | H20: 0 | I20: 0 | J20: 0 | K20: 0 | L20: 0 | M20: 0 | N20: 0 | O20: 0 | P20: 0 | Q20: 0 | R20: 0 | S20: 0 | T20: 0 | U20: 0 | V20: 0 | W20: 0 | X20: 0 | Y20: 2 | Z20: 0.25 | AA20: 0.25 | AB20: 0 | AC20: 0 | AD20: 2
A21: Barley | B21: The same render account for 4.5 quarters 2 bushels from the whole issue of barley from the grange with the increment of the granary. | C21: 0 | D21: 0 | E21: 0 | F21: 0 | G21: 0 | H21: 0 | I21: 0 | J21: 0 | K21: 0 | L21: 0 | M21: 0 | N21: 0 | O21: 0 | P21: 0 | Q21: 0 | R21: 0 | S21: 0 | T21: 4.5 | U21: 2 | V21: 4.75 | W21: 0 | X21: 4.5 | Y21: 2 | Z21: 4.75 | AA21: 4.75 | AB21: 0 | AC21: 4.5 | AD21: 2
A22: Barley | B22: 6.5 quarters received above from winter barley. | C22: 0 | D22: 0 | E22: 0 | F22: 0 | G22: 0 | H22: 0 | I22: 0 | J22: 0 | K22: 0 | L22: 0 | M22: 0 | N22: 0 | O22: 0 | P22: 0 | Q22: 0 | R22: 0 | S22: 0 | T22: 0 | U22: 0 | V22: 0 | W22: 0 | X22: 6.5 | Y22: 0 | Z22: 6.5 | AA22: 6.5 | AB22: 0 | AC22: 6.5 | AD22: 0
A23: Barley | B23: 1.5 quarters [received] below from vetches. | C23: 0 | D23: 0 | E23: 0 | F23: 0 | G23: 0 | H23: 0 | I23: 0 | J23: 0 | K23: 0 | L23: 0 | M23: 0 | N23: 0 | O23: 0 | P23: 0 | Q23: 0 | R23: 0 | S23: 0 | T23: 0 | U23: 0 | V23: 0 | W23: 0 | X23: 1.5 | Y23: 0 | Z23: 1.5 | AA23: 1.5 | AB23: 0 | AC23: 1.5 | AD23: 0
A24: Barley | B24: 20.5 quarters bought as noted above. | C24: 0 | D24: 0 | E24: 0 | F24: 0 | G24: 0 | H24: 20.5 | I24: 0 | J24: 20.5 | K24: 0 | L24: 0 | M24: 0 | N24: 0 | O24: 0 | P24: 0 | Q24: 0 | R24: 0 | S24: 0 | T24: 0 | U24: 0 | V24: 0 | W24: 0 | X24: 20.5 | Y24: 0 | Z24: 20.5 | AA24: 20.5 | AB24: 0 | AC24: 20.5 | AD24: 0
A25: Barley | B25: Total, 33 quarters 2 bushels | C25: 0 | D25: 0 | E25: 0 | F25: 0 | G25: 0 | H25: 0 | I25: 0 | J25: 0 | K25: 0 | L25: 0 | M25: 0 | N25: 0 | O25: 0 | P25: 0 | Q25: 0 | R25: 0 | S25: 0 | T25: 0 | U25: 0 | V25: 0 | W25: 0 | X25: 33 | Y25: 2 | Z25: 33.25 | AA25: 33.25 | AB25: 0 | AC25: 33 | AD25: 2
A26: Barley | B26: Sown over 6 acres measured by the perch which lie in the field of Westssend', 3 quarters. | C26: 0 | D26: 0 | E26: 3 | F26: 0 | G26: 3 | H26: 0 | I26: 0 | J26: 0 | K26: 0 | L26: 0 | M26: 0 | N26: 0 | O26: 0 | P26: 0 | Q26: 0 | R26: 0 | S26: 0 | T26: 0 | U26: 0 | V26: 0 | W26: 0 | X26: 3 | Y26: 0 | Z26: 3 | AA26: 3 | AB26: 0 | AC26: 3 | AD26: 0
A27: Barley | B27: that is, 4 bushels an acre. | C27: 0 | D27: 0 | E27: 0 | F27: 0 | G27: 0 | H27: 0 | I27: 0 | J27: 0 | K27: 0 | L27: 0 | M27: 0 | N27: 0 | O27: 0 | P27: 0 | Q27: 0 | R27: 0 | S27: 0 | T27: 0 | U27: 0 | V27: 0 | W27: 0 | X27: 0 | Y27: 4 | Z27: 0.5 | AA27: 0.5 | AB27: 0 | AC27: 0 | AD27: 4
A28: Barley | B28: Delivered to 1 sergeant for the year, 3 quarters 2 bushels, because he takes the rest in wheat. | C28: 0 | D28: 0 | E28: 0 | F28: 0 | G28: 0 | H28: 0 | I28: 0 | J28: 0 | K28: 0 | L28: 0 | M28: 0 | N28: 0 | O28: 0 | P28: 0 | Q28: 0 | R28: 0 | S28: 0 | T28: 0 | U28: 0 | V28: 0 | W28: 0 | X28: 3 | Y28: 2 | Z28: 3.25 | AA28: 3.25 | AB28: 0 | AC28: 3 | AD28: 2
A29: Barley | B29: Delivered to 1 carter and 3 drovers for the year, 26 quarters. | C29: 0 | D29: 0 | E29: 0 | F29: 0 | G29: 0 | H29: 0 | I29: 0 | J29: 0 | K29: 0 | L29: 0 | M29: 0 | N29: 0 | O29: 0 | P29: 0 | Q29: 0 | R29: 0 | S29: 0 | T29: 0 | U29: 0 | V29: 0 | W29: 0 | X29: 26 | Y29: 0 | Z29: 26 | AA29: 26 | AB29: 0 | AC29: 26 | AD29: 0
A30: Barley | B30: Sold at the audit, 1 qr. | C30: 0 | D30: 0 | E30: 0 | F30: 0 | G30: 0 | H30: 0 | I30: 0 | J30: 0 | K30: 0 | L30: 0 | M30: 0 | N30: 0 | O30: 0 | P30: 0 | Q30: 0 | R30: 0 | S30: 0 | T30: 0 | U30: 0 | V30: 0 | W30: 0
A31: Barley | B31: Total | C31: 0 | D31: 0 | E31: 0 | F31: 0 | G31: 0 | H31: 0 | I31: 0 | J31: 0 | K31: 0 | L31: 0 | M31: 0 | N31: 0 | O31: 0 | P31: 0 | Q31: 0 | R31: 0 | S31: 0 | T31: 0 | U31: 0 | V31: 0 | W31: 0
A32: Oats | B32: (Yield: 26 quarters more than sown} | C32: 0 | D32: 0 | E32: 26 | F32: 0 | G32: 26 | H32: 0 | I32: 0 | J32: 0 | K32: 0 | L32: 0 | M32: 0 | N32: 0 | O32: 0 | P32: 0 | Q32: 0 | R32: 0 | S32: 0 | T32: 0 | U32: 0 | V32: 0 | W32: 0 | X32: 26 | Y32: 0 | Z32: 26 | AA32: 26 | AB32: 0 | AC32: 26 | AD32: 0
A33: Oats | B33: The same render account for 61.5 quarters 1 bushels from the whole issue of oats from the grange with the increment of the granary. | C33: 0 | D33: 0 | E33: 0 | F33: 0 | G33: 0 | H33: 0 | I33: 0 | J33: 0 | K33: 0 | L33: 0 | M33: 0 | N33: 0 | O33: 0 | P33: 0 | Q33: 0 | R33: 0 | S33: 0 | T33: 61.5 | U33: 1 | V33: 61.625 | W33: 0 | X33: 61.5 | Y33: 1 | Z33: 61.625 | AA33: 61.625 | AB33: 0 | AC33: 61.5 | AD33: 1
A34: Oats | B34: 13 quarters by estimation in sheaves given to oxen. | C34: 0 | D34: 0 | E34: 0 | F34: 0 | G34: 0 | H34: 0 | I34: 0 | J34: 0 | K34: 0 | L34: 0 | M34: 0 | N34: 0 | O34: 0 | P34: 0 | Q34: 0 | R34: 0 | S34: 0 | T34: 0 | U34: 0 | V34: 0 | W34: 0 | X34: 13 | Y34: 0 | Z34: 13 | AA34: 13 | AB34: 0 | AC34: 13 | AD34: 0
A35: Oats | B35: Total, 74.5 quarters 1 bushels | C35: 0 | D35: 0 | E35: 0 | F35: 0 | G35: 0 | H35: 0 | I35: 0 | J35: 0 | K35: 0 | L35: 0 | M35: 0 | N35: 0 | O35: 0 | P35: 0 | Q35: 0 | R35: 0 | S35: 0 | T35: 0 | U35: 0 | V35: 0 | W35: 0 | X35: 74.5 | Y35: 1 | Z35: 74.625 | AA35: 74.625 | AB35: 0 | AC35: 74.5 | AD35: 1
A36: Oats | B36: Sown over 78 acres measured by the perch which lie in the field of Westfeld', 40.5 quarters 2 bushels. | C36: 0 | D36: 0 | E36: 40.5 | F36: 2 | G36: 40.75 | H36: 0 | I36: 0 | J36: 0 | K36: 0 | L36: 0 | M36: 0 | N36: 0 | O36: 0 | P36: 0 | Q36: 0 | R36: 0 | S36: 0 | T36: 0 | U36: 0 | V36: 0 | W36: 0 | X36: 40.5 | Y36: 2 | Z36: 40.75 | AA36: 40.75 | AB36: 0 | AC36: 40.5 | AD36: 2
A37: Oats | B37: that is, 4 bushels an acre, plus 1.5 quarters 2 bushels in all. | C37: 0 | D37: 0 | E37: 0 | F37: 0 | G37: 0 | H37: 0 | I37: 0 | J37: 0 | K37: 0 | L37: 0 | M37: 0 | N37: 0 | O37: 0 | P37: 0 | Q37: 0 | R37: 0 | S37: 0 | T37: 0 | U37: 0 | V37: 0 | W37: 0 | X37: 1.5 | Y37: 2 | Z37: 1.75 | AA37: 0.5 | AB37: 1.25 | AC37: 0 | AD37: 4 | AE37: 1.5 | AF37: 2
A38: Oats | B38: . | C38: 0 | D38: 0 | E38: 0 | F38: 0 | G38: 0 | H38: 0 | I38: 0 | J38: 0 | K38: 0 | L38: 0 | M38: 0 | N38: 0 | O38: 0 | P38: 0 | Q38: 0 | R38: 0 | S38: 0 | T38: 0 | U38: 0 | V38: 0 | W38: 0 | X38: 0 | Y38: 0 | Z38: 0 | AA38: 0 | AB38: 0 | AC38: 0 | AD38: 0
A39: Oats | B39: . | C39: 0 | D39: 0 | E39: 0 | F39: 0 | G39: 0 | H39: 0 | I39: 0 | J39: 0 | K39: 0 | L39: 0 | M39: 0 | N39: 0 | O39: 0 | P39: 0 | Q39: 0 | R39: 0 | S39: 0 | T39: 0 | U39: 0 | V39: 0 | W39: 0 | X39: 0 | Y39: 0 | Z39: 0 | AA39: 0 | AB39: 0 | AC39: 0 | AD39: 0
A40: Oats | B40: . | C40: 0 | D40: 0 | E40: 0 | F40: 0 | G40: 0 | H40: 0 | I40: 0 | J40: 0 | K40: 0 | L40: 0 | M40: 0 | N40: 0 | O40: 0 | P40: 0 | Q40: 0 | R40: 0 | S40: 0 | T40: 0 | U40: 0 | V40: 0 | W40: 0 | X40: 0 | Y40: 0 | Z40: 0 | AA40: 0 | AB40: 0 | AC40: 0 | AD40: 0
...

Sheet Sale of Corn Prices
A1: Heading | B1: Sentence | C1: Total in Pounds | D1: Pounds | E1: Shillings | F1: Pence | G1: Corn | H1: Total Quarters Except 1 | I1: Total Bushels Except 1 | J1: Total Corn Cross-Check | K1: Total Corn Manorial Account | L1: Corn Quantity Error | M1: Quarters 0 | N1: Bushels 0 | O1: shilling a quarter 1 | P1: pence a quarter 1 | Q1: Quarters 1 | R1: Bushels 1 | S1: shilling a quarter 2 | T1: pence a quarter 2 | U1: Quarters 2 | V1: Bushels 2 | W1: shilling a quarter 3 | X1: pence a quarter 3 | Y1: Quarters 3 | Z1: Bushels 3 | AA1: shilling a quarter 4 | AB1: pence a quarter 4 | AC1: £ a quarter 1 | AD1: £ a quarter 2 | AE1: £ a quarter 3 | AF1: £ a quarter 4 | AG1: Quarters Sold | AH1: Weighted Average Price per Quarter | AI1: Non-Weighted Average Price per Quarter | AJ1: Corn lowercase
A2: Sale of corn | B2: The same render account for £25 4 shilling from 84 quarters of wheat sold, at 6 shilling a quarters. | C2: 25.2 | D2: 25 | E2: 4 | F2: 0 | G2: wheat | H2: 84 | I2: 0 | J2: 84 | K2: 84 | L2: 0 | M2: 84 | N2: 0 | O2: 6 | P2: 0 | AC2: 0.3 | AG2: 84 | AH2: 0.3 | AI2: 0.3 | AJ2: wheat
A3: Sale of corn | B3: 8 shilling 1.5pence from 3 quarters 3 bushels of curall sold, at 2 shilling 4pence a quarters. | C3: 0.41 | D3: 0 | E3: 8 | F3: 1.5 | G3: curall | H3: 3 | I3: 3 | J3: 3.375 | K3: 3.375 | L3: 0 | M3: 3 | N3: 3 | O3: 2 | P3: 4 | AC3: 0.11666667 | AG3: 3.375 | AH3: 0.11666667 | AI3: 0.11666667 | AJ3: curall
A4: Sale of corn | B4: 3 shilling from 1 quarters of barley sold at the audit. | C4: 0.15 | D4: 0 | E4: 3 | F4: 0 | G4: barley | H4: 1 | I4: 0 | J4: 1 | K4: 1 | L4: 0 | M4: 1 | N4: 0 | AC4: 0.15 | AG4: 1 | AH4: 0.15 | AI4: 0.15 | AJ4: barley
A5: Sale of corn | B5: £1 8 shilling from 12 quarters of oats sold, at 2 shilling 4pence a quarters. | C5: 1.4 | D5: 1 | E5: 8 | F5: 0 | G5: oats | H5: 12 | I5: 0 | J5: 12 | K5: 12 | L5: 0 | M5: 12 | N5: 0 | O5: 2 | P5: 4 | AC5: 0.11666667 | AG5: 12 | AH5: 0.11666667 | AI5: 0.11666667 | AJ5: oats
A6: Sale of corn | B6: Total, £27 3 shilling 1.5pence | C6: 27.16 | D6: 27 | E6: 3 | F6: 1.5 | H6: 0 | I6: 0 | J6: 0 | K6: 0 | L6: 0 | M6: 0 | N6: 0 | AC6: inf | AG6: 0 | AH6: inf | AI6: inf

Sheet raw data
A1: Heading | B1: Sentence | C1: Total in Pounds | D1: Pounds | E1: Shillings | F1: Pence | G1: Corn | H1: Total Quarters Except 1 | I1: Total Bushels Except 1 | J1: Total Corn Cross-Check | K1: Total Corn Manorial Account | L1: Corn Quantity Error | M1: Quarters 1 | N1: Bushels 1 | O1: Quarters 2 | P1: Bushels 2 | Q1: Quarters 3 | R1: Bushels 3 | S1: Quarters 4 | T1: Bushels 4 | U1: shilling a quarter 1 | V1: pence a quarter 1 | W1: shilling a quarter 2 | X1: pence a quarter 2 | Y1: shilling a quarter 3 | Z1: pence a quarter 3 | AA1: shilling a quarter 4 | AB1: pence a quarter 4 | AC1: shilling a bushel 1 | AD1: pence a bushel 1 | AE1: shilling a bushel 2 | AF1: pence a bushel 2 | AG1: shilling a bushel 3 | AH1: pence a bushel 3 | AI1: shilling a bushel 4 | AJ1: pence a bushel 4
A2: Arrears | B2: James de Northon', bailiff, and William le Stynt', reeve, render account for £9 18 shilling 9.5pence of arrears from the previous year. | C2: 9.94 | D2: 9 | E2: 18 | F2: 9.5 | H2: 0 | I2: 0 | J2: 0 | K2: 0 | L2: 0 | M2: 0 | N2: 0
A3: Arrears | B3: All delivered to Sir Geoffrey, treasurer of Wolvesey, and they are quit. | C3: 0 | D3: 0 | E3: 0 | F3: 0 | H3: 0 | I3: 0 | J3: 0 | K3: 0 | L3: 0 | M3: 0 | N3: 0
A4: Rents of assize | B4: The same render account for £8 16 shilling 10.25pence for all rents of assize at Easter (22 April). | C4: 8.84 | D4: 8 | E4: 16 | F4: 10.25 | H4: 0 | I4: 0 | J4: 0 | K4: 0 | L4: 0 | M4: 0 | N4: 0
A5: Rents of assize | B5: £8 16 shilling 10.25pence at Michaelmas (29 September). | C5: 8.84 | D5: 8 | E5: 16 | F5: 10.25 | H5: 0 | I5: 0 | J5: 0 | K5: 0 | L5: 0 | M5: 0 | N5: 0
A6: Rents of assize | B6: Total, £17 13 shilling 9pence | C6: 17.69 | D6: 17 | E6: 13 | F6: 9 | H6: 0 | I6: 0 | J6: 0 | K6: 0 | L6: 0 | M6: 0 | N6: 0
A7: Quittances | B7: In quittance of 1 reeve for the year 5 shilling. | C7: 0.25 | D7: 0 | E7: 5 | F7: 0 | H7: 0 | I7: 0 | J7: 0 | K7: 0 | L7: 0 | M7: 0 | N7: 0
A8: Quittances | B8: 1 shepherd for the year 3 shilling. | C8: 0.15 | D8: 0 | E8: 3 | F8: 0 | H8: 0 | I8: 0 | J8: 0 | K8: 0 | L8: 0 | M8: 0 | N8: 0
A9: Quittances | B9: 3 ploughmen for the year 6 shilling. | C9: 0.3 | D9: 0 | E9: 6 | F9: 0 | H9: 0 | I9: 0 | J9: 0 | K9: 0 | L9: 0 | M9: 0 | N9: 0
A10: Quittances | B10: 1 smith for the year 2 shilling Total, 16 shilling | C10: 0.1 | D10: 0 | E10: 2 | F10: 0 | H10: 0 | I10: 0 | J10: 0 | K10: 0 | L10: 0 | M10: 0 | N10: 0
A11: Defaults of rent | B11: In default of 2 acres of Sampson drawn into demesne 1 shilling 3pence. | C11: 0.06 | D11: 0 | E11: 1 | F11: 3 | H11: 0 | I11: 0 | J11: 0 | K11: 0 | L11: 0 | M11: 0 | N11: 0
A12: Defaults of rent | B12: 2.5 acres in Costouue 4 shilling 9pence. | C12: 0.24 | D12: 0 | E12: 4 | F12: 9 | H12: 0 | I12: 0 | J12: 0 | K12: 0 | L12: 0 | M12: 0 | N12: 0
A13: Defaults of rent | B13: certain land of Gundevyl' drawn into demesne 6pence. | C13: 0.03 | D13: 0 | E13: 0 | F13: 6 | H13: 0 | I13: 0 | J13: 0 | K13: 0 | L13: 0 | M13: 0 | N13: 0
... A36: Issues of the manor | B36: 1 shilling 3pence from 10 hens from churchscot sold. | C36: 0.06 | D36: 0 | E36: 1 | F36: 3 | H36: 0 | I36: 0 | J36: 0 | K36: 0 | L36: 0 | M36: 0 | N36: 0
A37: Issues of the manor | B37: 3 shilling 10.25pence from 19 quarters of wheat from Rikestreth'. | C37: 0.19 | D37: 0 | E37: 3 | F37: 10.25 | G37: wheat | H37: 19 | I37: 0 | J37: 19 | K37: 19 | L37: 0 | M37: 19 | N37: 0
A38: Issues of the manor | B38: 6 shilling 9pence from customary tenants for release from harrowing which is called `Dustsegynge'. | C38: 0.34 | D38: 0 | E38: 6 | F38: 9 | H38: 0 | I38: 0 | J38: 0 | K38: 0 | L38: 0 | M38: 0 | N38: 0
A39: Issues of the manor | B39: £1 6 shilling 8pence from 2 casks of cider remaining from the previous year sold without the wood. | C39: 1.33 | D39: 1 | E39: 6 | F39: 8 | H39: 0 | I39: 0 | J39: 0 | K39: 0 | L39: 0 | M39: 0 | N39: 0
A40: Issues of the manor | B40: 5 shilling from .5 cask of cider solpence Total, £6 6.25pence | C40: 6.03 | D40: 6 | E40: 0 | F40: 6.25 | H40: 0 | I40: 0 | J40: 0 | K40: 0 | L40: 0 | M40: 0 | N40: 0
A41: Sale of corn | B41: The same render account for £25 4 shilling from 84 quarters of wheat sold, at 6 shilling a quarters. | C41: 25.2 | D41: 25 | E41: 4 | F41: 0 | G41: wheat | H41: 84 | I41: 0 | J41: 84 | K41: 84 | L41: 0 | M41: 84 | N41: 0 | U41: 6 | V41: 0
A42: Sale of corn | B42: 8 shilling 1.5pence from 3 quarters 3 bushels of curall sold, at 2 shilling 4pence a quarters. | C42: 0.41 | D42: 0 | E42: 8 | F42: 1.5 | G42: curall | H42: 3 | I42: 3 | J42: 3.375 | K42: 3.375 | L42: 0 | M42: 3 | N42: 3 | U42: 2 | V42: 4
A43: Sale of corn | B43: 3 shilling from 1 quarters of barley sold at the audit. | C43: 0.15 | D43: 0 | E43: 3 | F43: 0 | G43: barley | H43: 1 | I43: 0 | J43: 1 | K43: 1 | L43: 0 | M43: 1 | N43: 0
A44: Sale of corn | B44: £1 8 shilling from 12 quarters of oats sold, at 2 shilling 4pence a quarters. | C44: 1.4 | D44: 1 | E44: 8 | F44: 0 | G44: oats | H44: 12 | I44: 0 | J44: 12 | K44: 12 | L44: 0 | M44: 12 | N44: 0 | U44: 2 | V44: 4
A45: Sale of corn | B45: Total, £27 3 shilling 1.5pence | C45: 27.16 | D45: 27 | E45: 3 | F45: 1.5 | H45: 0 | I45: 0 | J45: 0 | K45: 0 | L45: 0 | M45: 0 | N45: 0
A46: Entry and marriage fines | B46: The same render account for 2 shilling from Peter Burel for 5 acres of purpresture which he recovered from Joan de Marisco. | C46: 0.1 | D46: 0 | E46: 2 | F46: 0 | H46: 0 | I46: 0 | J46: 0 | K46: 0 | L46: 0 | M46: 0 | N46: 0
A47: Entry and marriage fines | B47: £1 6 shilling 8pence from Richard, son of Richard le Hyne, and Margaret his wife, daughter of John ate Pull', for 1 messuage and .5 virgate of land which belonged to John ate Pull' by quitclaim of Hugh ate Slade and Richard le Hyne. | C47: 1.33 | D47: 1 | E47: 6 | F47: 8 | H47: 0 | I47: 0 | J47: 0 | K47: 0 | L47: 0 | M47: 0 | N47: 0
A48: Entry and marriage fines | B48: 13 shilling 4pence from William ate Hole to have 1 messuage and 1 ferling of land which belonged to Robert ate Hole his father. | C48: 0.67 | D48: 0 | E48: 13 | F48: 4 | H48: 0 | I48: 0 | J48: 0 | K48: 0 | L48: 0 | M48: 0 | N48: 0
A49: Entry and marriage fines | B49: £1 13 shilling 4pence from John Knygt' to have 1 messuage 8 acres of land which he recovered from Robert de Tymbeden' by inquest taken in the absence of the said Robert for his many defaults. | C49: 1.67 | D49: 1 | E49: 13 | F49: 4 | H49: 0 | I49: 0 | J49: 0 | K49: 0 | L49: 0 | M49: 0 | N49: 0
A50: Entry and marriage fines | B50: 13 shilling 4pence from Robert Babbe and Emma his wife to have 1 messuage and 1 curtilage and 4 acres of land which belonged to Blyssot', relict of Sampson. | C50: 0.67 | D50: 0 | E50: 13 | F50: 4 | H50: 0 | I50: 0 | J50: 0 | K50: 0 | L50: 0 | M50: 0 | N50: 0
A51: Entry and marriage fines | B51: Total, £4 8 shilling 8pence | C51: 4.43 | D51: 4 | E51: 8 | F51: 8 | H51: 0 | I51: 0 | J51: 0 | K51: 0 | L51: 0 | M51: 0 | N51: 0
A52: Perquisites | B52: The same render account for 6pence from the reeve of Bentley because he put himself on an inquest. | C52: 0.03 | D52: 0 | E52: 0 | F52: 6 | H52: 0 | I52: 0 | J52: 0 | K52: 0 | L52: 0 | M52: 0 | N52: 0
A53: Perquisites | B53: 2 shilling from Robert de Tettemoll' for false complaint. | C53: 0.1 | D53: 0 | E53: 2 | F53: 0 | H53: 0 | I53: 0 | J53: 0 | K53: 0 | L53: 0 | M53: 0 | N53: 0
A54: Perquisites | B54: 2 shilling from the tithing of Bentley because it did not produce in court Richard Babb' and William Archyr. | C54: 0.1 | D54: 0 | E54: 2 | F54: 0 | H54: 0 | I54: 0 | J54: 0 | K54: 0 | L54: 0 | M54: 0 | N54: 0
A55: Perquisites | B55: 3pence from Richard Vassal for default. | C55: 0.01 | D55: 0 | E55: 0 | F55: 3 | H55: 0 | I55: 0 | J55: 0 | K55: 0 | L55: 0 | M55: 0 | N55: 0
A56: Perquisites | B56: 6pence from Peter Sweyn for the hue. | C56: 0.03 | D56: 0 | E56: 0 | F56: 6 | H56: 0 | I56: 0 | J56: 0 | K56: 0 | L56: 0 | M56: 0 | N56: 0
... A98: Expenses of ploughs | B98: forage' bought for oxen 8 shilling Total, £5 18 shilling 11.5pence | C98: 5.95 | D98: 5 | E98: 18 | F98: 11.5 | H98: 0 | I98: 0 | J98: 0 | K98: 0 | L98: 0 | M98: 0 | N98: 0
A99: Purchase of seed and liveries | B99: In 20.5 quarters of barley bought for the liveries of the manorial servants £2 16 shilling 4pence, at 3 shilling 4pence a quarters for 7 quarters, 2 shilling 8pence a quarters for 4.5 quarters, and 2 shilling 4pence a quarters for 9 quarters. | C99: 2.82 | D99: 2 | E99: 16 | F99: 4 | G99: barley | H99: 20.5 | I99: 0 | J99: 20.5 | K99: 20.5 | L99: 0 | M99: 20.5 | N99: 0 | O99: 7 | P99: 0 | Q99: 4.5 | R99: 0 | S99: 9 | T99: 0 | U99: 3 | V99: 4 | W99: 2 | X99: 8 | Y99: 2 | Z99: 4
A100: Purchase of seed and liveries | B100: Total, £2 16 shilling 4pence | C100: 2.82 | D100: 2 | E100: 16 | F100: 4 | H100: 0 | I100: 0 | J100: 0 | K100: 0 | L100: 0 | M100: 0 | N100: 0
A101: Carts | B101: In 1 pair of wheels bought 2 shilling .5pence. | C101: 0.12 | D101: 0 | E101: 2 | F101: 5 | H101: 0 | I101: 0 | J101: 0 | K101: 0 | L101: 0 | M101: 0 | N101: 0
A102: Carts | B102: clouts with nails bought 8pence. | C102: 0.03 | D102: 0 | E102: 0 | F102: 8 | H102: 0 | I102: 0 | J102: 0 | K102: 0 | L102: 0 | M102: 0 | N102: 0
A103: Carts | B103: grease bought 3.5pence. | C103: 0.01 | D103: 0 | E103: 0 | F103: 3.5 | H103: 0 | I103: 0 | J103: 0 | K103: 0 | L103: 0 | M103: 0 | N103: 0
...
