Workbook

Sheet Overview
A1: BISHOPS WALTHAM | B1: Total in £ | C1: Error | D1: Note
A2: CASH ACCOUNT
A3: RECEIPTS
A4: Arrears total
A5: Rents of assize total
A6: Quittances total
A7: Defaults of rent total
A8: Defaults of rent through the pestilence total
A9: Cotlands defaults total
A10: Cotlands total
A11: Total of quittances and defaults of rent total
A12: Total of rents remaining clear total
A13: Farms total
... A22: Farm of the demesne land total
A23: Total of all receipts (calculated here) | B23: =Receipts!F251 -> 210.17833
A24: Total of all receipts (calculated here) incl arrears | B24: =Receipts!F252 -> 282.08833
A25: Total recorded in the accounts excl. arrears | B25: =Receipts!F250 -> 230.19 | C25: =B25-B23 -> 20.011667
A26: Total recorded in the accounts incl. arrears
A29: EXPENSES
A30: Cost of ploughs total
A31: Purchase of corn total
A32: Cost of carts and wagons total
A33: Cost of dairy total
A34: Purchase of stock total
A35: Sheepcote total
A36: Cost of buildings total
A37: Threshing total
A38: Barley expenses
A39: Expenses of the harvest total
... A43: Annual fees
A44: Total of all expenses per account | B44: =Expenses!F163 -> 54.45
A45: Total of all expenses (calculated here) | B45: =Expenses!F164 -> 53.956667
A46: Total fixed investment | B46: =Expenses!F165 -> 12.888333
A47: Total Demesne fixed investment | B47: =Expenses!F166 -> 8.7883333
A49: Owed by the reeve
A50: From accounts
A52: Allowances
A53: Cash deliveries
A54: Sum of the above
A55: Total of all allowances and cash deliveries in accounts
...

Sheet Receipts
A1: BISHOPS WALTHAM RECEIPT
A2: Heading | B2: £ | C2: s | D2: d | F2: Total in £ | G2: Error | H2: Notes
A3: Arrears | B3: 71 | C3: 18 | D3: 3.5 | F3: 71.91 | H3: Robert de Froyle, bailiff, and Robert Stretthe, reeve, render account for £71 18 shilling 3.5pence of arrears from the previous year.
A4: Arrears | B4: 0 | C4: 0 | D4: 0 | F4: 0 | H4: All delivered to Sir Geoffrey, treasurer of Wolvesey, by 1 tally, and they are quit.
A5: Arrears | F5: 71.91 | G5: =F5-F3 -> 0 | H5: Total
A7: Rents | B7: 14 | C7: 10 | D7: 10.75 | F7: 14.54 | H7: The same render account for £14 10 shilling 10.75pence for all rents of assize at Christmas.
A8: Rents | B8: 23 | C8: 0 | D8: 8.75 | F8: 23.04 | H8: £23 8.75pence at Easter (22 April).
A9: Rents | B9: 14 | C9: 10 | D9: 10.5 | F9: 14.54 | H9: £14 10 shilling 10.5pence at the Nativity of St John the Baptist (24 June).
A10: Rents | B10: 23 | C10: 19 | D10: 3.5 | F10: 23.96 | H10: £23 19 shilling 3.5pence at Michaelmas (29 September).
A11: Rents | B11: 76 | C11: 1 | D11: 9.5 | F11: 76.09 | H11: Total, £76 1 shilling 9.5pence
A12: Rents | F12: 76.08 | G12: -0.01 | H12: Total
A14: Quittances | B14: 0 | C14: 5 | D14: 0 | F14: 0.25 | H14: In quittance of 1 reeve for the year 5 shilling.
A15: Quittances | B15: 0 | C15: 5 | D15: 0 | F15: 0.25 | H15: 1 beadle for the year 5 shilling.
A16: Quittances | B16: 0 | C16: 10 | D16: 0 | F16: 0.5 | H16: 1 swineherd, 1 smith, 1 hayward who kept the lord's corn and pasture and sowed the wheat and barley, 1 shepherd of wethers, and 1 keeper of ewes, 10 shilling, or 2 shilling each.
A17: Quittances | B17: 0 | C17: 8 | D17: 6 | F17: 0.43 | H17: 4 ploughmen for the year, and 1 ploughman for 1 term, 8 shilling 6pence.
A18: Quittances | B18: 0 | C18: 18 | D18: 0 | F18: 0.9 | H18: 9 workers, each of whom are bound to reap everyday at harvest-time 1 acre as it lies and after the harvest are bound to work twice a week, 18 shilling, or 2 shilling each.
A19: Quittances | B19: 0 | C19: 3 | D19: 0 | F19: 0.15 | H19: 3 cottars for the year, each of whom are bound to reap everyday .5 acre as it lies and after the harvest are bound to work once a week, 3 shilling.
A20: Quittances | B20: 0 | C20: 6 | D20: 0 | F20: 0.3 | H20: 2 workers who are bound to reap everyday at harvest-time 1 acre as it lies and after the harvest are bound to work twice a week with their carts, working at the lord's pleasure, besides carrying dung, 6 shilling for the year.
A21: Quittances | B21: 0 | C21: 2 | D21: 0 | F21: =B21+C21/20+D21/240 -> 0.1 | H21: 1 granary-keeper for the year 2 shilling
A22: Quittances | B22: 2 | C22: 17 | D22: 6 | F22: 2.88 | H22: Total, £2 17 shilling 6pence
A23: Quittances | F23: =SUM(F14:F21) -> 2.88 | G23: =F23-F22 -> 0 | H23: Total
A25: Defaults of rent | B25: 1 | C25: 2 | D25: 8 | F25: 1.13 | H25: In default of the land between the Barton and garden drawn into demesne, £1 2 shilling 8pence for the year.
A26: Defaults of rent | B26: 0 | C26: 0 | D26: 8 | F26: 0.03 | H26: the land of Osbert de Langely, 8pence for the year.
A27: Defaults of rent | B27: 0 | C27: 0 | D27: 6 | F27: 0.03 | H27: the land of Richard Baton, 6pence for the year.
A28: Defaults of rent | B28: 0 | C28: 0 | D28: 6 | F28: 0.03 | H28: the land of Hugh son of Agnes, 6pence for the year.
A29: Defaults of rent | B29: 0 | C29: 0 | D29: 3 | F29: 0.01 | H29: the land of Richard Swanemere, 3pence for the year.
A30: Defaults of rent | B30: 0 | C30: 6 | D30: 5 | F30: 0.32 | H30: the land of the mill drawn into the park, 6 shilling 5pence for the year.
A31: Defaults of rent | B31: 0 | C31: 1 | D31: 6 | F31: 0.08 | H31: the rent of Peter Clericus, 1 shilling 6pence for the year.
A32: Defaults of rent | B32: 1 | C32: 12 | D32: 6 | F32: 1.62 | H32: Total, £1 12 shilling 6pence
A33: Defaults of rent | F33: 1.63 | G33: 0.01 | H33: Total
A35: Total of quittances and defaults of rent | B35: 4 | C35: 10 | D35: 0 | F35: 4.5 | H35: Total of quittances and defaults of rent, £4 10 shilling
A36: Total of quittances and defaults of rent | F36: 4.5 | G36: =F36-F35 -> 0 | H36: Total
A38: Total of rents remaining | B38: 71 | C38: 0 | D38: 0 | F38: 71 | H38: Total of rents remaining, £71 11 s. 9.5pence
A39: Total of rents remaining | F39: 71 | G39: =F39-F38 -> 0 | H39: Total
A41: Cumin | B41: 0 | C41: 0 | D41: 0 | F41: 0 | H41: The same render account for 1 lb of cumin from Peter Clericus for a certain messuage.
A42: Cumin | B42: 0 | C42: 0 | D42: 0 | F42: 0 | H42: 1 lb from John Suneburn and Thomas Canon for the same.
A43: Cumin | B43: 0 | C43: 0 | D43: 0 | F43: 0 | H43: 1 lb from Robert Faber to have 1 plot beside the fishpond.
A44: Cumin | B44: 0 | C44: 0 | D44: 0 | F44: 0 | H44: 1 lb from William Burg' for the same.
A45: Cumin | B45: 0 | C45: 0 | D45: 0 | F45: 0 | H45: 1 lb from Robert Ude for the same.
A46: Cumin | B46: 0 | C46: 0 | D46: 0 | F46: 0 | H46: 1 lb from Richard Doggecherl for the same.
...

Sheet Expenses
A1: BISHOPS WALTHAM EXPENSES
A2: Heading | B2: £ | C2: s | D2: d | F2: Total in £ | G2: Error | H2: Notes | J2: Fixed investment | K2: Demesne fixed investment
A3: Cost of ploughs | B3: 0 | C3: 9 | D3: 10 | F3: =B3+C3/20+D3/240 -> 0.49166667 | H3: In iron and steel bought for 4 ploughs for the year and 1 plough for' year 9 shilling 10pence | J3: =F3 -> 0.49166667 | K3: =J3 -> 0.49166667
A4: Cost of ploughs | B4: 0 | C4: 0 | D4: 8 | F4: 0.03 | H4: 4 ploughs made anew 8pence. | J4: =F4 -> 0.03 | K4: =J4 -> 0.03
A5: Cost of ploughs | B5: 0 | C5: 1 | D5: 4 | F5: 0.07 | H5: 4 pairs of wheels bought for ploughs 1 shilling 4pence. | J5: =F5 -> 0.07 | K5: =J5 -> 0.07
A6: Cost of ploughs | B6: 0 | C6: 0 | D6: 5.5 | F6: 0.02 | H6: fitting ploughs with iron tyres 5.5pence. | J6: =F6 -> 0.02 | K6: =J6 -> 0.02
A7: Cost of ploughs | B7: 0 | C7: 3 | D7: 0 | F7: 0.15 | H7: 4 ploughshares bought 3 shilling. | J7: =F7 -> 0.15 | K7: =J7 -> 0.15
A8: Cost of ploughs | B8: 0 | C8: 2 | D8: 6 | F8: 0.12 | H8: 5 plough feet bought 2 shilling 6pence. | J8: =F8 -> 0.12 | K8: =J8 -> 0.12
A9: Cost of ploughs | B9: 0 | C9: 1 | D9: 4 | F9: 0.07 | H9: 1 coulter bought for ploughs 1 shilling 4pence. | J9: =F9 -> 0.07 | K9: =J9 -> 0.07
A10: Cost of ploughs | B10: 0 | C10: 0 | D10: 1.5 | F10: 0.01 | H10: 3 halters of hemp bought for the plough-horses 1.5pence. | J10: =F10 -> 0.01 | K10: =J10 -> 0.01
A11: Cost of ploughs | B11: 0 | C11: 0 | D11: 4 | F11: 0.02 | H11: mending old ploughs 4pence. | J11: =F11 -> 0.02 | K11: =J11 -> 0.02
A12: Cost of ploughs | B12: 0 | C12: 3 | D12: 0 | F12: 0.15 | H12: shoeing 4 plough-horses for the year 3 shilling, because in between times I when they were not ploughing they carried the dung. | J12: =F12 -> 0.15 | K12: =J12 -> 0.15
A13: Cost of ploughs | B13: 0 | C13: 4 | D13: 0 | F13: 0.2 | H13: boon-works of 48 ploughmen from within the hundred 4 shilling, and each ploughman will plough 2 acres as they lie.
A14: Cost of ploughs | B14: 0 | C14: 0 | D14: 0 | F14: 0 | H14: Moreover, within the hundred they are bound to plough 52 acres as they lie for landrighe without the cost of the lorpence.
A15: Cost of ploughs | B15: 0 | C15: 1 | D15: 11 | F15: 0.1 | H15: winter boon-works of 23 ploughmen from Droxford this year 1 shilling 11pence, or 1pence a ploughman, and each ploughman will plough 2 acres as they lie.
A16: Cost of ploughs | B16: 0 | C16: 4 | D16: 1 | F16: 0.2 | H16: Lenten boon-works of 48 ploughmen from within the hundred 4 shilling, or 1pence a ploughman, and each ploughman will plough acre as it lies.
A17: Cost of ploughs | B17: 0 | C17: 13 | D17: 10 | F17: 0.69 | H17: stipend of 4 ploughmen for 8 Saturday ploughings at the time of the winter sowing, 11 Saturdays at the summer sowing, and 10 Saturdays at the fallowing, with the stipend of 1 ploughman for 8 Saturday ploughings at the sowing of the barley, 13 shilling 10pence, or 1.5pence each when ploughing for sowing, and 1pence when fallowing.
A18: Cost of ploughs | B18: 0 | C18: 13 | D18: 6 | F18: 0.68 | H18: stipend of 4 drovers for the year and 1 drover for' year 13 shilling 6pence, or 3 shilling each.
A19: Cost of ploughs | B19: 0 | C19: 9 | D19: 6 | F19: 0.48 | H19: 1 plough-horse bought 9 shilling 6pence.
A20: Cost of ploughs | B20: 5 | C20: 0 | D20: 8 | F20: 5.03 | H20: 9 oxen bought £5 8pence, at 9 shilling 6pence for 1,10 shilling 1pence each for 2, 11 shilling 6pence each for 2, and 12 shilling each for 4..
A21: Cost of ploughs | B21: 0 | C21: 1 | D21: 4 | F21: 0.07 | H21: 4 bushels of peas bought for sowing 1 shilling 4pence.
A22: Cost of ploughs | B22: 0 | C22: 5 | D22: 5 | F22: 0.27 | H22: 3 quarters 2 bushels of vetches bought 5 shilling 5pence, at 1 shilling 8pence a qr.
A23: Cost of ploughs | B23: 1 | C23: 4 | D23: 0 | F23: 1.2 | H23: forage bought to support the lord's stock £1 4 shilling
A24: Cost of ploughs | B24: 10 | C24: 1 | D24: 5 | F24: =B24+C24/20+D24/240 -> 10.070833 | H24: Total, £10 1 shilling 5pence
A25: Cost of ploughs | F25: =SUM(F3:F23) -> 10.051667 | G25: =F25-F24 -> -0.019166667 | H25: Total
A27: Cost of carts | B27: 0 | C27: 14 | D27: 0 | F27: 0.7 | H27: In 1 new cart with iron tyres with all equipment bought 14 shilling. | J27: =F27 -> 0.7 | K27: =J27 -> 0.7
A28: Cost of carts | B28: 0 | C28: 0 | D28: 0.5 | F28: =B28+C28/20+D28/240 -> 0.0020833333 | H28: mending the old cart 1 .5pence. | J28: =F28 -> 0.0020833333 | K28: =J28 -> 0.0020833333
A29: Cost of carts | B29: 0 | C29: 1 | D29: 10 | F29: 0.09 | H29: clouts, nails and grease bought 1 shilling 10pence. | J29: =F29 -> 0.09 | K29: =J29 -> 0.09
A30: Cost of carts | B30: 0 | C30: 0 | D30: 6.25 | F30: 0.03 | H30: fitting the carts with axles at various times with axles bought for the same 6.25pence. | J30: =F30 -> 0.03 | K30: =J30 -> 0.03
A31: Cost of carts | B31: 0 | C31: 0 | D31: 3 | F31: 0.01 | H31: 1 cart-rail made anew for the cart 3pence. | J31: =F31 -> 0.01 | K31: =J31 -> 0.01
A32: Cost of carts | B32: 0 | C32: 0 | D32: 5.5 | F32: 0.02 | H32: 1 pair of traces bought 5.5pence. | J32: =F32 -> 0.02 | K32: =J32 -> 0.02
A33: Cost of carts | B33: 0 | C33: 2 | D33: 4 | F33: 0.12 | H33: 3 collars and 1 pair of saddle-pads bought 2 shilling 4pence. | J33: =F33 -> 0.12 | K33: =J33 -> 0.12
A34: Cost of carts | B34: 0 | C34: 0 | D34: 11 | F34: 0.05 | H34: a hemp rope bought 11pence. | J34: =F34 -> 0.05 | K34: =J34 -> 0.05
A35: Cost of carts | B35: 0 | C35: 0 | D35: 4 | F35: 0.02 | H35: white leather bought 4pence. | J35: =F35 -> 0.02 | K35: =J35 -> 0.02
A36: Cost of carts | B36: 0 | C36: 0 | D36: 2 | F36: 0.01 | H36: 2 pairs of swingletrees 2pence. | J36: =F36 -> 0.01 | K36: =J36 -> 0.01
A37: Cost of carts | B37: 0 | C37: 0 | D37: 2.5 | F37: 0.01 | H37: 1 saddle for the same 2.5pence. | J37: =F37 -> 0.01 | K37: =J37 -> 0.01
A38: Cost of carts | B38: 0 | C38: 0 | D38: 1.25 | F38: 0.01 | H38: 1 thill-rope (tilropt') bought 1.25pence. | J38: =F38 -> 0.01 | K38: =J38 -> 0.01
A39: Cost of carts | B39: 0 | C39: 0 | D39: 2 | F39: 0.01 | H39: hooping wooden frets to the hubs of the old cart 2pence. | J39: =F39 -> 0.01 | K39: =J39 -> 0.01
A40: Cost of carts | B40: 0 | C40: 3 | D40: 0 | F40: 0.15 | H40: forage for 2 cart-horses for the year 3 shilling.
A41: Cost of carts | B41: 0 | C41: 3 | D41: 0 | F41: 0.15 | H41: stipend of 1 carter for the year 3 shilling.
...

Sheet Issues of the Grange
A1: Gross Output | B1: Total Quantity | C1: Account Total Quarters | D1: Bought in Total Quarters | E1: Received from churchscot | F1: Sold Total Quarters | G1: Difference Produced+Bought-Sold | H1: Weighted Average Price per Quarter | I1: Value of Total Production weighted
A2: wheat | B2: 132.25 | D2: 0 | F2: 73.5 | G2: =B2-F2 -> 58.75 | H2: 0.31000567 | I2: =H2*B2 -> 40.99825
A3: curall | B3: 10 | D3: 0 | F3: 8 | G3: =B3-F3 -> 2 | H3: 0.1089372 | I3: =H3*B3 -> 1.089372
A4: barley | B4: 83.375 | D4: 0 | F4: 5.3125 | G4: =B4-F4 -> 78.0625 | H4: 0.2 | I4: =H4*B4 -> 16.675
A5: oats | B5: 205.0625 | D5: 0 | F5: 58.875 | G5: =B5-F5 -> 146.1875 | H5: 0.11365888 | I5: =H5*B5 -> 23.307174
A6: peas | B6: 3.8125 | D6: 0.5 | F6: 0.25 | G6: =B6-F6 -> 3.5625 | H6: 0.13333333 | I6: =H6*B6 -> 0.50833333
A7: vetches | B7: 11.375 | D7: 3.25 | F7: 2.125 | G7: =B7-F7 -> 9.25 | H7: 0.1 | I7: =H7*B7 -> 1.1375
A10: Net output | B10: Gross output | C10: Seed quarters | D10: Seed bushels | E10: Seed total quarters | F10: tithe quarters | G10: tithe bushels | H10: tithe total | I10: manorial servants quarters | J10: manorial servants bushels | K10: manorial servants total quarters | L10: output net of tithe, seed, liveries | M10: in stock from last year | N10: Price in £ | O10: Value of net output in £ | P10: Value of sales (in "Sale of Corn") in £
A11: wheat | B11: =B2 -> 132.25 | C11: 47 | D11: 1 | E11: =C11+D11/8 -> 47.125 | I11: =1+4.5+4+2 -> 11.5 | J11: 1 | K11: =I11+J11/8 -> 11.625 | L11: =B11-E11-K11 -> 73.5 | N11: =H2 -> 0.31000567 | O11: =N11*L11 -> 22.785417
A12: curall | B12: =B3 -> 10 | E12: =C12+D12/8 -> 0 | I12: 1 | J12: 3 | K12: =I12+J12/8 -> 1.375 | L12: =B12-E12-K12 -> 8.625 | N12: =H3 -> 0.1089372 | O12: =N12*L12 -> 0.93958333
A13: barley | B13: =B4 -> 83.375 | C13: 20 | E13: =C13+D13/8 -> 20 | I13: =26+6.5+6.5+4+5+4+1+2+2 -> 57 | J13: =2.5+1.5+1 -> 5 | K13: =I13+J13/8 -> 57.625 | L13: =B13-E13-K13 -> 5.75 | N13: =H4 -> 0.2 | O13: =N13*L13 -> 1.15
A14: oats | B14: =B5 -> 205.0625 | C14: 88.5 | D14: 0.5 | E14: =C14+D14/8 -> 88.5625 | I14: =15.5+5.5+2+4+5+25 -> 57 | J14: =2+2.5 -> 4.5 | K14: =I14+J14/8 -> 57.5625 | L14: =B14-E14-K14 -> 58.9375 | N14: =H5 -> 0.11365888 | O14: =N14*L14 -> 6.6987703
A15: peas | B15: =B6 -> 3.8125 | C15: 2 | D15: 3.5 | E15: =C15+D15/8 -> 2.4375 | I15: 1 | J15: 1 | K15: =I15+J15/8 -> 1.125 | L15: =B15-E15-K15 -> 0.25 | N15: =H6 -> 0.13333333 | O15: =N15*L15 -> 0.033333333
A16: vetches | B16: =B7 -> 11.375 | C16: 5.5 | E16: =C16+D16/8 -> 5.5 | I16: =2+1.5 -> 3.5 | J16: 1 | K16: =I16+J16/8 -> 3.625 | L16: =B16-E16-K16 -> 2.25 | N16: =H7 -> 0.1 | O16: =N16*L16 -> 0.225

Sheet Issues of the Mills

Sheet Stock
A1: BISHOPS WALTHAM STOCK ACCOUNT
C3: added | G3: subtracted
A4: Livestock | B4: Inherited stock | C4: added | D4: strays | E4: herbage | F4: churchscot | G4: of which in default | H4: sold | I4: in murrain | J4: accounted for elsewhere | K4: End-period stock | L4: cross-check | M4: stock building | N4: raw production | O4: Unit price (£) | P4: Value of stock (£) at given value | Q4: Value of stock (£) at sales prices | R4: Sales in (£) | S4: Value of stock building (£) | T4: Value of production (£) at sales prices | U4: Details
A5: Cart-horses | B5: 2 | K5: 2
A6: Mares
A7: Plough horses | B7: 3 | C7: =1+1+1 -> 3 | H7: 2 | K7: 4 | O7: =R7/H7 -> 0.285 | R7: =Receipts!F73+Receipts!F74 -> 0.57
A8: Colts (unspecified years)
A9: Colts (2 years)
A10: Colts (1 year)
A11: Foals
A12: Oxen | B12: 48 | C12: =3+1+1+9 -> 14 | H12: 6 | I12: 2 | K12: 54 | O12: =R12/H12 -> 0.46666667 | R12: =Receipts!F75 -> 2.8
A13: Bulls | B13: 1 | K13: 1
A14: Cows | B14: 27 | C14: =8+8 -> 16 | H14: 6 | I14: 1 | K14: 40 | O14: =R14/H14 -> 0.3 | R14: =Receipts!F76 -> 1.8
A15: Steers | B15: 12 | C15: 1 | I15: 2 | J15: =3+8 -> 11 | K15: 0
A16: Bullocks | B16: 11 | I16: 3 | K16: 8
A17: Yearlings | B17: 11 | I17: 4 | K17: 7
A18: Calves | B18: 19 | C18: =8 -> 8 | H18: 6 | I18: 1 | J18: =2 -> 2 | K18: 11 | O18: =R18/H18 -> 0.05 | R18: =Receipts!F77 -> 0.3
A19: Wethers | B19: 249 | H19: 7 | I19: =18+11 -> 29 | K19: 271 | O19: =R19/H19 -> 0.05 | R19: =Receipts!F78 -> 0.35
A20: Rams | B20: 2 | C20: 6 | K20: 8
A21: Ewes | B21: 226 | C21: 50 | H21: 7 | I21: =30+1+2 -> 33 | K21: 236 | O21: =R21/H21 -> 0.041428571 | R21: =Receipts!F79 -> 0.29
A22: Hoggs | B22: 145 | H22: 26 | I22: 5 | J22: =58+6+50 -> 114 | K22: 0 | O22: =R22/H22 -> 0.026153846 | R22: =Receipts!F80 -> 0.68
A23: Lambs | C23: 172 | H23: 12 | I23: =16+3 -> 19 | J23: =16+3 -> 19 | K23: 122 | O23: =R23/H23 -> 0.018333333 | R23: =Receipts!F81 -> 0.22
A24: Boars | B24: 1 | C24: 1 | H24: 1 | K24: 1 | O24: =R24/H24 -> 0.05 | R24: =Receipts!F82 -> 0.05
A25: Sows | B25: 2 | K25: 2
A26: Pigs | B26: 12 | C26: =30+1 -> 31 | H26: 5 | I26: =3+2 -> 5 | K26: 33 | O26: =R26/H26 -> 0.124 | R26: =Receipts!F83 -> 0.62
A27: Hoggets | B27: 37 | I27: 6 | J27: =1+30 -> 31 | K27: 0
A28: Piglets | C28: 17 | I28: 3 | J28: 1 | K28: 13
A29: Swans | B29: 13 | C29: 3 | K29: 16
A30: Peacocks | B30: 6 | C30: 1 | I30: 5 | K30: 5 | U30: accounting doesnt add up
A31: Total Value | R31: =SUM(R5:R29) -> 7.68
A34: Wool
A35: Coarse wool | C35: 528 | J35: =53+375 -> 428 | O35: 0.02 | T35: =O35*J35 -> 8.56
A36: Lamb's wool | C36: 122 | J36: 122 | O36: 0.01 | T36: =O36*J36 -> 1.22
A37: Wool locks | C37: 6 | H37: 6 | O37: =10.5/240 -> 0.04375 | T37: =O37*H37 -> 0.2625 | U37: measured in cloves
A38: Wool sold at shearing
A39: Total wool | T39: =SUM(T35:T38) -> 10.0425
A42: Hides
A43: Ox hides
A44: Mare
A45: Steer
...

Sheet Issues of the Grange raw
A1: Heading | B1: Sentence | C1: Quarters 1_x | D1: Bushels 1_x | E1: Sown Quarters | F1: Sown Bushels | G1: Sown Total Quarters | H1: Bought in Quarters | I1: Bought in Bushels | J1: Bought in Total Quarters | K1: Tithe Quarters | L1: Tithe Bushels | M1: Tithe Total Quarters | N1: Manorial servants & livestock Quarters | O1: Manorial servants & livestock Bushels | P1: Manorial servants & livestock Total Quarters | Q1: Sold Quarters | R1: Sold Bushels | S1: Sold Total Quarters | T1: Account Quarters | U1: Account Bushels | V1: Account Total Quarters | W1: bought only | X1: Total Quarters Except 1 | Y1: Total Bushels Except 1 | Z1: Total Corn Cross-Check | AA1: Total Corn Manorial Account | AB1: Corn Quantity Error | AC1: Quarters 1_y | AD1: Bushels 1_y | AE1: Quarters 2 | AF1: Bushels 2 | AG1: Quarters 3 | AH1: Bushels 3 | AI1: Quarters 4 | AJ1: Bushels 4 | AK1: Quarters 5 | AL1: Bushels 5
A2: And thus he owes clear | B2: Total | C2: 0 | D2: 0 | E2: 0 | F2: 0 | G2: 0 | H2: 0 | I2: 0 | J2: 0 | K2: 0 | L2: 0 | M2: 0 | N2: 0 | O2: 0 | P2: 0 | Q2: 0 | R2: 0 | S2: 0 | T2: 0 | U2: 0 | V2: 0 | W2: 0
A3: Wheat | B3: {yield: three-fold plus 5 quarters 1.5 bushels} | C3: 0 | D3: 0 | E3: 0 | F3: 0 | G3: 0 | H3: 0 | I3: 0 | J3: 0 | K3: 0 | L3: 0 | M3: 0 | N3: 0 | O3: 0 | P3: 0 | Q3: 0 | R3: 0 | S3: 0 | T3: 0 | U3: 0 | V3: 0 | W3: 0 | X3: 5 | Y3: 1.5 | Z3: 5.1875 | AA3: 5.1875 | AB3: 0 | AC3: 5 | AD3: 1.5
A4: Wheat | B4: The same render account for 131.5 quarters from the whole issue of wheat by struck measure. | C4: 0 | D4: 0 | E4: 0 | F4: 0 | G4: 0 | H4: 0 | I4: 0 | J4: 0 | K4: 0 | L4: 0 | M4: 0 | N4: 0 | O4: 0 | P4: 0 | Q4: 0 | R4: 0 | S4: 0 | T4: 131.5 | U4: 0 | V4: 131.5 | W4: 0 | X4: 131.5 | Y4: 0 | Z4: 131.5 | AA4: 131.5 | AB4: 0 | AC4: 131.5 | AD4: 0
A5: Wheat | B5: 6 bushels from churchscot. | C5: 0 | D5: 0 | E5: 0 | F5: 0 | G5: 0 | H5: 0 | I5: 0 | J5: 0 | K5: 0 | L5: 0 | M5: 0 | N5: 0 | O5: 0 | P5: 0 | Q5: 0 | R5: 0 | S5: 0 | T5: 0 | U5: 0 | V5: 0 | W5: 0 | X5: 0 | Y5: 6 | Z5: 0.75 | AA5: 0.75 | AB5: 0 | AC5: 0 | AD5: 6
A6: Wheat | B6: Total, 1.32 quarters 2 bushels | C6: 0 | D6: 0 | E6: 0 | F6: 0 | G6: 0 | H6: 0 | I6: 0 | J6: 0 | K6: 0 | L6: 0 | M6: 0 | N6: 0 | O6: 0 | P6: 0 | Q6: 0 | R6: 0 | S6: 0 | T6: 0 | U6: 0 | V6: 0 | W6: 0 | X6: 1.32 | Y6: 2 | Z6: 1.57 | AA6: 1.57 | AB6: 0 | AC6: 1.32 | AD6: 2
A7: Wheat | B7: Sown over 453 acres as they lie in Rouerigg', la Mere and la Woth', 47 quarters 1 bushels. | C7: 0 | D7: 0 | E7: 47 | F7: 1 | G7: 47.125 | H7: 0 | I7: 0 | J7: 0 | K7: 0 | L7: 0 | M7: 0 | N7: 0 | O7: 0 | P7: 0 | Q7: 0 | R7: 0 | S7: 0 | T7: 0 | U7: 0 | V7: 0 | W7: 0 | X7: 47 | Y7: 1 | Z7: 47.125 | AA7: 47.125 | AB7: 0 | AC7: 47 | AD7: 1
A8: Wheat | B8: that is, 5 bushels over 6 acres, less'' bushels in all. | C8: 0 | D8: 0 | E8: 0 | F8: 0 | G8: 0 | H8: 0 | I8: 0 | J8: 0 | K8: 0 | L8: 0 | M8: 0 | N8: 0 | O8: 0 | P8: 0 | Q8: 0 | R8: 0 | S8: 0 | T8: 0 | U8: 0 | V8: 0 | W8: 0 | X8: 0 | Y8: 5 | Z8: 0.625 | AA8: 0.625 | AB8: 0 | AC8: 0 | AD8: 5
A9: Wheat | B9: . | C9: 0 | D9: 0 | E9: 0 | F9: 0 | G9: 0 | H9: 0 | I9: 0 | J9: 0 | K9: 0 | L9: 0 | M9: 0 | N9: 0 | O9: 0 | P9: 0 | Q9: 0 | R9: 0 | S9: 0 | T9: 0 | U9: 0 | V9: 0 | W9: 0 | X9: 0 | Y9: 0 | Z9: 0 | AA9: 0 | AB9: 0 | AC9: 0 | AD9: 0
A10: Wheat | B10: . | C10: 0 | D10: 0 | E10: 0 | F10: 0 | G10: 0 | H10: 0 | I10: 0 | J10: 0 | K10: 0 | L10: 0 | M10: 0 | N10: 0 | O10: 0 | P10: 0 | Q10: 0 | R10: 0 | S10: 0 | T10: 0 | U10: 0 | V10: 0 | W10: 0 | X10: 0 | Y10: 0 | Z10: 0 | AA10: 0 | AB10: 0 | AC10: 0 | AD10: 0
A11: Wheat | B11: . | C11: 0 | D11: 0 | E11: 0 | F11: 0 | G11: 0 | H11: 0 | I11: 0 | J11: 0 | K11: 0 | L11: 0 | M11: 0 | N11: 0 | O11: 0 | P11: 0 | Q11: 0 | R11: 0 | S11: 0 | T11: 0 | U11: 0 | V11: 0 | W11: 0 | X11: 0 | Y11: 0 | Z11: 0 | AA11: 0 | AB11: 0 | AC11: 0 | AD11: 0
A12: Wheat | B12: provision of the steward for his visits by 2 tallies, 1 qr. | C12: 0 | D12: 0 | E12: 0 | F12: 0 | G12: 0 | H12: 0 | I12: 0 | J12: 0 | K12: 0 | L12: 0 | M12: 0 | N12: 0 | O12: 0 | P12: 0 | Q12: 0 | R12: 0 | S12: 0 | T12: 0 | U12: 0 | V12: 0 | W12: 0
A13: Wheat | B13: . | C13: 0 | D13: 0 | E13: 0 | F13: 0 | G13: 0 | H13: 0 | I13: 0 | J13: 0 | K13: 0 | L13: 0 | M13: 0 | N13: 0 | O13: 0 | P13: 0 | Q13: 0 | R13: 0 | S13: 0 | T13: 0 | U13: 0 | V13: 0 | W13: 0 | X13: 0 | Y13: 0 | Z13: 0 | AA13: 0 | AB13: 0 | AC13: 0 | AD13: 0
A14: Wheat | B14: . | C14: 0 | D14: 0 | E14: 0 | F14: 0 | G14: 0 | H14: 0 | I14: 0 | J14: 0 | K14: 0 | L14: 0 | M14: 0 | N14: 0 | O14: 0 | P14: 0 | Q14: 0 | R14: 0 | S14: 0 | T14: 0 | U14: 0 | V14: 0 | W14: 0 | X14: 0 | Y14: 0 | Z14: 0 | AA14: 0 | AB14: 0 | AC14: 0 | AD14: 0
A15: Wheat | B15: . | C15: 0 | D15: 0 | E15: 0 | F15: 0 | G15: 0 | H15: 0 | I15: 0 | J15: 0 | K15: 0 | L15: 0 | M15: 0 | N15: 0 | O15: 0 | P15: 0 | Q15: 0 | R15: 0 | S15: 0 | T15: 0 | U15: 0 | V15: 0 | W15: 0 | X15: 0 | Y15: 0 | Z15: 0 | AA15: 0 | AB15: 0 | AC15: 0 | AD15: 0
A16: Wheat | B16: provision of Roger, bailiff from Michaelmas until Christmas, 4.5 quarters. | C16: 0 | D16: 0 | E16: 0 | F16: 0 | G16: 0 | H16: 0 | I16: 0 | J16: 0 | K16: 0 | L16: 0 | M16: 0 | N16: 0 | O16: 0 | P16: 0 | Q16: 0 | R16: 0 | S16: 0 | T16: 0 | U16: 0 | V16: 0 | W16: 0 | X16: 4.5 | Y16: 0 | Z16: 4.5 | AA16: 4.5 | AB16: 0 | AC16: 4.5 | AD16: 0
A17: Wheat | B17: . | C17: 0 | D17: 0 | E17: 0 | F17: 0 | G17: 0 | H17: 0 | I17: 0 | J17: 0 | K17: 0 | L17: 0 | M17: 0 | N17: 0 | O17: 0 | P17: 0 | Q17: 0 | R17: 0 | S17: 0 | T17: 0 | U17: 0 | V17: 0 | W17: 0 | X17: 0 | Y17: 0 | Z17: 0 | AA17: 0 | AB17: 0 | AC17: 0 | AD17: 0
A18: Wheat | B18: . | C18: 0 | D18: 0 | E18: 0 | F18: 0 | G18: 0 | H18: 0 | I18: 0 | J18: 0 | K18: 0 | L18: 0 | M18: 0 | N18: 0 | O18: 0 | P18: 0 | Q18: 0 | R18: 0 | S18: 0 | T18: 0 | U18: 0 | V18: 0 | W18: 0 | X18: 0 | Y18: 0 | Z18: 0 | AA18: 0 | AB18: 0 | AC18: 0 | AD18: 0
A19: Wheat | B19: . | C19: 0 | D19: 0 | E19: 0 | F19: 0 | G19: 0 | H19: 0 | I19: 0 | J19: 0 | K19: 0 | L19: 0 | M19: 0 | N19: 0 | O19: 0 | P19: 0 | Q19: 0 | R19: 0 | S19: 0 | T19: 0 | U19: 0 | V19: 0 | W19: 0 | X19: 0 | Y19: 0 | Z19: 0 | AA19: 0 | AB19: 0 | AC19: 0 | AD19: 0
A20: Wheat | B20: provision of Robert the bailiff for his visits from Christmas until Michaelmas, 4 quarters. | C20: 0 | D20: 0 | E20: 0 | F20: 0 | G20: 0 | H20: 0 | I20: 0 | J20: 0 | K20: 0 | L20: 0 | M20: 0 | N20: 0 | O20: 0 | P20: 0 | Q20: 0 | R20: 0 | S20: 0 | T20: 0 | U20: 0 | V20: 0 | W20: 0 | X20: 4 | Y20: 0 | Z20: 4 | AA20: 4 | AB20: 0 | AC20: 4 | AD20: 0
A21: Wheat | B21: Delivered to 1 hayward from the Circumcision (1 January) until Lammas (1 August), for 30 weeks, and from the Decollation of St John (29 August) until Michaelmas (29 September), for 4 weeks, 2 quarters 1 bushels, because he takes the rest in barley. | C21: 0 | D21: 0 | E21: 0 | F21: 0 | G21: 0 | H21: 0 | I21: 0 | J21: 0 | K21: 0 | L21: 0 | M21: 0 | N21: 0 | O21: 0 | P21: 0 | Q21: 0 | R21: 0 | S21: 0 | T21: 0 | U21: 0 | V21: 0 | W21: 0 | X21: 2 | Y21: 1 | Z21: 2.125 | AA21: 2.125 | AB21: 0 | AC21: 2 | AD21: 1
A22: Wheat | B22: he takes a quarter every 8 weeks and in between times sits at table. | C22: 0 | D22: 0 | E22: 0 | F22: 0 | G22: 0 | H22: 0 | I22: 0 | J22: 0 | K22: 0 | L22: 0 | M22: 0 | N22: 0 | O22: 0 | P22: 0 | Q22: 0 | R22: 0 | S22: 0 | T22: 0 | U22: 0 | V22: 0 | W22: 0 | X22: 0 | Y22: 0 | Z22: 0 | AA22: 0 | AB22: 0 | AC22: 0 | AD22: 0
A23: Wheat | B23: Sold, 73 quarters 4 bushels It balances. | C23: 0 | D23: 0 | E23: 0 | F23: 0 | G23: 0 | H23: 0 | I23: 0 | J23: 0 | K23: 0 | L23: 0 | M23: 0 | N23: 0 | O23: 0 | P23: 0 | Q23: 73 | R23: 4 | S23: 73.5 | T23: 0 | U23: 0 | V23: 0 | W23: 0 | X23: 73 | Y23: 4 | Z23: 73.5 | AA23: 73.5 | AB23: 0 | AC23: 73 | AD23: 4
A24: Wheat | B24: Total | C24: 0 | D24: 0 | E24: 0 | F24: 0 | G24: 0 | H24: 0 | I24: 0 | J24: 0 | K24: 0 | L24: 0 | M24: 0 | N24: 0 | O24: 0 | P24: 0 | Q24: 0 | R24: 0 | S24: 0 | T24: 0 | U24: 0 | V24: 0 | W24: 0
A25: Curall | B25: The same render account for 9 quarters 3.5 bushels from the whole issue of curall by struck measure. | C25: 0 | D25: 0 | E25: 0 | F25: 0 | G25: 0 | H25: 0 | I25: 0 | J25: 0 | K25: 0 | L25: 0 | M25: 0 | N25: 0 | O25: 0 | P25: 0 | Q25: 0 | R25: 0 | S25: 0 | T25: 9 | U25: 3.5 | V25: 9.4375 | W25: 0 | X25: 9 | Y25: 3.5 | Z25: 9.4375 | AA25: 9.4375 | AB25: 0 | AC25: 9 | AD25: 3.5
A26: Curall | B26: Mixed with barley for the liveries of the manorial servants, 1 qr 3 bushels Sold, 8 quarters .5 bushels It balances. | C26: 0 | D26: 0 | E26: 0 | F26: 0 | G26: 0 | H26: 0 | I26: 0 | J26: 0 | K26: 0 | L26: 0 | M26: 0 | N26: 8 | O26: 0 | P26: 8 | Q26: 8 | R26: 0 | S26: 8 | T26: 0 | U26: 0 | V26: 0 | W26: 0
A27: Curall | B27: Total | C27: 0 | D27: 0 | E27: 0 | F27: 0 | G27: 0 | H27: 0 | I27: 0 | J27: 0 | K27: 0 | L27: 0 | M27: 0 | N27: 0 | O27: 0 | P27: 0 | Q27: 0 | R27: 0 | S27: 0 | T27: 0 | U27: 0 | V27: 0 | W27: 0
A28: Barley | B28: {yield: four-fold less 4 quarters 5 bushels} | C28: 0 | D28: 0 | E28: 0 | F28: 0 | G28: 0 | H28: 0 | I28: 0 | J28: 0 | K28: 0 | L28: 0 | M28: 0 | N28: 0 | O28: 0 | P28: 0 | Q28: 0 | R28: 0 | S28: 0 | T28: 0 | U28: 0 | V28: 0 | W28: 0 | X28: 4 | Y28: 5 | Z28: 4.625 | AA28: 4.625 | AB28: 0 | AC28: 4 | AD28: 5
A29: Barley | B29: The same render account for 77 quarters 3 bushels from the whole issue of barley by struck measure. | C29: 0 | D29: 0 | E29: 0 | F29: 0 | G29: 0 | H29: 0 | I29: 0 | J29: 0 | K29: 0 | L29: 0 | M29: 0 | N29: 0 | O29: 0 | P29: 0 | Q29: 0 | R29: 0 | S29: 0 | T29: 77 | U29: 3 | V29: 77.375 | W29: 0 | X29: 77 | Y29: 3 | Z29: 77.375 | AA29: 77.375 | AB29: 0 | AC29: 77 | AD29: 3
A30: Barley | B30: 1 qr 3 bushels received above from curall. | C30: 0 | D30: 0 | E30: 0 | F30: 0 | G30: 0 | H30: 0 | I30: 0 | J30: 0 | K30: 0 | L30: 0 | M30: 0 | N30: 0 | O30: 0 | P30: 0 | Q30: 0 | R30: 0 | S30: 0 | T30: 0 | U30: 0 | V30: 0 | W30: 0
A31: Barley | B31: 1 qr 1 bushels received below from peas. | C31: 0 | D31: 0 | E31: 0 | F31: 0 | G31: 0 | H31: 0 | I31: 0 | J31: 0 | K31: 0 | L31: 0 | M31: 0 | N31: 0 | O31: 0 | P31: 0 | Q31: 0 | R31: 0 | S31: 0 | T31: 0 | U31: 0 | V31: 0 | W31: 0
A32: Barley | B32: 2 quarters 1 bushels received from vetches. | C32: 0 | D32: 0 | E32: 0 | F32: 0 | G32: 0 | H32: 0 | I32: 0 | J32: 0 | K32: 0 | L32: 0 | M32: 0 | N32: 0 | O32: 0 | P32: 0 | Q32: 0 | R32: 0 | S32: 0 | T32: 0 | U32: 0 | V32: 0 | W32: 0 | X32: 2 | Y32: 1 | Z32: 2.125 | AA32: 2.125 | AB32: 0 | AC32: 2 | AD32: 1
A33: Barley | B33: Total, 82 quarters. | C33: 0 | D33: 0 | E33: 0 | F33: 0 | G33: 0 | H33: 0 | I33: 0 | J33: 0 | K33: 0 | L33: 0 | M33: 0 | N33: 0 | O33: 0 | P33: 0 | Q33: 0 | R33: 0 | S33: 0 | T33: 0 | U33: 0 | V33: 0 | W33: 0 | X33: 82 | Y33: 0 | Z33: 82 | AA33: 82 | AB33: 0 | AC33: 82 | AD33: 0
A34: Barley | B34: Sown over 98 acres as they lie on both sides of la Longehegg' and in Crikelescrofte, 20 quarters. | C34: 0 | D34: 0 | E34: 20 | F34: 0 | G34: 20 | H34: 0 | I34: 0 | J34: 0 | K34: 0 | L34: 0 | M34: 0 | N34: 0 | O34: 0 | P34: 0 | Q34: 0 | R34: 0 | S34: 0 | T34: 0 | U34: 0 | V34: 0 | W34: 0 | X34: 20 | Y34: 0 | Z34: 20 | AA34: 20 | AB34: 0 | AC34: 20 | AD34: 0
A35: Barley | B35: that is, 3 bushels 1 peck an acre, plus .5 bushels 1 peck in all. | C35: 0 | D35: 0 | E35: 0 | F35: 0 | G35: 0 | H35: 0 | I35: 0 | J35: 0 | K35: 0 | L35: 0 | M35: 0 | N35: 0 | O35: 0 | P35: 0 | Q35: 0 | R35: 0 | S35: 0 | T35: 0 | U35: 0 | V35: 0 | W35: 0 | X35: 0 | Y35: 5 | Z35: 0.625 | AA35: 0.375 | AB35: 0.25 | AC35: 0 | AD35: 3 | AE35: 0 | AF35: 5
A36: Barley | B36: Delivered to 4 drovers for the year, 26 quarters, taking a quarter every 8 weeks. | C36: 0 | D36: 0 | E36: 0 | F36: 0 | G36: 0 | H36: 0 | I36: 0 | J36: 0 | K36: 0 | L36: 0 | M36: 0 | N36: 0 | O36: 0 | P36: 0 | Q36: 0 | R36: 0 | S36: 0 | T36: 0 | U36: 0 | V36: 0 | W36: 0 | X36: 26 | Y36: 0 | Z36: 26 | AA36: 26 | AB36: 0 | AC36: 26 | AD36: 0
A37: Barley | B37: Delivered to 1 carter for the year, 6.5 quarters, who takes as before. | C37: 0 | D37: 0 | E37: 0 | F37: 0 | G37: 0 | H37: 0 | I37: 0 | J37: 0 | K37: 0 | L37: 0 | M37: 0 | N37: 0 | O37: 0 | P37: 0 | Q37: 0 | R37: 0 | S37: 0 | T37: 0 | U37: 0 | V37: 0 | W37: 0 | X37: 6.5 | Y37: 0 | Z37: 6.5 | AA37: 6.5 | AB37: 0 | AC37: 6.5 | AD37: 0
A38: Barley | B38: Delivered to 1 drover who drove the horse-plough for .5 year and the other cart for the other .5 year, 6.5 quarters, and he takes as before. | C38: 0 | D38: 0 | E38: 0 | F38: 0 | G38: 0 | H38: 0 | I38: 0 | J38: 0 | K38: 0 | L38: 0 | M38: 0 | N38: 0 | O38: 0 | P38: 0 | Q38: 0 | R38: 0 | S38: 0 | T38: 0 | U38: 0 | V38: 0 | W38: 0 | X38: 6.5 | Y38: 0 | Z38: 6.5 | AA38: 6.5 | AB38: 0 | AC38: 6.5 | AD38: 0
A39: Barley | B39: Delivered to 1 cowherd for the year, 4 quarters 2.5 bushels, taking a quarter every 12 weeks. | C39: 0 | D39: 0 | E39: 0 | F39: 0 | G39: 0 | H39: 0 | I39: 0 | J39: 0 | K39: 0 | L39: 0 | M39: 0 | N39: 0 | O39: 0 | P39: 0 | Q39: 0 | R39: 0 | S39: 0 | T39: 0 | U39: 0 | V39: 0 | W39: 0 | X39: 4 | Y39: 2.5 | Z39: 4.3125 | AA39: 4.3125 | AB39: 0 | AC39: 4 | AD39: 2.5
A40: Barley | B40: Delivered to to 1 dairymaid for the year, 5 quarters 1.5 bushels, taking a quarter every 10 weeks. {Henceforth the dairymaid should take nothing except a quarter every 12 weeks. | C40: 0 | D40: 0 | E40: 0 | F40: 0 | G40: 0 | H40: 0 | I40: 0 | J40: 0 | K40: 0 | L40: 0 | M40: 0 | N40: 0 | O40: 0 | P40: 0 | Q40: 0 | R40: 0 | S40: 0 | T40: 0 | U40: 0 | V40: 0 | W40: 0 | X40: 5 | Y40: 1.5 | Z40: 5.1875 | AA40: 5.1875 | AB40: 0 | AC40: 5 | AD40: 1.5
...

Sheet Sale of Corn Prices
A1: Heading | B1: Sentence | C1: Total in Pounds | D1: Pounds | E1: Shillings | F1: Pence | G1: Corn | H1: Total Quarters Except 1 | I1: Total Bushels Except 1 | J1: Total Corn Cross-Check | K1: Total Corn Manorial Account | L1: Corn Quantity Error | M1: Quarters 0 | N1: Bushels 0 | O1: shilling a quarter 1 | P1: pence a quarter 1 | Q1: Quarters 1 | R1: Bushels 1 | S1: shilling a quarter 2 | T1: pence a quarter 2 | U1: Quarters 2 | V1: Bushels 2 | W1: shilling a quarter 3 | X1: pence a quarter 3 | Y1: Quarters 3 | Z1: Bushels 3 | AA1: shilling a quarter 4 | AB1: pence a quarter 4 | AC1: Quarters 4 | AD1: Bushels 4 | AE1: £ a quarter 1 | AF1: £ a quarter 2 | AG1: £ a quarter 3 | AH1: £ a quarter 4 | AI1: Quarters Sold | AJ1: Weighted Average Price per Quarter | AK1: Non-Weighted Average Price per Quarter | AL1: Corn lowercase
A2: Sale of corn | B2: The same render account for £22 15 shilling 8.5pence from 73.5 quarters of wheat sold, at 5 shilling a quarters for 7.5 quarters 1 bushels, 5 shilling 4pence a quarters for 6.5 quarters, 6 shilling a quarters for 19 quarters 3 bushels, and 6 shilling 8pence a quarters for 40 quarters.. | C2: 22.79 | D2: 22 | E2: 15 | F2: 8.5 | G2: wheat | H2: 73 | I2: 4 | J2: 73.5 | K2: 73.5 | L2: 0 | M2: 73.5 | N2: 0 | O2: 5 | P2: 0 | Q2: 7.5 | R2: 1 | S2: 5 | T2: 4 | U2: 6.5 | V2: 0 | W2: 6 | X2: 0 | Y2: 19 | Z2: 3 | AA2: 6 | AB2: 8 | AC2: 40 | AD2: 0 | AE2: 0.25 | AF2: 0.26666667 | AG2: 0.3 | AH2: 0.33333333 | AI2: 73.5 | AJ2: 0.31000567 | AK2: 0.2875 | AL2: wheat
A3: Sale of corn | B3: 17 shilling 5.75pence from 8 quarters' bushels of curall sold, at 2 shilling a quarters for 4 quarters, and 2 shilling 4pence a quarters for 4 quarters .5 bushels. | C3: 0.87 | D3: 0 | E3: 17 | F3: 5.75 | G3: curall | H3: 8 | I3: 5 | J3: 8.625 | K3: 8 | L3: 0.625 | M3: 8 | N3: 0 | O3: 2 | P3: 0 | Q3: 4 | R3: 0 | S3: 2 | T3: 4 | U3: 4 | V3: 0 | Y3: 0 | Z3: 5 | AE3: 0.1 | AF3: 0.11666667 | AI3: 8 | AJ3: 0.10833333 | AK3: 0.10833333 | AL3: curall
A4: Sale of corn | B4: £1 1 shilling 3pence from 5 quarters 2.5 bushels of barley sold, at 4 shilling a quarters. | C4: 1.06 | D4: 1 | E4: 1 | F4: 3 | G4: barley | H4: 5 | I4: 2.5 | J4: 5.3125 | K4: 5.3125 | L4: 0 | M4: 5 | N4: 2.5 | O4: 4 | P4: 0 | AE4: 0.2 | AI4: 5.3125 | AJ4: 0.2 | AK4: 0.2 | AL4: barley
A5: Sale of corn | B5: £6 13 shilling 10pence from 58.5 quarters 3 bushels, of oats sold, at 2 shilling a quarters for 31 quarters, 2 shilling 4pence a quarters for 7.5 quarters, and 2 shilling 8pence a quarters for 20 quarters 3 bushels. | C5: 6.69 | D5: 6 | E5: 13 | F5: 10 | G5: oats | H5: 58.5 | I5: 3 | J5: 58.875 | K5: 58.875 | L5: 0 | M5: 58.5 | N5: 3 | O5: 2 | P5: 0 | Q5: 31 | R5: 0 | S5: 2 | T5: 4 | U5: 7.5 | V5: 0 | W5: 2 | X5: 8 | Y5: 20 | Z5: 3 | AE5: 0.1 | AF5: 0.11666667 | AG5: 0.13333333 | AI5: 58.875 | AJ5: 0.11365888 | AK5: 0.11666667 | AL5: oats
A6: Sale of corn | B6: 8pence from 2 bushels of peas sold. | C6: 0.03 | D6: 0 | E6: 0 | F6: 8 | G6: peas | H6: 0 | I6: 2 | J6: 0.25 | K6: 0.25 | L6: 0 | M6: 0 | N6: 2 | AE6: 0.12 | AI6: 0.25 | AJ6: 0.12 | AK6: 0.12 | AL6: peas
A7: Sale of corn | B7: 4 shilling 3pence from 2 quarters 1 bushels of vetches sold, at 2 shilling a quarters. | C7: 0.21 | D7: 0 | E7: 4 | F7: 3 | G7: vetches | H7: 2 | I7: 1 | J7: 2.125 | K7: 2.125 | L7: 0 | M7: 2 | N7: 1 | O7: 2 | P7: 0 | AE7: 0.1 | AI7: 2.125 | AJ7: 0.1 | AK7: 0.1 | AL7: vetches
A8: Sale of corn | B8: Total, £31 13 shilling 2.25pence | C8: 31.66 | D8: 31 | E8: 13 | F8: 2.25 | H8: 0 | I8: 0 | J8: 0 | K8: 0 | L8: 0 | M8: 0 | N8: 0 | AE8: inf | AI8: 0 | AJ8: inf | AK8: inf

Sheet raw data
A1: Heading | B1: Sentence | C1: Total in Pounds | D1: Pounds | E1: Shillings | F1: Pence | G1: Corn | H1: Total Quarters Except 1 | I1: Total Bushels Except 1 | J1: Total Corn Cross-Check | K1: Total Corn Manorial Account | L1: Corn Quantity Error | M1: Quarters 1 | N1: Bushels 1 | O1: Quarters 2 | P1: Bushels 2 | Q1: Quarters 3 | R1: Bushels 3 | S1: Quarters 4 | T1: Bushels 4 | U1: Quarters 5 | V1: Bushels 5 | W1: shilling a quarter 1 | X1: pence a quarter 1 | Y1: shilling a quarter 2 | Z1: pence a quarter 2 | AA1: shilling a quarter 3 | AB1: pence a quarter 3 | AC1: shilling a quarter 4 | AD1: pence a quarter 4 | AE1: shilling a bushel 1 | AF1: pence a bushel 1 | AG1: shilling a bushel 2 | AH1: pence a bushel 2 | AI1: shilling a bushel 3 | AJ1: pence a bushel 3 | AK1: shilling a bushel 4 | AL1: pence a bushel 4
A2: Arrears | B2: Robert de Froyle, bailiff, and Robert Stretthe, reeve, render account for £71 18 shilling 3.5pence of arrears from the previous year. | C2: 71.91 | D2: 71 | E2: 18 | F2: 3.5 | H2: 0 | I2: 0 | J2: 0 | K2: 0 | L2: 0 | M2: 0 | N2: 0
A3: Arrears | B3: All delivered to Sir Geoffrey, treasurer of Wolvesey, by 1 tally, and they are quit. | C3: 0 | D3: 0 | E3: 0 | F3: 0 | H3: 0 | I3: 0 | J3: 0 | K3: 0 | L3: 0 | M3: 0 | N3: 0
A4: Rents | B4: The same render account for £14 10 shilling 10.75pence for all rents of assize at Christmas. | C4: 14.54 | D4: 14 | E4: 10 | F4: 10.75 | H4: 0 | I4: 0 | J4: 0 | K4: 0 | L4: 0 | M4: 0 | N4: 0
A5: Rents | B5: £23 8.75pence at Easter (22 April). | C5: 23.04 | D5: 23 | E5: 0 | F5: 8.75 | H5: 0 | I5: 0 | J5: 0 | K5: 0 | L5: 0 | M5: 0 | N5: 0
A6: Rents | B6: £14 10 shilling 10.5pence at the Nativity of St John the Baptist (24 June). | C6: 14.54 | D6: 14 | E6: 10 | F6: 10.5 | H6: 0 | I6: 0 | J6: 0 | K6: 0 | L6: 0 | M6: 0 | N6: 0
A7: Rents | B7: £23 19 shilling 3.5pence at Michaelmas (29 September). | C7: 23.96 | D7: 23 | E7: 19 | F7: 3.5 | H7: 0 | I7: 0 | J7: 0 | K7: 0 | L7: 0 | M7: 0 | N7: 0
A8: Rents | B8: Total, £76 1 shilling 9.5pence | C8: 76.09 | D8: 76 | E8: 1 | F8: 9.5 | H8: 0 | I8: 0 | J8: 0 | K8: 0 | L8: 0 | M8: 0 | N8: 0
A9: Quittances | B9: In quittance of 1 reeve for the year 5 shilling. | C9: 0.25 | D9: 0 | E9: 5 | F9: 0 | H9: 0 | I9: 0 | J9: 0 | K9: 0 | L9: 0 | M9: 0 | N9: 0
A10: Quittances | B10: 1 beadle for the year 5 shilling. | C10: 0.25 | D10: 0 | E10: 5 | F10: 0 | H10: 0 | I10: 0 | J10: 0 | K10: 0 | L10: 0 | M10: 0 | N10: 0
A11: Quittances | B11: 1 swineherd, 1 smith, 1 hayward who kept the lord's corn and pasture and sowed the wheat and barley, 1 shepherd of wethers, and 1 keeper of ewes, 10 shilling, or 2 shilling each. | C11: 0.5 | D11: 0 | E11: 10 | F11: 0 | G11: barley, wheat | H11: 0 | I11: 0 | J11: 0 | K11: 0 | L11: 0 | M11: 0 | N11: 0
A12: Quittances | B12: 4 ploughmen for the year, and 1 ploughman for 1 term, 8 shilling 6pence. | C12: 0.43 | D12: 0 | E12: 8 | F12: 6 | H12: 0 | I12: 0 | J12: 0 | K12: 0 | L12: 0 | M12: 0 | N12: 0
A13: Quittances | B13: 9 workers, each of whom are bound to reap everyday at harvest-time 1 acre as it lies and after the harvest are bound to work twice a week, 18 shilling, or 2 shilling each. | C13: 0.9 | D13: 0 | E13: 18 | F13: 0 | H13: 0 | I13: 0 | J13: 0 | K13: 0 | L13: 0 | M13: 0 | N13: 0
A14: Quittances | B14: 3 cottars for the year, each of whom are bound to reap everyday .5 acre as it lies and after the harvest are bound to work once a week, 3 shilling. | C14: 0.15 | D14: 0 | E14: 3 | F14: 0 | H14: 0 | I14: 0 | J14: 0 | K14: 0 | L14: 0 | M14: 0 | N14: 0
A15: Quittances | B15: 2 workers who are bound to reap everyday at harvest-time 1 acre as it lies and after the harvest are bound to work twice a week with their carts, working at the lord's pleasure, besides carrying dung, 6 shilling for the year. | C15: 0.3 | D15: 0 | E15: 6 | F15: 0 | H15: 0 | I15: 0 | J15: 0 | K15: 0 | L15: 0 | M15: 0 | N15: 0
A16: Quittances | B16: 1 granary-keeper for the year 2 shilling Total, £2 17 shilling 6pence | C16: 2.88 | D16: 2 | E16: 17 | F16: 6 | H16: 0 | I16: 0 | J16: 0 | K16: 0 | L16: 0 | M16: 0 | N16: 0
A17: Defaults of rent | B17: In default of the land between the Barton and garden drawn into demesne, £1 2 shilling 8pence for the year. | C17: 1.13 | D17: 1 | E17: 2 | F17: 8 | H17: 0 | I17: 0 | J17: 0 | K17: 0 | L17: 0 | M17: 0 | N17: 0
A18: Defaults of rent | B18: the land of Osbert de Langely, 8pence for the year. | C18: 0.03 | D18: 0 | E18: 0 | F18: 8 | H18: 0 | I18: 0 | J18: 0 | K18: 0 | L18: 0 | M18: 0 | N18: 0
A19: Defaults of rent | B19: the land of Richard Baton, 6pence for the year. | C19: 0.03 | D19: 0 | E19: 0 | F19: 6 | H19: 0 | I19: 0 | J19: 0 | K19: 0 | L19: 0 | M19: 0 | N19: 0
A20: Defaults of rent | B20: the land of Hugh son of Agnes, 6pence for the year. | C20: 0.03 | D20: 0 | E20: 0 | F20: 6 | H20: 0 | I20: 0 | J20: 0 | K20: 0 | L20: 0 | M20: 0 | N20: 0
A21: Defaults of rent | B21: the land of Richard Swanemere, 3pence for the year. | C21: 0.01 | D21: 0 | E21: 0 | F21: 3 | H21: 0 | I21: 0 | J21: 0 | K21: 0 | L21: 0 | M21: 0 | N21: 0
A22: Defaults of rent | B22: the land of the mill drawn into the park, 6 shilling 5pence for the year. | C22: 0.32 | D22: 0 | E22: 6 | F22: 5 | H22: 0 | I22: 0 | J22: 0 | K22: 0 | L22: 0 | M22: 0 | N22: 0
A23: Defaults of rent | B23: the rent of Peter Clericus, 1 shilling 6pence for the year. | C23: 0.08 | D23: 0 | E23: 1 | F23: 6 | H23: 0 | I23: 0 | J23: 0 | K23: 0 | L23: 0 | M23: 0 | N23: 0
... A144: Issues of the manor | B144: £19 7 shilling 7pence from 50 Yearlings bought and agisted in the park the previous year and afterwards solpence Total, £77 8 shilling 1pence | C144: 19.38 | D144: 19 | E144: 7 | F144: 7 | H144: 0 | I144: 0 | J144: 0 | K144: 0 | L144: 0 | M144: 0 | N144: 0
A145: Sale of corn | B145: The same render account for £22 15 shilling 8.5pence from 73.5 quarters of wheat sold, at 5 shilling a quarters for 7.5 quarters 1 bushels, 5 shilling 4pence a quarters for 6.5 quarters, 6 shilling a quarters for 19 quarters 3 bushels, and 6 shilling 8pence a quarters for 40 quarters.. | C145: 22.79 | D145: 22 | E145: 15 | F145: 8.5 | G145: wheat | H145: 73 | I145: 4 | J145: 73.5 | K145: 73.5 | L145: 0 | M145: 73.5 | N145: 0 | O145: 7.5 | P145: 1 | Q145: 6.5 | R145: 0 | S145: 19 | T145: 3 | U145: 40 | V145: 0 | W145: 5 | X145: 0 | Y145: 5 | Z145: 4 | AA145: 6 | AB145: 0 | AC145: 6 | AD145: 8
A146: Sale of corn | B146: 17 shilling 5.75pence from 8 quarters' bushels of curall sold, at 2 shilling a quarters for 4 quarters, and 2 shilling 4pence a quarters for 4 quarters .5 bushels. | C146: 0.87 | D146: 0 | E146: 17 | F146: 5.75 | G146: curall | H146: 8 | I146: 5 | J146: 8.625 | K146: 8 | L146: 0.625 | M146: 8 | N146: 0 | O146: 4 | P146: 0 | Q146: 4 | R146: 0 | S146: 0 | T146: 5 | W146: 2 | X146: 0 | Y146: 2 | Z146: 4
A147: Sale of corn | B147: £1 1 shilling 3pence from 5 quarters 2.5 bushels of barley sold, at 4 shilling a quarters. | C147: 1.06 | D147: 1 | E147: 1 | F147: 3 | G147: barley | H147: 5 | I147: 2.5 | J147: 5.3125 | K147: 5.3125 | L147: 0 | M147: 5 | N147: 2.5 | W147: 4 | X147: 0
A148: Sale of corn | B148: £6 13 shilling 10pence from 58.5 quarters 3 bushels, of oats sold, at 2 shilling a quarters for 31 quarters, 2 shilling 4pence a quarters for 7.5 quarters, and 2 shilling 8pence a quarters for 20 quarters 3 bushels. | C148: 6.69 | D148: 6 | E148: 13 | F148: 10 | G148: oats | H148: 58.5 | I148: 3 | J148: 58.875 | K148: 58.875 | L148: 0 | M148: 58.5 | N148: 3 | O148: 31 | P148: 0 | Q148: 7.5 | R148: 0 | S148: 20 | T148: 3 | W148: 2 | X148: 0 | Y148: 2 | Z148: 4 | AA148: 2 | AB148: 8
A149: Sale of corn | B149: 8pence from 2 bushels of peas sold. | C149: 0.03 | D149: 0 | E149: 0 | F149: 8 | G149: peas | H149: 0 | I149: 2 | J149: 0.25 | K149: 0.25 | L149: 0 | M149: 0 | N149: 2
A150: Sale of corn | B150: 4 shilling 3pence from 2 quarters 1 bushels of vetches sold, at 2 shilling a quarters. | C150: 0.21 | D150: 0 | E150: 4 | F150: 3 | G150: vetches | H150: 2 | I150: 1 | J150: 2.125 | K150: 2.125 | L150: 0 | M150: 2 | N150: 1 | W150: 2 | X150: 0
A151: Sale of corn | B151: Total, £31 13 shilling 2.25pence | C151: 31.66 | D151: 31 | E151: 13 | F151: 2.25 | H151: 0 | I151: 0 | J151: 0 | K151: 0 | L151: 0 | M151: 0 | N151: 0
A152: East mill | B152: The same render account for 7 shilling 7pence from 1 quarters 3 bushels of wheat sold, at 5 shilling 4pence for 1 quarters, and 9pence a bushels for 3 bushels. | C152: 0.38 | D152: 0 | E152: 7 | F152: 7 | G152: wheat | H152: 1 | I152: 3 | J152: 1.375 | K152: 1.375 | L152: 0 | M152: 1 | N152: 3 | O152: 1 | P152: 0 | Q152: 0 | R152: 3 | AE152: 0 | AF152: 9
A153: East mill | B153: £3 3 shilling 6pence from 18 quarters 1 bushels of maslin sold, at 3 shilling 4pence a quarters for 7 quarters, and 4 shilling a quarters for 8 quarters 1 bushels Total, £3 11 shilling 1pence | C153: 3.17 | D153: 3 | E153: 3 | F153: 6 | G153: maslin | H153: 15 | I153: 1 | J153: 15.125 | K153: 18.125 | L153: -3 | M153: 18 | N153: 1 | O153: 7 | P153: 0 | Q153: 8 | R153: 1 | W153: 3 | X153: 4 | Y153: 4 | Z153: 0
A154: Mill outside the gate | B154: The same render account for 6 shilling 3pence from 1 quarters 1 bushels of wheat sold, at 7pence for 1 bushels, 8pence a bushels for 4 bushels, and 9pence a bushels for 3 bushels. | C154: 0.31 | D154: 0 | E154: 6 | F154: 3 | G154: wheat | H154: 1 | I154: 8 | J154: 2 | K154: 1.125 | L154: 0.875 | M154: 1 | N154: 1 | O154: 0 | P154: 1 | Q154: 0 | R154: 4 | S154: 0 | T154: 3 | AE154: 0 | AF154: 8 | AG154: 0 | AH154: 9
A155: Mill outside the gate | B155: 9 shilling 2r.5-1pence from 2 quarters 5 bushels of maslin sold, at 4.5pence a bushels for 5 bushels, 3 shilling 4pence for 1 quarters, and 4 shilling for 1 quarters. | C155: 0.45 | D155: 0 | E155: 9 | F155: 1 | G155: maslin | H155: 2 | I155: 5 | J155: 2.625 | K155: 2.625 | L155: 0 | M155: 2 | N155: 5 | O155: 0 | P155: 5 | Q155: 1 | R155: 0 | S155: 1 | T155: 0 | AE155: 0 | AF155: 4.5
A156: Mill outside the gate | B156: £1 12 shilling 4pence from 5 quarters 5.5 bushels of coarse-ground corn sold, at 5 shilling 4pence a quarters for 2 quarters 5.5 bushels, and 6 shilling a quarters for 3 quarters. | C156: 1.62 | D156: 1 | E156: 12 | F156: 4 | H156: 5 | I156: 5.5 | J156: 5.6875 | K156: 5.6875 | L156: 0 | M156: 5 | N156: 5.5 | O156: 2 | P156: 5.5 | Q156: 3 | R156: 0 | W156: 5 | X156: 4 | Y156: 6 | Z156: 0
A157: Mill outside the gate | B157: £1 13 shilling 8pence from 13.5 quarters of malt sold, at 2 shilling 4pence a quarters for 5 quarters, 2 shilling 6pence a quarters for 4 quarters, and 2 shilling 8pence a quarters for 4.5 quarters. | C157: 1.68 | D157: 1 | E157: 13 | F157: 8 | H157: 13.5 | I157: 0 | J157: 13.5 | K157: 13.5 | L157: 0 | M157: 13.5 | N157: 0 | O157: 5 | P157: 0 | Q157: 4 | R157: 0 | S157: 4.5 | T157: 0 | W157: 2 | X157: 4 | Y157: 2 | Z157: 6 | AA157: 2 | AB157: 8
A158: Mill outside the gate | B158: 6 shilling 8pence from 1 quarters of oatmeal solpence Total, £4 8 shilling 1.5pence Total of both, £7 19 shilling 2.5pence | C158: 4.41 | D158: 4 | E158: 8 | F158: 1.5 | G158: oatmeal | H158: 1 | I158: 0 | J158: 1 | K158: 1 | L158: 0 | M158: 1 | N158: 0
A159: Entry and marriage fines | B159: The same render account for 10 shilling from the 2 tithings of Bishops Waltham for tithingpenny at the hundred-court of Martinmas (11 November). | C159: 0.5 | D159: 0 | E159: 10 | F159: 0 | H159: 0 | I159: 0 | J159: 0 | K159: 0 | L159: 0 | M159: 0 | N159: 0
A160: Entry and marriage fines | B160: 4 shilling from the tithing of Mensingefeld' for the same. | C160: 0.2 | D160: 0 | E160: 4 | F160: 0 | H160: 0 | I160: 0 | J160: 0 | K160: 0 | L160: 0 | M160: 0 | N160: 0
...
