Workbook

Sheet Bishopstone Overview
A1: BISHOPSTONE | B1: £ | C1: s | D1: d | G1: Total in £ | H1: Error
A3: CASH ACCOUNT
A4: RECEIPTS
A5: Arrears | G5: ='Bishopstone Receipts'!F5 -> 10.934375
A6: Rents of assize | G6: ='Bishopstone Receipts'!F14 -> 12.275
A7: Quittances | G7: ='Bishopstone Receipts'!F22 -> 0.7625
A8: Defaults of rent | G8: ='Bishopstone Receipts'!F27 -> 0.025
A9: Annual reconizances | G9: ='Bishopstone Receipts'!F36 -> 0.075
A10: Rents remaining | G10: ='Bishopstone Receipts'!F29 -> 11.4875
A11: Issues of the Manor | G11: ='Bishopstone Receipts'!F65 -> 14.485417
A12: Sale of corn | G12: ='Bishopstone Receipts'!F77 -> 36.342708
A13: Entry and marriage fines | G13: ='Bishopstone Receipts'!F89 -> 2.0166667
A14: Pleas & Perquisites | G14: ='Bishopstone Receipts'!F96 -> 2.3
A15: Sum of the above (incl. arrears) | G15: =G5+G9+G10+G11+G12+G13+G14 -> 77.641667
A16: Total recorded in the accounts excl. arrears | G16: ='Bishopstone Receipts'!F100 -> 66.707292
A17: Total recorded in the accounts incl. arrears | G17: n/a
A20: EXPENSES
A21: Cost of ploughs | G21: ='Bishopstone Expenses'!F13 -> 1.7583333
A22: Purchase of corn
A23: Cost of carts and wagons | G23: ='Bishopstone Expenses'!F22 -> 0.085416667
A24: Cost of dairy | G24: ='Bishopstone Expenses'!F32 -> 0.25833333
A25: Purchase of stock
A26: Sheepcote | G26: ='Bishopstone Expenses'!F42 -> 1.2604167
A27: Cost of buildings | G27: ='Bishopstone Expenses'!F51 -> 0.066666667
A28: Threshing | G28: ='Bishopstone Expenses'!F62 -> 1.7979167
A29: Expenses of the harvest | G29: ='Bishopstone Expenses'!F70 -> 0.61041667
A30: Stewards expenses | G30: =
A31: Sum of the above | G31: =SUM(G21:G30) -> 5.8375
A32: Total of all expenses | G32: ='Bishopstone Expenses'!F80 -> 7.8395833 | H32: =G31-G32 -> -2.0020833
A33: Total Demesne fixed investment | G33: ='Bishopstone Expenses'!F85 -> 2.7208333
A35: Owed by the reeve | G35: ='Bishopstone Expenses'!F82 -> 58.867708
A36: From accounts
A38: Cash deliveries | G38: ='Bishopstone Expenses'!F83 -> 47.4
A39: Sum of the above | B39: =SUM(B38:B38) -> 0 | C39: =SUM(C38:C38) -> 0 | D39: =SUM(D38:D38) -> 0 | E39: =SUM(E38:E38) -> 0 | G39: =SUM(G38:G38) -> 47.4
A40: Total of all allowances and cash deliveries in accounts | B40: n/a
A42: Net amount owed | G42: ='Bishopstone Expenses'!F84 -> 11.467708
A43: Net amount owed in accounts | H43: =G42-G43 -> 11.467708
A45: GRANGE ACCOUNT | B45: Net Production
A46: Grange | B46: qrs | C46: bus | F46: Value of total gross production in £ | G46: Value of total net production in £
A47: Wheat | B47: ='Issues of the Grange'!J18 -> 49.25 | F47: ='Issues of the Grange'!P5 -> 17.867132 | G47: ='Issues of the Grange'!M18 -> 12.39375
...

Sheet Bishopstone Receipts
A1: BISHOPSTONE RECEIPTS
B2: £ | C2: s | D2: d | F2: Total in £ | G2: Error | H2: Notes
A4: Arrears
A5: arrears from previous year | B5: 10 | C5: 18 | D5: 8.25 | F5: =B5+C5/20+D5/240 -> 10.934375
A6: of which delivered to treasurer of Wolvesey | B6: 10 | C6: 18 | D6: 8.25 | F6: =B6+C6/20+D6/240 -> 10.934375
A8: Rents of assize
A9: Christmas | B9: 3 | C9: 1 | D9: 8.5 | F9: =B9+C9/20+D9/240 -> 3.0854167
A10: Easter | B10: 3 | C10: 1 | D10: 8.5 | F10: =B10+C10/20+D10/240 -> 3.0854167
A11: Nativity of John the Baptist | B11: 3 | C11: 1 | D11: 8.5 | F11: =B11+C11/20+D11/240 -> 3.0854167
A12: Michaelmas | B12: 3 | D12: 4.5 | F12: =B12+C12/20+D12/240 -> 3.01875
A13: Total recorded in accounts | B13: 12 | C13: 5 | D13: 6 | F13: =B13+C13/20+D13/240 -> 12.275
A14: Total | B14: =SUM(B9:B12) -> 12 | C14: =SUM(C9:C12) -> 3 | D14: =SUM(D9:D12) -> 30 | F14: =B14+C14/20+D14/240 -> 12.275 | G14: =F14-F13 -> 0
A16: Quittances
A17: 1 reeve for year | C17: 4 | F17: =B17+C17/20+D17/240 -> 0.2
A18: 2 ploughmen for year | C18: 5 | F18: =B18+C18/20+D18/240 -> 0.25
A19: 1 hayward for 1/2 year | C19: 1 | D19: 3 | F19: =B19+C19/20+D19/240 -> 0.0625
A20: 2 shephers for the year | C20: 5 | F20: =B20+C20/20+D20/240 -> 0.25
A21: Total recorded in accounts | C21: 15 | D21: 3 | F21: =B21+C21/20+D21/240 -> 0.7625
A22: Total | B22: =SUM(B17:B20) -> 0 | C22: =SUM(C17:C20) -> 15 | D22: =SUM(D17:D20) -> 3 | F22: =B22+C22/20+D22/240 -> 0.7625 | G22: =F22-F21 -> 0
A24: Defaults of rent
A25: default of a plot formerly belonging to John Vicar' | D25: 6 | F25: =B25+C25/20+D25/240 -> 0.025
A26: Total recorded in accounts | D26: 6 | F26: =B26+C26/20+D26/240 -> 0.025
A27: Total | B27: =SUM(B25:B25) -> 0 | C27: =SUM(C25:C25) -> 0 | D27: =SUM(D25:D25) -> 6 | F27: =B27+C27/20+D27/240 -> 0.025 | G27: =F27-F26 -> 0
A29: Total of rents remaining | B29: 11 | C29: 9 | D29: 9 | F29: =B29+C29/20+D29/240 -> 11.4875
A31: Annual recognizances
A32: from John Pavel | D32: 6 | F32: =B32+C32/20+D32/240 -> 0.025
A33: from John Scherewynd | D33: 6 | F33: =B33+C33/20+D33/240 -> 0.025
A34: from Roger le Dregh to come to 2 tous and pay suit for his tithing | D34: 6 | F34: =B34+C34/20+D34/240 -> 0.025
A35: Total recorded in accounts | C35: 1 | D35: 6 | F35: =B35+C35/20+D35/240 -> 0.075
A36: Total | B36: =SUM(B32:B34) -> 0 | C36: =SUM(C32:C34) -> 0 | D36: =SUM(D32:D34) -> 18 | F36: =B36+C36/20+D36/240 -> 0.075 | G36: =F36-F35 -> 0
A38: Issues of the manor
A39: from panage of pigs | C39: 3 | D39: 11 | F39: =B39+C39/20+D39/240 -> 0.19583333
A40: from pannage of oxen (at Martinmas) | C40: 10 | F40: =B40+C40/20+D40/240 -> 0.5
A41: from panage of oxen (at Hockday) | C41: 10 | D41: 4 | F41: =B41+C41/20+D41/240 -> 0.51666667
A42: from panage of sheep | D42: 8.5 | F42: =B42+C42/20+D42/240 -> 0.035416667
A43: from hay sold | B43: 1 | C43: 4 | F43: =B43+C43/20+D43/240 -> 1.2
A44: from the residue of Peter's Pence | C44: 4 | D44: 8 | F44: =B44+C44/20+D44/240 -> 0.23333333
A45: from 1 feeble and sick ox sold | C45: 5 | D45: 6 | F45: =B45+C45/20+D45/240 -> 0.275
A46: from 7 late-born calves sold | C46: 7 | D46: 9 | F46: =B46+C46/20+D46/240 -> 0.3875
A47: from 21 kebb wethers and 40 ewes sold | B47: 2 | C47: 14 | D47: 1 | F47: =B47+C47/20+D47/240 -> 2.7041667
...

Sheet Bishopstone Expenses
A1: BISHOPSTONE EXPENSES
B2: £ | C2: s | D2: d | F2: Total in £ | G2: Error | H2: Notes
A3: Cost of Ploughs
A4: in ironwork of 2 ploughs for the year with stipend of smith | C4: 12 | D4: 6 | F4: =B4+C4/20+D4/240 -> 0.625
A5: in 2 ploughfeet | D5: 6 | F5: =B5+C5/20+D5/240 -> 0.025
A6: in 2 yokes | D6: 2 | F6: =B6+C6/20+D6/240 -> 0.0083333333
A7: in 4 wheels | D7: 6 | F7: =B7+C7/20+D7/240 -> 0.025
A8: in 1 boon-work of 16 ploughmen in winter and 14 in lent | C8: 5 | F8: =B8+C8/20+D8/240 -> 0.25
A9: in stipend of 2 ploughmen for the year | C9: 6 | F9: =B9+C9/20+D9/240 -> 0.3
A10: in allowance of Thomas reeve for making a plough which ihe is bound to do according to custom | C10: 1 | D10: 6 | F10: =B10+C10/20+D10/240 -> 0.075
A11: in 1 ox bought for the plough | C11: 9 | F11: =B11+C11/20+D11/240 -> 0.45
A12: Total recorded in accounts | B12: 1 | C12: 15 | D12: 2 | F12: =B12+C12/20+D12/240 -> 1.7583333
A13: Total | B13: =SUM(B4:B11) -> 0 | C13: =SUM(C4:C11) -> 33 | D13: =SUM(D4:D11) -> 26 | F13: =B13+C13/20+D13/240 -> 1.7583333 | G13: =F13-F12 -> 0
A14: Total capital expenses | B14: =SUM(B10:B11,B4:B7) -> 0 | C14: =SUM(C10:C11,C4:C7) -> 22 | D14: =SUM(D10:D11,D4:D7) -> 26 | F14: =B14+C14/20+D14/240 -> 1.2083333
F15: =B15+C15/20+D15/240 -> 0
A16: Cost of Carts and Wagons
A17: in 4 clouts | D17: 3 | F17: =B17+C17/20+D17/240 -> 0.0125
A18: in 1 halter | D18: 1 | F18: =B18+C18/20+D18/240 -> 0.0041666667
A19: in shoeing the carthorse | C19: 1 | D19: 3 | F19: =B19+C19/20+D19/240 -> 0.0625
A20: in white leather bought | D20: 1.5 | F20: =B20+C20/20+D20/240 -> 0.00625
A21: Total recorded in accounts | C21: 1 | D21: 8.5 | F21: =B21+C21/20+D21/240 -> 0.085416667
A22: Total | B22: =SUM(B17:B20) -> 0 | C22: =SUM(C17:C20) -> 1 | D22: =SUM(D17:D20) -> 8.5 | F22: =B22+C22/20+D22/240 -> 0.085416667 | G22: =F22-F21 -> 0
A23: Total capital expenses | B23: =SUM(B17:B20) -> 0 | C23: =SUM(C17:C20) -> 1 | D23: =SUM(D17:D20) -> 8.5 | F23: =B23+C23/20+D23/240 -> 0.085416667
A25: Cost of Dairy
A26: in 5 bus of salt bought for salting cheese and butter | C26: 1 | D26: 3 | F26: =B26+C26/20+D26/240 -> 0.0625
A27: in linen and woollen cloth bought for cheese | D27: 8.5 | F27: =B27+C27/20+D27/240 -> 0.035416667
A28: in earthenware pots and pans | D28: 2.5 | F28: =B28+C28/20+D28/240 -> 0.010416667
A29: in a press bought | D29: 6 | F29: =B29+C29/20+D29/240 -> 0.025
A30: in stipend of 1 dairymaid for the year | C30: 2 | D30: 6 | F30: =B30+C30/20+D30/240 -> 0.125
A31: Total recorded in accounts | C31: 5 | D31: 2 | F31: =B31+C31/20+D31/240 -> 0.25833333
A32: Total | B32: =SUM(B26:B30) -> 0 | C32: =SUM(C26:C30) -> 3 | D32: =SUM(D26:D30) -> 26 | F32: =B32+C32/20+D32/240 -> 0.25833333 | G32: =F32-F31 -> 0
A33: Total capital expenses | B33: =SUM(B26:B29) -> 0 | C33: =SUM(C26:C29) -> 1 | D33: =SUM(D26:D29) -> 20 | F33: =B33+C33/20+D33/240 -> 0.13333333
A35: Sheepcote
A36: in grease, vinegar and copperas bought for greasing sheep | C36: 16 | D36: 8.5 | F36: =B36+C36/20+D36/240 -> 0.83541667
A37: in 1 stake bought | D37: 10 | F37: =B37+C37/20+D37/240 -> 0.041666667
A38: in 27 hurdles bought | C38: 2 | D38: 8 | F38: =B38+C38/20+D38/240 -> 0.13333333
A39: in 16 ells of canvas bought for packing wool | C39: 4 | D39: 4 | F39: =B39+C39/20+D39/240 -> 0.21666667
A40: in packing the said wool and making sacks with the thread bought for the same | D40: 8 | F40: =B40+C40/20+D40/240 -> 0.033333333
A41: Total recorded in accounts | B41: 1 | C41: 5 | D41: 2.5 | F41: =B41+C41/20+D41/240 -> 1.2604167
A42: Total | B42: =SUM(B36:B40) -> 0 | C42: =SUM(C36:C40) -> 22 | D42: =SUM(D36:D40) -> 38.5 | F42: =B42+C42/20+D42/240 -> 1.2604167 | G42: =F42-F41 -> 0
...

Sheet Issues of the Grange
B1: The issue of the grange account gives the total "yield" at the top of each heading in curly brackets, measurements used: fold, qrs, bus
B2: In "Issues of the grange" (p.xx) | G2: In "Sale of Corn" (p.x) | P2: Value of Total Production
A3: Gross output | B3: Quantity | D3: Additional bought-in | F3: Quantity | G3: Quantity noted as sold | J3: Difference Produced vs. Sold | K3: Price 1 | L3: Quantity 1 | M3: Price 2 | N3: Quantity 2 | O3: Unit price | P3: Value
B4: qrs | C4: bus | D4: qrs | E4: bus | F4: qrs | G4: qrs | H4: bus | I4: qrs | K4: £ | L4: qrs | M4: £ | N4: qrs | O4: £ per qr | P4: £
A5: Wheat | B5: 71 | F5: =B5+D5+C5/8+E5/8 -> 71 | G5: 48 | H5: 10 | I5: =G5+H5/8 -> 49.25 | J5: =F5-I5 -> 21.75 | K5: ='Bishopstone Receipts'!F68 -> 12.31875 | L5: =48+7/8 -> 48.875 | M5: ='Bishopstone Receipts'!F69 -> 0.075 | N5: =3/8 -> 0.375 | O5: =IFERROR((K5+M5)/(L5+N5),0) -> 0.25164975 | P5: =O5*F5 -> 17.867132
A6: Curall | B6: 7 | C6: 6 | F6: =B6+D6+C6/8+E6/8 -> 7.75 | G6: 7 | H6: 6 | I6: =G6+H6/8 -> 7.75 | J6: =F6-I6 -> 0 | K6: ='Bishopstone Receipts'!F70 -> 1.0760417 | L6: =I6 -> 7.75 | O6: =IFERROR((K6+M6)/(L6+N6),0) -> 0.13884409 | P6: =O6*F6 -> 1.0760417
A7: Barley | B7: 120.5 | F7: =B7+D7+C7/8+E7/8 -> 120.5 | G7: 75 | H7: 1 | I7: =G7+H7/8 -> 75.125 | J7: =F7-I7 -> 45.375 | K7: ='Bishopstone Receipts'!F72 -> 15.004167 | L7: =I7 -> 75.125 | O7: =IFERROR((K7+M7)/(L7+N7),0) -> 0.19972268 | P7: =O7*F7 -> 24.066583
A8: Oats | B8: 60 | C8: 1 | F8: =B8+D8+C8/8+E8/8 -> 60.125 | G8: 35 | I8: =G8+H8/8 -> 35 | J8: =F8-I8 -> 25.125 | K8: ='Bishopstone Receipts'!F73 -> 4.6666667 | L8: =I8 -> 35 | O8: =IFERROR((K8+M8)/(L8+N8),0) -> 0.13333333 | P8: =O8*F8 -> 8.0166667
A9: Peas | B9: 21 | C9: 7 | F9: =B9+D9+C9/8+E9/8 -> 21.875 | G9: 13.5 | I9: =G9+H9/8 -> 13.5 | J9: =F9-I9 -> 8.375 | K9: ='Bishopstone Receipts'!F74 -> 2.25 | L9: =G9 -> 13.5 | O9: =IFERROR((K9+M9)/(L9+N9),0) -> 0.16666667 | P9: =O9*F9 -> 3.6458333
A10: Vetches | B10: 9 | C10: 4 | F10: =B10+D10+C10/8+E10/8 -> 9.5 | G10: 7 | I10: =G10+H10/8 -> 7 | J10: =F10-I10 -> 2.5 | K10: ='Bishopstone Receipts'!F75 -> 0.93333333 | L10: =I10 -> 7 | O10: =IFERROR((#REF!+M10)/(K10+N10),0) -> 0 | P10: =O10*F10 -> 0
A12: Total Production | F12: =SUM(F5:F10) -> 290.75 | P12: =SUM(P5:P10) -> 54.672257 | Q12: Production value is significantly more, as much less was sold than what was produced
A13: Sales of corn (as recorded in accounts) | F13: =SUM(I5:I10) -> 187.625 | P13: =SUM(K5:K10,M5:M10) -> 36.323958
A16: Net output | B16: Gross output | C16: Seed | F16: tithe | G16: to manorial servants & livestock | J16: Output net of tithe & seed & liveries to manorial servants | K16: in stock from last year | L16: Price | M16: Value of net output | N16: Value of sales (in "Sale of Corn")
B17: qrs | C17: qrs | D17: bus | E17: qrs | F17: qrs | G17: qrs | H17: bus | I17: qrs | J17: qrs | K17: qrs | L17: £ per qr | M17: £ | N17: £
A18: Wheat | B18: =B5 -> 71 | C18: 18 | D18: 1 | E18: =C18+D18/8 -> 18.125 | G18: 2.5 | H18: 9 | I18: =G18+H18/8 -> 3.625 | J18: =B18-(E18+F18+I18) -> 49.25 | L18: =O5 -> 0.25164975 | M18: =L18*J18 -> 12.39375 | N18: =I5*O5 -> 12.39375
A19: Curall | B19: =B6 -> 7 | E19: =C19+D19/8 -> 0 | I19: =G19+H19/8 -> 0 | J19: =B19-(E19+F19+I19) -> 7 | L19: =O6 -> 0.13884409 | M19: =L19*J19 -> 0.9719086 | N19: =I6*O6 -> 1.0760417
A20: Barley | B20: =B7 -> 120.5 | C20: 22 | D20: 6 | E20: =C20+D20/8 -> 22.75 | G20: 21.5 | H20: 8 | I20: =G20+H20/8 -> 22.5 | J20: =B20-(E20+F20+I20) -> 75.25 | L20: =O7 -> 0.19972268 | M20: =L20*J20 -> 15.029132 | N20: =I7*O7 -> 15.004167
A21: Oats | B21: =B8 -> 60 | C21: 21 | D21: 6 | E21: =C21+D21/8 -> 21.75 | G21: 3 | H21: 3 | I21: =G21+H21/8 -> 3.375 | J21: =B21-(E21+F21+I21) -> 34.875 | L21: =O8 -> 0.13333333 | M21: =L21*J21 -> 4.65 | N21: =I8*O8 -> 4.6666667
A22: Peas | B22: =B9 -> 21 | C22: 3 | D22: 2 | E22: =C22+D22/8 -> 3.25 | H22: 2 | I22: =G22+H22/8 -> 0.25 | J22: =B22-(E22+F22+I22) -> 17.5 | L22: =O9 -> 0.16666667 | M22: =L22*J22 -> 2.9166667 | N22: =I9*O9 -> 2.25
A23: Vetches | B23: =B10 -> 9 | C23: 2 | D23: 4 | E23: =C23+D23/8 -> 2.5 | J23: =B23-(E23+F23+I23) -> 6.5 | L23: =O10 -> 0 | M23: =L23*J23 -> 0 | N23: =I10*O10 -> 0
A24: Liveries of manorial servants
A25: Total | B25: =SUM(B18:B23) -> 288.5 | E25: =SUM(E18:E23) -> 68.375 | J25: =SUM(J18:J23) -> 190.375 | M25: =SUM(M18:M23) -> 35.961457

Sheet Stock
A1: EAST KNOYLE STOCK ACCOUNT
A3: Livestock | B3: Inherited stock | C3: Bought / added not produced | D3: Produced | E3: strays | F3: herbage | G3: sold | H3: in murrain | I3: accounted for elsewhere | J3: End-period stock | K3: cross-check | L3: price 1 | M3: units 1 | N3: price 2 | O3: units 2 | P3: Weight (weys) | Q3: Unit price (£) | R3: Value of production (£) at sales prices | S3: Sales in (£) | T3: Details
A4: Cart-horses | K4: =B4+C4+D4-E4-F4-G4-H4-I4 -> 0 | Q4: =IFERROR((L4+N4)/(M4+O4),"") | R4: =IFERROR(D4*Q4,"") | S4: =IFERROR(Q4*G4,"")
A5: Mares | K5: =B5+C5+D5-E5-F5-G5-H5-I5 -> 0 | Q5: =IFERROR((L5+N5)/(M5+O5),"") | R5: =IFERROR(D5*Q5,"") | S5: =IFERROR(Q5*G5,"")
A6: Plough horses | B6: 1 | J6: 1 | K6: =B6+C6+D6-E6-F6-G6-H6-I6 -> 1 | Q6: =IFERROR((L6+N6)/(M6+O6),"") | R6: =IFERROR(D6*Q6,"") | S6: =IFERROR(Q6*G6,"")
A7: Colts (2 years) | K7: =B7+C7+D7-E7-F7-G7-H7-I7 -> 0 | Q7: =IFERROR((L7+N7)/(M7+O7),"") | R7: =IFERROR(D7*Q7,"") | S7: =IFERROR(Q7*G7,"")
A8: Colts (2 years) | K8: =B8+C8+D8-E8-F8-G8-H8-I8 -> 0 | Q8: =IFERROR((L8+N8)/(M8+O8),"") | R8: =IFERROR(D8*Q8,"") | S8: =IFERROR(Q8*G8,"")
A9: Colts (1 year) | K9: =B9+C9+D9-E9-F9-G9-H9-I9 -> 0 | Q9: =IFERROR((L9+N9)/(M9+O9),"") | R9: =IFERROR(D9*Q9,"") | S9: =IFERROR(Q9*G9,"")
A10: Foals | K10: =B10+C10+D10-E10-F10-G10-H10-I10 -> 0 | Q10: =IFERROR((L10+N10)/(M10+O10),"") | R10: =IFERROR(D10*Q10,"") | S10: =IFERROR(Q10*G10,"")
A11: Oxen | B11: 16 | C11: 2 | D11: 1 | G11: 1 | J11: 18 | K11: =B11+C11+D11-E11-F11-G11-H11-I11 -> 18 | L11: ='Bishopstone Receipts'!F45 -> 0.275 | M11: 1 | Q11: =IFERROR((L11+N11)/(M11+O11),"") -> 0.275 | R11: =IFERROR(D11*Q11,"") -> 0.275 | S11: =IFERROR(Q11*G11,"") -> 0.275
A12: Bulls | B12: 1 | C12: 1 | I12: 1 | J12: 1 | K12: =B12+C12+D12-E12-F12-G12-H12-I12 -> 1 | Q12: =IFERROR((L12+N12)/(M12+O12),"") | R12: =IFERROR(D12*Q12,"") | S12: =IFERROR(Q12*G12,"")
A13: Cows | B13: 11 | C13: 1 | H13: 1 | J13: 11 | K13: =B13+C13+D13-E13-F13-G13-H13-I13 -> 11 | Q13: =IFERROR((L13+N13)/(M13+O13),"") | R13: =IFERROR(D13*Q13,"") | S13: =IFERROR(Q13*G13,"")
A14: Steers | B14: 4 | H14: 1 | I14: 3 | K14: =B14+C14+D14-E14-F14-G14-H14-I14 -> 0 | Q14: =IFERROR((L14+N14)/(M14+O14),"") | R14: =IFERROR(D14*Q14,"") | S14: =IFERROR(Q14*G14,"")
A15: Bullocks | B15: 2 | C15: 2 | H15: 1 | J15: 3 | K15: =B15+C15+D15-E15-F15-G15-H15-I15 -> 3 | Q15: =IFERROR((L15+N15)/(M15+O15),"") | R15: =IFERROR(D15*Q15,"") | S15: =IFERROR(Q15*G15,"")
A16: Yearlings | B16: 3 | J16: 3 | K16: =B16+C16+D16-E16-F16-G16-H16-I16 -> 3 | Q16: =IFERROR((L16+N16)/(M16+O16),"") | R16: =IFERROR(D16*Q16,"") | S16: =IFERROR(Q16*G16,"")
A17: Calves | D17: 11 | G17: 7 | H17: 1 | I17: 1 | J17: 2 | K17: =B17+C17+D17-E17-F17-G17-H17-I17 -> 2 | L17: ='Bishopstone Receipts'!F46 -> 0.3875 | M17: 7 | Q17: =IFERROR((L17+N17)/(M17+O17),"") -> 0.055357143 | R17: =IFERROR(D17*Q17,"") -> 0.60892857 | S17: =IFERROR(Q17*G17,"") -> 0.3875
A18: Wethers | B18: 275 | C18: 81 | G18: 27 | H18: 26 | I18: 2 | J18: 301 | K18: =B18+C18+D18-E18-F18-G18-H18-I18 -> 301 | L18: ='Bishopstone Receipts'!F48 -> 0.175 | M18: 6 | N18: ='Bishopstone Receipts'!F47/3 -> 0.90138889 | O18: 21 | Q18: =IFERROR((L18+N18)/(M18+O18),"") -> 0.039866255 | R18: =IFERROR(D18*Q18,"") -> 0 | S18: =IFERROR(Q18*G18,"") -> 1.0763889 | T18: Price of ewes and wethers conflated in receipts - assume same price
A19: Rams | B19: 4 | J19: 4 | K19: =B19+C19+D19-E19-F19-G19-H19-I19 -> 4 | Q19: =IFERROR((L19+N19)/(M19+O19),"") | R19: =IFERROR(D19*Q19,"") | S19: =IFERROR(Q19*G19,"")
A20: Ewes | B20: 340 | C20: 71 | G20: 40 | H20: 14 | J20: 357 | K20: =B20+C20+D20-E20-F20-G20-H20-I20 -> 357 | L20: ='Bishopstone Receipts'!F47*2/3 -> 1.8027778 | M20: 40 | Q20: =IFERROR((L20+N20)/(M20+O20),"") -> 0.045069444 | R20: =IFERROR(D20*Q20,"") -> 0 | S20: =IFERROR(Q20*G20,"") -> 1.8027778 | T20: Price of ewes and wethers conflated in receipts - assume same price
A21: Hoggs | B21: 158 | H21: 6 | I21: 152 | J21: 0 | K21: =B21+C21+D21-E21-F21-G21-H21-I21 -> 0 | Q21: =IFERROR((L21+N21)/(M21+O21),"") | R21: =IFERROR(D21*Q21,"") | S21: =IFERROR(Q21*G21,"")
A22: Lambs | D22: 276 | F22: 7 | G22: 50 | H22: 18 | I22: 30 | J22: 171 | K22: =B22+C22+D22-E22-F22-G22-H22-I22 -> 171 | L22: ='Bishopstone Receipts'!F49 -> 1.1208333 | M22: 50 | Q22: =IFERROR((L22+N22)/(M22+O22),"") -> 0.022416667 | R22: =IFERROR(D22*Q22,"") -> 6.187 | S22: =IFERROR(Q22*G22,"") -> 1.1208333 | T22: account states 185 remain
A23: Boars | K23: =B23+C23+D23-E23-F23-G23-H23-I23 -> 0 | Q23: =IFERROR((L23+N23)/(M23+O23),"") | R23: =IFERROR(D23*Q23,"") | S23: =IFERROR(Q23*G23,"")
A24: Sows | K24: =B24+C24+D24-E24-F24-G24-H24-I24 -> 0 | Q24: =IFERROR((L24+N24)/(M24+O24),"") | R24: =IFERROR(D24*Q24,"") | S24: =IFERROR(Q24*G24,"")
A25: Pigs | K25: =B25+C25+D25-E25-F25-G25-H25-I25 -> 0 | Q25: =IFERROR((L25+N25)/(M25+O25),"") | R25: =IFERROR(D25*Q25,"") | S25: =IFERROR(Q25*G25,"")
A26: Hoggets | K26: =B26+C26+D26-E26-F26-G26-H26-I26 -> 0 | Q26: =IFERROR((L26+N26)/(M26+O26),"") | R26: =IFERROR(D26*Q26,"") | S26: =IFERROR(Q26*G26,"")
A27: Piglets | K27: =B27+C27+D27-E27-F27-G27-H27-I27 -> 0 | Q27: =IFERROR((L27+N27)/(M27+O27),"") | R27: =IFERROR(D27*Q27,"") | S27: =IFERROR(Q27*G27,"")
A28: Swans | K28: =B28+C28+D28-E28-F28-G28-H28-I28 -> 0 | Q28: =IFERROR((L28+N28)/(M28+O28),"") | R28: =IFERROR(D28*Q28,"") | S28: =IFERROR(Q28*G28,"")
A29: Peacocks | K29: =B29+C29+D29-E29-F29-G29-H29-I29 -> 0 | Q29: =IFERROR((L29+N29)/(M29+O29),"") | R29: =IFERROR(D29*Q29,"") | S29: =IFERROR(Q29*G29,"")
A30: Total | K30: =B30+C30+D30-E30-F30-G30-H30-I30 -> 0 | Q30: =IFERROR((L30+N30)/(M30+O30),"") | R30: =IFERROR(D30*Q30,"") | S30: =SUM(S4:S29) -> 4.6625
A32: Wool | K32: =B32+C32+D32-E32-F32-G32-H32-I32 -> 0 | Q32: =IFERROR((L32+N32)/(M32+O32),"") | R32: =IFERROR(D32*Q32,"") | S32: =IFERROR(Q32*G32,"")
A33: Fleeces | D33: 684 | I33: =615+69 -> 684 | J33: 0 | K33: =B33+C33+D33-E33-F33-G33-H33-I33 -> 0 | Q33: 0.02 | R33: =IFERROR(D33*Q33,"") -> 13.68 | S33: =IFERROR(Q33*G33,"") -> 0 | T33: 615 sent to Wolvesey which made 4 weys and 5 cloves
A34: Coarse wool | K34: =B34+C34+D34-E34-F34-G34-H34-I34 -> 0 | Q34: =IFERROR((L34+N34)/(M34+O34),"") | R34: =IFERROR(D34*Q34,"") | S34: =IFERROR(Q34*G34,"")
A35: Lamb's wool | D35: 237 | I35: 237 | J35: 0 | K35: =B35+C35+D35-E35-F35-G35-H35-I35 -> 0 | Q35: 0.01 | R35: =IFERROR(D35*Q35,"") -> 2.37 | S35: =IFERROR(Q35*G35,"") -> 0 | T35: 273 sent to Wolvesey which made 0.5 weys
A36: Wool locks | D36: =7.5*Assumptions!E7 -> 0.53571429 | G36: =D36 -> 0.53571429 | J36: 0 | K36: =B36+C36+D36-E36-F36-G36-H36-I36 -> 0 | L36: ='Bishopstone Receipts'!F56 -> 0.53333333 | M36: =P36 -> 0.53571429 | P36: =G36 -> 0.53571429 | Q36: =IFERROR((L36+N36)/(M36+O36),"") -> 0.99555556 | R36: =IFERROR(D36*Q36,"") -> 0.53333333 | S36: =IFERROR(Q36*G36,"") -> 0.53333333
A37: Wool sold at shearing | K37: =B37+C37+D37-E37-F37-G37-H37-I37 -> 0 | Q37: =IFERROR((L37+N37)/(M37+O37),"") | R37: =IFERROR(D37*Q37,"") | S37: =IFERROR(Q37*G37,"")
A38: Total | K38: =B38+C38+D38-E38-F38-G38-H38-I38 -> 0 | Q38: =IFERROR((L38+N38)/(M38+O38),"") | R38: =SUM(R33:R37) -> 16.583333
A41: Hides | K41: =B41+C41+D41-E41-F41-G41-H41-I41 -> 0 | Q41: =IFERROR((L41+N41)/(M41+O41),"") | R41: =IFERROR(D41*Q41,"") | S41: =IFERROR(Q41*G41,"")
A42: Ox hides | K42: =B42+C42+D42-E42-F42-G42-H42-I42 -> 0 | Q42: =IFERROR((L42+N42)/(M42+O42),"") | R42: =IFERROR(D42*Q42,"") | S42: =IFERROR(Q42*G42,"")
A43: Cow hides | D43: 1 | G43: 1 | J43: 0 | K43: =B43+C43+D43-E43-F43-G43-H43-I43 -> 0 | L43: ='Bishopstone Receipts'!F50 -> 0.091666667 | M43: 1 | Q43: =IFERROR((L43+N43)/(M43+O43),"") -> 0.091666667 | R43: =IFERROR(D43*Q43,"") -> 0.091666667 | S43: =IFERROR(Q43*G43,"") -> 0.091666667
A44: Mare hides | K44: =B44+C44+D44-E44-F44-G44-H44-I44 -> 0 | Q44: =IFERROR((L44+N44)/(M44+O44),"") | R44: =IFERROR(D44*Q44,"") | S44: =IFERROR(Q44*G44,"")
...

Sheet Assumptions
A1: ASSUMPTIONS
B3: Weights | C3: Value (in lbs) | D3: Value (in cloves) | E3: Value (in weys) | F3: Value (in stone)
B4: Lbs | C4: 1 | D4: =C4/C5 -> 0.14285714 | E4: =C4/C6 -> 0.0057142857 | F4: =C4/C7 -> 0.08
B5: Cloves | C5: 7 | D5: 1 | E5: =C5/C6 -> 0.04 | F5: =C7/C5 -> 1.7857143
B6: Wey | C6: 175 | D6: =C6/C5 -> 25 | E6: =C6/C6 -> 1 | F6: =C7/C6 -> 0.071428571
B7: Stone | C7: =175/14 -> 12.5 | D7: =C5/C7 -> 0.56 | E7: =C7/C6 -> 0.071428571 | F7: 1
