Workbook

Sheet Crawley Overview
A1: CRAWLEY | B1: £ | C1: s | D1: d | G1: Total in £ | H1: Error
A3: CASH ACCOUNT
A4: RECEIPTS
A5: Arrears total | G5: =IF(INDEX('Crawley Receipts'!$A$4:$F$110,MATCH('Crawley Overview'!$A5,'Crawley Receipts'!$A$4:$A$110,0),6)=0,"",INDEX('Crawley Receipts'!$A$4:$F$110,MATCH('Crawley Overview'!$A5,'Crawley Receipts'!$A$4:$A$110,0),6)) -> 7.4333333
A6: Rents of assize total | G6: =IF(INDEX('Crawley Receipts'!$A$4:$F$110,MATCH('Crawley Overview'!$A6,'Crawley Receipts'!$A$4:$A$110,0),6)=0,"",INDEX('Crawley Receipts'!$A$4:$F$110,MATCH('Crawley Overview'!$A6,'Crawley Receipts'!$A$4:$A$110,0),6)) -> 14.079167
A7: Quittances total | G7: =IF(INDEX('Crawley Receipts'!$A$4:$F$110,MATCH('Crawley Overview'!$A7,'Crawley Receipts'!$A$4:$A$110,0),6)=0,"",INDEX('Crawley Receipts'!$A$4:$F$110,MATCH('Crawley Overview'!$A7,'Crawley Receipts'!$A$4:$A$110,0),6)) -> 2.7833333
A8: Defaults of rent total | G8: =IF(INDEX('Crawley Receipts'!$A$4:$F$110,MATCH('Crawley Overview'!$A8,'Crawley Receipts'!$A$4:$A$110,0),6)=0,"",INDEX('Crawley Receipts'!$A$4:$F$110,MATCH('Crawley Overview'!$A8,'Crawley Receipts'!$A$4:$A$110,0),6)) -> 1.0166667
A9: Total of rents remaining | G9: ='Crawley Receipts'!F36 -> 10.279167
A10: Annual recognizances total | G10: =IF(INDEX('Crawley Receipts'!$A$4:$F$110,MATCH('Crawley Overview'!$A10,'Crawley Receipts'!$A$4:$A$110,0),6)=0,"",INDEX('Crawley Receipts'!$A$4:$F$110,MATCH('Crawley Overview'!$A10,'Crawley Receipts'!$A$4:$A$110,0),6)) -> 0.0875
A11: Issues of the Manor total | G11: =IF(INDEX('Crawley Receipts'!$A$4:$F$110,MATCH('Crawley Overview'!$A11,'Crawley Receipts'!$A$4:$A$110,0),6)=0,"",INDEX('Crawley Receipts'!$A$4:$F$110,MATCH('Crawley Overview'!$A11,'Crawley Receipts'!$A$4:$A$110,0),6)) -> 19.945833
A12: Sale of corn total | G12: =IF(INDEX('Crawley Receipts'!$A$4:$F$110,MATCH('Crawley Overview'!$A12,'Crawley Receipts'!$A$4:$A$110,0),6)=0,"",INDEX('Crawley Receipts'!$A$4:$F$110,MATCH('Crawley Overview'!$A12,'Crawley Receipts'!$A$4:$A$110,0),6)) -> 23.983333
A13: Entry and marriage fines total | G13: =IF(INDEX('Crawley Receipts'!$A$4:$F$110,MATCH('Crawley Overview'!$A13,'Crawley Receipts'!$A$4:$A$110,0),6)=0,"",INDEX('Crawley Receipts'!$A$4:$F$110,MATCH('Crawley Overview'!$A13,'Crawley Receipts'!$A$4:$A$110,0),6)) -> 0.86666667
A14: Pleas & perquisites total | G14: =IF(INDEX('Crawley Receipts'!$A$4:$F$110,MATCH('Crawley Overview'!$A14,'Crawley Receipts'!$A$4:$A$110,0),6)=0,"",INDEX('Crawley Receipts'!$A$4:$F$110,MATCH('Crawley Overview'!$A14,'Crawley Receipts'!$A$4:$A$110,0),6)) -> 0.99583333
A15: Sum of the above (incl. arrears) | G15: =G5+G9+G10+G11+G12+G13+G14 -> 63.591667
A16: Total recorded in the accounts excl. arrears | G16: ='Crawley Receipts'!F110 -> 56.1625 | H16: matches excl. arrear sum
A17: Total recorded in the accounts incl. arrears
A20: EXPENSES
A21: Cost of ploughs total | G21: =IF(INDEX('Crawley Expenses'!$A$2:$F$108,MATCH('Crawley Overview'!$A21,'Crawley Expenses'!$A$2:$A$108,0),6)=0,"",INDEX('Crawley Expenses'!$A$2:$F$108,MATCH('Crawley Overview'!$A21,'Crawley Expenses'!$A$2:$A$108,0),6)) -> 3.553125
A22: Purchase of corn total | G22: =IF(INDEX('Crawley Expenses'!$A$2:$F$108,MATCH('Crawley Overview'!$A22,'Crawley Expenses'!$A$2:$A$108,0),6)=0,"",INDEX('Crawley Expenses'!$A$2:$F$108,MATCH('Crawley Overview'!$A22,'Crawley Expenses'!$A$2:$A$108,0),6)) -> 0.84166667
A23: Cost of carts and wagons total | G23: =IF(INDEX('Crawley Expenses'!$A$2:$F$108,MATCH('Crawley Overview'!$A23,'Crawley Expenses'!$A$2:$A$108,0),6)=0,"",INDEX('Crawley Expenses'!$A$2:$F$108,MATCH('Crawley Overview'!$A23,'Crawley Expenses'!$A$2:$A$108,0),6)) -> 0.81875
A24: Cost of dairy total | G24: =IF(INDEX('Crawley Expenses'!$A$2:$F$108,MATCH('Crawley Overview'!$A24,'Crawley Expenses'!$A$2:$A$108,0),6)=0,"",INDEX('Crawley Expenses'!$A$2:$F$108,MATCH('Crawley Overview'!$A24,'Crawley Expenses'!$A$2:$A$108,0),6)) -> 3.9729167
A25: Cost of buildings total | G25: =IF(INDEX('Crawley Expenses'!$A$2:$F$108,MATCH('Crawley Overview'!$A25,'Crawley Expenses'!$A$2:$A$108,0),6)=0,"",INDEX('Crawley Expenses'!$A$2:$F$108,MATCH('Crawley Overview'!$A25,'Crawley Expenses'!$A$2:$A$108,0),6)) -> 0.321875
A26: Threshing total | G26: =IF(INDEX('Crawley Expenses'!$A$2:$F$108,MATCH('Crawley Overview'!$A26,'Crawley Expenses'!$A$2:$A$108,0),6)=0,"",INDEX('Crawley Expenses'!$A$2:$F$108,MATCH('Crawley Overview'!$A26,'Crawley Expenses'!$A$2:$A$108,0),6)) -> 1.0208333
A27: Expenses of the harvest total | G27: =IF(INDEX('Crawley Expenses'!$A$2:$F$108,MATCH('Crawley Overview'!$A27,'Crawley Expenses'!$A$2:$A$108,0),6)=0,"",INDEX('Crawley Expenses'!$A$2:$F$108,MATCH('Crawley Overview'!$A27,'Crawley Expenses'!$A$2:$A$108,0),6)) -> 1.6916667
A28: Steward's expenses total | G28: =IF(INDEX('Crawley Expenses'!$A$2:$F$108,MATCH('Crawley Overview'!$A28,'Crawley Expenses'!$A$2:$A$108,0),6)=0,"",INDEX('Crawley Expenses'!$A$2:$F$108,MATCH('Crawley Overview'!$A28,'Crawley Expenses'!$A$2:$A$108,0),6)) -> 1.2177083
A29: Sum of the above | G29: =SUM(G21:G28) -> 13.438542
A30: Total of all expenses | G30: ='Crawley Expenses'!F103 -> 13.403125 | H30: =G29-G30 -> 0.035416667
A31: Total Demesne fixed investment | G31: ='Crawley Expenses'!F108 -> 8.8708333
A33: Owed by the reeve | G33: ='Crawley Expenses'!F105 -> 42.726042
A34: From accounts
A36: Cash deliveries | G36: ='Crawley Expenses'!F106 -> 27.716667
A37: Total of all allowances and cash deliveries in accounts | B37: n/a
A39: Net amount owed | G39: =G33-G36 -> 15.009375
A40: Net amount owed in accounts | G40: ='Crawley Expenses'!F107 -> 15.009375 | H40: =G39-G40 -> 0
A42: GRANGE ACCOUNT | B42: Net Production
A43: Grange | B43: qrs | G43: £ | I43: Note: Columns indexed are hardcoded, do not alter number of columns in issues of grange
A44: Net wheat | B44: =IF(INDEX('Issues of the Grange'!$A$2:$P$26,MATCH('Crawley Overview'!$A44,'Issues of the Grange'!$A$2:$A$26,0),10)=0,"",INDEX('Issues of the Grange'!$A$2:$P$26,MATCH('Crawley Overview'!$A44,'Issues of the Grange'!$A$2:$A$26,0),10)) -> 40 | G44: =IF(INDEX('Issues of the Grange'!$A$2:$P$26,MATCH('Crawley Overview'!$A44,'Issues of the Grange'!$A$2:$A$26,0),13)=0,"",INDEX('Issues of the Grange'!$A$2:$P$26,MATCH('Crawley Overview'!$A44,'Issues of the Grange'!$A$2:$A$26,0),13)) -> 11.908333
A45: Net curall | B45: =IF(INDEX('Issues of the Grange'!$A$2:$P$26,MATCH('Crawley Overview'!$A45,'Issues of the Grange'!$A$2:$A$26,0),10)=0,"",INDEX('Issues of the Grange'!$A$2:$P$26,MATCH('Crawley Overview'!$A45,'Issues of the Grange'!$A$2:$A$26,0),10)) -> 12.0625 | G45: =IF(INDEX('Issues of the Grange'!$A$2:$P$26,MATCH('Crawley Overview'!$A45,'Issues of the Grange'!$A$2:$A$26,0),13)=0,"",INDEX('Issues of the Grange'!$A$2:$P$26,MATCH('Crawley Overview'!$A45,'Issues of the Grange'!$A$2:$A$26,0),13)) -> 2.2770833
A46: Net Bere | B46: =IF(INDEX('Issues of the Grange'!$A$2:$P$26,MATCH('Crawley Overview'!$A46,'Issues of the Grange'!$A$2:$A$26,0),10)=0,"",INDEX('Issues of the Grange'!$A$2:$P$26,MATCH('Crawley Overview'!$A46,'Issues of the Grange'!$A$2:$A$26,0),10)) | G46: =IF(INDEX('Issues of the Grange'!$A$2:$P$26,MATCH('Crawley Overview'!$A46,'Issues of the Grange'!$A$2:$A$26,0),13)=0,"",INDEX('Issues of the Grange'!$A$2:$P$26,MATCH('Crawley Overview'!$A46,'Issues of the Grange'!$A$2:$A$26,0),13))
A47: Net barley | B47: =IF(INDEX('Issues of the Grange'!$A$2:$P$26,MATCH('Crawley Overview'!$A47,'Issues of the Grange'!$A$2:$A$26,0),10)=0,"",INDEX('Issues of the Grange'!$A$2:$P$26,MATCH('Crawley Overview'!$A47,'Issues of the Grange'!$A$2:$A$26,0),10)) -> 22.1875 | G47: =IF(INDEX('Issues of the Grange'!$A$2:$P$26,MATCH('Crawley Overview'!$A47,'Issues of the Grange'!$A$2:$A$26,0),13)=0,"",INDEX('Issues of the Grange'!$A$2:$P$26,MATCH('Crawley Overview'!$A47,'Issues of the Grange'!$A$2:$A$26,0),13)) -> 4.4832046
...

Sheet Crawley Receipts
A1: CRAWLEY RECEIPTS
B2: £ | C2: s | D2: d | F2: Total in £ | G2: Error | H2: Notes
A4: Arrears
A5: Arrears total | B5: 7 | C5: 8 | D5: 8 | F5: =B5+C5/20+D5/240 -> 7.4333333
A6: of which delivered to treasurer of Wolvesey | B6: 7 | C6: 8 | D6: 8 | F6: =B6+C6/20+D6/240 -> 7.4333333
A8: Rents of assize
A9: Christmas | B9: 3 | C9: 1 | D9: 4 | F9: =B9+C9/20+D9/240 -> 3.0666667
A10: Easter | B10: 3 | C10: 1 | D10: 4 | F10: =B10+C10/20+D10/240 -> 3.0666667
A11: John the Baptist | B11: 3 | C11: 1 | D11: 4 | F11: =B11+C11/20+D11/240 -> 3.0666667
A12: Michaelmas | B12: 4 | C12: 17 | D12: 7 | F12: =B12+C12/20+D12/240 -> 4.8791667
A13: Total recorded in accounts | B13: 14 | C13: 1 | D13: 7 | F13: =B13+C13/20+D13/240 -> 14.079167
A14: Rents of assize total | B14: =SUM(B9:B12) -> 13 | C14: =SUM(C9:C12) -> 20 | D14: =SUM(D9:D12) -> 19 | F14: =B14+C14/20+D14/240 -> 14.079167 | G14: =F14-F13 -> 0
A16: Quittances
A17: 1 reeve for the year | C17: 5 | F17: =B17+C17/20+D17/240 -> 0.25
A18: 6 ploughmen 1 smith for the year | C18: 18 | D18: 8 | F18: =B18+C18/20+D18/240 -> 0.93333333
A19: 2 shepherds for the year | C19: 5 | D19: 4 | F19: =B19+C19/20+D19/240 -> 0.26666667
A20: 8 workers | B20: 1 | C20: 1 | D20: 4 | F20: =B20+C20/20+D20/240 -> 1.0666667
A21: 1 swineherd and 1 cowherd | C21: 5 | D21: 4 | F21: =B21+C21/20+D21/240 -> 0.26666667
A22: Total recorded in accounts | B22: 2 | C22: 15 | D22: 8 | F22: =B22+C22/20+D22/240 -> 2.7833333
A23: Quittances total | B23: =SUM(B17:B21) -> 1 | C23: =SUM(C17:C21) -> 34 | D23: =SUM(D17:D21) -> 20 | F23: =B23+C23/20+D23/240 -> 2.7833333 | G23: =F23-F22 -> 0
A25: Defaults of rent
A26: in default of le stronge into demesne | C26: 2 | F26: =B26+C26/20+D26/240 -> 0.1
A27: land of william | C27: 2 | D27: 8 | F27: =B27+C27/20+D27/240 -> 0.13333333
A28: land of Alebrok | C28: 5 | F28: =B28+C28/20+D28/240 -> 0.25
A29: land of Robert | C29: 2 | D29: 8 | F29: =B29+C29/20+D29/240 -> 0.13333333
A30: land of Robert Coye | C30: 2 | D30: 8 | F30: =B30+C30/20+D30/240 -> 0.13333333
A31: land of Roger le Pokyr | C31: 2 | D31: 8 | F31: =B31+C31/20+D31/240 -> 0.13333333
A32: land of Richard Vaccar | C32: 2 | D32: 8 | F32: =B32+C32/20+D32/240 -> 0.13333333
A33: Total recorded in accounts | B33: 1 | D33: 4 | F33: =B33+C33/20+D33/240 -> 1.0166667
A34: Defaults of rent total | B34: =SUM(B26:B32) -> 0 | C34: =SUM(C26:C32) -> 17 | D34: =SUM(D26:D32) -> 40 | F34: =B34+C34/20+D34/240 -> 1.0166667 | G34: =F34-F33 -> 0
A36: Total of rents remaining | B36: 10 | C36: 5 | D36: 7 | F36: =B36+C36/20+D36/240 -> 10.279167 | H36: not included in receipts
A38: Annual recognizances
A39: from Walter | D39: 6 | F39: =B39+C39/20+D39/240 -> 0.025
A40: from Robert | D40: 6 | F40: =B40+C40/20+D40/240 -> 0.025
A41: from Robert le Pottere | D41: 6 | F41: =B41+C41/20+D41/240 -> 0.025
A42: from John | D42: 3 | F42: =B42+C42/20+D42/240 -> 0.0125
A43: Total recorded in accounts | C43: 1 | D43: 9 | F43: =B43+C43/20+D43/240 -> 0.0875
A44: Annual recognizances total | B44: =SUM(B39:B42) -> 0 | C44: =SUM(C39:C42) -> 0 | D44: =SUM(D39:D42) -> 21 | F44: =B44+C44/20+D44/240 -> 0.0875 | G44: =F44-F43 -> 0
A46: Issues of the manor
A47: panage of pigs | C47: 6 | D47: 2.5 | F47: =B47+C47/20+D47/240 -> 0.31041667
...

Sheet Crawley Expenses
A1: CRAWLEY EXPENSES
B2: £ | C2: s | D2: d | F2: Total in £ | G2: Error | H2: Notes
A3: Cost of Ploughs
A4: in iron and steel bought for 4 ploughs | C4: 9 | F4: =B4+C4/20+D4/240 -> 0.45
A5: in 2 ploughshares bought | C5: 1 | D5: 8 | F5: =B5+C5/20+D5/240 -> 0.083333333
A6: in 1 coulter mended | D6: 2 | F6: =B6+C6/20+D6/240 -> 0.0083333333
A7: in 2 plough feet bought | D7: 7.5 | F7: =B7+C7/20+D7/240 -> 0.03125
A8: in 4 pairs of wheels bought | C8: 1 | D8: 4 | F8: =B8+C8/20+D8/240 -> 0.066666667
A9: in 2 ploughs made anew and other mending | C9: 1 | D9: 3 | F9: =B9+C9/20+D9/240 -> 0.0625
A10: in fitting ploughs with iron tyres | D10: 2.5 | F10: =B10+C10/20+D10/240 -> 0.010416667
A11: in shoeing 6 plough-horses | C11: 3 | D11: 11 | F11: =B11+C11/20+D11/240 -> 0.19583333
A12: in boon-works of 9 ploughmen | D12: 9 | F12: =B12+C12/20+D12/240 -> 0.0375
A13: in 5 halters made from the horeses own hair | D13: 1.75 | F13: =B13+C13/20+D13/240 -> 0.0072916667
A14: in stipend of 2 ploughmen for the year | C14: 6 | F14: =B14+C14/20+D14/240 -> 0.3
A15: in 5 oxen bought | B15: 2 | C15: 6 | F15: =B15+C15/20+D15/240 -> 2.3
A16: Total recorded in accounts | B16: 3 | C16: 11 | D16: 0.25 | F16: =B16+C16/20+D16/240 -> 3.5510417
A17: Cost of ploughs total | B17: =SUM(B4:B15) -> 2 | C17: =SUM(C4:C15) -> 27 | D17: =SUM(D4:D15) -> 48.75 | F17: =B17+C17/20+D17/240 -> 3.553125 | G17: =F17-F16 -> 0.0020833333
A18: Total capital expenses | B18: =SUM(B15,B13,B4:B11) -> 2 | C18: =SUM(C15,C13,C4:C11) -> 21 | D18: =SUM(D15,D13,D4:D11) -> 39.75 | F18: =B18+C18/20+D18/240 -> 3.215625
A20: Purchase of Corn
A21: in 6 bus of wheat bought for sowing | C21: 4 | D21: 6 | F21: =B21+C21/20+D21/240 -> 0.225
A22: in 3 qrs 6 bus of barley bought | C22: 12 | D22: 4 | F22: =B22+C22/20+D22/240 -> 0.61666667
A23: Total recorded in accounts | C23: 16 | D23: 10 | F23: =B23+C23/20+D23/240 -> 0.84166667
A24: Purchase of corn total | B24: =SUM(B21:B22) -> 0 | C24: =SUM(C21:C22) -> 16 | D24: =SUM(D21:D22) -> 10 | F24: =B24+C24/20+D24/240 -> 0.84166667 | G24: =F24-F23 -> 0
A26: Cost of Carts and Wagons
A27: in 1 pair of wheels bought | C27: 3 | D27: 4 | F27: =B27+C27/20+D27/240 -> 0.16666667
A28: in 1 old binding renewed and fitted | C28: 3 | F28: =B28+C28/20+D28/240 -> 0.15
A29: in fitting the cart with axles | D29: 8 | F29: =B29+C29/20+D29/240 -> 0.033333333
A30: in clouts nails and grease bought for the same | C30: 1 | F30: =B30+C30/20+D30/240 -> 0.05
A31: in 1 pair of traces bought | D31: 5.5 | F31: =B31+C31/20+D31/240 -> 0.022916667
A32: in 1 rope bought | D32: 2 | F32: =B32+C32/20+D32/240 -> 0.0083333333
A33: in shoeing 2 cart horses | C33: 2 | D33: 6 | F33: =B33+C33/20+D33/240 -> 0.125
A34: in white leather bought | D34: 4 | F34: =B34+C34/20+D34/240 -> 0.016666667
A35: in mending old harnesses | D35: 2 | F35: =B35+C35/20+D35/240 -> 0.0083333333
A36: in 1 collar bought | D36: 7 | F36: =B36+C36/20+D36/240 -> 0.029166667
A37: in stipend of 1 carter | C37: 3 | F37: =B37+C37/20+D37/240 -> 0.15
A38: in mending the cart at various times | D38: 2 | F38: =B38+C38/20+D38/240 -> 0.0083333333
A39: in 1 new cart-body bought | C39: 1 | F39: =B39+C39/20+D39/240 -> 0.05
A40: Total recorded in accounts | C40: 16 | D40: 4.5 | F40: =B40+C40/20+D40/240 -> 0.81875
A41: Cost of carts and wagons total | B41: =SUM(B27:B39) -> 0 | C41: =SUM(C27:C39) -> 13 | D41: =SUM(D27:D39) -> 40.5 | F41: =B41+C41/20+D41/240 -> 0.81875 | G41: =F41-F40 -> 0
A42: Total capital expenses | B42: =SUM(B38:B39,B27:B36) -> 0 | C42: =SUM(C38:C39,C27:C36) -> 10 | D42: =SUM(D38:D39,D27:D36) -> 40.5 | F42: =B42+C42/20+D42/240 -> 0.66875
...

Sheet Issues of the Grange
B1: The issue of the grange account gives the total "yield" at the top of each heading in curly brackets, measurements used: fold, qrs, bus
B2: In "Issues of the grange" (p.xx) | G2: In "Sale of Corn" (p.x) | P2: Value of Total Production
A3: Gross output | B3: Quantity | D3: Additional bought-in | F3: Quantity | G3: Quantity noted as sold | J3: Difference Produced vs. Sold | K3: Price 1 | L3: Quantity 1 | M3: Price 2 | N3: Quantity 2 | O3: Unit price | P3: Value
B4: qrs | C4: bus | D4: qrs | E4: bus | F4: qrs | G4: qrs | H4: bus | I4: qrs | K4: £ | L4: qrs | M4: £ | N4: qrs | O4: £ per qr | P4: £
A5: Wheat | B5: 58 | C5: 6 | E5: 6 | F5: =B5+D5+C5/8+E5/8 -> 59.5 | G5: 40 | I5: =G5+H5/8 -> 40 | J5: =F5-I5 -> 19.5 | K5: ='Crawley Receipts'!F82 -> 11.908333 | L5: 40 | O5: =IFERROR((K5+M5)/(L5+N5),0) -> 0.29770833 | P5: =O5*F5 -> 17.713646
A6: Curall | B6: 12 | C6: 0.5 | F6: =B6+D6+C6/8+E6/8 -> 12.0625 | G6: 12 | H6: 0.5 | I6: =G6+H6/8 -> 12.0625 | J6: =F6-I6 -> 0 | K6: ='Crawley Receipts'!F83 -> 2.2770833 | L6: =I6 -> 12.0625 | O6: =IFERROR((K6+M6)/(L6+N6),0) -> 0.18877375 | P6: =O6*F6 -> 2.2770833
A7: Bere | B7: 4 | C7: 2 | F7: =B7+D7+C7/8+E7/8 -> 4.25 | I7: =G7+H7/8 -> 0 | J7: =F7-I7 -> 4.25 | O7: =IFERROR((K7+M7)/(L7+N7),0) -> 0 | P7: =O7*F7 -> 0
A8: Barley | B8: 91 | C8: 5 | D8: 3 | E8: 6 | F8: =B8+D8+C8/8+E8/8 -> 95.375 | G8: 21.5 | H8: 6 | I8: =G8+H8/8 -> 22.25 | J8: =F8-I8 -> 73.125 | K8: ='Crawley Receipts'!F84 -> 4.3958333 | L8: =21+6/8 -> 21.75 | M8: ='Crawley Receipts'!F88 -> 0.1 | N8: 0.5 | O8: =IFERROR((K8+M8)/(L8+N8),0) -> 0.20205993 | P8: =O8*F8 -> 19.271465
A9: Oats | B9: 170 | F9: =B9+D9+C9/8+E9/8 -> 170 | G9: 43 | I9: =G9+H9/8 -> 43 | J9: =F9-I9 -> 127 | K9: ='Crawley Receipts'!F85 -> 4.3833333 | L9: 43 | O9: =IFERROR((K9+M9)/(L9+N9),0) -> 0.10193798 | P9: =O9*F9 -> 17.329457
A10: Peas | B10: 6.5 | F10: =B10+D10+C10/8+E10/8 -> 6.5 | G10: 3 | H10: 1 | I10: =G10+H10/8 -> 3.125 | J10: =F10-I10 -> 3.375 | K10: ='Crawley Receipts'!F86 -> 0.46875 | L10: =I10 -> 3.125 | O10: =IFERROR((K10+M10)/(L10+N10),0) -> 0.15 | P10: =O10*F10 -> 0.975
A11: Vetches | B11: 7 | C11: 6 | F11: =B11+D11+C11/8+E11/8 -> 7.75 | G11: 4.5 | I11: =G11+H11/8 -> 4.5 | J11: =F11-I11 -> 3.25 | K11: ='Crawley Receipts'!F87 -> 0.45 | L11: 4.5 | O11: =IFERROR((K11+M11)/(L11+N11),0) -> 0.1 | P11: =O11*F11 -> 0.775
A13: Total Production | F13: =SUM(F5:F11) -> 355.4375 | P13: =SUM(P5:P11) -> 58.341652 | Q13: Production value is significantly more, as much less was sold than what was produced
A14: Sales of corn (as recorded in accounts) | F14: =SUM(I5:I11) -> 124.9375 | P14: =SUM(K5:K11,M5:M11) -> 23.983333
A17: Net output | B17: Gross output | C17: Seed | F17: tithe | G17: to manorial servants & livestock | J17: Output net of tithe & seed & liveries to manorial servants | K17: in stock from last year | L17: Price | M17: Value of net output | N17: Value of sales (in "Sale of Corn")
B18: qrs | C18: qrs | D18: bus | E18: qrs | F18: qrs | G18: qrs | H18: bus | I18: qrs | J18: qrs | K18: qrs | L18: £ per qr | M18: £ | N18: £
A19: Net wheat | B19: =F5 -> 59.5 | C19: 16 | D19: 5 | E19: =C19+D19/8 -> 16.625 | G19: 2 | H19: 7 | I19: =G19+H19/8 -> 2.875 | J19: =B19-(E19+F19+I19) -> 40 | L19: =O5 -> 0.29770833 | M19: =L19*J19 -> 11.908333 | N19: =O5*I5 -> 11.908333
A20: Net curall | B20: =F6 -> 12.0625 | E20: =C20+D20/8 -> 0 | I20: =G20+H20/8 -> 0 | J20: =B20-(E20+F20+I20) -> 12.0625 | L20: =O6 -> 0.18877375 | M20: =L20*J20 -> 2.2770833 | N20: =O6*I6 -> 2.2770833
A21: Net Bere | B21: =F7 -> 4.25 | E21: =C21+D21/8 -> 0 | G21: 4 | H21: 2 | I21: =G21+H21/8 -> 4.25 | J21: =B21-(E21+F21+I21) -> 0 | L21: =O7 -> 0 | M21: =L21*J21 -> 0 | N21: =O7*I7 -> 0
A22: Net barley | B22: =F8 -> 95.375 | C22: 43 | D22: 2 | E22: =C22+D22/8 -> 43.25 | G22: =19.5+0.5+2+3+2+0.5 -> 27.5 | H22: =6.5+6+7 -> 19.5 | I22: =G22+H22/8 -> 29.9375 | J22: =B22-(E22+F22+I22) -> 22.1875 | L22: =O8 -> 0.20205993 | M22: =L22*J22 -> 4.4832046 | N22: =O8*I8 -> 4.4958333
A23: Net oats | B23: =F9 -> 170 | C23: 83 | D23: 3 | E23: =C23+D23/8 -> 83.375 | G23: =6+4+12+20 -> 42 | H23: =6+2+5 -> 13 | I23: =G23+H23/8 -> 43.625 | J23: =B23-(E23+F23+I23) -> 43 | L23: =O9 -> 0.10193798 | M23: =L23*J23 -> 4.3833333 | N23: =O9*I9 -> 4.3833333
A24: Net peas | B24: =F10 -> 6.5 | C24: 3 | E24: =C24+D24/8 -> 3 | H24: 3 | I24: =G24+H24/8 -> 0.375 | J24: =B24-(E24+F24+I24) -> 3.125 | L24: =O10 -> 0.15 | M24: =L24*J24 -> 0.46875 | N24: =O10*I10 -> 0.46875
A25: Net vetches | B25: =F11 -> 7.75 | C25: 3 | D25: 2 | E25: =C25+D25/8 -> 3.25 | I25: =G25+H25/8 -> 0 | J25: =B25-(E25+F25+I25) -> 4.5 | L25: =O11 -> 0.1 | M25: =L25*J25 -> 0.45 | N25: =O11*I11 -> 0.45
A26: Total | B26: =SUM(B19:B25) -> 355.4375 | E26: =SUM(E19:E25) -> 149.5 | J26: =SUM(J19:J25) -> 124.875 | M26: =SUM(M19:M25) -> 23.970705 | N26: =SUM(N19:N25) -> 23.983333

Sheet Stock
A1: EAST KNOYLE STOCK ACCOUNT
A3: Livestock | B3: Inherited stock | C3: Bought | D3: Produced | E3: strays | F3: herbage | G3: sold | H3: in murrain | I3: accounted for elsewhere | J3: End-period stock | K3: cross-check | L3: price 1 | M3: units 1 | N3: price 2 | O3: units 2 | P3: Weight (weys) | Q3: Unit price (£) | R3: Value of production (£) at sales prices | S3: Sales in (£) | T3: Details
A4: Cart-horses | B4: 2 | J4: 2 | K4: =B4+C4+D4+E4-F4-G4-H4-I4 -> 2 | Q4: =IFERROR((L4+N4)/(M4+O4),"") | R4: =IFERROR(D4*Q4,"") | S4: =IFERROR(Q4*G4,"")
A5: Mares | K5: =B5+C5+D5+E5-F5-G5-H5-I5 -> 0 | Q5: =IFERROR((L5+N5)/(M5+O5),"") | R5: =IFERROR(D5*Q5,"") | S5: =IFERROR(Q5*G5,"")
A6: Plough horses | B6: 5 | C6: 1 | D6: 1 | H6: 1 | J6: 6 | K6: =B6+C6+D6+E6-F6-G6-H6-I6 -> 6 | Q6: =IFERROR((L6+N6)/(M6+O6),"") | R6: =IFERROR(D6*Q6,"") | S6: =IFERROR(Q6*G6,"")
A7: Colts (2 years) | K7: =B7+C7+D7+E7-F7-G7-H7-I7 -> 0 | Q7: =IFERROR((L7+N7)/(M7+O7),"") | R7: =IFERROR(D7*Q7,"") | S7: =IFERROR(Q7*G7,"")
A8: Colts (2 years) | K8: =B8+C8+D8+E8-F8-G8-H8-I8 -> 0 | Q8: =IFERROR((L8+N8)/(M8+O8),"") | R8: =IFERROR(D8*Q8,"") | S8: =IFERROR(Q8*G8,"")
A9: Colts (1 year) | K9: =B9+C9+D9+E9-F9-G9-H9-I9 -> 0 | Q9: =IFERROR((L9+N9)/(M9+O9),"") | R9: =IFERROR(D9*Q9,"") | S9: =IFERROR(Q9*G9,"")
A10: Foals | K10: =B10+C10+D10+E10-F10-G10-H10-I10 -> 0 | Q10: =IFERROR((L10+N10)/(M10+O10),"") | R10: =IFERROR(D10*Q10,"") | S10: =IFERROR(Q10*G10,"")
A11: Oxen | B11: 30 | C11: 5 | D11: 1 | E11: 1 | H11: 2 | J11: 35 | K11: =B11+C11+D11+E11-F11-G11-H11-I11 -> 35 | Q11: =IFERROR((L11+N11)/(M11+O11),"") | R11: =IFERROR(D11*Q11,"") | S11: =IFERROR(Q11*G11,"")
A12: Bulls | B12: 1 | J12: 1 | K12: =B12+C12+D12+E12-F12-G12-H12-I12 -> 1 | Q12: =IFERROR((L12+N12)/(M12+O12),"") | R12: =IFERROR(D12*Q12,"") | S12: =IFERROR(Q12*G12,"")
A13: Cows | B13: 17 | D13: 2 | J13: 19 | K13: =B13+C13+D13+E13-F13-G13-H13-I13 -> 19 | Q13: =IFERROR((L13+N13)/(M13+O13),"") | R13: =IFERROR(D13*Q13,"") | S13: =IFERROR(Q13*G13,"")
A14: Steers | B14: 4 | H14: 1 | I14: 3 | J14: 0 | K14: =B14+C14+D14+E14-F14-G14-H14-I14 -> 0 | Q14: =IFERROR((L14+N14)/(M14+O14),"") | R14: =IFERROR(D14*Q14,"") | S14: =IFERROR(Q14*G14,"")
A15: Bullocks | B15: 5 | H15: 1 | J15: 4 | K15: =B15+C15+D15+E15-F15-G15-H15-I15 -> 4 | Q15: =IFERROR((L15+N15)/(M15+O15),"") | R15: =IFERROR(D15*Q15,"") | S15: =IFERROR(Q15*G15,"")
A16: Yearlings | B16: 6 | H16: 1 | J16: 5 | K16: =B16+C16+D16+E16-F16-G16-H16-I16 -> 5 | Q16: =IFERROR((L16+N16)/(M16+O16),"") | R16: =IFERROR(D16*Q16,"") | S16: =IFERROR(Q16*G16,"")
A17: Calves | D17: 13 | G17: 5 | H17: 1 | I17: 1 | J17: 6 | K17: =B17+C17+D17+E17-F17-G17-H17-I17 -> 6 | L17: ='Crawley Receipts'!F54 -> 0.25 | M17: 5 | Q17: =IFERROR((L17+N17)/(M17+O17),"") -> 0.05 | R17: =IFERROR(D17*Q17,"") -> 0.65 | S17: =IFERROR(Q17*G17,"") -> 0.25
A18: Wethers | B18: 383 | D18: 132 | G18: 47 | H18: 35 | J18: 433 | K18: =B18+C18+D18+E18-F18-G18-H18-I18 -> 433 | L18: ='Crawley Receipts'!F55 -> 2.7416667 | M18: 47 | Q18: =IFERROR((L18+N18)/(M18+O18),"") -> 0.058333333 | R18: =IFERROR(D18*Q18,"") -> 7.7 | S18: =IFERROR(Q18*G18,"") -> 2.7416667
A19: Rams | K19: =B19+C19+D19+E19-F19-G19-H19-I19 -> 0 | Q19: =IFERROR((L19+N19)/(M19+O19),"") | R19: =IFERROR(D19*Q19,"") | S19: =IFERROR(Q19*G19,"")
A20: Ewes | B20: 536 | D20: 131 | G20: 55 | H20: 37 | J20: 575 | K20: =B20+C20+D20+E20-F20-G20-H20-I20 -> 575 | L20: ='Crawley Receipts'!F56 -> 2.2916667 | M20: 55 | Q20: =IFERROR((L20+N20)/(M20+O20),"") -> 0.041666667 | R20: =IFERROR(D20*Q20,"") -> 5.4583333 | S20: =IFERROR(Q20*G20,"") -> 2.2916667
A21: Hoggs | B21: 286 | H21: 23 | I21: 263 | J21: 0 | K21: =B21+C21+D21+E21-F21-G21-H21-I21 -> 0 | Q21: =IFERROR((L21+N21)/(M21+O21),"") | R21: =IFERROR(D21*Q21,"") | S21: =IFERROR(Q21*G21,"")
A22: Lambs | D22: 392 | H22: 88 | I22: 36 | J22: 268 | K22: =B22+C22+D22+E22-F22-G22-H22-I22 -> 268 | Q22: =IFERROR((L22+N22)/(M22+O22),"") | R22: =IFERROR(D22*Q22,"") | S22: =IFERROR(Q22*G22,"") | T22: Accounted for elsewhere is tithe
A23: Boars | B23: 1 | J23: 1 | K23: =B23+C23+D23+E23-F23-G23-H23-I23 -> 1 | Q23: =IFERROR((L23+N23)/(M23+O23),"") | R23: =IFERROR(D23*Q23,"") | S23: =IFERROR(Q23*G23,"")
A24: Sows | K24: =B24+C24+D24+E24-F24-G24-H24-I24 -> 0 | Q24: =IFERROR((L24+N24)/(M24+O24),"") | R24: =IFERROR(D24*Q24,"") | S24: =IFERROR(Q24*G24,"")
A25: Pigs | B25: 27 | D25: 29 | G25: 26 | J25: 30 | K25: =B25+C25+D25+E25-F25-G25-H25-I25 -> 30 | L25: ='Crawley Receipts'!F57 -> 3.3666667 | M25: 26 | Q25: =IFERROR((L25+N25)/(M25+O25),"") -> 0.12948718 | R25: =IFERROR(D25*Q25,"") -> 3.7551282 | S25: =IFERROR(Q25*G25,"") -> 3.3666667
A26: Hoggets | B26: 29 | I26: 29 | J26: 0 | K26: =B26+C26+D26+E26-F26-G26-H26-I26 -> 0 | Q26: =IFERROR((L26+N26)/(M26+O26),"") | R26: =IFERROR(D26*Q26,"") | S26: =IFERROR(Q26*G26,"")
A27: Piglets | D27: 32 | E27: 2 | H27: 8 | I27: 3 | J27: 23 | K27: =B27+C27+D27+E27-F27-G27-H27-I27 -> 23 | Q27: =IFERROR((L27+N27)/(M27+O27),"") | R27: =IFERROR(D27*Q27,"") | S27: =IFERROR(Q27*G27,"") | T27: Accounted for elsewhere is tithe
A28: Swans | K28: =B28+C28+D28+E28-F28-G28-H28-I28 -> 0 | Q28: =IFERROR((L28+N28)/(M28+O28),"") | R28: =IFERROR(D28*Q28,"") | S28: =IFERROR(Q28*G28,"")
A29: Peacocks | K29: =B29+C29+D29+E29-F29-G29-H29-I29 -> 0 | Q29: =IFERROR((L29+N29)/(M29+O29),"") | R29: =IFERROR(D29*Q29,"") | S29: =IFERROR(Q29*G29,"")
A30: Total | S30: =SUM(S4:S29) -> 8.65
K31: =B31+C31+D31+E31-F31-G31-H31-I31 -> 0 | Q31: =IFERROR((L31+N31)/(M31+O31),"") | R31: =IFERROR(D31*Q31,"") | S31: =IFERROR(Q31*G31,"")
K32: =B32+C32+D32+E32-F32-G32-H32-I32 -> 0 | Q32: =IFERROR((L32+N32)/(M32+O32),"") | R32: =IFERROR(D32*Q32,"") | S32: =IFERROR(Q32*G32,"")
A33: Wool | K33: =B33+C33+D33+E33-F33-G33-H33-I33 -> 0 | Q33: =IFERROR((L33+N33)/(M33+O33),"") | R33: =IFERROR(D33*Q33,"") | S33: =IFERROR(Q33*G33,"")
A34: Fleeces | K34: =B34+C34+D34+E34-F34-G34-H34-I34 -> 0 | Q34: =IFERROR((L34+N34)/(M34+O34),"") | R34: =IFERROR(D34*Q34,"") | S34: =IFERROR(Q34*G34,"")
A35: Coarse wool | D35: 1035 | G35: 929 | I35: 106 | J35: 0 | K35: =B35+C35+D35+E35-F35-G35-H35-I35 -> 0 | L35: 0 | P35: =6.5+3*0.04 -> 6.62 | Q35: 0.02 | R35: =IFERROR(D35*Q35,"") -> 20.7 | S35: =IFERROR(Q35*G35,"") -> 18.58 | T35: unit price from overview sheet (UnitPricesStocks_averages)
A36: Lamb's wool | D36: 283 | G36: 283 | J36: 0 | K36: =B36+C36+D36+E36-F36-G36-H36-I36 -> 0 | L36: 0 | P36: =15*0.04 -> 0.6 | Q36: 0.01 | R36: =IFERROR(D36*Q36,"") -> 2.83 | S36: =IFERROR(Q36*G36,"") -> 2.83 | T36: unit price from overview sheet (UnitPricesStocks_averages)
A37: Wool locks | D37: =5*0.04 -> 0.2 | G37: =5*0.04 -> 0.2 | K37: =B37+C37+D37+E37-F37-G37-H37-I37 -> 0 | L37: ='Crawley Receipts'!F76 -> 0.21875 | M37: =5*0.04 -> 0.2 | P37: =5*0.04 -> 0.2 | Q37: =IFERROR((L37+N37)/(M37+O37),"") -> 1.09375 | R37: =IFERROR(D37*Q37,"") -> 0.21875 | S37: =IFERROR(Q37*G37,"") -> 0.21875
A38: Wool sold at shearing | K38: =B38+C38+D38+E38-F38-G38-H38-I38 -> 0 | Q38: =IFERROR((L38+N38)/(M38+O38),"") | R38: =IFERROR(D38*Q38,"") | S38: =IFERROR(Q38*G38,"")
A39: Total | K39: =B39+C39+D39+E39-F39-G39-H39-I39 -> 0 | Q39: =IFERROR((L39+N39)/(M39+O39),"") | R39: =IFERROR(D39*Q39,"") | S39: =SUM(S35:S38) -> 21.62875
K40: =B40+C40+D40+E40-F40-G40-H40-I40 -> 0 | Q40: =IFERROR((L40+N40)/(M40+O40),"") | R40: =IFERROR(D40*Q40,"") | S40: =IFERROR(Q40*G40,"")
K41: =B41+C41+D41+E41-F41-G41-H41-I41 -> 0 | Q41: =IFERROR((L41+N41)/(M41+O41),"") | R41: =IFERROR(D41*Q41,"") | S41: =IFERROR(Q41*G41,"")
...

Sheet Assumptions
A1: ASSUMPTIONS
B3: Weights | C3: Value (in lbs) | D3: Value (in cloves) | E3: Value (in weys) | F3: Value (in stone)
B4: Lbs | C4: 1 | D4: =C4/C5 -> 0.14285714 | E4: =C4/C6 -> 0.0057142857 | F4: =C4/C7 -> 0.08
B5: Cloves | C5: 7 | D5: 1 | E5: =C5/C6 -> 0.04 | F5: =C7/C5 -> 1.7857143
B6: Wey | C6: 175 | D6: =C6/C5 -> 25 | E6: =C6/C6 -> 1 | F6: =C7/C6 -> 0.071428571
B7: Stone | C7: =175/14 -> 12.5 | D7: =C5/C7 -> 0.56 | E7: =C7/C6 -> 0.071428571 | F7: 1
