Workbook

Sheet Overview
A1: HARWELL | B1: Total in £ | C1: Error | D1: Note
A2: CASH ACCOUNT
A3: RECEIPTS
A4: Arrears total
A5: Rents of assize total
A6: Quittances total
A7: Defaults of rent total
A8: Defaults of rent through the pestilence total
A9: Cotlands defaults total
A10: Cotlands total
A11: Total of quittances and defaults of rent total
A12: Total of rents remaining clear total
A13: Farms total
... A22: Farm of the demesne land total
A23: Total of all receipts (calculated here) | B23: =Receipts!F70 -> 52.814167
A24: Total of all receipts (calculated here) incl arrears | B24: =Receipts!F71 -> 79.984167
A25: Total recorded in the accounts excl. arrears | D25: no total given in accounts
A26: Total recorded in the accounts incl. arrears
A29: EXPENSES
A30: Cost of ploughs total
A31: Purchase of corn total
A32: Cost of carts and wagons total
A33: Cost of dairy total
A34: Purchase of stock total
A35: Sheepcote total
A36: Cost of buildings total
A37: Threshing total
A38: Barley expenses
A39: Expenses of the harvest total
... A43: Annual fees
A44: Total of all expenses per account | B44: =Expenses!F112 -> 14.29
A45: Total of all expenses (calculated here) | B45: =Expenses!F113 -> 14.073958
A46: Total fixed investment | B46: =Expenses!F114 -> 3.3554167
A47: Total Demesne fixed investment | B47: =Expenses!F115 -> 3.0304167
A49: Owed by the reeve
A50: From accounts
A52: Allowances
A53: Cash deliveries
A54: Sum of the above
A55: Total of all allowances and cash deliveries in accounts
...

Sheet Receipts
A1: HARWELL RECEIPTS
A2: Heading | B2: £ | C2: s | D2: d | F2: Total in £ | G2: Error | H2: Notes | I2: Own notes
A3: Arrears | B3: 27 | C3: 3 | D3: 6 | F3: 27.17 | H3: Roginald de Lynham, bailiff, and John Leyrmonger', reeve, render account for £27 3 shilling 6pence of arrears from the last account.
A4: Arrears | B4: 27 | C4: 3 | D4: 6 | F4: 27.17 | H4: Delivered to Sir Geoffrey, treasurer of Wolvesey, £27 3 shilling 6pence by 1 tally.
A5: Arrears | B5: 0 | C5: 0 | D5: 0 | F5: 0 | H5: They are quit.
A6: Arrears | F6: 27.17 | G6: =F6-F4 -> 0 | H6: Total
A8: Rents of assize | B8: 16 | C8: 12 | D8: 6 | F8: 16.62 | H8: The same render account for £16 12 shilling 6pence for rents of assize for the whole year at Michaelmas (29 September).
A9: Rents of assize | B9: 16 | C9: 12 | D9: 6 | F9: 16.62 | H9: Total, £16 12 shilling 6pence
A10: Rents of assize | F10: 16.62 | G10: 0 | H10: Total
A12: Quittances | B12: 0 | C12: 5 | D12: 0 | F12: 0.25 | H12: In quittance of 1 reeve for the year 5 shilling.
A13: Quittances | B13: 0 | C13: 12 | D13: 0 | F13: 0.6 | H13: 4 ploughmen for the year 12 shilling, or 3 shilling each.
A14: Quittances | B14: 0 | C14: 17 | D14: 0 | F14: 0.85 | H14: Total, 17 shilling
A15: Quittances | F15: 0.85 | G15: 0 | H15: Total
A17: Defaults of rent | B17: 0 | C17: 3 | D17: 0 | F17: 0.15 | H17: In default of the rent of 1 croft which Roger Gunth' held drawn into demesne 3 shilling
A18: Defaults of rent | B18: 0 | C18: 3 | D18: 0 | F18: 0.15 | H18: Total, 3 shilling
A19: Defaults of rent | F19: 0.15 | G19: 0 | H19: Total
A21: Total of quittances and defaults of rent | B21: 1 | C21: 0 | D21: 0 | F21: 1 | H21: Total of quittances and defaults of rent, £1.
A22: Total of quittances and defaults of rent | F22: 1 | G22: =F22-F21 -> 0 | H22: Total
A24: Total of rents remaining | B24: 15 | C24: 12 | D24: 6 | F24: 15.62 | H24: Total of rents remaining, £15 12 shilling 6pence
A25: Total of rents remaining | F25: 15.62 | G25: =F25-F24 -> 0 | H25: Total
A27: Annual recognizance | B27: 0 | C27: 0 | D27: 6 | F27: 0.03 | H27: The same render account for 6pence from Walter, son of Walter Edward, for annual recognizance.
A28: Annual recognizance | B28: 0 | C28: 0 | D28: 6 | F28: 0.03 | H28: 6pence from Thomas in Angle so that he may remain where he pleases, and nonetheless pay suit for his tithing and pay tithingpenny.
A29: Annual recognizance | B29: 0 | C29: 1 | D29: 0 | F29: 0.05 | H29: Total, 1 shilling
A30: Annual recognizance | F30: 0.06 | G30: 0.01 | H30: Total
A32: Issues of the manor | B32: 0 | C32: 7 | D32: 4 | F32: 0.37 | H32: The same render account for 7 shilling 4pence from pannage of pigs at Martinmas (11 November).
A33: Issues of the manor | B33: 0 | C33: 5 | D33: 5 | F33: 0.27 | H33: 5 shilling 5pence from tolls on inns.
A34: Issues of the manor | B34: 0 | C34: 5 | D34: 0 | F34: 0.25 | H34: 5 shilling from winter pasturage sold.
A35: Issues of the manor | B35: 0 | C35: 5 | D35: 6 | F35: 0.28 | H35: 5 shilling 6pence from 66 cocks and hens from churchscot at Martinmas.
A36: Issues of the manor | B36: 0 | C36: 1 | D36: 3 | F36: 0.06 | H36: 1 shilling 3pence from the heriot of John Miles for 1.5 virgates of land which he held of the lord, and note that noone will give more for 0.5 virgate for a heriot even if he has 1 beast.
A37: Issues of the manor | B37: 0 | C37: 4 | D37: 0 | F37: 0.2 | H37: 4 shilling from the herbage in the garden sold.
A38: Issues of the manor | B38: 0 | C38: 8 | D38: 0 | F38: 0.4 | H38: 8 shilling from 1 feeble cart-horse sold.
A39: Issues of the manor | B39: 1 | C39: 17 | D39: 0 | F39: 1.85 | H39: £1 17 shilling from 1 cart-horse sold.
A40: Issues of the manor | B40: 1 | C40: 7 | D40: 0 | F40: =B40+C40/20+D40/240 -> 1.35 | H40: £1 7shilling 6pence from 2 horses from the heriot of John Miles for 2 virgates of land which he held of the bishop sold to the relict of the same John.
A41: Issues of the manor | B41: 0 | C41: 8 | D41: 0 | F41: 0.4 | H41: 8 shilling from 1 ox sold to Richard Tockesmal because rotten.
A42: Issues of the manor | B42: 0 | C42: 7 | D42: 0 | F42: 0.35 | H42: 7 shilling from 1 sterile cow from the heriot of Walter Roed sold.
A43: Issues of the manor | B43: 0 | C43: 6 | D43: 0 | F43: 0.3 | H43: 6 shilling from 2 pigs sold.
A44: Issues of the manor | B44: 0 | C44: 1 | D44: 6 | F44: 0.08 | H44: 1 shilling 6pence from stubble sold.
A45: Issues of the manor | B45: 0 | C45: 0 | D45: 1 | F45: =B45+C45/20+D45/240 -> 0.0041666667 | H45: 1 pence from the tail of 1 peacock sold
A46: Issues of the manor | B46: 6 | C46: 3 | D46: 7 | F46: 6.18 | H46: Total, £6 3 shilling 7pence
A47: Issues of the manor | F47: =SUM(F32:F45) -> 6.1641667 | G47: =F47-F46 -> -0.015833333 | H47: Total
...

Sheet Expenses
A1: HARWELL EXPENSES
A2: Heading | B2: £ | C2: s | D2: d | F2: Total in £ | G2: Error | H2: Notes | I2: Own notes | K2: Fixed investment | L2: Demesne fixed investment
A3: Cost of ploughs | B3: 0 | C3: 3 | D3: 7.5 | F3: 0.18 | H3: In 4 pieces of steel bought for 3 ploughs for the year 3 shilling 7.5pence. | K3: =F3 -> 0.18 | L3: =K3 -> 0.18
A4: Cost of ploughs | B4: 0 | C4: 3 | D4: 2 | F4: 0.16 | H4: stipend of the smith forging the said steel for the said ploughs 3 shilling 2pence. | K4: =F4 -> 0.16 | L4: =K4/2 -> 0.08
A5: Cost of ploughs | B5: 0 | C5: 0 | D5: 6 | F5: 0.03 | H5: stipend of the smith repairing the said ploughs with the demesne's iron 6pence. | K5: =F5 -> 0.03 | L5: =K5 -> 0.03
A6: Cost of ploughs | B6: 0 | C6: 2 | D6: 0 | F6: 0.1 | H6: 5 ploughs made anew, 3 of them for winter, and other old ploughs mended 2 shilling. | K6: =F6 -> 0.1 | L6: =K6/2 -> 0.05
A7: Cost of ploughs | B7: 0 | C7: 0 | D7: 6 | F7: 0.03 | H7: hooping 3 ploughs around the holes for the coulters with the demesne's iron 6pence. | K7: =F7 -> 0.03 | L7: =K7 -> 0.03
A8: Cost of ploughs | B8: 0 | C8: 2 | D8: 10 | F8: 0.14 | H8: 1 ploughshare and 2 coulters bought new for the ploughs with repairs to the same 2 shilling 10pence. | K8: =F8 -> 0.14 | L8: =K8/2 -> 0.07
A9: Cost of ploughs | B9: 0 | C9: 0 | D9: 9 | F9: 0.04 | H9: 4 ox-yokes bought 9pence. | K9: =F9 -> 0.04 | L9: =K9 -> 0.04
A10: Cost of ploughs | B10: 0 | C10: 0 | D10: 11 | F10: 0.05 | H10: 15 ox-bows bought for the same 11pence. | K10: =F10 -> 0.05 | L10: =K10/2 -> 0.025
A11: Cost of ploughs | B11: 0 | C11: 0 | D11: 4 | F11: 0.02 | H11: 2 plough feet bought for ploughs 4pence. | K11: =F11 -> 0.02 | L11: =K11 -> 0.02
A12: Cost of ploughs | B12: 0 | C12: 0 | D12: 4 | F12: 0.02 | H12: 2 wheels bought for the same 4pence. | K12: =F12 -> 0.02 | L12: =K12/2 -> 0.01
A13: Cost of ploughs | B13: 0 | C13: 1 | D13: 1 | F13: 0.05 | H13: oak withies bought for ploughs, for making the draught-chains (hart') therefrom, 1 shilling 1 pence. | K13: =F13 -> 0.05 | L13: =K13 -> 0.05
A14: Cost of ploughs | B14: 0 | C14: 0 | D14: 5 | F14: 0.02 | H14: 1 wheelbarrow bought 5pence. | K14: =F14 -> 0.02 | L14: =K14/2 -> 0.01
A15: Cost of ploughs | B15: 0 | C15: 0 | D15: 2 | F15: 0.01 | H15: fitting 1 plough with a share-beam together with buying the share-beam 2pence. | K15: =F15 -> 0.01 | L15: =K15 -> 0.01
A16: Cost of ploughs | B16: 0 | C16: 6 | D16: 10 | F16: 0.34 | H16: customary payment to 1 reeve and 4 ploughmen for their corrodies at Christmas and Easter 10pence Paid to 2 ploughmen and 1 carter for their pease pottage for the year 6 shilling 6pence, or .5pence each a week.
A17: Cost of ploughs | B17: 0 | C17: 14 | D17: 0 | F17: =B17+C17/20+D17/240 -> 0.7 | H17: 1 ox bought for ploughs 14 shilling
A18: Cost of ploughs | B18: 1 | C18: 17 | D18: 11.5 | F18: 1.9 | H18: Total, £1 17 shilling 11.5pence
A19: Cost of ploughs | F19: =SUM(F3:F17) -> 1.89 | G19: =F19-F18 -> -0.01 | H19: Total
A21: Cost of carts, wains and ironwork | B21: 1 | C21: 4 | D21: 0 | F21: 1.2 | H21: In 1 cart-horse bought £1 4 shilling.
A22: Cost of carts, wains and ironwork | B22: 1 | C22: 6 | D22: 0 | F22: 1.3 | H22: 1 cart-horse bought at Abingdon £1 6 shilling.
A23: Cost of carts, wains and ironwork | B23: 0 | C23: 2 | D23: 5.25 | F23: 0.12 | H23: 1 pair of new wheels bought for clearing dung 2 shilling 5.25pence. | K23: =F23 -> 0.12 | L23: =K23 -> 0.12
A24: Cost of carts, wains and ironwork | B24: 0 | C24: 0 | D24: 10.75 | F24: 0.04 | H24: 1 new cart saddle with 1 pair of new saddle-pads bought 10.75pence. | K24: =F24 -> 0.04 | L24: =K24 -> 0.04
A25: Cost of carts, wains and ironwork | B25: 0 | C25: 1 | D25: 4 | F25: 0.07 | H25: 2 new horse-collars bought 1 shilling 4pence. | K25: =F25 -> 0.07 | L25: =K25 -> 0.07
A26: Cost of carts, wains and ironwork | B26: 0 | C26: 0 | D26: 10 | F26: 0.04 | H26: clouts, nails, grease, and fitting the cart with axles at various times, 10pence. | K26: =F26 -> 0.04 | L26: =K26 -> 0.04
A27: Cost of carts, wains and ironwork | B27: 0 | C27: 0 | D27: 3 | F27: 0.01 | H27: white leather bought for harnesses 3pence. | K27: =F27 -> 0.01 | L27: =K27 -> 0.01
A28: Cost of carts, wains and ironwork | B28: 0 | C28: 0 | D28: 2 | F28: 0.01 | H28: 1 hame bought 2pence. | K28: =F28 -> 0.01 | L28: =K28 -> 0.01
A29: Cost of carts, wains and ironwork | B29: 0 | C29: 0 | D29: 8 | F29: 0.03 | H29: 1 tumbrel for dung bought 8pence. | K29: =F29 -> 0.03 | L29: =K29 -> 0.03
A30: Cost of carts, wains and ironwork | B30: 0 | C30: 0 | D30: 3 | F30: 0.01 | H30: 1 leather halter bought 3pence. | K30: =F30 -> 0.01 | L30: =K30 -> 0.01
A31: Cost of carts, wains and ironwork | B31: 0 | C31: 1 | D31: 7 | F31: =B31+C31/20+D31/240 -> 0.079166667 | H31: shoeing 2 cart-horses for the year 1 shilling 7pence | K31: =F31 -> 0.079166667 | L31: =K31 -> 0.079166667
A32: Cost of carts, wains and ironwork | B32: 2 | C32: 18 | D32: 5 | F32: 2.92 | H32: Total, £2 18 shilling 5pence
A33: Cost of carts, wains and ironwork | F33: =SUM(F21:F31) -> 2.9091667 | G33: =F33-F32 -> -0.010833333 | H33: Total
A35: Cost of wagons | B35: 0 | C35: 7 | D35: 11 | F35: 0.4 | H35: In 2 pairs of wheels bought for wagons 7 shilling 11pence. | K35: =F35 -> 0.4 | L35: =F35 -> 0.4
A36: Cost of wagons | B36: 0 | C36: 0 | D36: 11 | F36: 0.05 | H36: clouts, nails, grease bought for wagons 11pence. | K36: =F36 -> 0.05 | L36: =F36 -> 0.05
A37: Cost of wagons | B37: 0 | C37: 0 | D37: 6 | F37: 0.03 | H37: fitting the said 2 wagons with axles 6pence. | K37: =F37 -> 0.03 | L37: =F37 -> 0.03
A38: Cost of wagons | B38: 0 | C38: 1 | D38: 0 | F38: =B38+C38/20+D38/240 -> 0.05 | H38: hiring 1 carpenter to repair the bodies of wagons and to make 8 new frets for the abovesaid wheels for 5 days 1 shilling | K38: =F38 -> 0.05 | L38: =F38 -> 0.05
A39: Cost of wagons | B39: 0 | C39: 10 | D39: 4 | F39: =B39+C39/20+D387249 -> 0.5 | H39: Total, 10 shilling 4pence
A40: Cost of wagons | F40: =SUM(F35:F38) -> 0.53 | G40: =F40-F39 -> 0.03 | H40: Total
A42: Small necessaries | B42: 0 | C42: 1 | D42: 4 | F42: 0.07 | H42: In 2 sacks bought for carrying corn 1 shilling 4pence. | K42: =F42 -> 0.07 | L42: =K42 -> 0.07
A43: Small necessaries | B43: 0 | C43: 2 | D43: 8 | F43: 0.13 | H43: 1 linen sheet for winnowing (bintheamine ventator') bought 2 shilling 8pence. | K43: =F43 -> 0.13 | L43: =K43 -> 0.13
...

Sheet Issues of the Grange
A1: Gross Output | B1: Total Quantity | C1: Account Total Quarters | D1: Bought in Total Quarters | E1: Received from churchscot | F1: Sold Total Quarters | G1: Difference Produced+Bought-Sold | H1: Weighted Average Price per Quarter | I1: Value of Total Production weighted
A2: wheat | B2: 95.875 | C2: 95.875 | D2: 0 | F2: 69.0625 | G2: =B2-F2 -> 26.8125 | H2: 0.28108597 | I2: =H2*B2 -> 26.949118
A3: barley | B3: 49.75 | C3: 49.75 | D3: 0 | F3: 15.0625 | G3: =B3-F3 -> 34.6875 | H3: 0.17482711 | I3: =H3*B3 -> 8.6976487
A4: dredge | B4: 54.625 | C4: 54.625 | D4: 0 | F4: 34.25 | G4: =B4-F4 -> 20.375 | H4: 0.15 | I4: =H4*B4 -> 8.19375
A5: vetches | B5: 4.375 | C5: 4.375 | D5: 0 | F5: 0.625 | G5: =B5-F5 -> 3.75 | H5: 0.05 | I5: =H5*B5 -> 0.21875
A6: beans | B6: 5.25 | C6: 0 | D6: 5.25 | I6: =H6*B6 -> 0
A8: Total Production | I8: =SUM(I2:I6) -> 44.059266
A9: Sales of corn (as recorded in accounts)
A12: Net output | B12: Gross output | C12: Seed quarters | D12: Seed bushels | E12: Seed total quarters | F12: tithe quarters | G12: tithe bushels | H12: tithe total | I12: manorial servants quarters | J12: manorial servants bushels | K12: manorial servants total quarters | L12: output net of tithe, seed, liveries | M12: in stock from last year | N12: Price in £ | O12: Value of net output in £ | P12: Value of sales (in "Sale of Corn") in £
A13: wheat | B13: =B2 -> 95.875 | C13: =23 -> 23 | D13: 5 | E13: =C13+D13/8 -> 23.625 | I13: =3 -> 3 | J13: =2 -> 2 | K13: =I13+J13/8 -> 3.25 | L13: =B13-E13-K13 -> 69 | N13: =H2 -> 0.28108597 | O13: =L13*N13 -> 19.394932
A14: barley | B14: =B3 -> 49.75 | C14: =12 -> 12 | D14: =7 -> 7 | E14: =C14+D14/8 -> 12.875 | I14: =3+15+3 -> 21 | J14: =2+3.5 -> 5.5 | K14: =I14+J14/8 -> 21.6875 | L14: =B14-E14-K14 -> 15.1875 | N14: =H3 -> 0.17482711 | O14: =L14*N14 -> 2.6551867
A15: dredge | B15: =B4 -> 54.625 | C15: 20 | D15: 3 | E15: =C15+D15/8 -> 20.375 | K15: =I15+J15/8 -> 0 | L15: =B15-E15-K15 -> 34.25 | N15: =H4 -> 0.15 | O15: =L15*N15 -> 5.1375
A16: vetches | B16: =B5 -> 4.375 | D16: 6 | E16: =C16+D16/8 -> 0.75 | I16: 3 | K16: =I16+J16/8 -> 3 | L16: =B16-E16-K16 -> 0.625 | N16: =H5 -> 0.05 | O16: =L16*N16 -> 0.03125
A17: beans | B17: =B6 -> 5.25 | C17: 3 | E17: =C17+D17/8 -> 3 | I17: 2 | J17: 2 | K17: =I17+J17/8 -> 2.25 | L17: =B17-E17-K17 -> 0 | N17: =H6 -> 0 | O17: =L17*N17 -> 0
A19: Total

Sheet Issues of the Mills

Sheet Stock
A1: HARWELL STOCK ACCOUNT
C3: added | G3: subtracted
A4: Livestock | B4: Inherited stock | C4: added | D4: strays | E4: herbage | F4: churchscot | G4: of which in default | H4: sold | I4: in murrain | J4: accounted for elsewhere | K4: End-period stock | L4: cross-check | M4: stock building | N4: raw production | O4: Unit price (£) | P4: Value of stock (£) at given value | Q4: Value of stock (£) at sales prices | R4: Sales in (£) | S4: Value of stock building (£) | T4: Value of production (£) at sales prices | U4: Details
A5: Cart-horses | B5: 2 | C5: =2+2 -> 4 | H5: 4 | K5: 2 | O5: =R5/H5 -> 0.9 | R5: =Receipts!F38+Receipts!F39+Receipts!F40 -> 3.6
A6: Mares
A7: Plough horses
A8: Colts (unspecified years)
A9: Colts (2 years)
A10: Colts (1 year)
A11: Foals
A12: Oxen | B12: 24 | C12: 1 | H12: 1 | K12: 24 | O12: =R12/H12 -> 0.4 | R12: =Receipts!F41 -> 0.4
A13: Bulls
A14: Cows | C14: 1 | H14: 1 | O14: =R14/H14 -> 0.35 | R14: =Receipts!F42 -> 0.35
A15: Steers
A16: Bullocks
A17: Yearlings
A18: Calves
A19: Wethers
A20: Rams
A21: Ewes
A22: Hoggs
A23: Lambs
A24: Boars
A25: Sows
A26: Pigs | C26: =3 -> 3 | H26: 2 | K26: 1 | O26: =R26/H26 -> 0.15 | R26: =Receipts!F43 -> 0.3
A27: Hoggets
A28: Piglets | C28: 8 | K28: 8
A29: Swans
A30: Peacocks | B30: 3 | I30: 1 | K30: 2 | R30: =Receipts!F45 -> 0.0041666667 | U30: sale of peacock feathers
A31: Total Value | R31: =SUM(R5:R30) -> 4.6541667
A34: Wool
A35: Coarse wool
A36: Lamb's wool
A37: Wool locks
A38: Wool sold at shearing
A39: Total wool
A42: Hides
A43: Ox hides
A44: Mare
A45: Steer
...

Sheet raw data
A1: Heading | B1: Sentence | C1: Total in Pounds | D1: Pounds | E1: Shillings | F1: Pence | G1: Corn | H1: Total Quarters Except 1 | I1: Total Bushels Except 1 | J1: Total Corn Cross-Check | K1: Total Corn Manorial Account | L1: Corn Quantity Error | M1: Quarters 1 | N1: Bushels 1 | O1: Quarters 2 | P1: Bushels 2 | Q1: Quarters 3 | R1: Bushels 3 | S1: Quarters 4 | T1: Bushels 4 | U1: shilling a quarter 1 | V1: pence a quarter 1 | W1: shilling a quarter 2 | X1: pence a quarter 2 | Y1: shilling a quarter 3 | Z1: pence a quarter 3 | AA1: shilling a quarter 4 | AB1: pence a quarter 4 | AC1: shilling a bushel 1 | AD1: pence a bushel 1 | AE1: shilling a bushel 2 | AF1: pence a bushel 2 | AG1: shilling a bushel 3 | AH1: pence a bushel 3 | AI1: shilling a bushel 4 | AJ1: pence a bushel 4
A2: Arrears | B2: Roginald de Lynham, bailiff, and John Leyrmonger', reeve, render account for £27 3 shilling 6pence of arrears from the last account. | C2: 27.17 | D2: 27 | E2: 3 | F2: 6 | H2: 0 | I2: 0 | J2: 0 | K2: 0 | L2: 0 | M2: 0 | N2: 0
A3: Arrears | B3: Delivered to Sir Geoffrey, treasurer of Wolvesey, £27 3 shilling 6pence by 1 tally. | C3: 27.17 | D3: 27 | E3: 3 | F3: 6 | H3: 0 | I3: 0 | J3: 0 | K3: 0 | L3: 0 | M3: 0 | N3: 0
A4: Arrears | B4: They are quit. | C4: 0 | D4: 0 | E4: 0 | F4: 0 | H4: 0 | I4: 0 | J4: 0 | K4: 0 | L4: 0 | M4: 0 | N4: 0
A5: Rents of assize | B5: The same render account for £16 12 shilling 6pence for rents of assize for the whole year at Michaelmas (29 September). | C5: 16.62 | D5: 16 | E5: 12 | F5: 6 | H5: 0 | I5: 0 | J5: 0 | K5: 0 | L5: 0 | M5: 0 | N5: 0
A6: Rents of assize | B6: Total, £16 12 shilling 6pence | C6: 16.62 | D6: 16 | E6: 12 | F6: 6 | H6: 0 | I6: 0 | J6: 0 | K6: 0 | L6: 0 | M6: 0 | N6: 0
A7: Quittances | B7: In quittance of 1 reeve for the year 5 shilling. | C7: 0.25 | D7: 0 | E7: 5 | F7: 0 | H7: 0 | I7: 0 | J7: 0 | K7: 0 | L7: 0 | M7: 0 | N7: 0
A8: Quittances | B8: 4 ploughmen for the year 12 shilling, or 3 shilling each. | C8: 0.6 | D8: 0 | E8: 12 | F8: 0 | H8: 0 | I8: 0 | J8: 0 | K8: 0 | L8: 0 | M8: 0 | N8: 0
A9: Quittances | B9: Total, 17 shilling | C9: 0.85 | D9: 0 | E9: 17 | F9: 0 | H9: 0 | I9: 0 | J9: 0 | K9: 0 | L9: 0 | M9: 0 | N9: 0
A10: Defaults of rent | B10: In default of the rent of 1 croft which Roger Gunth' held drawn into demesne 3 shilling Total, 3 shilling | C10: 0.15 | D10: 0 | E10: 3 | F10: 0 | H10: 0 | I10: 0 | J10: 0 | K10: 0 | L10: 0 | M10: 0 | N10: 0
A11: Total of quittances and defaults of rent | B11: Total of quittances and defaults of rent, £1. | C11: 1 | D11: 1 | E11: 0 | F11: 0 | H11: 0 | I11: 0 | J11: 0 | K11: 0 | L11: 0 | M11: 0 | N11: 0
A12: Total of rents remaining | B12: Total of rents remaining, £15 12 shilling 6pence | C12: 15.62 | D12: 15 | E12: 12 | F12: 6 | H12: 0 | I12: 0 | J12: 0 | K12: 0 | L12: 0 | M12: 0 | N12: 0
A13: Annual recognizance | B13: The same render account for 6pence from Walter, son of Walter Edward, for annual recognizance. | C13: 0.03 | D13: 0 | E13: 0 | F13: 6 | H13: 0 | I13: 0 | J13: 0 | K13: 0 | L13: 0 | M13: 0 | N13: 0
... A31: Farm | B31: Total, 13 shilling 4pence | C31: 0.67 | D31: 0 | E31: 13 | F31: 4 | H31: 0 | I31: 0 | J31: 0 | K31: 0 | L31: 0 | M31: 0 | N31: 0
A32: Sale of corn | B32: The same render account for £19 7 shilling 7.5pence from 68 quarters 7 bushels of wheat sold, at 5 shilling a quarters for 4 quarters, and 5 shilling 8pence a quarters for 64 quarters 7 bushels. | C32: 19.38 | D32: 19 | E32: 7 | F32: 7.5 | G32: wheat | H32: 68 | I32: 7 | J32: 68.875 | K32: 68.875 | L32: 0 | M32: 68 | N32: 7 | O32: 4 | P32: 0 | Q32: 64 | R32: 7 | U32: 5 | V32: 0 | W32: 5 | X32: 8
A33: Sale of corn | B33: £2 10 shilling 3.75pence from 14 quarters 3 bushels of barley sold, at 3 shilling 6pence a quarters. | C33: 2.52 | D33: 2 | E33: 10 | F33: 3.75 | G33: barley | H33: 14 | I33: 3 | J33: 14.375 | K33: 14.375 | L33: 0 | M33: 14 | N33: 3 | U33: 3 | V33: 6
A34: Sale of corn | B34: £4 12 shilling 3pence from 30 quarters 6 bushels of dredge sold, at 3 shilling a quarters. | C34: 4.61 | D34: 4 | E34: 12 | F34: 3 | H34: 30 | I34: 6 | J34: 30.75 | K34: 30.75 | L34: 0 | M34: 30 | N34: 6 | U34: 3 | V34: 0
A35: Sale of corn | B35: 7.5pence from 5 bushels of vetches sold, at 1.5pence a bushels. | C35: 0.03 | D35: 0 | E35: 0 | F35: 7.5 | G35: vetches | H35: 0 | I35: 5 | J35: 0.625 | K35: 0.625 | L35: 0 | M35: 0 | N35: 5 | AC35: 0 | AD35: 1.5
A36: Sale of corn | B36: 7.5pence from 1.5 bushels of wheat sold at the audit. | C36: 0.03 | D36: 0 | E36: 0 | F36: 7.5 | G36: wheat | H36: 0 | I36: 1.5 | J36: 0.1875 | K36: 0.1875 | L36: 0 | M36: 0 | N36: 1.5
A37: Sale of corn | B37: 2 shilling 4.25pence from 5.5 bushels of barley sold at the audit. | C37: 0.12 | D37: 0 | E37: 2 | F37: 4.25 | G37: barley | H37: 0 | I37: 5.5 | J37: 0.6875 | K37: 0.6875 | L37: 0 | M37: 0 | N37: 5.5
A38: Sale of corn | B38: 10 shilling 6pence from 3.5 quarters of dredge sold at the audit, at 3 shilling a quarters. | C38: 0.53 | D38: 0 | E38: 10 | F38: 6 | H38: 3.5 | I38: 0 | J38: 3.5 | K38: 3.5 | L38: 0 | M38: 3.5 | N38: 0 | U38: 3 | V38: 0
A39: Sale of corn | B39: Total, £27 4 shilling 4pence | C39: 27.22 | D39: 27 | E39: 4 | F39: 4 | H39: 0 | I39: 0 | J39: 0 | K39: 0 | L39: 0 | M39: 0 | N39: 0
A40: Entry and marriage finest | B40: The same render account for £1 6 shilling 8pence from all the tithings for tithingpenny at the 2 hundred-courts for the year. | C40: 1.33 | D40: 1 | E40: 6 | F40: 8 | H40: 0 | I40: 0 | J40: 0 | K40: 0 | L40: 0 | M40: 0 | N40: 0
A41: Entry and marriage finest | B41: 2 shilling from Christina le Rop for marrying Matilda her daughter outside. | C41: 0.1 | D41: 0 | E41: 2 | F41: 0 | H41: 0 | I41: 0 | J41: 0 | K41: 0 | L41: 0 | M41: 0 | N41: 0
A42: Entry and marriage finest | B42: £3 from John Bartelot to have Matilda, relict of Richard le Kyn2 with .5 virgate of her land. | C42: 3 | D42: 3 | E42: 0 | F42: 0 | H42: 0 | I42: 0 | J42: 0 | K42: 0 | L42: 0 | M42: 0 | N42: 0
A43: Entry and marriage finest | B43: 6 shilling 8pence from Richard Huscarl so that he may till the holding of Matilda de Hyb' until the arrival of the said Matilda in England if she should live. | C43: 0.33 | D43: 0 | E43: 6 | F43: 8 | H43: 0 | I43: 0 | J43: 0 | K43: 0 | L43: 0 | M43: 0 | N43: 0
A44: Entry and marriage finest | B44: 6 shilling 8pence from Roger le Ber' for marrying Matilda his daughter outside, because thus far he has not shown his feoffment. | C44: 0.33 | D44: 0 | E44: 6 | F44: 8 | H44: 0 | I44: 0 | J44: 0 | K44: 0 | L44: 0 | M44: 0 | N44: 0
A45: Entry and marriage finest | B45: Total, £5 2 shilling | C45: 5.1 | D45: 5 | E45: 2 | F45: 0 | H45: 0 | I45: 0 | J45: 0 | K45: 0 | L45: 0 | M45: 0 | N45: 0
A46: Perquisites | B46: The same render account for 4 shilling 9pence from the small amercements of the court held on the Saturday of Martinmas (11 November). | C46: 0.24 | D46: 0 | E46: 4 | F46: 9 | H46: 0 | I46: 0 | J46: 0 | K46: 0 | L46: 0 | M46: 0 | N46: 0
A47: Perquisites | B47: 11 shilling 2pence from the small amercements of the hundred-court of Martinmas held on Thursday the morrow of St Lucy the Virgin (14 December). | C47: 0.56 | D47: 0 | E47: 11 | F47: 2 | H47: 0 | I47: 0 | J47: 0 | K47: 0 | L47: 0 | M47: 0 | N47: 0
A48: Perquisites | B48: 5 shilling 9pence from the perquisites of the court held on Thursday after Epiphany (11 January). | C48: 0.29 | D48: 0 | E48: 5 | F48: 9 | H48: 0 | I48: 0 | J48: 0 | K48: 0 | L48: 0 | M48: 0 | N48: 0
A49: Perquisites | B49: 3 shilling 6pence from the perquisites of the court on Tuesday before the feast of St Peter's Chair (20 February). | C49: 0.17 | D49: 0 | E49: 3 | F49: 6 | H49: 0 | I49: 0 | J49: 0 | K49: 0 | L49: 0 | M49: 0 | N49: 0
A50: Perquisites | B50: 9 shilling 2pence from the perquisites of the court held on Tuesday before the feast of St Dunstan (15 May). | C50: 0.46 | D50: 0 | E50: 9 | F50: 2 | H50: 0 | I50: 0 | J50: 0 | K50: 0 | L50: 0 | M50: 0 | N50: 0
... A67: Cost of ploughs | B67: fitting 1 plough with a share-beam together with buying the share-beam 2pence. | C67: 0.01 | D67: 0 | E67: 0 | F67: 2 | H67: 0 | I67: 0 | J67: 0 | K67: 0 | L67: 0 | M67: 0 | N67: 0
A68: Cost of ploughs | B68: customary payment to 1 reeve and 4 ploughmen for their corrodies at Christmas and Easter 10pence Paid to 2 ploughmen and 1 carter for their pease pottage for the year 6 shilling 6pence, or .5pence each a week. | C68: 0.34 | D68: 0 | E68: 6 | F68: 10 | G68: peas | H68: 0 | I68: 0 | J68: 0 | K68: 0 | L68: 0 | M68: 0 | N68: 0
A69: Cost of ploughs | B69: . | C69: 0 | D69: 0 | E69: 0 | F69: 0 | H69: 0 | I69: 0 | J69: 0 | K69: 0 | L69: 0 | M69: 0 | N69: 0
A70: Cost of ploughs | B70: 1 ox bought for ploughs 14 shilling Total, £1 17 shilling 11.5pence | C70: 1.9 | D70: 1 | E70: 17 | F70: 11.5 | H70: 0 | I70: 0 | J70: 0 | K70: 0 | L70: 0 | M70: 0 | N70: 0
A71: Cost of carts, wains and ironwork | B71: In 1 cart-horse bought £1 4 shilling. | C71: 1.2 | D71: 1 | E71: 4 | F71: 0 | H71: 0 | I71: 0 | J71: 0 | K71: 0 | L71: 0 | M71: 0 | N71: 0
A72: Cost of carts, wains and ironwork | B72: 1 cart-horse bought at Abingdon £1 6 shilling. | C72: 1.3 | D72: 1 | E72: 6 | F72: 0 | H72: 0 | I72: 0 | J72: 0 | K72: 0 | L72: 0 | M72: 0 | N72: 0
A73: Cost of carts, wains and ironwork | B73: 1 pair of new wheels bought for clearing dung 2 shilling 5.25pence. | C73: 0.12 | D73: 0 | E73: 2 | F73: 5.25 | H73: 0 | I73: 0 | J73: 0 | K73: 0 | L73: 0 | M73: 0 | N73: 0
...

Sheet Issues of the Grange raw
A1: Heading | B1: Sentence | C1: Quarters 1_x | D1: Bushels 1_x | E1: Sown Quarters | F1: Sown Bushels | G1: Sown Total Quarters | H1: Bought in Quarters | I1: Bought in Bushels | J1: Bought in Total Quarters | K1: Tithe Quarters | L1: Tithe Bushels | M1: Tithe Total Quarters | N1: Manorial servants & livestock Quarters | O1: Manorial servants & livestock Bushels | P1: Manorial servants & livestock Total Quarters | Q1: Sold Quarters | R1: Sold Bushels | S1: Sold Total Quarters | T1: Account Quarters | U1: Account Bushels | V1: Account Total Quarters | W1: bought only | X1: Total Quarters Except 1 | Y1: Total Bushels Except 1 | Z1: Total Corn Cross-Check | AA1: Total Corn Manorial Account | AB1: Corn Quantity Error | AC1: Quarters 1_y | AD1: Bushels 1_y | AE1: Quarters 2 | AF1: Bushels 2 | AG1: Quarters 3 | AH1: Bushels 3 | AI1: Quarters 4 | AJ1: Bushels 4
A2: Cash deliveries | B2: Total | C2: 0 | D2: 0 | E2: 0 | F2: 0 | G2: 0 | H2: 0 | I2: 0 | J2: 0 | K2: 0 | L2: 0 | M2: 0 | N2: 0 | O2: 0 | P2: 0 | Q2: 0 | R2: 0 | S2: 0 | T2: 0 | U2: 0 | V2: 0 | W2: 0
A3: Wheat | B3: (yield: . . . less . . .) | C3: 0 | D3: 0 | E3: 0 | F3: 0 | G3: 0 | H3: 0 | I3: 0 | J3: 0 | K3: 0 | L3: 0 | M3: 0 | N3: 0 | O3: 0 | P3: 0 | Q3: 0 | R3: 0 | S3: 0 | T3: 0 | U3: 0 | V3: 0 | W3: 0 | X3: 0 | Y3: 0 | Z3: 0 | AA3: 0 | AB3: 0 | AC3: 0 | AD3: 0
A4: Wheat | B4: The same render account for 81 quarters 7 bushels of wheat from the whole issue of the grange by 3 tallies of struck measure, of which 57 quarters threshed by piece-work and 24 quarters 5 bushels by labour service. | C4: 0 | D4: 0 | E4: 0 | F4: 0 | G4: 0 | H4: 0 | I4: 0 | J4: 0 | K4: 0 | L4: 0 | M4: 0 | N4: 0 | O4: 0 | P4: 0 | Q4: 0 | R4: 0 | S4: 0 | T4: 162 | U4: 12 | V4: 163.5 | W4: 0 | X4: 81 | Y4: 5 | Z4: 81.625 | AA4: 81.875 | AB4: -0.25 | AC4: 81 | AD4: 7 | AE4: 57 | AF4: 0 | AG4: 24 | AH4: 5
A5: Wheat | B5: 14 quarters from churchscot at Martinmas. | C5: 0 | D5: 0 | E5: 0 | F5: 0 | G5: 0 | H5: 0 | I5: 0 | J5: 0 | K5: 0 | L5: 0 | M5: 0 | N5: 0 | O5: 0 | P5: 0 | Q5: 0 | R5: 0 | S5: 0 | T5: 0 | U5: 0 | V5: 0 | W5: 0 | X5: 14 | Y5: 0 | Z5: 14 | AA5: 14 | AB5: 0 | AC5: 14 | AD5: 0
A6: Wheat | B6: Total, 95 quarters 7 bushels | C6: 0 | D6: 0 | E6: 0 | F6: 0 | G6: 0 | H6: 0 | I6: 0 | J6: 0 | K6: 0 | L6: 0 | M6: 0 | N6: 0 | O6: 0 | P6: 0 | Q6: 0 | R6: 0 | S6: 0 | T6: 0 | U6: 0 | V6: 0 | W6: 0 | X6: 95 | Y6: 7 | Z6: 95.875 | AA6: 95.875 | AB6: 0 | AC6: 95 | AD6: 7
A7: Wheat | B7: Sown over 133 acres of land as they lie in the field, 23 quarters 5 bushels by 1 tally. | C7: 0 | D7: 0 | E7: 23 | F7: 5 | G7: 23.625 | H7: 0 | I7: 0 | J7: 0 | K7: 0 | L7: 0 | M7: 0 | N7: 0 | O7: 0 | P7: 0 | Q7: 0 | R7: 0 | S7: 0 | T7: 0 | U7: 0 | V7: 0 | W7: 0 | X7: 23 | Y7: 5 | Z7: 23.625 | AA7: 23.625 | AB7: 0 | AC7: 23 | AD7: 5
A8: Wheat | B8: that is, 1.5 bushels an acre, less 1 qr 2 bushels in all. | C8: 0 | D8: 0 | E8: 0 | F8: 0 | G8: 0 | H8: 0 | I8: 0 | J8: 0 | K8: 0 | L8: 0 | M8: 0 | N8: 0 | O8: 0 | P8: 0 | Q8: 0 | R8: 0 | S8: 0 | T8: 0 | U8: 0 | V8: 0 | W8: 0
A9: Wheat | B9: Delivered to 1 overseer of the harvest for the year, 3 quarters 2 bushels, because he takes the rest in barley, taking a quarter every 8 weeks. | C9: 0 | D9: 0 | E9: 0 | F9: 0 | G9: 0 | H9: 0 | I9: 0 | J9: 0 | K9: 0 | L9: 0 | M9: 0 | N9: 0 | O9: 0 | P9: 0 | Q9: 0 | R9: 0 | S9: 0 | T9: 0 | U9: 0 | V9: 0 | W9: 0 | X9: 3 | Y9: 2 | Z9: 3.25 | AA9: 3.25 | AB9: 0 | AC9: 3 | AD9: 2
A10: Wheat | B10: Sold, 68 quarters 7 bushels Sold at the audit, 1 bushels Total, 95 quarters 7 bushels None remains. | C10: 0 | D10: 0 | E10: 0 | F10: 0 | G10: 0 | H10: 0 | I10: 0 | J10: 0 | K10: 0 | L10: 0 | M10: 0 | N10: 0 | O10: 0 | P10: 0 | Q10: 163 | R10: 14 | S10: 164.75 | T10: 0 | U10: 0 | V10: 0 | W10: 0 | X10: 95 | Y10: 8 | Z10: 96 | AA10: 68.875 | AB10: 27.125 | AC10: 68 | AD10: 7 | AE10: 0 | AF10: 1 | AG10: 95 | AH10: 7
A11: Wheat | B11: Total | C11: 0 | D11: 0 | E11: 0 | F11: 0 | G11: 0 | H11: 0 | I11: 0 | J11: 0 | K11: 0 | L11: 0 | M11: 0 | N11: 0 | O11: 0 | P11: 0 | Q11: 0 | R11: 0 | S11: 0 | T11: 0 | U11: 0 | V11: 0 | W11: 0
A12: Barley | B12: (yield: 4-fold plus 3 quarters 6 bushels) | C12: 0 | D12: 0 | E12: 0 | F12: 0 | G12: 0 | H12: 0 | I12: 0 | J12: 0 | K12: 0 | L12: 0 | M12: 0 | N12: 0 | O12: 0 | P12: 0 | Q12: 0 | R12: 0 | S12: 0 | T12: 0 | U12: 0 | V12: 0 | W12: 0 | X12: 3 | Y12: 6 | Z12: 3.75 | AA12: 3.75 | AB12: 0 | AC12: 3 | AD12: 6
A13: Barley | B13: The same render account for 49 quarters 6 bushels of barley from the whole issue of the grange, threshed by piece-work by 1 tally of struck measure. | C13: 0 | D13: 0 | E13: 0 | F13: 0 | G13: 0 | H13: 0 | I13: 0 | J13: 0 | K13: 0 | L13: 0 | M13: 0 | N13: 0 | O13: 0 | P13: 0 | Q13: 0 | R13: 0 | S13: 0 | T13: 49 | U13: 6 | V13: 49.75 | W13: 0 | X13: 49 | Y13: 6 | Z13: 49.75 | AA13: 49.75 | AB13: 0 | AC13: 49 | AD13: 6
A14: Barley | B14: Total, 49 quarters 6 bushels Sown over 26 acres of land as they lie in the field, 12 quarters 7 bushels by 1 tally. | C14: 0 | D14: 0 | E14: 61 | F14: 13 | G14: 62.625 | H14: 0 | I14: 0 | J14: 0 | K14: 0 | L14: 0 | M14: 0 | N14: 0 | O14: 0 | P14: 0 | Q14: 0 | R14: 0 | S14: 0 | T14: 0 | U14: 0 | V14: 0 | W14: 0 | X14: 12 | Y14: 7 | Z14: 12.875 | AA14: 49.75 | AB14: -36.875 | AC14: 49 | AD14: 6 | AE14: 12 | AF14: 7
A15: Barley | B15: that is, 0.5 qr an acre, less 1 bushels in all. | C15: 0 | D15: 0 | E15: 0 | F15: 0 | G15: 0 | H15: 0 | I15: 0 | J15: 0 | K15: 0 | L15: 0 | M15: 0 | N15: 0 | O15: 0 | P15: 0 | Q15: 0 | R15: 0 | S15: 0 | T15: 0 | U15: 0 | V15: 0 | W15: 0
A16: Barley | B16: Delivered to 1 overseer of the harvest for the year, 3 quarters 2 bushels, because he takes the rest in wheat, taking a quarter every 8 weeks. | C16: 0 | D16: 0 | E16: 0 | F16: 0 | G16: 0 | H16: 0 | I16: 0 | J16: 0 | K16: 0 | L16: 0 | M16: 0 | N16: 0 | O16: 0 | P16: 0 | Q16: 0 | R16: 0 | S16: 0 | T16: 0 | U16: 0 | V16: 0 | W16: 0 | X16: 3 | Y16: 2 | Z16: 3.25 | AA16: 3.25 | AB16: 0 | AC16: 3 | AD16: 2
A17: Barley | B17: Delivered to 1 carter and 2 drovers for the year, 15 quarters 3.5 bushels, or 5 quarters 2 bushels each, taking a quarter every 10 weeks. | C17: 0 | D17: 0 | E17: 0 | F17: 0 | G17: 0 | H17: 0 | I17: 0 | J17: 0 | K17: 0 | L17: 0 | M17: 0 | N17: 0 | O17: 0 | P17: 0 | Q17: 0 | R17: 0 | S17: 0 | T17: 0 | U17: 0 | V17: 0 | W17: 0 | X17: 5 | Y17: 2 | Z17: 5.25 | AA17: 15.4375 | AB17: -10.1875 | AC17: 15 | AD17: 3.5 | AE17: 5 | AF17: 2
A18: Barley | B18: Mixed with dredge for sowing as made clear below, 3 quarters. | C18: 0 | D18: 0 | E18: 0 | F18: 0 | G18: 0 | H18: 0 | I18: 0 | J18: 0 | K18: 0 | L18: 0 | M18: 0 | N18: 0 | O18: 0 | P18: 0 | Q18: 0 | R18: 0 | S18: 0 | T18: 0 | U18: 0 | V18: 0 | W18: 0 | X18: 3 | Y18: 0 | Z18: 3 | AA18: 3 | AB18: 0 | AC18: 3 | AD18: 0
A19: Barley | B19: Sold, 14 quarters 3 bushels Sold at the audit, 5.5 bushels Total, 49 quarters 6 bushels None remains. | C19: 0 | D19: 0 | E19: 0 | F19: 0 | G19: 0 | H19: 0 | I19: 0 | J19: 0 | K19: 0 | L19: 0 | M19: 0 | N19: 0 | O19: 0 | P19: 0 | Q19: 63 | R19: 9 | S19: 64.125 | T19: 0 | U19: 0 | V19: 0 | W19: 0 | X19: 49 | Y19: 11.5 | Z19: 50.4375 | AA19: 14.375 | AB19: 36.0625 | AC19: 14 | AD19: 3 | AE19: 0 | AF19: 5.5 | AG19: 49 | AH19: 6
A20: Barley | B20: Total | C20: 0 | D20: 0 | E20: 0 | F20: 0 | G20: 0 | H20: 0 | I20: 0 | J20: 0 | K20: 0 | L20: 0 | M20: 0 | N20: 0 | O20: 0 | P20: 0 | Q20: 0 | R20: 0 | S20: 0 | T20: 0 | U20: 0 | V20: 0 | W20: 0
A21: Dredge | B21: (yield: three-fold less 3 quarters 7 bushels) The same render account for 51 quarters grange by 2 tallies of struck measure, and 4 quarters 2 bushels by labour service. | C21: 0 | D21: 0 | E21: 0 | F21: 0 | G21: 0 | H21: 0 | I21: 0 | J21: 0 | K21: 0 | L21: 0 | M21: 0 | N21: 0 | O21: 0 | P21: 0 | Q21: 0 | R21: 0 | S21: 0 | T21: 58 | U21: 9 | V21: 59.125 | W21: 0 | X21: 55 | Y21: 2 | Z21: 55.25 | AA21: 3.875 | AB21: 51.375 | AC21: 3 | AD21: 7 | AE21: 51 | AF21: 0 | AG21: 4 | AH21: 2
A22: Dredge | B22: 3 sowing. | C22: 0 | D22: 0 | E22: 0 | F22: 0 | G22: 0 | H22: 0 | I22: 0 | J22: 0 | K22: 0 | L22: 0 | M22: 0 | N22: 0 | O22: 0 | P22: 0 | Q22: 0 | R22: 0 | S22: 0 | T22: 0 | U22: 0 | V22: 0 | W22: 0 | X22: 0 | Y22: 0 | Z22: 0 | AA22: 0 | AB22: 0 | AC22: 0 | AD22: 0
A23: Dredge | B23: Total, 54 quarters 5 bushels | C23: 0 | D23: 0 | E23: 0 | F23: 0 | G23: 0 | H23: 0 | I23: 0 | J23: 0 | K23: 0 | L23: 0 | M23: 0 | N23: 0 | O23: 0 | P23: 0 | Q23: 0 | R23: 0 | S23: 0 | T23: 0 | U23: 0 | V23: 0 | W23: 0 | X23: 54 | Y23: 5 | Z23: 54.625 | AA23: 54.625 | AB23: 0 | AC23: 54 | AD23: 5
A24: Dredge | B24: Total, 54 quarters 5 bushels | C24: 0 | D24: 0 | E24: 0 | F24: 0 | G24: 0 | H24: 0 | I24: 0 | J24: 0 | K24: 0 | L24: 0 | M24: 0 | N24: 0 | O24: 0 | P24: 0 | Q24: 0 | R24: 0 | S24: 0 | T24: 0 | U24: 0 | V24: 0 | W24: 0 | X24: 54 | Y24: 5 | Z24: 54.625 | AA24: 54.625 | AB24: 0 | AC24: 54 | AD24: 5
A25: Dredge | B25: Sown over 63 acres of land as they lie plus 1 bushels in all. | C25: 0 | D25: 0 | E25: 0 | F25: 0 | G25: 0 | H25: 0 | I25: 0 | J25: 0 | K25: 0 | L25: 0 | M25: 0 | N25: 0 | O25: 0 | P25: 0 | Q25: 0 | R25: 0 | S25: 0 | T25: 0 | U25: 0 | V25: 0 | W25: 0 | X25: 0 | Y25: 1 | Z25: 0.125 | AA25: 0.125 | AB25: 0 | AC25: 0 | AD25: 1
A26: Dredge | B26: Sold, 20 quarters 6 bushels None remains. 5 bushels of dredge from the whole issue of the of which 43 quarters 1 bushels threshed by piece-work quarters of barley received to mix with dredge for in the field, 20 quarters 3 bushels. | C26: 0 | D26: 0 | E26: 0 | F26: 0 | G26: 0 | H26: 0 | I26: 0 | J26: 0 | K26: 0 | L26: 0 | M26: 0 | N26: 0 | O26: 0 | P26: 0 | Q26: 83 | R26: 10 | S26: 84.25 | T26: 83 | U26: 10 | V26: 84.25 | W26: 0 | X26: 63 | Y26: 9 | Z26: 64.125 | AA26: 20.75 | AB26: 43.375 | AC26: 20 | AD26: 6 | AE26: 0 | AF26: 5 | AG26: 43 | AH26: 1 | AI26: 20 | AJ26: 3
A27: Dredge | B27: that is, 3 bushels an acre, Sold at the audit, 3.5 quarters. | C27: 0 | D27: 0 | E27: 0 | F27: 0 | G27: 0 | H27: 0 | I27: 0 | J27: 0 | K27: 0 | L27: 0 | M27: 0 | N27: 0 | O27: 0 | P27: 0 | Q27: 3.5 | R27: 0 | S27: 3.5 | T27: 0 | U27: 0 | V27: 0 | W27: 0 | X27: 3.5 | Y27: 3 | Z27: 3.875 | AA27: 0.375 | AB27: 3.5 | AC27: 0 | AD27: 3 | AE27: 3.5 | AF27: 0
A28: Dredge | B28: Total, 54 quarters 5 bushels | C28: 0 | D28: 0 | E28: 0 | F28: 0 | G28: 0 | H28: 0 | I28: 0 | J28: 0 | K28: 0 | L28: 0 | M28: 0 | N28: 0 | O28: 0 | P28: 0 | Q28: 0 | R28: 0 | S28: 0 | T28: 0 | U28: 0 | V28: 0 | W28: 0 | X28: 54 | Y28: 5 | Z28: 54.625 | AA28: 54.625 | AB28: 0 | AC28: 54 | AD28: 5
A29: Dredge | B29: Total, 54 quarters 5 bushels | C29: 0 | D29: 0 | E29: 0 | F29: 0 | G29: 0 | H29: 0 | I29: 0 | J29: 0 | K29: 0 | L29: 0 | M29: 0 | N29: 0 | O29: 0 | P29: 0 | Q29: 0 | R29: 0 | S29: 0 | T29: 0 | U29: 0 | V29: 0 | W29: 0 | X29: 54 | Y29: 5 | Z29: 54.625 | AA29: 54.625 | AB29: 0 | AC29: 54 | AD29: 5
A30: Dredge | B30: Total | C30: 0 | D30: 0 | E30: 0 | F30: 0 | G30: 0 | H30: 0 | I30: 0 | J30: 0 | K30: 0 | L30: 0 | M30: 0 | N30: 0 | O30: 0 | P30: 0 | Q30: 0 | R30: 0 | S30: 0 | T30: 0 | U30: 0 | V30: 0 | W30: 0
A31: Vetches | B31: (yield: 4-fold, less 1 bushels) | C31: 0 | D31: 0 | E31: 0 | F31: 0 | G31: 0 | H31: 0 | I31: 0 | J31: 0 | K31: 0 | L31: 0 | M31: 0 | N31: 0 | O31: 0 | P31: 0 | Q31: 0 | R31: 0 | S31: 0 | T31: 0 | U31: 0 | V31: 0 | W31: 0 | X31: 0 | Y31: 1 | Z31: 0.125 | AA31: 0.125 | AB31: 0 | AC31: 0 | AD31: 1
A32: Vetches | B32: The same render account for 1 qr 3 bushels of vetches from the issue of the grange, threshed by piece-work by struck measure. | C32: 0 | D32: 0 | E32: 0 | F32: 0 | G32: 0 | H32: 0 | I32: 0 | J32: 0 | K32: 0 | L32: 0 | M32: 0 | N32: 0 | O32: 0 | P32: 0 | Q32: 0 | R32: 0 | S32: 0 | T32: 0 | U32: 0 | V32: 0 | W32: 0
A33: Vetches | B33: 3 quarters from the same issue by estimation in sheaves for oxen. | C33: 0 | D33: 0 | E33: 0 | F33: 0 | G33: 0 | H33: 0 | I33: 0 | J33: 0 | K33: 0 | L33: 0 | M33: 0 | N33: 0 | O33: 0 | P33: 0 | Q33: 0 | R33: 0 | S33: 0 | T33: 0 | U33: 0 | V33: 0 | W33: 0 | X33: 3 | Y33: 0 | Z33: 3 | AA33: 3 | AB33: 0 | AC33: 3 | AD33: 0
A34: Vetches | B34: Total, 4 quarters 3 bushels | C34: 0 | D34: 0 | E34: 0 | F34: 0 | G34: 0 | H34: 0 | I34: 0 | J34: 0 | K34: 0 | L34: 0 | M34: 0 | N34: 0 | O34: 0 | P34: 0 | Q34: 0 | R34: 0 | S34: 0 | T34: 0 | U34: 0 | V34: 0 | W34: 0 | X34: 4 | Y34: 3 | Z34: 4.375 | AA34: 4.375 | AB34: 0 | AC34: 4 | AD34: 3
A35: Vetches | B35: Sown, 6 bushels. | C35: 0 | D35: 0 | E35: 0 | F35: 0 | G35: 0 | H35: 0 | I35: 0 | J35: 0 | K35: 0 | L35: 0 | M35: 0 | N35: 0 | O35: 0 | P35: 0 | Q35: 0 | R35: 0 | S35: 0 | T35: 0 | U35: 0 | V35: 0 | W35: 0 | X35: 0 | Y35: 6 | Z35: 0.75 | AA35: 0.75 | AB35: 0 | AC35: 0 | AD35: 6
A36: Vetches | B36: fodder of oxen by estimation in sheaves, 3 quarters. | C36: 0 | D36: 0 | E36: 0 | F36: 0 | G36: 0 | H36: 0 | I36: 0 | J36: 0 | K36: 0 | L36: 0 | M36: 0 | N36: 3 | O36: 0 | P36: 3 | Q36: 0 | R36: 0 | S36: 0 | T36: 0 | U36: 0 | V36: 0 | W36: 0 | X36: 3 | Y36: 0 | Z36: 3 | AA36: 3 | AB36: 0 | AC36: 3 | AD36: 0
A37: Vetches | B37: Sold, 5 bushels Total, 4 quarters 3 bushels None remains. | C37: 0 | D37: 0 | E37: 0 | F37: 0 | G37: 0 | H37: 0 | I37: 0 | J37: 0 | K37: 0 | L37: 0 | M37: 0 | N37: 0 | O37: 0 | P37: 0 | Q37: 4 | R37: 3 | S37: 4.375 | T37: 0 | U37: 0 | V37: 0 | W37: 0 | X37: 4 | Y37: 3 | Z37: 4.375 | AA37: 0.625 | AB37: 3.75 | AC37: 0 | AD37: 5 | AE37: 4 | AF37: 3
A38: Vetches | B38: Total | C38: 0 | D38: 0 | E38: 0 | F38: 0 | G38: 0 | H38: 0 | I38: 0 | J38: 0 | K38: 0 | L38: 0 | M38: 0 | N38: 0 | O38: 0 | P38: 0 | Q38: 0 | R38: 0 | S38: 0 | T38: 0 | U38: 0 | V38: 0 | W38: 0
A39: Beans | B39: The same render account for 5 quarters 2 bushels of beans bought as noted above. | C39: 0 | D39: 0 | E39: 0 | F39: 0 | G39: 0 | H39: 5 | I39: 2 | J39: 5.25 | K39: 0 | L39: 0 | M39: 0 | N39: 0 | O39: 0 | P39: 0 | Q39: 0 | R39: 0 | S39: 0 | T39: 5 | U39: 2 | V39: 5.25 | W39: 1 | X39: 5 | Y39: 2 | Z39: 5.25 | AA39: 5.25 | AB39: 0 | AC39: 5 | AD39: 2
A40: Beans | B40: Total, 5 quarters 2 bushels Sown over 7 acres of land, 3 quarters. | C40: 0 | D40: 0 | E40: 8 | F40: 2 | G40: 8.25 | H40: 0 | I40: 0 | J40: 0 | K40: 0 | L40: 0 | M40: 0 | N40: 0 | O40: 0 | P40: 0 | Q40: 0 | R40: 0 | S40: 0 | T40: 0 | U40: 0 | V40: 0 | W40: 0 | X40: 3 | Y40: 2 | Z40: 3.25 | AA40: 5.25 | AB40: -2 | AC40: 5 | AD40: 2 | AE40: 3 | AF40: 0
...

Sheet Sale of Corn Prices
A1: Heading | B1: Sentence | C1: Total in Pounds | D1: Pounds | E1: Shillings | F1: Pence | G1: Corn | H1: Total Quarters Except 1 | I1: Total Bushels Except 1 | J1: Total Corn Cross-Check | K1: Total Corn Manorial Account | L1: Corn Quantity Error | M1: Quarters 0 | N1: Bushels 0 | O1: shilling a quarter 1 | P1: pence a quarter 1 | Q1: Quarters 1 | R1: Bushels 1 | S1: shilling a quarter 2 | T1: pence a quarter 2 | U1: Quarters 2 | V1: Bushels 2 | W1: shilling a quarter 3 | X1: pence a quarter 3 | Y1: Quarters 3 | Z1: Bushels 3 | AA1: shilling a quarter 4 | AB1: pence a quarter 4 | AC1: £ a quarter 1 | AD1: £ a quarter 2 | AE1: £ a quarter 3 | AF1: £ a quarter 4 | AG1: Quarters Sold | AH1: Weighted Average Price per Quarter | AI1: Non-Weighted Average Price per Quarter | AJ1: Corn lowercase
A2: Sale of corn | B2: The same render account for £19 7 shilling 7.5pence from 68 quarters 7 bushels of wheat sold, at 5 shilling a quarters for 4 quarters, and 5 shilling 8pence a quarters for 64 quarters 7 bushels. | C2: 19.38 | D2: 19 | E2: 7 | F2: 7.5 | G2: wheat | H2: 68 | I2: 7 | J2: 68.875 | K2: 68.875 | L2: 0 | M2: 68 | N2: 7 | O2: 5 | P2: 0 | Q2: 4 | R2: 0 | S2: 5 | T2: 8 | U2: 64 | V2: 7 | AC2: 0.25 | AD2: 0.28333333 | AG2: 68.875 | AH2: 0.28139746 | AI2: 0.26666667 | AJ2: wheat
A3: Sale of corn | B3: £2 10 shilling 3.75pence from 14 quarters 3 bushels of barley sold, at 3 shilling 6pence a quarters. | C3: 2.52 | D3: 2 | E3: 10 | F3: 3.75 | G3: barley | H3: 14 | I3: 3 | J3: 14.375 | K3: 14.375 | L3: 0 | M3: 14 | N3: 3 | O3: 3 | P3: 6 | AC3: 0.175 | AG3: 14.375 | AH3: 0.175 | AI3: 0.175 | AJ3: barley
A4: Sale of corn | B4: £4 12 shilling 3pence from 30 quarters 6 bushels of dredge sold, at 3 shilling a quarters. | C4: 4.61 | D4: 4 | E4: 12 | F4: 3 | H4: 30 | I4: 6 | J4: 30.75 | K4: 30.75 | L4: 0 | M4: 30 | N4: 6 | O4: 3 | P4: 0 | AC4: 0.15 | AG4: 30.75 | AH4: 0.15 | AI4: 0.15
A5: Sale of corn | B5: 7.5pence from 5 bushels of vetches sold, at 1.5pence a bushels. | C5: 0.03 | D5: 0 | E5: 0 | F5: 7.5 | G5: vetches | H5: 0 | I5: 5 | J5: 0.625 | K5: 0.625 | L5: 0 | M5: 0 | N5: 5 | AC5: 0.048 | AG5: 0.625 | AH5: 0.048 | AI5: 0.048 | AJ5: vetches
A6: Sale of corn | B6: 7.5pence from 1.5 bushels of wheat sold at the audit. | C6: 0.03 | D6: 0 | E6: 0 | F6: 7.5 | G6: wheat | H6: 0 | I6: 1.5 | J6: 0.1875 | K6: 0.1875 | L6: 0 | M6: 0 | N6: 1.5 | AC6: 0.16 | AG6: 0.1875 | AH6: 0.16 | AI6: 0.16 | AJ6: wheat
A7: Sale of corn | B7: 2 shilling 4.25pence from 5.5 bushels of barley sold at the audit. | C7: 0.12 | D7: 0 | E7: 2 | F7: 4.25 | G7: barley | H7: 0 | I7: 5.5 | J7: 0.6875 | K7: 0.6875 | L7: 0 | M7: 0 | N7: 5.5 | AC7: 0.17454545 | AG7: 0.6875 | AH7: 0.17454545 | AI7: 0.17454545 | AJ7: barley
A8: Sale of corn | B8: 10 shilling 6pence from 3.5 quarters of dredge sold at the audit, at 3 shilling a quarters. | C8: 0.53 | D8: 0 | E8: 10 | F8: 6 | H8: 3.5 | I8: 0 | J8: 3.5 | K8: 3.5 | L8: 0 | M8: 3.5 | N8: 0 | O8: 3 | P8: 0 | AC8: 0.15 | AG8: 3.5 | AH8: 0.15 | AI8: 0.15
A9: Sale of corn | B9: Total, £27 4 shilling 4pence | C9: 27.22 | D9: 27 | E9: 4 | F9: 4 | H9: 0 | I9: 0 | J9: 0 | K9: 0 | L9: 0 | M9: 0 | N9: 0 | AC9: inf | AG9: 0 | AH9: inf | AI9: inf
