Workbook

Sheet Overview
A1: MORTON | B1: Total in £ | C1: Error | D1: Note
A2: CASH ACCOUNT
A3: RECEIPTS
A4: Arrears total
A5: Rents of assize total
A6: Quittances total
A7: Defaults of rent total
A8: Defaults of rent through the pestilence total
A9: Cotlands defaults total
A10: Cotlands total
A11: Total of quittances and defaults of rent total
A12: Total of rents remaining clear total
A13: Farms total
... A183: % of capital expenses as calculated previously

Sheet Receipts
A1: MORTON RECEIPTS
A2: Heading | B2: £ | C2: s | D2: d | F2: Total in £ | G2: Error | H2: Notes
A3: Arrears | B3: 3 | C3: 10 | D3: 3 | F3: 3.51 | H3: William, bailiff, and Richard, reeve, render account for £3 10 shilling 3pence of arrears from the previous year.
A4: Arrears | B4: 3 | C4: 10 | D4: 3 | F4: 3.51 | H4: Delivered to Sir Geoffrey, treasurer of Wolvesey, by 1 tally, £3 10 shilling 3pence They are quit.
A5: Arrears | F5: 7.02 | G5: 3.51 | H5: Total
A7: Rents | B7: 1 | C7: 3 | D7: 3.25 | F7: 1.16 | H7: The same render account for £1 3 shilling 3.25pence for all rents of assize at Christmas.
A8: Rents | B8: 1 | C8: 3 | D8: 3.25 | F8: 1.16 | H8: £1 3 shilling 3.25pence at the Annunciation (25 March).
A9: Rents | B9: 1 | C9: 3 | D9: 3.25 | F9: 1.16 | H9: £1 3 shilling 3.25pence at the Nativity of St John the Baptist (24 June).
A10: Rents | B10: 1 | C10: 3 | D10: 3.25 | F10: 1.16 | H10: £1 3 shilling 3.25pence at Michaelmas (29 September).
A11: Rents | B11: 4 | C11: 13 | D11: 1 | F11: 4.65 | H11: Total of all rents for the year, £4 13 shilling 1pence
A12: Rents | F12: 4.64 | G12: -0.01 | H12: Total
A14: Quittances | B14: 0 | C14: 2 | D14: 0 | F14: 0.1 | H14: In quittance of 1 reeve for the year 2 shilling.
A15: Quittances | B15: 0 | C15: 12 | D15: 0 | F15: 0.6 | H15: 6 men holding 6 virgates of land, 3 of whom hold the lord's ploughs for 1 week and the other three for the other week, 12 shilling for the year.
A16: Quittances | B16: 0 | C16: 14 | D16: 0 | F16: 0.7 | H16: Total of quittances, 14 shilling
A17: Quittances | F17: 0.7 | G17: 0 | H17: Total
A19: Defaults of rent | B19: 0 | C19: 4 | D19: 0 | F19: 0.2 | H19: In default of 1 virgate of land which belonged to William de Bury drawn into demesne, 4 shilling for the year.
A20: Defaults of rent | B20: 0 | C20: 3 | D20: 0 | F20: 0.15 | H20: 1.5 virgates and 1 ferling of land which belonged to Roger drawn into demesne, 3 shilling for the year.
A21: Defaults of rent | B21: 0 | C21: 1 | D21: 8 | F21: 0.08 | H21: 1.5 virgates and a farthing of land which belonged to William Alfnth drawn into demesne, 1 shilling 8pence for the year.
A22: Defaults of rent | B22: 0 | C22: 0 | D22: 9 | F22: 0.04 | H22: 1 ferling of land which belonged to William le Nywman drawn into demesne, 9pence for the year.
A23: Defaults of rent | B23: 0 | C23: 1 | D23: 3 | F23: 0.06 | H23: 1 ferling and a farthing of land which belonged to Alice drawn into demesne, 1 shilling 3pence for the year.
A24: Defaults of rent | B24: 0 | C24: 0 | D24: 0 | F24: 0 | H24: a curtilage which belonged to Roger Pound' drawn into demesne, 7'/ pence for the year.
A25: Defaults of rent | B25: 0 | C25: 11 | D25: 3.5 | F25: 0.56 | H25: Total of defaults of rent, 11 shilling 3.5pence
A26: Defaults of rent | F26: 0.53 | G26: -0.03 | H26: Total
A28: Total of quittances and defaults of rent | B28: 1 | C28: 5 | D28: 3.5 | F28: 1.26 | H28: Total of quittances and defaults of rent, £1 5 shilling 3.5pence
A29: Total of quittances and defaults of rent | F29: 1.26 | G29: =F29-F28 -> 0 | H29: Total
A31: Annual recognizance | B31: 0 | C31: 0 | D31: 0 | F31: 0 | H31: Nothing from annual recognizance.
A32: Annual recognizance | F32: 0 | G32: 0 | H32: Total
A34: Issues of the manor | B34: 0 | C34: 0 | D34: 9.5 | F34: 0.04 | H34: The same render account for 9.5pence from common pannage of the whole vill.
A35: Issues of the manor | B35: 0 | C35: 1 | D35: 6 | F35: 0.08 | H35: 1 shilling 6pence from stubble sold.
A36: Issues of the manor | B36: 0 | C36: 2 | D36: 0 | F36: 0.1 | H36: 2 shilling from mast in the grove sold.
A37: Issues of the manor | B37: 0 | C37: 3 | D37: 0 | F37: 0.15 | H37: 3 shilling from winter cheese sold.
A38: Issues of the manor | B38: 1 | C38: 15 | D38: 0 | F38: 1.75 | H38: £1 15 shilling from 3.5 weys of summer cheese sold, at 10 shilling a wey.
A39: Issues of the manor | B39: 0 | C39: 4 | D39: 3 | F39: 0.21 | H39: 4 shilling 3pence from 8.5 gallons of butter sold, at 6pence a gallon.
A40: Issues of the manor | B40: 0 | C40: 0 | D40: 0 | F40: 0 | H40: nothing from hay sold this year.
A41: Issues of the manor | B41: 0 | C41: 0 | D41: 8 | F41: 0.03 | H41: 8pence from apples from the issue of the garden sold this year.
A42: Issues of the manor | B42: 0 | C42: 0 | D42: 0 | F42: 0 | H42: nothing from the agistment of bullocks in the pasture this year because there were sheep.
A43: Issues of the manor | B43: 0 | C43: 1 | D43: 9 | F43: 0.09 | H43: 1 shilling 9pence from dairy produce sold at the audit.
A44: Issues of the manor | B44: 2 | C44: 8 | D44: 11.5 | F44: 2.45 | H44: Total, £2 8 shilling 11.5pence
A45: Issues of the manor | F45: 2.45 | G45: 0 | H45: Total
A47: Issues of stock | B47: 1 | C47: 0 | D47: 4 | F47: 1.02 | H47: The same render account for £1 4pence from 4 plough-horses sold, at 6 shilling for 1, 5 shilling 6pence each for 2, and 3 shilling 4pence for 1.
...

Sheet Expenses
A1: MORTON EXPENSES
A2: Heading | B2: £ | C2: s | D2: d | F2: Total in £ | G2: Error | H2: Notes
A3: Expenses for ploughs | B3: 0 | C3: 3 | D3: 1 | F3: 0.15 | H3: In ironwork of 3 ploughs for the year 3 shilling 1pence.
A4: Expenses for ploughs | B4: 0 | C4: 0 | D4: 4 | F4: 0.02 | H4: 2 plough-shoes (calconibus) bought 4pence.
A5: Expenses for ploughs | B5: 0 | C5: 1 | D5: 4 | F5: 0.07 | H5: 2 ploughshares bought 1 shilling 4pence.
A6: Expenses for ploughs | B6: 0 | C6: 2 | D6: 0.5 | F6: 0.1 | H6: stipend of the smith making the ironwork of 3 ploughs for the year 2 shilling 0.5pence.
A7: Expenses for ploughs | B7: 0 | C7: 0 | D7: 8 | F7: 0.03 | H7: 4 new ploughs made from the lord's timber 8pence.
A8: Expenses for ploughs | B8: 0 | C8: 0 | D8: 2 | F8: 0.01 | H8: repairing the same 2pence.
A9: Expenses for ploughs | B9: 0 | C9: 0 | D9: 11 | F9: 0.05 | H9: ox-bows, withies and draught-chains (hart') for the ploughs 11pence.
A10: Expenses for ploughs | B10: 0 | C10: 0 | D10: 1.5 | F10: 0.01 | H10: 1 harrow made from the lord's timber 1.5pence.
A11: Expenses for ploughs | B11: 0 | C11: 0 | D11: 2 | F11: 0.01 | H11: blood-letting of oxen 2pence.
A12: Expenses for ploughs | B12: 0 | C12: 0 | D12: 1.5 | F12: 0.01 | H12: 6 halters made from their own hair 1.5pence.
A13: Expenses for ploughs | B13: 0 | C13: 6 | D13: 0 | F13: 0.3 | H13: stipend of 3 oxherds driving the lord's ploughs from Michaelmas until the Annunciation 6 shilling, and for the rest of their stipends each takes at harvest-time 72 sheaves of wheat which contain by estimation 1 quarters 2 bushels, and 72 sheaves of oats which contain by estimation 1 quarters.
A14: Expenses for ploughs | B14: 0 | C14: 4 | D14: 6 | F14: 0.23 | H14: stipend of 3 ploughmen for working 36 Saturdays 4 shilling 6pence, or .5pence each, because they are not obliged to work on Saturdays.
... A19: Expenses for ploughs | B19: 1 | C19: 3 | D19: 6.5 | F19: 1.18 | H19: forage bought for stock £1 3 shilling 6.5pence
A20: Expenses for ploughs | B20: 12 | C20: 17 | D20: 10.5 | F20: =B20+C20/20+D20/240 -> 12.89375 | H20: Total, £12 17 shilling 10.5pence
A21: Expenses for ploughs | F21: =SUM(F3:F19) -> 12.92 | G21: =F21-F20 -> 0.02625 | H21: Total
A23: Expenses for carts | B23: 0 | C23: 1 | D23: 4 | F23: 0.07 | H23: In 2 pairs of wheels made from the lord's timber for clearing dung 1 shilling 4pence.
A24: Expenses for carts | B24: 0 | C24: 1 | D24: 0 | F24: 0.05 | H24: fitting the cart with axles, with clouts, nails and grease for the same for the year, 1 shilling.
A25: Expenses for carts | B25: 0 | C25: 0 | D25: 4 | F25: 0.02 | H25: white leather for mending harnesses of the cart 4pence.
A26: Expenses for carts | B26: 0 | C26: 0 | D26: 4.5 | F26: 0.02 | H26: 1 pair of traces bought 4.5pence.
A27: Expenses for carts | B27: 0 | C27: 1 | D27: 1 | F27: 0.05 | H27: 2 hemp ropes bought 1 shilling 1pence.
A28: Expenses for carts | B28: 0 | C28: 1 | D28: 2 | F28: 0.06 | H28: 2 collars bought 1 shilling 2pence.
A29: Expenses for carts | B29: 0 | C29: 2 | D29: 0 | F29: 0.1 | H29: shoeing 2 plough-horses hauling the cart for the year 2 shilling.
A30: Expenses for carts | B30: 0 | C30: 2 | D30: 0 | F30: 0.1 | H30: stipend of 1 carter from Michaelmas until the Annunciation 2 shilling, and for the rest of his stipend he takes sheaves at harvest-time like the rest of the manorial servants.
A31: Expenses for carts | B31: 0 | C31: 9 | D31: 3.5 | F31: 0.46 | H31: Total, 9 shilling 3.5pence
A32: Expenses for carts | F32: =SUM(F23:F30) -> 0.47 | G32: =F32-F31 -> 0.01 | H32: Total
A34: Harvest-time | B34: 0 | C34: 1 | D34: 0 | F34: 0.05 | H34: 1 sickle bought 1 shilling.
A35: Harvest-time | B35: 0 | C35: 0 | D35: 2 | F35: 0.01 | H35: sharpening 3 sickles 2pence.
A36: Harvest-time | B36: 0 | C36: 3 | D36: 6 | F36: 0.17 | H36: spreading and tossing the frinineeeadmoewn who were overseeing the reapers at 2 harvest boon-works as if for 1 day and 3 shilling 6pence.
A37: Harvest-time | B37: 0 | C37: 1 | D37: 6 | F37: 0.08 | H37: weeding corn 1 shilling 6pence.
A38: Harvest-time | B38: 0 | C38: 8 | D38: 1.5 | F38: 0.41 | H38: relish and ale bought for 96 men with 8 having bread from the grange 8 shilling They reaped almost all the corn together with the other 2 boon-works which are without food, each thus taking 1.5pence a day.
A39: Harvest-time | B39: 0 | C39: 14 | D39: 2 | F39: 0.71 | H39: Total, 14 shilling 2pence
A40: Harvest-time | F40: =SUM(F34:F38) -> 0.72 | G40: =F40-F39 -> 0.01 | H40: Total
A42: Wages | B42: 1 | C42: 11 | D42: 6 | F42: 1.57 | H42: In wages of Ralph, sergeant, from Sunday before the feast of St Vincent (21 January) until Michaelmas (29 September), for 36 weeks, £1 11 shilling 6pence, that is, 10.5pence every week.'.
A43: Wages | B43: 0 | C43: 6 | D43: 8 | F43: =B43+C43/20+D43/240 -> 0.33333333 | H43: stipend of the same sergeant for the year 6 shilling 8pence
A44: Wages | B44: 1 | C44: 18 | D44: 2 | F44: 1.91 | H44: Total, £1 18 shilling 2pence
A45: Wages | F45: =SUM(F42:F43) -> 1.9033333 | G45: =F45-F44 -> -0.0066666667 | H45: Total
A47: Dairy | B47: 0 | C47: 2 | D47: 6 | F47: 0.12 | H47: In 5 quarters 1 bushels of beans planted and watered 2 shilling 6pence.
A48: Dairy | B48: 0 | C48: 0 | D48: 9 | F48: 0.04 | H48: 2 Fbushels1 of salt bought for the dairy 9pence, at 4.5pence a bushels.
...

Sheet Issues of the Grange
A1: Gross Output | B1: Total Quantity | C1: Account Total Quarters | D1: Bought in Total Quarters | E1: Received from churchscot | F1: Sold Total Quarters | G1: Difference Produced+Bought-Sold | H1: Weighted Average Price per Quarter | I1: Value of Total Production weighted
A2: wheat | B2: 92.375 | C2: 64.75 | D2: 20.125 | F2: 48.75 | G2: =B2-F2 -> 43.625 | H2: 0.22235043 | I2: =H2*B2 -> 20.539621
A3: curall | B3: 27 | C3: 27 | D3: 0 | G3: =B3-F3 -> 27 | I3: =H3*B3 -> 0
A4: barley | B4: 65.375 | C4: 65.375 | D4: 0 | F4: 32.5 | G4: =B4-F4 -> 32.875 | H4: 0.16666667 | I4: =H4*B4 -> 10.895833
A5: oats | B5: 11.375 | C5: 11.375 | D5: 2.5 | G5: =B5-F5 -> 11.375 | I5: =H5*B5 -> 0
A6: beans | B6: 43.875 | C6: 43.875 | D6: 0 | F6: 1 | G6: =B6-F6 -> 42.875 | H6: =2/20 -> 0.1 | I6: =H6*B6 -> 4.3875
A8: Total Production
A9: Sales of corn (as recorded in accounts)
A12: Net output | B12: Gross output | C12: Seed quarters | D12: Seed bushels | E12: Seed total quarters | F12: tithe quarters | G12: tithe bushels | H12: tithe total | I12: manorial servants quarters | J12: manorial servants bushels | K12: manorial servants total quarters | L12: output net of tithe, seed, liveries | M12: in stock from last year | N12: Price in £ | O12: Value of net output in £ | P12: Value of sales (in "Sale of Corn") in £
A13: wheat | B13: =B2 -> 92.375 | C13: 35 | D13: 1 | E13: =C13+D13/8 -> 35.125 | I13: =1+7.5 -> 8.5 | K13: =I13+J13/8 -> 8.5 | L13: =B13-E13-H13-K13 -> 48.75 | N13: =H2 -> 0.22235043 | O13: =L13*N13 -> 10.839583
A14: curall | B14: =B3 -> 27 | E14: =C14+D14/8 -> 0 | K14: =I14+J14/8 -> 0 | L14: =B14-E14-H14-K14 -> 27 | N14: =H3 -> 0 | O14: =L14*N14 -> 0
A15: barley | B15: =B4 -> 65.375 | C15: 24 | D15: 1 | E15: =C15+D15/8 -> 24.125 | I15: =8 -> 8 | J15: =5 -> 5 | K15: =I15+J15/8 -> 8.625 | L15: =B15-E15-H15-K15 -> 32.625 | N15: =H4 -> 0.16666667 | O15: =L15*N15 -> 5.4375
A16: oats | B16: =B5 -> 11.375 | C16: 2 | D16: 2 | E16: =C16+D16/8 -> 2.25 | I16: =6+3 -> 9 | J16: 1 | K16: =I16+J16/8 -> 9.125 | L16: =B16-E16-H16-K16 -> 0 | N16: =H5 -> 0 | O16: =L16*N16 -> 0
A17: beans | B17: =B6 -> 43.875 | C17: 5 | D17: 1 | E17: =C17+D17/8 -> 5.125 | I17: =26+4+5+2 -> 37 | J17: =2.5+1.5+2 -> 6 | K17: =I17+J17/8 -> 37.75 | L17: =B17-E17-H17-K17 -> 1 | N17: =H6 -> 0.1 | O17: =L17*N17 -> 0.1
A19: Total

Sheet Issues of the Mills

Sheet Stock
A1: MORTON STOCK ACCOUNT
C3: added | G3: subtracted
A4: Livestock | B4: Inherited stock | C4: added | D4: strays | E4: herbage | F4: churchscot | G4: of which in default | H4: sold | I4: in murrain | J4: accounted for elsewhere | K4: End-period stock | L4: cross-check | M4: stock building | N4: raw production | O4: Unit price (£) | P4: Value of stock (£) at given value | Q4: Value of stock (£) at sales prices | R4: Sales in (£) | S4: Value of stock building (£) | T4: Value of production (£) at sales prices | U4: Details
A5: Cart-horses
A6: Mares
A7: Plough horses | B7: 9 | H7: 4 | I7: 1 | K7: 4 | R7: =Receipts!F47 -> 1.02
A8: Colts (unspecified years)
A9: Colts (2 years)
A10: Colts (1 year)
A11: Foals
A12: Oxen | B12: 19 | C12: =4+10 -> 14 | H12: 3 | I12: 1 | K12: 29 | R12: =Receipts!F48 -> 1.45
A13: Bulls | B13: 1 | K13: 1
A14: Cows | B14: 12 | H14: 1 | K14: 11 | R14: =Receipts!F49 -> 0.43
A15: Steers | B15: 5 | H15: 1 | J15: 4 | K15: 0 | R15: =Receipts!F50 -> 0.22
A16: Bullocks | B16: 3 | K16: 3
A17: Yearlings | B17: 5 | K17: 5
A18: Calves | C18: 11 | H18: 6 | I18: 1 | J18: 1 | K18: 3 | R18: =Receipts!F51 -> 0.3
A19: Wethers
A20: Rams
A21: Ewes
A22: Hoggs
A23: Lambs
A24: Boars
A25: Sows
A26: Pigs
A27: Hoggets
A28: Piglets
A29: Swans
A30: Peacocks
A31: Total Value | R31: =SUM(R5:R30) -> 3.42
A34: Wool
A35: Coarse wool | B35: nothing because the lord's sheep are not there
A36: Lamb's wool
A37: Wool locks
A38: Wool sold at shearing
A39: Total wool
A42: Hides
A43: Ox hides | C43: 1 | H43: 1 | R43: =Receipts!F53 -> 0.1 | U43: only recorded in issues
A44: plough horse | C44: 1 | H44: 1 | R44: =Receipts!F52 -> 0.03 | U44: only recorded in issues
A45: Mare
...

Sheet raw data
A1: Heading | B1: Sentence | C1: Total in Pounds | D1: Pounds | E1: Shillings | F1: Pence | G1: Corn | H1: Total Quarters Except 1 | I1: Total Bushels Except 1 | J1: Total Corn Cross-Check | K1: Total Corn Manorial Account | L1: Corn Quantity Error | M1: Quarters 1 | N1: Bushels 1 | O1: Quarters 2 | P1: Bushels 2 | Q1: Quarters 3 | R1: Bushels 3 | S1: Quarters 4 | T1: Bushels 4 | U1: shilling a quarter 1 | V1: pence a quarter 1 | W1: shilling a quarter 2 | X1: pence a quarter 2 | Y1: shilling a quarter 3 | Z1: pence a quarter 3 | AA1: shilling a quarter 4 | AB1: pence a quarter 4 | AC1: shilling a bushel 1 | AD1: pence a bushel 1 | AE1: shilling a bushel 2 | AF1: pence a bushel 2 | AG1: shilling a bushel 3 | AH1: pence a bushel 3 | AI1: shilling a bushel 4 | AJ1: pence a bushel 4
A2: Arrears | B2: William, bailiff, and Richard, reeve, render account for £3 10 shilling 3pence of arrears from the previous year. | C2: 3.51 | D2: 3 | E2: 10 | F2: 3 | H2: 0 | I2: 0 | J2: 0 | K2: 0 | L2: 0 | M2: 0 | N2: 0
A3: Arrears | B3: Delivered to Sir Geoffrey, treasurer of Wolvesey, by 1 tally, £3 10 shilling 3pence They are quit. | C3: 3.51 | D3: 3 | E3: 10 | F3: 3 | H3: 0 | I3: 0 | J3: 0 | K3: 0 | L3: 0 | M3: 0 | N3: 0
A4: Rents | B4: The same render account for £1 3 shilling 3.25pence for all rents of assize at Christmas. | C4: 1.16 | D4: 1 | E4: 3 | F4: 3.25 | H4: 0 | I4: 0 | J4: 0 | K4: 0 | L4: 0 | M4: 0 | N4: 0
A5: Rents | B5: £1 3 shilling 3.25pence at the Annunciation (25 March). | C5: 1.16 | D5: 1 | E5: 3 | F5: 3.25 | H5: 0 | I5: 0 | J5: 0 | K5: 0 | L5: 0 | M5: 0 | N5: 0
A6: Rents | B6: £1 3 shilling 3.25pence at the Nativity of St John the Baptist (24 June). | C6: 1.16 | D6: 1 | E6: 3 | F6: 3.25 | H6: 0 | I6: 0 | J6: 0 | K6: 0 | L6: 0 | M6: 0 | N6: 0
A7: Rents | B7: £1 3 shilling 3.25pence at Michaelmas (29 September). | C7: 1.16 | D7: 1 | E7: 3 | F7: 3.25 | H7: 0 | I7: 0 | J7: 0 | K7: 0 | L7: 0 | M7: 0 | N7: 0
A8: Rents | B8: Total of all rents for the year, £4 13 shilling 1pence | C8: 4.65 | D8: 4 | E8: 13 | F8: 1 | H8: 0 | I8: 0 | J8: 0 | K8: 0 | L8: 0 | M8: 0 | N8: 0
A9: Quittances | B9: In quittance of 1 reeve for the year 2 shilling. | C9: 0.1 | D9: 0 | E9: 2 | F9: 0 | H9: 0 | I9: 0 | J9: 0 | K9: 0 | L9: 0 | M9: 0 | N9: 0
A10: Quittances | B10: 6 men holding 6 virgates of land, 3 of whom hold the lord's ploughs for 1 week and the other three for the other week, 12 shilling for the year. | C10: 0.6 | D10: 0 | E10: 12 | F10: 0 | H10: 0 | I10: 0 | J10: 0 | K10: 0 | L10: 0 | M10: 0 | N10: 0
A11: Quittances | B11: Total of quittances, 14 shilling | C11: 0.7 | D11: 0 | E11: 14 | F11: 0 | H11: 0 | I11: 0 | J11: 0 | K11: 0 | L11: 0 | M11: 0 | N11: 0
A12: Defaults of rent | B12: In default of 1 virgate of land which belonged to William de Bury drawn into demesne, 4 shilling for the year. | C12: 0.2 | D12: 0 | E12: 4 | F12: 0 | H12: 0 | I12: 0 | J12: 0 | K12: 0 | L12: 0 | M12: 0 | N12: 0
A13: Defaults of rent | B13: 1.5 virgates and 1 ferling of land which belonged to Roger drawn into demesne, 3 shilling for the year. | C13: 0.15 | D13: 0 | E13: 3 | F13: 0 | H13: 0 | I13: 0 | J13: 0 | K13: 0 | L13: 0 | M13: 0 | N13: 0
... A42: Issues of stock | B42: Total, £3 11 shilling 9pence | C42: 3.59 | D42: 3 | E42: 11 | F42: 9 | H42: 0 | I42: 0 | J42: 0 | K42: 0 | L42: 0 | M42: 0 | N42: 0
A43: Sale of corn | B43: The same render account for £10 16 shilling 9.5pence from 48 quarters 6 bushels of wheat sold, at 5 shilling a quarters for 25 quarters 1 bushels). 4 shilling a quarters for 18.5 quarters 1 bushels, and 3 shilling 4pence a quarters for 5 quarters. | C43: 10.84 | D43: 10 | E43: 16 | F43: 9.5 | G43: wheat | H43: 48.5 | I43: 2 | J43: 48.75 | K43: 48.75 | L43: 0 | M43: 48 | N43: 6 | O43: 25 | P43: 1 | Q43: 18.5 | R43: 1 | S43: 5 | T43: 0 | U43: 5 | V43: 0 | W43: 4 | X43: 0 | Y43: 3 | Z43: 4
A44: Sale of corn | B44: £5 8 shilling 9pence from 32.5 quarters I bushels of barley sold, at 3 shilling 4pence a quarters. | C44: 5.44 | D44: 5 | E44: 8 | F44: 9 | G44: barley | H44: 32.5 | I44: 0 | J44: 32.5 | K44: 32.5 | L44: 0 | M44: 32.5 | N44: 0 | U44: 3 | V44: 4
A45: Sale of corn | B45: 2 shilling from 1 quarters of beans sold. | C45: 0.1 | D45: 0 | E45: 2 | F45: 0 | G45: beans | H45: 1 | I45: 0 | J45: 1 | K45: 1 | L45: 0 | M45: 1 | N45: 0
A46: Sale of corn | B46: £1 6 shilling 8pence from a certain part of the stack of beans sold wholesale. | C46: 1.33 | D46: 1 | E46: 6 | F46: 8 | G46: beans | H46: 0 | I46: 0 | J46: 0 | K46: 0 | L46: 0 | M46: 0 | N46: 0
A47: Sale of corn | B47: Total, £17 14 shilling 2.5pence | C47: 17.71 | D47: 17 | E47: 14 | F47: 2.5 | H47: 0 | I47: 0 | J47: 0 | K47: 0 | L47: 0 | M47: 0 | N47: 0
A48: Entry and marriage fines | B48: The same render account for 5 shilling from John atte Watere for marrying Claricia his daughter outside. | C48: 0.25 | D48: 0 | E48: 5 | F48: 0 | H48: 0 | I48: 0 | J48: 0 | K48: 0 | L48: 0 | M48: 0 | N48: 0
A49: Entry and marriage fines | B49: 8 shilling from 2 tithings for tithingpenny at the hundred-court of Martinmas. | C49: 0.4 | D49: 0 | E49: 8 | F49: 0 | H49: 0 | I49: 0 | J49: 0 | K49: 0 | L49: 0 | M49: 0 | N49: 0
A50: Entry and marriage fines | B50: 8 shilling from the same tithings for tithingpenny at the hundred-court of Hockday. | C50: 0.4 | D50: 0 | E50: 8 | F50: 0 | H50: 0 | I50: 0 | J50: 0 | K50: 0 | L50: 0 | M50: 0 | N50: 0
A51: Entry and marriage fines | B51: Total, £1 1 shilling | C51: 1.05 | D51: 1 | E51: 1 | F51: 0 | H51: 0 | I51: 0 | J51: 0 | K51: 0 | L51: 0 | M51: 0 | N51: 0
A52: Pleas and perquisites | B52: The same render account for 2 shilling 6pence from the pleas and perquisites of all the courts for the whole year. | C52: 0.12 | D52: 0 | E52: 2 | F52: 6 | H52: 0 | I52: 0 | J52: 0 | K52: 0 | L52: 0 | M52: 0 | N52: 0
A53: Pleas and perquisites | B53: Total, 2 shilling 6pence | C53: 0.12 | D53: 0 | E53: 2 | F53: 6 | H53: 0 | I53: 0 | J53: 0 | K53: 0 | L53: 0 | M53: 0 | N53: 0
A54: Total of both | B54: Total of both, £1 3 shilling 6pence | C54: 1.17 | D54: 1 | E54: 3 | F54: 6 | H54: 0 | I54: 0 | J54: 0 | K54: 0 | L54: 0 | M54: 0 | N54: 0
A55: Total of all expenses | B55: Total of all expenses, £28 6 shilling 2.5pence | C55: 28.31 | D55: 28 | E55: 6 | F55: 2.5 | H55: 0 | I55: 0 | J55: 0 | K55: 0 | L55: 0 | M55: 0 | N55: 0
A56: Expenses for ploughs | B56: In ironwork of 3 ploughs for the year 3 shilling 1pence. | C56: 0.15 | D56: 0 | E56: 3 | F56: 1 | H56: 0 | I56: 0 | J56: 0 | K56: 0 | L56: 0 | M56: 0 | N56: 0
A57: Expenses for ploughs | B57: 2 plough-shoes (calconibus) bought 4pence. | C57: 0.02 | D57: 0 | E57: 0 | F57: 4 | H57: 0 | I57: 0 | J57: 0 | K57: 0 | L57: 0 | M57: 0 | N57: 0
A58: Expenses for ploughs | B58: 2 ploughshares bought 1 shilling 4pence. | C58: 0.07 | D58: 0 | E58: 1 | F58: 4 | H58: 0 | I58: 0 | J58: 0 | K58: 0 | L58: 0 | M58: 0 | N58: 0
... A65: Expenses for ploughs | B65: 6 halters made from their own hair 1.5pence. | C65: 0.01 | D65: 0 | E65: 0 | F65: 1.5 | H65: 0 | I65: 0 | J65: 0 | K65: 0 | L65: 0 | M65: 0 | N65: 0
A66: Expenses for ploughs | B66: stipend of 3 oxherds driving the lord's ploughs from Michaelmas until the Annunciation 6 shilling, and for the rest of their stipends each takes at harvest-time 72 sheaves of wheat which contain by estimation 1 quarters 2 bushels, and 72 sheaves of oats which contain by estimation 1 quarters. | C66: 0.3 | D66: 0 | E66: 6 | F66: 0 | G66: oats, wheat | H66: 1 | I66: 2 | J66: 1.25 | K66: 1.25 | L66: 0 | M66: 1 | N66: 2 | O66: 1 | P66: 0
A67: Expenses for ploughs | B67: . | C67: 0 | D67: 0 | E67: 0 | F67: 0 | H67: 0 | I67: 0 | J67: 0 | K67: 0 | L67: 0 | M67: 0 | N67: 0
A68: Expenses for ploughs | B68: stipend of 3 ploughmen for working 36 Saturdays 4 shilling 6pence, or .5pence each, because they are not obliged to work on Saturdays. | C68: 0.23 | D68: 0 | E68: 4 | F68: 6 | H68: 0 | I68: 0 | J68: 0 | K68: 0 | L68: 0 | M68: 0 | N68: 0
A69: Expenses for ploughs | B69: . | C69: 0 | D69: 0 | E69: 0 | F69: 0 | H69: 0 | I69: 0 | J69: 0 | K69: 0 | L69: 0 | M69: 0 | N69: 0
A70: Expenses for ploughs | B70: 10 oxen bought £6 11 shilling 1pence, at 14 shilling 1pence each for 3, 13 shilling 6pence each for 3, and 12 shilling 1pence each for 4.. | C70: 6.55 | D70: 6 | E70: 11 | F70: 1 | H70: 0 | I70: 0 | J70: 0 | K70: 0 | L70: 0 | M70: 0 | N70: 0
A71: Expenses for ploughs | B71: 20 quarters 1 bushels of wheat bought for sowing and the provision of the harvest boon-works £3 13 shilling 1.5pence, at 3 shilling 8pence a quarters for 18 quarters 1 bushels, and 3 shilling 4pence a quarters for 2 quarters. | C71: 3.66 | D71: 3 | E71: 13 | F71: 1.5 | G71: wheat | H71: 20 | I71: 1 | J71: 20.125 | K71: 20.125 | L71: 0 | M71: 20 | N71: 1 | O71: 18 | P71: 1 | Q71: 2 | R71: 0 | U71: 3 | V71: 8 | W71: 3 | X71: 4
A72: Expenses for ploughs | B72: . | C72: 0 | D72: 0 | E72: 0 | F72: 0 | H72: 0 | I72: 0 | J72: 0 | K72: 0 | L72: 0 | M72: 0 | N72: 0
A73: Expenses for ploughs | B73: 2.5 quarters of oats bought for sowing and the fodder of plough-horses 4 shilling 2pence, at 1 shilling 8pence a quarters. | C73: 0.21 | D73: 0 | E73: 4 | F73: 2 | G73: oats | H73: 2.5 | I73: 0 | J73: 2.5 | K73: 2.5 | L73: 0 | M73: 2.5 | N73: 0 | U73: 1 | V73: 8
A74: Expenses for ploughs | B74: . | C74: 0 | D74: 0 | E74: 0 | F74: 0 | H74: 0 | I74: 0 | J74: 0 | K74: 0 | L74: 0 | M74: 0 | N74: 0
...

Sheet Issues of the Grange raw
A1: Heading | B1: Sentence | C1: Quarters 1_x | D1: Bushels 1_x | E1: Sown Quarters | F1: Sown Bushels | G1: Sown Total Quarters | H1: Bought in Quarters | I1: Bought in Bushels | J1: Bought in Total Quarters | K1: Tithe Quarters | L1: Tithe Bushels | M1: Tithe Total Quarters | N1: Manorial servants & livestock Quarters | O1: Manorial servants & livestock Bushels | P1: Manorial servants & livestock Total Quarters | Q1: Sold Quarters | R1: Sold Bushels | S1: Sold Total Quarters | T1: Account Quarters | U1: Account Bushels | V1: Account Total Quarters | W1: bought only | X1: Total Quarters Except 1 | Y1: Total Bushels Except 1 | Z1: Total Corn Cross-Check | AA1: Total Corn Manorial Account | AB1: Corn Quantity Error | AC1: Quarters 1_y | AD1: Bushels 1_y | AE1: Quarters 2 | AF1: Bushels 2 | AG1: Quarters 3 | AH1: Bushels 3 | AI1: Quarters 4 | AJ1: Bushels 4
A2: Cash deliveries | B2: Total | C2: 0 | D2: 0 | E2: 0 | F2: 0 | G2: 0 | H2: 0 | I2: 0 | J2: 0 | K2: 0 | L2: 0 | M2: 0 | N2: 0 | O2: 0 | P2: 0 | Q2: 0 | R2: 0 | S2: 0 | T2: 0 | U2: 0 | V2: 0 | W2: 0
A3: Wheat | B3: {yield: three-fold less 4 quarters 2 bushels} | C3: 0 | D3: 0 | E3: 0 | F3: 0 | G3: 0 | H3: 0 | I3: 0 | J3: 0 | K3: 0 | L3: 0 | M3: 0 | N3: 0 | O3: 0 | P3: 0 | Q3: 0 | R3: 0 | S3: 0 | T3: 0 | U3: 0 | V3: 0 | W3: 0 | X3: 4 | Y3: 2 | Z3: 4.25 | AA3: 4.25 | AB3: 0 | AC3: 4 | AD3: 2
A4: Wheat | B4: (Henceforth no corn should be withheld for the stipends of the manorial servants. | C4: 0 | D4: 0 | E4: 0 | F4: 0 | G4: 0 | H4: 0 | I4: 0 | J4: 0 | K4: 0 | L4: 0 | M4: 0 | N4: 0 | O4: 0 | P4: 0 | Q4: 0 | R4: 0 | S4: 0 | T4: 0 | U4: 0 | V4: 0 | W4: 0 | X4: 0 | Y4: 0 | Z4: 0 | AA4: 0 | AB4: 0 | AC4: 0 | AD4: 0
A5: Wheat | B5: that is, money should be withheld for them, the best price that is able to be had, so that all the lord's corn reaches the grange} | C5: 0 | D5: 0 | E5: 0 | F5: 0 | G5: 0 | H5: 0 | I5: 0 | J5: 0 | K5: 0 | L5: 0 | M5: 0 | N5: 0 | O5: 0 | P5: 0 | Q5: 0 | R5: 0 | S5: 0 | T5: 0 | U5: 0 | V5: 0 | W5: 0 | X5: 0 | Y5: 0 | Z5: 0 | AA5: 0 | AB5: 0 | AC5: 0 | AD5: 0
A6: Wheat | B6: The same render account for 64 quarters 6 bushels from the whole issue of wheat from the grange in the granary by struck measure. | C6: 0 | D6: 0 | E6: 0 | F6: 0 | G6: 0 | H6: 0 | I6: 0 | J6: 0 | K6: 0 | L6: 0 | M6: 0 | N6: 0 | O6: 0 | P6: 0 | Q6: 0 | R6: 0 | S6: 0 | T6: 64 | U6: 6 | V6: 64.75 | W6: 0 | X6: 64 | Y6: 6 | Z6: 64.75 | AA6: 64.75 | AB6: 0 | AC6: 64 | AD6: 6
A7: Wheat | B7: 7.5 quarters by estimation in sheaves given to the manorial servants. | C7: 0 | D7: 0 | E7: 0 | F7: 0 | G7: 0 | H7: 0 | I7: 0 | J7: 0 | K7: 0 | L7: 0 | M7: 0 | N7: 0 | O7: 0 | P7: 0 | Q7: 0 | R7: 0 | S7: 0 | T7: 0 | U7: 0 | V7: 0 | W7: 0 | X7: 7.5 | Y7: 0 | Z7: 7.5 | AA7: 7.5 | AB7: 0 | AC7: 7.5 | AD7: 0
A8: Wheat | B8: 20 quarters 1 bushels bought. | C8: 0 | D8: 0 | E8: 0 | F8: 0 | G8: 0 | H8: 20 | I8: 1 | J8: 20.125 | K8: 0 | L8: 0 | M8: 0 | N8: 0 | O8: 0 | P8: 0 | Q8: 0 | R8: 0 | S8: 0 | T8: 0 | U8: 0 | V8: 0 | W8: 0 | X8: 20 | Y8: 1 | Z8: 20.125 | AA8: 20.125 | AB8: 0 | AC8: 20 | AD8: 1
A9: Wheat | B9: Total, 92 quarters 3 bushels | C9: 0 | D9: 0 | E9: 0 | F9: 0 | G9: 0 | H9: 0 | I9: 0 | J9: 0 | K9: 0 | L9: 0 | M9: 0 | N9: 0 | O9: 0 | P9: 0 | Q9: 0 | R9: 0 | S9: 0 | T9: 0 | U9: 0 | V9: 0 | W9: 0 | X9: 92 | Y9: 3 | Z9: 92.375 | AA9: 92.375 | AB9: 0 | AC9: 92 | AD9: 3
A10: Wheat | B10: Sown over 94 acres measured by the perch which lie in the fields of Buryfurlong, Rodelond, Cheldebreth', Langilond', Stockyng', Berhgforlong, Sevenacr', and Annaysbuttes, 35 quarters 1 bushels. | C10: 0 | D10: 0 | E10: 35 | F10: 1 | G10: 35.125 | H10: 0 | I10: 0 | J10: 0 | K10: 0 | L10: 0 | M10: 0 | N10: 0 | O10: 0 | P10: 0 | Q10: 0 | R10: 0 | S10: 0 | T10: 0 | U10: 0 | V10: 0 | W10: 0 | X10: 35 | Y10: 1 | Z10: 35.125 | AA10: 35.125 | AB10: 0 | AC10: 35 | AD10: 1
A11: Wheat | B11: that is, 3 bushels an acre, less 1 bushels in all. | C11: 0 | D11: 0 | E11: 0 | F11: 0 | G11: 0 | H11: 0 | I11: 0 | J11: 0 | K11: 0 | L11: 0 | M11: 0 | N11: 0 | O11: 0 | P11: 0 | Q11: 0 | R11: 0 | S11: 0 | T11: 0 | U11: 0 | V11: 0 | W11: 0 | X11: 0 | Y11: 1 | Z11: 0.125 | AA11: 0.375 | AB11: -0.25 | AC11: 0 | AD11: 3 | AE11: 0 | AF11: 1
A12: Wheat | B12: . | C12: 0 | D12: 0 | E12: 0 | F12: 0 | G12: 0 | H12: 0 | I12: 0 | J12: 0 | K12: 0 | L12: 0 | M12: 0 | N12: 0 | O12: 0 | P12: 0 | Q12: 0 | R12: 0 | S12: 0 | T12: 0 | U12: 0 | V12: 0 | W12: 0 | X12: 0 | Y12: 0 | Z12: 0 | AA12: 0 | AB12: 0 | AC12: 0 | AD12: 0
A13: Wheat | B13: bread for 2 harvest boon-works, 1 qr. | C13: 0 | D13: 0 | E13: 0 | F13: 0 | G13: 0 | H13: 0 | I13: 0 | J13: 0 | K13: 0 | L13: 0 | M13: 0 | N13: 0 | O13: 0 | P13: 0 | Q13: 0 | R13: 0 | S13: 0 | T13: 0 | U13: 0 | V13: 0 | W13: 0
A14: Wheat | B14: Given to 6 manorial servants this year, that is, 1 carter, 3 oxherds, 1 cowherd, 1 shepherd, for their stipends in summer by estimation in sheaves, 7.5 quarters, or 1 qr 2 bushels each. | C14: 0 | D14: 0 | E14: 0 | F14: 0 | G14: 0 | H14: 0 | I14: 0 | J14: 0 | K14: 0 | L14: 0 | M14: 0 | N14: 0 | O14: 0 | P14: 0 | Q14: 0 | R14: 0 | S14: 0 | T14: 0 | U14: 0 | V14: 0 | W14: 0
A15: Wheat | B15: Sold as noted above, 48 quarters 6 bushels | C15: 0 | D15: 0 | E15: 0 | F15: 0 | G15: 0 | H15: 0 | I15: 0 | J15: 0 | K15: 0 | L15: 0 | M15: 0 | N15: 0 | O15: 0 | P15: 0 | Q15: 48 | R15: 6 | S15: 48.75 | T15: 0 | U15: 0 | V15: 0 | W15: 0 | X15: 48 | Y15: 6 | Z15: 48.75 | AA15: 48.75 | AB15: 0 | AC15: 48 | AD15: 6
A16: Wheat | B16: Total | C16: 0 | D16: 0 | E16: 0 | F16: 0 | G16: 0 | H16: 0 | I16: 0 | J16: 0 | K16: 0 | L16: 0 | M16: 0 | N16: 0 | O16: 0 | P16: 0 | Q16: 0 | R16: 0 | S16: 0 | T16: 0 | U16: 0 | V16: 0 | W16: 0
A17: Curall | B17: The same render account for 13.5 quarters from the whole issue of curall of the same wheat from the grange in the granary by struck measure. | C17: 0 | D17: 0 | E17: 0 | F17: 0 | G17: 0 | H17: 0 | I17: 0 | J17: 0 | K17: 0 | L17: 0 | M17: 0 | N17: 0 | O17: 0 | P17: 0 | Q17: 0 | R17: 0 | S17: 0 | T17: 13.5 | U17: 0 | V17: 13.5 | W17: 0 | X17: 13.5 | Y17: 0 | Z17: 13.5 | AA17: 13.5 | AB17: 0 | AC17: 13.5 | AD17: 0
A18: Curall | B18: mixed below with beans for the liveries of the manorial servants, 13.5 quarters. | C18: 0 | D18: 0 | E18: 0 | F18: 0 | G18: 0 | H18: 0 | I18: 0 | J18: 0 | K18: 0 | L18: 0 | M18: 0 | N18: 13.5 | O18: 0 | P18: 13.5 | Q18: 0 | R18: 0 | S18: 0 | T18: 0 | U18: 0 | V18: 0 | W18: 0 | X18: 13.5 | Y18: 0 | Z18: 13.5 | AA18: 13.5 | AB18: 0 | AC18: 13.5 | AD18: 0
A19: Curall | B19: Total | C19: 0 | D19: 0 | E19: 0 | F19: 0 | G19: 0 | H19: 0 | I19: 0 | J19: 0 | K19: 0 | L19: 0 | M19: 0 | N19: 0 | O19: 0 | P19: 0 | Q19: 0 | R19: 0 | S19: 0 | T19: 0 | U19: 0 | V19: 0 | W19: 0
A20: Barley | B20: (yield: 4.5-fold plus 5.5 bushels} | C20: 0 | D20: 0 | E20: 0 | F20: 0 | G20: 0 | H20: 0 | I20: 0 | J20: 0 | K20: 0 | L20: 0 | M20: 0 | N20: 0 | O20: 0 | P20: 0 | Q20: 0 | R20: 0 | S20: 0 | T20: 0 | U20: 0 | V20: 0 | W20: 0 | X20: 0 | Y20: 5.5 | Z20: 0.6875 | AA20: 0.6875 | AB20: 0 | AC20: 0 | AD20: 5.5
A21: Barley | B21: The same render account for 65 quarters 3 bushels from the whole issue of barley and dredge from the grange in the granary by struck measure. | C21: 0 | D21: 0 | E21: 0 | F21: 0 | G21: 0 | H21: 0 | I21: 0 | J21: 0 | K21: 0 | L21: 0 | M21: 0 | N21: 0 | O21: 0 | P21: 0 | Q21: 0 | R21: 0 | S21: 0 | T21: 65 | U21: 3 | V21: 65.375 | W21: 0 | X21: 65 | Y21: 3 | Z21: 65.375 | AA21: 65.375 | AB21: 0 | AC21: 65 | AD21: 3
A22: Barley | B22: Sown over 48.5 acres measured by the perch which lie in Eldefeld', Gores and Buttes, 24 quarters 1 bushels. | C22: 0 | D22: 0 | E22: 24 | F22: 1 | G22: 24.125 | H22: 0 | I22: 0 | J22: 0 | K22: 0 | L22: 0 | M22: 0 | N22: 0 | O22: 0 | P22: 0 | Q22: 0 | R22: 0 | S22: 0 | T22: 0 | U22: 0 | V22: 0 | W22: 0 | X22: 24 | Y22: 1 | Z22: 24.125 | AA22: 24.125 | AB22: 0 | AC22: 24 | AD22: 1
A23: Barley | B23: that is, .5 qr an acre. | C23: 0 | D23: 0 | E23: 0 | F23: 0 | G23: 0 | H23: 0 | I23: 0 | J23: 0 | K23: 0 | L23: 0 | M23: 0 | N23: 0 | O23: 0 | P23: 0 | Q23: 0 | R23: 0 | S23: 0 | T23: 0 | U23: 0 | V23: 0 | W23: 0
A24: Barley | B24: Mixed below with beans for the liveries of the manorial servants 8 quarters 5 bushels Sold as noted above, 32.5 quarters 1 bushels | C24: 0 | D24: 0 | E24: 0 | F24: 0 | G24: 0 | H24: 0 | I24: 0 | J24: 0 | K24: 0 | L24: 0 | M24: 0 | N24: 40.5 | O24: 6 | P24: 41.25 | Q24: 40.5 | R24: 6 | S24: 41.25 | T24: 0 | U24: 0 | V24: 0 | W24: 0 | X24: 32.5 | Y24: 1 | Z24: 32.625 | AA24: 8.625 | AB24: 24 | AC24: 8 | AD24: 5 | AE24: 32.5 | AF24: 1
A25: Barley | B25: Total | C25: 0 | D25: 0 | E25: 0 | F25: 0 | G25: 0 | H25: 0 | I25: 0 | J25: 0 | K25: 0 | L25: 0 | M25: 0 | N25: 0 | O25: 0 | P25: 0 | Q25: 0 | R25: 0 | S25: 0 | T25: 0 | U25: 0 | V25: 0 | W25: 0
A26: Oats | B26: {yield: three-fold less 7 bushels} | C26: 0 | D26: 0 | E26: 0 | F26: 0 | G26: 0 | H26: 0 | I26: 0 | J26: 0 | K26: 0 | L26: 0 | M26: 0 | N26: 0 | O26: 0 | P26: 0 | Q26: 0 | R26: 0 | S26: 0 | T26: 0 | U26: 0 | V26: 0 | W26: 0 | X26: 0 | Y26: 7 | Z26: 0.875 | AA26: 0.875 | AB26: 0 | AC26: 0 | AD26: 7
A27: Oats | B27: The same render account for 2 quarters 7 bushels from the whole issue of oats from the grange in the granary by struck measure. | C27: 0 | D27: 0 | E27: 0 | F27: 0 | G27: 0 | H27: 0 | I27: 0 | J27: 0 | K27: 0 | L27: 0 | M27: 0 | N27: 0 | O27: 0 | P27: 0 | Q27: 0 | R27: 0 | S27: 0 | T27: 2 | U27: 7 | V27: 2.875 | W27: 0 | X27: 2 | Y27: 7 | Z27: 2.875 | AA27: 2.875 | AB27: 0 | AC27: 2 | AD27: 7
A28: Oats | B28: 6 quarters of oats by estimation in sheaves given to the manorial servants. | C28: 0 | D28: 0 | E28: 0 | F28: 0 | G28: 0 | H28: 0 | I28: 0 | J28: 0 | K28: 0 | L28: 0 | M28: 0 | N28: 0 | O28: 0 | P28: 0 | Q28: 0 | R28: 0 | S28: 0 | T28: 0 | U28: 0 | V28: 0 | W28: 0 | X28: 6 | Y28: 0 | Z28: 6 | AA28: 6 | AB28: 0 | AC28: 6 | AD28: 0
A29: Oats | B29: 2.5 quarters bought. | C29: 0 | D29: 0 | E29: 0 | F29: 0 | G29: 0 | H29: 2.5 | I29: 0 | J29: 2.5 | K29: 0 | L29: 0 | M29: 0 | N29: 0 | O29: 0 | P29: 0 | Q29: 0 | R29: 0 | S29: 0 | T29: 0 | U29: 0 | V29: 0 | W29: 0 | X29: 2.5 | Y29: 0 | Z29: 2.5 | AA29: 2.5 | AB29: 0 | AC29: 2.5 | AD29: 0
A30: Oats | B30: Total, 11 quarters 3 bushels | C30: 0 | D30: 0 | E30: 0 | F30: 0 | G30: 0 | H30: 0 | I30: 0 | J30: 0 | K30: 0 | L30: 0 | M30: 0 | N30: 0 | O30: 0 | P30: 0 | Q30: 0 | R30: 0 | S30: 0 | T30: 0 | U30: 0 | V30: 0 | W30: 0 | X30: 11 | Y30: 3 | Z30: 11.375 | AA30: 11.375 | AB30: 0 | AC30: 11 | AD30: 3
A31: Oats | B31: Sown over 3 acres measured by the perch which lie below Bereth', 2 quarters 2 bushels. | C31: 0 | D31: 0 | E31: 2 | F31: 2 | G31: 2.25 | H31: 0 | I31: 0 | J31: 0 | K31: 0 | L31: 0 | M31: 0 | N31: 0 | O31: 0 | P31: 0 | Q31: 0 | R31: 0 | S31: 0 | T31: 0 | U31: 0 | V31: 0 | W31: 0 | X31: 2 | Y31: 2 | Z31: 2.25 | AA31: 2.25 | AB31: 0 | AC31: 2 | AD31: 2
A32: Oats | B32: that is, 6 bushels an acre. | C32: 0 | D32: 0 | E32: 0 | F32: 0 | G32: 0 | H32: 0 | I32: 0 | J32: 0 | K32: 0 | L32: 0 | M32: 0 | N32: 0 | O32: 0 | P32: 0 | Q32: 0 | R32: 0 | S32: 0 | T32: 0 | U32: 0 | V32: 0 | W32: 0 | X32: 0 | Y32: 6 | Z32: 0.75 | AA32: 0.75 | AB32: 0 | AC32: 0 | AD32: 6
A33: Oats | B33: Given to 6 manorial servants, that is, 1 carter, 3 oxherds, 1 cowherd and 1 shepherd, for their stipends for .5 year in summer by estimation in sheaves, 6 quarters, or 1 qr each. | C33: 0 | D33: 0 | E33: 0 | F33: 0 | G33: 0 | H33: 0 | I33: 0 | J33: 0 | K33: 0 | L33: 0 | M33: 0 | N33: 0 | O33: 0 | P33: 0 | Q33: 0 | R33: 0 | S33: 0 | T33: 0 | U33: 0 | V33: 0 | W33: 0
A34: Oats | B34: . | C34: 0 | D34: 0 | E34: 0 | F34: 0 | G34: 0 | H34: 0 | I34: 0 | J34: 0 | K34: 0 | L34: 0 | M34: 0 | N34: 0 | O34: 0 | P34: 0 | Q34: 0 | R34: 0 | S34: 0 | T34: 0 | U34: 0 | V34: 0 | W34: 0 | X34: 0 | Y34: 0 | Z34: 0 | AA34: 0 | AB34: 0 | AC34: 0 | AD34: 0
A35: Oats | B35: fodder of 2 plough-horses hauling ploughs and harrows for the year, 3 quarters 1 bushels | C35: 0 | D35: 0 | E35: 0 | F35: 0 | G35: 0 | H35: 0 | I35: 0 | J35: 0 | K35: 0 | L35: 0 | M35: 0 | N35: 3 | O35: 1 | P35: 3.125 | Q35: 0 | R35: 0 | S35: 0 | T35: 0 | U35: 0 | V35: 0 | W35: 0 | X35: 3 | Y35: 1 | Z35: 3.125 | AA35: 3.125 | AB35: 0 | AC35: 3 | AD35: 1
A36: Oats | B36: Total | C36: 0 | D36: 0 | E36: 0 | F36: 0 | G36: 0 | H36: 0 | I36: 0 | J36: 0 | K36: 0 | L36: 0 | M36: 0 | N36: 0 | O36: 0 | P36: 0 | Q36: 0 | R36: 0 | S36: 0 | T36: 0 | U36: 0 | V36: 0 | W36: 0
A37: Beans | B37: {yield: four-fold less 1.5 quarters 3 bushels) | C37: 0 | D37: 0 | E37: 0 | F37: 0 | G37: 0 | H37: 0 | I37: 0 | J37: 0 | K37: 0 | L37: 0 | M37: 0 | N37: 0 | O37: 0 | P37: 0 | Q37: 0 | R37: 0 | S37: 0 | T37: 0 | U37: 0 | V37: 0 | W37: 0 | X37: 1.5 | Y37: 3 | Z37: 1.875 | AA37: 1.875 | AB37: 0 | AC37: 1.5 | AD37: 3
A38: Beans | B38: The same render account for 11 quarters 5 bushels remaining from the previous year. | C38: 0 | D38: 0 | E38: 0 | F38: 0 | G38: 0 | H38: 0 | I38: 0 | J38: 0 | K38: 0 | L38: 0 | M38: 0 | N38: 0 | O38: 0 | P38: 0 | Q38: 0 | R38: 0 | S38: 0 | T38: 11 | U38: 5 | V38: 11.625 | W38: 0 | X38: 11 | Y38: 5 | Z38: 11.625 | AA38: 11.625 | AB38: 0 | AC38: 11 | AD38: 5
A39: Beans | B39: 10 quarters 1 bushels from the whole issue from the grange in the granary by struck measure, because a certain part of 1 stack of beans was sold wholesale. | C39: 0 | D39: 0 | E39: 0 | F39: 0 | G39: 0 | H39: 0 | I39: 0 | J39: 0 | K39: 0 | L39: 0 | M39: 0 | N39: 0 | O39: 0 | P39: 0 | Q39: 10 | R39: 1 | S39: 10.125 | T39: 10 | U39: 1 | V39: 10.125 | W39: 0 | X39: 10 | Y39: 1 | Z39: 10.125 | AA39: 10.125 | AB39: 0 | AC39: 10 | AD39: 1
A40: Beans | B40: 13.5 quarters of curall received above and mixed with that for the liveries of the manorial servants. | C40: 0 | D40: 0 | E40: 0 | F40: 0 | G40: 0 | H40: 0 | I40: 0 | J40: 0 | K40: 0 | L40: 0 | M40: 0 | N40: 13.5 | O40: 0 | P40: 13.5 | Q40: 0 | R40: 0 | S40: 0 | T40: 0 | U40: 0 | V40: 0 | W40: 0 | X40: 13.5 | Y40: 0 | Z40: 13.5 | AA40: 13.5 | AB40: 0 | AC40: 13.5 | AD40: 0
...

Sheet Sale of Corn Prices
A1: Heading | B1: Sentence | C1: Total in Pounds | D1: Pounds | E1: Shillings | F1: Pence | G1: Corn | H1: Total Quarters Except 1 | I1: Total Bushels Except 1 | J1: Total Corn Cross-Check | K1: Total Corn Manorial Account | L1: Corn Quantity Error | M1: Quarters 0 | N1: Bushels 0 | O1: shilling a quarter 1 | P1: pence a quarter 1 | Q1: Quarters 1 | R1: Bushels 1 | S1: shilling a quarter 2 | T1: pence a quarter 2 | U1: Quarters 2 | V1: Bushels 2 | W1: shilling a quarter 3 | X1: pence a quarter 3 | Y1: Quarters 3 | Z1: Bushels 3 | AA1: shilling a quarter 4 | AB1: pence a quarter 4 | AC1: £ a quarter 1 | AD1: £ a quarter 2 | AE1: £ a quarter 3 | AF1: £ a quarter 4 | AG1: Quarters Sold | AH1: Weighted Average Price per Quarter | AI1: Non-Weighted Average Price per Quarter | AJ1: Corn lowercase
A2: Sale of corn | B2: The same render account for £10 16 shilling 9.5pence from 48 quarters 6 bushels of wheat sold, at 5 shilling a quarters for 25 quarters 1 bushels). 4 shilling a quarters for 18.5 quarters 1 bushels, and 3 shilling 4pence a quarters for 5 quarters. | C2: 10.84 | D2: 10 | E2: 16 | F2: 9.5 | G2: wheat | H2: 48.5 | I2: 2 | J2: 48.75 | K2: 48.75 | L2: 0 | M2: 48 | N2: 6 | O2: 5 | P2: 0 | Q2: 25 | R2: 1 | S2: 4 | T2: 0 | U2: 18.5 | V2: 1 | W2: 3 | X2: 4 | Y2: 5 | Z2: 0 | AC2: 0.25 | AD2: 0.2 | AE2: 0.16666667 | AG2: 48.75 | AH2: 0.22235043 | AI2: 0.20555556 | AJ2: wheat
A3: Sale of corn | B3: £5 8 shilling 9pence from 32.5 quarters I bushels of barley sold, at 3 shilling 4pence a quarters. | C3: 5.44 | D3: 5 | E3: 8 | F3: 9 | G3: barley | H3: 32.5 | I3: 0 | J3: 32.5 | K3: 32.5 | L3: 0 | M3: 32.5 | N3: 0 | O3: 3 | P3: 4 | AC3: 0.16666667 | AG3: 32.5 | AH3: 0.16666667 | AI3: 0.16666667 | AJ3: barley
A4: Sale of corn | B4: 2 shilling from 1 quarters of beans sold. | C4: 0.1 | D4: 0 | E4: 2 | F4: 0 | G4: beans | H4: 1 | I4: 0 | J4: 1 | K4: 1 | L4: 0 | M4: 1 | N4: 0 | AC4: 0.1 | AG4: 1 | AH4: 0.1 | AI4: 0.1 | AJ4: beans
A5: Sale of corn | B5: £1 6 shilling 8pence from a certain part of the stack of beans sold wholesale. | C5: 1.33 | D5: 1 | E5: 6 | F5: 8 | G5: beans | H5: 0 | I5: 0 | J5: 0 | K5: 0 | L5: 0 | M5: 0 | N5: 0 | AC5: inf | AG5: 0 | AH5: inf | AI5: inf | AJ5: beans
A6: Sale of corn | B6: Total, £17 14 shilling 2.5pence | C6: 17.71 | D6: 17 | E6: 14 | F6: 2.5 | H6: 0 | I6: 0 | J6: 0 | K6: 0 | L6: 0 | M6: 0 | N6: 0 | AC6: inf | AG6: 0 | AH6: inf | AI6: inf
