Workbook

Sheet Overton Borough Overview
A1: OVERTON BOROUGH | B1: £ | C1: s | D1: d | G1: Total in £ | H1: Error
A3: CASH ACCOUNT
A4: RECEIPTS
A5: Arrears total | G5: =IF(INDEX('Overton Borough Receipts'!$A$4:$F$70,MATCH('Overton Borough Overview'!$A5,'Overton Borough Receipts'!$A$4:$A$70,0),6)=0,"",INDEX('Overton Borough Receipts'!$A$4:$F$70,MATCH('Overton Borough Overview'!$A5,'Overton Borough Receipts'!$A$4:$A$70,0),6)) -> 2.0604167
A6: Rents of assize total | G6: =IF(INDEX('Overton Borough Receipts'!$A$4:$F$70,MATCH('Overton Borough Overview'!$A6,'Overton Borough Receipts'!$A$4:$A$70,0),6)=0,"",INDEX('Overton Borough Receipts'!$A$4:$F$70,MATCH('Overton Borough Overview'!$A6,'Overton Borough Receipts'!$A$4:$A$70,0),6)) -> 8.2145833
A7: Quittances total | G7: =IF(INDEX('Overton Borough Receipts'!$A$4:$F$70,MATCH('Overton Borough Overview'!$A7,'Overton Borough Receipts'!$A$4:$A$70,0),6)=0,"",INDEX('Overton Borough Receipts'!$A$4:$F$70,MATCH('Overton Borough Overview'!$A7,'Overton Borough Receipts'!$A$4:$A$70,0),6)) -> 0.1
A8: Defaults of rent total | G8: =IF(INDEX('Overton Borough Receipts'!$A$4:$F$70,MATCH('Overton Borough Overview'!$A8,'Overton Borough Receipts'!$A$4:$A$70,0),6)=0,"",INDEX('Overton Borough Receipts'!$A$4:$F$70,MATCH('Overton Borough Overview'!$A8,'Overton Borough Receipts'!$A$4:$A$70,0),6)) -> 0.025
A9: Annual recognizances total | G9: =IF(INDEX('Overton Borough Receipts'!$A$4:$F$70,MATCH('Overton Borough Overview'!$A9,'Overton Borough Receipts'!$A$4:$A$70,0),6)=0,"",INDEX('Overton Borough Receipts'!$A$4:$F$70,MATCH('Overton Borough Overview'!$A9,'Overton Borough Receipts'!$A$4:$A$70,0),6)) -> 0.025
A10: Issues of the Manor total | G10: =IF(INDEX('Overton Borough Receipts'!$A$4:$F$70,MATCH('Overton Borough Overview'!$A10,'Overton Borough Receipts'!$A$4:$A$70,0),6)=0,"",INDEX('Overton Borough Receipts'!$A$4:$F$70,MATCH('Overton Borough Overview'!$A10,'Overton Borough Receipts'!$A$4:$A$70,0),6)) -> 0.8
A11: Sale of corn total | G11: ='Overton Borough Receipts'!F44 -> 0
A12: Entry and marriage fines total | G12: =IF(INDEX('Overton Borough Receipts'!$A$4:$F$70,MATCH('Overton Borough Overview'!$A12,'Overton Borough Receipts'!$A$4:$A$70,0),6)=0,"",INDEX('Overton Borough Receipts'!$A$4:$F$70,MATCH('Overton Borough Overview'!$A12,'Overton Borough Receipts'!$A$4:$A$70,0),6))
A13: Pleas & perquisites total | G13: =IF(INDEX('Overton Borough Receipts'!$A$4:$F$70,MATCH('Overton Borough Overview'!$A13,'Overton Borough Receipts'!$A$4:$A$70,0),6)=0,"",INDEX('Overton Borough Receipts'!$A$4:$F$70,MATCH('Overton Borough Overview'!$A13,'Overton Borough Receipts'!$A$4:$A$70,0),6)) -> 3.2625
A14: Sum of the above (incl. arrears) | G14: =SUM(G5:G13)-SUM(G7:G8) -> 14.3625
A15: Total recorded in the accounts excl. arrears | G15: ='Overton Borough Receipts'!F69 -> 12.675 | H15: =G14-G15 -> 1.6875
A16: Total recorded in the accounts incl. arrears | G16: ='Overton Borough Receipts'!F70 -> 0
A19: EXPENSES
A20: Cost of ploughs total | G20: =IF(INDEX('Overton Borough Expenses'!$A$2:$F$120,MATCH('Overton Borough Overview'!$A20,'Overton Borough Expenses'!$A$2:$A$120,0),6)=0,"",INDEX('Overton Borough Expenses'!$A$2:$F$120,MATCH('Overton Borough Overview'!$A20,'Overton Borough Expenses'!$A$2:$A$120,0),6))
A21: Purchase of corn total | G21: =IF(INDEX('Overton Borough Expenses'!$A$2:$F$120,MATCH('Overton Borough Overview'!$A21,'Overton Borough Expenses'!$A$2:$A$120,0),6)=0,"",INDEX('Overton Borough Expenses'!$A$2:$F$120,MATCH('Overton Borough Overview'!$A21,'Overton Borough Expenses'!$A$2:$A$120,0),6))
A22: Cost of carts and wagons total | G22: =IF(INDEX('Overton Borough Expenses'!$A$2:$F$120,MATCH('Overton Borough Overview'!$A22,'Overton Borough Expenses'!$A$2:$A$120,0),6)=0,"",INDEX('Overton Borough Expenses'!$A$2:$F$120,MATCH('Overton Borough Overview'!$A22,'Overton Borough Expenses'!$A$2:$A$120,0),6))
A23: Cost of dairy total | G23: =IF(INDEX('Overton Borough Expenses'!$A$2:$F$120,MATCH('Overton Borough Overview'!$A23,'Overton Borough Expenses'!$A$2:$A$120,0),6)=0,"",INDEX('Overton Borough Expenses'!$A$2:$F$120,MATCH('Overton Borough Overview'!$A23,'Overton Borough Expenses'!$A$2:$A$120,0),6))
A24: Purchase of stock total | G24: =IF(INDEX('Overton Borough Expenses'!$A$2:$F$120,MATCH('Overton Borough Overview'!$A24,'Overton Borough Expenses'!$A$2:$A$120,0),6)=0,"",INDEX('Overton Borough Expenses'!$A$2:$F$120,MATCH('Overton Borough Overview'!$A24,'Overton Borough Expenses'!$A$2:$A$120,0),6))
A25: Sheepcote total | G25: =IF(INDEX('Overton Borough Expenses'!$A$2:$F$120,MATCH('Overton Borough Overview'!$A25,'Overton Borough Expenses'!$A$2:$A$120,0),6)=0,"",INDEX('Overton Borough Expenses'!$A$2:$F$120,MATCH('Overton Borough Overview'!$A25,'Overton Borough Expenses'!$A$2:$A$120,0),6))
A26: Cost of buildings total | G26: =IF(INDEX('Overton Borough Expenses'!$A$2:$F$120,MATCH('Overton Borough Overview'!$A26,'Overton Borough Expenses'!$A$2:$A$120,0),6)=0,"",INDEX('Overton Borough Expenses'!$A$2:$F$120,MATCH('Overton Borough Overview'!$A26,'Overton Borough Expenses'!$A$2:$A$120,0),6)) -> 0.25833333
A27: Threshing total | G27: =IF(INDEX('Overton Borough Expenses'!$A$2:$F$120,MATCH('Overton Borough Overview'!$A27,'Overton Borough Expenses'!$A$2:$A$120,0),6)=0,"",INDEX('Overton Borough Expenses'!$A$2:$F$120,MATCH('Overton Borough Overview'!$A27,'Overton Borough Expenses'!$A$2:$A$120,0),6))
A28: Expenses of the harvest total | G28: =IF(INDEX('Overton Borough Expenses'!$A$2:$F$120,MATCH('Overton Borough Overview'!$A28,'Overton Borough Expenses'!$A$2:$A$120,0),6)=0,"",INDEX('Overton Borough Expenses'!$A$2:$F$120,MATCH('Overton Borough Overview'!$A28,'Overton Borough Expenses'!$A$2:$A$120,0),6))
A29: Steward's expenses total | G29: =IF(INDEX('Overton Borough Expenses'!$A$2:$F$120,MATCH('Overton Borough Overview'!$A29,'Overton Borough Expenses'!$A$2:$A$120,0),6)=0,"",INDEX('Overton Borough Expenses'!$A$2:$F$120,MATCH('Overton Borough Overview'!$A29,'Overton Borough Expenses'!$A$2:$A$120,0),6))
A30: Sum of the above | G30: =SUM(G20:G29) -> 0.25833333
A31: Total of all expenses | G31: ='Overton Borough Expenses'!F115 -> 0 | H31: =G30-G31 -> 0.25833333
A32: Capital Expenses | G32: ='Overton Borough Expenses'!F120 -> 0.10416667
A34: Owed by the reeve
A35: From accounts
A37: Cash deliveries
A38: Total of all allowances and cash deliveries in accounts | B38: n/a
A40: Net amount owed
A41: Net amount owed in accounts | H41: =G40-G41 -> 0
A43: GRANGE ACCOUNT | B43: Net Production
A44: Grange | B44: qrs | G44: £ | I44: Note: Columns indexed are hardcoded, do not alter number of columns in issues of grange
A45: Net wheat | B45: =IF(INDEX('Issues of the Grange'!$A$2:$P$24,MATCH('Overton Borough Overview'!$A45,'Issues of the Grange'!$A$2:$A$24,0),10)=0,"",INDEX('Issues of the Grange'!$A$2:$P$24,MATCH('Overton Borough Overview'!$A45,'Issues of the Grange'!$A$2:$A$24,0),10)) -> #N/A | G45: =IF(INDEX('Issues of the Grange'!$A$2:$P$24,MATCH('Overton Borough Overview'!$A45,'Issues of the Grange'!$A$2:$A$24,0),13)=0,"",INDEX('Issues of the Grange'!$A$2:$P$24,MATCH('Overton Borough Overview'!$A45,'Issues of the Grange'!$A$2:$A$24,0),13)) -> #N/A
A46: Net curall | B46: =IF(INDEX('Issues of the Grange'!$A$2:$P$24,MATCH('Overton Borough Overview'!$A46,'Issues of the Grange'!$A$2:$A$24,0),10)=0,"",INDEX('Issues of the Grange'!$A$2:$P$24,MATCH('Overton Borough Overview'!$A46,'Issues of the Grange'!$A$2:$A$24,0),10)) -> #N/A | G46: =IF(INDEX('Issues of the Grange'!$A$2:$P$24,MATCH('Overton Borough Overview'!$A46,'Issues of the Grange'!$A$2:$A$24,0),13)=0,"",INDEX('Issues of the Grange'!$A$2:$P$24,MATCH('Overton Borough Overview'!$A46,'Issues of the Grange'!$A$2:$A$24,0),13)) -> #N/A
A47: Net barley | B47: =IF(INDEX('Issues of the Grange'!$A$2:$P$24,MATCH('Overton Borough Overview'!$A47,'Issues of the Grange'!$A$2:$A$24,0),10)=0,"",INDEX('Issues of the Grange'!$A$2:$P$24,MATCH('Overton Borough Overview'!$A47,'Issues of the Grange'!$A$2:$A$24,0),10)) -> #N/A | G47: =IF(INDEX('Issues of the Grange'!$A$2:$P$24,MATCH('Overton Borough Overview'!$A47,'Issues of the Grange'!$A$2:$A$24,0),13)=0,"",INDEX('Issues of the Grange'!$A$2:$P$24,MATCH('Overton Borough Overview'!$A47,'Issues of the Grange'!$A$2:$A$24,0),13)) -> #N/A
...

Sheet Overton Borough Receipts
A1: OVERTON BOROUGH RECEIPTS
B2: £ | C2: s | D2: d | F2: Total in £ | G2: Error | H2: Notes
A4: Arrears
A5: Arrears total | B5: 2 | C5: 1 | D5: 2.5 | F5: =B5+C5/20+D5/240 -> 2.0604167
A6: of which delivered to treasurer of Wolvesey | B6: 2 | C6: 1 | D6: 2.5 | F6: =B6+C6/20+D6/240 -> 2.0604167
A8: Rents of assize
A9: renst of assize for the year all paid at Michaelmas | B9: 8 | C9: 4 | D9: 3.5 | F9: =B9+C9/20+D9/240 -> 8.2145833
A10: Total recorded in accounts | B10: 8 | C10: 4 | D10: 3.5 | F10: =B10+C10/20+D10/240 -> 8.2145833
A11: Rents of assize total | B11: =SUM(B9:B9) -> 8 | C11: =SUM(C9:C9) -> 4 | D11: =SUM(D9:D9) -> 3.5 | F11: =B11+C11/20+D11/240 -> 8.2145833 | G11: =F11-F10 -> 0
A13: Quittances
A14: one reeve for the year | C14: 2 | F14: =B14+C14/20+D14/240 -> 0.1
A15: Total recorded in accounts | C15: 2 | F15: =B15+C15/20+D15/240 -> 0.1
A16: Quittances total | B16: =SUM(B14:B14) -> 0 | C16: =SUM(C14:C14) -> 2 | D16: =SUM(D14:D14) -> 0 | F16: =B16+C16/20+D16/240 -> 0.1 | G16: =F16-F15 -> 0
A18: Defaults of rent
A19: default of the house of Gilbert le Pynk | D19: 6 | F19: =B19+C19/20+D19/240 -> 0.025
A20: Total recorded in accounts | D20: 6 | F20: =B20+C20/20+D20/240 -> 0.025
A21: Defaults of rent total | B21: =SUM(B19:B19) -> 0 | C21: =SUM(C19:C19) -> 0 | D21: =SUM(D19:D19) -> 6 | F21: =B21+C21/20+D21/240 -> 0.025 | G21: =F21-F20 -> 0
A23: Total of rents remaining | B23: 8 | C23: 1 | D23: 9.5 | F23: =B23+C23/20+D23/240 -> 8.0895833 | H23: not included in receipts
A25: Wax
F26: =B26+C26/20+D26/240 -> 0
A27: Total recorded in accounts | F27: =B27+C27/20+D27/240 -> 0
A28: Wax total | B28: =SUM(B26) -> 0 | C28: =SUM(C26) -> 0 | D28: =SUM(D26) -> 0 | F28: =B28+C28/20+D28/240 -> 0 | G28: =F28-F27 -> 0
A30: Annual recognizances
A31: from Richard Hayward | D31: 6 | F31: =B31+C31/20+D31/240 -> 0.025
A32: Total recorded in accounts | D32: 6 | F32: =B32+C32/20+D32/240 -> 0.025
A33: Annual recognizances total | B33: =SUM(B31:B31) -> 0 | C33: =SUM(C31:C31) -> 0 | D33: =SUM(D31:D31) -> 6 | F33: =B33+C33/20+D33/240 -> 0.025 | G33: =F33-F32 -> 0
A35: Selds and stalls (no issue of the manor)
A36: 16 selds hired in the borough | C36: 10 | D36: 8 | F36: =B36+C36/20+D36/240 -> 0.53333333
A37: 32 stalls | C37: 5 | D37: 4 | F37: =B37+C37/20+D37/240 -> 0.26666667
A38: Total recorded in accounts | C38: 16 | F38: =B38+C38/20+D38/240 -> 0.8
A39: Issues of the manor total | B39: =SUM(B36:B37) -> 0 | C39: =SUM(C36:C37) -> 15 | D39: =SUM(D36:D37) -> 12 | F39: =B39+C39/20+D39/240 -> 0.8 | G39: =F39-F38 -> 0
A41: Sale of corn
A42: nothing | F42: =B42+C42/20+D42/240 -> 0
A43: Total recorded in accounts | F43: =B43+C43/20+D43/240 -> 0
A44: Sale of corn total | B44: =SUM(B42:B42) -> 0 | C44: =SUM(C42:C42) -> 0 | D44: =SUM(D42:D42) -> 0 | F44: =B44+C44/20+D44/240 -> 0 | G44: =F44-F43 -> 0
A46: Entry and marriage fines
A47: nothing | F47: =B47+C47/20+D47/240 -> 0
A48: Total recorded in accounts | F48: =B48+C48/20+D48/240 -> 0
A49: Entry and marriage fines total | B49: =SUM(B47:B47) -> 0 | C49: =SUM(C47:C47) -> 0 | D49: =SUM(D47:D47) -> 0 | F49: =B49+C49/20+D49/240 -> 0 | G49: =F49-F48 -> 0
A52: Farm of Freefolk
...

Sheet Overton Borough Expenses
A1: OVERTON BOROUGH EXPENSES
B2: £ | C2: s | D2: d | F2: Total in £ | G2: Error | H2: Notes
A3: Cost of Ploughs
F4: =B4+C4/20+D4/240 -> 0
F5: =B5+C5/20+D5/240 -> 0
F6: =B6+C6/20+D6/240 -> 0
F7: =B7+C7/20+D7/240 -> 0
F8: =B8+C8/20+D8/240 -> 0
F9: =B9+C9/20+D9/240 -> 0
F10: =B10+C10/20+D10/240 -> 0
F11: =B11+C11/20+D11/240 -> 0
F12: =B12+C12/20+D12/240 -> 0
F13: =B13+C13/20+D13/240 -> 0
F14: =B14+C14/20+D14/240 -> 0
F15: =B15+C15/20+D15/240 -> 0
A16: Total recorded in accounts | F16: =B16+C16/20+D16/240 -> 0
A17: Cost of ploughs total | B17: =SUM(B3:B15) -> 0 | C17: =SUM(C3:C15) -> 0 | D17: =SUM(D3:D15) -> 0 | F17: =B17+C17/20+D17/240 -> 0 | G17: =F17-F16 -> 0
A18: Total capital expenses | B18: =SUM(B4:B7,B9,B10:B11,B13,B15) -> 0 | C18: =SUM(C4:C7,C9,C10:C11,C13,C15) -> 0 | D18: =SUM(D4:D7,D9,D10:D11,D13,D15) -> 0 | F18: =B18+C18/20+D18/240 -> 0
A20: Purchase of Corn
F21: =B21+C21/20+D21/240 -> 0
A22: Total recorded in accounts | F22: =B22+C22/20+D22/240 -> 0
A23: Purchase of corn total | B23: =SUM(B21) -> 0 | C23: =SUM(C21) -> 0 | D23: =SUM(D21) -> 0 | F23: =B23+C23/20+D23/240 -> 0 | G23: =F23-F22 -> 0
A25: Cost of Carts and Wagons
F26: =B26+C26/20+D26/240 -> 0
F27: =B27+C27/20+D27/240 -> 0
F28: =B28+C28/20+D28/240 -> 0
F29: =B29+C29/20+D29/240 -> 0
F30: =B30+C30/20+D30/240 -> 0
F31: =B31+C31/20+D31/240 -> 0
F32: =B32+C32/20+D32/240 -> 0
F33: =B33+C33/20+D33/240 -> 0
F34: =B34+C34/20+D34/240 -> 0
F35: =B35+C35/20+D35/240 -> 0
F36: =B36+C36/20+D36/240 -> 0
F37: =B37+C37/20+D37/240 -> 0
... F40: =B40+C40/20+D40/240 -> 0
A41: Total recorded in accounts | F41: =B41+C41/20+D41/240 -> 0
A42: Cost of carts and wagons total | B42: =SUM(B26:B40) -> 0 | C42: =SUM(C26:C40) -> 0 | D42: =SUM(D26:D40) -> 0 | F42: =B42+C42/20+D42/240 -> 0 | G42: =F42-F41 -> 0
A43: Total capital expenses | B43: =SUM(B26:B39) -> 0 | C43: =SUM(C26:C39) -> 0 | D43: =SUM(D26:D39) -> 0 | F43: =B43+C43/20+D43/240 -> 0
A45: Cost of Dairy
...

Sheet Issues of the Grange
A1: no grange

Sheet Stock
A2: no stock account

Sheet Assumptions
A1: ASSUMPTIONS
B3: Weights | C3: Value (in lbs) | D3: Value (in cloves) | E3: Value (in weys) | F3: Value (in stone)
B4: Lbs | C4: 1 | D4: =C4/C5 -> 0.14285714 | E4: =C4/C6 -> 0.0057142857 | F4: =C4/C7 -> 0.08
B5: Cloves | C5: 7 | D5: 1 | E5: =C5/C6 -> 0.04 | F5: =C7/C5 -> 1.7857143
B6: Wey | C6: 175 | D6: =C6/C5 -> 25 | E6: =C6/C6 -> 1 | F6: =C7/C6 -> 0.071428571
B7: Stone | C7: =175/14 -> 12.5 | D7: =C5/C7 -> 0.56 | E7: =C7/C6 -> 0.071428571 | F7: 1
