Workbook

Sheet Overton Overview
A1: OVERTON OVERVIEW | B1: £ | C1: s | D1: d | G1: Total in £ | H1: Error
A2: CASH ACCOUNT
A3: RECEIPTS
A4: Arrears total | G4: =IF(INDEX('Overton Receipts'!$A$4:$F$171,MATCH('Overton Overview'!$A4,'Overton Receipts'!$A$4:$A$171,0),6)=0,"",INDEX('Overton Receipts'!$A$4:$F$171,MATCH('Overton Overview'!$A4,'Overton Receipts'!$A$4:$A$171,0),6)) -> 17.214583
A5: Rents of assize total | G5: =IF(INDEX('Overton Receipts'!$A$4:$F$171,MATCH('Overton Overview'!$A5,'Overton Receipts'!$A$4:$A$171,0),6)=0,"",INDEX('Overton Receipts'!$A$4:$F$171,MATCH('Overton Overview'!$A5,'Overton Receipts'!$A$4:$A$171,0),6)) -> 30.992708
A6: Quittances total | G6: =IF(INDEX('Overton Receipts'!$A$4:$F$171,MATCH('Overton Overview'!$A6,'Overton Receipts'!$A$4:$A$171,0),6)=0,"",INDEX('Overton Receipts'!$A$4:$F$171,MATCH('Overton Overview'!$A6,'Overton Receipts'!$A$4:$A$171,0),6)) -> 1.85
A7: Defaults of rent total | G7: =IF(INDEX('Overton Receipts'!$A$4:$F$171,MATCH('Overton Overview'!$A7,'Overton Receipts'!$A$4:$A$171,0),6)=0,"",INDEX('Overton Receipts'!$A$4:$F$171,MATCH('Overton Overview'!$A7,'Overton Receipts'!$A$4:$A$171,0),6)) -> 5.4625
A8: Annual recognizances total | G8: =IF(INDEX('Overton Receipts'!$A$4:$F$171,MATCH('Overton Overview'!$A8,'Overton Receipts'!$A$4:$A$171,0),6)=0,"",INDEX('Overton Receipts'!$A$4:$F$171,MATCH('Overton Overview'!$A8,'Overton Receipts'!$A$4:$A$171,0),6))
A9: Issues of the Manor total | G9: =IF(INDEX('Overton Receipts'!$A$4:$F$171,MATCH('Overton Overview'!$A9,'Overton Receipts'!$A$4:$A$171,0),6)=0,"",INDEX('Overton Receipts'!$A$4:$F$171,MATCH('Overton Overview'!$A9,'Overton Receipts'!$A$4:$A$171,0),6)) -> 23.0125
A10: Sale of corn total | G10: =IF(INDEX('Overton Receipts'!$A$4:$F$171,MATCH('Overton Overview'!$A10,'Overton Receipts'!$A$4:$A$171,0),6)=0,"",INDEX('Overton Receipts'!$A$4:$F$171,MATCH('Overton Overview'!$A10,'Overton Receipts'!$A$4:$A$171,0),6)) -> 41.472917
A11: Entry and marriage fines total | G11: =IF(INDEX('Overton Receipts'!$A$4:$F$171,MATCH('Overton Overview'!$A11,'Overton Receipts'!$A$4:$A$171,0),6)=0,"",INDEX('Overton Receipts'!$A$4:$F$171,MATCH('Overton Overview'!$A11,'Overton Receipts'!$A$4:$A$171,0),6)) -> 4.8
A12: Pleas & perquisites total | G12: =IF(INDEX('Overton Receipts'!$A$4:$F$171,MATCH('Overton Overview'!$A12,'Overton Receipts'!$A$4:$A$171,0),6)=0,"",INDEX('Overton Receipts'!$A$4:$F$171,MATCH('Overton Overview'!$A12,'Overton Receipts'!$A$4:$A$171,0),6)) -> 4.9625
A13: Sum of the above (incl. arrears) | G13: ='Overton Receipts'!F169 -> 126.49479
A14: Total recorded in the accounts excl. arrears | G14: ='Overton Receipts'!F170 -> 109.28229 | H14: =G13-G14 -> 17.2125 | I14: difference is arrears
A15: Total recorded in the accounts incl. arrears | G15: ='Overton Receipts'!F171 -> 0 | I15: not recorded
A18: EXPENSES
A19: Cost of ploughs total | G19: =IF(INDEX('Overton Expenses'!$A$2:$F$156,MATCH('Overton Overview'!$A19,'Overton Expenses'!$A$2:$A$156,0),6)=0,"",INDEX('Overton Expenses'!$A$2:$F$156,MATCH('Overton Overview'!$A19,'Overton Expenses'!$A$2:$A$156,0),6)) -> 6.2604167
A20: Purchase of corn total | G20: =IF(INDEX('Overton Expenses'!$A$2:$F$156,MATCH('Overton Overview'!$A20,'Overton Expenses'!$A$2:$A$156,0),6)=0,"",INDEX('Overton Expenses'!$A$2:$F$156,MATCH('Overton Overview'!$A20,'Overton Expenses'!$A$2:$A$156,0),6))
A21: Cost of carts and wagons total | G21: =IF(INDEX('Overton Expenses'!$A$2:$F$156,MATCH('Overton Overview'!$A21,'Overton Expenses'!$A$2:$A$156,0),6)=0,"",INDEX('Overton Expenses'!$A$2:$F$156,MATCH('Overton Overview'!$A21,'Overton Expenses'!$A$2:$A$156,0),6)) -> 1.775
A22: Cost of dairy total | G22: =IF(INDEX('Overton Expenses'!$A$2:$F$156,MATCH('Overton Overview'!$A22,'Overton Expenses'!$A$2:$A$156,0),6)=0,"",INDEX('Overton Expenses'!$A$2:$F$156,MATCH('Overton Overview'!$A22,'Overton Expenses'!$A$2:$A$156,0),6)) -> 0.54583333
A23: Purchase of stock total | G23: =IF(INDEX('Overton Expenses'!$A$2:$F$156,MATCH('Overton Overview'!$A23,'Overton Expenses'!$A$2:$A$156,0),6)=0,"",INDEX('Overton Expenses'!$A$2:$F$156,MATCH('Overton Overview'!$A23,'Overton Expenses'!$A$2:$A$156,0),6))
A24: Sheepcote total | G24: =IF(INDEX('Overton Expenses'!$A$2:$F$156,MATCH('Overton Overview'!$A24,'Overton Expenses'!$A$2:$A$156,0),6)=0,"",INDEX('Overton Expenses'!$A$2:$F$156,MATCH('Overton Overview'!$A24,'Overton Expenses'!$A$2:$A$156,0),6)) -> 7.2708333
A25: Cost of buildings total | G25: =IF(INDEX('Overton Expenses'!$A$2:$F$156,MATCH('Overton Overview'!$A25,'Overton Expenses'!$A$2:$A$156,0),6)=0,"",INDEX('Overton Expenses'!$A$2:$F$156,MATCH('Overton Overview'!$A25,'Overton Expenses'!$A$2:$A$156,0),6)) -> 2.4875
A26: Threshing total | G26: =IF(INDEX('Overton Expenses'!$A$2:$F$156,MATCH('Overton Overview'!$A26,'Overton Expenses'!$A$2:$A$156,0),6)=0,"",INDEX('Overton Expenses'!$A$2:$F$156,MATCH('Overton Overview'!$A26,'Overton Expenses'!$A$2:$A$156,0),6)) -> 1.5083333
A27: Expenses of the harvest total | G27: =IF(INDEX('Overton Expenses'!$A$2:$F$156,MATCH('Overton Overview'!$A27,'Overton Expenses'!$A$2:$A$156,0),6)=0,"",INDEX('Overton Expenses'!$A$2:$F$156,MATCH('Overton Overview'!$A27,'Overton Expenses'!$A$2:$A$156,0),6)) -> 1.2239583
A28: Steward's expenses total | G28: =IF(INDEX('Overton Expenses'!$A$2:$F$156,MATCH('Overton Overview'!$A28,'Overton Expenses'!$A$2:$A$156,0),6)=0,"",INDEX('Overton Expenses'!$A$2:$F$156,MATCH('Overton Overview'!$A28,'Overton Expenses'!$A$2:$A$156,0),6)) -> 2.2208333
A29: Sum of the above | G29: ='Overton Expenses'!F149 -> 23.844792
A30: Total of all expenses | G30: ='Overton Expenses'!F148 -> 25.926042 | H30: =G29-G30 -> -2.08125
A31: Capital Expenses | G31: ='Overton Expenses'!F157 -> 8.5708333
A33: Owed by the reeve | G33: =G13-G29-G4 -> 85.435417
A34: From accounts | G34: ='Overton Expenses'!F151 -> 83.35625 | H34: =G34-G33 -> -2.0791667
A36: Cash deliveries | G36: ='Overton Expenses'!F153 -> 40.45
A37: Total of all allowances and cash deliveries in accounts | B37: n/a | G37: =G36 -> 40.45
A39: Net amount owed | G39: =G34-G37 -> 42.90625
A40: Net amount owed in accounts | G40: ='Overton Expenses'!F154 -> 42.90625 | H40: =G39-G40 -> 0
A42: GRANGE ACCOUNT | B42: Net Production | G42: Value of net production | H42: Value of total gross production in £
A43: Grange | B43: qrs | G43: £ | H43: £ | I43: Note: Columns indexed are hardcoded, do not alter number of columns in issues of grange
A44: Net wheat | B44: ='Issues of the Grange'!L19 -> 45.75 | G44: ='Issues of the Grange'!O19 -> 12.390625 | H44: ='Issues of the Grange'!T5 -> 17.908854
A45: Net curall | B45: ='Issues of the Grange'!L20 -> 2 | G45: ='Issues of the Grange'!O20 -> 0.4 | H45: ='Issues of the Grange'!T6 -> 0.45
A46: Net barley | B46: ='Issues of the Grange'!L21 -> 17 | G46: ='Issues of the Grange'!O21 -> 2.975 | H46: ='Issues of the Grange'!T7 -> 17.11875
...

Sheet Overton Receipts
A1: Overton RECEIPTS
B2: £ | C2: s | D2: d | F2: Total in £ | G2: Error | H2: Notes
A4: Arrears
A5: Arrears total | B5: 17 | C5: 4 | D5: 3.5 | F5: =B5+C5/20+D5/240 -> 17.214583
A6: of which delivered to treasurer of Wolvesey | B6: 17 | C6: 4 | D6: 3.5 | F6: =B6+C6/20+D6/240 -> 17.214583
A8: Rents of assize
A9: rents of assize Christmas | B9: 6 | C9: 6 | F9: =B9+C9/20+D9/240 -> 6.3
A10: Easter | B10: 6 | C10: 11 | D10: 4 | F10: =B10+C10/20+D10/240 -> 6.5666667
A11: Nativity | B11: 6 | C11: 3 | D11: 4 | F11: =B11+C11/20+D11/240 -> 6.1666667
A12: Michaelmas | B12: 11 | C12: 19 | D12: 2.25 | F12: =B12+C12/20+D12/240 -> 11.959375
A13: Total recorded in accounts | B13: 30 | C13: 19 | D13: 10.25 | F13: =B13+C13/20+D13/240 -> 30.992708
A14: Rents of assize total | B14: =SUM(B9:B12) -> 29 | C14: =SUM(C9:C12) -> 39 | D14: =SUM(D9:D12) -> 10.25 | F14: =B14+C14/20+D14/240 -> 30.992708 | G14: =F14-F13 -> 0
A16: Quittances
A17: quittance for 1 reeve for the year | C17: 5 | F17: =B17+C17/20+D17/240 -> 0.25
A18: 1 bartoner for the year | C18: 3 | F18: =B18+C18/20+D18/240 -> 0.15
A19: 2 haywards | C19: 6 | F19: =B19+C19/20+D19/240 -> 0.3
A20: 3 ploughmen for the year | C20: 9 | F20: =B20+C20/20+D20/240 -> 0.45
A21: 1 ploughman | C21: 1 | D21: 6 | F21: =B21+C21/20+D21/240 -> 0.075
A22: 1 smith for the year | C22: 3 | F22: =B22+C22/20+D22/240 -> 0.15
A23: 2 shepherds for the year | C23: 6 | F23: =B23+C23/20+D23/240 -> 0.3
A24: 1 keeper of hoggs | D24: 6 | F24: =B24+C24/20+D24/240 -> 0.025
A25: 1 cowherd | C25: 3 | F25: =B25+C25/20+D25/240 -> 0.15
F26: =B26+C26/20+D26/240 -> 0
A27: Total recorded in accounts | B27: 1 | C27: 17 | F27: =B27+C27/20+D27/240 -> 1.85
A28: Quittances total | B28: =SUM(B17:B26) -> 0 | C28: =SUM(C17:C26) -> 36 | D28: =SUM(D17:D26) -> 12 | F28: =B28+C28/20+D28/240 -> 1.85 | G28: =F28-F27 -> 0
A30: Defaults of rent
A31: default of the mill of Lynch | B31: 1 | F31: =B31+C31/20+D31/240 -> 1
A32: the land of Bascon drawn | C32: 3 | F32: =B32+C32/20+D32/240 -> 0.15
A33: land of Strockyng drawn | C33: 3 | F33: =B33+C33/20+D33/240 -> 0.15
A34: ... | C34: 3 | F34: =B34+C34/20+D34/240 -> 0.15
A35: ... | C35: 1 | F35: =B35+C35/20+D35/240 -> 0.05
A36: ... | C36: 1 | D36: 6 | F36: =B36+C36/20+D36/240 -> 0.075
A37: ... | C37: 1 | D37: 6 | F37: =B37+C37/20+D37/240 -> 0.075
A38: the land of le Cran | C38: 2 | F38: =B38+C38/20+D38/240 -> 0.1
A39: ... | C39: 2 | F39: =B39+C39/20+D39/240 -> 0.1
A40: land of William | C40: 1 | D40: 6 | F40: =B40+C40/20+D40/240 -> 0.075
A41: ... | C41: 2 | F41: =B41+C41/20+D41/240 -> 0.1
A42: land of Codeboye | C42: 2 | F42: =B42+C42/20+D42/240 -> 0.1
A43: ... | C43: 2 | F43: =B43+C43/20+D43/240 -> 0.1
A44: ... | C44: 1 | D44: 10 | F44: =B44+C44/20+D44/240 -> 0.091666667
...

Sheet Overton Expenses
A1: OVERTON EXPENSES
B2: £ | C2: s | D2: d | F2: Total in £ | G2: Error | H2: Notes | J2: fixed investment | K2: demesne investment
A3: Cost of Ploughs
A4: iron and steel | C4: 10 | D4: 6 | F4: =B4+C4/20+D4/240 -> 0.525 | J4: =F4 -> 0.525 | K4: =J4 -> 0.525
A5: 2 plougshares | C5: 1 | D5: 8 | F5: =B5+C5/20+D5/240 -> 0.083333333 | J5: =F5 -> 0.083333333 | K5: =J5 -> 0.083333333
A6: plough feet | C6: 1 | D6: 9 | F6: =B6+C6/20+D6/240 -> 0.0875 | J6: =F6 -> 0.0875 | K6: =J6 -> 0.0875
A7: 2 ploughs made anew | D7: 6 | F7: =B7+C7/20+D7/240 -> 0.025 | J7: =F7 -> 0.025 | K7: =J7 -> 0.025
A8: fitting the same and others with iron tyres | D8: 6.5 | F8: =B8+C8/20+D8/240 -> 0.027083333 | J8: =F8 -> 0.027083333 | K8: =J8 -> 0.027083333
A9: 7 pairs of wheels | D9: 7 | F9: =B9+C9/20+D9/240 -> 0.029166667 | J9: =F9 -> 0.029166667 | K9: =J9 -> 0.029166667
A10: old ploughs fitted with share-beams | D10: 6 | F10: =B10+C10/20+D10/240 -> 0.025 | J10: =F10 -> 0.025 | K10: =J10 -> 0.025
A11: 14 halters made | D11: 3.5 | F11: =B11+C11/20+D11/240 -> 0.014583333 | J11: =F11 -> 0.014583333 | K11: =J11 -> 0.014583333
A12: shoeing 9 plough-horses | C12: 9 | F12: =B12+C12/20+D12/240 -> 0.45 | J12: =F12 -> 0.45 | K12: =J12 -> 0.45
A13: shoeing horses | D13: 11 | F13: =B13+C13/20+D13/240 -> 0.045833333 | J13: =F13 -> 0.045833333 | K13: =J13 -> 0.045833333
A14: in ale and relish for boon-works | C14: 6 | D14: 8 | F14: =B14+C14/20+D14/240 -> 0.33333333
A15: stipend of 3 oxherds | C15: 9 | F15: =B15+C15/20+D15/240 -> 0.45
A16: 2 oxen bought | B16: 1 | C16: 2 | D16: 8 | F16: =B16+C16/20+D16/240 -> 1.1333333
A17: wheat bought | C17: 6 | D17: 3 | F17: =B17+C17/20+D17/240 -> 0.3125
A18: bere bought | B18: 1 | C18: 4 | D18: 8.5 | F18: =B18+C18/20+D18/240 -> 1.2354167
A19: barly bought | B19: 1 | C19: 6 | D19: 1.5 | F19: =B19+C19/20+D19/240 -> 1.30625
A20: peas bought | C20: 1 | D20: 8 | F20: =B20+C20/20+D20/240 -> 0.083333333
A21: vetches bought | C21: 1 | D21: 10.5 | F21: =B21+C21/20+D21/240 -> 0.09375
A22: Total recorded in accounts | B22: 6 | C22: 5 | D22: 2.5 | F22: =B22+C22/20+D22/240 -> 6.2604167
A23: Cost of ploughs total | B23: =SUM(B3:B21) -> 3 | C23: =SUM(C3:C21) -> 56 | D23: =SUM(D3:D21) -> 110.5 | F23: =B23+C23/20+D23/240 -> 6.2604167 | G23: =F23-F22 -> 0
A25: Purchase of Corn
A26: nothing | F26: =B26+C26/20+D26/240 -> 0
A27: Total recorded in accounts | F27: =B27+C27/20+D27/240 -> 0
A28: Purchase of corn total | B28: =SUM(B26) -> 0 | C28: =SUM(C26) -> 0 | D28: =SUM(D26) -> 0 | F28: =B28+C28/20+D28/240 -> 0 | G28: =F28-F27 -> 0
A30: Cost of Carts and Wagons
A31: 1 pair of wheels | C31: 2 | F31: =B31+C31/20+D31/240 -> 0.1 | J31: =F31 -> 0.1 | K31: =J31 -> 0.1
A32: fitting an old binding incl. stipend of smith | C32: 3 | D32: 4 | F32: =B32+C32/20+D32/240 -> 0.16666667 | J32: =F32 -> 0.16666667 | K32: =J32 -> 0.16666667
A33: in hooping the felloes of the cart | D33: 3 | F33: =B33+C33/20+D33/240 -> 0.0125 | J33: =F33 -> 0.0125 | K33: =J33 -> 0.0125
A34: clouts, nails, grease and white leather | C34: 1 | D34: 0.5 | F34: =B34+C34/20+D34/240 -> 0.052083333 | J34: =F34 -> 0.052083333 | K34: =J34 -> 0.052083333
A35: fitting the cart with axles | D35: 6 | F35: =B35+C35/20+D35/240 -> 0.025 | J35: =F35 -> 0.025 | K35: =J35 -> 0.025
A36: mending the old cart | D36: 9 | F36: =B36+C36/20+D36/240 -> 0.0375 | J36: =F36 -> 0.0375 | K36: =J36 -> 0.0375
A37: 1 pair of traces bought | D37: 4 | F37: =B37+C37/20+D37/240 -> 0.016666667 | J37: =F37 -> 0.016666667 | K37: =J37 -> 0.016666667
A38: in 1 collar and 1 pair of tie-beams | C38: 1 | F38: =B38+C38/20+D38/240 -> 0.05 | J38: =F38 -> 0.05 | K38: =J38 -> 0.05
A39: in 1 halter bought | D39: 0.5 | F39: =B39+C39/20+D39/240 -> 0.0020833333 | J39: =F39 -> 0.0020833333 | K39: =J39 -> 0.0020833333
A40: in 1 pair of wheels made for dung | D40: 9 | F40: =B40+C40/20+D40/240 -> 0.0375 | J40: =F40 -> 0.0375 | K40: =J40 -> 0.0375
A41: in shoeing 2 cart-horses | C41: 2 | D41: 6 | F41: =B41+C41/20+D41/240 -> 0.125 | J41: =F41 -> 0.125 | K41: =J41 -> 0.125
A42: in 1 cart-horse bought | B42: 1 | F42: =B42+C42/20+D42/240 -> 1
...

Sheet Issues of the Grange
B1: The issue of the grange account gives the total "yield" at the top of each heading in curly brackets, measurements used: fold, qrs, bus
B2: In "Issues of the grange" (p.96ff) | I2: In "Sale of Corn" (p.93) | T2: Value of Total Production
A3: Gross output | B3: Quantity | D3: Additional bought-in | F3: from previous year | H3: Quantity | I3: Quantity noted as sold | L3: Difference Produced vs. Sold | M3: Price 1 | N3: Quantity 1 | O3: Price 2 | P3: Quantity 2 | Q3: Price 3 | R3: Quantity 3 | S3: Unit price | T3: Value
B4: qrs | C4: bus | D4: qrs | E4: bus | F4: qrs | G4: bus | H4: qrs | I4: qrs | J4: bus | K4: qrs | M4: £ | N4: qrs | O4: £ | P4: qrs | Q4: £ | R4: qrs | S4: £ per qr | T4: £
A5: Wheat | B5: 64 | C5: 7 | D5: 1 | E5: 2 | H5: =B5+D5+F5+C5/8+E5/8+G5/8 -> 66.125 | I5: 50.5 | K5: =I5+J5/8 -> 50.5 | L5: =H5-K5 -> 15.625 | M5: =5/20+6/240 -> 0.275 | N5: 1 | O5: =5/20+4/240 -> 0.26666667 | P5: 1 | Q5: =6/20 -> 0.3 | R5: 1 | S5: =IFERROR((M5+O5)/(N5+P5),0) -> 0.27083333 | T5: =S5*H5 -> 17.908854
A6: Curall | B6: 2 | C6: 2 | H6: =B6+D6+F6+C6/8+E6/8+G6/8 -> 2.25 | I6: 2 | J6: 2 | K6: =I6+J6/8 -> 2.25 | L6: =H6-K6 -> 0 | M6: =4/20 -> 0.2 | N6: 1 | S6: =IFERROR((M6+O6)/(N6+P6),0) -> 0.2 | T6: =S6*H6 -> 0.45
A7: Bere | B7: =83+2+1+2 -> 88 | C7: 3 | D7: 12 | E7: 2 | F7: 13.5 | H7: =B7+D7+F7+C7/8+E7/8+G7/8 -> 114.125 | I7: 48 | J7: 2 | K7: =I7+J7/8 -> 48.25 | L7: =H7-K7 -> 65.875 | M7: =3/20 -> 0.15 | N7: 1 | S7: =IFERROR((M7+O7)/(N7+P7),0) -> 0.15 | T7: =S7*H7 -> 17.11875
A8: Barley | B8: 81.5 | D8: 7 | E8: 1 | H8: =B8+D8+F8+C8/8+E8/8+G8/8 -> 88.625 | I8: 75 | J8: 5 | K8: =I8+J8/8 -> 75.625 | L8: =H8-K8 -> 13 | M8: =3/20 -> 0.15 | N8: 1 | O8: =4/20 -> 0.2 | P8: 1 | S8: =IFERROR((M8+O8)/(N8+P8),0) -> 0.175 | T8: =S8*H8 -> 15.509375
A9: Oats | B9: 144 | C9: 3.5 | H9: =B9+D9+F9+C9/8+E9/8+G9/8 -> 144.4375 | I9: 37 | K9: =I9+J9/8 -> 37 | L9: =H9-K9 -> 107.4375 | M9: =2/20 -> 0.1 | N9: 1 | O9: =2/20+6/240 -> 0.125 | P9: 1 | S9: =IFERROR((M9+O9)/(N9+P9),0) -> 0.1125 | T9: =S9*H9 -> 16.249219
A10: Peas | B10: 1 | C10: 5 | H10: =B10+D10+F10+C10/8+E10/8+G10/8 -> 1.625 | I10: 1 | J10: 1 | K10: =I10+J10/8 -> 1.125 | L10: =H10-K10 -> 0.5 | M10: =3/20 -> 0.15 | N10: 1 | S10: =IFERROR((M10+O10)/(N10+P10),0) -> 0.15 | T10: =S10*H10 -> 0.24375
A11: Vetches | B11: 3 | C11: 3 | D11: 1 | E11: 1 | F11: 1 | H11: =B11+D11+F11+C11/8+E11/8+G11/8 -> 5.5 | I11: 4 | J11: 3 | K11: =I11+J11/8 -> 4.375 | L11: =H11-K11 -> 1.125 | M11: =1/20 -> 0.05 | N11: 1 | S11: =IFERROR((M11+O11)/(N11+P11),0) -> 0.05 | T11: =S11*H11 -> 0.275
A13: Total Production | H13: =SUM(H5:H11) -> 422.6875 | T13: =SUM(T5:T11) -> 67.754948 | U13: Production value is significantly more, as much less was sold than what was produced
A14: Sales of corn (as recorded in accounts) | H14: =SUM(K5:K11) -> 219.125 | T14: =41+9/20+5.5/240 -> 41.472917
A17: Net output | B17: Gross output | C17: Seed | H17: tithe | I17: to manorial servants & livestock | L17: Output net of tithe & seed & liveries to manorial servants | M17: in stock from last year | N17: Price | O17: Value of net output | P17: Value of sales (in "Sale of Corn")
B18: qrs | C18: qrs | D18: bus | E18: qrs | H18: qrs | I18: qrs | J18: bus | K18: qrs | L18: qrs | M18: qrs | N18: £ per qr | O18: £ | P18: £
A19: Net wheat | B19: =B5 -> 64 | C19: 11 | D19: 2 | E19: =C19+D19/8 -> 11.25 | I19: =3+4 -> 7 | K19: =I19+J19/8 -> 7 | L19: =B19-(E19+H19+K19) -> 45.75 | N19: =S5 -> 0.27083333 | O19: =N19*L19 -> 12.390625 | P19: =S5*K5 -> 13.677083
A20: Net curall | B20: =B6 -> 2 | E20: =C20+D20/8 -> 0 | K20: =I20+J20/8 -> 0 | L20: =B20-(E20+H20+K20) -> 2 | N20: =S6 -> 0.2 | O20: =N20*L20 -> 0.4 | P20: =S6*K6 -> 0.45
A21: Net barley | B21: =B8 -> 81.5 | C21: 20 | D21: 1 | E21: =C21+D21/8 -> 20.125 | I21: =26+4+4+1.5+3+2+1+2 -> 43.5 | J21: =7 -> 7 | K21: =I21+J21/8 -> 44.375 | L21: =B21-(E21+H21+K21) -> 17 | N21: =S8 -> 0.175 | O21: =N21*L21 -> 2.975 | P21: =S8*K8 -> 13.234375
A22: Net oats | B22: =B9 -> 144 | C22: 65 | E22: =C22+D22/8 -> 65 | I22: =15+12+10+1+4 -> 42 | J22: =2+1.5 -> 3.5 | K22: =I22+J22/8 -> 42.4375 | L22: =B22-(E22+H22+K22) -> 36.5625 | N22: =S9 -> 0.1125 | O22: =N22*L22 -> 4.1132812 | P22: =S9*K9 -> 4.1625
A23: Net peas | B23: =B10 -> 1 | D23: 4 | E23: =C23+D23/8 -> 0.5 | K23: =I23+J23/8 -> 0 | L23: =B23-(E23+H23+K23) -> 0.5 | N23: =S10 -> 0.15 | O23: =N23*L23 -> 0.075 | P23: =S10*K10 -> 0.16875
A24: Net vetches | B24: =B11 -> 3 | C24: 1 | D24: 1 | E24: =C24+D24/8 -> 1.125 | K24: =I24+J24/8 -> 0 | L24: =B24-(E24+H24+K24) -> 1.875 | N24: =S11 -> 0.05 | O24: =N24*L24 -> 0.09375 | P24: =S11*K11 -> 0.21875
A25: Total | B25: =SUM(B19:B24) -> 295.5 | E25: =SUM(E19:E24) -> 98 | L25: =SUM(L19:L24) -> 103.6875 | O25: =SUM(O19:O24) -> 20.047656 | P25: =SUM(P19:P24) -> 31.911458

Sheet Issues of the Mill
A1: OVERTON MILL ACCOUNT
B2: In "Issue of the Mill" (p.98) | F2: In "Mills" (p.95) | P2: Value of Total Production
B3: Quantity | D3: Quantity (produced) | E3: Quantity (produced) | F3: Prices per qr | H3: Prices per bus | J3: Quantities (noted as sold) | M3: Difference produced vs. sold | N3: Price | O3: Price | P3: Value avg price | Q3: Value avg price (busel) | R3: Value of production
B4: qrs | C4: bus | D4: qrs | E4: bus | F4: s | G4: d | H4: s | I4: d | J4: qrs | K4: bus | L4: qrs | M4: qrs | N4: £ per qr | O4: £ per bus | P4: £
A5: Wheat - Town Mill | B5: 3 | D5: =B5+C5/8 -> 3 | F5: 5 | G5: 4 | J5: 3 | L5: =J5+K5/8 -> 3 | M5: =D5-L5 -> 0 | N5: =F5/20+G5/240 -> 0.26666667 | P5: =N5 -> 0.26666667 | R5: =P5*D5 -> 0.8
A6: Maslin - Town Mill | B6: 4 | C6: 5 | D6: =B6+C6/8 -> 4.625 | E6: =C6+B6*8 -> 37 | I6: 6 | K6: 5 | L6: =J6+K6/8 -> 0.625 | M6: =D6-L6 -> 4 | O6: =H6/20+I6/240 -> 0.025 | Q6: =O6 -> 0.025 | R6: =Q6*E6 -> 0.925
A7: Coarse-ground corn - Town Mill | B7: 5 | C7: 7 | D7: =B7+C7/8 -> 5.875 | F7: 6 | J7: 5 | K7: 7 | L7: =J7+K7/8 -> 5.875 | M7: =D7-L7 -> 0 | N7: =F7/20+G7/240 -> 0.3 | P7: =N7 -> 0.3 | R7: =P7*D7 -> 1.7625
A8: Malt - Town Hill | B8: 24 | C8: 1 | D8: =B8+C8/8 -> 24.125 | F8: 2 | G8: 4 | J8: 24 | K8: 1 | L8: =J8+K8/8 -> 24.125 | M8: =D8-L8 -> 0 | N8: =F8/20+G8/240 -> 0.11666667 | P8: =N8 -> 0.11666667 | R8: =P8*D8 -> 2.8145833
A9: Mills of Lynch & Subhurn | B9: nothing because at farm
A11: Total production value - average | R11: =SUM(R5:R8) -> 6.3020833
A12: Sale of mill corn (as noted in Mill Account) | R12: =5+10/20+0.5/240 -> 5.5020833

Sheet Stock
A1: EAST KNOYLE STOCK ACCOUNT
A3: Livestock | B3: Inherited stock | C3: Bought | D3: Produced | E3: strays | F3: herbage | G3: sold | H3: in murrain | I3: accounted for elsewhere | J3: End-period stock | K3: cross-check | L3: price 1 | M3: units 1 | N3: price 2 | O3: units 2 | P3: Weight (weys) | Q3: Unit price (£) | R3: Value of production (£) at sales prices | S3: Sales in (£) | T3: Details
A4: Cart-horses | B4: 2 | C4: 1 | G4: 1 | J4: 2 | K4: =B4+C4+D4+E4-F4-G4-H4-I4 -> 2 | L4: =S4/G4 -> 0.3 | Q4: =L4 -> 0.3 | R4: =D4*Q4 -> 0 | S4: ='Overton Receipts'!F81 -> 0.3
A5: Mares | K5: =B5+C5+D5+E5-F5-G5-H5-I5 -> 0 | Q5: =IFERROR((L5+N5)/(M5+O5),"") | S5: =IFERROR(Q5*G5,"")
A6: Plough horses | B6: 9 | E6: 1 | J6: 10 | K6: =B6+C6+D6+E6-F6-G6-H6-I6 -> 10 | Q6: =IFERROR((L6+N6)/(M6+O6),"") | S6: =IFERROR(Q6*G6,"")
A7: Colts (2 years) | K7: =B7+C7+D7+E7-F7-G7-H7-I7 -> 0 | Q7: =IFERROR((L7+N7)/(M7+O7),"") | S7: =IFERROR(Q7*G7,"")
A8: Colts (2 years) | K8: =B8+C8+D8+E8-F8-G8-H8-I8 -> 0 | Q8: =IFERROR((L8+N8)/(M8+O8),"") | S8: =IFERROR(Q8*G8,"")
A9: Colts (1 year) | K9: =B9+C9+D9+E9-F9-G9-H9-I9 -> 0 | Q9: =IFERROR((L9+N9)/(M9+O9),"") | S9: =IFERROR(Q9*G9,"")
A10: Foals | K10: =B10+C10+D10+E10-F10-G10-H10-I10 -> 0 | Q10: =IFERROR((L10+N10)/(M10+O10),"") | S10: =IFERROR(Q10*G10,"")
A11: Oxen | B11: 20 | C11: 2 | G11: 2 | J11: 20 | K11: =B11+C11+D11+E11-F11-G11-H11-I11 -> 20 | L11: =S11/G11 -> 0.4875 | Q11: =L11 -> 0.4875 | R11: =D11*Q11 -> 0 | S11: ='Overton Receipts'!F82 -> 0.975
A12: Bulls | B12: 1 | D12: 1 | G12: 1 | J12: 1 | K12: =B12+C12+D12+E12-F12-G12-H12-I12 -> 1 | L12: =S12/G12 -> 0.5 | Q12: =L12 -> 0.5 | R12: =D12*Q12 -> 0.5 | S12: ='Overton Receipts'!F83 -> 0.5
A13: Cows | B13: 25 | D13: 3 | E13: 1 | G13: 2 | H13: 1 | J13: 26 | K13: =B13+C13+D13+E13-F13-G13-H13-I13 -> 26 | L13: =S13/G13 -> 0.4 | Q13: =L13 -> 0.4 | R13: =D13*Q13 -> 1.2 | S13: ='Overton Receipts'!F84 -> 0.8
A14: Steers | B14: 5 | G14: 1 | I14: 4 | J14: 0 | K14: =B14+C14+D14+E14-F14-G14-H14-I14 -> 0 | L14: =S14/G14 -> 0.35 | Q14: =L14 -> 0.35 | R14: =D14*Q14 -> 0 | S14: ='Overton Receipts'!F85 -> 0.35
A15: Bullocks | B15: 9 | J15: 9 | K15: =B15+C15+D15+E15-F15-G15-H15-I15 -> 9
A16: Yearlings | B16: 10 | H16: 1 | J16: 9 | K16: =B16+C16+D16+E16-F16-G16-H16-I16 -> 9
A17: Calves | B17: 25 | G17: 11 | H17: 3 | I17: 2 | J17: 9 | K17: =B17+C17+D17+E17-F17-G17-H17-I17 -> 9 | L17: =S17/G17 -> 0.04469697 | Q17: =L17 -> 0.04469697 | R17: =D17*Q17 -> 0 | S17: ='Overton Receipts'!F86 -> 0.49166667
A18: Wethers | K18: =B18+C18+D18+E18-F18-G18-H18-I18 -> 0
A19: Rams | B19: 20 | C19: 1 | D19: 7 | I19: 11 | J19: 17 | K19: =B19+C19+D19+E19-F19-G19-H19-I19 -> 17
A20: Ewes | B20: 495 | C20: 106 | D20: 102 | G20: 39 | H20: =7+14+12 -> 33 | J20: 631 | K20: =B20+C20+D20+E20-F20-G20-H20-I20 -> 631 | L20: =S20/G20 -> 0.0375 | Q20: =L20 -> 0.0375 | R20: =D20*Q20 -> 3.825 | S20: ='Overton Receipts'!F87 -> 1.4625 | T20: issues of the manor only records sale of 29 ewes
A21: Hoggs | B21: 234 | G21: 12 | H21: 12 | I21: =102+7+101 -> 210 | J21: 0 | K21: =B21+C21+D21+E21-F21-G21-H21-I21 -> 0 | L21: =S21/G21 -> 0.025 | Q21: =L21 -> 0.025 | R21: =D21*Q21 -> 0 | S21: ='Overton Receipts'!F89 -> 0.3
A22: Lambs | B22: 401 | H22: =61+12+14 -> 87 | I22: =34 -> 34 | J22: 280 | K22: =B22+C22+D22+E22-F22-G22-H22-I22 -> 280
A23: Boars | K23: =B23+C23+D23+E23-F23-G23-H23-I23 -> 0
A24: Sows | K24: =B24+C24+D24+E24-F24-G24-H24-I24 -> 0
A25: Pigs | C25: 2 | G25: 2 | K25: =B25+C25+D25+E25-F25-G25-H25-I25 -> 0 | L25: =S25/G25 -> 0.18958333 | Q25: =L25 -> 0.18958333 | R25: =D25*Q25 -> 0 | S25: ='Overton Receipts'!F90 -> 0.37916667
A26: Hoggets | K26: =B26+C26+D26+E26-F26-G26-H26-I26 -> 0 | Q26: =IFERROR((L26+N26)/(M26+O26),"") | R26: =IFERROR(D26*Q26,"") | S26: =IFERROR(Q26*G26,"")
A27: Piglets | K27: =B27+C27+D27+E27-F27-G27-H27-I27 -> 0 | Q27: =IFERROR((L27+N27)/(M27+O27),"") | R27: =IFERROR(D27*Q27,"") | S27: =IFERROR(Q27*G27,"")
A28: Swans | K28: =B28+C28+D28+E28-F28-G28-H28-I28 -> 0 | Q28: =IFERROR((L28+N28)/(M28+O28),"") | R28: =IFERROR(D28*Q28,"") | S28: =IFERROR(Q28*G28,"")
A29: Peacocks | B29: 10 | D29: 2 | H29: 1 | J29: 11 | K29: =B29+C29+D29+E29-F29-G29-H29-I29 -> 11 | Q29: =IFERROR((L29+N29)/(M29+O29),"") | R29: =IFERROR(D29*Q29,"") | S29: =IFERROR(Q29*G29,"")
A30: Total | S30: =SUM(S4:S29) -> 5.5583333
A33: Wool | K33: =B33+C33+D33+E33-F33-G33-H33-I33 -> 0 | Q33: =IFERROR((L33+N33)/(M33+O33),"") | R33: =IFERROR(D33*Q33,"") | S33: =IFERROR(Q33*G33,"")
A34: Fleeces | D34: 1013 | I34: =101+2+910 -> 1013 | K34: =B34+C34+D34+E34-F34-G34-H34-I34 -> 0 | Q34: 0.02 | R34: =IFERROR(D34*Q34,"") -> 20.26 | S34: =IFERROR(Q34*G34,"") -> 0
A35: Coarse wool | K35: =B35+C35+D35+E35-F35-G35-H35-I35 -> 0 | Q35: =IFERROR((L35+N35)/(M35+O35),"") | R35: =IFERROR(D35*Q35,"") | S35: =IFERROR(Q35*G35,"")
A36: Lamb's wool | D36: 294 | I36: 294 | K36: =B36+C36+D36+E36-F36-G36-H36-I36 -> 0 | Q36: 0.01 | R36: =IFERROR(D36*Q36,"") -> 2.94 | S36: =IFERROR(Q36*G36,"") -> 0
A37: Wool locks | K37: =B37+C37+D37+E37-F37-G37-H37-I37 -> 0 | Q37: =IFERROR((L37+N37)/(M37+O37),"") | R37: =IFERROR(D37*Q37,"") | S37: ='Overton Receipts'!F91 -> 0.46666667 | T37: in issues of manor woollocks sold
A38: Wool sold at shearing | K38: =B38+C38+D38+E38-F38-G38-H38-I38 -> 0 | Q38: =IFERROR((L38+N38)/(M38+O38),"") | R38: =IFERROR(D38*Q38,"") | S38: =IFERROR(Q38*G38,"")
A39: Total | R39: =SUM(R34:R38)+S37 -> 23.666667
A42: Hides | Q42: =IFERROR((L42+N42)/(M42+O42),"") | R42: =IFERROR(D42*Q42,"") | S42: =IFERROR(Q42*G42,"")
A43: Ox hides | K43: =B43+C43+D43+E43-F43-G43-H43-I43 -> 0 | Q43: =IFERROR((L43+N43)/(M43+O43),"") | R43: =IFERROR(D43*Q43,"") | S43: =IFERROR(Q43*G43,"")
A44: Cow hides | K44: =B44+C44+D44+E44-F44-G44-H44-I44 -> 0 | Q44: =IFERROR((L44+N44)/(M44+O44),"") | R44: =IFERROR(D44*Q44,"") | S44: =IFERROR(Q44*G44,"")
A45: Mare hides | K45: =B45+C45+D45+E45-F45-G45-H45-I45 -> 0 | Q45: =IFERROR((L45+N45)/(M45+O45),"") | R45: =IFERROR(D45*Q45,"") | S45: =IFERROR(Q45*G45,"")
...

Sheet Assumptions
A1: ASSUMPTIONS
B3: Weights | C3: Value (in lbs) | D3: Value (in cloves) | E3: Value (in weys) | F3: Value (in stone)
B4: Lbs | C4: 1 | D4: =C4/C5 -> 0.14285714 | E4: =C4/C6 -> 0.0057142857 | F4: =C4/C7 -> 0.08
B5: Cloves | C5: 7 | D5: 1 | E5: =C5/C6 -> 0.04 | F5: =C7/C5 -> 1.7857143
B6: Wey | C6: 175 | D6: =C6/C5 -> 25 | E6: =C6/C6 -> 1 | F6: =C7/C6 -> 0.071428571
B7: Stone | C7: =175/14 -> 12.5 | D7: =C5/C7 -> 0.56 | E7: =C7/C6 -> 0.071428571 | F7: 1
