Workbook

Sheet Overview
A1: POUNDISFORD | B1: Total in £ | C1: Error | D1: Note
A2: CASH ACCOUNT
A3: RECEIPTS
A4: Arrears total
A5: Rents of assize total
A6: Quittances total
A7: Defaults of rent total
A8: Defaults of rent through the pestilence total
A9: Cotlands defaults total
A10: Cotlands total
A11: Total of quittances and defaults of rent total
A12: Total of rents remaining clear total
A13: Farms total
... A183: % of capital expenses as calculated previously

Sheet Receipts
A1: POUNDSIFORD RECEIPTS
A2: Heading | B2: £ | C2: s | D2: d | F2: Total in £ | G2: Error | H2: Notes
A3: Rents | B3: 38 | C3: 13 | D3: 3.25 | F3: 38.66 | H3: The same renders account for £38 13 shilling 3.25pence for rents of assize at Christmas, Easter (22 April), the Nativity of the blessed John the Baptist (24 June), and Michaelmas (29 September), in equal portions.
A4: Rents | B4: 38 | C4: 13 | D4: 3.25 | F4: 38.66 | H4: Total, £38 13 shilling 3.25pence
A5: Rents | F5: 38.66 | G5: 0 | H5: Total
A7: Quittances | B7: 0 | C7: 14 | D7: 0 | F7: 0.7 | H7: In quittance of one ploughman at Corfe for the year and six workers working 2 days a week for three terms of the year and everyday at harvest-time except Saturday 14 shilling, or 2 shilling each.
A8: Quittances | B8: 0 | C8: 2 | D8: 0 | F8: 0.1 | H8: 1 ploughman and 1 worker working for' year as above 2 shilling.
A9: Quittances | B9: 0 | C9: 1 | D9: 0 | F9: 0.05 | H9: 1 worker working 1 day a week for 3 terms of the year and two days a week at harvest-time 1 shilling.
A10: Quittances | B10: 0 | C10: 8 | D10: 9 | F10: 0.44 | H10: 2 ploughmen, 1 beadle and 4 workers at Poundisford working 2 days a week for 3 terms of the year and everyday at harvest-time except Saturday 8 shilling 9pence, or 1 shilling 3pence each.
A11: Quittances | B11: 0 | C11: 1 | D11: 10.5 | F11: 0.09 | H11: 3 cottars working 1 day a week for 3 terms of the year and 3 days a week at harvest-time 1 shilling 10.5pence, or 7.5pence each.
A12: Quittances | B12: 0 | C12: 0 | D12: 3.25 | F12: =B12+C12/20+D12/240 -> 0.013541667 | H12: 1 cottar working 1 day a week for 3 terms of the year and two days a week at harvest-time 3.25pence
A13: Quittances | B13: 1 | C13: 7 | D13: 11.25 | F13: 1.4 | H13: Total, £1 7 shilling 11.25pence
A14: Quittances | F14: =SUM(F7:F12) -> 1.3935417 | G14: =F14-F13 -> -0.0064583333 | H14: Total
A16: Defaults of rent | B16: 0 | C16: 15 | D16: 9.5 | F16: 0.79 | H16: In default of the land drawn into the park, that is, 104 acres and one perch, which the Prior of Taunton, Adam Sydewyn', Richard Cadel, Aelnerius, Richard le Wastur, Ingolf, Walter Tottyng, German Molendinarius, Hugh de Clyve, William Faber, William Cnap, Richard Gore, Richard Suvenoke, William Cuttyng, Cngermins de Fuleford, Osbert de Amnyngeford, Roger Cherd', Robert Dun, Richard Brice, Roger Spyryng, William Frensh', Philip Spyryng, Roger Cherd, Stephen de Canesgrove, Robert Faber, Christina, widow of Roger de Annyngeford, and Adam de Annyngeford held, 15 shilling 9.5pence.
A17: Defaults of rent | B17: 0 | C17: 2 | D17: 6 | F17: 0.12 | H17: 2 cottages (cotell') similarly drawn into the park 2 shilling 6pence.
A18: Defaults of rent | B18: 0 | C18: 1 | D18: 3.5 | F18: 0.06 | H18: the land of Adam de Dudeleston', that is, 9 acres, similarly drawn into demesne 1 shilling
A19: Defaults of rent | B19: 0 | C19: 19 | D19: 3.5 | F19: =B19+C19/20+D19/240 -> 0.96458333 | H19: Total of defaults of rent, 19 shilling 3.5pence
A21: Defaults of rent | B21: 2 | C21: 7 | D21: 2.75 | F21: 2.36 | H21: Total of quittances and defaults of rent, £2 7 shilling 2.75pence
A23: Total of rents remaining | B23: 36 | C23: 6 | D23: 0.5 | F23: 36.3 | H23: Total of rents remaining, £36 6 shilling 0.5pence
A24: Total of rents remaining | F24: =F5-F21 -> 36.3 | G24: =F24-F23 -> 0 | H24: Total
A26: Issues of the manor | B26: 1 | C26: 16 | D26: 9.5 | F26: 1.84 | H26: The same renders account for £1 16 shilling 9.5pence from pannage of pigs this year.
A27: Issues of the manor | B27: 1 | C27: 3 | D27: 10 | F27: 1.19 | H27: £1 3 shilling 10pence from hundredpenny.
A28: Issues of the manor | B28: 0 | C28: 12 | D28: 0 | F28: 0.6 | H28: 12 shilling from the pasturage of Holemere and Rededon' sold in winter and summer.
A29: Issues of the manor | B29: 0 | C29: 0 | D29: 0 | F29: 0 | H29: nothing from the pasturage of Dyhfulrlong, Esterdon' and Westeredon' this year because they were sown with wheat.
A30: Issues of the manor | B30: 0 | C30: 3 | D30: 0 | F30: 0.15 | H30: 3 shilling from the pasturage of Corfmor sold in winter.
A31: Issues of the manor | B31: 0 | C31: 0 | D31: 0 | F31: 0 | H31: nothing from the pasturage of Lakemed this year because it was pastured with the lord's livestock.
A32: Issues of the manor | B32: 0 | C32: 1 | D32: 6 | F32: 0.08 | H32: 1 shilling 6pence from the pasturage of Fenalre and Fenhurst sold in winter.
A33: Issues of the manor | B33: 3 | C33: 1 | D33: 0 | F33: 3.05 | H33: £3 1 shilling from 5 oxen sold, at 12 shilling 3pence each for 4, and 12 shilling for one.
A34: Issues of the manor | B34: 3 | C34: 18 | D34: 0 | F34: 3.9 | H34: £3 18 shilling from 13 cows sold before breeding, at 6 shilling each.
A35: Issues of the manor | B35: 0 | C35: 2 | D35: 6 | F35: 0.12 | H35: 2 shilling 6pence from the moiety of 1 cow from the heriot of Henry Abel sold.
A36: Issues of the manor | B36: 0 | C36: 4 | D36: 0 | F36: 0.2 | H36: 4 shilling from 1 steer sold.
A37: Issues of the manor | B37: 1 | C37: 2 | D37: 0 | F37: 1.1 | H37: £1 2 shilling from 22 suckling calves sold, at 1 shilling each.
... A51: Issues of the manor | B51: 0 | C51: 0 | D51: 6 | F51: 0.03 | H51: 6pence from the heriot of Edith la Webbe because she did not have 1 beast.
A52: Issues of the manor | B52: 0 | C52: 6 | D52: 0 | F52: =B52+C52/20+D52/240 -> 0.3 | H52: 6 shilling from the moiety of 1 ox solpence
A53: Issues of the manor | B53: 31 | C53: 13 | D53: 8 | F53: 31.68 | H53: Total, £31 13 shilling 8pence
A54: Issues of the manor | F54: =SUM(F26:F52) -> 31.68 | G54: =F54-F53 -> 0 | H54: Total
A56: Sale of corn | B56: 15 | C56: 16 | D56: 3.5 | F56: 15.81 | H56: The same renders account for £15 16 shilling 3.5pence from 46.5 quarters of wheat sold, at 6 shilling 8pence a qr for 8 quarters 6 bushels, and 6 shilling 10pence a qr for 37 quarters 6 bushels sold to customary tenants.
A57: Sale of corn | B57: 13 | C57: 9 | D57: 6 | F57: 13.47 | H57: £13 9 shilling 6pence from 154 quarters of oats sold to customary tenants, at 1 shilling 9pence a qr.
A58: Sale of corn | B58: 29 | C58: 5 | D58: 9.5 | F58: 29.29 | H58: Total, £29 5 shilling 9.5pence
A59: Sale of corn | F59: 29.28 | G59: -0.01 | H59: Total
...

Sheet Expenses
A1: POUNDSIFORD EXPENSES
A2: Heading | B2: £ | C2: s | D2: d | F2: Total in £ | G2: Error | H2: Notes
A3: Cost of ploughs | B3: 0 | C3: 15 | D3: 11 | F3: 0.8 | H3: In iron and steel for making and repairing the ironwork of 4 ploughs for the year 15 shilling 11pence.
A4: Cost of ploughs | B4: 0 | C4: 3 | D4: 10 | F4: 0.19 | H4: stipend of the smith making and repairing the said ironwork for the year 3 shilling 10pence.
A5: Cost of ploughs | B5: 0 | C5: 2 | D5: 4 | F5: 0.12 | H5: 4 ploughshares bought 2 shilling 4pence.
A6: Cost of ploughs | B6: 0 | C6: 7 | D6: 0.5 | F6: 0.35 | H6: boon-works of 42 ploughmen ploughing 2 full days in winter and as many full days in Lent at Corfe and Poundisford 7 shilling, at 0.5pence a ploughman a day.
A7: Cost of ploughs | B7: 0 | C7: 1 | D7: 6.5 | F7: 0.08 | H7: trimming and sawing timber for ploughs, yokes and wooden halters 1 shilling 6.5pence.
A8: Cost of ploughs | B8: 0 | C8: 0 | D8: 6 | F8: 0.03 | H8: making 4 new ploughs 6pence.
A9: Cost of ploughs | B9: 0 | C9: 1 | D9: 2 | F9: 0.06 | H9: repairing the old ploughs many times during the year 1 shilling 2pence.
A10: Cost of ploughs | B10: 0 | C10: 0 | D10: 5 | F10: 0.02 | H10: making yokes and wooden halters 5pence.
A11: Cost of ploughs | B11: 0 | C11: 1 | D11: 0 | F11: 0.05 | H11: food for two beadles and 4 ploughmen according to custom at Christmas and Easter 1 shilling.
A12: Cost of ploughs | B12: 0 | C12: 0 | D12: 8 | F12: 0.03 | H12: food for 8 workers according to the same custom 8pence.
A13: Cost of ploughs | B13: 0 | C13: 12 | D13: 6 | F13: 0.62 | H13: stipend of 4 oxherds and 1 swineherd for the year 12 shilling 6pence, or 2 shilling 6pence each.
A14: Cost of ploughs | B14: 0 | C14: 6 | D14: 8 | F14: 0.33 | H14: stipend of 1 park-keeper and hayward for the year 6 shilling 8pence.
... A21: Cost of ploughs | B21: 3 | C21: 13 | D21: 5.5 | F21: 3.67 | H21: Total, £3 13 shilling 5.5pence
A22: Cost of ploughs | F22: 3.67 | G22: 0 | H22: Total
A24: Purchase of corn | B24: 3 | C24: 16 | D24: 7 | F24: 3.83 | H24: In 19 quarters 6.5 bushels of maslin bought £3 16 shilling 7pence, at 3 shilling 4pence a qr for 4 quarters, and 4 shilling a qr for 15 quarters 6.5 bushels.
A25: Purchase of corn | B25: 5 | C25: 12 | D25: 6 | F25: 5.62 | H25: 75 quarters of oats bought from customary tenants according to custom £5 12 shilling 6pence, at 1 shilling 6pence a qr.
A26: Purchase of corn | B26: 9 | C26: 9 | D26: 1 | F26: 9.45 | H26: Total, £9 9 shilling 1pence
A27: Purchase of corn | F27: 9.45 | G27: 0 | H27: Total
A29: Purchase of stock | B29: 1 | C29: 6 | D29: 3 | F29: 1.31 | H29: In 3 cows bought before breeding £1 6 shilling 3pence, at 8 shilling 9pence each.
A30: Purchase of stock | B30: 0 | C30: 16 | D30: 9 | F30: 0.84 | H30: two cows bought after breeding 16 shilling 9pence, at 8 shilling for one, and 8 shilling 9pence for the other.
A31: Purchase of stock | B31: 2 | C31: 3 | D31: 0 | F31: 2.15 | H31: Total, £2 3 shilling
A32: Purchase of stock | F32: 2.15 | G32: 0 | H32: Total
A34: Repair of buildings with small expenses | B34: 0 | C34: 0 | D34: 10 | F34: 0.04 | H34: In re-roofing the larger barn in places 10pence.
A35: Repair of buildings with small expenses | B35: 0 | C35: 0 | D35: 4 | F35: 0.02 | H35: 1 lock bought for the door of the same barn 4pence.
A36: Repair of buildings with small expenses | B36: 0 | C36: 0 | D36: 3 | F36: 0.01 | H36: one three-pronged dung-fork fitted with iron 3pence.
A37: Repair of buildings with small expenses | B37: 0 | C37: 0 | D37: 10 | F37: 0.04 | H37: making well (sanand') 32 female piglets 10pence.
A38: Repair of buildings with small expenses | B38: 0 | C38: 2 | D38: 10 | F38: 0.14 | H38: clearing dung from the curia to the fields 2 shilling 10pence.
A39: Repair of buildings with small expenses | B39: 0 | C39: 0 | D39: 9 | F39: 0.04 | H39: digging 12 perches of ditches beside la Westered' 9pence, at 0.75pence a perch.
A40: Repair of buildings with small expenses | B40: 0 | C40: 1 | D40: 8 | F40: 0.08 | H40: digging 20 perches of ditches there 1 shilling 8pence
A41: Repair of buildings with small expenses | B41: 0 | C41: 7 | D41: 6 | F41: =B41+C41/20+D41/240 -> 0.375 | H41: Total, 7 shilling 6pence
A42: Repair of buildings with small expenses | F42: 0.37 | G42: =F42-F41 -> -0.005 | H42: Total
A44: Threshing of corn | B44: 0 | C44: 4 | D44: 4 | F44: 0.22 | H44: In threshing 20 quarters 6 bushels of wheat by piece-work 4 shilling 4pence, at 2.5pence a heaped quarter.
A45: Threshing of corn | B45: 0 | C45: 4 | D45: 4 | F45: 0.22 | H45: Total, 4 shilling 4pence
A46: Threshing of corn | F46: 0.22 | G46: 0 | H46: Total
A48: Cost of the harvest | B48: 0 | C48: 0 | D48: 6 | F48: 0.03 | H48: In customary payment for the mowing of 17 acres of meadow at Corfe 6pence.
A49: Cost of the harvest | B49: 0 | C49: 0 | D49: 5 | F49: 0.02 | H49: mowing 1 acre of meadow which belonged to the Prior of Taunton there 5pence.
A50: Cost of the harvest | B50: 0 | C50: 0 | D50: 6 | F50: 0.03 | H50: customary payment for the mowing of 13 acres of meadow at Poundisford 6pence.
A51: Cost of the harvest | B51: 0 | C51: 0 | D51: 5 | F51: 0.02 | H51: customary payment for the boon-reaping at Corfe 5pence.
...

Sheet Issues of the Grange
A1: Gross Output | B1: Total Quantity | C1: Account Total Quarters | D1: Bought in Total Quarters | E1: Received from churchscot | F1: Sold Total Quarters | G1: Difference Produced+Bought-Sold | H1: Weighted Average Price per Quarter | I1: Value of Total Production weighted
A2: wheat | B2: 83.0625 | C2: 83.0625 | D2: 0 | F2: 46.5 | G2: =B2-F2 -> 36.5625 | H2: 0.34009857 | I2: =H2*B2 -> 28.249437
A3: oats | B3: 202.75 | C3: 127.75 | D3: 75 | F3: 154 | G3: =B3-F3 -> 48.75 | H3: 0.0875 | I3: =H3*B3 -> 17.740625
A5: Total Production
A6: Sales of corn (as recorded in accounts)
A8: Net output | B8: Gross output | C8: Seed quarters | D8: Seed bushels | E8: Seed total quarters | F8: tithe quarters | G8: tithe bushels | H8: tithe total | I8: manorial servants quarters | J8: manorial servants bushels | K8: manorial servants total quarters | L8: output net of tithe, seed, liveries | M8: in stock from last year | N8: Price in £ | O8: Value of net output in £ | P8: Value of sales (in "Sale of Corn") in £
A9: wheat | B9: =B2 -> 83.0625 | C9: 26 | D9: 2 | E9: =C9+D9/8 -> 26.25 | I9: =4+6 -> 10 | J9: 2.5 | K9: =I9+J9/8 -> 10.3125 | L9: =B9-E9-H9-K9 -> 46.5 | N9: =H2 -> 0.34009857 | O9: =N9*L9 -> 15.814583
A10: oats | B10: =B3 -> 202.75 | C10: 48 | D10: 6 | E10: =C10+D10/8 -> 48.75 | K10: =I10+J10/8 -> 0 | L10: =B10-E10-H10-K10 -> 154 | N10: =H3 -> 0.0875 | O10: =N10*L10 -> 13.475
A12: Total

Sheet Issues of the Mills

Sheet Stock
A1: POUNDISFORD STOCK ACCOUNT
C3: added | G3: subtracted
A4: Livestock | B4: Inherited stock | C4: added | D4: strays | E4: herbage | F4: churchscot | G4: of which in default | H4: sold | I4: in murrain | J4: accounted for elsewhere | K4: End-period stock | L4: cross-check | M4: stock building | N4: raw production | O4: Unit price (£) | P4: Value of stock (£) at given value | Q4: Value of stock (£) at sales prices | R4: Sales in (£) | S4: Value of stock building (£) | T4: Value of production (£) at sales prices | U4: Details
A5: Cart-horses | B5: 1 | K5: 1 | L5: =B5+C5+D5+E5+F5-G5-H5-I5-J5 -> 1
A6: Mares | L6: =B6+C6+D6+E6+F6-G6-H6-I6-J6 -> 0
A7: Plough horses | L7: =B7+C7+D7+E7+F7-G7-H7-I7-J7 -> 0
A8: Colts (unspecified years) | B8: 2 | K8: 2 | L8: =B8+C8+D8+E8+F8-G8-H8-I8-J8 -> 2
A9: Colts (2 years)
A10: Colts (1 year)
A11: Foals
A12: Oxen | B12: 44 | C12: =3+1 -> 4 | H12: 5 | I12: 2 | K12: 41 | L12: =B12+C12+D12+E12+F12-G12-H12-I12-J12 -> 41 | O12: =R12/H12 -> 0.61 | R12: =Receipts!F33 -> 3.05
A13: Bulls | B13: 3 | K13: 3 | L13: =B13+C13+D13+E13+F13-G13-H13-I13-J13 -> 3
A14: Cows | B14: 47 | C14: =3+1+1+3+1+1+2 -> 12 | H14: 13 | I14: =2+1 -> 3 | K14: 43 | L14: =B14+C14+D14+E14+F14-G14-H14-I14-J14 -> 43 | O14: =R14/H14 -> 0.3 | R14: =Receipts!F34 -> 3.9
A15: Steers | B15: 10 | H15: 1 | I15: 3 | J15: =3+3 -> 6 | K15: 0 | L15: =B15+C15+D15+E15+F15-G15-H15-I15-J15 -> 0 | O15: =R15/H15 -> 0.2 | R15: =Receipts!F36 -> 0.2
A16: Bullocks | B16: 16 | K16: 16 | L16: =B16+C16+D16+E16+F16-G16-H16-I16-J16 -> 16
A17: Yearlings | B17: 8 | I17: 1 | K17: 7 | L17: =B17+C17+D17+E17+F17-G17-H17-I17-J17 -> 7
A18: Calves | B18: 35 | H18: 22 | J18: 3 | K18: 10 | L18: =B18+C18+D18+E18+F18-G18-H18-I18-J18 -> 10 | O18: =R18/H18 -> 0.05 | R18: =Receipts!F37 -> 1.1
A19: Wethers | C19: 1 | J19: 1 | K19: 0 | L19: =B19+C19+D19+E19+F19-G19-H19-I19-J19 -> 0
A20: Rams
A21: Ewes
A22: Hoggs
A23: Lambs
A24: Boars
A25: Sows
A26: Pigs | B26: 82 | C26: 40 | H26: 69 | K26: 53 | L26: =B26+C26+D26+E26+F26-G26-H26-I26-J26 -> 53 | O26: =R26/H26 -> 0.16594203 | R26: =Receipts!F38 -> 11.45
A27: Hoggets | B27: 46 | I27: 6 | J27: 40 | K27: 0 | L27: =B27+C27+D27+E27+F27-G27-H27-I27-J27 -> 0
A28: Piglets | C28: =18+22+18 -> 58 | I28: =5 -> 5 | J28: 5 | K28: 48 | L28: =B28+C28+D28+E28+F28-G28-H28-I28-J28 -> 48
A29: Swans
A30: Peacocks
A31: Total Value | R31: =SUM(R6:R30) -> 19.7
A34: Wool
A35: Coarse wool
A36: Lamb's wool
A37: Wool locks
A38: Wool sold at shearing
A39: Total wool
A42: Hides
A43: Ox hides | C43: 2 | H43: 2 | O43: =R43/H43 -> 0.12 | R43: =Receipts!F39 -> 0.24
A44: cow | C44: 3 | H44: 3 | O44: =R44/H44 -> 0.096666667 | R44: =Receipts!F40+Receipts!F41+Receipts!F42 -> 0.29
A45: Mare
...

Sheet raw data
A1: Heading | B1: Sentence | C1: Total in Pounds | D1: Pounds | E1: Shillings | F1: Pence | G1: Corn | H1: Total Quarters Except 1 | I1: Total Bushels Except 1 | J1: Total Corn Cross-Check | K1: Total Corn Manorial Account | L1: Corn Quantity Error | M1: Quarters 1 | N1: Bushels 1 | O1: Quarters 2 | P1: Bushels 2 | Q1: Quarters 3 | R1: Bushels 3 | S1: shilling a quarter 1 | T1: pence a quarter 1 | U1: shilling a quarter 2 | V1: pence a quarter 2 | W1: shilling a quarter 3 | X1: pence a quarter 3 | Y1: shilling a quarter 4 | Z1: pence a quarter 4 | AA1: shilling a bushel 1 | AB1: pence a bushel 1 | AC1: shilling a bushel 2 | AD1: pence a bushel 2 | AE1: shilling a bushel 3 | AF1: pence a bushel 3 | AG1: shilling a bushel 4 | AH1: pence a bushel 4
A2: Rents | B2: The same renders account for £38 13 shilling 3.25pence for rents of assize at Christmas, Easter (22 April), the Nativity of the blessed John the Baptist (24 June), and Michaelmas (29 September), in equal portions. | C2: 38.66 | D2: 38 | E2: 13 | F2: 3.25 | H2: 0 | I2: 0 | J2: 0 | K2: 0 | L2: 0 | M2: 0 | N2: 0
A3: Rents | B3: Total, £38 13 shilling 3.25pence | C3: 38.66 | D3: 38 | E3: 13 | F3: 3.25 | H3: 0 | I3: 0 | J3: 0 | K3: 0 | L3: 0 | M3: 0 | N3: 0
A4: Quittances | B4: In quittance of one ploughman at Corfe for the year and six workers working 2 days a week for three terms of the year and everyday at harvest-time except Saturday 14 shilling, or 2 shilling each. | C4: 0.7 | D4: 0 | E4: 14 | F4: 0 | H4: 0 | I4: 0 | J4: 0 | K4: 0 | L4: 0 | M4: 0 | N4: 0
A5: Quittances | B5: 1 ploughman and 1 worker working for' year as above 2 shilling. | C5: 0.1 | D5: 0 | E5: 2 | F5: 0 | H5: 0 | I5: 0 | J5: 0 | K5: 0 | L5: 0 | M5: 0 | N5: 0
A6: Quittances | B6: 1 worker working 1 day a week for 3 terms of the year and two days a week at harvest-time 1 shilling. | C6: 0.05 | D6: 0 | E6: 1 | F6: 0 | H6: 0 | I6: 0 | J6: 0 | K6: 0 | L6: 0 | M6: 0 | N6: 0
A7: Quittances | B7: 2 ploughmen, 1 beadle and 4 workers at Poundisford working 2 days a week for 3 terms of the year and everyday at harvest-time except Saturday 8 shilling 9pence, or 1 shilling 3pence each. | C7: 0.44 | D7: 0 | E7: 8 | F7: 9 | H7: 0 | I7: 0 | J7: 0 | K7: 0 | L7: 0 | M7: 0 | N7: 0
A8: Quittances | B8: 3 cottars working 1 day a week for 3 terms of the year and 3 days a week at harvest-time 1 shilling 10.5pence, or 7.5pence each. | C8: 0.09 | D8: 0 | E8: 1 | F8: 10.5 | H8: 0 | I8: 0 | J8: 0 | K8: 0 | L8: 0 | M8: 0 | N8: 0
A9: Quittances | B9: 1 cottar working 1 day a week for 3 terms of the year and two days a week at harvest-time 3.25pence Total, £1 7 shilling 11.25pence | C9: 1.4 | D9: 1 | E9: 7 | F9: 11.25 | H9: 0 | I9: 0 | J9: 0 | K9: 0 | L9: 0 | M9: 0 | N9: 0
A10: Defaults of rent | B10: In default of the land drawn into the park, that is, 104 acres and one perch, which the Prior of Taunton, Adam Sydewyn', Richard Cadel, Aelnerius, Richard le Wastur, Ingolf, Walter Tottyng, German Molendinarius, Hugh de Clyve, William Faber, William Cnap, Richard Gore, Richard Suvenoke, William Cuttyng, Cngermins de Fuleford, Osbert de Amnyngeford, Roger Cherd', Robert Dun, Richard Brice, Roger Spyryng, William Frensh', Philip Spyryng, Roger Cherd, Stephen de Canesgrove, Robert Faber, Christina, widow of Roger de Annyngeford, and Adam de Annyngeford held, 15 shilling 9.5pence. | C10: 0.79 | D10: 0 | E10: 15 | F10: 9.5 | H10: 0 | I10: 0 | J10: 0 | K10: 0 | L10: 0 | M10: 0 | N10: 0
A11: Defaults of rent | B11: 2 cottages (cotell') similarly drawn into the park 2 shilling 6pence. | C11: 0.12 | D11: 0 | E11: 2 | F11: 6 | H11: 0 | I11: 0 | J11: 0 | K11: 0 | L11: 0 | M11: 0 | N11: 0
A12: Defaults of rent | B12: the land of Adam de Dudeleston', that is, 9 acres, similarly drawn into demesne 1 shilling Total of defaults of rent, 19 shilling 3.5pence | C12: 0.06 | D12: 0 | E12: 1 | F12: 3.5 | H12: 0 | I12: 0 | J12: 0 | K12: 0 | L12: 0 | M12: 0 | N12: 0
A13: Defaults of rent | B13: Total of quittances and defaults of rent, £2 7 shilling 2.75pence | C13: 2.36 | D13: 2 | E13: 7 | F13: 2.75 | H13: 0 | I13: 0 | J13: 0 | K13: 0 | L13: 0 | M13: 0 | N13: 0
... A17: Issues of the manor | B17: 12 shilling from the pasturage of Holemere and Rededon' sold in winter and summer. | C17: 0.6 | D17: 0 | E17: 12 | F17: 0 | H17: 0 | I17: 0 | J17: 0 | K17: 0 | L17: 0 | M17: 0 | N17: 0
A18: Issues of the manor | B18: nothing from the pasturage of Dyhfulrlong, Esterdon' and Westeredon' this year because they were sown with wheat. | C18: 0 | D18: 0 | E18: 0 | F18: 0 | G18: wheat | H18: 0 | I18: 0 | J18: 0 | K18: 0 | L18: 0 | M18: 0 | N18: 0
A19: Issues of the manor | B19: 3 shilling from the pasturage of Corfmor sold in winter. | C19: 0.15 | D19: 0 | E19: 3 | F19: 0 | H19: 0 | I19: 0 | J19: 0 | K19: 0 | L19: 0 | M19: 0 | N19: 0
A20: Issues of the manor | B20: nothing from the pasturage of Lakemed this year because it was pastured with the lord's livestock. | C20: 0 | D20: 0 | E20: 0 | F20: 0 | H20: 0 | I20: 0 | J20: 0 | K20: 0 | L20: 0 | M20: 0 | N20: 0
A21: Issues of the manor | B21: 1 shilling 6pence from the pasturage of Fenalre and Fenhurst sold in winter. | C21: 0.08 | D21: 0 | E21: 1 | F21: 6 | H21: 0 | I21: 0 | J21: 0 | K21: 0 | L21: 0 | M21: 0 | N21: 0
A22: Issues of the manor | B22: £3 1 shilling from 5 oxen sold, at 12 shilling 3pence each for 4, and 12 shilling for one. | C22: 3.05 | D22: 3 | E22: 1 | F22: 0 | H22: 0 | I22: 0 | J22: 0 | K22: 0 | L22: 0 | M22: 0 | N22: 0
A23: Issues of the manor | B23: £3 18 shilling from 13 cows sold before breeding, at 6 shilling each. | C23: 3.9 | D23: 3 | E23: 18 | F23: 0 | H23: 0 | I23: 0 | J23: 0 | K23: 0 | L23: 0 | M23: 0 | N23: 0
A24: Issues of the manor | B24: 2 shilling 6pence from the moiety of 1 cow from the heriot of Henry Abel sold. | C24: 0.12 | D24: 0 | E24: 2 | F24: 6 | H24: 0 | I24: 0 | J24: 0 | K24: 0 | L24: 0 | M24: 0 | N24: 0
A25: Issues of the manor | B25: 4 shilling from 1 steer sold. | C25: 0.2 | D25: 0 | E25: 4 | F25: 0 | H25: 0 | I25: 0 | J25: 0 | K25: 0 | L25: 0 | M25: 0 | N25: 0
A26: Issues of the manor | B26: £1 2 shilling from 22 suckling calves sold, at 1 shilling each. | C26: 1.1 | D26: 1 | E26: 2 | F26: 0 | H26: 0 | I26: 0 | J26: 0 | K26: 0 | L26: 0 | M26: 0 | N26: 0
A27: Issues of the manor | B27: £11 9 shilling from 69 pigs sold, at 2 shilling each for 15, 2 shilling 6pence each for 10, 3 shilling 6pence each for 4, and 4 shilling each for 40. | C27: 11.45 | D27: 11 | E27: 9 | F27: 0 | H27: 0 | I27: 0 | J27: 0 | K27: 0 | L27: 0 | M27: 0 | N27: 0
A28: Issues of the manor | B28: 4 shilling 9pence from the hides sold of two oxen dead from murrain soon after Christmas. | C28: 0.24 | D28: 0 | E28: 4 | F28: 9 | H28: 0 | I28: 0 | J28: 0 | K28: 0 | L28: 0 | M28: 0 | N28: 0
A29: Issues of the manor | B29: 3 shilling 6pence from the hide and flesh sold of 1 cow dead from murrain before breeding. | C29: 0.17 | D29: 0 | E29: 3 | F29: 6 | H29: 0 | I29: 0 | J29: 0 | K29: 0 | L29: 0 | M29: 0 | N29: 0
A30: Issues of the manor | B30: 1 shilling from the hide sold of 1 cow dead from murrain before breeding. | C30: 0.05 | D30: 0 | E30: 1 | F30: 0 | H30: 0 | I30: 0 | J30: 0 | K30: 0 | L30: 0 | M30: 0 | N30: 0
... A41: Issues of the manor | B41: 6 shilling from the moiety of 1 ox solpence Total, £31 13 shilling 8pence | C41: 31.68 | D41: 31 | E41: 13 | F41: 8 | H41: 0 | I41: 0 | J41: 0 | K41: 0 | L41: 0 | M41: 0 | N41: 0
A42: Sale of corn | B42: The same renders account for £15 16 shilling 3.5pence from 46.5 quarters of wheat sold, at 6 shilling 8pence a quarters for 8 quarters 6 bushels, and 6 shilling 10pence a quarters for 37 quarters 6 bushels sold to customary tenants. | C42: 15.81 | D42: 15 | E42: 16 | F42: 3.5 | G42: wheat | H42: 45 | I42: 12 | J42: 46.5 | K42: 46.5 | L42: 0 | M42: 46.5 | N42: 0 | O42: 8 | P42: 6 | Q42: 37 | R42: 6 | S42: 6 | T42: 8 | U42: 6 | V42: 10
A43: Sale of corn | B43: £13 9 shilling 6pence from 154 quarters of oats sold to customary tenants, at 1 shilling 9pence a quarters. | C43: 13.47 | D43: 13 | E43: 9 | F43: 6 | G43: oats | H43: 154 | I43: 0 | J43: 154 | K43: 154 | L43: 0 | M43: 154 | N43: 0 | S43: 1 | T43: 9
A44: Sale of corn | B44: Total, £29 5 shilling 9.5pence | C44: 29.29 | D44: 29 | E44: 5 | F44: 9.5 | H44: 0 | I44: 0 | J44: 0 | K44: 0 | L44: 0 | M44: 0 | N44: 0
A45: Entry and marriage fines | B45: The same renders account for £1 13 shilling 4pence from John Goddey to have Gunilda attare Balke with her land. | C45: 1.67 | D45: 1 | E45: 13 | F45: 4 | H45: 0 | I45: 0 | J45: 0 | K45: 0 | L45: 0 | M45: 0 | N45: 0
A46: Entry and marriage fines | B46: 6 shilling 8pence from Gunilda, who was wife of Henry Abel, to retain 1 messuage and 5 acres of land which belonged to the aforesaid Henry her husband. | C46: 0.33 | D46: 0 | E46: 6 | F46: 8 | H46: 0 | I46: 0 | J46: 0 | K46: 0 | L46: 0 | M46: 0 | N46: 0
A47: Entry and marriage fines | B47: 6 shilling 8pence from John, son of Walter de Fuleford, to have 1 house which belonged to Henry de Fuleford in South Trendle. | C47: 0.33 | D47: 0 | E47: 6 | F47: 8 | H47: 0 | I47: 0 | J47: 0 | K47: 0 | L47: 0 | M47: 0 | N47: 0
A48: Entry and marriage fines | B48: £1 6 shilling 8pence from Walter de Fuleford' to have 5 acres of land and 1 plot containing about 3 perches which belonged to the aforesaid Henry. | C48: 1.33 | D48: 1 | E48: 6 | F48: 8 | H48: 0 | I48: 0 | J48: 0 | K48: 0 | L48: 0 | M48: 0 | N48: 0
A49: Entry and marriage fines | B49: 6 shilling 8pence from Walter Bach' to have half acre of meadow which belonged to Henry de Fuleford'. | C49: 0.33 | D49: 0 | E49: 6 | F49: 8 | H49: 0 | I49: 0 | J49: 0 | K49: 0 | L49: 0 | M49: 0 | N49: 0
A50: Entry and marriage fines | B50: 1 shilling from Edmund Parcarius to have the moiety of 1 house which belonged to Adam le Whyttere in Poundisford. | C50: 0.05 | D50: 0 | E50: 1 | F50: 0 | H50: 0 | I50: 0 | J50: 0 | K50: 0 | L50: 0 | M50: 0 | N50: 0
A51: Entry and marriage fines | B51: 4 shilling from Matilda, who was wife of Stephen le Hopere, to retain 1 messuage and 7 acres of land which belonged to the aforesaid Stephen her husband. | C51: 0.2 | D51: 0 | E51: 4 | F51: 0 | H51: 0 | I51: 0 | J51: 0 | K51: 0 | L51: 0 | M51: 0 | N51: 0
A52: Entry and marriage fines | B52: £6 from Roger Aylwyn' to have 1 messuage and' virgate by surrender of Alice his mother. | C52: 6 | D52: 6 | E52: 0 | F52: 0 | H52: 0 | I52: 0 | J52: 0 | K52: 0 | L52: 0 | M52: 0 | N52: 0
A53: Entry and marriage fines | B53: 2 shilling from Hugh Dun to have one house in South Trendle by surrender of Geoffrey Pope. | C53: 0.1 | D53: 0 | E53: 2 | F53: 0 | H53: 0 | I53: 0 | J53: 0 | K53: 0 | L53: 0 | M53: 0 | N53: 0
...

Sheet Issues of the Grange raw
A1: Heading | B1: Sentence | C1: Quarters 1_x | D1: Bushels 1_x | E1: Sown Quarters | F1: Sown Bushels | G1: Sown Total Quarters | H1: Bought in Quarters | I1: Bought in Bushels | J1: Bought in Total Quarters | K1: Tithe Quarters | L1: Tithe Bushels | M1: Tithe Total Quarters | N1: Manorial servants & livestock Quarters | O1: Manorial servants & livestock Bushels | P1: Manorial servants & livestock Total Quarters | Q1: Sold Quarters | R1: Sold Bushels | S1: Sold Total Quarters | T1: Account Quarters | U1: Account Bushels | V1: Account Total Quarters | W1: bought only | X1: Total Quarters Except 1 | Y1: Total Bushels Except 1 | Z1: Total Corn Cross-Check | AA1: Total Corn Manorial Account | AB1: Corn Quantity Error | AC1: Quarters 1_y | AD1: Bushels 1_y | AE1: Quarters 2 | AF1: Bushels 2 | AG1: Quarters 3 | AH1: Bushels 3
A2: Cash deliveries | B2: Total | C2: 0 | D2: 0 | E2: 0 | F2: 0 | G2: 0 | H2: 0 | I2: 0 | J2: 0 | K2: 0 | L2: 0 | M2: 0 | N2: 0 | O2: 0 | P2: 0 | Q2: 0 | R2: 0 | S2: 0 | T2: 0 | U2: 0 | V2: 0 | W2: 0
A3: Wheat | B3: {yield: two-and-a-half-fold less 5.5 bushels} | C3: 0 | D3: 0 | E3: 0 | F3: 0 | G3: 0 | H3: 0 | I3: 0 | J3: 0 | K3: 0 | L3: 0 | M3: 0 | N3: 0 | O3: 0 | P3: 0 | Q3: 0 | R3: 0 | S3: 0 | T3: 0 | U3: 0 | V3: 0 | W3: 0 | X3: 0 | Y3: 5.5 | Z3: 0.6875 | AA3: 0.6875 | AB3: 0 | AC3: 0 | AD3: 5.5
A4: Wheat | B4: The same renders account for 83 quarters 0.5 bushels from the whole issue of wheat by struck | C4: 0 | D4: 0 | E4: 0 | F4: 0 | G4: 0 | H4: 0 | I4: 0 | J4: 0 | K4: 0 | L4: 0 | M4: 0 | N4: 0 | O4: 0 | P4: 0 | Q4: 0 | R4: 0 | S4: 0 | T4: 83 | U4: 0.5 | V4: 83.0625 | W4: 0 | X4: 83 | Y4: 0.5 | Z4: 83.0625 | AA4: 83.0625 | AB4: 0 | AC4: 83 | AD4: 0.5
A5: Wheat | B5: measure. | C5: 0 | D5: 0 | E5: 0 | F5: 0 | G5: 0 | H5: 0 | I5: 0 | J5: 0 | K5: 0 | L5: 0 | M5: 0 | N5: 0 | O5: 0 | P5: 0 | Q5: 0 | R5: 0 | S5: 0 | T5: 0 | U5: 0 | V5: 0 | W5: 0 | X5: 0 | Y5: 0 | Z5: 0 | AA5: 0 | AB5: 0 | AC5: 0 | AD5: 0
A6: Wheat | B6: Sown over 111.5 acres at Poundisford and Corfe, 26 quarters 2 bushels. | C6: 0 | D6: 0 | E6: 26 | F6: 2 | G6: 26.25 | H6: 0 | I6: 0 | J6: 0 | K6: 0 | L6: 0 | M6: 0 | N6: 0 | O6: 0 | P6: 0 | Q6: 0 | R6: 0 | S6: 0 | T6: 0 | U6: 0 | V6: 0 | W6: 0 | X6: 26 | Y6: 2 | Z6: 26.25 | AA6: 26.25 | AB6: 0 | AC6: 26 | AD6: 2
A7: Wheat | B7: that is, 2 bushels an acre, less 1 qr 5 bushels in all. | C7: 0 | D7: 0 | E7: 0 | F7: 0 | G7: 0 | H7: 0 | I7: 0 | J7: 0 | K7: 0 | L7: 0 | M7: 0 | N7: 0 | O7: 0 | P7: 0 | Q7: 0 | R7: 0 | S7: 0 | T7: 0 | U7: 0 | V7: 0 | W7: 0
A8: Wheat | B8: Also sown at Poundisford by the villeins according to custom, 26.5 acres.1 Delivered to the park-keeper for the year, 4 quarters 2.5 bushels, taking a quarter every 12 weeks. | C8: 0 | D8: 0 | E8: 4 | F8: 2.5 | G8: 4.3125 | H8: 0 | I8: 0 | J8: 0 | K8: 0 | L8: 0 | M8: 0 | N8: 0 | O8: 0 | P8: 0 | Q8: 0 | R8: 0 | S8: 0 | T8: 0 | U8: 0 | V8: 0 | W8: 0 | X8: 4 | Y8: 2.5 | Z8: 4.3125 | AA8: 4.3125 | AB8: 0 | AC8: 4 | AD8: 2.5
A9: Wheat | B9: Mixed below for the liveries of the manorial servants, 6 quarters. | C9: 0 | D9: 0 | E9: 0 | F9: 0 | G9: 0 | H9: 0 | I9: 0 | J9: 0 | K9: 0 | L9: 0 | M9: 0 | N9: 6 | O9: 0 | P9: 6 | Q9: 0 | R9: 0 | S9: 0 | T9: 0 | U9: 0 | V9: 0 | W9: 0 | X9: 6 | Y9: 0 | Z9: 6 | AA9: 6 | AB9: 0 | AC9: 6 | AD9: 0
A10: Wheat | B10: Sold, 46.5 quarters. | C10: 0 | D10: 0 | E10: 0 | F10: 0 | G10: 0 | H10: 0 | I10: 0 | J10: 0 | K10: 0 | L10: 0 | M10: 0 | N10: 0 | O10: 0 | P10: 0 | Q10: 46.5 | R10: 0 | S10: 46.5 | T10: 0 | U10: 0 | V10: 0 | W10: 0 | X10: 46.5 | Y10: 0 | Z10: 46.5 | AA10: 46.5 | AB10: 0 | AC10: 46.5 | AD10: 0
A11: Wheat | B11: Total, 83 quarters 0.5 bushels It balances. | C11: 0 | D11: 0 | E11: 0 | F11: 0 | G11: 0 | H11: 0 | I11: 0 | J11: 0 | K11: 0 | L11: 0 | M11: 0 | N11: 0 | O11: 0 | P11: 0 | Q11: 0 | R11: 0 | S11: 0 | T11: 0 | U11: 0 | V11: 0 | W11: 0 | X11: 83 | Y11: 0.5 | Z11: 83.0625 | AA11: 83.0625 | AB11: 0 | AC11: 83 | AD11: 0.5
A12: Wheat | B12: Total | C12: 0 | D12: 0 | E12: 0 | F12: 0 | G12: 0 | H12: 0 | I12: 0 | J12: 0 | K12: 0 | L12: 0 | M12: 0 | N12: 0 | O12: 0 | P12: 0 | Q12: 0 | R12: 0 | S12: 0 | T12: 0 | U12: 0 | V12: 0 | W12: 0
A13: Oats | B13: {yield: two-fold plus 6 quarters 6 bushels} | C13: 0 | D13: 0 | E13: 0 | F13: 0 | G13: 0 | H13: 0 | I13: 0 | J13: 0 | K13: 0 | L13: 0 | M13: 0 | N13: 0 | O13: 0 | P13: 0 | Q13: 0 | R13: 0 | S13: 0 | T13: 0 | U13: 0 | V13: 0 | W13: 0 | X13: 6 | Y13: 6 | Z13: 6.75 | AA13: 6.75 | AB13: 0 | AC13: 6 | AD13: 6
A14: Oats | B14: The same renders account for 127 quarters 6 bushels from the whole issue of oats by struck measure. | C14: 0 | D14: 0 | E14: 0 | F14: 0 | G14: 0 | H14: 0 | I14: 0 | J14: 0 | K14: 0 | L14: 0 | M14: 0 | N14: 0 | O14: 0 | P14: 0 | Q14: 0 | R14: 0 | S14: 0 | T14: 127 | U14: 6 | V14: 127.75 | W14: 0 | X14: 127 | Y14: 6 | Z14: 127.75 | AA14: 127.75 | AB14: 0 | AC14: 127 | AD14: 6
A15: Oats | B15: 75 quarters bought. | C15: 0 | D15: 0 | E15: 0 | F15: 0 | G15: 0 | H15: 75 | I15: 0 | J15: 75 | K15: 0 | L15: 0 | M15: 0 | N15: 0 | O15: 0 | P15: 0 | Q15: 0 | R15: 0 | S15: 0 | T15: 0 | U15: 0 | V15: 0 | W15: 0 | X15: 75 | Y15: 0 | Z15: 75 | AA15: 75 | AB15: 0 | AC15: 75 | AD15: 0
A16: Oats | B16: Total, 202 quarters 6 bushels | C16: 0 | D16: 0 | E16: 0 | F16: 0 | G16: 0 | H16: 0 | I16: 0 | J16: 0 | K16: 0 | L16: 0 | M16: 0 | N16: 0 | O16: 0 | P16: 0 | Q16: 0 | R16: 0 | S16: 0 | T16: 0 | U16: 0 | V16: 0 | W16: 0 | X16: 202 | Y16: 6 | Z16: 202.75 | AA16: 202.75 | AB16: 0 | AC16: 202 | AD16: 6
A17: Oats | B17: Sown over 119.5 acres at Poundisford and Corfe, 48 quarters 6 bushels. | C17: 0 | D17: 0 | E17: 48 | F17: 6 | G17: 48.75 | H17: 0 | I17: 0 | J17: 0 | K17: 0 | L17: 0 | M17: 0 | N17: 0 | O17: 0 | P17: 0 | Q17: 0 | R17: 0 | S17: 0 | T17: 0 | U17: 0 | V17: 0 | W17: 0 | X17: 48 | Y17: 6 | Z17: 48.75 | AA17: 48.75 | AB17: 0 | AC17: 48 | AD17: 6
A18: Oats | B18: that is, 4 bushels an acre, less 11 quarters in all. | C18: 0 | D18: 0 | E18: 0 | F18: 0 | G18: 0 | H18: 0 | I18: 0 | J18: 0 | K18: 0 | L18: 0 | M18: 0 | N18: 0 | O18: 0 | P18: 0 | Q18: 0 | R18: 0 | S18: 0 | T18: 0 | U18: 0 | V18: 0 | W18: 0 | X18: 11 | Y18: 4 | Z18: 11.5 | AA18: 0.5 | AB18: 11 | AC18: 0 | AD18: 4 | AE18: 11 | AF18: 0
A19: Oats | B19: Also sown at Poundisford by the villeins according to custom, 26.5 acres. | C19: 0 | D19: 0 | E19: 0 | F19: 0 | G19: 0 | H19: 0 | I19: 0 | J19: 0 | K19: 0 | L19: 0 | M19: 0 | N19: 0 | O19: 0 | P19: 0 | Q19: 0 | R19: 0 | S19: 0 | T19: 0 | U19: 0 | V19: 0 | W19: 0 | X19: 0 | Y19: 0 | Z19: 0 | AA19: 0 | AB19: 0 | AC19: 0 | AD19: 0
A20: Oats | B20: Sold, 154 quarters. | C20: 0 | D20: 0 | E20: 0 | F20: 0 | G20: 0 | H20: 0 | I20: 0 | J20: 0 | K20: 0 | L20: 0 | M20: 0 | N20: 0 | O20: 0 | P20: 0 | Q20: 154 | R20: 0 | S20: 154 | T20: 0 | U20: 0 | V20: 0 | W20: 0 | X20: 154 | Y20: 0 | Z20: 154 | AA20: 154 | AB20: 0 | AC20: 154 | AD20: 0
A21: Oats | B21: Total, 202 quarters 6 bushels It balances. | C21: 0 | D21: 0 | E21: 0 | F21: 0 | G21: 0 | H21: 0 | I21: 0 | J21: 0 | K21: 0 | L21: 0 | M21: 0 | N21: 0 | O21: 0 | P21: 0 | Q21: 0 | R21: 0 | S21: 0 | T21: 0 | U21: 0 | V21: 0 | W21: 0 | X21: 202 | Y21: 6 | Z21: 202.75 | AA21: 202.75 | AB21: 0 | AC21: 202 | AD21: 6

Sheet Sale of Corn Prices
A1: Heading | B1: Sentence | C1: Total in Pounds | D1: Pounds | E1: Shillings | F1: Pence | G1: Corn | H1: Total Quarters Except 1 | I1: Total Bushels Except 1 | J1: Total Corn Cross-Check | K1: Total Corn Manorial Account | L1: Corn Quantity Error | M1: Quarters 0 | N1: Bushels 0 | O1: shilling a quarter 1 | P1: pence a quarter 1 | Q1: Quarters 1 | R1: Bushels 1 | S1: shilling a quarter 2 | T1: pence a quarter 2 | U1: Quarters 2 | V1: Bushels 2 | W1: shilling a quarter 3 | X1: pence a quarter 3 | Y1: shilling a quarter 4 | Z1: pence a quarter 4 | AA1: £ a quarter 1 | AB1: £ a quarter 2 | AC1: £ a quarter 3 | AD1: £ a quarter 4 | AE1: Quarters Sold | AF1: Weighted Average Price per Quarter | AG1: Non-Weighted Average Price per Quarter | AH1: Corn lowercase
A2: Sale of corn | B2: The same renders account for £15 16 shilling 3.5pence from 46.5 quarters of wheat sold, at 6 shilling 8pence a quarters for 8 quarters 6 bushels, and 6 shilling 10pence a quarters for 37 quarters 6 bushels sold to customary tenants. | C2: 15.81 | D2: 15 | E2: 16 | F2: 3.5 | G2: wheat | H2: 45 | I2: 12 | J2: 46.5 | K2: 46.5 | L2: 0 | M2: 46.5 | N2: 0 | O2: 6 | P2: 8 | Q2: 8 | R2: 6 | S2: 6 | T2: 10 | U2: 37 | V2: 6 | AA2: 0.33333333 | AB2: 0.34166667 | AE2: 46.5 | AF2: 0.34009857 | AG2: 0.3375 | AH2: wheat
A3: Sale of corn | B3: £13 9 shilling 6pence from 154 quarters of oats sold to customary tenants, at 1 shilling 9pence a quarters. | C3: 13.47 | D3: 13 | E3: 9 | F3: 6 | G3: oats | H3: 154 | I3: 0 | J3: 154 | K3: 154 | L3: 0 | M3: 154 | N3: 0 | O3: 1 | P3: 9 | AA3: 0.0875 | AE3: 154 | AF3: 0.0875 | AG3: 0.0875 | AH3: oats
A4: Sale of corn | B4: Total, £29 5 shilling 9.5pence | C4: 29.29 | D4: 29 | E4: 5 | F4: 9.5 | H4: 0 | I4: 0 | J4: 0 | K4: 0 | L4: 0 | M4: 0 | N4: 0 | AA4: inf | AE4: 0 | AF4: inf | AG4: inf
