Workbook

Sheet Overview
A1: ALVERSTOKE OVERVIEW - COMPLETED | B1: Total in £ | C1: Error | D1: Note
A2: CASH ACCOUNT
A3: RECEIPTS
A4: Arrears total | B4: 0.33
A5: Rents of assize total | B5: 53.56
A6: Quittances total
A7: Defaults of rent total
A8: Defaults of rent through the pestilence total
A9: Cotlands defaults total
A10: Cotlands total
A11: Total of quittances and defaults of rent total
A12: Total of rents remaining clear total
A13: Farms total
A14: Annual recognizances total
A15: Issues of the Manor total
A16: Issues of the tenements in the lord's hands total
A17: Sale of labour services total
... A22: Farm of the demesne land total
A23: Total of all receipts (calculated here) | B23: =SUM(B5:B11)
A24: Total of all receipts (calculated here) incl arrears | B24: =SUM(B4:B11)
A25: Total recorded in the accounts excl. arrears | B25: =Receipts!F24 | C25: =B23-B25
A26: Total recorded in the accounts incl. arrears | B26: =Receipts!F25
A29: EXPENSES
A30: Cost of ploughs total
A31: Purchase of corn total
A32: Cost of carts and wagons total
A33: Cost of dairy total
A34: Purchase of stock total
A35: Sheepcote total
A36: Cost of buildings total
A37: Threshing total
A38: Barley expenses
A39: Expenses of the harvest total
A40: Necessary expenses
... A43: Annual fees
A44: Total of all expenses per account | B44: 0
A45: Total of all expenses (calculated here) | B45: 0
A46: Total fixed investment | B46: 0
A47: Total Demesne fixed investment | B47: 0
A49: Owed by the reeve | B49: =B23-B45
...

Sheet Receipts
A1: ALVERSTOKE RECEIPTS
A2: Heading | B2: £ | C2: s | D2: d | F2: Total in £ | G2: Error | H2: Notes | I2: Own notes
A3: Arrears | B3: 0 | C3: 6 | D3: 8 | F3: 0.33 | H3: The same answers for 6 shilling 8pence of arrears from his last account of the preceding year.
A4: Arrears | B4: 0 | C4: 6 | D4: 8 | F4: 0.33 | H4: Total, 6 shilling 8pence.
A5: Arrears total | F5: 0.33 | G5: 0 | H5: Total
A7: Rents of assize | B7: 13 | C7: 0 | D7: 0 | F7: 13 | H7: And for £13 for all rents of assize at All Saints (1 November).
A8: Rents of assize | B8: 13 | C8: 0 | D8: 0 | F8: 13 | H8: £13 at the Purification (2 February).
A9: Rents of assize | B9: 13 | C9: 0 | D9: 0 | F9: 13 | H9: £13 at the Invention of the Cross in May (3 May).
A10: Rents of assize | B10: 14 | C10: 0 | D10: 6 | F10: 14.03 | H10: £14 6pence at Michaelmas (29 September).
A11: Rents of assize | B11: 0 | C11: 10 | D11: 0 | F11: 0.5 | H11: 10 shilling from John Chark' for 1 messuage and 1 virgate of villein land in Chark' at the said Michaelmas.
A12: Rents of assize | B12: 0 | C12: 0 | D12: 8 | F12: 0.03 | H12: 8pence from John Crede and Alice Upton' for 2 streams (fluetr) and 1 marsh at the same.
A13: Rents of assize | B13: 53 | C13: 11 | D13: 2.5 | F13: 53.56 | H13: Total, £53 11 shilling 2.5pence.
A14: Rents of assize total | F14: 53.56 | G14: 0 | H14: Total
A16: Reliefs | B16: 0 | C16: 3 | D16: 2 | F16: 0.16 | H16: And for 3 shilling 2pence for the relief of Agnes, wife of John Swele, to have 1 toft and certain land and a tenement in Elston' which descended to her by hereditary right after the death of Thomas Carpent' her brother.
A17: Reliefs | B17: 0 | C17: 3 | D17: 2 | F17: 0.16 | H17: Total, 3 shilling 2pence.
A18: Reliefs total | F18: 0.16 | G18: 0 | H18: Total
A20: Perquisites | B20: 0 | C20: 6 | D20: 1 | F20: 0.3 | H20: And for 6 shilling 1pence from the perquisites of the tourn of Martinmas (11 November).
A21: Perquisites | B21: 0 | C21: 4 | D21: 7 | F21: 0.23 | H21: 4 shilling 7pence from the perquisites of the tourn of Hockday (1 April).
A22: Perquisites | B22: 0 | C22: 7 | D22: 3 | F22: 0.36 | H22: 7 shilling 3pence from the perquisites of the courts held by the bailiff.
A23: Perquisites total | B23: 0 | C23: 17 | D23: 11 | F23: 0.9 | G23: 0.54 | H23: Total, 17 shilling 11pence.
A24: Total of all receipts recorded in accounts (calculated here) | F24: =SUMIF(A1:A23,"* total",F1:F23)-SUMIF(A1:A23,"Arrears total",F1:F23)
A25: Total of all receipts (calculated here) incl arrears | F25: =F24+SUMIF(A1:A23,"Arrears total",F1:F23)

Sheet Expenses
A1: ALVERSTOKE EXPENSES
A2: Heading | B2: £ | C2: s | D2: d | F2: Total in £ | G2: Error | H2: Sentence | I2: Fixed Investments | J2: Demesne Fixed Investments
A4: Cash deliveries | B4: 55 | C4: 0 | D4: 5.5 | F4: 55.02 | H4: Delivered to John Arnold', receiver of Wolvesey, by 1 tally, £55 5.5pence.
A5: Cash deliveries | B5: 55 | C5: 0 | D5: 5.5 | F5: 55.02 | H5: Total, £55 5.5pence.
A6: Cash deliveries total | F6: 55.02 | G6: 0 | H6: Total

Sheet Stock
A1: ALVERSTOKE STOCK ACCOUNT
C3: added | G3: subtracted
A4: Livestock | B4: Inherited stock | C4: added | D4: strays | E4: herbage | F4: churchscot | G4: of which in default | H4: sold | I4: in murrain | J4: accounted for elsewhere | K4: End-period stock | L4: cross-check | M4: stock building | N4: raw production | O4: Unit price (£) | P4: Value of stock (£) at given value | Q4: Value of stock (£) at sales prices | R4: Sales in (£) | S4: Value of stock building (£) | T4: Value of production (£) at sales prices | U4: Details
A5: Cart-horses | B5: 0 | C5: 0 | H5: 0 | I5: 0 | K5: =B5+C5-H5-I5 | L5: =B5+C5-H5 | M5: =L5-B5 | N5: =C5 | O5: 0 | P5: =O5*K5 | R5: 0 | S5: =O5*M5 | T5: =O5*N5
A6: Mares | B6: 0 | C6: 0 | H6: 0 | I6: 0 | K6: =B6+C6-H6-I6 | L6: =B6+C6-H6 | M6: =L6-B6 | N6: =C6 | O6: 0 | P6: =O6*K6 | R6: 0 | S6: =O6*M6 | T6: =O6*N6
A7: Plough horses | B7: 0 | C7: 0 | H7: 0 | I7: 0 | K7: =B7+C7-H7-I7 | L7: =B7+C7-H7 | M7: =L7-B7 | N7: =C7 | O7: 0 | P7: =O7*K7 | R7: 0 | S7: =O7*M7 | T7: =O7*N7
A8: Colts (unspecified years) | B8: 0 | C8: 0 | H8: 0 | I8: 0 | K8: =B8+C8-H8-I8 | L8: =B8+C8-H8 | M8: =L8-B8 | N8: =C8 | O8: 0 | P8: =O8*K8 | R8: 0 | S8: =O8*M8 | T8: =O8*N8
A9: Colts (2 years) | B9: 0 | C9: 0 | H9: 0 | I9: 0 | K9: =B9+C9-H9-I9 | L9: =B9+C9-H9 | M9: =L9-B9 | N9: =C9 | O9: 0 | P9: =O9*K9 | R9: 0 | S9: =O9*M9 | T9: =O9*N9
A10: Colts (1 year) | B10: 0 | C10: 0 | H10: 0 | I10: 0 | K10: =B10+C10-H10-I10 | L10: =B10+C10-H10 | M10: =L10-B10 | N10: =C10 | O10: 0 | P10: =O10*K10 | R10: 0 | S10: =O10*M10 | T10: =O10*N10
A11: Foals | B11: 0 | C11: 0 | H11: 0 | I11: 0 | K11: =B11+C11-H11-I11 | L11: =B11+C11-H11 | M11: =L11-B11 | N11: =C11 | O11: 0 | P11: =O11*K11 | R11: 0 | S11: =O11*M11 | T11: =O11*N11
A12: Oxen | B12: 0 | C12: 0 | H12: 0 | I12: 0 | K12: =B12+C12-H12-I12 | L12: =B12+C12-H12 | M12: =L12-B12 | N12: =C12 | O12: 0 | P12: =O12*K12 | R12: 0 | S12: =O12*M12 | T12: =O12*N12
A13: Bulls | B13: 0 | C13: 0 | H13: 0 | I13: 0 | K13: =B13+C13-H13-I13 | L13: =B13+C13-H13 | M13: =L13-B13 | N13: =C13 | O13: 0 | P13: =O13*K13 | R13: 0 | S13: =O13*M13 | T13: =O13*N13
A14: Cows | B14: 0 | C14: 0 | H14: 0 | I14: 0 | K14: =B14+C14-H14-I14 | L14: =B14+C14-H14 | M14: =L14-B14 | N14: =C14 | O14: 0 | P14: =O14*K14 | R14: 0 | S14: =O14*M14 | T14: =O14*N14
A15: Steers | B15: 0 | C15: 0 | H15: 0 | I15: 0 | K15: =B15+C15-H15-I15 | L15: =B15+C15-H15 | M15: =L15-B15 | N15: =C15 | O15: 0 | P15: =O15*K15 | R15: 0 | S15: =O15*M15 | T15: =O15*N15
A16: Bullocks | B16: 0 | C16: 0 | H16: 0 | I16: 0 | K16: =B16+C16-H16-I16 | L16: =B16+C16-H16 | M16: =L16-B16 | N16: =C16 | O16: 0 | P16: =O16*K16 | R16: 0 | S16: =O16*M16 | T16: =O16*N16
... A20: Rams | B20: 0 | C20: 0 | H20: 0 | I20: 0 | K20: =B20+C20-H20-I20 | L20: =B20+C20-H20 | M20: =L20-B20 | N20: =C20 | O20: 0 | P20: =O20*K20 | R20: 0 | S20: =O20*M20 | T20: =O20*N20
A21: Ewes | B21: 0 | C21: 0 | H21: 0 | I21: 0 | K21: =B21+C21-H21-I21 | L21: =B21+C21-H21 | M21: =L21-B21 | N21: =C21 | O21: 0 | P21: =O21*K21 | Q21: 0 | R21: 0 | S21: =O21*M21 | T21: =O21*N21
A22: Hoggs | B22: 0 | C22: 0 | H22: 0 | I22: 0 | K22: =B22+C22-H22-I22 | L22: =B22+C22-H22 | M22: =L22-B22 | N22: =C22 | O22: 0 | P22: =O22*K22 | R22: 0 | S22: =O22*M22 | T22: =O22*N22
A23: Lambs | B23: 0 | C23: 0 | H23: 0 | I23: 0 | K23: =B23+C23-H23-I23 | L23: =B23+C23-H23 | M23: =L23-B23 | N23: =C23 | O23: 0 | P23: =O23*K23 | R23: 0 | S23: =O23*M23 | T23: =O23*N23
A24: Boars | B24: 0 | C24: 0 | H24: 0 | I24: 0 | K24: =B24+C24-H24-I24 | L24: =B24+C24-H24 | M24: =L24-B24 | N24: =C24 | O24: 0 | P24: =O24*K24 | R24: 0 | S24: =O24*M24 | T24: =O24*N24
A25: Sows | B25: 0 | C25: 0 | H25: 0 | I25: 0 | K25: =B25+C25-H25-I25 | L25: =B25+C25-H25 | M25: =L25-B25 | N25: =C25 | O25: 0 | P25: =O25*K25 | R25: 0 | S25: =O25*M25 | T25: =O25*N25
A26: Pigs | B26: 0 | C26: 0 | H26: 0 | I26: 0 | K26: =B26+C26-H26-I26 | L26: =B26+C26-H26 | M26: =L26-B26 | N26: =C26 | O26: 0 | P26: =O26*K26 | R26: 0 | S26: =O26*M26 | T26: =O26*N26
A27: Hoggets | B27: 0 | C27: 0 | H27: 0 | I27: 0 | K27: =B27+C27-H27-I27 | L27: =B27+C27-H27 | M27: =L27-B27 | N27: =C27 | O27: 0 | P27: =O27*K27 | R27: 0 | S27: =O27*M27 | T27: =O27*N27
A28: Piglets | B28: 0 | C28: 0 | H28: 0 | I28: 0 | K28: =B28+C28-H28-I28 | L28: =B28+C28-H28 | M28: =L28-B28 | N28: =C28 | O28: 0 | P28: =O28*K28 | R28: 0 | S28: =O28*M28 | T28: =O28*N28
A29: Swans | B29: 0 | C29: 0 | H29: 0 | I29: 0 | K29: =B29+C29-H29-I29 | L29: =B29+C29-H29 | M29: =L29-B29 | N29: =C29 | O29: 0 | P29: =O29*K29 | R29: 0 | S29: =O29*M29 | T29: =O29*N29
A30: Peacocks | B30: 0 | C30: 0 | H30: 0 | I30: 0 | K30: =B30+C30-H30-I30 | L30: =B30+C30-H30 | M30: =L30-B30 | N30: =C30 | O30: 0 | P30: =O30*K30 | R30: 0 | S30: =O30*M30 | T30: =O30*N30
A31: Total Value
A34: Wool | B34: 0 | C34: 0 | H34: 0 | I34: 0
A35: Coarse wool | B35: 0 | C35: 0 | H35: 0 | I35: 0
A36: Lamb's wool | B36: 0 | C36: 0 | H36: 0 | I36: 0
A37: Wool locks | B37: 0 | C37: 0 | H37: 0 | I37: 0
A38: Wool sold at shearing | B38: 0 | C38: 0 | H38: 0 | I38: 0
A39: Total wool | B39: 0 | C39: 0 | H39: 0 | I39: 0
B40: 0 | C40: 0 | H40: 0 | I40: 0
B41: 0 | C41: 0 | H41: 0 | I41: 0
A42: Hides | B42: 0 | C42: 0 | H42: 0 | I42: 0
A43: Ox hides | B43: 0 | C43: 0 | H43: 0 | I43: 0
A44: Mare | B44: 0 | C44: 0 | H44: 0 | I44: 0
A45: Steer | B45: 0 | C45: 0 | H45: 0 | I45: 0
A46: calves | B46: 0 | C46: 0 | H46: 0 | I46: 0
...

Sheet raw data
A1: Heading | B1: Sentence | C1: Total in Pounds | D1: Pounds | E1: Shillings | F1: Pence | G1: Corn | H1: Total Quarters Except 1 | I1: Total Bushels Except 1 | J1: Total Corn Cross-Check | K1: Total Corn Manorial Account | L1: Corn Quantity Error | M1: Quarters 1 | N1: Bushels 1 | O1: shilling a quarter 1 | P1: pence a quarter 1 | Q1: shilling a quarter 2 | R1: pence a quarter 2 | S1: shilling a quarter 3 | T1: pence a quarter 3 | U1: shilling a quarter 4 | V1: pence a quarter 4 | W1: shilling a bushel 1 | X1: pence a bushel 1 | Y1: shilling a bushel 2 | Z1: pence a bushel 2 | AA1: shilling a bushel 3 | AB1: pence a bushel 3 | AC1: shilling a bushel 4 | AD1: pence a bushel 4
A2: Alverstoke | B2: The account of John Weston’, bailiff there, from Michaelmas of the fifth year of the translation of Henry Beaufort’, lord bishop of Winchester, until Michaelmas of the sixth year, for one whole year, and the elevent year of the reign of King Henry the Fourth. | C2: 0 | D2: 0 | E2: 0 | F2: 0 | H2: 0 | I2: 0 | J2: 0 | K2: 0 | L2: 0 | M2: 0 | N2: 0
A3: Arrears | B3: The same answers for 6 shilling 8pence of arrears from his last account of the preceding year. | C3: 0.33 | D3: 0 | E3: 6 | F3: 8 | H3: 0 | I3: 0 | J3: 0 | K3: 0 | L3: 0 | M3: 0 | N3: 0
A4: Arrears | B4: Total, 6 shilling 8pence. | C4: 0.33 | D4: 0 | E4: 6 | F4: 8 | H4: 0 | I4: 0 | J4: 0 | K4: 0 | L4: 0 | M4: 0 | N4: 0
A5: Rents of assize | B5: And for £13 for all rents of assize at All Saints (1 November). | C5: 13 | D5: 13 | E5: 0 | F5: 0 | H5: 0 | I5: 0 | J5: 0 | K5: 0 | L5: 0 | M5: 0 | N5: 0
A6: Rents of assize | B6: £13 at the Purification (2 February). | C6: 13 | D6: 13 | E6: 0 | F6: 0 | H6: 0 | I6: 0 | J6: 0 | K6: 0 | L6: 0 | M6: 0 | N6: 0
A7: Rents of assize | B7: £13 at the Invention of the Cross in May (3 May). | C7: 13 | D7: 13 | E7: 0 | F7: 0 | H7: 0 | I7: 0 | J7: 0 | K7: 0 | L7: 0 | M7: 0 | N7: 0
A8: Rents of assize | B8: £14 6pence at Michaelmas (29 September). | C8: 14.03 | D8: 14 | E8: 0 | F8: 6 | H8: 0 | I8: 0 | J8: 0 | K8: 0 | L8: 0 | M8: 0 | N8: 0
A9: Rents of assize | B9: 10 shilling from John Chark' for 1 messuage and 1 virgate of villein land in Chark' at the said Michaelmas. | C9: 0.5 | D9: 0 | E9: 10 | F9: 0 | H9: 0 | I9: 0 | J9: 0 | K9: 0 | L9: 0 | M9: 0 | N9: 0
A10: Rents of assize | B10: 8pence from John Crede and Alice Upton' for 2 streams (fluetr) and 1 marsh at the same. | C10: 0.03 | D10: 0 | E10: 0 | F10: 8 | H10: 0 | I10: 0 | J10: 0 | K10: 0 | L10: 0 | M10: 0 | N10: 0
A11: Rents of assize | B11: Total, £53 11 shilling 2.5pence. | C11: 53.56 | D11: 53 | E11: 11 | F11: 2.5 | H11: 0 | I11: 0 | J11: 0 | K11: 0 | L11: 0 | M11: 0 | N11: 0
A12: Mills | B12: Nothing for the farm of the mill because it is completely destroyed. | C12: 0 | D12: 0 | E12: 0 | F12: 0 | H12: 0 | I12: 0 | J12: 0 | K12: 0 | L12: 0 | M12: 0 | N12: 0
A13: Mills | B13: Nothing for annual recognizance this year. | C13: 0 | D13: 0 | E13: 0 | F13: 0 | H13: 0 | I13: 0 | J13: 0 | K13: 0 | L13: 0 | M13: 0 | N13: 0
... A16: Issues of the land | B16: Total, 4 shilling 10pence. | C16: 0.24 | D16: 0 | E16: 4 | F16: 10 | H16: 0 | I16: 0 | J16: 0 | K16: 0 | L16: 0 | M16: 0 | N16: 0
A17: Annual farms | B17: And for 3 shilling 4pence for the annual farm of Thomas le Mulward', so that he will not be prosecuted (occasionetur)1 because he grinds the malt of the tenants in Alverstoke in his horse-mill, whilst it pleases the lord. | C17: 0.17 | D17: 0 | E17: 3 | F17: 4 | G17: malt | H17: 0 | I17: 0 | J17: 0 | K17: 0 | L17: 0 | M17: 0 | N17: 0
A18: Annual farms | B18: nothing of the 8 shilling from John Norton' for 1 messuage and 22 acres of land in Bury which belonged to Richard Caugemyle because Richard Russell' made relief for the same as the heir and kinsman of the said Richard. | C18: 0.4 | D18: 0 | E18: 8 | F18: 0 | H18: 0 | I18: 0 | J18: 0 | K18: 0 | L18: 0 | M18: 0 | N18: 0
A19: Annual farms | B19: Total, 3 shilling 4pence. | C19: 0.17 | D19: 0 | E19: 3 | F19: 4 | H19: 0 | I19: 0 | J19: 0 | K19: 0 | L19: 0 | M19: 0 | N19: 0
A20: Reliefs | B20: And for 3 shilling 2pence for the relief of Agnes, wife of John Swele, to have 1 toft and certain land and a tenement in Elston' which descended to her by hereditary right after the death of Thomas Carpent' her brother. | C20: 0.16 | D20: 0 | E20: 3 | F20: 2 | H20: 0 | I20: 0 | J20: 0 | K20: 0 | L20: 0 | M20: 0 | N20: 0
A21: Reliefs | B21: Total, 3 shilling 2pence. | C21: 0.16 | D21: 0 | E21: 3 | F21: 2 | H21: 0 | I21: 0 | J21: 0 | K21: 0 | L21: 0 | M21: 0 | N21: 0
A22: Perquisites | B22: And for 6 shilling 1pence from the perquisites of the tourn of Martinmas (11 November). | C22: 0.3 | D22: 0 | E22: 6 | F22: 1 | H22: 0 | I22: 0 | J22: 0 | K22: 0 | L22: 0 | M22: 0 | N22: 0
A23: Perquisites | B23: 4 shilling 7pence from the perquisites of the tourn of Hockday (1 April). | C23: 0.23 | D23: 0 | E23: 4 | F23: 7 | H23: 0 | I23: 0 | J23: 0 | K23: 0 | L23: 0 | M23: 0 | N23: 0
A24: Perquisites | B24: 7 shilling 3pence from the perquisites of the courts held by the bailiff. | C24: 0.36 | D24: 0 | E24: 7 | F24: 3 | H24: 0 | I24: 0 | J24: 0 | K24: 0 | L24: 0 | M24: 0 | N24: 0
A25: Perquisites | B25: Total, 17 shilling 11pence. | C25: 0.9 | D25: 0 | E25: 17 | F25: 11 | H25: 0 | I25: 0 | J25: 0 | K25: 0 | L25: 0 | M25: 0 | N25: 0
A26: Total of all receipts with arrears | B26: Total of all receipts with arrears, £55 7 shilling 1.5pence. | C26: 55.36 | D26: 55 | E26: 7 | F26: 1.5 | H26: 0 | I26: 0 | J26: 0 | K26: 0 | L26: 0 | M26: 0 | N26: 0
A27: Cash deliveries | B27: Delivered to John Arnold', receiver of Wolvesey, by 1 tally, £55 5.5pence. | C27: 55.02 | D27: 55 | E27: 0 | F27: 5.5 | H27: 0 | I27: 0 | J27: 0 | K27: 0 | L27: 0 | M27: 0 | N27: 0
A28: Cash deliveries | B28: Total, £55 5.5pence. | C28: 55.02 | D28: 55 | E28: 0 | F28: 5.5 | H28: 0 | I28: 0 | J28: 0 | K28: 0 | L28: 0 | M28: 0 | N28: 0
A29: And he owes clear | B29: And he owes clear, 6 shilling 8pence, all of which is in the hands of the escheator, for which he is charged in the following account. | C29: 0.33 | D29: 0 | E29: 6 | F29: 8 | H29: 0 | I29: 0 | J29: 0 | K29: 0 | L29: 0 | M29: 0 | N29: 0

Sheet Issues of the Grange

Sheet Issues of the Mills

Sheet Stock_raw

Sheet Prices

Sheet Labour Rents

Sheet not needed
