Workbook

Sheet Overview
A1: BISHOPSSUTTON OVERVIEW - COMPLETED | B1: Total in £ | C1: Error | D1: Note
A2: CASH ACCOUNT
A3: RECEIPTS
A4: Arrears total | B4: 8.88
A5: Rents of assize total | B5: 52.01
A6: Quittances total | B6: 0.8
A7: Defaults of rent total | B7: 4.77
A8: Defaults of rent through the pestilence total
A9: Cotlands defaults total
A10: Cotlands total
A11: Total of quittances and defaults of rent total | B11: 10.4
A12: Total of rents remaining clear total | B12: 41.61
A13: Farms total
A14: Annual recognizances total | B14: 0.21
A15: Issues of the Manor total | B15: 31.1
A16: Issues of the tenements in the lord's hands total
A17: Sale of labour services total
A18: Sale of corn total
A19: Entry and marriage fines total
A20: Pleas & perquisites total | B20: 3.98
A21: Forfeited chattels total
A22: Farm of the demesne land total
A23: Total of all receipts (calculated here) | B23: =SUM(B5:B11) -> 67.98
A24: Total of all receipts (calculated here) incl arrears | B24: =SUM(B4:B11) -> 76.86
A25: Total recorded in the accounts excl. arrears | B25: =Receipts!F108 -> 148.63 | C25: =B23-B25 -> -80.65
A26: Total recorded in the accounts incl. arrears | B26: =Receipts!F109 -> 157.51
A29: EXPENSES
A30: Cost of ploughs total | B30: 1.39
A31: Purchase of corn total
A32: Cost of carts and wagons total | B32: 1.37
A33: Cost of dairy total
A34: Purchase of stock total
A35: Sheepcote total
A36: Cost of buildings total
A37: Threshing total | B37: 1.16
A38: Barley expenses
A39: Expenses of the harvest total | B39: 1.41
A40: Necessary expenses
A41: Wages of the bailiff
A42: Steward's expenses total | B42: 0.87
...

Sheet Receipts
A1: BISHOPSSUTTON RECEIPTS
A2: Heading | B2: £ | C2: s | D2: d | F2: Total in £ | G2: Error | H2: Notes | I2: Own notes
A3: Arrears | B3: 8 | C3: 17 | D3: 6 | F3: 8.88 | H3: The same answers for £8 17 shilling 6pence of arrears from his last account of the preceding year.
A4: Arrears | B4: 8 | C4: 17 | D4: 6 | F4: 8.88 | H4: Total, £8 17 shilling 6pence.
A5: Arrears total | F5: 8.88 | G5: 0 | H5: Total
A7: Rents of assize | B7: 9 | C7: 10 | D7: 10.25 | F7: 9.54 | H7: And for £9 10 shilling 10.25pence for all rents of assize at Christmas.
A8: Rents of assize | B8: 9 | C8: 10 | D8: 11 | F8: 9.55 | H8: £9 10 shilling 11pence at Easter (23 March).
A9: Rents of assize | B9: 9 | C9: 10 | D9: 10.25 | F9: 9.54 | H9: £9 10 shilling 10.25pence at the Nativity of St John the Baptist (24 June).
A10: Rents of assize | B10: 23 | C10: 7 | D10: 7 | F10: 23.38 | H10: £23 7 shilling 7pence at Michaelmas (29 September).
A11: Rents of assize | B11: 52 | C11: 0 | D11: 2.5 | F11: 52.01 | H11: Total, £52 2.5pence.
A12: Rents of assize total | F12: 52.01 | G12: 0 | H12: Total
A14: Quittances | B14: 0 | C14: 5 | D14: 0 | F14: 0.25 | H14: In quittance of rent of 1 reeve for the year 5 shilling.
A15: Quittances | B15: 0 | C15: 2 | D15: 0 | F15: 0.1 | H15: 1 smith for the year 2 shilling.
A16: Quittances | B16: 0 | C16: 0 | D16: 0 | F16: 0 | H16: 1 cowherd for the year, nothing, because there is none there from the customary tenants but he has the lord's livery as made clear elsewhere.
A17: Quittances | B17: 0 | C17: 3 | D17: 0 | F17: 0.15 | H17: 1 ploughman for the year 3 shilling.
A18: Quittances | B18: 0 | C18: 3 | D18: 0 | F18: 0.15 | H18: 1 keeper of wethers for the year 3 shilling.
A19: Quittances | B19: 0 | C19: 3 | D19: 0 | F19: 0.15 | H19: 1 swineherd for the year 3 shilling.
A20: Quittances | B20: 0 | C20: 16 | D20: 0 | F20: 0.8 | H20: Total, 16 shilling.
A21: Quittances total | F21: 0.8 | G21: 0 | H21: Total
A23: Defaults of rent | B23: 0 | C23: 2 | D23: 0 | F23: 0.1 | H23: In default of Philip Molendinarius, 2 shilling for the year.
A24: Defaults of rent | B24: 0 | C24: 1 | D24: 0 | F24: 0.05 | H24: the land of Geoffrey Hose given to the canons of Merton Priory 1 shilling.
A25: Defaults of rent | B25: 0 | C25: 0 | D25: 6 | F25: 0.03 | H25: 1 plot of land which belonged to John Pulent' 6pence.
A26: Defaults of rent | B26: 0 | C26: 10 | D26: 0 | F26: 0.5 | H26: I virgate of land of Adam Bedell' drawn into demesne, 10 shilling for the year.
A27: Defaults of rent | B27: 0 | C27: 3 | D27: 3 | F27: 0.16 | H27: 1 messuage pertaining to the mill and 1 plot pertaining to the bakehouse drawn into demesne, which William Carpunt' held, 3 shilling 3pence for the year.
A28: Defaults of rent | B28: 0 | C28: 1 | D28: 6 | F28: 0.08 | H28: 3 acres of land which Guy de Haywode held at la Gate drawn into demesne, 1 shilling 6pence for the year.
A29: Defaults of rent | B29: 0 | C29: 0 | D29: 8 | F29: 0.03 | H29: 1 plot of land which belonged to John Gilberd' drawn into demesne, 8pence for the year.
A30: Defaults of rent | B30: 2 | C30: 8 | D30: 4 | F30: 2.42 | H30: 1 messuage, 1 water-mill, 20.5 acres of land, 13 acres 1 kaild of purpresture, and 10 acres of wood, containing 40 acres of wood by estimation, formerly of John, son of John de Godisfeld', all of which was recently held unjustly by William de Overton', knight, by intrusion made into it in the time of William de Edyngdon', recently lord bishop of Winchester, and which the aforesaid bishop reseized, resumed and had drawn into demesne from the hands of the aforesaid William de Overton' as his right and that of his aforesaid church of Winchester, £2 8 shilling 4pence, and know that of the aforesaid 2 messuages 1 is at the mill beside the curia of Bishops Sutton and the other messuage is in fact that which the aforesaid John, son of John de Godisfeld', held and which Reginald Cornow held before, and that the third messuage is that which the aforesaid John, son of John de Godisfeld', held and which John atte Frithe held before, and nothing is in default because William Hokkele fined for the same, for this the fifty-first year.
A31: Defaults of rent | B31: 0 | C31: 0 | D31: 0 | F31: 0 | H31: all the land and tenements which belonged to John atte Fysshwer' and which William de Overton', knight, afterwards unjustly held and which the aforesaid bishop recovered and had drawn into demesne, as his right and that of his aforesaid church of.
A32: Defaults of rent | B32: 0 | C32: 7 | D32: 0 | F32: 0.35 | H32: Winchester, by a writ in the court of the lord king at Westminster in the thirty-second year of the reign of King Edward the Third after the Conquest (1358), under the description, 1 messuage 11h virgates of land, against the aforesaid William de Overton', by judgement tried (triat') in the same court against the accused, 7 shilling.
A33: Defaults of rent | B33: 0 | C33: 7 | D33: 0 | F33: 0.35 | H33: 1 messuage virgate of villein land formerly of Alice Clerk', who was wife of Roger Clerk' of Bishops Sutton, and which the aforesaid bishop recovered and had drawn into demense against the aforesaid William de Overton' in the aforesaid year in a similar way 7 shilling.
A34: Defaults of rent | B34: 0 | C34: 1 | D34: 6 | F34: 0.08 | H34: 3 acres of land lying in la Mullecroft, containing 5 acres by estimation, which the aforesaid bishop recovered and had drawn into demesne against the aforesaid wiiiiana de Overton' in the thirty-first and thirty-second years of the aforesaid king (1357-8), under the description, 5 acres of land, in a similar way, 1 shilling 6pence.
... A40: Defaults of rent | B40: 4 | C40: 14 | D40: 11 | F40: 4.75 | H40: Total, £4 14 shilling 11pence.
A41: Defaults of rent total | F41: 4.77 | G41: 0.02 | H41: Total
A43: Total of quittances and defaults of rent | B43: 10 | C43: 8 | D43: 0 | F43: 10.4 | H43: Total of quittances and defaults of rent, £10 8 shilling.
A44: Total of quittances and defaults of rent total | F44: 10.4 | G44: 0 | H44: Total
A46: Total of rents remaining clear | B46: 41 | C46: 12 | D46: 2.5 | F46: 41.61 | H46: Total of rents remaining clear, £41 12 shilling 2.5pence.
A47: Total of rents remaining clear total | F47: 41.61 | G47: 0 | H47: Total
A49: Annual recognizance | B49: 0 | C49: 1 | D49: 0 | F49: 0.05 | H49: Nothing of the 1 shilling for the annual recognizance of Robert Smyth' because he is dead as established by the court roll.
A50: Annual recognizance | B50: 0 | C50: 0 | D50: 2 | F50: 0.01 | H50: nothing of the 2pence for the annual recognizance of Thomas Tannere because he withdrew from the demesne as made clear as before.
A51: Annual recognizance | B51: 0 | C51: 1 | D51: 0 | F51: 0.05 | H51: 1 shilling from William Coupere so that he may dwell outside the lord's liberty as long as it pleases the lord and come to the tourn of Hockday for the year and remain the lord's villein as before.
...

Sheet Expenses
A1: BISHOPSSUTTON EXPENSES
A2: Heading | B2: £ | C2: s | D2: d | F2: Total in £ | G2: Error | H2: Sentence | I2: Fixed Investments | J2: Demesne Fixed Investments
A4: Cost of ploughs | B4: 0 | C4: 12 | D4: 10 | F4: 0.64 | H4: In iron and steel bought for the ironwork of 2 ploughs for the year 12 shilling 10pence. | I4: 0 | J4: 0
A5: Cost of ploughs | B5: 0 | C5: 1 | D5: 2 | F5: 0.06 | H5: 2 plough feet with nails bought for the same 1 shilling 2pence. | I5: 0 | J5: 0
A6: Cost of ploughs | B6: 0 | C6: 1 | D6: 4 | F6: 0.07 | H6: 2 pairs of wheels bought for the ploughs 1 shilling 4pence. | I6: 0 | J6: 0
A7: Cost of ploughs | B7: 0 | C7: 0 | D7: 6 | F7: 0.03 | H7: 1 plough made 6pence. | I7: 0 | J7: 0
A8: Cost of ploughs | B8: 0 | C8: 0 | D8: 4 | F8: 0.02 | H8: fitting the same with iron tyres 4pence. | I8: 0 | J8: 0
A9: Cost of ploughs | B9: 0 | C9: 0 | D9: 8 | F9: 0.03 | H9: fitting the ploughs with share-beams and mould-boards for the year 8pence.
A10: Cost of ploughs | B10: 0 | C10: 1 | D10: 6 | F10: 0.08 | H10: 1 ploughshare bought 1 shilling 6pence. | I10: 0.08 | J10: 0.08
A11: Cost of ploughs | B11: 0 | C11: 0 | D11: 6 | F11: 0.03 | H11: mending harrows 6pence. | I11: 0 | J11: 0
A12: Cost of ploughs | B12: 0 | C12: 2 | D12: 6 | F12: 0.12 | H12: shoeing 10 oxen and fastening them again 2 shilling 6pence. | I12: 0 | J12: 0
A13: Cost of ploughs | B13: 0 | C13: 2 | D13: 0 | F13: 0.1 | H13: customary payment to 12 customary tenants ploughing 24 acres as they lie at the winter and Lenten sowings 2 shilling. | I13: 0 | J13: 0
A14: Cost of ploughs | B14: 0 | C14: 0 | D14: 3 | F14: 0.01 | H14: 3 yokes made anew 3pence. | I14: 0 | J14: 0
A15: Cost of ploughs | B15: 0 | C15: 4 | D15: 0 | F15: 0.2 | H15: stipend of 1 drover for the year 4 shilling. | I15: 0 | J15: 0
A16: Cost of ploughs | B16: 1 | C16: 7 | D16: 8 | F16: 1.38 | H16: Total, £1 7 shilling 8pence. | I16: 0 | J16: 0
A17: Cost of ploughs total | F17: 1.39 | G17: 0.01 | H17: Total
A19: Cost of carts | B19: 0 | C19: 2 | D19: 0 | F19: 0.1 | H19: In clouts with nails bought for the carts 2 shilling.
A20: Cost of carts | B20: 0 | C20: 0 | D20: 8 | F20: 0.03 | H20: fitting the carts with axles 8pence.
A21: Cost of carts | B21: 0 | C21: 1 | D21: 0 | F21: 0.05 | H21: greasing the carts 1 shilling.
A22: Cost of carts | B22: 0 | C22: 1 | D22: 8 | F22: 0.08 | H22: white leather bought 1 shilling 8pence.
A23: Cost of carts | B23: 0 | C23: 0 | D23: 6 | F23: 0.03 | H23: 6 halters bought 6pence.
A24: Cost of carts | B24: 0 | C24: 2 | D24: 6 | F24: 0.12 | H24: 3 collars bought 2 shilling 6pence.
A25: Cost of carts | B25: 0 | C25: 1 | D25: 10 | F25: 0.09 | H25: 3 pairs of traces bought 1 shilling 10pence.
A26: Cost of carts | B26: 0 | C26: 1 | D26: 4 | F26: 0.07 | H26: 2 wood-ropes (woderop') bought 1 shilling 4pence.
A27: Cost of carts | B27: 0 | C27: 8 | D27: 0 | F27: 0.4 | H27: shoeing 4 horses for the year 8 shilling, and know that the smith will shoe 2 cart-horses at his own cost according to custom.
A28: Cost of carts | B28: 0 | C28: 8 | D28: 0 | F28: 0.4 | H28: stipend of 2 carters for the year 8 shilling.
A29: Cost of carts | B29: 1 | C29: 7 | D29: 6 | F29: 1.38 | H29: Total, £1 7 shilling 6pence.
A30: Cost of carts total | F30: 1.37 | G30: -0.01 | H30: Total
A32: Cost of the park | B32: 1 | C32: 15 | D32: 0 | F32: 1.75 | H32: In enclosing with new hedge 7 furlongs between Wyitonesrede and Clandon' £1 15 shilling, at 5 shilling a furlong. | I32: 1.75 | J32: 1.75
A33: Cost of the park | B33: 0 | C33: 0 | D33: 0 | F33: 0 | H33: enclosing with new hedge 2 furlongs at Brynkeworthes Rede lOs. | I33: 0 | J33: 0
A34: Cost of the park | B34: 3 | C34: 0 | D34: 10 | F34: 3.04 | H34: wages of the park-keeper for the year £3 10pence, taking 2pence a day. | I34: 0 | J34: 0
A35: Cost of the park | B35: 5 | C35: 5 | D35: 10 | F35: 5.29 | H35: Total, £5 5 shilling 10pence.
A36: Cost of the park total | F36: 4.79 | G36: -0.5 | H36: Total
A38: Cost of the mill | B38: 6 | C38: 0 | D38: 0 | F38: 6 | H38: In stipend of 4 carpenters making anew the mill-pond and sluice for 12 weeks £6 taking between them 10 shilling a week.
A39: Cost of the mill | B39: 0 | C39: 0 | D39: 0 | F39: 0 | H39: diverting the water from the mill, ramming i.
A40: Cost of the mill | B40: 0 | C40: 3 | D40: 4 | F40: 0.17 | H40: again, blocking it up and directing it into its right course by piece-work 3 shilling 4pence in expenses of the carters of the manor and other men helping to load the carts carrying timber to the aforesaid mill at various times 2 shilling.
A41: Cost of the mill | B41: 0 | C41: 6 | D41: 0 | F41: 0.3 | H41: 400 water-nails bought to fasten the flooring 6 shilling.
A42: Cost of the mill | B42: 0 | C42: 1 | D42: 0 | F42: 0.05 | H42: 200 floor-nails bought to fasten the boards of the water-wall with the same 1 shilling.
A43: Cost of the mill | B43: 6 | C43: 12 | D43: 4 | F43: 6.62 | H43: Total, £6 12 shilling 4pence.
A44: Cost of the mill total | F44: 6.52 | G44: -0.1 | H44: Total
...

Sheet Stock
A1: BISHOPSSUTTON STOCK ACCOUNT
C3: added | G3: subtracted
A4: Livestock | B4: Inherited stock | C4: added | D4: strays | E4: herbage | F4: churchscot | G4: of which in default | H4: sold | I4: in murrain | J4: accounted for elsewhere | K4: End-period stock | L4: cross-check | M4: stock building | N4: raw production | O4: Unit price (£) | P4: Value of stock (£) at given value | Q4: Value of stock (£) at sales prices | R4: Sales in (£) | S4: Value of stock building (£) | T4: Value of production (£) at sales prices | U4: Details
A5: Cart-horses | B5: 0 | C5: 0 | H5: 0 | I5: 0 | K5: =B5+C5-H5-I5 -> 0 | L5: =B5+C5-H5 -> 0 | M5: =L5-B5 -> 0 | N5: =C5 -> 0 | O5: 0 | P5: =O5*K5 -> 0 | R5: 0 | S5: =O5*M5 -> 0 | T5: =O5*N5 -> 0
A6: Mares | B6: 0 | C6: 0 | H6: 0 | I6: 0 | K6: =B6+C6-H6-I6 -> 0 | L6: =B6+C6-H6 -> 0 | M6: =L6-B6 -> 0 | N6: =C6 -> 0 | O6: 0 | P6: =O6*K6 -> 0 | R6: 0 | S6: =O6*M6 -> 0 | T6: =O6*N6 -> 0
A7: Plough horses | B7: 0 | C7: 0 | H7: 0 | I7: 0 | K7: =B7+C7-H7-I7 -> 0 | L7: =B7+C7-H7 -> 0 | M7: =L7-B7 -> 0 | N7: =C7 -> 0 | O7: 0 | P7: =O7*K7 -> 0 | R7: 0 | S7: =O7*M7 -> 0 | T7: =O7*N7 -> 0
A8: Colts (unspecified years) | B8: 0 | C8: 0 | H8: 0 | I8: 0 | K8: =B8+C8-H8-I8 -> 0 | L8: =B8+C8-H8 -> 0 | M8: =L8-B8 -> 0 | N8: =C8 -> 0 | O8: 0 | P8: =O8*K8 -> 0 | R8: 0 | S8: =O8*M8 -> 0 | T8: =O8*N8 -> 0
A9: Colts (2 years) | B9: 0 | C9: 0 | H9: 0 | I9: 0 | K9: =B9+C9-H9-I9 -> 0 | L9: =B9+C9-H9 -> 0 | M9: =L9-B9 -> 0 | N9: =C9 -> 0 | O9: 0 | P9: =O9*K9 -> 0 | R9: 0 | S9: =O9*M9 -> 0 | T9: =O9*N9 -> 0
A10: Colts (1 year) | B10: 0 | C10: 0 | H10: 0 | I10: 0 | K10: =B10+C10-H10-I10 -> 0 | L10: =B10+C10-H10 -> 0 | M10: =L10-B10 -> 0 | N10: =C10 -> 0 | O10: 0 | P10: =O10*K10 -> 0 | R10: 0 | S10: =O10*M10 -> 0 | T10: =O10*N10 -> 0
A11: Foals | B11: 0 | C11: 0 | H11: 0 | I11: 0 | K11: =B11+C11-H11-I11 -> 0 | L11: =B11+C11-H11 -> 0 | M11: =L11-B11 -> 0 | N11: =C11 -> 0 | O11: 0 | P11: =O11*K11 -> 0 | R11: 0 | S11: =O11*M11 -> 0 | T11: =O11*N11 -> 0
A12: Oxen | B12: 14 | C12: 0 | H12: 0 | I12: 2 | K12: =B12+C12-H12-I12 -> 12 | L12: =B12+C12-H12 -> 14 | M12: =L12-B12 -> 0 | N12: =C12 -> 0 | O12: 0 | P12: =O12*K12 -> 0 | R12: 0 | S12: =O12*M12 -> 0 | T12: =O12*N12 -> 0
A13: Bulls | B13: 0 | C13: 0 | H13: 1 | I13: 0 | K13: =B13+C13-H13-I13 -> -1 | L13: =B13+C13-H13 -> -1 | M13: =L13-B13 -> -1 | N13: =C13 -> 0 | O13: 0 | P13: =O13*K13 -> 0 | R13: 0 | S13: =O13*M13 -> 0 | T13: =O13*N13 -> 0
A14: Cows | B14: 22 | C14: 1 | H14: 1 | I14: 2 | K14: =B14+C14-H14-I14 -> 20 | L14: =B14+C14-H14 -> 22 | M14: =L14-B14 -> 0 | N14: =C14 -> 1 | O14: =90/240 -> 0.375 | P14: =O14*K14 -> 7.5 | R14: 0 | S14: =O14*M14 -> 0 | T14: =O14*N14 -> 0.375
A15: Steers | B15: 7 | C15: 0 | H15: 0 | I15: 0 | K15: =B15+C15-H15-I15 -> 7 | L15: =B15+C15-H15 -> 7 | M15: =L15-B15 -> 0 | N15: =C15 -> 0 | O15: 0 | P15: =O15*K15 -> 0 | R15: 0 | S15: =O15*M15 -> 0 | T15: =O15*N15 -> 0
A16: Bullocks | B16: 0 | C16: 0 | H16: 0 | I16: 0 | K16: =B16+C16-H16-I16 -> 0 | L16: =B16+C16-H16 -> 0 | M16: =L16-B16 -> 0 | N16: =C16 -> 0 | O16: 0 | P16: =O16*K16 -> 0 | R16: 0 | S16: =O16*M16 -> 0 | T16: =O16*N16 -> 0
A17: Yearlings | B17: 0 | C17: 0 | H17: 0 | I17: 0 | K17: =B17+C17-H17-I17 -> 0 | L17: =B17+C17-H17 -> 0 | M17: =L17-B17 -> 0 | N17: =C17 -> 0 | O17: 0 | P17: =O17*K17 -> 0 | R17: 0 | S17: =O17*M17 -> 0 | T17: =O17*N17 -> 0
A18: Calves | B18: 8 | C18: 20 | H18: 30 | I18: 0 | K18: =B18+C18-H18-I18 -> -2 | L18: =B18+C18-H18 -> -2 | M18: =L18-B18 -> -10 | N18: =C18 -> 20 | O18: 0.027666667 | P18: =O18*K18 -> -0.055333333 | R18: 0.83 | S18: =O18*M18 -> -0.27666667 | T18: =O18*N18 -> 0.55333333
A19: Wethers | B19: 534 | C19: 0 | H19: 12 | I19: 17 | K19: =B19+C19-H19-I19 -> 505 | L19: =B19+C19-H19 -> 522 | M19: =L19-B19 -> -12 | N19: =C19 -> 0 | O19: 0.05 | P19: =O19*K19 -> 25.25 | R19: 0.6 | S19: =O19*M19 -> -0.6 | T19: =O19*N19 -> 0
A20: Rams | B20: 0 | C20: 0 | H20: 0 | I20: 0 | K20: =B20+C20-H20-I20 -> 0 | L20: =B20+C20-H20 -> 0 | M20: =L20-B20 -> 0 | N20: =C20 -> 0 | O20: 0 | P20: =O20*K20 -> 0 | R20: 0 | S20: =O20*M20 -> 0 | T20: =O20*N20 -> 0
A21: Ewes | B21: 0 | C21: 2 | H21: 2 | I21: 0 | K21: =B21+C21-H21-I21 -> 0 | L21: =B21+C21-H21 -> 0 | M21: =L21-B21 -> 0 | N21: =C21 -> 2 | O21: 0.065 | P21: =O21*K21 -> 0 | Q21: 0 | R21: 0.13 | S21: =O21*M21 -> 0 | T21: =O21*N21 -> 0.13
A22: Hoggs | B22: 0 | C22: 80 | H22: 0 | I22: 0 | K22: =B22+C22-H22-I22 -> 80 | L22: =B22+C22-H22 -> 80 | M22: =L22-B22 -> 80 | N22: =C22 -> 80 | O22: =20/240 -> 0.083333333 | P22: =O22*K22 -> 6.6666667 | R22: 0 | S22: =O22*M22 -> 6.6666667 | T22: =O22*N22 -> 6.6666667
A23: Lambs | B23: 0 | C23: 8 | H23: 4 | I23: 1 | K23: =B23+C23-H23-I23 -> 3 | L23: =B23+C23-H23 -> 4 | M23: =L23-B23 -> 4 | N23: =C23 -> 8 | O23: 0.05 | P23: =O23*K23 -> 0.15 | R23: 0.2 | S23: =O23*M23 -> 0.2 | T23: =O23*N23 -> 0.4
A24: Boars | B24: 0 | C24: 0 | H24: 1 | I24: 0 | K24: =B24+C24-H24-I24 -> -1 | L24: =B24+C24-H24 -> -1 | M24: =L24-B24 -> -1 | N24: =C24 -> 0 | O24: =60/240 -> 0.25 | P24: =O24*K24 -> -0.25 | R24: 0 | S24: =O24*M24 -> -0.25 | T24: =O24*N24 -> 0
A25: Sows | B25: 2 | C25: 0 | H25: 0 | I25: 0 | K25: =B25+C25-H25-I25 -> 2 | L25: =B25+C25-H25 -> 2 | M25: =L25-B25 -> 0 | N25: =C25 -> 0 | O25: 0 | P25: =O25*K25 -> 0 | R25: 0 | S25: =O25*M25 -> 0 | T25: =O25*N25 -> 0
A26: Pigs | B26: 20 | C26: 0 | H26: 14 | I26: 0 | K26: =B26+C26-H26-I26 -> 6 | L26: =B26+C26-H26 -> 6 | M26: =L26-B26 -> -14 | N26: =C26 -> 0 | O26: 0.069285714 | P26: =O26*K26 -> 0.41571429 | R26: 0.97 | S26: =O26*M26 -> -0.97 | T26: =O26*N26 -> 0
A27: Hoggets | B27: 25 | C27: 0 | H27: 0 | I27: 3 | K27: =B27+C27-H27-I27 -> 22 | L27: =B27+C27-H27 -> 25 | M27: =L27-B27 -> 0 | N27: =C27 -> 0 | O27: 0 | P27: =O27*K27 -> 0 | R27: 0 | S27: =O27*M27 -> 0 | T27: =O27*N27 -> 0
A28: Piglets | B28: 25 | C28: 30 | H28: 0 | I28: 0 | K28: =B28+C28-H28-I28 -> 55 | L28: =B28+C28-H28 -> 55 | M28: =L28-B28 -> 30 | N28: =C28 -> 30 | O28: =0.5/240 -> 0.0020833333 | P28: =O28*K28 -> 0.11458333 | R28: 0 | S28: =O28*M28 -> 0.0625 | T28: =O28*N28 -> 0.0625
A29: Swans | B29: 0 | C29: 0 | H29: 0 | I29: 0 | K29: =B29+C29-H29-I29 -> 0 | L29: =B29+C29-H29 -> 0 | M29: =L29-B29 -> 0 | N29: =C29 -> 0 | O29: 0 | P29: =O29*K29 -> 0 | R29: 0 | S29: =O29*M29 -> 0 | T29: =O29*N29 -> 0
A30: Peacocks | B30: 0 | C30: 0 | H30: 0 | I30: 0 | K30: =B30+C30-H30-I30 -> 0 | L30: =B30+C30-H30 -> 0 | M30: =L30-B30 -> 0 | N30: =C30 -> 0 | O30: 0 | P30: =O30*K30 -> 0 | R30: 0 | S30: =O30*M30 -> 0 | T30: =O30*N30 -> 0
A31: Total Value
A34: Wool | B34: 0 | C34: 0 | H34: 0 | I34: 0
A35: Coarse wool | B35: 0 | C35: 0 | H35: 0 | I35: 2
A36: Lamb's wool | B36: 0 | C36: 0 | H36: 0 | I36: 0
A37: Wool locks | B37: 0 | C37: 0 | H37: 0 | I37: 0
A38: Wool sold at shearing | B38: 0 | C38: 0 | H38: 0 | I38: 0
A39: Total wool | B39: 0 | C39: 0 | H39: 0 | I39: 0
B40: 0 | C40: 0 | H40: 0 | I40: 0
B41: 0 | C41: 0 | H41: 0 | I41: 0
A42: Hides | B42: 0 | C42: 0 | H42: 0 | I42: 0
A43: Ox hides | B43: 0 | C43: 0 | H43: 0 | I43: 0
...

Sheet raw data
A1: Heading | B1: Sentence | C1: Total in Pounds | D1: Pounds | E1: Shillings | F1: Pence | G1: Corn | H1: Total Quarters Except 1 | I1: Total Bushels Except 1 | J1: Total Corn Cross-Check | K1: Total Corn Manorial Account | L1: Corn Quantity Error | M1: Quarters 1 | N1: Bushels 1 | O1: Quarters 2 | P1: Bushels 2 | Q1: Quarters 3 | R1: Bushels 3 | S1: Quarters 4 | T1: Bushels 4 | U1: Quarters 5 | V1: Bushels 5 | W1: Quarters 6 | X1: Bushels 6 | Y1: Quarters 7 | Z1: Bushels 7 | AA1: shilling a quarter 1 | AB1: pence a quarter 1 | AC1: shilling a quarter 2 | AD1: pence a quarter 2 | AE1: shilling a quarter 3 | AF1: pence a quarter 3 | AG1: shilling a quarter 4 | AH1: pence a quarter 4 | AI1: shilling a bushel 1 | AJ1: pence a bushel 1 | AK1: shilling a bushel 2 | AL1: pence a bushel 2 | AM1: shilling a bushel 3 | AN1: pence a bushel 3 | AO1: shilling a bushel 4 | AP1: pence a bushel 4
A2: bishops sutton | B2: the account of laurence sourlond', reeve there, from michaelmas of the fifth year of the translation of henry beaufort', lord bishop of winchester, until michaelmas of the sixth year, and the eleventh year of the reign of king henry the fourth. | C2: 0 | D2: 0 | E2: 0 | F2: 0 | H2: 0 | I2: 0 | J2: 0 | K2: 0 | L2: 0 | M2: 0 | N2: 0
A3: arrears | B3: the same answers for £8 17 shilling 6pence of arrears from his last account of the preceding year. | C3: 8.88 | D3: 8 | E3: 17 | F3: 6 | H3: 0 | I3: 0 | J3: 0 | K3: 0 | L3: 0 | M3: 0 | N3: 0
A4: arrears | B4: total, £8 17 shilling 6pence. | C4: 8.88 | D4: 8 | E4: 17 | F4: 6 | H4: 0 | I4: 0 | J4: 0 | K4: 0 | L4: 0 | M4: 0 | N4: 0
A5: rents of assize | B5: and for £9 10 shilling 10.25pence for all rents of assize at christmas. | C5: 9.54 | D5: 9 | E5: 10 | F5: 10.25 | H5: 0 | I5: 0 | J5: 0 | K5: 0 | L5: 0 | M5: 0 | N5: 0
A6: rents of assize | B6: £9 10 shilling 11pence at easter (23 march). | C6: 9.55 | D6: 9 | E6: 10 | F6: 11 | H6: 0 | I6: 0 | J6: 0 | K6: 0 | L6: 0 | M6: 0 | N6: 0
A7: rents of assize | B7: £9 10 shilling 10.25pence at the nativity of st john the baptist (24 june). | C7: 9.54 | D7: 9 | E7: 10 | F7: 10.25 | H7: 0 | I7: 0 | J7: 0 | K7: 0 | L7: 0 | M7: 0 | N7: 0
A8: rents of assize | B8: £23 7 shilling 7pence at michaelmas (29 september). | C8: 23.38 | D8: 23 | E8: 7 | F8: 7 | H8: 0 | I8: 0 | J8: 0 | K8: 0 | L8: 0 | M8: 0 | N8: 0
A9: rents of assize | B9: total, £52 2.5pence. | C9: 52.01 | D9: 52 | E9: 0 | F9: 2.5 | H9: 0 | I9: 0 | J9: 0 | K9: 0 | L9: 0 | M9: 0 | N9: 0
A10: quittances | B10: in quittance of rent of 1 reeve for the year 5 shilling. | C10: 0.25 | D10: 0 | E10: 5 | F10: 0 | H10: 0 | I10: 0 | J10: 0 | K10: 0 | L10: 0 | M10: 0 | N10: 0
A11: quittances | B11: 1 smith for the year 2 shilling. | C11: 0.1 | D11: 0 | E11: 2 | F11: 0 | H11: 0 | I11: 0 | J11: 0 | K11: 0 | L11: 0 | M11: 0 | N11: 0
A12: quittances | B12: 1 cowherd for the year, nothing, because there is none there from the customary tenants but he has the lord's livery as made clear elsewhere. | C12: 0 | D12: 0 | E12: 0 | F12: 0 | H12: 0 | I12: 0 | J12: 0 | K12: 0 | L12: 0 | M12: 0 | N12: 0
A13: quittances | B13: 1 ploughman for the year 3 shilling. | C13: 0.15 | D13: 0 | E13: 3 | F13: 0 | H13: 0 | I13: 0 | J13: 0 | K13: 0 | L13: 0 | M13: 0 | N13: 0
... A102: issues of the manor | B102: nothing from apples in the garden this year because there was no fruit. | C102: 0 | D102: 0 | E102: 0 | F102: 0 | H102: 0 | I102: 0 | J102: 0 | K102: 0 | L102: 0 | M102: 0 | N102: 0
A103: issues of the manor | B103: £1 from 15 quarters of limestone sold, at 1 shilling 4pence a quarters. | C103: 1 | D103: 1 | E103: 0 | F103: 0 | H103: 15 | I103: 0 | J103: 15 | K103: 15 | L103: 0 | M103: 15 | N103: 0 | AA103: 1 | AB103: 4
A104: issues of the manor | B104: total, £31 9pence. | C104: 31.04 | D104: 31 | E104: 0 | F104: 9 | H104: 0 | I104: 0 | J104: 0 | K104: 0 | L104: 0 | M104: 0 | N104: 0
A105: issues of the warren | B105: and for 8 shilling 4pence from 52 rabbits sold to the lord's household, at 4pence a pair. | C105: 0.42 | D105: 0 | E105: 8 | F105: 4 | H105: 0 | I105: 0 | J105: 0 | K105: 0 | L105: 0 | M105: 0 | N105: 0
A106: issues of the warren | B106: £3 1 shilling 9pence from 494 young rabbits sold to the lord's household, at 3pence a pair. | C106: 3.09 | D106: 3 | E106: 1 | F106: 9 | H106: 0 | I106: 0 | J106: 0 | K106: 0 | L106: 0 | M106: 0 | N106: 0
A107: issues of the warren | B107: total, £3 10 shilling 1pence. | C107: 3.5 | D107: 3 | E107: 10 | F107: 1 | H107: 0 | I107: 0 | J107: 0 | K107: 0 | L107: 0 | M107: 0 | N107: 0
A108: issues of the lands and tenements in the lord's hands which were recovered from william overtone | B108: nothing of the 10 shilling for the herbage of the meadow called vertdelay because of the lord's cattle. | C108: 0.5 | D108: 0 | E108: 10 | F108: 0 | H108: 0 | I108: 0 | J108: 0 | K108: 0 | L108: 0 | M108: 0 | N108: 0
A109: issues of the lands and tenements in the lord's hands which were recovered from william overtone | B109: nothing of the 4 shilling for the summer pasturage of 1 croft beside the south side of the said meadow because of the lord's cattle. | C109: 0.2 | D109: 0 | E109: 4 | F109: 0 | H109: 0 | I109: 0 | J109: 0 | K109: 0 | L109: 0 | M109: 0 | N109: 0
A110: issues of the lands and tenements in the lord's hands which were recovered from william overtone | B110: 16 shilling 6pence from william overton' for 1 toft with a curtilage and 1 croft containing 1 acre by estimation, 1 meadow formerly of john atte fysshewer', 1 croft containing 2 acres by estimation which lies on the west side of the tenement of the aforesaid william, 1 garden with a pond, 1 vennel called wranglane which lies on the east side of the tenement of the same william, and 2 acres called wodeacres which lie on the west side of 1 croft of the aforesaid william called swetele, demised to the aforesaid william by fine made with the lord therefor. | C110: 0.83 | D110: 0 | E110: 16 | F110: 6 | H110: 0 | I110: 0 | J110: 0 | K110: 0 | L110: 0 | M110: 0 | N110: 0
A111: issues of the lands and tenements in the lord's hands which were recovered from william overtone | B111: 1 shilling 6pence from 1 small garden beside the garden of la fysshewer', let to richard sourlond' this year. | C111: 0.08 | D111: 0 | E111: 1 | F111: 6 | H111: 0 | I111: 0 | J111: 0 | K111: 0 | L111: 0 | M111: 0 | N111: 0
A112: issues of the lands and tenements in the lord's hands which were recovered from william overtone | B112: nothing from the sale of beech saplings in la inhome this year. | C112: 0 | D112: 0 | E112: 0 | F112: 0 | H112: 0 | I112: 0 | J112: 0 | K112: 0 | L112: 0 | M112: 0 | N112: 0
A113: issues of the lands and tenements in the lord's hands which were recovered from william overtone | B113: 8 shilling from the issue of 6 acres of land which formerly belonged to thomas smyth' and 1 small wooded grove with 2 crofts at le3 brokes which belonged to john de godisfeld', let to roger maffey for the term of his life. | C113: 0.4 | D113: 0 | E113: 8 | F113: 0 | H113: 0 | I113: 0 | J113: 0 | K113: 0 | L113: 0 | M113: 0 | N113: 0
A114: issues of the lands and tenements in the lord's hands which were recovered from william overtone | B114: 5 shilling from the issue of 1 cottage which formerly belonged to john, son of john godisfeld', and before to reginald cornow and which was taken from william de overton' into the lord's hands and for which john schalden' fined, for this the twenty-fifth year. | C114: 0.25 | D114: 0 | E114: 5 | F114: 0 | H114: 0 | I114: 0 | J114: 0 | K114: 0 | L114: 0 | M114: 0 | N114: 0
A115: issues of the lands and tenements in the lord's hands which were recovered from william overtone | B115: nothing from apples in the garden beside the garden of william de overton' because william overton' fined for the same. | C115: 0 | D115: 0 | E115: 0 | F115: 0 | H115: 0 | I115: 0 | J115: 0 | K115: 0 | L115: 0 | M115: 0 | N115: 0
... A150: release of labour services | B150: total, £1 2 shilling 10pence. | C150: 1.14 | D150: 1 | E150: 2 | F150: 10 | H150: 0 | I150: 0 | J150: 0 | K150: 0 | L150: 0 | M150: 0 | N150: 0
A151: sale of corn and malt | B151: and for £14 7 shilling 11.75pence1 from 30 quarters of wheat sold, of which 7 quarters 4 bushels sold to the lord's household for £3 10 shilling, at 9 shilling 4pence a quarters, 1 quarters 1 bushels to the guardians of john coupere until he should come of age for 3 shilling 9pence, and 21 quarters 3 bushels per mutuum for £10 13 shilling 9pence, at 10 shilling a quarters. | C151: 14.4 | D151: 14 | E151: 7 | F151: 11.75 | G151: wheat | H151: 29 | I151: 8 | J151: 30 | K151: 30 | L151: 0 | M151: 30 | N151: 0 | O151: 7 | P151: 4 | Q151: 1 | R151: 1 | S151: 21 | T151: 3 | AA151: 9 | AB151: 4 | AC151: 10 | AD151: 0
A152: sale of corn and malt | B152: £50 14 shilling from 174 quarters of malt sold to the lord's household, at 6 shilling a quarters for 144 quarters, or £43 4 shilling, and 5 shilling a quarters for 30 quarters, or £7 10 shilling. | C152: 50.7 | D152: 50 | E152: 14 | F152: 0 | G152: malt | H152: 174 | I152: 0 | J152: 174 | K152: 174 | L152: 0 | M152: 174 | N152: 0 | O152: 144 | P152: 0 | Q152: 30 | R152: 0 | AA152: 6 | AB152: 0 | AC152: 5 | AD152: 0
A153: sale of corn and malt | B153: total, £65 1 shilling 11.75pence. | C153: 65.1 | D153: 65 | E153: 1 | F153: 11.75 | H153: 0 | I153: 0 | J153: 0 | K153: 0 | L153: 0 | M153: 0 | N153: 0
A154: sale of stock | B154: and for 7 shilling 10pence from 1 bull sold. | C154: 0.39 | D154: 0 | E154: 7 | F154: 10 | H154: 0 | I154: 0 | J154: 0 | K154: 0 | L154: 0 | M154: 0 | N154: 0
A155: sale of stock | B155: 7 shilling 6pence from 1 cow useless for the stock sold. | C155: 0.38 | D155: 0 | E155: 7 | F155: 6 | H155: 0 | I155: 0 | J155: 0 | K155: 0 | L155: 0 | M155: 0 | N155: 0
A156: sale of stock | B156: 16 shilling 8pence from 10 calves sold, at 1 shilling 8pence each. | C156: 0.83 | D156: 0 | E156: 16 | F156: 8 | H156: 0 | I156: 0 | J156: 0 | K156: 0 | L156: 0 | M156: 0 | N156: 0
A157: sale of stock | B157: 12 shilling from 12 of the worse kebb wethers sold in the market after shearing, at 1 shilling each. | C157: 0.6 | D157: 0 | E157: 12 | F157: 0 | H157: 0 | I157: 0 | J157: 0 | K157: 0 | L157: 0 | M157: 0 | N157: 0
A158: sale of stock | B158: 2 shilling 8pence from 2 kebb ewes from a heriot sold. | C158: 0.13 | D158: 0 | E158: 2 | F158: 8 | H158: 0 | I158: 0 | J158: 0 | K158: 0 | L158: 0 | M158: 0 | N158: 0
A159: sale of stock | B159: 4 shilling from 4 lambs sold. | C159: 0.2 | D159: 0 | E159: 4 | F159: 0 | H159: 0 | I159: 0 | J159: 0 | K159: 0 | L159: 0 | M159: 0 | N159: 0
A160: sale of stock | B160: 5 shilling from 1 boar sold to the lord's household. | C160: 0.25 | D160: 0 | E160: 5 | F160: 0 | H160: 0 | I160: 0 | J160: 0 | K160: 0 | L160: 0 | M160: 0 | N160: 0
A161: sale of stock | B161: 19 shilling from 14 pigs sold to the lord's household, at 2 shilling 6pence each for 2, and 1 shilling 2pence each for 12.. | C161: 0.97 | D161: 0 | E161: 19 | F161: 6 | H161: 0 | I161: 0 | J161: 0 | K161: 0 | L161: 0 | M161: 0 | N161: 0
A162: sale of stock | B162: total, £3 14 shilling 8pence. | C162: 3.73 | D162: 3 | E162: 14 | F162: 8 | H162: 0 | I162: 0 | J162: 0 | K162: 0 | L162: 0 | M162: 0 | N162: 0
...

Sheet Stock_raw
A1: Heading | B1: Sentence | C1: Quarters 1 | D1: Bushels 1 | E1: stock | F1: inherited stock | G1: added | H1: murrain | I1: sold
A2: Oats | B2: Total | C2: 0 | D2: 0
A3: Stock | B3: Horses: 6 remain. | C3: 0 | D3: 0 | F3: 6
A4: Stock | B4: Oxen: 14 remain. | C4: 0 | D4: 0 | E4: Oxen | F4: 14
A5: Stock | B5: 1 from the heriot of John Reedere. | C5: 0 | D5: 0 | E5: Oxen
A6: Stock | B6: 1 from the heriot of Walter Gylberd'. | C6: 0 | D6: 0 | E6: Oxen
A7: Stock | B7: 3 added from steers below. | C7: 0 | D7: 0 | E7: Oxen
A8: Stock | B8: Total, 19. 2 in murrain. | C8: 0 | D8: 0 | E8: Oxen | H8: 2
A9: Stock | B9: Total, 2. 17 remain. | C9: 0 | D9: 0 | E9: Oxen
A10: Stock | B10: Bulls: 1 remains. | C10: 0 | D10: 0 | E10: Bulls
A11: Stock | B11: 1 added from steers below. | C11: 0 | D11: 0 | E11: Bulls
A12: Stock | B12: Total, 2. 1 sold. | C12: 0 | D12: 0 | E12: Bulls | I12: 1
A13: Stock | B13: 1 remains. | C13: 0 | D13: 0 | E13: Bulls
A14: Stock | B14: Cows: 22 remain, 1 bought. | C14: 0 | D14: 0 | E14: Cows | F14: 22 | G14: 1
A15: Stock | B15: 3 added from steers below. | C15: 0 | D15: 0 | E15: Cows
A16: Stock | B16: Total, 26. 2 in murrain, 1 sold because useless for the stock. | C16: 0 | D16: 0 | E16: Cows | H16: 2 | I16: 1
A17: Stock | B17: Total, 3. 23 remain, 1 of them a kebb. | C17: 0 | D17: 0 | E17: Cows
A18: Stock | B18: Steers: 7 use remain from the bullocks. | C18: 0 | D18: 0 | E18: Steers | F18: 7
A19: Stock | B19: Total, 7. 3 added above to oxen, 1 to bulls and 3. | C19: 0 | D19: 0 | E19: Steers
A20: Stock | B20: to cows. | C20: 0 | D20: 0 | E20: Steers
A21: Stock | B21: none remain. | C21: 0 | D21: 0 | E21: Steers
A22: Stock | B22: Calves: 20 offspring and not more because 1 cow died before calving and 1 was sold before calving. | C22: 0 | D22: 0 | E22: Calves | G22: 20 | I22: 20
A23: Stock | B23: Total, 20. 2 in tithe. | C23: 0 | D23: 0 | E23: Calves
A24: Stock | B24: 10 sold within. | C24: 0 | D24: 0 | E24: Calves | I24: 10
A25: Stock | B25: 8 remain. | C25: 0 | D25: 0 | E25: Calves | F25: 8
A26: Stock | B26: Wethers: 534 remain. | C26: 0 | D26: 0 | E26: Wethers | F26: 534
A27: Stock | B27: 80 added from hoggs below. | C27: 0 | D27: 0 | E27: Wethers
A28: Stock | B28: 1 from strays before shearing. | C28: 0 | D28: 0 | E28: Wethers
A29: Stock | B29: Total, 615. 17 in murrain before shearing and 12 after shearing. | C29: 0 | D29: 0 | E29: Wethers | H29: 17
A30: Stock | B30: 12 of the worse kebbs sold in the market after shearing. | C30: 0 | D30: 0 | E30: Wethers | I30: 12
A31: Stock | B31: Total, 79.1 574 remain, of which 38 delivered to the lord's household. | C31: 0 | D31: 0 | E31: Wethers
A32: Stock | B32: Ewes: 2 from the heriot of John Spede. | C32: 0 | D32: 0 | E32: Ewes
A33: Stock | B33: 2 bought. | C33: 0 | D33: 0 | E33: Ewes | G33: 2
A34: Stock | B34: Total, 4. 2 in liveries of the shepherd and smith according to custom at Martinmas. | C34: 0 | D34: 0 | E34: Ewes
A35: Stock | B35: 2 sold within. | C35: 0 | D35: 0 | E35: Ewes | I35: 2
A36: Stock | B36: none remain. | C36: 0 | D36: 0 | E36: Ewes
A37: Stock | B37: Hoggs: 80 bought before shearing from the reeve of Alresford. | C37: 0 | D37: 0 | E37: Hoggs | G37: 80
A38: Stock | B38: Total, 80. All added above to wethers. | C38: 0 | D38: 0 | E38: Hoggs
A39: Stock | B39: none remain. | C39: 0 | D39: 0 | E39: Hoggs
A40: Stock | B40: Lambs: 8 from the offspring of as many ewes going to mate (in mulo) with the wethers. | C40: 0 | D40: 0 | E40: Lambs | G40: 8
...

Sheet Issues of the Mills

Sheet Prices

Sheet Labour Rents

Sheet not needed

Sheet Issues of the Grange raw
A1: Heading | B1: Sentence | C1: Quarters 1_x | D1: Bushels 1_x | E1: Sown Quarters | F1: Sown Bushels | G1: Sown Total Quarters | H1: Bought in Quarters | I1: Bought in Bushels | J1: Bought in Total Quarters | K1: Tithe Quarters | L1: Tithe Bushels | M1: Tithe Total Quarters | N1: Manorial servants & livestock Quarters | O1: Manorial servants & livestock Bushels | P1: Manorial servants & livestock Total Quarters | Q1: Sold Quarters | R1: Sold Bushels | S1: Sold Total Quarters | T1: Account Quarters | U1: Account Bushels | V1: Account Total Quarters | W1: bought only | X1: Total Quarters Except 1 | Y1: Total Bushels Except 1 | Z1: Total Corn Cross-Check | AA1: Total Corn Manorial Account | AB1: Corn Quantity Error | AC1: Quarters 1_y | AD1: Bushels 1_y | AE1: Quarters 2 | AF1: Bushels 2 | AG1: Quarters 3 | AH1: Bushels 3 | AI1: Quarters 4 | AJ1: Bushels 4 | AK1: Quarters 5 | AL1: Bushels 5 | AM1: Quarters 6 | AN1: Bushels 6 | AO1: Quarters 7 | AP1: Bushels 7 | AQ1: Total Bought Quarters
A2: and he owes | B2: total | C2: 0 | D2: 0 | E2: 0 | F2: 0 | G2: 0 | H2: 0 | I2: 0 | J2: 0 | K2: 0 | L2: 0 | M2: 0 | N2: 0 | O2: 0 | P2: 0 | Q2: 0 | R2: 0 | S2: 0 | T2: 0 | U2: 0 | V2: 0 | W2: 0 | AQ2: 0
A3: wheat | B3: laurence sourlond', reeve there, answers for 30 quarters 4 bushels from the whole issue, threshed by piece-work. | C3: 0 | D3: 0 | E3: 0 | F3: 0 | G3: 0 | H3: 0 | I3: 0 | J3: 0 | K3: 0 | L3: 0 | M3: 0 | N3: 0 | O3: 0 | P3: 0 | Q3: 0 | R3: 0 | S3: 0 | T3: 30 | U3: 4 | V3: 30.5 | W3: 0 | X3: 30 | Y3: 4 | Z3: 30.5 | AA3: 30.5 | AB3: 0 | AC3: 30 | AD3: 4 | AQ3: 0
A4: wheat | B4: 6 bushels from the same issue by estimation in sheaves. | C4: 0 | D4: 0 | E4: 0 | F4: 0 | G4: 0 | H4: 0 | I4: 0 | J4: 0 | K4: 0 | L4: 0 | M4: 0 | N4: 0 | O4: 0 | P4: 0 | Q4: 0 | R4: 0 | S4: 0 | T4: 0 | U4: 0 | V4: 0 | W4: 0 | X4: 0 | Y4: 6 | Z4: 0.75 | AA4: 0.75 | AB4: 0 | AC4: 0 | AD4: 6 | AQ4: 0
A5: wheat | B5: 22 quarters 4 bushels from the churchscot of the customary tenants at martinmas. | C5: 0 | D5: 0 | E5: 0 | F5: 0 | G5: 0 | H5: 0 | I5: 0 | J5: 0 | K5: 0 | L5: 0 | M5: 0 | N5: 0 | O5: 0 | P5: 0 | Q5: 0 | R5: 0 | S5: 0 | T5: 0 | U5: 0 | V5: 0 | W5: 0 | X5: 22 | Y5: 4 | Z5: 22.5 | AA5: 22.5 | AB5: 0 | AC5: 22 | AD5: 4 | AQ5: 0
A6: wheat | B6: 9 quarters 2 bushels surcharged so that he answers for a 3.5-fold yield. | C6: 0 | D6: 0 | E6: 0 | F6: 0 | G6: 0 | H6: 0 | I6: 0 | J6: 0 | K6: 0 | L6: 0 | M6: 0 | N6: 0 | O6: 0 | P6: 0 | Q6: 0 | R6: 0 | S6: 0 | T6: 0 | U6: 0 | V6: 0 | W6: 0 | X6: 9 | Y6: 2 | Z6: 9.25 | AA6: 9.25 | AB6: 0 | AC6: 9 | AD6: 2 | AQ6: 0
A7: wheat | B7: total, 63 quarters. | C7: 0 | D7: 0 | E7: 0 | F7: 0 | G7: 0 | H7: 0 | I7: 0 | J7: 0 | K7: 0 | L7: 0 | M7: 0 | N7: 0 | O7: 0 | P7: 0 | Q7: 0 | R7: 0 | S7: 0 | T7: 0 | U7: 0 | V7: 0 | W7: 0 | X7: 63 | Y7: 0 | Z7: 63 | AA7: 63 | AB7: 0 | AC7: 63 | AD7: 0 | AQ7: 0
A8: wheat | B8: sown over 54 acres of land by the perch in la reede, reghele and dellond', 13 quarters 4 bushels. | C8: 0 | D8: 0 | E8: 13 | F8: 4 | G8: 13.5 | H8: 0 | I8: 0 | J8: 0 | K8: 0 | L8: 0 | M8: 0 | N8: 0 | O8: 0 | P8: 0 | Q8: 0 | R8: 0 | S8: 0 | T8: 0 | U8: 0 | V8: 0 | W8: 0 | X8: 13 | Y8: 4 | Z8: 13.5 | AA8: 13.5 | AB8: 0 | AC8: 13 | AD8: 4 | AQ8: 0
A9: wheat | B9: that is, 2 bushels an acre. | C9: 0 | D9: 0 | E9: 0 | F9: 0 | G9: 0 | H9: 0 | I9: 0 | J9: 0 | K9: 0 | L9: 0 | M9: 0 | N9: 0 | O9: 0 | P9: 0 | Q9: 0 | R9: 0 | S9: 0 | T9: 0 | U9: 0 | V9: 0 | W9: 0 | X9: 0 | Y9: 2 | Z9: 0.25 | AA9: 0.25 | AB9: 0 | AC9: 0 | AD9: 2 | AQ9: 0
A10: wheat | B10: bread baked for the provision of richard wyot, steward, holding the tourns of martinmas and hockday, 4 bushels by bill. | C10: 0 | D10: 0 | E10: 0 | F10: 0 | G10: 0 | H10: 0 | I10: 0 | J10: 0 | K10: 0 | L10: 0 | M10: 0 | N10: 0 | O10: 0 | P10: 0 | Q10: 0 | R10: 0 | S10: 0 | T10: 0 | U10: 0 | V10: 0 | W10: 0 | X10: 0 | Y10: 4 | Z10: 0.5 | AA10: 0.5 | AB10: 0 | AC10: 0 | AD10: 4 | AQ10: 0
A11: wheat | B11: quittance of 3 half-virgates of land, of lucy cartere, john schephurde and thomas mauncell', which william wykeham, recently lord bishop of winchester, let at farm by his charter and the confirmation of the chapter to the warden and scholars of the blessed mary and their successors, just as is fully made clear within under the heading of issues through the pestilence, 3 quarters 3 bushels, of which each was accustomed to pay 1 qr 1 bushels for the year. | C11: 0 | D11: 0 | E11: 0 | F11: 0 | G11: 0 | H11: 0 | I11: 0 | J11: 0 | K11: 0 | L11: 0 | M11: 0 | N11: 0 | O11: 0 | P11: 0 | Q11: 0 | R11: 0 | S11: 0 | T11: 0 | U11: 0 | V11: 0 | W11: 0 | AQ11: 0
A12: wheat | B12: default of the churchscot of the land of alice clerk', formerly of john atte mere, now in the lord's hands through the death of the same in the first pestilence, 1 qr 1 bushels. | C12: 0 | D12: 0 | E12: 0 | F12: 0 | G12: 0 | H12: 0 | I12: 0 | J12: 0 | K12: 0 | L12: 0 | M12: 0 | N12: 0 | O12: 0 | P12: 0 | Q12: 0 | R12: 0 | S12: 0 | T12: 0 | U12: 0 | V12: 0 | W12: 0 | AQ12: 0
A13: wheat | B13: default of 4 half-virgates of land, of roger albard', john atte puynde, william hockele and john hockele, in the lord's hands because the said roger, john, william and john surrendered the said lands into the lord's hands and refused to hold them any longer, 4 quarters. | C13: 0 | D13: 0 | E13: 0 | F13: 0 | G13: 0 | H13: 0 | I13: 0 | J13: 0 | K13: 0 | L13: 0 | M13: 0 | N13: 0 | O13: 0 | P13: 0 | Q13: 0 | R13: 0 | S13: 0 | T13: 0 | U13: 0 | V13: 0 | W13: 0 | X13: 4 | Y13: 0 | Z13: 4 | AA13: 4 | AB13: 0 | AC13: 4 | AD13: 0 | AQ13: 0
A14: wheat | B14: liveries of the reeve and smith according to custom in 2 acres as they he, 6 bushels. | C14: 0 | D14: 0 | E14: 0 | F14: 0 | G14: 0 | H14: 0 | I14: 0 | J14: 0 | K14: 0 | L14: 0 | M14: 0 | N14: 0 | O14: 0 | P14: 0 | Q14: 0 | R14: 0 | S14: 0 | T14: 0 | U14: 0 | V14: 0 | W14: 0 | X14: 0 | Y14: 6 | Z14: 0.75 | AA14: 0.75 | AB14: 0 | AC14: 0 | AD14: 6 | AQ14: 0
A15: wheat | B15: sold within, 30 quarters, of which 7 quarters 4 bushels sold to the lord's household.. | C15: 0 | D15: 0 | E15: 0 | F15: 0 | G15: 0 | H15: 0 | I15: 0 | J15: 0 | K15: 0 | L15: 0 | M15: 0 | N15: 0 | O15: 0 | P15: 0 | Q15: 37 | R15: 4 | S15: 37.5 | T15: 0 | U15: 0 | V15: 0 | W15: 0 | X15: 7 | Y15: 4 | Z15: 7.5 | AA15: 30 | AB15: -22.5 | AC15: 30 | AD15: 0 | AE15: 7 | AF15: 4 | AQ15: 0
A16: wheat | B16: sold at the audit, 9 quarters 2 bushels for £3 14 shilling. | C16: 0 | D16: 0 | E16: 0 | F16: 0 | G16: 0 | H16: 0 | I16: 0 | J16: 0 | K16: 0 | L16: 0 | M16: 0 | N16: 0 | O16: 0 | P16: 0 | Q16: 9 | R16: 2 | S16: 9.25 | T16: 0 | U16: 0 | V16: 0 | W16: 0 | X16: 9 | Y16: 2 | Z16: 9.25 | AA16: 9.25 | AB16: 0 | AC16: 9 | AD16: 2 | AQ16: 0
A17: wheat | B17: total as before. | C17: 0 | D17: 0 | E17: 0 | F17: 0 | G17: 0 | H17: 0 | I17: 0 | J17: 0 | K17: 0 | L17: 0 | M17: 0 | N17: 0 | O17: 0 | P17: 0 | Q17: 0 | R17: 0 | S17: 0 | T17: 0 | U17: 0 | V17: 0 | W17: 0 | X17: 0 | Y17: 0 | Z17: 0 | AA17: 0 | AB17: 0 | AC17: 0 | AD17: 0 | AQ17: 0
A18: wheat | B18: it balances. | C18: 0 | D18: 0 | E18: 0 | F18: 0 | G18: 0 | H18: 0 | I18: 0 | J18: 0 | K18: 0 | L18: 0 | M18: 0 | N18: 0 | O18: 0 | P18: 0 | Q18: 0 | R18: 0 | S18: 0 | T18: 0 | U18: 0 | V18: 0 | W18: 0 | X18: 0 | Y18: 0 | Z18: 0 | AA18: 0 | AB18: 0 | AC18: 0 | AD18: 0 | AQ18: 0
A19: wheat | B19: total | C19: 0 | D19: 0 | E19: 0 | F19: 0 | G19: 0 | H19: 0 | I19: 0 | J19: 0 | K19: 0 | L19: 0 | M19: 0 | N19: 0 | O19: 0 | P19: 0 | Q19: 0 | R19: 0 | S19: 0 | T19: 0 | U19: 0 | V19: 0 | W19: 0 | AQ19: 0
A20: curall | B20: and for 1 qr 4 bushels of curall from the issue of the said wheat, threshed by piece-work. | C20: 0 | D20: 0 | E20: 0 | F20: 0 | G20: 0 | H20: 0 | I20: 0 | J20: 0 | K20: 0 | L20: 0 | M20: 0 | N20: 0 | O20: 0 | P20: 0 | Q20: 0 | R20: 0 | S20: 0 | T20: 0 | U20: 0 | V20: 0 | W20: 0 | AQ20: 0
A21: curall | B21: liveries of the manorial servants. | C21: 0 | D21: 0 | E21: 0 | F21: 0 | G21: 0 | H21: 0 | I21: 0 | J21: 0 | K21: 0 | L21: 0 | M21: 0 | N21: 0 | O21: 0 | P21: 0 | Q21: 0 | R21: 0 | S21: 0 | T21: 0 | U21: 0 | V21: 0 | W21: 0 | X21: 0 | Y21: 0 | Z21: 0 | AA21: 0 | AB21: 0 | AC21: 0 | AD21: 0 | AQ21: 0
A22: curall | B22: none remains. | C22: 0 | D22: 0 | E22: 0 | F22: 0 | G22: 0 | H22: 0 | I22: 0 | J22: 0 | K22: 0 | L22: 0 | M22: 0 | N22: 0 | O22: 0 | P22: 0 | Q22: 0 | R22: 0 | S22: 0 | T22: 0 | U22: 0 | V22: 0 | W22: 0 | X22: 0 | Y22: 0 | Z22: 0 | AA22: 0 | AB22: 0 | AC22: 0 | AD22: 0 | AQ22: 0
A23: curall | B23: total | C23: 0 | D23: 0 | E23: 0 | F23: 0 | G23: 0 | H23: 0 | I23: 0 | J23: 0 | K23: 0 | L23: 0 | M23: 0 | N23: 0 | O23: 0 | P23: 0 | Q23: 0 | R23: 0 | S23: 0 | T23: 0 | U23: 0 | V23: 0 | W23: 0 | AQ23: 0
A24: barley | B24: and for 53 quarters 4 bushels from the whole issue, threshed by piece-work. | C24: 0 | D24: 0 | E24: 0 | F24: 0 | G24: 0 | H24: 0 | I24: 0 | J24: 0 | K24: 0 | L24: 0 | M24: 0 | N24: 0 | O24: 0 | P24: 0 | Q24: 0 | R24: 0 | S24: 0 | T24: 53 | U24: 4 | V24: 53.5 | W24: 0 | X24: 53 | Y24: 4 | Z24: 53.5 | AA24: 53.5 | AB24: 0 | AC24: 53 | AD24: 4 | AQ24: 0
A25: barley | B25: 167 quarters 2.5 bushels bought, of which 115 quarters 3 bushels bought from the reeve of hambledon, 6 quarters 6 bushels from the reeve of north waltham, 12 quarters from the reeve of alresford, 12 quarters from the reeve of cheriton, 10 quarters from the reeve of overton, and 11 quarters 1.5 bushels in the market. | C25: 0 | D25: 0 | E25: 0 | F25: 0 | G25: 0 | H25: 333 | I25: 13 | J25: 334.62 | K25: 0 | L25: 0 | M25: 0 | N25: 0 | O25: 0 | P25: 0 | Q25: 0 | R25: 0 | S25: 0 | T25: 0 | U25: 0 | V25: 0 | W25: 0 | X25: 166 | Y25: 10.5 | Z25: 167.31 | AA25: 167.31 | AB25: 0 | AC25: 167 | AD25: 2.5 | AE25: 115 | AF25: 3 | AG25: 6 | AH25: 6 | AI25: 12 | AJ25: 0 | AK25: 12 | AL25: 0 | AM25: 10 | AN25: 0 | AO25: 11 | AP25: 1.5 | AQ25: 0
A26: barley | B26: 8 quarters 5 bushels surcharged so that he answers for a 3.5-fold yield. | C26: 0 | D26: 0 | E26: 0 | F26: 0 | G26: 0 | H26: 0 | I26: 0 | J26: 0 | K26: 0 | L26: 0 | M26: 0 | N26: 0 | O26: 0 | P26: 0 | Q26: 0 | R26: 0 | S26: 0 | T26: 0 | U26: 0 | V26: 0 | W26: 0 | X26: 8 | Y26: 5 | Z26: 8.62 | AA26: 8.62 | AB26: 0 | AC26: 8 | AD26: 5 | AQ26: 0
A27: barley | B27: total, 229 quarters 3.5 bushels sown over 36.5 acres below la northhull' and la bertones and swetecombe, 18 quarters 2 bushels. | C27: 0 | D27: 0 | E27: 247 | F27: 5.5 | G27: 247.69 | H27: 0 | I27: 0 | J27: 0 | K27: 0 | L27: 0 | M27: 0 | N27: 0 | O27: 0 | P27: 0 | Q27: 0 | R27: 0 | S27: 0 | T27: 0 | U27: 0 | V27: 0 | W27: 0 | X27: 18 | Y27: 2 | Z27: 18.25 | AA27: 229.44 | AB27: -211.19 | AC27: 229 | AD27: 3.5 | AE27: 18 | AF27: 2 | AQ27: 0
A28: barley | B28: that is, 4 bushels an acre. | C28: 0 | D28: 0 | E28: 0 | F28: 0 | G28: 0 | H28: 0 | I28: 0 | J28: 0 | K28: 0 | L28: 0 | M28: 0 | N28: 0 | O28: 0 | P28: 0 | Q28: 0 | R28: 0 | S28: 0 | T28: 0 | U28: 0 | V28: 0 | W28: 0 | X28: 0 | Y28: 4 | Z28: 0.5 | AA28: 0.5 | AB28: 0 | AC28: 0 | AD28: 4 | AQ28: 0
A29: barley | B29: liveries of the manorial servants below, 28 quarters 3.5 bushels. | C29: 0 | D29: 0 | E29: 0 | F29: 0 | G29: 0 | H29: 0 | I29: 0 | J29: 0 | K29: 0 | L29: 0 | M29: 0 | N29: 0 | O29: 0 | P29: 0 | Q29: 0 | R29: 0 | S29: 0 | T29: 0 | U29: 0 | V29: 0 | W29: 0 | X29: 28 | Y29: 3.5 | Z29: 28.44 | AA29: 28.44 | AB29: 0 | AC29: 28 | AD29: 3.5 | AQ29: 0
A30: barley | B30: malting below, 174 quarters 1 bushels. | C30: 0 | D30: 0 | E30: 0 | F30: 0 | G30: 0 | H30: 0 | I30: 0 | J30: 0 | K30: 0 | L30: 0 | M30: 0 | N30: 0 | O30: 0 | P30: 0 | Q30: 0 | R30: 0 | S30: 0 | T30: 0 | U30: 0 | V30: 0 | W30: 0 | X30: 174 | Y30: 1 | Z30: 174.12 | AA30: 174.12 | AB30: 0 | AC30: 174 | AD30: 1 | AQ30: 0
A31: barley | B31: sold at the audit, 8 quarters 5 bushels for £2 13 shilling. | C31: 0 | D31: 0 | E31: 0 | F31: 0 | G31: 0 | H31: 0 | I31: 0 | J31: 0 | K31: 0 | L31: 0 | M31: 0 | N31: 0 | O31: 0 | P31: 0 | Q31: 8 | R31: 5 | S31: 8.62 | T31: 0 | U31: 0 | V31: 0 | W31: 0 | X31: 8 | Y31: 5 | Z31: 8.62 | AA31: 8.62 | AB31: 0 | AC31: 8 | AD31: 5 | AQ31: 0
A32: barley | B32: total as before. | C32: 0 | D32: 0 | E32: 0 | F32: 0 | G32: 0 | H32: 0 | I32: 0 | J32: 0 | K32: 0 | L32: 0 | M32: 0 | N32: 0 | O32: 0 | P32: 0 | Q32: 0 | R32: 0 | S32: 0 | T32: 0 | U32: 0 | V32: 0 | W32: 0 | X32: 0 | Y32: 0 | Z32: 0 | AA32: 0 | AB32: 0 | AC32: 0 | AD32: 0 | AQ32: 0
A33: barley | B33: it balances. | C33: 0 | D33: 0 | E33: 0 | F33: 0 | G33: 0 | H33: 0 | I33: 0 | J33: 0 | K33: 0 | L33: 0 | M33: 0 | N33: 0 | O33: 0 | P33: 0 | Q33: 0 | R33: 0 | S33: 0 | T33: 0 | U33: 0 | V33: 0 | W33: 0 | X33: 0 | Y33: 0 | Z33: 0 | AA33: 0 | AB33: 0 | AC33: 0 | AD33: 0 | AQ33: 0
A34: barley | B34: total | C34: 0 | D34: 0 | E34: 0 | F34: 0 | G34: 0 | H34: 0 | I34: 0 | J34: 0 | K34: 0 | L34: 0 | M34: 0 | N34: 0 | O34: 0 | P34: 0 | Q34: 0 | R34: 0 | S34: 0 | T34: 0 | U34: 0 | V34: 0 | W34: 0 | AQ34: 0
A35: oats | B35: and for 33 quarters 3 bushels from the whole issue, threshed by piece-work, besides 6 quarters 7 bushels from the same issue, threshed the preceding year. | C35: 0 | D35: 0 | E35: 0 | F35: 0 | G35: 0 | H35: 0 | I35: 0 | J35: 0 | K35: 0 | L35: 0 | M35: 0 | N35: 0 | O35: 0 | P35: 0 | Q35: 0 | R35: 0 | S35: 0 | T35: 39 | U35: 10 | V35: 40.25 | W35: 0 | X35: 6 | Y35: 7 | Z35: 6.88 | AA35: 33.38 | AB35: -26.5 | AC35: 33 | AD35: 3 | AE35: 6 | AF35: 7 | AQ35: 0
A36: oats | B36: 6 quarters 6 bushels from the issue by estimation in sheaves. | C36: 0 | D36: 0 | E36: 0 | F36: 0 | G36: 0 | H36: 0 | I36: 0 | J36: 0 | K36: 0 | L36: 0 | M36: 0 | N36: 0 | O36: 0 | P36: 0 | Q36: 0 | R36: 0 | S36: 0 | T36: 0 | U36: 0 | V36: 0 | W36: 0 | X36: 6 | Y36: 6 | Z36: 6.75 | AA36: 6.75 | AB36: 0 | AC36: 6 | AD36: 6 | AQ36: 0
A37: oats | B37: 1 qr 1 bushels bought. | C37: 0 | D37: 0 | E37: 0 | F37: 0 | G37: 0 | H37: 0 | I37: 0 | J37: 0 | K37: 0 | L37: 0 | M37: 0 | N37: 0 | O37: 0 | P37: 0 | Q37: 0 | R37: 0 | S37: 0 | T37: 0 | U37: 0 | V37: 0 | W37: 0 | AQ37: 0
A38: oats | B38: 4 quarters 3 bushels surcharged so that he answers for a 3-fold yield.. | C38: 0 | D38: 0 | E38: 0 | F38: 0 | G38: 0 | H38: 0 | I38: 0 | J38: 0 | K38: 0 | L38: 0 | M38: 0 | N38: 0 | O38: 0 | P38: 0 | Q38: 0 | R38: 0 | S38: 0 | T38: 0 | U38: 0 | V38: 0 | W38: 0 | X38: 4 | Y38: 3 | Z38: 4.38 | AA38: 4.38 | AB38: 0 | AC38: 4 | AD38: 3 | AQ38: 0
A39: oats | B39: total, 45 quarters 5 bushels. | C39: 0 | D39: 0 | E39: 0 | F39: 0 | G39: 0 | H39: 0 | I39: 0 | J39: 0 | K39: 0 | L39: 0 | M39: 0 | N39: 0 | O39: 0 | P39: 0 | Q39: 0 | R39: 0 | S39: 0 | T39: 0 | U39: 0 | V39: 0 | W39: 0 | X39: 45 | Y39: 5 | Z39: 45.62 | AA39: 45.62 | AB39: 0 | AC39: 45 | AD39: 5 | AQ39: 0
A40: oats | B40: sown over 35 acres by the perch in tattescombe and reghele, 17 quarters 4 bushels. | C40: 0 | D40: 0 | E40: 17 | F40: 4 | G40: 17.5 | H40: 0 | I40: 0 | J40: 0 | K40: 0 | L40: 0 | M40: 0 | N40: 0 | O40: 0 | P40: 0 | Q40: 0 | R40: 0 | S40: 0 | T40: 0 | U40: 0 | V40: 0 | W40: 0 | X40: 17 | Y40: 4 | Z40: 17.5 | AA40: 17.5 | AB40: 0 | AC40: 17 | AD40: 4 | AQ40: 0
...

Sheet Issues of the Grange
A1: Gross Output | B1: Bought Only Aggregated | C1: Account Quarters | D1: Account Bushels | E1: Account Total Quarters | F1: Bought in Quarters | G1: Bought in Bushels | H1: Total Bought Quarters | I1: Sold Quarters | J1: Sold Bushels | K1: Sold Total Quarters | L1: Total Corn Quantity | M1: Difference Produced+Bought-Sold | N1: Weighted Average Price per Quarter | O1: Non-Weighted Average Price per Quarter | P1: Value of Total Production weighted | Q1: Value of Total Production unweighted
A2: and he owes | B2: 0 | C2: 0 | D2: 0 | E2: 0 | F2: 0 | G2: 0 | H2: 0 | I2: 0 | J2: 0 | K2: 0 | L2: 0 | M2: 0
A3: wheat | B3: 0 | C3: 30 | D3: 4 | E3: 30.5 | F3: 0 | G3: 0 | H3: 0 | I3: 37 | J3: 4 | K3: 37.5 | L3: 30.5 | M3: -7 | N3: 0.47 | O3: 0.48 | P3: 14.37 | Q3: 14.74
A4: curall | B4: 0 | C4: 0 | D4: 0 | E4: 0 | F4: 0 | G4: 0 | H4: 0 | I4: 0 | J4: 0 | K4: 0 | L4: 0 | M4: 0
A5: barley | B5: 0 | C5: 53 | D5: 4 | E5: 53.5 | F5: 0 | G5: 13 | H5: 0 | I5: 8 | J5: 5 | K5: 8.62 | L5: 53.5 | M5: 44.88
A6: oats | B6: 0 | C6: 39 | D6: 10 | E6: 40.25 | F6: 0 | G6: 0 | H6: 0 | I6: 9 | J6: 3 | K6: 9.38 | L6: 40.25 | M6: 30.88
A7: Mancorn | B7: 0 | C7: 0 | D7: 0 | E7: 0 | F7: 0 | G7: 0 | H7: 0 | I7: 0 | J7: 0 | K7: 0 | L7: 0 | M7: 0
A8: Maslin | B8: 0 | C8: 0 | D8: 0 | E8: 0 | F8: 0 | G8: 0 | H8: 0 | I8: 0 | J8: 0 | K8: 0 | L8: 0 | M8: 0
A9: First-grade malt | B9: 0 | C9: 0 | D9: 0 | E9: 0 | F9: 0 | G9: 0 | H9: 0 | I9: 0 | J9: 0 | K9: 0 | L9: 0 | M9: 0
A10: Second-grade malt | B10: 0 | C10: 0 | D10: 0 | E10: 0 | F10: 0 | G10: 0 | H10: 0 | I10: 0 | J10: 0 | K10: 0 | L10: 0 | M10: 0
A11: Peas | B11: 0 | C11: 0 | D11: 0 | E11: 0 | F11: 0 | G11: 0 | H11: 0 | I11: 0 | J11: 0 | K11: 0 | L11: 0 | M11: 0
A12: Oatmeal | B12: 0 | C12: 0 | D12: 0 | E12: 0 | F12: 0 | G12: 0 | H12: 0 | I12: 0 | J12: 0 | K12: 0 | L12: 0 | M12: 0
A13: Vetches | B13: 0 | C13: 0 | D13: 0 | E13: 0 | F13: 0 | G13: 0 | H13: 0 | I13: 0 | J13: 0 | K13: 0 | L13: 0 | M13: 0
A14: Rye | B14: 0 | C14: 0 | D14: 0 | E14: 0 | F14: 0 | G14: 0 | H14: 0 | I14: 0 | J14: 0 | K14: 0 | L14: 0 | M14: 0
A15: Dredge | B15: 0 | C15: 0 | D15: 0 | E15: 0 | F15: 0 | G15: 0 | H15: 0 | I15: 0 | J15: 0 | K15: 0 | L15: 0 | M15: 0
A16: Malt | B16: 0 | C16: 0 | D16: 0 | E16: 0 | F16: 0 | G16: 0 | H16: 0 | I16: 0 | J16: 0 | K16: 0 | L16: 0 | M16: 0 | N16: 0.29 | O16: 0.28 | P16: 0 | Q16: 0
A17: Meal | B17: 0 | C17: 0 | D17: 0 | E17: 0 | F17: 0 | G17: 0 | H17: 0 | I17: 0 | J17: 0 | K17: 0 | L17: 0 | M17: 0

Sheet Sale of Corn Prices
A1: Heading | B1: Sentence | C1: Total in Pounds | D1: Pounds | E1: Shillings | F1: Pence | G1: Corn | H1: Total Quarters Except 1 | I1: Total Bushels Except 1 | J1: Total Corn Cross-Check | K1: Total Corn Manorial Account | L1: Corn Quantity Error | M1: Quarters 0 | N1: Bushels 0 | O1: shilling a quarter 1 | P1: pence a quarter 1 | Q1: Quarters 1 | R1: Bushels 1 | S1: shilling a quarter 2 | T1: pence a quarter 2 | U1: Quarters 2 | V1: Bushels 2 | W1: shilling a quarter 3 | X1: pence a quarter 3 | Y1: Quarters 3 | Z1: Bushels 3 | AA1: shilling a quarter 4 | AB1: pence a quarter 4 | AC1: Quarters 4 | AD1: Bushels 4 | AE1: Quarters 5 | AF1: Bushels 5 | AG1: Quarters 6 | AH1: Bushels 6 | AI1: £ a quarter 1 | AJ1: £ a quarter 2 | AK1: £ a quarter 3 | AL1: £ a quarter 4 | AM1: Quarters Sold | AN1: Weighted Average Price per Quarter | AO1: Non-Weighted Average Price per Quarter | AP1: Corn lowercase
A2: sale of corn and malt | B2: and for £14 7 shilling 11.75pence1 from 30 quarters of wheat sold, of which 7 quarters 4 bushels sold to the lord's household for £3 10 shilling, at 9 shilling 4pence a quarters, 1 quarters 1 bushels to the guardians of john coupere until he should come of age for 3 shilling 9pence, and 21 quarters 3 bushels per mutuum for £10 13 shilling 9pence, at 10 shilling a quarters. | C2: 14.4 | D2: 14 | E2: 7 | F2: 11.75 | G2: wheat | H2: 29 | I2: 8 | J2: 30 | K2: 30 | L2: 0 | M2: 30 | N2: 0 | O2: 9 | P2: 4 | Q2: 7 | R2: 4 | S2: 10 | T2: 0 | U2: 1 | V2: 1 | Y2: 21 | Z2: 3 | AI2: 0.47 | AJ2: 0.5 | AM2: 30 | AN2: 0.47 | AO2: 0.48 | AP2: wheat
A3: sale of corn and malt | B3: £50 14 shilling from 174 quarters of malt sold to the lord's household, at 6 shilling a quarters for 144 quarters, or £43 4 shilling, and 5 shilling a quarters for 30 quarters, or £7 10 shilling. | C3: 50.7 | D3: 50 | E3: 14 | F3: 0 | G3: malt | H3: 174 | I3: 0 | J3: 174 | K3: 174 | L3: 0 | M3: 174 | N3: 0 | O3: 6 | P3: 0 | Q3: 144 | R3: 0 | S3: 5 | T3: 0 | U3: 30 | V3: 0 | AI3: 0.3 | AJ3: 0.25 | AM3: 174 | AN3: 0.29 | AO3: 0.28 | AP3: malt
A4: sale of corn and malt | B4: total, £65 1 shilling 11.75pence. | C4: 65.1 | D4: 65 | E4: 1 | F4: 11.75 | H4: 0 | I4: 0 | J4: 0 | K4: 0 | L4: 0 | M4: 0 | N4: 0 | AI4: inf | AM4: 0 | AN4: inf | AO4: inf
