Workbook

Sheet Overview
A1: BISHOPSFONTHILL OVERVIEW - COMPLETED | B1: Total in £ | C1: Error | D1: Note
A2: CASH ACCOUNT
A3: RECEIPTS
A4: Arrears total | B4: 0.19
A5: Rents of assize total | B5: 0
A6: Quittances total
A7: Defaults of rent total
A8: Defaults of rent through the pestilence total
A9: Cotlands defaults total
A10: Cotlands total
A11: Total of quittances and defaults of rent total
A12: Total of rents remaining clear total
A13: Farms total
A14: Annual recognizances total | B14: 0.03
A15: Issues of the Manor total | B15: 1.88
A16: Issues of the tenements in the lord's hands total
A17: Sale of labour services total
A18: Sale of corn total
A19: Entry and marriage fines total
A20: Pleas & perquisites total | B20: 0.33
A21: Forfeited chattels total
A22: Farm of the demesne land total
A23: Total of all receipts (calculated here) | B23: =SUM(B5:B11) -> 0
A24: Total of all receipts (calculated here) incl arrears | B24: =SUM(B4:B11) -> 0.19
A25: Total recorded in the accounts excl. arrears | B25: =Receipts!F31 -> 2.98 | C25: =B23-B25 -> -2.98
A26: Total recorded in the accounts incl. arrears | B26: =Receipts!F32 -> 3.17
A29: EXPENSES
A30: Cost of ploughs total
A31: Purchase of corn total
A32: Cost of carts and wagons total
A33: Cost of dairy total
A34: Purchase of stock total
A35: Sheepcote total
A36: Cost of buildings total
A37: Threshing total
A38: Barley expenses
A39: Expenses of the harvest total
A40: Necessary expenses
A41: Wages of the bailiff
A42: Steward's expenses total | B42: 0.35
...

Sheet Receipts
A1: BISHOPSFONTHILL RECEIPTS
A2: Heading | B2: £ | C2: s | D2: d | F2: Total in £ | G2: Error | H2: Notes | I2: Own notes
A3: Arrears | B3: 0 | C3: 3 | D3: 10 | F3: 0.19 | H3: John Brounyng', farmer there, answers for 3 shilling 10pence of arrears from his last account of the preceding year.
A4: Arrears | B4: 0 | C4: 3 | D4: 10 | F4: 0.19 | H4: Total, 3 shilling 10pence.
A5: Arrears total | F5: 0.19 | G5: 0 | H5: Total
A7: Rents | B7: 0 | C7: 0 | D7: 0 | F7: 0 | H7: Nothing for rents because they pertain to the farmer, the full total of which is made clear in the first year of the translation of the lord and in the preceding pipe rolls.
A8: Rents total | F8: 0 | G8: 0 | H8: Total
A10: Annual recognizance | B10: 0 | C10: 0 | D10: 6 | F10: 0.03 | H10: And for 6pence for the annual recognizance of Thomas Davy the younger, the lord's villein, so that he may dwell outside the lord's liberty as long as it pleases the lord and come to the tourn of Hockday for the year and remain the lord's villein as before.
A11: Annual recognizance | B11: 0 | C11: 0 | D11: 6 | F11: 0.03 | H11: Total, 6pence.
A12: Annual recognizance total | F12: 0.03 | G12: 0 | H12: Total
A14: Issues of the manor | B14: 1 | C14: 17 | D14: 8 | F14: 1.88 | H14: And for £1 17 shilling 8pence from underwood sold this year.
A15: Issues of the manor | B15: 1 | C15: 17 | D15: 8 | F15: 1.88 | H15: Total, £1 17 shilling 8pence.
A16: Issues of the manor total | F16: 1.88 | G16: 0 | H16: Total
A18: Sale of stock | B18: 0 | C18: 14 | D18: 0 | F18: 0.7 | H18: And for 14 shilling from 2 cows from a heriot sold.
A19: Sale of stock | B19: 0 | C19: 14 | D19: 0 | F19: 0.7 | H19: Total, 14 shilling.
A20: Sale of stock total | F20: 0.7 | G20: 0 | H20: Total
A22: Perquisites of court | B22: 0 | C22: 0 | D22: 8 | F22: 0.03 | H22: And for 8pence from the perquisites of the tourn of Martinmas.
A23: Perquisites of court | B23: 0 | C23: 1 | D23: 1 | F23: 0.05 | H23: 1 shilling 1pence from the perquisites of the tourn of Hockday.
A24: Perquisites of court | B24: 0 | C24: 5 | D24: 1 | F24: 0.25 | H24: 5 shilling 1pence from the perquisites of the courts held during the year, that is, from the amercements pertaining to the tourn.
A25: Perquisites of court | B25: 0 | C25: 6 | D25: 10 | F25: 0.34 | H25: Total, 6 shilling 10pence.
A26: Perquisites of court total | F26: 0.33 | G26: -0.01 | H26: Total
A28: Reliefs | B28: 0 | C28: 0 | D28: 10 | F28: 0.04 | H28: And for 10pence from William Elys for the relief of a hundred and twentieth part of one.
A29: Reliefs | B29: 0 | C29: 0 | D29: 0 | F29: 0 | H29: knight's fee in Bishops Fonthill by hereditary right.
A30: Reliefs total | B30: 0 | C30: 0 | D30: 10 | F30: 0.04 | G30: 0.04 | H30: Total, 10pence.
A31: Total of all receipts recorded in accounts (calculated here) | F31: =SUMIF(A1:A30,"* total",F1:F30)-SUMIF(A1:A30,"Arrears total",F1:F30) -> 2.98
A32: Total of all receipts (calculated here) incl arrears | F32: =F31+SUMIF(A1:A30,"Arrears total",F1:F30) -> 3.17

Sheet Expenses
A1: BISHOPSFONTHILL EXPENSES
A2: Heading | B2: £ | C2: s | D2: d | F2: Total in £ | G2: Error | H2: Sentence | I2: Fixed Investments | J2: Demesne Fixed Investments
A4: Stipends | B4: 0 | C4: 5 | D4: 0 | F4: 0.25 | H4: In stipend of 1 overseer of the harvest, keeping the woods and officiating at the tourns and courts and collecting the money therefrom, 5 shilling for the year.
A5: Stipends | B5: 0 | C5: 5 | D5: 0 | F5: 0.25 | H5: Total, 5 shilling.
A6: Stipends total | F6: 0.25 | G6: 0 | H6: Total
A8: Expenses of the steward | B8: 0 | C8: 7 | D8: 0 | F8: 0.35 | H8: In expenses of the steward coming there to survey the manor and stock at the tourns of Martinmas and Hockday, by 2 sealed bills, together with expenses for the road at Marlborough, 7 shilling.
A9: Expenses of the steward | B9: 0 | C9: 7 | D9: 0 | F9: 0.35 | H9: Total, 7 shilling.
A10: Expenses of the steward total | F10: 0.35 | G10: 0 | H10: Total
A12: And he owes | B12: 22 | C12: 1 | D12: 10 | F12: 22.09 | H12: And he owes, £22 1 shilling 10pence.
A13: And he owes total | F13: 22.09 | G13: 0 | H13: Total
A15: Cash deliveries | B15: 21 | C15: 18 | D15: 0 | F15: 21.9 | H15: Delivered to John Arnald', receiver of Wolvesey, by 1 tally, £21 18 shilling.
A16: Cash deliveries total | B16: 21 | C16: 18 | D16: 0 | F16: 21.9 | G16: 0 | H16: Total, £21 18 shilling.

Sheet Stock
A1: BISHOPSFONTHILL STOCK ACCOUNT
C3: added | G3: subtracted
A4: Livestock | B4: Inherited stock | C4: added | D4: strays | E4: herbage | F4: churchscot | G4: of which in default | H4: sold | I4: in murrain | J4: accounted for elsewhere | K4: End-period stock | L4: cross-check | M4: stock building | N4: raw production | O4: Unit price (£) | P4: Value of stock (£) at given value | Q4: Value of stock (£) at sales prices | R4: Sales in (£) | S4: Value of stock building (£) | T4: Value of production (£) at sales prices | U4: Details
A5: Cart-horses | B5: 0 | C5: 0 | H5: 0 | I5: 0 | K5: =B5+C5-H5-I5 -> 0 | L5: =B5+C5-H5 -> 0 | M5: =L5-B5 -> 0 | N5: =C5 -> 0 | O5: 0 | P5: =O5*K5 -> 0 | R5: 0 | S5: =O5*M5 -> 0 | T5: =O5*N5 -> 0
A6: Mares | B6: 0 | C6: 0 | H6: 0 | I6: 0 | K6: =B6+C6-H6-I6 -> 0 | L6: =B6+C6-H6 -> 0 | M6: =L6-B6 -> 0 | N6: =C6 -> 0 | O6: 0 | P6: =O6*K6 -> 0 | R6: 0 | S6: =O6*M6 -> 0 | T6: =O6*N6 -> 0
A7: Plough horses | B7: 2 | C7: 0 | H7: 0 | I7: 0 | K7: =B7+C7-H7-I7 -> 2 | L7: =B7+C7-H7 -> 2 | M7: =L7-B7 -> 0 | N7: =C7 -> 0 | O7: =80/240 -> 0.33333333 | P7: =O7*K7 -> 0.66666667 | R7: 0 | S7: =O7*M7 -> 0 | T7: =O7*N7 -> 0
A8: Colts (unspecified years) | B8: 0 | C8: 0 | H8: 0 | I8: 0 | K8: =B8+C8-H8-I8 -> 0 | L8: =B8+C8-H8 -> 0 | M8: =L8-B8 -> 0 | N8: =C8 -> 0 | O8: 0 | P8: =O8*K8 -> 0 | R8: 0 | S8: =O8*M8 -> 0 | T8: =O8*N8 -> 0
A9: Colts (2 years) | B9: 0 | C9: 0 | H9: 0 | I9: 0 | K9: =B9+C9-H9-I9 -> 0 | L9: =B9+C9-H9 -> 0 | M9: =L9-B9 -> 0 | N9: =C9 -> 0 | O9: 0 | P9: =O9*K9 -> 0 | R9: 0 | S9: =O9*M9 -> 0 | T9: =O9*N9 -> 0
A10: Colts (1 year) | B10: 0 | C10: 0 | H10: 0 | I10: 0 | K10: =B10+C10-H10-I10 -> 0 | L10: =B10+C10-H10 -> 0 | M10: =L10-B10 -> 0 | N10: =C10 -> 0 | O10: 0 | P10: =O10*K10 -> 0 | R10: 0 | S10: =O10*M10 -> 0 | T10: =O10*N10 -> 0
A11: Foals | B11: 0 | C11: 0 | H11: 0 | I11: 0 | K11: =B11+C11-H11-I11 -> 0 | L11: =B11+C11-H11 -> 0 | M11: =L11-B11 -> 0 | N11: =C11 -> 0 | O11: 0 | P11: =O11*K11 -> 0 | R11: 0 | S11: =O11*M11 -> 0 | T11: =O11*N11 -> 0
A12: Oxen | B12: 12 | C12: 0 | H12: 0 | I12: 0 | K12: =B12+C12-H12-I12 -> 12 | L12: =B12+C12-H12 -> 12 | M12: =L12-B12 -> 0 | N12: =C12 -> 0 | O12: =160/240 -> 0.66666667 | P12: =O12*K12 -> 8 | R12: 0 | S12: =O12*M12 -> 0 | T12: =O12*N12 -> 0
A13: Bulls | B13: 0 | C13: 0 | H13: 0 | I13: 0 | K13: =B13+C13-H13-I13 -> 0 | L13: =B13+C13-H13 -> 0 | M13: =L13-B13 -> 0 | N13: =C13 -> 0 | O13: 0 | P13: =O13*K13 -> 0 | R13: 0 | S13: =O13*M13 -> 0 | T13: =O13*N13 -> 0
A14: Cows | B14: 0 | C14: 0 | H14: 0 | I14: 0 | K14: =B14+C14-H14-I14 -> 0 | L14: =B14+C14-H14 -> 0 | M14: =L14-B14 -> 0 | N14: =C14 -> 0 | O14: 0 | P14: =O14*K14 -> 0 | R14: 0.7 | S14: =O14*M14 -> 0 | T14: =O14*N14 -> 0
A15: Steers | B15: 0 | C15: 0 | H15: 0 | I15: 0 | K15: =B15+C15-H15-I15 -> 0 | L15: =B15+C15-H15 -> 0 | M15: =L15-B15 -> 0 | N15: =C15 -> 0 | O15: 0 | P15: =O15*K15 -> 0 | R15: 0 | S15: =O15*M15 -> 0 | T15: =O15*N15 -> 0
A16: Bullocks | B16: 0 | C16: 0 | H16: 0 | I16: 0 | K16: =B16+C16-H16-I16 -> 0 | L16: =B16+C16-H16 -> 0 | M16: =L16-B16 -> 0 | N16: =C16 -> 0 | O16: 0 | P16: =O16*K16 -> 0 | R16: 0 | S16: =O16*M16 -> 0 | T16: =O16*N16 -> 0
A17: Yearlings | B17: 0 | C17: 0 | H17: 0 | I17: 0 | K17: =B17+C17-H17-I17 -> 0 | L17: =B17+C17-H17 -> 0 | M17: =L17-B17 -> 0 | N17: =C17 -> 0 | O17: 0 | P17: =O17*K17 -> 0 | R17: 0 | S17: =O17*M17 -> 0 | T17: =O17*N17 -> 0
A18: Calves | B18: 0 | C18: 0 | H18: 0 | I18: 0 | K18: =B18+C18-H18-I18 -> 0 | L18: =B18+C18-H18 -> 0 | M18: =L18-B18 -> 0 | N18: =C18 -> 0 | O18: 0 | P18: =O18*K18 -> 0 | R18: 0 | S18: =O18*M18 -> 0 | T18: =O18*N18 -> 0
A19: Wethers | B19: 300 | C19: 0 | H19: 0 | I19: 0 | K19: =B19+C19-H19-I19 -> 300 | L19: =B19+C19-H19 -> 300 | M19: =L19-B19 -> 0 | N19: =C19 -> 0 | O19: =22/240 -> 0.091666667 | P19: =O19*K19 -> 27.5 | R19: 0 | S19: =O19*M19 -> 0 | T19: =O19*N19 -> 0
A20: Rams | B20: 0 | C20: 0 | H20: 0 | I20: 0 | K20: =B20+C20-H20-I20 -> 0 | L20: =B20+C20-H20 -> 0 | M20: =L20-B20 -> 0 | N20: =C20 -> 0 | O20: 0 | P20: =O20*K20 -> 0 | R20: 0 | S20: =O20*M20 -> 0 | T20: =O20*N20 -> 0
A21: Ewes | B21: 0 | C21: 0 | H21: 0 | I21: 0 | K21: =B21+C21-H21-I21 -> 0 | L21: =B21+C21-H21 -> 0 | M21: =L21-B21 -> 0 | N21: =C21 -> 0 | O21: 0 | P21: =O21*K21 -> 0 | Q21: 0 | R21: 0 | S21: =O21*M21 -> 0 | T21: =O21*N21 -> 0
A22: Hoggs | B22: 0 | C22: 0 | H22: 0 | I22: 0 | K22: =B22+C22-H22-I22 -> 0 | L22: =B22+C22-H22 -> 0 | M22: =L22-B22 -> 0 | N22: =C22 -> 0 | O22: 0 | P22: =O22*K22 -> 0 | R22: 0 | S22: =O22*M22 -> 0 | T22: =O22*N22 -> 0
A23: Lambs | B23: 0 | C23: 0 | H23: 0 | I23: 0 | K23: =B23+C23-H23-I23 -> 0 | L23: =B23+C23-H23 -> 0 | M23: =L23-B23 -> 0 | N23: =C23 -> 0 | O23: 0 | P23: =O23*K23 -> 0 | R23: 0 | S23: =O23*M23 -> 0 | T23: =O23*N23 -> 0
A24: Boars | B24: 0 | C24: 0 | H24: 0 | I24: 0 | K24: =B24+C24-H24-I24 -> 0 | L24: =B24+C24-H24 -> 0 | M24: =L24-B24 -> 0 | N24: =C24 -> 0 | O24: 0 | P24: =O24*K24 -> 0 | R24: 0 | S24: =O24*M24 -> 0 | T24: =O24*N24 -> 0
A25: Sows | B25: 0 | C25: 0 | H25: 0 | I25: 0 | K25: =B25+C25-H25-I25 -> 0 | L25: =B25+C25-H25 -> 0 | M25: =L25-B25 -> 0 | N25: =C25 -> 0 | O25: 0 | P25: =O25*K25 -> 0 | R25: 0 | S25: =O25*M25 -> 0 | T25: =O25*N25 -> 0
A26: Pigs | B26: 0 | C26: 0 | H26: 0 | I26: 0 | K26: =B26+C26-H26-I26 -> 0 | L26: =B26+C26-H26 -> 0 | M26: =L26-B26 -> 0 | N26: =C26 -> 0 | O26: 0 | P26: =O26*K26 -> 0 | R26: 0 | S26: =O26*M26 -> 0 | T26: =O26*N26 -> 0
A27: Hoggets | B27: 0 | C27: 0 | H27: 0 | I27: 0 | K27: =B27+C27-H27-I27 -> 0 | L27: =B27+C27-H27 -> 0 | M27: =L27-B27 -> 0 | N27: =C27 -> 0 | O27: 0 | P27: =O27*K27 -> 0 | R27: 0 | S27: =O27*M27 -> 0 | T27: =O27*N27 -> 0
A28: Piglets | B28: 0 | C28: 0 | H28: 0 | I28: 0 | K28: =B28+C28-H28-I28 -> 0 | L28: =B28+C28-H28 -> 0 | M28: =L28-B28 -> 0 | N28: =C28 -> 0 | O28: 0 | P28: =O28*K28 -> 0 | R28: 0 | S28: =O28*M28 -> 0 | T28: =O28*N28 -> 0
A29: Swans | B29: 0 | C29: 0 | H29: 0 | I29: 0 | K29: =B29+C29-H29-I29 -> 0 | L29: =B29+C29-H29 -> 0 | M29: =L29-B29 -> 0 | N29: =C29 -> 0 | O29: 0 | P29: =O29*K29 -> 0 | R29: 0 | S29: =O29*M29 -> 0 | T29: =O29*N29 -> 0
A30: Peacocks | B30: 0 | C30: 0 | H30: 0 | I30: 0 | K30: =B30+C30-H30-I30 -> 0 | L30: =B30+C30-H30 -> 0 | M30: =L30-B30 -> 0 | N30: =C30 -> 0 | O30: 0 | P30: =O30*K30 -> 0 | R30: 0 | S30: =O30*M30 -> 0 | T30: =O30*N30 -> 0
A31: Total Value
A34: Wool | B34: 0 | C34: 0 | H34: 0 | I34: 0
A35: Coarse wool | B35: 0 | C35: 0 | H35: 0 | I35: 0
A36: Lamb's wool | B36: 0 | C36: 0 | H36: 0 | I36: 0
A37: Wool locks | B37: 0 | C37: 0 | H37: 0 | I37: 0
A38: Wool sold at shearing | B38: 0 | C38: 0 | H38: 0 | I38: 0
A39: Total wool | B39: 0 | C39: 0 | H39: 0 | I39: 0
B40: 0 | C40: 0 | H40: 0 | I40: 0
B41: 0 | C41: 0 | H41: 0 | I41: 0
A42: Hides | B42: 0 | C42: 0 | H42: 0 | I42: 0
A43: Ox hides | B43: 0 | C43: 0 | H43: 0 | I43: 0
...

Sheet raw data
A1: Heading | B1: Sentence | C1: Total in Pounds | D1: Pounds | E1: Shillings | F1: Pence | G1: Corn | H1: Total Quarters Except 1 | I1: Total Bushels Except 1 | J1: Total Corn Cross-Check | K1: Total Corn Manorial Account | L1: Corn Quantity Error | M1: Quarters 1 | N1: Bushels 1 | O1: Quarters 2 | P1: Bushels 2 | Q1: shilling a quarter 1 | R1: pence a quarter 1 | S1: shilling a quarter 2 | T1: pence a quarter 2 | U1: shilling a quarter 3 | V1: pence a quarter 3 | W1: shilling a quarter 4 | X1: pence a quarter 4 | Y1: shilling a bushel 1 | Z1: pence a bushel 1 | AA1: shilling a bushel 2 | AB1: pence a bushel 2 | AC1: shilling a bushel 3 | AD1: pence a bushel 3 | AE1: shilling a bushel 4 | AF1: pence a bushel 4
A2: bishops fonthill | B2: the account of the same from michaelmas of the fifth year of the translation of henry beaufort', lord bishop of winchester, until michaelmas of the sixth year, for one whole year, and the eleventh year of the reign of king henry the fourth. | C2: 0 | D2: 0 | E2: 0 | F2: 0 | H2: 0 | I2: 0 | J2: 0 | K2: 0 | L2: 0 | M2: 0 | N2: 0
A3: arrears | B3: john brounyng', farmer there, answers for 3 shilling 10pence of arrears from his last account of the preceding year. | C3: 0.19 | D3: 0 | E3: 3 | F3: 10 | H3: 0 | I3: 0 | J3: 0 | K3: 0 | L3: 0 | M3: 0 | N3: 0
A4: arrears | B4: total, 3 shilling 10pence. | C4: 0.19 | D4: 0 | E4: 3 | F4: 10 | H4: 0 | I4: 0 | J4: 0 | K4: 0 | L4: 0 | M4: 0 | N4: 0
A5: rents | B5: nothing for rents because they pertain to the farmer, the full total of which is made clear in the first year of the translation of the lord and in the preceding pipe rolls. | C5: 0 | D5: 0 | E5: 0 | F5: 0 | H5: 0 | I5: 0 | J5: 0 | K5: 0 | L5: 0 | M5: 0 | N5: 0
A6: farms | B6: and for £20 for the farm of the manor for the year, with the lands, meadows, rents, services, both of the free tenants and of the villeins, and all other things pertaining to it, except wards, reliefs, marriages, escheats, heriots, strays, entry fines, wood and underwood, and everything pertaining in whatever way to the tourn, besides which he will have from the lord's wood reasonable housebote and haybote and withies to make hurdles for the lord's fold to deliver to the lord's officials, demised to john brounyng' for a term of 12 years, this year being the fifth, to be paid in equal portions at the 4 principal terms of the year. | C6: 20 | D6: 20 | E6: 0 | F6: 0 | H6: 0 | I6: 0 | J6: 0 | K6: 0 | L6: 0 | M6: 0 | N6: 0
A7: farms | B7: total, £20.. | C7: 20 | D7: 20 | E7: 0 | F7: 0 | H7: 0 | I7: 0 | J7: 0 | K7: 0 | L7: 0 | M7: 0 | N7: 0
A8: annual recognizance | B8: and for 6pence for the annual recognizance of thomas davy the younger, the lord's villein, so that he may dwell outside the lord's liberty as long as it pleases the lord and come to the tourn of hockday for the year and remain the lord's villein as before. | C8: 0.03 | D8: 0 | E8: 0 | F8: 6 | H8: 0 | I8: 0 | J8: 0 | K8: 0 | L8: 0 | M8: 0 | N8: 0
A9: annual recognizance | B9: total, 6pence. | C9: 0.03 | D9: 0 | E9: 0 | F9: 6 | H9: 0 | I9: 0 | J9: 0 | K9: 0 | L9: 0 | M9: 0 | N9: 0
A10: issues of the manor | B10: and for £1 17 shilling 8pence from underwood sold this year. | C10: 1.88 | D10: 1 | E10: 17 | F10: 8 | H10: 0 | I10: 0 | J10: 0 | K10: 0 | L10: 0 | M10: 0 | N10: 0
A11: issues of the manor | B11: total, £1 17 shilling 8pence. | C11: 1.88 | D11: 1 | E11: 17 | F11: 8 | H11: 0 | I11: 0 | J11: 0 | K11: 0 | L11: 0 | M11: 0 | N11: 0
A12: sale of stock | B12: and for 14 shilling from 2 cows from a heriot sold. | C12: 0.7 | D12: 0 | E12: 14 | F12: 0 | H12: 0 | I12: 0 | J12: 0 | K12: 0 | L12: 0 | M12: 0 | N12: 0
A13: sale of stock | B13: total, 14 shilling. | C13: 0.7 | D13: 0 | E13: 14 | F13: 0 | H13: 0 | I13: 0 | J13: 0 | K13: 0 | L13: 0 | M13: 0 | N13: 0
... A36: and he owes clear | B36: and he owes clear, 3 shilling 10pence, all of which is in the hands of the escheator. | C36: 0.19 | D36: 0 | E36: 3 | F36: 10 | H36: 0 | I36: 0 | J36: 0 | K36: 0 | L36: 0 | M36: 0 | N36: 0
A37: wheat | B37: john brounyng', farmer there, answers for 12 quarters of wheat remaining in the hands of the farmer, to be restored at the end of his term. | C37: 0 | D37: 0 | E37: 0 | F37: 0 | G37: wheat | H37: 12 | I37: 0 | J37: 12 | K37: 12 | L37: 0 | M37: 12 | N37: 0
A38: barley | B38: and for 20 quarters of barley remaining in the hands of the farmer, to be restored at the end of his term. | C38: 0 | D38: 0 | E38: 0 | F38: 0 | G38: barley | H38: 20 | I38: 0 | J38: 20 | K38: 20 | L38: 0 | M38: 20 | N38: 0
A39: oats | B39: and for 12 quarters of oats remaining. | C39: 0 | D39: 0 | E39: 0 | F39: 0 | G39: oats | H39: 12 | I39: 0 | J39: 12 | K39: 12 | L39: 0 | M39: 12 | N39: 0
A40: oats | B40: 1 quarters from the farm for the year.. | C40: 0 | D40: 0 | E40: 0 | F40: 0 | H40: 1 | I40: 0 | J40: 1 | K40: 1 | L40: 0 | M40: 1 | N40: 0
A41: oats | B41: total, 13 quarters. | C41: 0 | D41: 0 | E41: 0 | F41: 0 | H41: 13 | I41: 0 | J41: 13 | K41: 13 | L41: 0 | M41: 13 | N41: 0
A42: oats | B42: delivered to the farmer of east knoyle, 4 bushels. | C42: 0 | D42: 0 | E42: 0 | F42: 0 | H42: 0 | I42: 4 | J42: 0.5 | K42: 0.5 | L42: 0 | M42: 0 | N42: 4
A43: oats | B43: provision of the steward, 4 bushels. | C43: 0 | D43: 0 | E43: 0 | F43: 0 | H43: 0 | I43: 4 | J43: 0.5 | K43: 0.5 | L43: 0 | M43: 0 | N43: 4
A44: oats | B44: total, 1 quarters. 12 quarters remain in the hands of the farmer, to be restored at the end of his term. | C44: 0 | D44: 0 | E44: 0 | F44: 0 | H44: 12 | I44: 0 | J44: 12 | K44: 1 | L44: 11 | M44: 1 | N44: 0 | O44: 12 | P44: 0
A45: pulses | B45: and for 1 quarters 4 bushels of pulses remaining in the hands of the farmer, to be restored at the end of his term. | C45: 0 | D45: 0 | E45: 0 | F45: 0 | H45: 1 | I45: 4 | J45: 1.5 | K45: 1.5 | L45: 0 | M45: 1 | N45: 4
A46: stock | B46: plough-horses: 2 remain in the hands of the farmer, worth 6 shilling 8pence each, to be restored at the end of his term. | C46: 0.33 | D46: 0 | E46: 6 | F46: 8 | H46: 0 | I46: 0 | J46: 0 | K46: 0 | L46: 0 | M46: 0 | N46: 0
A47: stock | B47: oxen: 12 remain in the hands of the farmer, worth 13 shilling 4pence each, to be restored at the end of his term. | C47: 0.67 | D47: 0 | E47: 13 | F47: 4 | H47: 0 | I47: 0 | J47: 0 | K47: 0 | L47: 0 | M47: 0 | N47: 0
A48: stock | B48: cows: 2 from the heriot of robert ingram. | C48: 0 | D48: 0 | E48: 0 | F48: 0 | H48: 0 | I48: 0 | J48: 0 | K48: 0 | L48: 0 | M48: 0 | N48: 0
A49: stock | B49: sold within. | C49: 0 | D49: 0 | E49: 0 | F49: 0 | H49: 0 | I49: 0 | J49: 0 | K49: 0 | L49: 0 | M49: 0 | N49: 0
A50: stock | B50: none remain. | C50: 0 | D50: 0 | E50: 0 | F50: 0 | H50: 0 | I50: 0 | J50: 0 | K50: 0 | L50: 0 | M50: 0 | N50: 0
A51: stock | B51: wethers: 300 remain in the hands of the farmer, worth 1 shilling 10pence each, to be restored at the end of his term. | C51: 0.09 | D51: 0 | E51: 1 | F51: 10 | H51: 0 | I51: 0 | J51: 0 | K51: 0 | L51: 0 | M51: 0 | N51: 0
A52: stock | B52: utensils: 2 ploughs with 2 pairs of wheels, worth 2 shilling, 2 coulters and 2 ploughshares, weighing 33 lb, 2 plough shoes (soltowys), 8 chains, 8 crooks, 8 rings and 8 staples, weighing 110 lbs, 8 yokes, worth 1 shilling, 2 harrows with iron teeth, worth 3 shilling, 1 cart with iron tyres with a frame and cart-rail, 2 hurters, 2 linch-pins, 1 cart-saddle, 1 harness for the cart-shafts (thilharneys), 2 collars, 1 pair of traces, 1 cart-rope and 1 dung-pot, worth in all 16 shilling 8pence, 1 winnowing-fan, worth 2 shilling, 1 sack, worth 8pence, 1 iron bushel measure, worth 1 shilling, 1 basket for carrying corn, worth 10pence, 2 small tables, worth 1 shilling, 1 shovel and 1 fork, worth 8pence, 1 post (ippere), worth 10pence, 2 benches, worth 6pence, and 1 ladder, worth 1 shilling, remain. | C52: 0.13 | D52: 0 | E52: 2 | F52: 8 | H52: 0 | I52: 0 | J52: 0 | K52: 0 | L52: 0 | M52: 0 | N52: 0
A53: stock | B53: all this remains in the hands of the farmer, to be restored at the end of his term or the value of the same at the lord's will. | C53: 0 | D53: 0 | E53: 0 | F53: 0 | H53: 0 | I53: 0 | J53: 0 | K53: 0 | L53: 0 | M53: 0 | N53: 0

Sheet Stock_raw
A1: Heading | B1: Sentence | C1: Quarters 1 | D1: Bushels 1 | E1: stock | F1: inherited stock | G1: added | H1: murrain | I1: sold
A2: Oats | B2: Total | C2: 0 | D2: 0
A3: Stock | B3: Plough-horses: 2 remain in the hands of the farmer, worth 6 shilling 8pence each, to be restored at the end of his term. | C3: 0 | D3: 0 | E3: Plough-horses | F3: 2
A4: Stock | B4: Oxen: 12 remain in the hands of the farmer, worth 13 shilling 4pence each, to be restored at the end of his term. | C4: 0 | D4: 0 | E4: Oxen | F4: 12
A5: Stock | B5: Cows: 2 from the heriot of Robert Ingram. | C5: 0 | D5: 0 | E5: Cows
A6: Stock | B6: sold within. | C6: 0 | D6: 0 | E6: Cows
A7: Stock | B7: none remain. | C7: 0 | D7: 0 | E7: Cows
A8: Stock | B8: Wethers: 300 remain in the hands of the farmer, worth 1 shilling 10pence each, to be restored at the end of his term. | C8: 0 | D8: 0 | E8: Wethers | F8: 300
A9: Stock | B9: Utensils: 2 ploughs with 2 pairs of wheels, worth 2 shilling, 2 coulters and 2 ploughshares, weighing 33 lb, 2 plough shoes (soltowys), 8 chains, 8 crooks, 8 rings and 8 staples, weighing 110 lbs, 8 yokes, worth 1 shilling, 2 harrows with iron teeth, worth 3 shilling, 1 cart with iron tyres with a frame and cart-rail, 2 hurters, 2 linch-pins, 1 cart-saddle, 1 harness for the cart-shafts (thilharneys), 2 collars, 1 pair of traces, 1 cart-rope and 1 dung-pot, worth in all 16 shilling 8pence, 1 winnowing-fan, worth 2 shilling, 1 sack, worth 8pence, 1 iron bushel measure, worth 1 shilling, 1 basket for carrying corn, worth 10pence, 2 small tables, worth 1 shilling, 1 shovel and 1 fork, worth 8pence, 1 post (ippere), worth 10pence, 2 benches, worth 6pence, and 1 ladder, worth 1 shilling, remain. | C9: 0 | D9: 0 | E9: Utensils
A10: Stock | B10: All this remains in the hands of the farmer, to be restored at the end of his term or the value of the same at the lord's will. | C10: 0 | D10: 0 | E10: Utensils
A11: Stock | B11: Total | C11: 0 | D11: 0 | E11: Utensils

Sheet Issues of the Mills

Sheet Prices

Sheet Labour Rents

Sheet not needed

Sheet Issues of the Grange raw
A1: Heading | B1: Sentence | C1: Quarters 1_x | D1: Bushels 1_x | E1: Sown Quarters | F1: Sown Bushels | G1: Sown Total Quarters | H1: Bought in Quarters | I1: Bought in Bushels | J1: Bought in Total Quarters | K1: Tithe Quarters | L1: Tithe Bushels | M1: Tithe Total Quarters | N1: Manorial servants & livestock Quarters | O1: Manorial servants & livestock Bushels | P1: Manorial servants & livestock Total Quarters | Q1: Sold Quarters | R1: Sold Bushels | S1: Sold Total Quarters | T1: Account Quarters | U1: Account Bushels | V1: Account Total Quarters | W1: bought only | X1: Total Quarters Except 1 | Y1: Total Bushels Except 1 | Z1: Total Corn Cross-Check | AA1: Total Corn Manorial Account | AB1: Corn Quantity Error | AC1: Quarters 1_y | AD1: Bushels 1_y | AE1: Quarters 2 | AF1: Bushels 2 | AG1: Total Bought Quarters
A2: cash deliveries | B2: total | C2: 0 | D2: 0 | E2: 0 | F2: 0 | G2: 0 | H2: 0 | I2: 0 | J2: 0 | K2: 0 | L2: 0 | M2: 0 | N2: 0 | O2: 0 | P2: 0 | Q2: 0 | R2: 0 | S2: 0 | T2: 0 | U2: 0 | V2: 0 | W2: 0 | AG2: 0
A3: wheat | B3: john brounyng', farmer there, answers for 12 quarters of wheat remaining in the hands of the farmer, to be restored at the end of his term. | C3: 0 | D3: 0 | E3: 0 | F3: 0 | G3: 0 | H3: 0 | I3: 0 | J3: 0 | K3: 0 | L3: 0 | M3: 0 | N3: 0 | O3: 0 | P3: 0 | Q3: 0 | R3: 0 | S3: 0 | T3: 0 | U3: 0 | V3: 0 | W3: 0 | X3: 12 | Y3: 0 | Z3: 12 | AA3: 12 | AB3: 0 | AC3: 12 | AD3: 0 | AG3: 0
A4: wheat | B4: total | C4: 0 | D4: 0 | E4: 0 | F4: 0 | G4: 0 | H4: 0 | I4: 0 | J4: 0 | K4: 0 | L4: 0 | M4: 0 | N4: 0 | O4: 0 | P4: 0 | Q4: 0 | R4: 0 | S4: 0 | T4: 0 | U4: 0 | V4: 0 | W4: 0 | AG4: 0
A5: barley | B5: and for 20 quarters of barley remaining in the hands of the farmer, to be restored at the end of his term. | C5: 0 | D5: 0 | E5: 0 | F5: 0 | G5: 0 | H5: 0 | I5: 0 | J5: 0 | K5: 0 | L5: 0 | M5: 0 | N5: 0 | O5: 0 | P5: 0 | Q5: 0 | R5: 0 | S5: 0 | T5: 0 | U5: 0 | V5: 0 | W5: 0 | X5: 20 | Y5: 0 | Z5: 20 | AA5: 20 | AB5: 0 | AC5: 20 | AD5: 0 | AG5: 0
A6: barley | B6: total | C6: 0 | D6: 0 | E6: 0 | F6: 0 | G6: 0 | H6: 0 | I6: 0 | J6: 0 | K6: 0 | L6: 0 | M6: 0 | N6: 0 | O6: 0 | P6: 0 | Q6: 0 | R6: 0 | S6: 0 | T6: 0 | U6: 0 | V6: 0 | W6: 0 | AG6: 0
A7: oats | B7: and for 12 quarters of oats remaining. | C7: 0 | D7: 0 | E7: 0 | F7: 0 | G7: 0 | H7: 0 | I7: 0 | J7: 0 | K7: 0 | L7: 0 | M7: 0 | N7: 0 | O7: 0 | P7: 0 | Q7: 0 | R7: 0 | S7: 0 | T7: 0 | U7: 0 | V7: 0 | W7: 0 | X7: 12 | Y7: 0 | Z7: 12 | AA7: 12 | AB7: 0 | AC7: 12 | AD7: 0 | AG7: 0
A8: oats | B8: 1 qr from the farm for the year.. | C8: 0 | D8: 0 | E8: 0 | F8: 0 | G8: 0 | H8: 0 | I8: 0 | J8: 0 | K8: 0 | L8: 0 | M8: 0 | N8: 0 | O8: 0 | P8: 0 | Q8: 0 | R8: 0 | S8: 0 | T8: 0 | U8: 0 | V8: 0 | W8: 0 | AG8: 0
A9: oats | B9: total, 13 quarters. | C9: 0 | D9: 0 | E9: 0 | F9: 0 | G9: 0 | H9: 0 | I9: 0 | J9: 0 | K9: 0 | L9: 0 | M9: 0 | N9: 0 | O9: 0 | P9: 0 | Q9: 0 | R9: 0 | S9: 0 | T9: 0 | U9: 0 | V9: 0 | W9: 0 | X9: 13 | Y9: 0 | Z9: 13 | AA9: 13 | AB9: 0 | AC9: 13 | AD9: 0 | AG9: 0
A10: oats | B10: delivered to the farmer of east knoyle, 4 bushels. | C10: 0 | D10: 0 | E10: 0 | F10: 0 | G10: 0 | H10: 0 | I10: 0 | J10: 0 | K10: 0 | L10: 0 | M10: 0 | N10: 0 | O10: 0 | P10: 0 | Q10: 0 | R10: 0 | S10: 0 | T10: 0 | U10: 0 | V10: 0 | W10: 0 | X10: 0 | Y10: 4 | Z10: 0.5 | AA10: 0.5 | AB10: 0 | AC10: 0 | AD10: 4 | AG10: 0
A11: oats | B11: provision of the steward, 4 bushels. | C11: 0 | D11: 0 | E11: 0 | F11: 0 | G11: 0 | H11: 0 | I11: 0 | J11: 0 | K11: 0 | L11: 0 | M11: 0 | N11: 0 | O11: 0 | P11: 0 | Q11: 0 | R11: 0 | S11: 0 | T11: 0 | U11: 0 | V11: 0 | W11: 0 | X11: 0 | Y11: 4 | Z11: 0.5 | AA11: 0.5 | AB11: 0 | AC11: 0 | AD11: 4 | AG11: 0
A12: oats | B12: total, 1 qr. 12 quarters remain in the hands of the farmer, to be restored at the end of his term. | C12: 0 | D12: 0 | E12: 0 | F12: 0 | G12: 0 | H12: 0 | I12: 0 | J12: 0 | K12: 0 | L12: 0 | M12: 0 | N12: 0 | O12: 0 | P12: 0 | Q12: 0 | R12: 0 | S12: 0 | T12: 0 | U12: 0 | V12: 0 | W12: 0 | AG12: 0

Sheet Issues of the Grange
A1: Gross Output | B1: Bought Only Aggregated | C1: Account Quarters | D1: Account Bushels | E1: Account Total Quarters | F1: Bought in Quarters | G1: Bought in Bushels | H1: Total Bought Quarters | I1: Sold Quarters | J1: Sold Bushels | K1: Sold Total Quarters | L1: Total Corn Quantity | M1: Difference Produced+Bought-Sold | N1: Weighted Average Price per Quarter | O1: Non-Weighted Average Price per Quarter | P1: Value of Total Production weighted | Q1: Value of Total Production unweighted
A2: cash deliveries | B2: 0 | C2: 0 | D2: 0 | E2: 0 | F2: 0 | G2: 0 | H2: 0 | I2: 0 | J2: 0 | K2: 0 | L2: 0 | M2: 0
A3: wheat | B3: 0 | C3: 0 | D3: 0 | E3: 0 | F3: 0 | G3: 0 | H3: 0 | I3: 0 | J3: 0 | K3: 0 | L3: 0 | M3: 0
A4: barley | B4: 0 | C4: 0 | D4: 0 | E4: 0 | F4: 0 | G4: 0 | H4: 0 | I4: 0 | J4: 0 | K4: 0 | L4: 0 | M4: 0
A5: oats | B5: 0 | C5: 0 | D5: 0 | E5: 0 | F5: 0 | G5: 0 | H5: 0 | I5: 0 | J5: 0 | K5: 0 | L5: 0 | M5: 0
A6: Mancorn | B6: 0 | C6: 0 | D6: 0 | E6: 0 | F6: 0 | G6: 0 | H6: 0 | I6: 0 | J6: 0 | K6: 0 | L6: 0 | M6: 0
A7: Maslin | B7: 0 | C7: 0 | D7: 0 | E7: 0 | F7: 0 | G7: 0 | H7: 0 | I7: 0 | J7: 0 | K7: 0 | L7: 0 | M7: 0
A8: First-grade malt | B8: 0 | C8: 0 | D8: 0 | E8: 0 | F8: 0 | G8: 0 | H8: 0 | I8: 0 | J8: 0 | K8: 0 | L8: 0 | M8: 0
A9: Second-grade malt | B9: 0 | C9: 0 | D9: 0 | E9: 0 | F9: 0 | G9: 0 | H9: 0 | I9: 0 | J9: 0 | K9: 0 | L9: 0 | M9: 0
A10: Peas | B10: 0 | C10: 0 | D10: 0 | E10: 0 | F10: 0 | G10: 0 | H10: 0 | I10: 0 | J10: 0 | K10: 0 | L10: 0 | M10: 0
A11: Oatmeal | B11: 0 | C11: 0 | D11: 0 | E11: 0 | F11: 0 | G11: 0 | H11: 0 | I11: 0 | J11: 0 | K11: 0 | L11: 0 | M11: 0
A12: Vetches | B12: 0 | C12: 0 | D12: 0 | E12: 0 | F12: 0 | G12: 0 | H12: 0 | I12: 0 | J12: 0 | K12: 0 | L12: 0 | M12: 0
A13: Rye | B13: 0 | C13: 0 | D13: 0 | E13: 0 | F13: 0 | G13: 0 | H13: 0 | I13: 0 | J13: 0 | K13: 0 | L13: 0 | M13: 0
... A17: Curall | B17: 0 | C17: 0 | D17: 0 | E17: 0 | F17: 0 | G17: 0 | H17: 0 | I17: 0 | J17: 0 | K17: 0 | L17: 0 | M17: 0

Sheet Sale of Corn Prices
A1: Heading | B1: Sentence | C1: Total in Pounds | D1: Pounds | E1: Shillings | F1: Pence | G1: Corn | H1: Total Quarters Except 1 | I1: Total Bushels Except 1 | J1: Total Corn Cross-Check | K1: Total Corn Manorial Account | L1: Corn Quantity Error | M1: Quarters 0 | N1: Bushels 0 | O1: shilling a quarter 1 | P1: pence a quarter 1 | Q1: Quarters 1 | R1: Bushels 1 | S1: shilling a quarter 2 | T1: pence a quarter 2 | U1: shilling a quarter 3 | V1: pence a quarter 3 | W1: shilling a quarter 4 | X1: pence a quarter 4 | Y1: £ a quarter 1 | Z1: £ a quarter 2 | AA1: £ a quarter 3 | AB1: £ a quarter 4 | AC1: Quarters Sold | AD1: Weighted Average Price per Quarter | AE1: Non-Weighted Average Price per Quarter | AF1: Corn lowercase
