Workbook

Sheet Adderbury Overview
A1: ADDERBURY | B1: Total in £ | C1: Error | D1: Note
A2: CASH ACCOUNT
A3: RECEIPTS
A4: Arrears total
A5: Rents of assize total | B5: ='Adderbury Receipts'!F9
A6: Quittances total | B6: ='Adderbury Receipts'!F22
A7: Defaults of rent total | B7: ='Adderbury Receipts'!F27
A8: Defaults of rent through the pestilence total | B8: ='Adderbury Receipts'!F36
A9: Cotlands defaults total | B9: ='Adderbury Receipts'!F45
A10: Cotlands total | B10: ='Adderbury Receipts'!F54
A11: Total of quittances and defaults of rent total | B11: ='Adderbury Receipts'!F56
A12: Total of rents remaining clear total | B12: ='Adderbury Receipts'!F58
A13: Farms total | B13: ='Adderbury Receipts'!F70
A14: Annual recognizances total | B14: ='Adderbury Receipts'!F90
A15: Issues of the Manor total | B15: ='Adderbury Receipts'!F117
A16: Issues of the tenements in the lord's hands total | B16: ='Adderbury Receipts'!F126
A17: Sale of labour services total | B17: ='Adderbury Receipts'!F135
A18: Sale of corn total | B18: ='Adderbury Receipts'!F138
A19: Entry and marriage fines total | B19: ='Adderbury Receipts'!F166
A20: Pleas & perquisites total | B20: ='Adderbury Receipts'!F173
A21: Forfeited chattels total | B21: ='Adderbury Receipts'!F177
A22: Farm of the demesne land total | B22: ='Adderbury Receipts'!F181
A23: Total of all receipts (calculated here) | B23: ='Adderbury Receipts'!F185
A24: Total of all receipts (calculated here) incl arrears
A25: Total recorded in the accounts excl. arrears | B25: ='Adderbury Receipts'!F184 | C25: =B23-B25
A26: Total recorded in the accounts incl. arrears
A29: EXPENSES
A30: Cost of ploughs total
A31: Purchase of corn total
A32: Cost of carts and wagons total
A33: Cost of dairy total
A34: Purchase of stock total
A35: Sheepcote total
A36: Cost of buildings total | B36: ='Adderbury Expenses'!F26
A37: Threshing total
A38: Barley expenses
A39: Expenses of the harvest total
A40: Necessary expenses
A41: Wages of the bailiff | B41: ='Adderbury Expenses'!F30
A42: Steward's expenses total | B42: ='Adderbury Expenses'!F33
...

Sheet Bishopstone Stock
A1: BISHOPSTONE STOCK ACCOUNT
C3: added | G3: subtracted
A4: Livestock | B4: Inherited stock | C4: added | D4: strays | E4: herbage | F4: churchscot | G4: of which in default | H4: sold | I4: in murrain | J4: accounted for elsewhere | K4: End-period stock | L4: cross-check | M4: stock building | N4: raw production | O4: Unit price (£) | P4: Value of stock (£) at given value | Q4: Value of stock (£) at sales prices | R4: Sales in (£) | S4: Value of stock building (£) | T4: Value of production (£) at sales prices | U4: Details
A5: Cart-horses | B5: 0 | C5: 0 | H5: 0 | I5: 0 | L5: =B5+C5-H5 | M5: =L5-B5 | N5: =C5 | O5: 0 | P5: =O5*K5 | R5: 0 | S5: =O5*M5 | T5: =O5*N5
A6: Mares | B6: 0 | C6: 0 | H6: 0 | I6: 0 | L6: =B6+C6-H6 | M6: =L6-B6 | N6: =C6 | O6: 0 | P6: =O6*K6 | R6: 0 | S6: =O6*M6 | T6: =O6*N6
A7: Plough horses | B7: 2 | C7: 0 | H7: 0 | I7: 0 | L7: =B7+C7-H7 | M7: =L7-B7 | N7: =C7 | O7: 0 | P7: =O7*K7 | R7: 0 | S7: =O7*M7 | T7: =O7*N7
A8: Colts (unspecified years) | B8: 0 | C8: 0 | H8: 0 | I8: 0 | L8: =B8+C8-H8 | M8: =L8-B8 | N8: =C8 | O8: 0 | P8: =O8*K8 | R8: 0 | S8: =O8*M8 | T8: =O8*N8
A9: Colts (2 years) | B9: 0 | C9: 0 | H9: 0 | I9: 0 | L9: =B9+C9-H9 | M9: =L9-B9 | N9: =C9 | O9: 0 | P9: =O9*K9 | R9: 0 | S9: =O9*M9 | T9: =O9*N9
A10: Colts (1 year) | B10: 0 | C10: 0 | H10: 0 | I10: 0 | L10: =B10+C10-H10 | M10: =L10-B10 | N10: =C10 | O10: 0 | P10: =O10*K10 | R10: 0 | S10: =O10*M10 | T10: =O10*N10
A11: Foals | B11: 0 | C11: 0 | H11: 0 | I11: 0 | L11: =B11+C11-H11 | M11: =L11-B11 | N11: =C11 | O11: 0 | P11: =O11*K11 | R11: 0 | S11: =O11*M11 | T11: =O11*N11
A12: Oxen | B12: 19 | C12: 2 | H12: 3 | I12: 0 | L12: =B12+C12-H12 | M12: =L12-B12 | N12: =C12 | O12: 0.44333333 | P12: =O12*K12 | R12: 1.33 | S12: =O12*M12 | T12: =O12*N12
A13: Bulls | B13: 0 | C13: 0 | H13: 0 | I13: 0 | L13: =B13+C13-H13 | M13: =L13-B13 | N13: =C13 | O13: 0 | P13: =O13*K13 | R13: 0 | S13: =O13*M13 | T13: =O13*N13
A14: Cows | B14: 2 | C14: 0 | H14: 0 | I14: 0 | L14: =B14+C14-H14 | M14: =L14-B14 | N14: =C14 | O14: 0 | P14: =O14*K14 | R14: 0 | S14: =O14*M14 | T14: =O14*N14
A15: Steers | B15: 2 | C15: 0 | H15: 1 | I15: 0 | L15: =B15+C15-H15 | M15: =L15-B15 | N15: =C15 | O15: 0 | P15: =O15*K15 | R15: 0 | S15: =O15*M15 | T15: =O15*N15
A16: Bullocks | B16: 2 | C16: 0 | H16: 0 | I16: 0 | L16: =B16+C16-H16 | M16: =L16-B16 | N16: =C16 | O16: 0 | P16: =O16*K16 | R16: 0 | S16: =O16*M16 | T16: =O16*N16
... A20: Rams | B20: 9 | C20: 0 | H20: 1 | I20: 0 | L20: =B20+C20-H20 | M20: =L20-B20 | N20: =C20 | O20: 0 | P20: =O20*K20 | R20: 0 | S20: =O20*M20 | T20: =O20*N20
A21: Ewes | B21: 315 | C21: 0 | H21: 55 | I21: 18 | L21: =B21+C21-H21 | M21: =L21-B21 | N21: =C21 | O21: 0.067818182 | P21: =O21*K21 | Q21: 0 | R21: 3.73 | S21: =O21*M21 | T21: =O21*N21
A22: Hoggs | B22: 196 | C22: 0 | H22: 0 | I22: 5 | L22: =B22+C22-H22 | M22: =L22-B22 | N22: =C22 | O22: 0 | P22: =O22*K22 | R22: 0 | S22: =O22*M22 | T22: =O22*N22
A23: Lambs | B23: 204 | C23: 269 | H23: 16 | I23: 21 | L23: =B23+C23-H23 | M23: =L23-B23 | N23: =C23 | O23: 0.033125 | P23: =O23*K23 | R23: 0.53 | S23: =O23*M23 | T23: =O23*N23
A24: Boars | B24: 0 | C24: 0 | H24: 0 | I24: 0 | L24: =B24+C24-H24 | M24: =L24-B24 | N24: =C24 | O24: 0 | P24: =O24*K24 | R24: 0 | S24: =O24*M24 | T24: =O24*N24
A25: Sows | B25: 0 | C25: 0 | H25: 0 | I25: 0 | L25: =B25+C25-H25 | M25: =L25-B25 | N25: =C25 | O25: 0 | P25: =O25*K25 | R25: 0 | S25: =O25*M25 | T25: =O25*N25
A26: Pigs | B26: 0 | C26: 0 | H26: 0 | I26: 0 | L26: =B26+C26-H26 | M26: =L26-B26 | N26: =C26 | O26: 0 | P26: =O26*K26 | R26: 0 | S26: =O26*M26 | T26: =O26*N26
A27: Hoggets | B27: 0 | C27: 0 | H27: 0 | I27: 0 | L27: =B27+C27-H27 | M27: =L27-B27 | N27: =C27 | O27: 0 | P27: =O27*K27 | R27: 0 | S27: =O27*M27 | T27: =O27*N27
A28: Piglets | B28: 0 | C28: 0 | H28: 0 | I28: 0 | L28: =B28+C28-H28 | M28: =L28-B28 | N28: =C28 | O28: 0 | P28: =O28*K28 | R28: 0 | S28: =O28*M28 | T28: =O28*N28
A29: Swans | B29: 0 | C29: 0 | H29: 0 | I29: 0 | L29: =B29+C29-H29 | M29: =L29-B29 | N29: =C29 | O29: 0 | P29: =O29*K29 | R29: 0 | S29: =O29*M29 | T29: =O29*N29
A30: Peacocks | B30: 0 | C30: 0 | H30: 0 | I30: 0 | L30: =B30+C30-H30 | M30: =L30-B30 | N30: =C30 | O30: 0 | P30: =O30*K30 | R30: 0 | S30: =O30*M30 | T30: =O30*N30
A31: Total Value
A34: Wool | B34: 0 | C34: 0 | H34: 0 | I34: 0
A35: Coarse wool | B35: 0 | C35: 0 | H35: 0 | I35: 0
A36: Lamb's wool | B36: 0 | C36: 0 | H36: 0 | I36: 0
A37: Wool locks | B37: 0 | C37: 0 | H37: 0 | I37: 0
A38: Wool sold at shearing | B38: 0 | C38: 0 | H38: 0 | I38: 0
A39: Total wool | B39: 0 | C39: 0 | H39: 0 | I39: 0
B40: 0 | C40: 0 | H40: 0 | I40: 0
B41: 0 | C41: 0 | H41: 0 | I41: 0
A42: Hides | B42: 0 | C42: 0 | H42: 0 | I42: 0
A43: Ox hides | B43: 0 | C43: 0 | H43: 0 | I43: 0
A44: Mare | B44: 0 | C44: 0 | H44: 0 | I44: 0
A45: Steer | B45: 0 | C45: 0 | H45: 0 | I45: 0
A46: calves | B46: 2 | C46: 2 | H46: 0 | I46: 0
...

Sheet raw data
A1: Heading | B1: Sentence | C1: Total in Pounds | D1: Pounds | E1: Shillings | F1: Pence | G1: Corn | H1: Total Quarters Except 1 | I1: Total Bushels Except 1 | J1: Total Corn Cross-Check | K1: Total Corn Manorial Account | L1: Corn Quantity Error | M1: Quarters 1 | N1: Bushels 1 | O1: Quarters 2 | P1: Bushels 2 | Q1: Quarters 3 | R1: Bushels 3 | S1: shilling a quarter 1 | T1: pence a quarter 1 | U1: shilling a quarter 2 | V1: pence a quarter 2 | W1: shilling a quarter 3 | X1: pence a quarter 3 | Y1: shilling a quarter 4 | Z1: pence a quarter 4 | AA1: shilling a bushel 1 | AB1: pence a bushel 1 | AC1: shilling a bushel 2 | AD1: pence a bushel 2 | AE1: shilling a bushel 3 | AF1: pence a bushel 3 | AG1: shilling a bushel 4 | AH1: pence a bushel 4
A2: arrears | B2: john algar', reeve there, answers for 10 shilling 3pence of arrears from his last account of the preceding year. | C2: 0.51 | D2: 0 | E2: 10 | F2: 3 | H2: 0 | I2: 0 | J2: 0 | K2: 0 | L2: 0 | M2: 0 | N2: 0
A3: arrears | B3: total, 10 shilling 3pence. | C3: 0.51 | D3: 0 | E3: 10 | F3: 3 | H3: 0 | I3: 0 | J3: 0 | K3: 0 | L3: 0 | M3: 0 | N3: 0
A4: rents | B4: and for £12 7 shilling 8pence for all rents of assize, or £3 1 shilling 11pence at each of the terms of christmas, easter (23 march), the nativity of st john the baptist (24 june) and michaelmas (29 september). | C4: 12.38 | D4: 12 | E4: 7 | F4: 8 | H4: 0 | I4: 0 | J4: 0 | K4: 0 | L4: 0 | M4: 0 | N4: 0
A5: rents | B5: total, £12 7 shilling 8pence. | C5: 12.38 | D5: 12 | E5: 7 | F5: 8 | H5: 0 | I5: 0 | J5: 0 | K5: 0 | L5: 0 | M5: 0 | N5: 0
A6: quittances of rent | B6: in quittance of rent of 1 reeve for the year 4 shilling. | C6: 0.2 | D6: 0 | E6: 4 | F6: 0 | H6: 0 | I6: 0 | J6: 0 | K6: 0 | L6: 0 | M6: 0 | N6: 0
A7: quittances of rent | B7: 1 shepherd of ewes, nothing this year, because he has the lord's livery as made clear elsewhere. | C7: 0 | D7: 0 | E7: 0 | F7: 0 | H7: 0 | I7: 0 | J7: 0 | K7: 0 | L7: 0 | M7: 0 | N7: 0
A8: quittances of rent | B8: total, 4 shilling. | C8: 0.2 | D8: 0 | E8: 4 | F8: 0 | H8: 0 | I8: 0 | J8: 0 | K8: 0 | L8: 0 | M8: 0 | N8: 0
A9: defaults of rent | B9: in default of 1 plot of land which formerly belonged to the vicar of bishopstone 6pence. | C9: 0.03 | D9: 0 | E9: 0 | F9: 6 | H9: 0 | I9: 0 | J9: 0 | K9: 0 | L9: 0 | M9: 0 | N9: 0
A10: defaults of rent | B10: 1 virgate of land formerly of john salisbury in netton because in the lord's hands, 4 shilling 6pence for the year. | C10: 0.23 | D10: 0 | E10: 4 | F10: 6 | H10: 0 | I10: 0 | J10: 0 | K10: 0 | L10: 0 | M10: 0 | N10: 0
A11: defaults of rent | B11: 1 half-virgate of land formerly of gunnora burgeys, 1 half-virgate of land formerly of adam berewyke, 1 half-virgate of land formerly of richard dryvere, 1 half-virgate of land formerly of john holm', 1 half-virgate of land formerly of john salisbury, 1 half-virgate formerly of william hardyng', 1 half-virgate of land formerly of robert cryor' and 1 half-virgate of land formerly of john deyman' in bishopstone because in the lord's hands, £1 2 shilling for the year, or 2 shilling 9pence for each half-virgate. | C11: 1.1 | D11: 1 | E11: 2 | F11: 0 | H11: 0 | I11: 0 | J11: 0 | K11: 0 | L11: 0 | M11: 0 | N11: 0
A12: defaults of rent | B12: the holding formerly of andrew vicar' of bishopstone there because in the lord's hands, 5 shilling for the year. | C12: 0.25 | D12: 0 | E12: 5 | F12: 0 | H12: 0 | I12: 0 | J12: 0 | K12: 0 | L12: 0 | M12: 0 | N12: 0
A13: defaults of rent | B13: total, £1 12 shilling. | C13: 1.6 | D13: 1 | E13: 12 | F13: 0 | H13: 0 | I13: 0 | J13: 0 | K13: 0 | L13: 0 | M13: 0 | N13: 0
... A63: sale of pasture | B63: total, £1 14 shilling 6pence. | C63: 1.72 | D63: 1 | E63: 14 | F63: 6 | H63: 0 | I63: 0 | J63: 0 | K63: 0 | L63: 0 | M63: 0 | N63: 0
A64: sale of corn | B64: and for £17 16 shilling 3.75pence from 36 quarters 6.5 bushels of wheat sold, at 10 shilling a quarters for 25 quarters per mutuum, and 9 shilling a quarters for 11 quarters 6.5 bushels in the market. | C64: 17.82 | D64: 17 | E64: 16 | F64: 3.75 | G64: wheat | H64: 36 | I64: 6.5 | J64: 36.81 | K64: 36.81 | L64: 0 | M64: 36 | N64: 6.5 | O64: 25 | P64: 0 | Q64: 11 | R64: 6.5 | S64: 10 | T64: 0 | U64: 9 | V64: 0
A65: sale of corn | B65: £1 4 shilling from 4 quarters of curall sold. | C65: 1.2 | D65: 1 | E65: 4 | F65: 0 | G65: curall | H65: 4 | I65: 0 | J65: 4 | K65: 4 | L65: 0 | M65: 4 | N65: 0
A66: sale of corn | B66: £11 8 shilling 9pence from 38 quarters 1 bushels of barley sold per mutuum, at 6 shilling a quarters. | C66: 11.44 | D66: 11 | E66: 8 | F66: 9 | G66: barley | H66: 38 | I66: 1 | J66: 38.12 | K66: 38.12 | L66: 0 | M66: 38 | N66: 1 | S66: 6 | T66: 0
A67: sale of corn | B67: 15 shilling 5pence from 4 quarters 5 bushels of oats sold per mutuum, at 3 shilling 4pence a quarters. | C67: 0.77 | D67: 0 | E67: 15 | F67: 5 | G67: oats | H67: 4 | I67: 5 | J67: 4.62 | K67: 4.62 | L67: 0 | M67: 4 | N67: 5 | S67: 3 | T67: 4
A68: sale of corn | B68: 14 shilling from 2 quarters 5 bushels of peas sold, at 5 shilling 4pence a quarters. | C68: 0.72 | D68: 0 | E68: 14 | F68: 4 | G68: peas | H68: 2 | I68: 5 | J68: 2.62 | K68: 2.62 | L68: 0 | M68: 2 | N68: 5 | S68: 5 | T68: 4
A69: sale of corn | B69: 17 shilling 6pence from 3 quarters 3 bushels' of vetches sold, at 5 shilling a quarters. | C69: 0.88 | D69: 0 | E69: 17 | F69: 6 | G69: vetches | H69: 3 | I69: 3 | J69: 3.38 | K69: 3.38 | L69: 0 | M69: 3 | N69: 3 | S69: 5 | T69: 0
A70: sale of corn | B70: total, £32 15 shilling 11.75pence. | C70: 32.8 | D70: 32 | E70: 15 | F70: 11.75 | H70: 0 | I70: 0 | J70: 0 | K70: 0 | L70: 0 | M70: 0 | N70: 0
A71: sale of stock | B71: and for £1 6 shilling 8pence from 2 kebb oxen sold. | C71: 1.33 | D71: 1 | E71: 6 | F71: 8 | H71: 0 | I71: 0 | J71: 0 | K71: 0 | L71: 0 | M71: 0 | N71: 0
A72: sale of stock | B72: 8 shilling from 1 feeble ox sold. | C72: 0.4 | D72: 0 | E72: 8 | F72: 0 | H72: 0 | I72: 0 | J72: 0 | K72: 0 | L72: 0 | M72: 0 | N72: 0
A73: sale of stock | B73: 7 shilling from 1 steer sold because feeble and useless for the lord's stock. | C73: 0.35 | D73: 0 | E73: 7 | F73: 0 | H73: 0 | I73: 0 | J73: 0 | K73: 0 | L73: 0 | M73: 0 | N73: 0
A74: sale of stock | B74: £2 18 shilling 4pence from 35 kebb wethers sold before shearing, at 1 shilling 8pence each. | C74: 2.92 | D74: 2 | E74: 18 | F74: 4 | H74: 0 | I74: 0 | J74: 0 | K74: 0 | L74: 0 | M74: 0 | N74: 0
A75: sale of stock | B75: £3 14 shilling 8pence from 1 ram and 55 kebb ewes sold before shearing, at 1 shilling 4pence each. | C75: 3.73 | D75: 3 | E75: 14 | F75: 8 | H75: 0 | I75: 0 | J75: 0 | K75: 0 | L75: 0 | M75: 0 | N75: 0
A76: sale of stock | B76: 10 shilling from 16 lambs removed from stock and sold before shearing, at 7.5pence each. | C76: 0.53 | D76: 0 | E76: 10 | F76: 7.5 | H76: 0 | I76: 0 | J76: 0 | K76: 0 | L76: 0 | M76: 0 | N76: 0
A77: sale of stock | B77: 7 shilling 4pence from 22 geese sold, at 4pence each. | C77: 0.37 | D77: 0 | E77: 7 | F77: 4 | H77: 0 | I77: 0 | J77: 0 | K77: 0 | L77: 0 | M77: 0 | N77: 0
A78: sale of stock | B78: 8 shilling from 24 capons sold, at 4pence each. | C78: 0.42 | D78: 0 | E78: 8 | F78: 4 | H78: 0 | I78: 0 | J78: 0 | K78: 0 | L78: 0 | M78: 0 | N78: 0
A79: sale of stock | B79: total, £10.. | C79: 10 | D79: 10 | E79: 0 | F79: 0 | H79: 0 | I79: 0 | J79: 0 | K79: 0 | L79: 0 | M79: 0 | N79: 0
A80: entry fines | B80: and for 3 shilling from the tithing of bishopstone at the tourn of martinmas. | C80: 0.15 | D80: 0 | E80: 3 | F80: 0 | H80: 0 | I80: 0 | J80: 0 | K80: 0 | L80: 0 | M80: 0 | N80: 0
A81: entry fines | B81: 3 shilling from the tithing of flamston for similar. | C81: 0.15 | D81: 0 | E81: 3 | F81: 0 | H81: 0 | I81: 0 | J81: 0 | K81: 0 | L81: 0 | M81: 0 | N81: 0
... A145: cost of buildings | B145: total, 15 shilling. | C145: 0.75 | D145: 0 | E145: 15 | F145: 0 | H145: 0 | I145: 0 | J145: 0 | K145: 0 | L145: 0 | M145: 0 | N145: 0
A146: threshing and winnowing | B146: in threshing 49 quarters 1 bushels of wheat and 4 quarters of curall by piece-work 13 shilling 3pence, at 3pence a quarters. | C146: 0.66 | D146: 0 | E146: 13 | F146: 3 | G146: wheat, curall | H146: 4 | I146: 1 | J146: 4.12 | K146: 49.12 | L146: -45 | M146: 49 | N146: 1 | O146: 4 | P146: 0
A147: threshing and winnowing | B147: threshing 106 quarters 1 bushels of barley by piece-work 17 shilling 8.25pence, at 2pence a quarters. | C147: 0.88 | D147: 0 | E147: 17 | F147: 8.25 | G147: barley | H147: 106 | I147: 1 | J147: 106.12 | K147: 106.12 | L147: 0 | M147: 106 | N147: 1
A148: threshing and winnowing | B148: threshing 20 quarters 4 bushels of oats by piece-work 2 shilling 6.75pence, at 1.5pence a quarters. | C148: 0.13 | D148: 0 | E148: 2 | F148: 6.75 | G148: oats | H148: 20 | I148: 4 | J148: 20.5 | K148: 20.5 | L148: 0 | M148: 20 | N148: 4
A149: threshing and winnowing | B149: winnowing all the aforesaid corn by piece-work, both that threshed by piece-work and by the manorial servants, which made 191 quarters 3 bushels, 3 shilling 11.75pence, at 1pence per 4 quarters. | C149: 0.2 | D149: 0 | E149: 3 | F149: 11.75 | H149: 4 | I149: 3 | J149: 4.38 | K149: 191.38 | L149: -187 | M149: 191 | N149: 3 | O149: 4 | P149: 0
A150: threshing and winnowing | B150: total, £1 17 shilling 5.5pence. | C150: 1.87 | D150: 1 | E150: 17 | F150: 5.5 | H150: 0 | I150: 0 | J150: 0 | K150: 0 | L150: 0 | M150: 0 | N150: 0
A151: mowing the meadows | B151: in customary payment for the mowing of the lord's meadow 8pence. | C151: 0.03 | D151: 0 | E151: 0 | F151: 8 | H151: 0 | I151: 0 | J151: 0 | K151: 0 | L151: 0 | M151: 0 | N151: 0
A152: mowing the meadows | B152: customary payment. | C152: 0 | D152: 0 | E152: 0 | F152: 0 | H152: 0 | I152: 0 | J152: 0 | K152: 0 | L152: 0 | M152: 0 | N152: 0
...

Sheet Receipts
A1: BISHOPSTONE RECEIPTS
A2: Heading | B2: £ | C2: s | D2: d | F2: Total in £ | G2: Error | H2: Notes | I2: Own notes
A3: Arrears | B3: 0 | C3: 10 | D3: 3 | F3: 0.51 | H3: John Algar', reeve there, answers for 10 shilling 3pence of arrears from his last account of the preceding year.
A4: Arrears | B4: 0 | C4: 10 | D4: 3 | F4: 0.51 | H4: Total, 10 shilling 3pence.
A5: Arrears total | F5: 0.51 | G5: 0 | H5: Total
A7: Rents | B7: 12 | C7: 7 | D7: 8 | F7: 12.38 | H7: And for £12 7 shilling 8pence for all rents of assize, or £3 1 shilling 11pence at each of the terms of Christmas, Easter (23 March), the Nativity of St John the Baptist (24 June) and Michaelmas (29 September).
A8: Rents | B8: 12 | C8: 7 | D8: 8 | F8: 12.38 | H8: Total, £12 7 shilling 8pence.
A9: Rents total | F9: 12.38 | G9: 0 | H9: Total
A11: Defaults of rent | B11: 0 | C11: 0 | D11: 6 | F11: 0.03 | H11: In default of 1 plot of land which formerly belonged to the vicar of Bishopstone 6pence.
A12: Defaults of rent | B12: 0 | C12: 4 | D12: 6 | F12: 0.23 | H12: 1 virgate of land formerly of John Salisbury in Netton because in the lord's hands, 4 shilling 6pence for the year.
A13: Defaults of rent | B13: 1 | C13: 2 | D13: 0 | F13: 1.1 | H13: 1 half-virgate of land formerly of Gunnora Burgeys, 1 half-virgate of land formerly of Adam Berewyke, 1 half-virgate of land formerly of Richard Dryvere, 1 half-virgate of land formerly of John Holm', 1 half-virgate of land formerly of John Salisbury, 1 half-virgate formerly of William Hardyng', 1 half-virgate of land formerly of Robert Cryor' and 1 half-virgate of land formerly of John Deyman' in Bishopstone because in the lord's hands, £1 2 shilling for the year, or 2 shilling 9pence for each half-virgate.
A14: Defaults of rent | B14: 0 | C14: 5 | D14: 0 | F14: 0.25 | H14: the holding formerly of Andrew Vicar' of Bishopstone there because in the lord's hands, 5 shilling for the year.
A15: Defaults of rent | B15: 1 | C15: 12 | D15: 0 | F15: 1.6 | H15: Total, £1 12 shilling.
A16: Defaults of rent total | F16: 1.61 | G16: 0.01 | H16: Total
A18: Total of quittances and defaults of rent | B18: 1 | C18: 16 | D18: 0 | F18: 1.8 | H18: Total of quittances and defaults of rent, £1 16 shilling.
A19: Total of quittances and defaults of rent | B19: 10 | C19: 11 | D19: 8 | F19: 10.58 | H19: Total of rents remaining clear, £10 11 shilling 8pence.
A20: Total of quittances and defaults of rent total | F20: 12.38 | G20: 0 | H20: Total
A22: Issues of the manor | B22: 0 | C22: 3 | D22: 1 | F22: 0.15 | H22: And for 3 shilling from the pannage of pigs at Martinmas, at 1pence a pig over a year old, and .5pence below.
A23: Issues of the manor | B23: 0 | C23: 1 | D23: 9.25 | F23: 0.09 | H23: 1 shilling 9.25pence from the agistment of oxen, cows and 2-year old bullocks, at 2.5pence an ox and 1.25pence a bullock.
A24: Issues of the manor | B24: 0 | C24: 1 | D24: 5.5 | F24: 0.07 | H24: 1 shilling 5.5pence from the herbage of sheep in the lord's fold this year.
A25: Issues of the manor | B25: 0 | C25: 1 | D25: 6.75 | F25: 0.08 | H25: 1 shilling 6.75pence from the herbage of oxen, cows and bullocks at Hockday this year.
A26: Issues of the manor | B26: 0 | C26: 0 | D26: 0 | F26: 0 | H26: nothing from the sale of old hay this year.
A27: Issues of the manor | B27: 4 | C27: 15 | D27: 0 | F27: 4.75 | H27: £4 15 shilling from new hay sold this year.
A28: Issues of the manor | B28: 0 | C28: 4 | D28: 8 | F28: 0.23 | H28: 4 shilling 8pence from the residue of Peter's pence.
A29: Issues of the manor | B29: 0 | C29: 0 | D29: 6 | F29: 0.03 | H29: 6pence from 3 lb of wool locks sold.
A30: Issues of the manor | B30: 0 | C30: 5 | D30: 0 | F30: 0.25 | H30: 5 shilling from the milking of 2 cows.
A31: Issues of the manor | B31: 0 | C31: 0 | D31: 0 | F31: 0 | H31: nothing from the milking of the ewes this year because they were not in milk.
A32: Issues of the manor | B32: 0 | C32: 4 | D32: 8 | F32: 0.23 | H32: 4 shilling 8pence from the woolskins sold of 10 wethers, 10 ewes and 4 hoggs in murrain before shearing, at 3pence a skin of wethers, 2pence of ewes and 1.5pence of hoggs.
A33: Issues of the manor | B33: 0 | C33: 1 | D33: 2 | F33: 0.06 | H33: 1 shilling 2pence from the bare skins sold of 7 wethers and 7 ewes in murrain after shearing, at 1pence a skin.
... A45: Issues of the manor | B45: 8 | C45: 16 | D45: 1 | F45: 8.8 | H45: Total, £8 16 shilling 1pence.
A46: Issues of the manor total | F46: 8.79 | G46: -0.01 | H46: Total
A48: Sale of corn | B48: 17 | C48: 16 | D48: 3.75 | F48: 17.82 | H48: And for £17 16 shilling 3.75pence from 36 quarters 6.5 bushels of wheat sold, at 10 shilling a qr for 25 quarters per mutuum, and 9 shilling a qr for 11 quarters 6.5 bushels in the market.
A49: Sale of corn | B49: 1 | C49: 4 | D49: 0 | F49: 1.2 | H49: £1 4 shilling from 4 quarters of curall sold.
A50: Sale of corn | B50: 11 | C50: 8 | D50: 9 | F50: 11.44 | H50: £11 8 shilling 9pence from 38 quarters 1 bushels of barley sold per mutuum, at 6 shilling a qr.
A51: Sale of corn | B51: 0 | C51: 15 | D51: 5 | F51: 0.77 | H51: 15 shilling 5pence from 4 quarters 5 bushels of oats sold per mutuum, at 3 shilling 4pence a qr.
A52: Sale of corn | B52: 0 | C52: 14 | D52: 4 | F52: 0.72 | H52: 14 shilling from 2 quarters 5 bushels of peas sold, at 5 shilling 4pence a qr.
A53: Sale of corn | B53: 0 | C53: 17 | D53: 6 | F53: 0.88 | H53: 17 shilling 6pence from 3 quarters 3 bushels' of vetches sold, at 5 shilling a qr.
A54: Sale of corn | B54: 32 | C54: 15 | D54: 11.75 | F54: 32.8 | H54: Total, £32 15 shilling 11.75pence.
A55: Sale of corn total | F55: 32.83 | G55: 0.03 | H55: Total
A57: Sale of stock | B57: 1 | C57: 6 | D57: 8 | F57: 1.33 | H57: And for £1 6 shilling 8pence from 2 kebb oxen sold.
...

Sheet Stock
A1: Heading | B1: Sentence | C1: Quarters 1 | D1: Bushels 1 | E1: stock | F1: inherited stock | G1: added | H1: murrain | I1: sold
A2: Vetches | B2: Total | C2: 0 | D2: 0
A3: Stock | B3: Plough-horses: 2 remain. | C3: 0 | D3: 0 | E3: Plough-horses | F3: 2
A4: Stock | B4: Oxen: 19 remain. | C4: 0 | D4: 0 | E4: Oxen | F4: 19
A5: Stock | B5: 1 added from steers below. | C5: 0 | D5: 0 | E5: Oxen
A6: Stock | B6: 2 bought within. | C6: 0 | D6: 0 | E6: Oxen | G6: 2
A7: Stock | B7: Total, 22. 3 sold within. | C7: 0 | D7: 0 | E7: Oxen | I7: 3
A8: Stock | B8: 19 remain. | C8: 0 | D8: 0 | E8: Oxen
A9: Stock | B9: Cows: 2 remain. | C9: 0 | D9: 0 | E9: Cows | F9: 2
A10: Stock | B10: Steers: 2 remain from the bullocks. | C10: 0 | D10: 0 | E10: Steers | F10: 2
A11: Stock | B11: Total, 2. 1 added above to oxen. | C11: 0 | D11: 0 | E11: Steers
A12: Stock | B12: 1 sold within because useless for the lord's stock. | C12: 0 | D12: 0 | E12: Steers | I12: 1
A13: Stock | B13: Total as before. | C13: 0 | D13: 0 | E13: Steers
A14: Stock | B14: None remain. | C14: 0 | D14: 0 | E14: Steers
A15: Stock | B15: Bullocks: 2 remain from the yearlings. | C15: 0 | D15: 0 | E15: Bullocks | F15: 2
A16: Stock | B16: 2 remain. | C16: 0 | D16: 0 | E16: Bullocks
A17: Stock | B17: Yearlings: 2 remain from the calves. | C17: 0 | D17: 0 | E17: Yearlings | F17: 2
A18: Stock | B18: 2 remain. | C18: 0 | D18: 0 | E18: Yearlings
A19: Stock | B19: Calves: 2 from the offspring of the said cows. | C19: 0 | D19: 0 | E19: Calves | G19: 2
A20: Stock | B20: 2 remain. | C20: 0 | D20: 0 | E20: Calves | F20: 2
A21: Stock | B21: Wethers: 354 remain. | C21: 0 | D21: 0 | E21: Wethers | F21: 354
A22: Stock | B22: 101 added from hoggs below after shearing. | C22: 0 | D22: 0 | E22: Wethers
A23: Stock | B23: Total, 455. 11 in murrain before shearing, 7 after shearing. | C23: 0 | D23: 0 | E23: Wethers | H23: 11
A24: Stock | B24: 2 in customary payment to the customary tenants after shearing for mowing the lord's meadow. | C24: 0 | D24: 0 | E24: Wethers
A25: Stock | B25: 35 kebbs sold within before shearing. | C25: 0 | D25: 0 | E25: Wethers | I25: 35
A26: Stock | B26: Total, 55. 400 remain. | C26: 0 | D26: 0 | E26: Wethers
A27: Stock | B27: Rams: 9 remain. | C27: 0 | D27: 0 | E27: Rams | F27: 9
A28: Stock | B28: Total, 9. 1 sold within before shearing. | C28: 0 | D28: 0 | E28: Rams | I28: 1
A29: Stock | B29: 8 remain. | C29: 0 | D29: 0 | E29: Rams
A30: Stock | B30: Ewes: 315 remain. | C30: 0 | D30: 0 | E30: Ewes | F30: 315
A31: Stock | B31: 90 added from hoggs below after shearing. | C31: 0 | D31: 0 | E31: Ewes
A32: Stock | B32: 1 from the heriot of Walter Pynnok' before shearing. | C32: 0 | D32: 0 | E32: Ewes
A33: Stock | B33: 1 from the heriot of John Godishalfe after shearing. | C33: 0 | D33: 0 | E33: Ewes
A34: Stock | B34: Total, 407. 11 in murrain before shearing and lambing. | C34: 0 | D34: 0 | E34: Ewes | H34: 11
A35: Stock | B35: 7 in murrain after shearing. | C35: 0 | D35: 0 | E35: Ewes | H35: 7
A36: Stock | B36: 55 kebbs sold within before shearing. | C36: 0 | D36: 0 | E36: Ewes | I36: 55
A37: Stock | B37: Total, 73. 334 remain. | C37: 0 | D37: 0 | E37: Ewes
A38: Stock | B38: Hoggs: 196 remain from the lambs. | C38: 0 | D38: 0 | E38: Hoggs | F38: 196
A39: Stock | B39: Total, 196. 5 in murrain before shearing. | C39: 0 | D39: 0 | E39: Hoggs | H39: 5
A40: Stock | B40: 101 added above to wethers and 90 to ewes after shearing. | C40: 0 | D40: 0 | E40: Hoggs
...

Sheet Overview

Sheet Issues of the Mills

Sheet Prices

Sheet Labour Rents

Sheet not needed

Sheet Issues of the Grange raw
A1: Heading | B1: Sentence | C1: Quarters 1_x | D1: Bushels 1_x | E1: Sown Quarters | F1: Sown Bushels | G1: Sown Total Quarters | H1: Bought in Quarters | I1: Bought in Bushels | J1: Bought in Total Quarters | K1: Tithe Quarters | L1: Tithe Bushels | M1: Tithe Total Quarters | N1: Manorial servants & livestock Quarters | O1: Manorial servants & livestock Bushels | P1: Manorial servants & livestock Total Quarters | Q1: Sold Quarters | R1: Sold Bushels | S1: Sold Total Quarters | T1: Account Quarters | U1: Account Bushels | V1: Account Total Quarters | W1: bought only | X1: Total Quarters Except 1 | Y1: Total Bushels Except 1 | Z1: Total Corn Cross-Check | AA1: Total Corn Manorial Account | AB1: Corn Quantity Error | AC1: Quarters 1_y | AD1: Bushels 1_y | AE1: Quarters 2 | AF1: Bushels 2 | AG1: Quarters 3 | AH1: Bushels 3 | AI1: Total Bought Quarters
A2: total of all allowances and cash deliveries | B2: total | C2: 0 | D2: 0 | E2: 0 | F2: 0 | G2: 0 | H2: 0 | I2: 0 | J2: 0 | K2: 0 | L2: 0 | M2: 0 | N2: 0 | O2: 0 | P2: 0 | Q2: 0 | R2: 0 | S2: 0 | T2: 0 | U2: 0 | V2: 0 | W2: 0 | AI2: 0
A3: wheat | B3: john algare, reeve there, answers for 49 quarters 1 bushels of wheat from the whole issue of the grange, threshed by piece-work. | C3: 0 | D3: 0 | E3: 0 | F3: 0 | G3: 0 | H3: 0 | I3: 0 | J3: 0 | K3: 0 | L3: 0 | M3: 0 | N3: 0 | O3: 0 | P3: 0 | Q3: 0 | R3: 0 | S3: 0 | T3: 49 | U3: 1 | V3: 49.12 | W3: 0 | X3: 49 | Y3: 1 | Z3: 49.12 | AA3: 49.12 | AB3: 0 | AC3: 49 | AD3: 1 | AI3: 0
A4: wheat | B4: 4 quarters by estimation in sheaves in 4 acres, of which 1 is for the reeve, 1 for the men of croucheston and netton, 1 for the men of bishopstone, and 1 for all the manorial servants of the curia. | C4: 0 | D4: 0 | E4: 0 | F4: 0 | G4: 0 | H4: 0 | I4: 0 | J4: 0 | K4: 0 | L4: 0 | M4: 0 | N4: 0 | O4: 0 | P4: 0 | Q4: 0 | R4: 0 | S4: 0 | T4: 0 | U4: 0 | V4: 0 | W4: 0 | X4: 4 | Y4: 0 | Z4: 4 | AA4: 4 | AB4: 0 | AC4: 4 | AD4: 0 | AI4: 0
A5: wheat | B5: 5 quarters 3 bushels surcharged so that he answers for a 5-fold yield.. | C5: 0 | D5: 0 | E5: 0 | F5: 0 | G5: 0 | H5: 0 | I5: 0 | J5: 0 | K5: 0 | L5: 0 | M5: 0 | N5: 0 | O5: 0 | P5: 0 | Q5: 0 | R5: 0 | S5: 0 | T5: 0 | U5: 0 | V5: 0 | W5: 0 | X5: 5 | Y5: 3 | Z5: 5.38 | AA5: 5.38 | AB5: 0 | AC5: 5 | AD5: 3 | AI5: 0
A6: wheat | B6: total, 58 quarters 4 bushels. | C6: 0 | D6: 0 | E6: 0 | F6: 0 | G6: 0 | H6: 0 | I6: 0 | J6: 0 | K6: 0 | L6: 0 | M6: 0 | N6: 0 | O6: 0 | P6: 0 | Q6: 0 | R6: 0 | S6: 0 | T6: 0 | U6: 0 | V6: 0 | W6: 0 | X6: 58 | Y6: 4 | Z6: 58.5 | AA6: 58.5 | AB6: 0 | AC6: 58 | AD6: 4 | AI6: 0
A7: wheat | B7: sown over 48 acres, 12 quarters. | C7: 0 | D7: 0 | E7: 12 | F7: 0 | G7: 12 | H7: 0 | I7: 0 | J7: 0 | K7: 0 | L7: 0 | M7: 0 | N7: 0 | O7: 0 | P7: 0 | Q7: 0 | R7: 0 | S7: 0 | T7: 0 | U7: 0 | V7: 0 | W7: 0 | X7: 12 | Y7: 0 | Z7: 12 | AA7: 12 | AB7: 0 | AC7: 12 | AD7: 0 | AI7: 0
A8: wheat | B8: that is, 2 bushels an acre. | C8: 0 | D8: 0 | E8: 0 | F8: 0 | G8: 0 | H8: 0 | I8: 0 | J8: 0 | K8: 0 | L8: 0 | M8: 0 | N8: 0 | O8: 0 | P8: 0 | Q8: 0 | R8: 0 | S8: 0 | T8: 0 | U8: 0 | V8: 0 | W8: 0 | X8: 0 | Y8: 2 | Z8: 0.25 | AA8: 0.25 | AB8: 0 | AC8: 0 | AD8: 2 | AI8: 0
A9: wheat | B9: given to the customary tenants in 4 acres which they receive according to custom, 4 quarters. | C9: 0 | D9: 0 | E9: 0 | F9: 0 | G9: 0 | H9: 0 | I9: 0 | J9: 0 | K9: 0 | L9: 0 | M9: 0 | N9: 0 | O9: 0 | P9: 0 | Q9: 0 | R9: 0 | S9: 0 | T9: 0 | U9: 0 | V9: 0 | W9: 0 | X9: 4 | Y9: 0 | Z9: 4 | AA9: 4 | AB9: 0 | AC9: 4 | AD9: 0 | AI9: 0
A10: wheat | B10: provision of the steward at the tourns of martinmas and hockday, by 2 sealed bills, 2.5 bushels. | C10: 0 | D10: 0 | E10: 0 | F10: 0 | G10: 0 | H10: 0 | I10: 0 | J10: 0 | K10: 0 | L10: 0 | M10: 0 | N10: 0 | O10: 0 | P10: 0 | Q10: 0 | R10: 0 | S10: 0 | T10: 0 | U10: 0 | V10: 0 | W10: 0 | X10: 0 | Y10: 2.5 | Z10: 0.31 | AA10: 0.31 | AB10: 0 | AC10: 0 | AD10: 2.5 | AI10: 0
A11: wheat | B11: sold within, 36 quarters 6.5 bushels. | C11: 0 | D11: 0 | E11: 0 | F11: 0 | G11: 0 | H11: 0 | I11: 0 | J11: 0 | K11: 0 | L11: 0 | M11: 0 | N11: 0 | O11: 0 | P11: 0 | Q11: 36 | R11: 6.5 | S11: 36.81 | T11: 0 | U11: 0 | V11: 0 | W11: 0 | X11: 36 | Y11: 6.5 | Z11: 36.81 | AA11: 36.81 | AB11: 0 | AC11: 36 | AD11: 6.5 | AI11: 0
A12: wheat | B12: sold at the audit, 6 quarters' 3 bushels for £2 17 shilling 3pence. | C12: 0 | D12: 0 | E12: 0 | F12: 0 | G12: 0 | H12: 0 | I12: 0 | J12: 0 | K12: 0 | L12: 0 | M12: 0 | N12: 0 | O12: 0 | P12: 0 | Q12: 6 | R12: 0 | S12: 6 | T12: 0 | U12: 0 | V12: 0 | W12: 0 | X12: 6 | Y12: 3 | Z12: 6.38 | AA12: 6 | AB12: 0.38 | AC12: 6 | AD12: 0 | AE12: 0 | AF12: 3 | AI12: 0
A13: wheat | B13: total as before. | C13: 0 | D13: 0 | E13: 0 | F13: 0 | G13: 0 | H13: 0 | I13: 0 | J13: 0 | K13: 0 | L13: 0 | M13: 0 | N13: 0 | O13: 0 | P13: 0 | Q13: 0 | R13: 0 | S13: 0 | T13: 0 | U13: 0 | V13: 0 | W13: 0 | X13: 0 | Y13: 0 | Z13: 0 | AA13: 0 | AB13: 0 | AC13: 0 | AD13: 0 | AI13: 0
A14: wheat | B14: it balances. | C14: 0 | D14: 0 | E14: 0 | F14: 0 | G14: 0 | H14: 0 | I14: 0 | J14: 0 | K14: 0 | L14: 0 | M14: 0 | N14: 0 | O14: 0 | P14: 0 | Q14: 0 | R14: 0 | S14: 0 | T14: 0 | U14: 0 | V14: 0 | W14: 0 | X14: 0 | Y14: 0 | Z14: 0 | AA14: 0 | AB14: 0 | AC14: 0 | AD14: 0 | AI14: 0
A15: wheat | B15: total | C15: 0 | D15: 0 | E15: 0 | F15: 0 | G15: 0 | H15: 0 | I15: 0 | J15: 0 | K15: 0 | L15: 0 | M15: 0 | N15: 0 | O15: 0 | P15: 0 | Q15: 0 | R15: 0 | S15: 0 | T15: 0 | U15: 0 | V15: 0 | W15: 0 | AI15: 0
A16: curall | B16: and for 4 quarters of curall from the issue of the said wheat, threshed by piece-work. | C16: 0 | D16: 0 | E16: 0 | F16: 0 | G16: 0 | H16: 0 | I16: 0 | J16: 0 | K16: 0 | L16: 0 | M16: 0 | N16: 0 | O16: 0 | P16: 0 | Q16: 0 | R16: 0 | S16: 0 | T16: 0 | U16: 0 | V16: 0 | W16: 0 | X16: 4 | Y16: 0 | Z16: 4 | AA16: 4 | AB16: 0 | AC16: 4 | AD16: 0 | AI16: 0
A17: curall | B17: sold within. | C17: 0 | D17: 0 | E17: 0 | F17: 0 | G17: 0 | H17: 0 | I17: 0 | J17: 0 | K17: 0 | L17: 0 | M17: 0 | N17: 0 | O17: 0 | P17: 0 | Q17: 0 | R17: 0 | S17: 0 | T17: 0 | U17: 0 | V17: 0 | W17: 0 | X17: 0 | Y17: 0 | Z17: 0 | AA17: 0 | AB17: 0 | AC17: 0 | AD17: 0 | AI17: 0
A18: curall | B18: none remains. | C18: 0 | D18: 0 | E18: 0 | F18: 0 | G18: 0 | H18: 0 | I18: 0 | J18: 0 | K18: 0 | L18: 0 | M18: 0 | N18: 0 | O18: 0 | P18: 0 | Q18: 0 | R18: 0 | S18: 0 | T18: 0 | U18: 0 | V18: 0 | W18: 0 | X18: 0 | Y18: 0 | Z18: 0 | AA18: 0 | AB18: 0 | AC18: 0 | AD18: 0 | AI18: 0
A19: curall | B19: total | C19: 0 | D19: 0 | E19: 0 | F19: 0 | G19: 0 | H19: 0 | I19: 0 | J19: 0 | K19: 0 | L19: 0 | M19: 0 | N19: 0 | O19: 0 | P19: 0 | Q19: 0 | R19: 0 | S19: 0 | T19: 0 | U19: 0 | V19: 0 | W19: 0 | AI19: 0
A20: barley | B20: and for 106 quarters 1 bushels of barley from the whole issue of the grange, threshed by piece¬work. | C20: 0 | D20: 0 | E20: 0 | F20: 0 | G20: 0 | H20: 0 | I20: 0 | J20: 0 | K20: 0 | L20: 0 | M20: 0 | N20: 0 | O20: 0 | P20: 0 | Q20: 0 | R20: 0 | S20: 0 | T20: 106 | U20: 1 | V20: 106.12 | W20: 0 | X20: 106 | Y20: 1 | Z20: 106.12 | AA20: 106.12 | AB20: 0 | AC20: 106 | AD20: 1 | AI20: 0
A21: barley | B21: 1 qr 2 bushels by estimation in sheaves given for carrying the lord's corn at harvest-time. | C21: 0 | D21: 0 | E21: 0 | F21: 0 | G21: 0 | H21: 0 | I21: 0 | J21: 0 | K21: 0 | L21: 0 | M21: 0 | N21: 0 | O21: 0 | P21: 0 | Q21: 0 | R21: 0 | S21: 0 | T21: 0 | U21: 0 | V21: 0 | W21: 0 | AI21: 0
A22: barley | B22: no corn given to the customary tenants for reaping this year because they were paid for their reaping service as made clear within. | C22: 0 | D22: 0 | E22: 0 | F22: 0 | G22: 0 | H22: 0 | I22: 0 | J22: 0 | K22: 0 | L22: 0 | M22: 0 | N22: 0 | O22: 0 | P22: 0 | Q22: 0 | R22: 0 | S22: 0 | T22: 0 | U22: 0 | V22: 0 | W22: 0 | X22: 0 | Y22: 0 | Z22: 0 | AA22: 0 | AB22: 0 | AC22: 0 | AD22: 0 | AI22: 0
A23: barley | B23: 11 quarters 3 bushels surcharged so that he answers for a 5.5-fold yield.. | C23: 0 | D23: 0 | E23: 0 | F23: 0 | G23: 0 | H23: 0 | I23: 0 | J23: 0 | K23: 0 | L23: 0 | M23: 0 | N23: 0 | O23: 0 | P23: 0 | Q23: 0 | R23: 0 | S23: 0 | T23: 0 | U23: 0 | V23: 0 | W23: 0 | X23: 11 | Y23: 3 | Z23: 11.38 | AA23: 11.38 | AB23: 0 | AC23: 11 | AD23: 3 | AI23: 0
A24: barley | B24: total, 118 quarters 6 bushels. | C24: 0 | D24: 0 | E24: 0 | F24: 0 | G24: 0 | H24: 0 | I24: 0 | J24: 0 | K24: 0 | L24: 0 | M24: 0 | N24: 0 | O24: 0 | P24: 0 | Q24: 0 | R24: 0 | S24: 0 | T24: 0 | U24: 0 | V24: 0 | W24: 0 | X24: 118 | Y24: 6 | Z24: 118.75 | AA24: 118.75 | AB24: 0 | AC24: 118 | AD24: 6 | AI24: 0
A25: barley | B25: sown over 42 acres, 21 quarters. | C25: 0 | D25: 0 | E25: 21 | F25: 0 | G25: 21 | H25: 0 | I25: 0 | J25: 0 | K25: 0 | L25: 0 | M25: 0 | N25: 0 | O25: 0 | P25: 0 | Q25: 0 | R25: 0 | S25: 0 | T25: 0 | U25: 0 | V25: 0 | W25: 0 | X25: 21 | Y25: 0 | Z25: 21 | AA25: 21 | AB25: 0 | AC25: 21 | AD25: 0 | AI25: 0
A26: barley | B26: that is, 4 bushels an acre. | C26: 0 | D26: 0 | E26: 0 | F26: 0 | G26: 0 | H26: 0 | I26: 0 | J26: 0 | K26: 0 | L26: 0 | M26: 0 | N26: 0 | O26: 0 | P26: 0 | Q26: 0 | R26: 0 | S26: 0 | T26: 0 | U26: 0 | V26: 0 | W26: 0 | X26: 0 | Y26: 4 | Z26: 0.5 | AA26: 0.5 | AB26: 0 | AC26: 0 | AD26: 4 | AI26: 0
A27: barley | B27: given for carrying the lord's corn at harvest-time, 1 qr 2 bushels by estimation in sheaves. | C27: 0 | D27: 0 | E27: 0 | F27: 0 | G27: 0 | H27: 0 | I27: 0 | J27: 0 | K27: 0 | L27: 0 | M27: 0 | N27: 0 | O27: 0 | P27: 0 | Q27: 0 | R27: 0 | S27: 0 | T27: 0 | U27: 0 | V27: 0 | W27: 0 | AI27: 0
A28: barley | B28: provision of 3 harvest boon-works, 2 quarters. | C28: 0 | D28: 0 | E28: 0 | F28: 0 | G28: 0 | H28: 0 | I28: 0 | J28: 0 | K28: 0 | L28: 0 | M28: 0 | N28: 0 | O28: 0 | P28: 0 | Q28: 0 | R28: 0 | S28: 0 | T28: 0 | U28: 0 | V28: 0 | W28: 0 | X28: 2 | Y28: 0 | Z28: 2 | AA28: 2 | AB28: 0 | AC28: 2 | AD28: 0 | AI28: 0
A29: barley | B29: liveries of the manorial servants below, 45 quarters.. | C29: 0 | D29: 0 | E29: 0 | F29: 0 | G29: 0 | H29: 0 | I29: 0 | J29: 0 | K29: 0 | L29: 0 | M29: 0 | N29: 0 | O29: 0 | P29: 0 | Q29: 0 | R29: 0 | S29: 0 | T29: 0 | U29: 0 | V29: 0 | W29: 0 | X29: 45 | Y29: 0 | Z29: 45 | AA29: 45 | AB29: 0 | AC29: 45 | AD29: 0 | AI29: 0
A30: barley | B30: sold within, 38 quarters 1 bushels. | C30: 0 | D30: 0 | E30: 0 | F30: 0 | G30: 0 | H30: 0 | I30: 0 | J30: 0 | K30: 0 | L30: 0 | M30: 0 | N30: 0 | O30: 0 | P30: 0 | Q30: 38 | R30: 1 | S30: 38.12 | T30: 0 | U30: 0 | V30: 0 | W30: 0 | X30: 38 | Y30: 1 | Z30: 38.12 | AA30: 38.12 | AB30: 0 | AC30: 38 | AD30: 1 | AI30: 0
A31: barley | B31: sold at the audit, 11 quarters 3 bushels for £3 8 shilling 3pence. | C31: 0 | D31: 0 | E31: 0 | F31: 0 | G31: 0 | H31: 0 | I31: 0 | J31: 0 | K31: 0 | L31: 0 | M31: 0 | N31: 0 | O31: 0 | P31: 0 | Q31: 11 | R31: 3 | S31: 11.38 | T31: 0 | U31: 0 | V31: 0 | W31: 0 | X31: 11 | Y31: 3 | Z31: 11.38 | AA31: 11.38 | AB31: 0 | AC31: 11 | AD31: 3 | AI31: 0
A32: barley | B32: total as before. | C32: 0 | D32: 0 | E32: 0 | F32: 0 | G32: 0 | H32: 0 | I32: 0 | J32: 0 | K32: 0 | L32: 0 | M32: 0 | N32: 0 | O32: 0 | P32: 0 | Q32: 0 | R32: 0 | S32: 0 | T32: 0 | U32: 0 | V32: 0 | W32: 0 | X32: 0 | Y32: 0 | Z32: 0 | AA32: 0 | AB32: 0 | AC32: 0 | AD32: 0 | AI32: 0
A33: barley | B33: it balances. | C33: 0 | D33: 0 | E33: 0 | F33: 0 | G33: 0 | H33: 0 | I33: 0 | J33: 0 | K33: 0 | L33: 0 | M33: 0 | N33: 0 | O33: 0 | P33: 0 | Q33: 0 | R33: 0 | S33: 0 | T33: 0 | U33: 0 | V33: 0 | W33: 0 | X33: 0 | Y33: 0 | Z33: 0 | AA33: 0 | AB33: 0 | AC33: 0 | AD33: 0 | AI33: 0
A34: barley | B34: total | C34: 0 | D34: 0 | E34: 0 | F34: 0 | G34: 0 | H34: 0 | I34: 0 | J34: 0 | K34: 0 | L34: 0 | M34: 0 | N34: 0 | O34: 0 | P34: 0 | Q34: 0 | R34: 0 | S34: 0 | T34: 0 | U34: 0 | V34: 0 | W34: 0 | AI34: 0
A35: oats | B35: and for 20 quarters 4 bushels of oats from the whole issue2 of the grange, threshed by piece¬work. | C35: 0 | D35: 0 | E35: 0 | F35: 0 | G35: 0 | H35: 0 | I35: 0 | J35: 0 | K35: 0 | L35: 0 | M35: 0 | N35: 0 | O35: 0 | P35: 0 | Q35: 0 | R35: 0 | S35: 0 | T35: 20 | U35: 4 | V35: 20.5 | W35: 0 | X35: 20 | Y35: 4 | Z35: 20.5 | AA35: 20.5 | AB35: 0 | AC35: 20 | AD35: 4 | AI35: 0
A36: oats | B36: 6 bushels by estimation in sheaves given for carrying the lord's corn at harvest-time. | C36: 0 | D36: 0 | E36: 0 | F36: 0 | G36: 0 | H36: 0 | I36: 0 | J36: 0 | K36: 0 | L36: 0 | M36: 0 | N36: 0 | O36: 0 | P36: 0 | Q36: 0 | R36: 0 | S36: 0 | T36: 0 | U36: 0 | V36: 0 | W36: 0 | X36: 0 | Y36: 6 | Z36: 0.75 | AA36: 0.75 | AB36: 0 | AC36: 0 | AD36: 6 | AI36: 0
A37: oats | B37: no sheaves given for reaping for the aforesaid reason. | C37: 0 | D37: 0 | E37: 0 | F37: 0 | G37: 0 | H37: 0 | I37: 0 | J37: 0 | K37: 0 | L37: 0 | M37: 0 | N37: 0 | O37: 0 | P37: 0 | Q37: 0 | R37: 0 | S37: 0 | T37: 0 | U37: 0 | V37: 0 | W37: 0 | X37: 0 | Y37: 0 | Z37: 0 | AA37: 0 | AB37: 0 | AC37: 0 | AD37: 0 | AI37: 0
A38: oats | B38: 5 quarters 6 bushels surcharged so that he answers for a 3-fold yield.. | C38: 0 | D38: 0 | E38: 0 | F38: 0 | G38: 0 | H38: 0 | I38: 0 | J38: 0 | K38: 0 | L38: 0 | M38: 0 | N38: 0 | O38: 0 | P38: 0 | Q38: 0 | R38: 0 | S38: 0 | T38: 0 | U38: 0 | V38: 0 | W38: 0 | X38: 5 | Y38: 6 | Z38: 5.75 | AA38: 5.75 | AB38: 0 | AC38: 5 | AD38: 6 | AI38: 0
A39: oats | B39: total, 27 quarters. | C39: 0 | D39: 0 | E39: 0 | F39: 0 | G39: 0 | H39: 0 | I39: 0 | J39: 0 | K39: 0 | L39: 0 | M39: 0 | N39: 0 | O39: 0 | P39: 0 | Q39: 0 | R39: 0 | S39: 0 | T39: 0 | U39: 0 | V39: 0 | W39: 0 | X39: 27 | Y39: 0 | Z39: 27 | AA39: 27 | AB39: 0 | AC39: 27 | AD39: 0 | AI39: 0
A40: oats | B40: sown over 20 acres, 10 quarters. | C40: 0 | D40: 0 | E40: 10 | F40: 0 | G40: 10 | H40: 0 | I40: 0 | J40: 0 | K40: 0 | L40: 0 | M40: 0 | N40: 0 | O40: 0 | P40: 0 | Q40: 0 | R40: 0 | S40: 0 | T40: 0 | U40: 0 | V40: 0 | W40: 0 | X40: 10 | Y40: 0 | Z40: 10 | AA40: 10 | AB40: 0 | AC40: 10 | AD40: 0 | AI40: 0
...

Sheet Issues of the Grange
A1: Gross Output | B1: Bought Only Aggregated | C1: Account Quarters | D1: Account Bushels | E1: Account Total Quarters | F1: Bought in Quarters | G1: Bought in Bushels | H1: Total Bought Quarters | I1: Sold Quarters | J1: Sold Bushels | K1: Sold Total Quarters | L1: Total Corn Quantity | M1: Difference Produced+Bought-Sold | N1: Weighted Average Price per Quarter | O1: Non-Weighted Average Price per Quarter | P1: Value of Total Production weighted | Q1: Value of Total Production unweighted
A2: total of all allowances and cash deliveries | B2: 0 | C2: 0 | D2: 0 | E2: 0 | F2: 0 | G2: 0 | H2: 0 | I2: 0 | J2: 0 | K2: 0 | L2: 0 | M2: 0
A3: wheat | B3: 0 | C3: 49 | D3: 1 | E3: 49.12 | F3: 0 | G3: 0 | H3: 0 | I3: 36 | J3: 6.5 | K3: 36.81 | L3: 49.12 | M3: 12.31 | N3: 0.48 | O3: 0.47 | P3: 23.77 | Q3: 23.33
A4: curall | B4: 0 | C4: 0 | D4: 0 | E4: 0 | F4: 0 | G4: 0 | H4: 0 | I4: 0 | J4: 0 | K4: 0 | L4: 0 | M4: 0 | N4: 0.3 | O4: 0.3 | P4: 0 | Q4: 0
A5: barley | B5: 0 | C5: 106 | D5: 1 | E5: 106.12 | F5: 0 | G5: 0 | H5: 0 | I5: 38 | J5: 3 | K5: 38.12 | L5: 106.12 | M5: 68 | N5: 0.3 | O5: 0.3 | P5: 31.84 | Q5: 31.84
A6: oats | B6: 0 | C6: 20 | D6: 4 | E6: 20.5 | F6: 0 | G6: 0 | H6: 0 | I6: 5 | J6: 6 | K6: 5.75 | L6: 20.5 | M6: 14.75 | N6: 0.17 | O6: 0.17 | P6: 3.42 | Q6: 3.42
A7: peas | B7: 0 | C7: 0 | D7: 0 | E7: 0 | F7: 0 | G7: 0 | H7: 0 | I7: 2 | J7: 5 | K7: 2.62 | L7: 0 | M7: -2.62 | N7: 0.27 | O7: 0.27 | P7: 0 | Q7: 0
A8: vetches | B8: 0 | C8: 0 | D8: 0 | E8: 0 | F8: 0 | G8: 0 | H8: 0 | I8: 3 | J8: 4 | K8: 3.5 | L8: 0 | M8: -3.5 | N8: 0.25 | O8: 0.25 | P8: 0 | Q8: 0
A9: Mancorn | B9: 0 | C9: 0 | D9: 0 | E9: 0 | F9: 0 | G9: 0 | H9: 0 | I9: 0 | J9: 0 | K9: 0 | L9: 0 | M9: 0
A10: Maslin | B10: 0 | C10: 0 | D10: 0 | E10: 0 | F10: 0 | G10: 0 | H10: 0 | I10: 0 | J10: 0 | K10: 0 | L10: 0 | M10: 0
A11: First-grade malt | B11: 0 | C11: 0 | D11: 0 | E11: 0 | F11: 0 | G11: 0 | H11: 0 | I11: 0 | J11: 0 | K11: 0 | L11: 0 | M11: 0
A12: Second-grade malt | B12: 0 | C12: 0 | D12: 0 | E12: 0 | F12: 0 | G12: 0 | H12: 0 | I12: 0 | J12: 0 | K12: 0 | L12: 0 | M12: 0
A13: Oatmeal | B13: 0 | C13: 0 | D13: 0 | E13: 0 | F13: 0 | G13: 0 | H13: 0 | I13: 0 | J13: 0 | K13: 0 | L13: 0 | M13: 0
A14: Rye | B14: 0 | C14: 0 | D14: 0 | E14: 0 | F14: 0 | G14: 0 | H14: 0 | I14: 0 | J14: 0 | K14: 0 | L14: 0 | M14: 0
A15: Dredge | B15: 0 | C15: 0 | D15: 0 | E15: 0 | F15: 0 | G15: 0 | H15: 0 | I15: 0 | J15: 0 | K15: 0 | L15: 0 | M15: 0
A16: Malt | B16: 0 | C16: 0 | D16: 0 | E16: 0 | F16: 0 | G16: 0 | H16: 0 | I16: 0 | J16: 0 | K16: 0 | L16: 0 | M16: 0
A17: Meal | B17: 0 | C17: 0 | D17: 0 | E17: 0 | F17: 0 | G17: 0 | H17: 0 | I17: 0 | J17: 0 | K17: 0 | L17: 0 | M17: 0

Sheet Sale of Corn Prices
A1: Heading | B1: Sentence | C1: Total in Pounds | D1: Pounds | E1: Shillings | F1: Pence | G1: Corn | H1: Total Quarters Except 1 | I1: Total Bushels Except 1 | J1: Total Corn Cross-Check | K1: Total Corn Manorial Account | L1: Corn Quantity Error | M1: Quarters 0 | N1: Bushels 0 | O1: shilling a quarter 1 | P1: pence a quarter 1 | Q1: Quarters 1 | R1: Bushels 1 | S1: shilling a quarter 2 | T1: pence a quarter 2 | U1: Quarters 2 | V1: Bushels 2 | W1: shilling a quarter 3 | X1: pence a quarter 3 | Y1: shilling a quarter 4 | Z1: pence a quarter 4 | AA1: £ a quarter 1 | AB1: £ a quarter 2 | AC1: £ a quarter 3 | AD1: £ a quarter 4 | AE1: Quarters Sold | AF1: Weighted Average Price per Quarter | AG1: Non-Weighted Average Price per Quarter | AH1: Corn lowercase
A2: sale of corn | B2: and for £17 16 shilling 3.75pence from 36 quarters 6.5 bushels of wheat sold, at 10 shilling a quarters for 25 quarters per mutuum, and 9 shilling a quarters for 11 quarters 6.5 bushels in the market. | C2: 17.82 | D2: 17 | E2: 16 | F2: 3.75 | G2: wheat | H2: 36 | I2: 6.5 | J2: 36.81 | K2: 36.81 | L2: 0 | M2: 36 | N2: 6.5 | O2: 10 | P2: 0 | Q2: 25 | R2: 0 | S2: 9 | T2: 0 | U2: 11 | V2: 6.5 | AA2: 0.5 | AB2: 0.45 | AE2: 36.81 | AF2: 0.48 | AG2: 0.47 | AH2: wheat
A3: sale of corn | B3: £1 4 shilling from 4 quarters of curall sold. | C3: 1.2 | D3: 1 | E3: 4 | F3: 0 | G3: curall | H3: 4 | I3: 0 | J3: 4 | K3: 4 | L3: 0 | M3: 4 | N3: 0 | AA3: 0.3 | AE3: 4 | AF3: 0.3 | AG3: 0.3 | AH3: curall
A4: sale of corn | B4: £11 8 shilling 9pence from 38 quarters 1 bushels of barley sold per mutuum, at 6 shilling a quarters. | C4: 11.44 | D4: 11 | E4: 8 | F4: 9 | G4: barley | H4: 38 | I4: 1 | J4: 38.12 | K4: 38.12 | L4: 0 | M4: 38 | N4: 1 | O4: 6 | P4: 0 | AA4: 0.3 | AE4: 38.12 | AF4: 0.3 | AG4: 0.3 | AH4: barley
A5: sale of corn | B5: 15 shilling 5pence from 4 quarters 5 bushels of oats sold per mutuum, at 3 shilling 4pence a quarters. | C5: 0.77 | D5: 0 | E5: 15 | F5: 5 | G5: oats | H5: 4 | I5: 5 | J5: 4.62 | K5: 4.62 | L5: 0 | M5: 4 | N5: 5 | O5: 3 | P5: 4 | AA5: 0.17 | AE5: 4.62 | AF5: 0.17 | AG5: 0.17 | AH5: oats
A6: sale of corn | B6: 14 shilling from 2 quarters 5 bushels of peas sold, at 5 shilling 4pence a quarters. | C6: 0.72 | D6: 0 | E6: 14 | F6: 4 | G6: peas | H6: 2 | I6: 5 | J6: 2.62 | K6: 2.62 | L6: 0 | M6: 2 | N6: 5 | O6: 5 | P6: 4 | AA6: 0.27 | AE6: 2.62 | AF6: 0.27 | AG6: 0.27 | AH6: peas
A7: sale of corn | B7: 17 shilling 6pence from 3 quarters 3 bushels' of vetches sold, at 5 shilling a quarters. | C7: 0.88 | D7: 0 | E7: 17 | F7: 6 | G7: vetches | H7: 3 | I7: 3 | J7: 3.38 | K7: 3.38 | L7: 0 | M7: 3 | N7: 3 | O7: 5 | P7: 0 | AA7: 0.25 | AE7: 3.38 | AF7: 0.25 | AG7: 0.25 | AH7: vetches
A8: sale of corn | B8: total, £32 15 shilling 11.75pence. | C8: 32.8 | D8: 32 | E8: 15 | F8: 11.75 | H8: 0 | I8: 0 | J8: 0 | K8: 0 | L8: 0 | M8: 0 | N8: 0 | AA8: inf | AE8: 0 | AF8: inf | AG8: inf

Sheet Expenses
A1: BISHOPSTONE EXPENSES
A2: Heading | B2: £ | C2: s | D2: d | F2: Total in £ | G2: Error | H2: Notes
A4: Cost of ploughs | B4: 0 | C4: 16 | D4: 0 | F4: 0.8
A5: Cost of ploughs | B5: 0 | C5: 4 | D5: 0 | F5: 0.2
A6: Cost of ploughs | B6: 0 | C6: 0 | D6: 10 | F6: 0.04
A7: Cost of ploughs | B7: 0 | C7: 0 | D7: 6 | F7: 0.03
A8: Cost of ploughs | B8: 0 | C8: 0 | D8: 8 | F8: 0.03
A9: Cost of ploughs | B9: 0 | C9: 1 | D9: 6 | F9: 0.08
A10: Cost of ploughs | B10: 0 | C10: 0 | D10: 6 | F10: 0.03
A11: Cost of ploughs | B11: 0 | C11: 1 | D11: 4 | F11: 0.07
A12: Cost of ploughs | B12: 0 | C12: 6 | D12: 8 | F12: 0.33
A13: Cost of ploughs | B13: 0 | C13: 13 | D13: 4 | F13: 0.67
A14: Cost of ploughs | B14: 0 | C14: 2 | D14: 2 | F14: 0.11
A15: Cost of ploughs | B15: 2 | C15: 7 | D15: 6 | F15: 2.38
A16: Cost of ploughs total | F16: 2.39 | G16: 0.01
A18: Cost of carts | B18: 0 | C18: 0 | D18: 10 | F18: 0.04
A19: Cost of carts | B19: 0 | C19: 0 | D19: 2 | F19: 0.01
A20: Cost of carts | B20: 0 | C20: 0 | D20: 4 | F20: 0.02
A21: Cost of carts | B21: 0 | C21: 0 | D21: 4 | F21: 0.02
A22: Cost of carts | B22: 0 | C22: 0 | D22: 2 | F22: 0.01
A23: Cost of carts | B23: 0 | C23: 3 | D23: 0 | F23: 0.15
A24: Cost of carts | B24: 0 | C24: 6 | D24: 8 | F24: 0.33
A25: Cost of carts | B25: 0 | C25: 11 | D25: 6 | F25: 0.58
A26: Cost of carts total | F26: 0.58 | G26: 0
A28: Purchase of stock | B28: 1 | C28: 6 | D28: 0 | F28: 1.3
A29: Purchase of stock | B29: 1 | C29: 8 | D29: 9 | F29: 1.44
A30: Purchase of stock | B30: 2 | C30: 15 | D30: 5 | F30: 2.77
A31: Purchase of stock total | F31: 2.74 | G31: -0.03
A33: Cost of the dairy | B33: 0 | C33: 1 | D33: 0 | F33: 0.05
A34: Cost of the dairy | B34: 0 | C34: 0 | D34: 2 | F34: 0.01
A35: Cost of the dairy | B35: 0 | C35: 0 | D35: 2 | F35: 0.01
A36: Cost of the dairy | B36: 0 | C36: 2 | D36: 0 | F36: 0.1
A37: Cost of the dairy | B37: 0 | C37: 3 | D37: 4 | F37: 0.17
A38: Cost of the dairy total | F38: 0.17 | G38: 0
A40: Cost of buildings | B40: 0 | C40: 1 | D40: 10 | F40: 0.09
A41: Cost of buildings | B41: 0 | C41: 6 | D41: 10 | F41: 0.34
A42: Cost of buildings | B42: 0 | C42: 1 | D42: 0 | F42: 0.05
A43: Cost of buildings | B43: 0 | C43: 2 | D43: 4 | F43: 0.12
A44: Cost of buildings | B44: 0 | C44: 0 | D44: 5 | F44: 0.02
A45: Cost of buildings | B45: 0 | C45: 1 | D45: 8 | F45: 0.08
...
