Workbook

Sheet Adderbury Overview
A1: ADDERBURY | B1: Total in £ | C1: Error | D1: Note
A2: CASH ACCOUNT
A3: RECEIPTS
A4: Arrears total
A5: Rents of assize total | B5: ='Adderbury Receipts'!F9
A6: Quittances total | B6: ='Adderbury Receipts'!F22
A7: Defaults of rent total | B7: ='Adderbury Receipts'!F27
A8: Defaults of rent through the pestilence total | B8: ='Adderbury Receipts'!F36
A9: Cotlands defaults total | B9: ='Adderbury Receipts'!F45
A10: Cotlands total | B10: ='Adderbury Receipts'!F54
A11: Total of quittances and defaults of rent total | B11: ='Adderbury Receipts'!F56
A12: Total of rents remaining clear total | B12: ='Adderbury Receipts'!F58
A13: Farms total | B13: ='Adderbury Receipts'!F70
A14: Annual recognizances total | B14: ='Adderbury Receipts'!F90
A15: Issues of the Manor total | B15: ='Adderbury Receipts'!F117
A16: Issues of the tenements in the lord's hands total | B16: ='Adderbury Receipts'!F126
A17: Sale of labour services total | B17: ='Adderbury Receipts'!F135
A18: Sale of corn total | B18: ='Adderbury Receipts'!F138
A19: Entry and marriage fines total | B19: ='Adderbury Receipts'!F166
A20: Pleas & perquisites total | B20: ='Adderbury Receipts'!F173
A21: Forfeited chattels total | B21: ='Adderbury Receipts'!F177
A22: Farm of the demesne land total | B22: ='Adderbury Receipts'!F181
A23: Total of all receipts (calculated here) | B23: ='Adderbury Receipts'!F185
A24: Total of all receipts (calculated here) incl arrears
A25: Total recorded in the accounts excl. arrears | B25: ='Adderbury Receipts'!F184 | C25: =B23-B25
A26: Total recorded in the accounts incl. arrears
A29: EXPENSES
A30: Cost of ploughs total
A31: Purchase of corn total
A32: Cost of carts and wagons total
A33: Cost of dairy total
A34: Purchase of stock total
A35: Sheepcote total
A36: Cost of buildings total | B36: ='Adderbury Expenses'!F26
A37: Threshing total
A38: Barley expenses
A39: Expenses of the harvest total
A40: Necessary expenses
A41: Wages of the bailiff | B41: ='Adderbury Expenses'!F30
A42: Steward's expenses total | B42: ='Adderbury Expenses'!F33
...

Sheet Burghclere Stock
A1: BURGHCLERE STOCK ACCOUNT
C3: added | G3: subtracted
A4: Livestock | B4: Inherited stock | C4: added | D4: strays | E4: herbage | F4: churchscot | G4: of which in default | H4: sold | I4: in murrain | J4: accounted for elsewhere | K4: End-period stock | L4: cross-check | M4: stock building | N4: raw production | O4: Unit price (£) | P4: Value of stock (£) at given value | Q4: Value of stock (£) at sales prices | R4: Sales in (£) | S4: Value of stock building (£) | T4: Value of production (£) at sales prices | U4: Details
A5: Cart-horses | B5: 0 | C5: 0 | H5: 0 | I5: 0 | L5: =B5+C5-H5 | M5: =L5-B5 | N5: =C5 | O5: 0 | P5: =O5*K5 | R5: 0 | S5: =O5*M5 | T5: =O5*N5
A6: Mares | B6: 0 | C6: 0 | H6: 0 | I6: 0 | L6: =B6+C6-H6 | M6: =L6-B6 | N6: =C6 | O6: 0 | P6: =O6*K6 | R6: 0 | S6: =O6*M6 | T6: =O6*N6
A7: Plough horses | B7: 0 | C7: 0 | H7: 0 | I7: 0 | L7: =B7+C7-H7 | M7: =L7-B7 | N7: =C7 | O7: 0 | P7: =O7*K7 | R7: 0 | S7: =O7*M7 | T7: =O7*N7
A8: Colts (unspecified years) | B8: 0 | C8: 0 | H8: 0 | I8: 0 | L8: =B8+C8-H8 | M8: =L8-B8 | N8: =C8 | O8: 0 | P8: =O8*K8 | R8: 0 | S8: =O8*M8 | T8: =O8*N8
A9: Colts (2 years) | B9: 0 | C9: 0 | H9: 0 | I9: 0 | L9: =B9+C9-H9 | M9: =L9-B9 | N9: =C9 | O9: 0 | P9: =O9*K9 | R9: 0 | S9: =O9*M9 | T9: =O9*N9
A10: Colts (1 year) | B10: 0 | C10: 0 | H10: 0 | I10: 0 | L10: =B10+C10-H10 | M10: =L10-B10 | N10: =C10 | O10: 0 | P10: =O10*K10 | R10: 0 | S10: =O10*M10 | T10: =O10*N10
A11: Foals | B11: 0 | C11: 0 | H11: 0 | I11: 0 | L11: =B11+C11-H11 | M11: =L11-B11 | N11: =C11 | O11: 0 | P11: =O11*K11 | R11: 0 | S11: =O11*M11 | T11: =O11*N11
A12: Oxen | B12: 23 | C12: 0 | H12: 0 | I12: 0 | L12: =B12+C12-H12 | M12: =L12-B12 | N12: =C12 | O12: 0 | P12: =O12*K12 | R12: 0 | S12: =O12*M12 | T12: =O12*N12
A13: Bulls | B13: 0 | C13: 0 | H13: 0 | I13: 0 | L13: =B13+C13-H13 | M13: =L13-B13 | N13: =C13 | O13: 0 | P13: =O13*K13 | R13: 0 | S13: =O13*M13 | T13: =O13*N13
A14: Cows | B14: 0 | C14: 0 | H14: 0 | I14: 0 | L14: =B14+C14-H14 | M14: =L14-B14 | N14: =C14 | O14: 0 | P14: =O14*K14 | R14: 0 | S14: =O14*M14 | T14: =O14*N14
A15: Steers | B15: 0 | C15: 0 | H15: 0 | I15: 0 | L15: =B15+C15-H15 | M15: =L15-B15 | N15: =C15 | O15: 0 | P15: =O15*K15 | R15: 0 | S15: =O15*M15 | T15: =O15*N15
A16: Bullocks | B16: 0 | C16: 0 | H16: 0 | I16: 0 | L16: =B16+C16-H16 | M16: =L16-B16 | N16: =C16 | O16: 0 | P16: =O16*K16 | R16: 0 | S16: =O16*M16 | T16: =O16*N16
... A20: Rams | B20: 10 | C20: 0 | H20: 0 | I20: 5 | L20: =B20+C20-H20 | M20: =L20-B20 | N20: =C20 | O20: 0 | P20: =O20*K20 | R20: 0 | S20: =O20*M20 | T20: =O20*N20
A21: Ewes | B21: 388 | C21: 0 | H21: 20 | I21: 98 | L21: =B21+C21-H21 | M21: =L21-B21 | N21: =C21 | O21: 0.0475 | P21: =O21*K21 | Q21: 0 | R21: 0.95 | S21: =O21*M21 | T21: =O21*N21
A22: Hoggs | B22: 0 | C22: 196 | H22: 0 | I22: 0 | L22: =B22+C22-H22 | M22: =L22-B22 | N22: =C22 | O22: 0 | P22: =O22*K22 | R22: 0 | S22: =O22*M22 | T22: =O22*N22
A23: Lambs | B23: 0 | C23: 237 | H23: 167 | I23: 52 | L23: =B23+C23-H23 | M23: =L23-B23 | N23: =C23 | O23: 0.053832335 | P23: =O23*K23 | R23: 8.99 | S23: =O23*M23 | T23: =O23*N23
A24: Boars | B24: 0 | C24: 0 | H24: 0 | I24: 0 | L24: =B24+C24-H24 | M24: =L24-B24 | N24: =C24 | O24: 0 | P24: =O24*K24 | R24: 0 | S24: =O24*M24 | T24: =O24*N24
A25: Sows | B25: 0 | C25: 0 | H25: 0 | I25: 0 | L25: =B25+C25-H25 | M25: =L25-B25 | N25: =C25 | O25: 0 | P25: =O25*K25 | R25: 0 | S25: =O25*M25 | T25: =O25*N25
A26: Pigs | B26: 0 | C26: 0 | H26: 0 | I26: 0 | L26: =B26+C26-H26 | M26: =L26-B26 | N26: =C26 | O26: 0 | P26: =O26*K26 | R26: 0 | S26: =O26*M26 | T26: =O26*N26
A27: Hoggets | B27: 0 | C27: 0 | H27: 0 | I27: 0 | L27: =B27+C27-H27 | M27: =L27-B27 | N27: =C27 | O27: 0 | P27: =O27*K27 | R27: 0 | S27: =O27*M27 | T27: =O27*N27
A28: Piglets | B28: 0 | C28: 0 | H28: 0 | I28: 0 | L28: =B28+C28-H28 | M28: =L28-B28 | N28: =C28 | O28: 0 | P28: =O28*K28 | R28: 0 | S28: =O28*M28 | T28: =O28*N28
A29: Swans | B29: 0 | C29: 0 | H29: 0 | I29: 0 | L29: =B29+C29-H29 | M29: =L29-B29 | N29: =C29 | O29: 0 | P29: =O29*K29 | R29: 0 | S29: =O29*M29 | T29: =O29*N29
A30: Peacocks | B30: 0 | C30: 0 | H30: 0 | I30: 0 | L30: =B30+C30-H30 | M30: =L30-B30 | N30: =C30 | O30: 0 | P30: =O30*K30 | R30: 0 | S30: =O30*M30 | T30: =O30*N30
A31: Total Value
A34: Wool | B34: 0 | C34: 0 | H34: 0 | I34: 0
A35: Coarse wool | B35: 0 | C35: 0 | H35: 0 | I35: 0
A36: Lamb's wool | B36: 0 | C36: 0 | H36: 0 | I36: 0
A37: Wool locks | B37: 0 | C37: 0 | H37: 0 | I37: 0
A38: Wool sold at shearing | B38: 0 | C38: 0 | H38: 0 | I38: 0
A39: Total wool | B39: 0 | C39: 0 | H39: 0 | I39: 0
B40: 0 | C40: 0 | H40: 0 | I40: 0
B41: 0 | C41: 0 | H41: 0 | I41: 0
A42: Hides | B42: 0 | C42: 0 | H42: 0 | I42: 0
A43: Ox hides | B43: 0 | C43: 0 | H43: 0 | I43: 0
A44: Mare | B44: 0 | C44: 0 | H44: 0 | I44: 0
A45: Steer | B45: 0 | C45: 0 | H45: 0 | I45: 0
A46: calves | B46: 0 | C46: 0 | H46: 0 | I46: 0
...

Sheet raw data
A1: Heading | B1: Sentence | C1: Total in Pounds | D1: Pounds | E1: Shillings | F1: Pence | G1: Corn | H1: Total Quarters Except 1 | I1: Total Bushels Except 1 | J1: Total Corn Cross-Check | K1: Total Corn Manorial Account | L1: Corn Quantity Error | M1: Quarters 1 | N1: Bushels 1 | O1: Quarters 2 | P1: Bushels 2 | Q1: shilling a quarter 1 | R1: pence a quarter 1 | S1: shilling a quarter 2 | T1: pence a quarter 2 | U1: shilling a quarter 3 | V1: pence a quarter 3 | W1: shilling a quarter 4 | X1: pence a quarter 4 | Y1: shilling a bushel 1 | Z1: pence a bushel 1 | AA1: shilling a bushel 2 | AB1: pence a bushel 2 | AC1: shilling a bushel 3 | AD1: pence a bushel 3 | AE1: shilling a bushel 4 | AF1: pence a bushel 4
A2: burghclere | B2: the account of john seuare and richard le new, fanners, and john haller, collector of rents there, for the sixth year of the translation of henry beaufort', lord bishop of winchester, and the eleventh year of the reign of king henry the fourth. | C2: 0 | D2: 0 | E2: 0 | F2: 0 | H2: 0 | I2: 0 | J2: 0 | K2: 0 | L2: 0 | M2: 0 | N2: 0
A3: arrears | B3: the same answers for £25 15 shilling 7pence of arrears from the last account of the preceding year. | C3: 25.78 | D3: 25 | E3: 15 | F3: 7 | H3: 0 | I3: 0 | J3: 0 | K3: 0 | L3: 0 | M3: 0 | N3: 0
A4: arrears | B4: total, £25 15 shilling 7pence. | C4: 25.78 | D4: 25 | E4: 15 | F4: 7 | H4: 0 | I4: 0 | J4: 0 | K4: 0 | L4: 0 | M4: 0 | N4: 0
A5: rents of assize | B5: and for £2 19 shilling 7pence for all rents of assize there at christmas. | C5: 2.98 | D5: 2 | E5: 19 | F5: 7 | H5: 0 | I5: 0 | J5: 0 | K5: 0 | L5: 0 | M5: 0 | N5: 0
A6: rents of assize | B6: £2 19 shilling 7.25pence at easter (23 march). | C6: 2.98 | D6: 2 | E6: 19 | F6: 7.25 | H6: 0 | I6: 0 | J6: 0 | K6: 0 | L6: 0 | M6: 0 | N6: 0
A7: rents of assize | B7: £2 19 shilling 7.25pence at the nativity of the blessed john the baptist (24 june). | C7: 2.98 | D7: 2 | E7: 19 | F7: 7.25 | H7: 0 | I7: 0 | J7: 0 | K7: 0 | L7: 0 | M7: 0 | N7: 0
A8: rents of assize | B8: £17 8 shilling 10pence at michaelmas (29 september). | C8: 17.44 | D8: 17 | E8: 8 | F8: 10 | H8: 0 | I8: 0 | J8: 0 | K8: 0 | L8: 0 | M8: 0 | N8: 0
A9: rents of assize | B9: 1pence for the increment of rent of john smyth' of whitway for 1 plot of the lord's waste. | C9: 0 | D9: 0 | E9: 0 | F9: 1 | H9: 0 | I9: 0 | J9: 0 | K9: 0 | L9: 0 | M9: 0 | N9: 0
A10: rents of assize | B10: total, £26 7 shilling 8.5pence. | C10: 26.39 | D10: 26 | E10: 7 | F10: 8.5 | H10: 0 | I10: 0 | J10: 0 | K10: 0 | L10: 0 | M10: 0 | N10: 0
A11: quittances of rent | B11: in quittance of rent of 1 reeve, nothing, because there is none. | C11: 0 | D11: 0 | E11: 0 | F11: 0 | H11: 0 | I11: 0 | J11: 0 | K11: 0 | L11: 0 | M11: 0 | N11: 0
A12: quittances of rent | B12: 1 collector of rents for the year 4 shilling 8pence. | C12: 0.23 | D12: 0 | E12: 4 | F12: 8 | H12: 0 | I12: 0 | J12: 0 | K12: 0 | L12: 0 | M12: 0 | N12: 0
A13: quittances of rent | B13: 1 farmer who collects the estreats and makes all the summonses to the court, by fixed agreement made with the steward, 4 shilling 8pence. | C13: 0.23 | D13: 0 | E13: 4 | F13: 8 | H13: 0 | I13: 0 | J13: 0 | K13: 0 | L13: 0 | M13: 0 | N13: 0
... A132: cost of the sheepcote | B132: 4 cart-loads of straw bought for the same 4 shilling. | C132: 0.2 | D132: 0 | E132: 4 | F132: 0 | H132: 0 | I132: 0 | J132: 0 | K132: 0 | L132: 0 | M132: 0 | N132: 0
A133: cost of the sheepcote | B133: carrying the said straw to the sheepcote 1 shilling given to the shepherds for the price of 1 bushels of wheat as a reward made to them by the steward for their assiduous labour 1 shilling 3pence. | C133: 0.06 | D133: 0 | E133: 1 | F133: 3 | G133: wheat | H133: 0 | I133: 1 | J133: 0.12 | K133: 0.12 | L133: 0 | M133: 0 | N133: 1
A134: cost of the sheepcote | B134: total, £1 10 shilling 4pence. | C134: 1.52 | D134: 1 | E134: 10 | F134: 4 | H134: 0 | I134: 0 | J134: 0 | K134: 0 | L134: 0 | M134: 0 | N134: 0
A135: wages | B135: in wages of william fauconer, bailiff, in part payment of his wages, £2 10 shilling, and he takes the rest elsewhere. | C135: 2.5 | D135: 2 | E135: 10 | F135: 0 | H135: 0 | I135: 0 | J135: 0 | K135: 0 | L135: 0 | M135: 0 | N135: 0
A136: wages | B136: total, £2 10 shilling. | C136: 2.5 | D136: 2 | E136: 10 | F136: 0 | H136: 0 | I136: 0 | J136: 0 | K136: 0 | L136: 0 | M136: 0 | N136: 0
A137: necessary expenses | B137: in carrying the wool of this manor to wolvesey this year 1 shilling 8pence. | C137: 0.08 | D137: 0 | E137: 1 | F137: 8 | H137: 0 | I137: 0 | J137: 0 | K137: 0 | L137: 0 | M137: 0 | N137: 0
A138: necessary expenses | B138: making well 48 female hoggs 1 shilling 4pence, at 1pence for each 3.. | C138: 0.07 | D138: 0 | E138: 1 | F138: 4 | H138: 0 | I138: 0 | J138: 0 | K138: 0 | L138: 0 | M138: 0 | N138: 0
A139: necessary expenses | B139: total, 3 shilling. | C139: 0.15 | D139: 0 | E139: 3 | F139: 0 | H139: 0 | I139: 0 | J139: 0 | K139: 0 | L139: 0 | M139: 0 | N139: 0
A140: total of all expenses | B140: total of all expenses, £20 10 shilling. | C140: 20.5 | D140: 20 | E140: 10 | F140: 0 | H140: 0 | I140: 0 | J140: 0 | K140: 0 | L140: 0 | M140: 0 | N140: 0
A141: and he owes | B141: and he owes, £76 6 shilling 5pence. | C141: 76.32 | D141: 76 | E141: 6 | F141: 5 | H141: 0 | I141: 0 | J141: 0 | K141: 0 | L141: 0 | M141: 0 | N141: 0
A142: allowances without writ | B142: in allowance to the same for 16 shilling for various surcharges and disallowances made. | C142: 0.8 | D142: 0 | E142: 16 | F142: 0 | H142: 0 | I142: 0 | J142: 0 | K142: 0 | L142: 0 | M142: 0 | N142: 0
A143: allowances without writ | B143: against him in the present account. | C143: 0 | D143: 0 | E143: 0 | F143: 0 | H143: 0 | I143: 0 | J143: 0 | K143: 0 | L143: 0 | M143: 0 | N143: 0
A144: allowances without writ | B144: total, 16 shilling. | C144: 0.8 | D144: 0 | E144: 16 | F144: 0 | H144: 0 | I144: 0 | J144: 0 | K144: 0 | L144: 0 | M144: 0 | N144: 0
A145: allowances by writ | B145: in allowance to the same for 8 shilling 6pence delivered to john reede, treasurer of the lord's household, as the price of 51 ens for the provision of the said household, just as is 'made clear by the evidence of t hhe same john. | C145: 0.43 | D145: 0 | E145: 8 | F145: 6 | H145: 0 | I145: 0 | J145: 0 | K145: 0 | L145: 0 | M145: 0 | N145: 0
... A153: and thus he owes | B153: and thus he owes, £15 17 shilling 5pence, of which £1 11pence is in the hands of the escheator. | C153: 15.87 | D153: 15 | E153: 17 | F153: 5 | H153: 0 | I153: 0 | J153: 0 | K153: 0 | L153: 0 | M153: 0 | N153: 0
A154: wheat | B154: john seuare and richard le newe, farmers there, answer for 22 quarters of wheat remaining. | C154: 0 | D154: 0 | E154: 0 | F154: 0 | G154: wheat | H154: 22 | I154: 0 | J154: 22 | K154: 22 | L154: 0 | M154: 22 | N154: 0
A155: wheat | B155: total, 22 quarters.. | C155: 0 | D155: 0 | E155: 0 | F155: 0 | H155: 22 | I155: 0 | J155: 22 | K155: 22 | L155: 0 | M155: 22 | N155: 0
A156: wheat | B156: 22 quarters remain, worth 4 shilling a quarters, in the hands of the aforesaid farmers, to be handed back and restored at the end of their term of 7 years, this year being the fourth, or the value of the same at the lord's will. | C156: 0.2 | D156: 0 | E156: 4 | F156: 0 | H156: 22 | I156: 0 | J156: 22 | K156: 22 | L156: 0 | M156: 22 | N156: 0 | Q156: 4 | R156: 0
A157: beremancorn | B157: and for 4 quarters 4 bushels of beremancorn remaining.. | C157: 0 | D157: 0 | E157: 0 | F157: 0 | G157: mancorn | H157: 4 | I157: 4 | J157: 4.5 | K157: 4.5 | L157: 0 | M157: 4 | N157: 4
A158: beremancorn | B158: total, 4 quarters 4 bushels. | C158: 0 | D158: 0 | E158: 0 | F158: 0 | H158: 4 | I158: 4 | J158: 4.5 | K158: 4.5 | L158: 0 | M158: 4 | N158: 4
A159: beremancorn | B159: 4 quarters 4 bushels remain, worth 3 shilling a quarters, in the hands of the aforesaid farmers, to be handed back and restored at the end of the abovesaid term as before. | C159: 0.15 | D159: 0 | E159: 3 | F159: 0 | H159: 4 | I159: 4 | J159: 4.5 | K159: 4.5 | L159: 0 | M159: 4 | N159: 4 | Q159: 3 | R159: 0
A160: barley | B160: and for 16 quarters of barley remaining.. | C160: 0 | D160: 0 | E160: 0 | F160: 0 | G160: barley | H160: 16 | I160: 0 | J160: 16 | K160: 16 | L160: 0 | M160: 16 | N160: 0
A161: barley | B161: total, 16 quarters.. | C161: 0 | D161: 0 | E161: 0 | F161: 0 | H161: 16 | I161: 0 | J161: 16 | K161: 16 | L161: 0 | M161: 16 | N161: 0
A162: barley | B162: 16 quarters remain, worth 3 shilling a quarters, in the hands of the aforesaid farmers, to be handed back and restored as before. | C162: 0.15 | D162: 0 | E162: 3 | F162: 0 | H162: 16 | I162: 0 | J162: 16 | K162: 16 | L162: 0 | M162: 16 | N162: 0 | Q162: 3 | R162: 0
A163: pulses | B163: and for 6 bushels of pulses remaining.. | C163: 0 | D163: 0 | E163: 0 | F163: 0 | H163: 0 | I163: 6 | J163: 0.75 | K163: 0.75 | L163: 0 | M163: 0 | N163: 6
A164: pulses | B164: total, 6 bushels. | C164: 0 | D164: 0 | E164: 0 | F164: 0 | H164: 0 | I164: 6 | J164: 0.75 | K164: 0.75 | L164: 0 | M164: 0 | N164: 6
A165: pulses | B165: 6 bushels remain, worth 3 shilling, in the hands of the aforesaid farmers, to be handed back and restored as before. | C165: 0.15 | D165: 0 | E165: 3 | F165: 0 | H165: 0 | I165: 6 | J165: 0.75 | K165: 0.75 | L165: 0 | M165: 0 | N165: 6
...

Sheet Receipts
A1: BURGHCLERE RECEIPTS
A2: Heading | B2: £ | C2: s | D2: d | F2: Total in £ | G2: Error | H2: Notes | I2: Own notes
A3: Arrears | B3: 25 | C3: 15 | D3: 7 | F3: 25.78 | H3: The same answers for £25 15 shilling 7pence of arrears from the last account of the preceding year.
A4: Arrears | B4: 25 | C4: 15 | D4: 7 | F4: 25.78 | H4: Total, £25 15 shilling 7pence.
A5: Arrears total | F5: 25.78 | G5: 0 | H5: Total
A7: Rents of assize | B7: 2 | C7: 19 | D7: 7 | F7: 2.98 | H7: And for £2 19 shilling 7pence for all rents of assize there at Christmas.
A8: Rents of assize | B8: 2 | C8: 19 | D8: 7.25 | F8: 2.98 | H8: £2 19 shilling 7.25pence at Easter (23 March).
A9: Rents of assize | B9: 2 | C9: 19 | D9: 7.25 | F9: 2.98 | H9: £2 19 shilling 7.25pence at the Nativity of the blessed John the Baptist (24 June).
A10: Rents of assize | B10: 17 | C10: 8 | D10: 10 | F10: 17.44 | H10: £17 8 shilling 10pence at Michaelmas (29 September).
A11: Rents of assize | B11: 0 | C11: 0 | D11: 1 | F11: 0 | H11: 1pence for the increment of rent of John Smyth' of Whitway for 1 plot of the lord's waste.
A12: Rents of assize | B12: 26 | C12: 7 | D12: 8.5 | F12: 26.39 | H12: Total, £26 7 shilling 8.5pence.
A13: Rents of assize total | F13: 26.38 | G13: -0.01 | H13: Total
A15: Defaults of rent | B15: 1 | C15: 7 | D15: 0 | F15: 1.35 | H15: In default of 335 acres of land drawn into demesne, £1 7 shilling for the year.
A16: Defaults of rent | B16: 0 | C16: 3 | D16: 0 | F16: 0.15 | H16: the land of Aillewyn drawn into demesne, 3 shilling for the year.
A17: Defaults of rent | B17: 0 | C17: 1 | D17: 8 | F17: 0.08 | H17: 10 acres of land of Roger Manypetite drawn into demesne, 1 shilling 8pence for the year.
A18: Defaults of rent | B18: 0 | C18: 2 | D18: 6 | F18: 0.12 | H18: the land of Osmond Doust drawn into demesne, 2 shilling 6pence for the year.
A19: Defaults of rent | B19: 0 | C19: 1 | D19: 8 | F19: 0.08 | H19: the land of Simon Clerc' drawn into demesne, 1 shilling 8pence for the year.
A20: Defaults of rent | B20: 0 | C20: 1 | D20: 0 | F20: 0.05 | H20: the land of Aillewyn drawn into demesne, 1 shilling for the year.
A21: Defaults of rent | B21: 0 | C21: 0 | D21: 0 | F21: 0 | H21: 1 plot of purpresture formerly of John le Newe drawn into the park of Highclere, Id. this year.
A22: Defaults of rent | B22: 0 | C22: 0 | D22: 3 | F22: 0.01 | H22: .5 acre of purpresture formerly of Richard le Whyte drawn into the aforesaid park 3pence.
A23: Defaults of rent | B23: 0 | C23: 1 | D23: 0 | F23: 0.05 | H23: the land of Osmond Doust drawn into demesne, 1 shilling for the year.
A24: Defaults of rent | B24: 0 | C24: 8 | D24: 0 | F24: 0.4 | H24: 1 plot of purpresture formerly of John le Eir', containing 20 acres of land, drawn into the aforesaid park 8 shilling.
A25: Defaults of rent | B25: 2 | C25: 6 | D25: 2 | F25: 2.31 | H25: Total, £2 6 shilling 2pence.
A26: Defaults of rent total | F26: 2.29 | G26: -0.02 | H26: Total
A28: Total of quittances and defaults of rent | B28: 6 | C28: 0 | D28: 10.5 | F28: 6.04 | H28: Total of quittances and defaults of rent, £6 10.5pence.
A29: Total of quittances and defaults of rent total | F29: 6.04 | G29: 0 | H29: Total
A31: Total of rents remaining clear | B31: 20 | C31: 6 | D31: 10 | F31: 20.34 | H31: Total of rents remaining clear, £20 6 shilling 10pence.
A32: Total of rents remaining clear total | F32: 20.34 | G32: 0 | H32: Total
A34: Issues of the manor | B34: 0 | C34: 6 | D34: 1 | F34: 0.3 | H34: And for 6 shilling from the pannage of the pigs of the customary tenants at Martinmas, that is, for 50 pigs, at 1pence each, and 44 piglets, at .5pence each, and this through Henry, lord bishop of Winchester, because henceforth the men of Wolstret will only give 1pence instead of 2pence, which they and the other tenants were accustomed to pay for the common of Garston', which same common is let for a fixed rent.
A35: Issues of the manor | B35: 0 | C35: 0 | D35: 0 | F35: 0 | H35: nothing from the pasturage in Hareberd' and Eldehull' and the pasturage in Lovecombe because it is grazed by the lord's sheep.
A36: Issues of the manor | B36: 0 | C36: 5 | D36: 0 | F36: 0.25 | H36: 5 shilling from the men of Earlstone at Michaelmas according to custom for herbage.
A37: Issues of the manor | B37: 0 | C37: 0 | D37: 0 | F37: 0 | H37: nothing from the issue of the quarry this year.
A38: Issues of the manor | B38: 0 | C38: 3 | D38: 0 | F38: 0.15 | H38: 3 shilling from the men of Adbury for not making charcoal at Christmas.
A39: Issues of the manor | B39: 0 | C39: 3 | D39: 0 | F39: 0.15 | H39: 3 shilling from the free tenants in Earlstone for release from ploughing at Michaelmas, because the villeins will plough at the winter sowing and fallow.
A40: Issues of the manor | B40: 0 | C40: 2 | D40: 0 | F40: 0.1 | H40: 2 shilling from honey according to custom at Michaelmas for land which John Gerard' holds.
A41: Issues of the manor | B41: 0 | C41: 18 | D41: 6 | F41: 0.93 | H41: 18 shilling 6pence from the woolskins sold of 12 wethers and 93 rams and ewes in murrain before shearing, at 3pence a skin of wethers, and 2pence of rams and ewes.
A42: Issues of the manor | B42: 0 | C42: 1 | D42: 0 | F42: 0.05 | H42: 1 shilling from the bare skins sold of 12 wethers and ewes in murrain after shearing.
A43: Issues of the manor | B43: 0 | C43: 1 | D43: 11 | F43: 0.1 | H43: 1 shilling 11pence from the skins sold of 46 lambs in murrain before weaning.
A44: Issues of the manor | B44: 0 | C44: 0 | D44: 5 | F44: 0.02 | H44: .5pence from the rotted skin of 1 lamb in murrain after tithe and before weaning.
A45: Issues of the manor | B45: 0 | C45: 0 | D45: 0 | F45: 0 | H45: nothing from the sale of geese and capons this year because they were handed over with the farm.
...

Sheet Stock
A1: Heading | B1: Sentence | C1: Quarters 1 | D1: Bushels 1 | E1: stock | F1: inherited stock | G1: added | H1: murrain | I1: sold
A2: Oats | B2: Total | C2: 0 | D2: 0
A3: Stock | B3: Horses: 3 remain. | C3: 0 | D3: 0 | F3: 3
A4: Stock | B4: Total, 3. 3 remain, worth 6 shilling 8pence each, in the hands of the said farmers, to be handed back and restored at the end of the aforesaid term or the value of the same at the choice of the lord. | C4: 0 | D4: 0
A5: Stock | B5: Oxen: 23 remain. | C5: 0 | D5: 0 | E5: Oxen | F5: 23
A6: Stock | B6: Total, 23. 23 remain, worth 12 shilling each, in the hands of the said farmers, to be handed back at the end of the aforesaid term or the value of the same at the choice of the lord. | C6: 0 | D6: 0 | E6: Oxen
A7: Stock | B7: Cows: 1 from the heriot of William Baynton'. | C7: 0 | D7: 0 | E7: Cows
A8: Stock | B8: sold within. | C8: 0 | D8: 0 | E8: Cows
A9: Stock | B9: none remain. | C9: 0 | D9: 0 | E9: Cows
A10: Stock | B10: Wethers: 282 remain. | C10: 0 | D10: 0 | E10: Wethers | F10: 282
A11: Stock | B11: 67 added from hoggs below after shearing. | C11: 0 | D11: 0 | E11: Wethers
A12: Stock | B12: Total, 349. 13 in murrain before shearing and 4 after shearing. | C12: 0 | D12: 0 | E12: Wethers | H12: 13
A13: Stock | B13: 19 kebbs sold within before shearing. | C13: 0 | D13: 0 | E13: Wethers | I13: 19
A14: Stock | B14: Total, 36. 313 remain. | C14: 0 | D14: 0 | E14: Wethers
A15: Stock | B15: Rams: 10 remain. | C15: 0 | D15: 0 | E15: Rams | F15: 10
A16: Stock | B16: 5 added from hoggs below after shearing. | C16: 0 | D16: 0 | E16: Rams
A17: Stock | B17: Total, 15. 5 in murrain before shearing. | C17: 0 | D17: 0 | E17: Rams | H17: 5
A18: Stock | B18: Total, 5. 10 remain. | C18: 0 | D18: 0 | E18: Rams
A19: Stock | B19: Ewes: 388 remain. | C19: 0 | D19: 0 | E19: Ewes | F19: 388
A20: Stock | B20: 124 added from hoggs below after shearing. | C20: 0 | D20: 0 | E20: Ewes
A21: Stock | B21: 1 from the heriot of Richard Norman before shearing. | C21: 0 | D21: 0 | E21: Ewes
A22: Stock | B22: Total, 513. 98 in murrain before shearing and lambing and 8 after shearing. | C22: 0 | D22: 0 | E22: Ewes | H22: 98
A23: Stock | B23: 19 kebbs sold within after shearing. | C23: 0 | D23: 0 | E23: Ewes | I23: 19
A24: Stock | B24: 1 from the heriot sold before shearing. | C24: 0 | D24: 0 | E24: Ewes | I24: 1
A25: Stock | B25: Total, 125.' 387 remain. | C25: 0 | D25: 0 | E25: Ewes
A26: Stock | B26: Hoggs: 196 bought before shearing from the reeve of Ecchinswell. | C26: 0 | D26: 0 | E26: Hoggs | G26: 196
A27: Stock | B27: Total, 196. 67 added above to wethers after shearing, 5 to rams and 124 to ewes. | C27: 0 | D27: 0 | E27: Hoggs
A28: Stock | B28: Total as before. | C28: 0 | D28: 0 | E28: Hoggs
A29: Stock | B29: None remain. | C29: 0 | D29: 0 | E29: Hoggs
A30: Stock | B30: Lambs: 237 offspring this year and not more because 98 ewes died before lambing and 53 were sterile this year. | C30: 0 | D30: 0 | E30: Lambs | G30: 237
A31: Stock | B31: Total, 237. 51 in murrain before weaning. | C31: 0 | D31: 0 | E31: Lambs | H31: 51
A32: Stock | B32: 18 in tithe. | C32: 0 | D32: 0 | E32: Lambs
A33: Stock | B33: 1 in murrain after tithe and before weaning. | C33: 0 | D33: 0 | E33: Lambs | H33: 1
A34: Stock | B34: 166 sold to the reeve of Ecchinswell before shearing. | C34: 0 | D34: 0 | E34: Lambs | I34: 166
A35: Stock | B35: 1 removed and sold before shearing because unfit for the stock. | C35: 0 | D35: 0 | E35: Lambs | I35: 1
A36: Stock | B36: Total as before. | C36: 0 | D36: 0 | E36: Lambs
A37: Stock | B37: None remain. | C37: 0 | D37: 0 | E37: Lambs
A38: Stock | B38: Geese: 1 gander and 4 breeding geese remain. | C38: 0 | D38: 0 | E38: Poultry stock | F38: 1
A39: Stock | B39: Total, 5. 1 gander and 4 breeding geese, worth 2 shilling 6pence, remain in the hands of the said farmers, to be handed back and restored as before. | C39: 0 | D39: 0 | E39: Poultry stock
A40: Stock | B40: Cocks and hens: 1 cock and 5 hens remain. | C40: 0 | D40: 0 | E40: Poultry stock
...

Sheet Overview

Sheet Issues of the Mills

Sheet Prices

Sheet Labour Rents

Sheet not needed

Sheet Issues of the Grange raw
A1: Heading | B1: Sentence | C1: Quarters 1_x | D1: Bushels 1_x | E1: Sown Quarters | F1: Sown Bushels | G1: Sown Total Quarters | H1: Bought in Quarters | I1: Bought in Bushels | J1: Bought in Total Quarters | K1: Tithe Quarters | L1: Tithe Bushels | M1: Tithe Total Quarters | N1: Manorial servants & livestock Quarters | O1: Manorial servants & livestock Bushels | P1: Manorial servants & livestock Total Quarters | Q1: Sold Quarters | R1: Sold Bushels | S1: Sold Total Quarters | T1: Account Quarters | U1: Account Bushels | V1: Account Total Quarters | W1: bought only | X1: Total Quarters Except 1 | Y1: Total Bushels Except 1 | Z1: Total Corn Cross-Check | AA1: Total Corn Manorial Account | AB1: Corn Quantity Error | AC1: Quarters 1_y | AD1: Bushels 1_y | AE1: Quarters 2 | AF1: Bushels 2 | AG1: Total Bought Quarters
A2: and thus he owes | B2: total | C2: 0 | D2: 0 | E2: 0 | F2: 0 | G2: 0 | H2: 0 | I2: 0 | J2: 0 | K2: 0 | L2: 0 | M2: 0 | N2: 0 | O2: 0 | P2: 0 | Q2: 0 | R2: 0 | S2: 0 | T2: 0 | U2: 0 | V2: 0 | W2: 0 | AG2: 0
A3: wheat | B3: john seuare and richard le newe, farmers there, answer for 22 quarters of wheat remaining. | C3: 0 | D3: 0 | E3: 0 | F3: 0 | G3: 0 | H3: 0 | I3: 0 | J3: 0 | K3: 0 | L3: 0 | M3: 0 | N3: 0 | O3: 0 | P3: 0 | Q3: 0 | R3: 0 | S3: 0 | T3: 0 | U3: 0 | V3: 0 | W3: 0 | X3: 22 | Y3: 0 | Z3: 22 | AA3: 22 | AB3: 0 | AC3: 22 | AD3: 0 | AG3: 0
A4: wheat | B4: total, 22 quarters.. | C4: 0 | D4: 0 | E4: 0 | F4: 0 | G4: 0 | H4: 0 | I4: 0 | J4: 0 | K4: 0 | L4: 0 | M4: 0 | N4: 0 | O4: 0 | P4: 0 | Q4: 0 | R4: 0 | S4: 0 | T4: 0 | U4: 0 | V4: 0 | W4: 0 | X4: 22 | Y4: 0 | Z4: 22 | AA4: 22 | AB4: 0 | AC4: 22 | AD4: 0 | AG4: 0
A5: wheat | B5: 22 quarters remain, worth 4 shilling a qr, in the hands of the aforesaid farmers, to be handed back and restored at the end of their term of 7 years, this year being the fourth, or the value of the same at the lord's will. | C5: 0 | D5: 0 | E5: 0 | F5: 0 | G5: 0 | H5: 0 | I5: 0 | J5: 0 | K5: 0 | L5: 0 | M5: 0 | N5: 0 | O5: 0 | P5: 0 | Q5: 0 | R5: 0 | S5: 0 | T5: 0 | U5: 0 | V5: 0 | W5: 0 | AG5: 0
A6: wheat | B6: total | C6: 0 | D6: 0 | E6: 0 | F6: 0 | G6: 0 | H6: 0 | I6: 0 | J6: 0 | K6: 0 | L6: 0 | M6: 0 | N6: 0 | O6: 0 | P6: 0 | Q6: 0 | R6: 0 | S6: 0 | T6: 0 | U6: 0 | V6: 0 | W6: 0 | AG6: 0
A7: barley | B7: and for 16 quarters of barley remaining.. | C7: 0 | D7: 0 | E7: 0 | F7: 0 | G7: 0 | H7: 0 | I7: 0 | J7: 0 | K7: 0 | L7: 0 | M7: 0 | N7: 0 | O7: 0 | P7: 0 | Q7: 0 | R7: 0 | S7: 0 | T7: 0 | U7: 0 | V7: 0 | W7: 0 | X7: 16 | Y7: 0 | Z7: 16 | AA7: 16 | AB7: 0 | AC7: 16 | AD7: 0 | AG7: 0
A8: barley | B8: total, 16 quarters.. | C8: 0 | D8: 0 | E8: 0 | F8: 0 | G8: 0 | H8: 0 | I8: 0 | J8: 0 | K8: 0 | L8: 0 | M8: 0 | N8: 0 | O8: 0 | P8: 0 | Q8: 0 | R8: 0 | S8: 0 | T8: 0 | U8: 0 | V8: 0 | W8: 0 | X8: 16 | Y8: 0 | Z8: 16 | AA8: 16 | AB8: 0 | AC8: 16 | AD8: 0 | AG8: 0
A9: barley | B9: 16 quarters remain, worth 3 shilling a qr, in the hands of the aforesaid farmers, to be handed back and restored as before. | C9: 0 | D9: 0 | E9: 0 | F9: 0 | G9: 0 | H9: 0 | I9: 0 | J9: 0 | K9: 0 | L9: 0 | M9: 0 | N9: 0 | O9: 0 | P9: 0 | Q9: 0 | R9: 0 | S9: 0 | T9: 0 | U9: 0 | V9: 0 | W9: 0 | AG9: 0
A10: barley | B10: total | C10: 0 | D10: 0 | E10: 0 | F10: 0 | G10: 0 | H10: 0 | I10: 0 | J10: 0 | K10: 0 | L10: 0 | M10: 0 | N10: 0 | O10: 0 | P10: 0 | Q10: 0 | R10: 0 | S10: 0 | T10: 0 | U10: 0 | V10: 0 | W10: 0 | AG10: 0
A11: oats | B11: and for 40 quarters of oats remaining.. | C11: 0 | D11: 0 | E11: 0 | F11: 0 | G11: 0 | H11: 0 | I11: 0 | J11: 0 | K11: 0 | L11: 0 | M11: 0 | N11: 0 | O11: 0 | P11: 0 | Q11: 0 | R11: 0 | S11: 0 | T11: 0 | U11: 0 | V11: 0 | W11: 0 | X11: 40 | Y11: 0 | Z11: 40 | AA11: 40 | AB11: 0 | AC11: 40 | AD11: 0 | AG11: 0
A12: oats | B12: total, 40 quarters.. | C12: 0 | D12: 0 | E12: 0 | F12: 0 | G12: 0 | H12: 0 | I12: 0 | J12: 0 | K12: 0 | L12: 0 | M12: 0 | N12: 0 | O12: 0 | P12: 0 | Q12: 0 | R12: 0 | S12: 0 | T12: 0 | U12: 0 | V12: 0 | W12: 0 | X12: 40 | Y12: 0 | Z12: 40 | AA12: 40 | AB12: 0 | AC12: 40 | AD12: 0 | AG12: 0
A13: oats | B13: 40 quarters remain, of which 7 quarters 7 bushels by estimation in sheaves are for the fodder of oxen, worth 2 shilling a qr, in the hands of the aforesaid farmers, to be handed back and restored as before. | C13: 0 | D13: 0 | E13: 0 | F13: 0 | G13: 0 | H13: 0 | I13: 0 | J13: 0 | K13: 0 | L13: 0 | M13: 0 | N13: 47 | O13: 7 | P13: 47.88 | Q13: 0 | R13: 0 | S13: 0 | T13: 0 | U13: 0 | V13: 0 | W13: 0 | AG13: 0

Sheet Issues of the Grange
A1: Gross Output | B1: Bought Only Aggregated | C1: Account Quarters | D1: Account Bushels | E1: Account Total Quarters | F1: Bought in Quarters | G1: Bought in Bushels | H1: Total Bought Quarters | I1: Sold Quarters | J1: Sold Bushels | K1: Sold Total Quarters | L1: Total Corn Quantity | M1: Difference Produced+Bought-Sold | N1: Weighted Average Price per Quarter | O1: Non-Weighted Average Price per Quarter | P1: Value of Total Production weighted | Q1: Value of Total Production unweighted
A2: and thus he owes | B2: 0 | C2: 0 | D2: 0 | E2: 0 | F2: 0 | G2: 0 | H2: 0 | I2: 0 | J2: 0 | K2: 0 | L2: 0 | M2: 0
A3: wheat | B3: 0 | C3: 0 | D3: 0 | E3: 0 | F3: 0 | G3: 0 | H3: 0 | I3: 0 | J3: 0 | K3: 0 | L3: 0 | M3: 0
A4: barley | B4: 0 | C4: 0 | D4: 0 | E4: 0 | F4: 0 | G4: 0 | H4: 0 | I4: 0 | J4: 0 | K4: 0 | L4: 0 | M4: 0
A5: oats | B5: 0 | C5: 0 | D5: 0 | E5: 0 | F5: 0 | G5: 0 | H5: 0 | I5: 0 | J5: 0 | K5: 0 | L5: 0 | M5: 0
A6: Mancorn | B6: 0 | C6: 0 | D6: 0 | E6: 0 | F6: 0 | G6: 0 | H6: 0 | I6: 0 | J6: 0 | K6: 0 | L6: 0 | M6: 0
A7: Maslin | B7: 0 | C7: 0 | D7: 0 | E7: 0 | F7: 0 | G7: 0 | H7: 0 | I7: 0 | J7: 0 | K7: 0 | L7: 0 | M7: 0
A8: First-grade malt | B8: 0 | C8: 0 | D8: 0 | E8: 0 | F8: 0 | G8: 0 | H8: 0 | I8: 0 | J8: 0 | K8: 0 | L8: 0 | M8: 0
A9: Second-grade malt | B9: 0 | C9: 0 | D9: 0 | E9: 0 | F9: 0 | G9: 0 | H9: 0 | I9: 0 | J9: 0 | K9: 0 | L9: 0 | M9: 0
A10: Peas | B10: 0 | C10: 0 | D10: 0 | E10: 0 | F10: 0 | G10: 0 | H10: 0 | I10: 0 | J10: 0 | K10: 0 | L10: 0 | M10: 0
A11: Oatmeal | B11: 0 | C11: 0 | D11: 0 | E11: 0 | F11: 0 | G11: 0 | H11: 0 | I11: 0 | J11: 0 | K11: 0 | L11: 0 | M11: 0
A12: Vetches | B12: 0 | C12: 0 | D12: 0 | E12: 0 | F12: 0 | G12: 0 | H12: 0 | I12: 0 | J12: 0 | K12: 0 | L12: 0 | M12: 0
A13: Rye | B13: 0 | C13: 0 | D13: 0 | E13: 0 | F13: 0 | G13: 0 | H13: 0 | I13: 0 | J13: 0 | K13: 0 | L13: 0 | M13: 0
... A17: Curall | B17: 0 | C17: 0 | D17: 0 | E17: 0 | F17: 0 | G17: 0 | H17: 0 | I17: 0 | J17: 0 | K17: 0 | L17: 0 | M17: 0

Sheet Sale of Corn Prices
A1: Heading | B1: Sentence | C1: Total in Pounds | D1: Pounds | E1: Shillings | F1: Pence | G1: Corn | H1: Total Quarters Except 1 | I1: Total Bushels Except 1 | J1: Total Corn Cross-Check | K1: Total Corn Manorial Account | L1: Corn Quantity Error | M1: Quarters 0 | N1: Bushels 0 | O1: shilling a quarter 1 | P1: pence a quarter 1 | Q1: Quarters 1 | R1: Bushels 1 | S1: shilling a quarter 2 | T1: pence a quarter 2 | U1: shilling a quarter 3 | V1: pence a quarter 3 | W1: shilling a quarter 4 | X1: pence a quarter 4 | Y1: £ a quarter 1 | Z1: £ a quarter 2 | AA1: £ a quarter 3 | AB1: £ a quarter 4 | AC1: Quarters Sold | AD1: Weighted Average Price per Quarter | AE1: Non-Weighted Average Price per Quarter | AF1: Corn lowercase

Sheet Expenses
A1: BURGHCLERE EXPENSES
A2: Heading | B2: £ | C2: s | D2: d | F2: Total in £ | G2: Error | H2: Notes
A4: Cost of ploughs | B4: 0 | C4: 0 | D4: 0 | F4: 0
A5: Cost of ploughs total | F5: 0 | G5: 0
A7: Purchase of stock | B7: 16 | C7: 6 | D7: 8 | F7: 16.33
A8: Purchase of stock | B8: 16 | C8: 6 | D8: 8 | F8: 16.33
A9: Purchase of stock total | F9: 16.33 | G9: 0
A11: Necessary expenses | B11: 0 | C11: 1 | D11: 8 | F11: 0.08
A12: Necessary expenses | B12: 0 | C12: 1 | D12: 4 | F12: 0.07
A13: Necessary expenses | B13: 0 | C13: 3 | D13: 0 | F13: 0.15
A14: Necessary expenses total | F14: 0.15 | G14: 0
A16: Total of all expenses | B16: 20 | C16: 10 | D16: 0 | F16: 20.5
A17: Total of all expenses | F17: 0 | G17: -20.5
A19: And he owes | B19: 76 | C19: 6 | D19: 5 | F19: 76.32
A20: And he owes total | F20: 76.32 | G20: 0
A22: Cash deliveries | B22: 39 | C22: 4 | D22: 6 | F22: 39.23
A23: Cash deliveries | B23: 39 | C23: 4 | D23: 6 | F23: 39.23
A24: Cash deliveries total | F24: 39.23 | G24: 0
A26: Total of all allowances and cash deliveries | B26: 40 | C26: 9 | D26: 0 | F26: 40.45
A27: Total of all allowances and cash deliveries total | F27: 0 | G27: -40.45
A29: And thus he owes | B29: 15 | C29: 17 | D29: 5 | F29: 15.87
A31: Total of all expenses per account | B31: 20 | C31: 10 | D31: 0 | F31: =F16
A32: Total of all expenses (calculated here) | F32: =SUMIF(A1:A15,"* total",F1:F15)
A33: Total fixed investment
A34: Total Demesne fixed investment
