Workbook

Sheet Adderbury Overview
A1: ADDERBURY | B1: Total in £ | C1: Error | D1: Note
A2: CASH ACCOUNT
A3: RECEIPTS
A4: Arrears total
A5: Rents of assize total | B5: ='Adderbury Receipts'!F9
A6: Quittances total | B6: ='Adderbury Receipts'!F22
A7: Defaults of rent total | B7: ='Adderbury Receipts'!F27
A8: Defaults of rent through the pestilence total | B8: ='Adderbury Receipts'!F36
A9: Cotlands defaults total | B9: ='Adderbury Receipts'!F45
A10: Cotlands total | B10: ='Adderbury Receipts'!F54
A11: Total of quittances and defaults of rent total | B11: ='Adderbury Receipts'!F56
A12: Total of rents remaining clear total | B12: ='Adderbury Receipts'!F58
A13: Farms total | B13: ='Adderbury Receipts'!F70
A14: Annual recognizances total | B14: ='Adderbury Receipts'!F90
A15: Issues of the Manor total | B15: ='Adderbury Receipts'!F117
A16: Issues of the tenements in the lord's hands total | B16: ='Adderbury Receipts'!F126
A17: Sale of labour services total | B17: ='Adderbury Receipts'!F135
A18: Sale of corn total | B18: ='Adderbury Receipts'!F138
A19: Entry and marriage fines total | B19: ='Adderbury Receipts'!F166
A20: Pleas & perquisites total | B20: ='Adderbury Receipts'!F173
A21: Forfeited chattels total | B21: ='Adderbury Receipts'!F177
A22: Farm of the demesne land total | B22: ='Adderbury Receipts'!F181
A23: Total of all receipts (calculated here) | B23: ='Adderbury Receipts'!F185
A24: Total of all receipts (calculated here) incl arrears
A25: Total recorded in the accounts excl. arrears | B25: ='Adderbury Receipts'!F184 | C25: =B23-B25
A26: Total recorded in the accounts incl. arrears
A29: EXPENSES
A30: Cost of ploughs total
A31: Purchase of corn total
A32: Cost of carts and wagons total
A33: Cost of dairy total
A34: Purchase of stock total
A35: Sheepcote total
A36: Cost of buildings total | B36: ='Adderbury Expenses'!F26
A37: Threshing total
A38: Barley expenses
A39: Expenses of the harvest total
A40: Necessary expenses
A41: Wages of the bailiff | B41: ='Adderbury Expenses'!F30
A42: Steward's expenses total | B42: ='Adderbury Expenses'!F33
...

Sheet EastKnoyle Stock
A1: EASTKNOYLE STOCK ACCOUNT
C3: added | G3: subtracted
A4: Livestock | B4: Inherited stock | C4: added | D4: strays | E4: herbage | F4: churchscot | G4: of which in default | H4: sold | I4: in murrain | J4: accounted for elsewhere | K4: End-period stock | L4: cross-check | M4: stock building | N4: raw production | O4: Unit price (£) | P4: Value of stock (£) at given value | Q4: Value of stock (£) at sales prices | R4: Sales in (£) | S4: Value of stock building (£) | T4: Value of production (£) at sales prices | U4: Details
A5: Cart-horses | B5: 0 | C5: 0 | H5: 0 | I5: 0 | L5: =B5+C5-H5 | M5: =L5-B5 | N5: =C5 | O5: 0 | P5: =O5*K5 | R5: 0 | S5: =O5*M5 | T5: =O5*N5
A6: Mares | B6: 0 | C6: 0 | H6: 0 | I6: 0 | L6: =B6+C6-H6 | M6: =L6-B6 | N6: =C6 | O6: 0 | P6: =O6*K6 | R6: 0 | S6: =O6*M6 | T6: =O6*N6
A7: Plough horses | B7: 0 | C7: 0 | H7: 0 | I7: 0 | L7: =B7+C7-H7 | M7: =L7-B7 | N7: =C7 | O7: 0 | P7: =O7*K7 | R7: 0 | S7: =O7*M7 | T7: =O7*N7
A8: Colts (unspecified years) | B8: 0 | C8: 0 | H8: 0 | I8: 0 | L8: =B8+C8-H8 | M8: =L8-B8 | N8: =C8 | O8: 0 | P8: =O8*K8 | R8: 0 | S8: =O8*M8 | T8: =O8*N8
A9: Colts (2 years) | B9: 0 | C9: 0 | H9: 0 | I9: 0 | L9: =B9+C9-H9 | M9: =L9-B9 | N9: =C9 | O9: 0 | P9: =O9*K9 | R9: 0 | S9: =O9*M9 | T9: =O9*N9
A10: Colts (1 year) | B10: 0 | C10: 0 | H10: 0 | I10: 0 | L10: =B10+C10-H10 | M10: =L10-B10 | N10: =C10 | O10: 0 | P10: =O10*K10 | R10: 0 | S10: =O10*M10 | T10: =O10*N10
A11: Foals | B11: 0 | C11: 0 | H11: 0 | I11: 0 | L11: =B11+C11-H11 | M11: =L11-B11 | N11: =C11 | O11: 0 | P11: =O11*K11 | R11: 0 | S11: =O11*M11 | T11: =O11*N11
A12: Oxen | B12: 26 | C12: 0 | H12: 0 | I12: 0 | L12: =B12+C12-H12 | M12: =L12-B12 | N12: =C12 | O12: 0 | P12: =O12*K12 | R12: 0 | S12: =O12*M12 | T12: =O12*N12
A13: Bulls | B13: 0 | C13: 0 | H13: 0 | I13: 0 | L13: =B13+C13-H13 | M13: =L13-B13 | N13: =C13 | O13: 0 | P13: =O13*K13 | R13: 0 | S13: =O13*M13 | T13: =O13*N13
A14: Cows | B14: 0 | C14: 0 | H14: 0 | I14: 0 | L14: =B14+C14-H14 | M14: =L14-B14 | N14: =C14 | O14: 0 | P14: =O14*K14 | R14: 0 | S14: =O14*M14 | T14: =O14*N14
A15: Steers | B15: 0 | C15: 0 | H15: 0 | I15: 0 | L15: =B15+C15-H15 | M15: =L15-B15 | N15: =C15 | O15: 0 | P15: =O15*K15 | R15: 0 | S15: =O15*M15 | T15: =O15*N15
A16: Bullocks | B16: 0 | C16: 0 | H16: 0 | I16: 0 | L16: =B16+C16-H16 | M16: =L16-B16 | N16: =C16 | O16: 0 | P16: =O16*K16 | R16: 0 | S16: =O16*M16 | T16: =O16*N16
... A20: Rams | B20: 24 | C20: 0 | H20: 0 | I20: 0 | L20: =B20+C20-H20 | M20: =L20-B20 | N20: =C20 | O20: 0 | P20: =O20*K20 | R20: 0 | S20: =O20*M20 | T20: =O20*N20
A21: Ewes | B21: 434 | C21: 0 | H21: 0 | I21: 0 | L21: =B21+C21-H21 | M21: =L21-B21 | N21: =C21 | O21: 0 | P21: =O21*K21 | Q21: 0 | R21: 0 | S21: =O21*M21 | T21: =O21*N21
A22: Hoggs | B22: 0 | C22: 0 | H22: 0 | I22: 0 | L22: =B22+C22-H22 | M22: =L22-B22 | N22: =C22 | O22: 0 | P22: =O22*K22 | R22: 0 | S22: =O22*M22 | T22: =O22*N22
A23: Lambs | B23: 334 | C23: 0 | H23: 0 | I23: 0 | L23: =B23+C23-H23 | M23: =L23-B23 | N23: =C23 | O23: 0 | P23: =O23*K23 | R23: 0 | S23: =O23*M23 | T23: =O23*N23
A24: Boars | B24: 0 | C24: 0 | H24: 0 | I24: 0 | L24: =B24+C24-H24 | M24: =L24-B24 | N24: =C24 | O24: 0 | P24: =O24*K24 | R24: 0 | S24: =O24*M24 | T24: =O24*N24
A25: Sows | B25: 3 | C25: 0 | H25: 0 | I25: 0 | L25: =B25+C25-H25 | M25: =L25-B25 | N25: =C25 | O25: 0 | P25: =O25*K25 | R25: 0 | S25: =O25*M25 | T25: =O25*N25
A26: Pigs | B26: 0 | C26: 0 | H26: 0 | I26: 0 | L26: =B26+C26-H26 | M26: =L26-B26 | N26: =C26 | O26: 0 | P26: =O26*K26 | R26: 0 | S26: =O26*M26 | T26: =O26*N26
A27: Hoggets | B27: 0 | C27: 0 | H27: 0 | I27: 0 | L27: =B27+C27-H27 | M27: =L27-B27 | N27: =C27 | O27: 0 | P27: =O27*K27 | R27: 0 | S27: =O27*M27 | T27: =O27*N27
A28: Piglets | B28: 0 | C28: 0 | H28: 0 | I28: 0 | L28: =B28+C28-H28 | M28: =L28-B28 | N28: =C28 | O28: 0 | P28: =O28*K28 | R28: 0 | S28: =O28*M28 | T28: =O28*N28
A29: Swans | B29: 0 | C29: 0 | H29: 0 | I29: 0 | L29: =B29+C29-H29 | M29: =L29-B29 | N29: =C29 | O29: 0 | P29: =O29*K29 | R29: 0 | S29: =O29*M29 | T29: =O29*N29
A30: Peacocks | B30: 0 | C30: 0 | H30: 0 | I30: 0 | L30: =B30+C30-H30 | M30: =L30-B30 | N30: =C30 | O30: 0 | P30: =O30*K30 | R30: 0 | S30: =O30*M30 | T30: =O30*N30
A31: Total Value
A34: Wool | B34: 0 | C34: 0 | H34: 0 | I34: 0
A35: Coarse wool | B35: 0 | C35: 0 | H35: 0 | I35: 0
A36: Lamb's wool | B36: 0 | C36: 0 | H36: 0 | I36: 0
A37: Wool locks | B37: 0 | C37: 0 | H37: 0 | I37: 0
A38: Wool sold at shearing | B38: 0 | C38: 0 | H38: 0 | I38: 0
A39: Total wool | B39: 0 | C39: 0 | H39: 0 | I39: 0
B40: 0 | C40: 0 | H40: 0 | I40: 0
B41: 0 | C41: 0 | H41: 0 | I41: 0
A42: Hides | B42: 0 | C42: 0 | H42: 0 | I42: 0
A43: Ox hides | B43: 0 | C43: 0 | H43: 0 | I43: 0
A44: Mare | B44: 0 | C44: 0 | H44: 0 | I44: 0
A45: Steer | B45: 0 | C45: 0 | H45: 0 | I45: 0
A46: calves | B46: 0 | C46: 0 | H46: 0 | I46: 0
...

Sheet raw data
A1: Heading | B1: Sentence | C1: Total in Pounds | D1: Pounds | E1: Shillings | F1: Pence | G1: Corn | H1: Total Quarters Except 1 | I1: Total Bushels Except 1 | J1: Total Corn Cross-Check | K1: Total Corn Manorial Account | L1: Corn Quantity Error | M1: Quarters 1 | N1: Bushels 1 | O1: shilling a quarter 1 | P1: pence a quarter 1 | Q1: shilling a quarter 2 | R1: pence a quarter 2 | S1: shilling a quarter 3 | T1: pence a quarter 3 | U1: shilling a quarter 4 | V1: pence a quarter 4 | W1: shilling a bushel 1 | X1: pence a bushel 1 | Y1: shilling a bushel 2 | Z1: pence a bushel 2 | AA1: shilling a bushel 3 | AB1: pence a bushel 3 | AC1: shilling a bushel 4 | AD1: pence a bushel 4
A2: east knoyle | B2: the account of the same from michaelmas of the fifth year of the translation of henry. | C2: 0 | D2: 0 | E2: 0 | F2: 0 | H2: 0 | I2: 0 | J2: 0 | K2: 0 | L2: 0 | M2: 0 | N2: 0
A3: east knoyle | B3: beaufort', lord bishop of winchester, until michaelmas of the sixth year, for one whole. | C3: 0 | D3: 0 | E3: 0 | F3: 0 | H3: 0 | I3: 0 | J3: 0 | K3: 0 | L3: 0 | M3: 0 | N3: 0
A4: east knoyle | B4: year, and the eleventh year of the reign of king henry the fourth. | C4: 0 | D4: 0 | E4: 0 | F4: 0 | H4: 0 | I4: 0 | J4: 0 | K4: 0 | L4: 0 | M4: 0 | N4: 0
A5: arrears | B5: john bryt', farmer there, answers for £9 19 shilling 5.5pence of arrears from his last account of the preceding year. | C5: 9.97 | D5: 9 | E5: 19 | F5: 5.5 | H5: 0 | I5: 0 | J5: 0 | K5: 0 | L5: 0 | M5: 0 | N5: 0
A6: arrears | B6: total, £9 19 shilling 5.5pence. | C6: 9.97 | D6: 9 | E6: 19 | F6: 5.5 | H6: 0 | I6: 0 | J6: 0 | K6: 0 | L6: 0 | M6: 0 | N6: 0
A7: rents | B7: nothing for rents or from the issues of the land here because they pertain to the farmer, the full total of which is made clear in the first year of the translation of the lord and in the preceding pipe rolls.. | C7: 0 | D7: 0 | E7: 0 | F7: 0 | H7: 0 | I7: 0 | J7: 0 | K7: 0 | L7: 0 | M7: 0 | N7: 0
A8: issues of the manor | B8: nothing from the sale of thorns this year. | C8: 0 | D8: 0 | E8: 0 | F8: 0 | H8: 0 | I8: 0 | J8: 0 | K8: 0 | L8: 0 | M8: 0 | N8: 0
A9: farms | B9: and for £80 for the farm of the manor for the year, with the lands, meadows, rents, services, both of the free tenants and of the villeins, underwood on the east side, and all profits and their appurtenances, apart from wards, reliefs, marriages, escheats, heriots, strays, entry fines, advowsons and everything pertaining in whatever way to the tourn, for a term of 12 years, this year being the fifth, and paying £10 at easter (23 march), £30 at lammas (1 august) and £40 at michaelmas (29 september). | C9: 80 | D9: 80 | E9: 0 | F9: 0 | H9: 0 | I9: 0 | J9: 0 | K9: 0 | L9: 0 | M9: 0 | N9: 0
A10: farms | B10: total, £80.. | C10: 80 | D10: 80 | E10: 0 | F10: 0 | H10: 0 | I10: 0 | J10: 0 | K10: 0 | L10: 0 | M10: 0 | N10: 0
A11: sale of corn | B11: and for 1 shilling 10.5pence from 4 bushels' of oats sold, at 5pence a bushels. | C11: 0.09 | D11: 0 | E11: 1 | F11: 10.5 | G11: oats | H11: 0 | I11: 4 | J11: 0.5 | K11: 0.5 | L11: 0 | M11: 0 | N11: 4 | W11: 0 | X11: 5
A12: sale of corn | B12: total, 1 shilling 10.5pence. | C12: 0.09 | D12: 0 | E12: 1 | F12: 10.5 | H12: 0 | I12: 0 | J12: 0 | K12: 0 | L12: 0 | M12: 0 | N12: 0
A13: strays sold | B13: and for 12 shilling 6pence from 6 colts sold. | C13: 0.62 | D13: 0 | E13: 12 | F13: 6 | H13: 0 | I13: 0 | J13: 0 | K13: 0 | L13: 0 | M13: 0 | N13: 0
A14: strays sold | B14: 4 shilling from 1 ewe and 2 hoggs from strays sold. | C14: 0.2 | D14: 0 | E14: 4 | F14: 0 | H14: 0 | I14: 0 | J14: 0 | K14: 0 | L14: 0 | M14: 0 | N14: 0
A15: strays sold | B15: total, 16 shilling 6pence. | C15: 0.83 | D15: 0 | E15: 16 | F15: 6 | H15: 0 | I15: 0 | J15: 0 | K15: 0 | L15: 0 | M15: 0 | N15: 0
A16: entry fines | B16: and for 6 shilling 8pence from tithingpenny at the tourn of martinmas. | C16: 0.33 | D16: 0 | E16: 6 | F16: 8 | H16: 0 | I16: 0 | J16: 0 | K16: 0 | L16: 0 | M16: 0 | N16: 0
A17: entry fines | B17: 6 shilling 8pence from tithingpenny at the tourn of hockday. | C17: 0.33 | D17: 0 | E17: 6 | F17: 8 | H17: 0 | I17: 0 | J17: 0 | K17: 0 | L17: 0 | M17: 0 | N17: 0
A18: entry fines | B18: £2 from john, son of john golley the elder, to have 1 messuage and 0.5 virgate of villein land in la lyghe in the tithing of east knoyle by surrender of peter golley his brother. | C18: 2 | D18: 2 | E18: 0 | F18: 0 | H18: 0 | I18: 0 | J18: 0 | K18: 0 | L18: 0 | M18: 0 | N18: 0
A19: entry fines | B19: 3 shilling 4pence from walter irisshe to have 1 toft and' virgate of villein land in the tithing of milton which belonged to john joumyn' and which came into the lord's hands through the death of the same john in the great pestilence. | C19: 0.17 | D19: 0 | E19: 3 | F19: 4 | H19: 0 | I19: 0 | J19: 0 | K19: 0 | L19: 0 | M19: 0 | N19: 0
A20: entry fines | B20: total, £2 16 shilling 8pence. | C20: 2.83 | D20: 2 | E20: 16 | F20: 8 | H20: 0 | I20: 0 | J20: 0 | K20: 0 | L20: 0 | M20: 0 | N20: 0
A21: perquisites of court | B21: and for 4 shilling 10pence from the perquisites of the tourn of martinmas. | C21: 0.24 | D21: 0 | E21: 4 | F21: 10 | H21: 0 | I21: 0 | J21: 0 | K21: 0 | L21: 0 | M21: 0 | N21: 0
A22: perquisites of court | B22: 6 shilling 1pence from the perquisites of the courts held before the tourn of hockday, from the amercements pertaining to the tourn. | C22: 0.3 | D22: 0 | E22: 6 | F22: 1 | H22: 0 | I22: 0 | J22: 0 | K22: 0 | L22: 0 | M22: 0 | N22: 0
A23: perquisites of court | B23: 2 shilling 11pence from the perquisites of the tourn of hockday. | C23: 0.15 | D23: 0 | E23: 2 | F23: 11 | H23: 0 | I23: 0 | J23: 0 | K23: 0 | L23: 0 | M23: 0 | N23: 0
... A36: and he owes clear | B36: and he owes, 10 shilling 8pence, in the hands of the escheator, for which he is following year's account.. | C36: 0.53 | D36: 0 | E36: 10 | F36: 8 | H36: 0 | I36: 0 | J36: 0 | K36: 0 | L36: 0 | M36: 0 | N36: 0
A37: wheat | B37: john bryt, farmer there, answers for 20 quarters of wheat. | C37: 0 | D37: 0 | E37: 0 | F37: 0 | G37: wheat | H37: 20 | I37: 0 | J37: 20 | K37: 20 | L37: 0 | M37: 20 | N37: 0
A38: wheat | B38: 20 quarters remain in the hands of the fanner, to be restored at the end of his term. | C38: 0 | D38: 0 | E38: 0 | F38: 0 | H38: 20 | I38: 0 | J38: 20 | K38: 20 | L38: 0 | M38: 20 | N38: 0
A39: barley | B39: and for 20 quarters of barley remaining in the hands of the farmer, to be restored at the end of his term. | C39: 0 | D39: 0 | E39: 0 | F39: 0 | G39: barley | H39: 20 | I39: 0 | J39: 20 | K39: 20 | L39: 0 | M39: 20 | N39: 0
A40: oats | B40: and for 1 quarters of oats from the farm for the year. | C40: 0 | D40: 0 | E40: 0 | F40: 0 | G40: oats | H40: 1 | I40: 0 | J40: 1 | K40: 1 | L40: 0 | M40: 1 | N40: 0
A41: oats | B41: 4 bushels from the farmer of upton. | C41: 0 | D41: 0 | E41: 0 | F41: 0 | H41: 0 | I41: 4 | J41: 0.5 | K41: 0.5 | L41: 0 | M41: 0 | N41: 4
A42: oats | B42: 4 bushels from the fanner of bishops fonthill.. | C42: 0 | D42: 0 | E42: 0 | F42: 0 | H42: 0 | I42: 4 | J42: 0.5 | K42: 0.5 | L42: 0 | M42: 0 | N42: 4
A43: oats | B43: total, 2 quarters. | C43: 0 | D43: 0 | E43: 0 | F43: 0 | H43: 2 | I43: 0 | J43: 2 | K43: 2 | L43: 0 | M43: 2 | N43: 0
A44: oats | B44: in fodder of the horses of the steward at the toums of martinmas and hockday, by 2 sealed bills, 1 quarters 3.5 bushels. | C44: 0 | D44: 0 | E44: 0 | F44: 0 | H44: 1 | I44: 3.5 | J44: 1.44 | K44: 1.44 | L44: 0 | M44: 1 | N44: 3.5
A45: oats | B45: sold within, 4.5 bushels. | C45: 0 | D45: 0 | E45: 0 | F45: 0 | H45: 0 | I45: 4.5 | J45: 0.56 | K45: 0.56 | L45: 0 | M45: 0 | N45: 4.5
A46: oats | B46: total as before. | C46: 0 | D46: 0 | E46: 0 | F46: 0 | H46: 0 | I46: 0 | J46: 0 | K46: 0 | L46: 0 | M46: 0 | N46: 0
A47: oats | B47: it balances. | C47: 0 | D47: 0 | E47: 0 | F47: 0 | H47: 0 | I47: 0 | J47: 0 | K47: 0 | L47: 0 | M47: 0 | N47: 0
A48: stock | B48: horses: 3 remain in hand, worth 10 shilling each, to be restored at the end of his term.. | C48: 0.5 | D48: 0 | E48: 10 | F48: 0 | H48: 0 | I48: 0 | J48: 0 | K48: 0 | L48: 0 | M48: 0 | N48: 0
A49: stock | B49: yearling strays: 6 colts, 1 ewe and 2 hoggs over a year old from strays this year. | C49: 0 | D49: 0 | E49: 0 | F49: 0 | H49: 0 | I49: 0 | J49: 0 | K49: 0 | L49: 0 | M49: 0 | N49: 0
A50: stock | B50: all sold within. | C50: 0 | D50: 0 | E50: 0 | F50: 0 | H50: 0 | I50: 0 | J50: 0 | K50: 0 | L50: 0 | M50: 0 | N50: 0
A51: stock | B51: none remain. | C51: 0 | D51: 0 | E51: 0 | F51: 0 | H51: 0 | I51: 0 | J51: 0 | K51: 0 | L51: 0 | M51: 0 | N51: 0
A52: stock | B52: oxen: 26 remain in the hands of the farmer, worth 13 shilling 4pence each, to be restored at the end of his term. | C52: 0.67 | D52: 0 | E52: 13 | F52: 4 | H52: 0 | I52: 0 | J52: 0 | K52: 0 | L52: 0 | M52: 0 | N52: 0
...

Sheet Receipts
A1: EASTKNOYLE RECEIPTS
A2: Heading | B2: £ | C2: s | D2: d | F2: Total in £ | G2: Error | H2: Notes | I2: Own notes
A3: Arrears | B3: 9 | C3: 19 | D3: 5.5 | F3: 9.97 | H3: John Bryt', farmer there, answers for £9 19 shilling 5.5pence of arrears from his last account of the preceding year.
A4: Arrears | B4: 9 | C4: 19 | D4: 5.5 | F4: 9.97 | H4: Total, £9 19 shilling 5.5pence.
A5: Arrears total | F5: 9.97 | G5: 0 | H5: Total
A7: Rents | B7: 0 | C7: 0 | D7: 0 | F7: 0 | H7: Nothing for rents or from the issues of the land here because they pertain to the farmer, the full total of which is made clear in the first year of the translation of the lord and in the preceding pipe rolls..
A8: Rents total | F8: 0 | G8: 0 | H8: Total
A10: Issues of the manor | B10: 0 | C10: 0 | D10: 0 | F10: 0 | H10: Nothing from the sale of thorns this year.
A11: Issues of the manor total | F11: 0 | G11: 0 | H11: Total
A13: Sale of corn | B13: 0 | C13: 1 | D13: 10.5 | F13: 0.09 | H13: And for 1 shilling 10.5pence from 4 bushels' of oats sold, at 5pence a bushels.
A14: Sale of corn | B14: 0 | C14: 1 | D14: 10.5 | F14: 0.09 | H14: Total, 1 shilling 10.5pence.
A15: Sale of corn total | F15: 0.09 | G15: 0 | H15: Total
A17: Perquisites of court | B17: 0 | C17: 4 | D17: 10 | F17: 0.24 | H17: And for 4 shilling 10pence from the perquisites of the tourn of Martinmas.
A18: Perquisites of court | B18: 0 | C18: 6 | D18: 1 | F18: 0.3 | H18: 6 shilling 1pence from the perquisites of the courts held before the tourn of Hockday, from the amercements pertaining to the tourn.
A19: Perquisites of court | B19: 0 | C19: 2 | D19: 11 | F19: 0.15 | H19: 2 shilling 11pence from the perquisites of the tourn of Hockday.
A20: Perquisites of court | B20: 0 | C20: 3 | D20: 9 | F20: 0.19 | H20: 3 shilling 9pence from the perquisites of the courts held after the tourn of Hockday.
A21: Perquisites of court total | B21: 0 | C21: 17 | D21: 7 | F21: 0.88 | G21: 0.69 | H21: Total, 17 shilling 7pence.
A22: Total of all receipts recorded in accounts (calculated here) | F22: =SUMIF(A1:A21,"* total",F1:F21)-SUMIF(A1:A21,"Arrears total",F1:F21)
A23: Total of all receipts (calculated here) incl arrears | F23: =F22+SUMIF(A1:A21,"Arrears total",F1:F21)

Sheet Stock
A1: Heading | B1: Sentence | C1: Quarters 1 | D1: Bushels 1 | E1: stock | F1: inherited stock | G1: added | H1: murrain | I1: sold
A2: Oats | B2: Total | C2: 0 | D2: 0
A3: Stock | B3: Horses: 3 remain in hand, worth 10 shilling each, to be restored at the end of his term.. | C3: 0 | D3: 0 | F3: 3
A4: Stock | B4: Yearling strays: 6 colts, 1 ewe and 2 hoggs over a year old from strays this year. | C4: 0 | D4: 0
A5: Stock | B5: all sold within. | C5: 0 | D5: 0
A6: Stock | B6: none remain. | C6: 0 | D6: 0
A7: Stock | B7: Oxen: 26 remain in the hands of the farmer, worth 13 shilling 4pence each, to be restored at the end of his term. | C7: 0 | D7: 0 | E7: Oxen | F7: 26
A8: Stock | B8: Bullocks: 1 remains in the hands of the farmer, worth 6 shilling, to be restored at the end of his term. | C8: 0 | D8: 0 | E8: Bullocks
A9: Stock | B9: Wethers: 464 remain. | C9: 0 | D9: 0 | E9: Wethers | F9: 464
A10: Stock | B10: 4541 remain in the hands of the farmer, worth 1 shilling 10pence each, to be restored at the end of his term. | C10: 0 | D10: 0 | E10: Wethers
A11: Stock | B11: Rams: 24 remain in the hands of the farmer, worth 1 shilling 6pence each, to be restored at the end of his term. | C11: 0 | D11: 0 | E11: Rams | F11: 24
A12: Stock | B12: Ewes: 434 remain in the hands of the farmer, worth 1 shilling 6pence each, to be restored at the end of his term. | C12: 0 | D12: 0 | E12: Ewes | F12: 434
A13: Stock | B13: Lambs: 334 remain in the hands of the farmer, worth 1 shilling 2pence each, to be restored at the end of his term. | C13: 0 | D13: 0 | E13: Lambs | F13: 334
A14: Stock | B14: Boars: 1 remains in the hands of the farmer, worth 3 shilling 4pence, to be restored at the end of his term. | C14: 0 | D14: 0 | E14: Boars
A15: Stock | B15: Sows: 3 remain in the hands of the farmer, worth 3 shilling each, to be restored at the end of his term. | C15: 0 | D15: 0 | E15: Sows | F15: 3
A16: Stock | B16: Geese: 1 gander and 4 breeding geese remain in the hands of the farmer, to be restored at the end of his term. | C16: 0 | D16: 0 | E16: Poultry stock | F16: 1
A17: Stock | B17: Cocks and hens: 1 cock and 5 hens remain in the hands of the farmer, to be restored at the end of his term. | C17: 0 | D17: 0 | E17: Poultry stock
A18: Stock | B18: Utensils: 4 ploughs, worth 2 shilling 8pence, 4 pairs of iron tyres wighing 68 lb, 12 chains, 12 crooks, 12 staples and 12 rings weighing 220 lb, 12 yokes, worth 1 shilling 4pence, 3 harrows with iron teeth, worth 6 shilling, 1 wain with iron tyres with a frame, 2 rungs (exrong’) and other iron harness for the frame, 1 dung-pot (dongpot) and 1 rope, worth in all £1 14 shilling, 1 cart with iron tyres with a frame and cart-rail, 2 iron rungs (rong’), 2 linch-pins and 2 hurters, 1 dung-pot, 1 cart-rope, 1 cart-saddle, 1 harness for the cart-shafts (thilarneis), 4 collars, 3 pairs of traces, worth in £1 8 shilling 8pence, 2 worn out (debil’) ladders, 1 brass pot of 3 gallons, worth 2 shilling 6pence, 1 brass pan of 10 gallons, worth 5 shilling, 1 tripod, worth 1 shilling, 1 bucket hooped with iron by 1 cottar (coterell’), worth 8pence, 1 bucket to put grease in, also 1 vat and 7 moulds for making cheese and 9 stoups not valued, 1 winnowing-fan, worth 8pence, 2 sacks, worth 1 shilling, 1 iron bushel measure, worth 8pence, 3 posts (ypperis), worth 2 shilling, 2 pails and 4 tables for putting the cheese on, 2 fixed tables in the hall, each of 3 pieces, 4 tables and 10 trestles and 10 benches in 2 chambers remain. | C18: 0 | D18: 0 | E18: Utensils | F18: 4
A19: Stock | B19: All this remains in the hands of the farmer, to be restored at the end of his term or the value of the same.. | C19: 0 | D19: 0 | E19: Utensils
A20: Stock | B20: Total | C20: 0 | D20: 0 | E20: Utensils

Sheet Overview

Sheet Issues of the Mills

Sheet Prices

Sheet Labour Rents

Sheet not needed

Sheet Issues of the Grange raw
A1: Heading | B1: Sentence | C1: Quarters 1_x | D1: Bushels 1_x | E1: Sown Quarters | F1: Sown Bushels | G1: Sown Total Quarters | H1: Bought in Quarters | I1: Bought in Bushels | J1: Bought in Total Quarters | K1: Tithe Quarters | L1: Tithe Bushels | M1: Tithe Total Quarters | N1: Manorial servants & livestock Quarters | O1: Manorial servants & livestock Bushels | P1: Manorial servants & livestock Total Quarters | Q1: Sold Quarters | R1: Sold Bushels | S1: Sold Total Quarters | T1: Account Quarters | U1: Account Bushels | V1: Account Total Quarters | W1: bought only | X1: Total Quarters Except 1 | Y1: Total Bushels Except 1 | Z1: Total Corn Cross-Check | AA1: Total Corn Manorial Account | AB1: Corn Quantity Error | AC1: Quarters 1_y | AD1: Bushels 1_y | AE1: Total Bought Quarters
A2: cash deliveries | B2: total | C2: 0 | D2: 0 | E2: 0 | F2: 0 | G2: 0 | H2: 0 | I2: 0 | J2: 0 | K2: 0 | L2: 0 | M2: 0 | N2: 0 | O2: 0 | P2: 0 | Q2: 0 | R2: 0 | S2: 0 | T2: 0 | U2: 0 | V2: 0 | W2: 0 | AE2: 0
A3: wheat | B3: john bryt, farmer there, answers for 20 quarters of wheat. | C3: 0 | D3: 0 | E3: 0 | F3: 0 | G3: 0 | H3: 0 | I3: 0 | J3: 0 | K3: 0 | L3: 0 | M3: 0 | N3: 0 | O3: 0 | P3: 0 | Q3: 0 | R3: 0 | S3: 0 | T3: 0 | U3: 0 | V3: 0 | W3: 0 | X3: 20 | Y3: 0 | Z3: 20 | AA3: 20 | AB3: 0 | AC3: 20 | AD3: 0 | AE3: 0
A4: wheat | B4: 20 quarters remain in the hands of the fanner, to be restored at the end of his term. | C4: 0 | D4: 0 | E4: 0 | F4: 0 | G4: 0 | H4: 0 | I4: 0 | J4: 0 | K4: 0 | L4: 0 | M4: 0 | N4: 0 | O4: 0 | P4: 0 | Q4: 0 | R4: 0 | S4: 0 | T4: 0 | U4: 0 | V4: 0 | W4: 0 | X4: 20 | Y4: 0 | Z4: 20 | AA4: 20 | AB4: 0 | AC4: 20 | AD4: 0 | AE4: 0
A5: wheat | B5: total | C5: 0 | D5: 0 | E5: 0 | F5: 0 | G5: 0 | H5: 0 | I5: 0 | J5: 0 | K5: 0 | L5: 0 | M5: 0 | N5: 0 | O5: 0 | P5: 0 | Q5: 0 | R5: 0 | S5: 0 | T5: 0 | U5: 0 | V5: 0 | W5: 0 | AE5: 0
A6: barley | B6: and for 20 quarters of barley remaining in the hands of the farmer, to be restored at the end of his term. | C6: 0 | D6: 0 | E6: 0 | F6: 0 | G6: 0 | H6: 0 | I6: 0 | J6: 0 | K6: 0 | L6: 0 | M6: 0 | N6: 0 | O6: 0 | P6: 0 | Q6: 0 | R6: 0 | S6: 0 | T6: 0 | U6: 0 | V6: 0 | W6: 0 | X6: 20 | Y6: 0 | Z6: 20 | AA6: 20 | AB6: 0 | AC6: 20 | AD6: 0 | AE6: 0
A7: barley | B7: total | C7: 0 | D7: 0 | E7: 0 | F7: 0 | G7: 0 | H7: 0 | I7: 0 | J7: 0 | K7: 0 | L7: 0 | M7: 0 | N7: 0 | O7: 0 | P7: 0 | Q7: 0 | R7: 0 | S7: 0 | T7: 0 | U7: 0 | V7: 0 | W7: 0 | AE7: 0
A8: oats | B8: and for 1 qr of oats from the farm for the year. | C8: 0 | D8: 0 | E8: 0 | F8: 0 | G8: 0 | H8: 0 | I8: 0 | J8: 0 | K8: 0 | L8: 0 | M8: 0 | N8: 0 | O8: 0 | P8: 0 | Q8: 0 | R8: 0 | S8: 0 | T8: 0 | U8: 0 | V8: 0 | W8: 0 | AE8: 0
A9: oats | B9: 4 bushels from the farmer of upton. | C9: 0 | D9: 0 | E9: 0 | F9: 0 | G9: 0 | H9: 0 | I9: 0 | J9: 0 | K9: 0 | L9: 0 | M9: 0 | N9: 0 | O9: 0 | P9: 0 | Q9: 0 | R9: 0 | S9: 0 | T9: 0 | U9: 0 | V9: 0 | W9: 0 | X9: 0 | Y9: 4 | Z9: 0.5 | AA9: 0.5 | AB9: 0 | AC9: 0 | AD9: 4 | AE9: 0
A10: oats | B10: 4 bushels from the fanner of bishops fonthill.. | C10: 0 | D10: 0 | E10: 0 | F10: 0 | G10: 0 | H10: 0 | I10: 0 | J10: 0 | K10: 0 | L10: 0 | M10: 0 | N10: 0 | O10: 0 | P10: 0 | Q10: 0 | R10: 0 | S10: 0 | T10: 0 | U10: 0 | V10: 0 | W10: 0 | X10: 0 | Y10: 4 | Z10: 0.5 | AA10: 0.5 | AB10: 0 | AC10: 0 | AD10: 4 | AE10: 0
A11: oats | B11: total, 2 quarters. | C11: 0 | D11: 0 | E11: 0 | F11: 0 | G11: 0 | H11: 0 | I11: 0 | J11: 0 | K11: 0 | L11: 0 | M11: 0 | N11: 0 | O11: 0 | P11: 0 | Q11: 0 | R11: 0 | S11: 0 | T11: 0 | U11: 0 | V11: 0 | W11: 0 | X11: 2 | Y11: 0 | Z11: 2 | AA11: 2 | AB11: 0 | AC11: 2 | AD11: 0 | AE11: 0
A12: oats | B12: in fodder of the horses of the steward at the toums of martinmas and hockday, by 2 sealed bills, 1 qr 3.5 bushels. | C12: 0 | D12: 0 | E12: 0 | F12: 0 | G12: 0 | H12: 0 | I12: 0 | J12: 0 | K12: 0 | L12: 0 | M12: 0 | N12: 0 | O12: 0 | P12: 0 | Q12: 0 | R12: 0 | S12: 0 | T12: 0 | U12: 0 | V12: 0 | W12: 0 | AE12: 0
A13: oats | B13: sold within, 4.5 bushels. | C13: 0 | D13: 0 | E13: 0 | F13: 0 | G13: 0 | H13: 0 | I13: 0 | J13: 0 | K13: 0 | L13: 0 | M13: 0 | N13: 0 | O13: 0 | P13: 0 | Q13: 0 | R13: 0 | S13: 0 | T13: 0 | U13: 0 | V13: 0 | W13: 0 | X13: 0 | Y13: 4.5 | Z13: 0.56 | AA13: 0.56 | AB13: 0 | AC13: 0 | AD13: 4.5 | AE13: 0
A14: oats | B14: total as before. | C14: 0 | D14: 0 | E14: 0 | F14: 0 | G14: 0 | H14: 0 | I14: 0 | J14: 0 | K14: 0 | L14: 0 | M14: 0 | N14: 0 | O14: 0 | P14: 0 | Q14: 0 | R14: 0 | S14: 0 | T14: 0 | U14: 0 | V14: 0 | W14: 0 | X14: 0 | Y14: 0 | Z14: 0 | AA14: 0 | AB14: 0 | AC14: 0 | AD14: 0 | AE14: 0
A15: oats | B15: it balances. | C15: 0 | D15: 0 | E15: 0 | F15: 0 | G15: 0 | H15: 0 | I15: 0 | J15: 0 | K15: 0 | L15: 0 | M15: 0 | N15: 0 | O15: 0 | P15: 0 | Q15: 0 | R15: 0 | S15: 0 | T15: 0 | U15: 0 | V15: 0 | W15: 0 | X15: 0 | Y15: 0 | Z15: 0 | AA15: 0 | AB15: 0 | AC15: 0 | AD15: 0 | AE15: 0

Sheet Issues of the Grange
A1: Gross Output | B1: Bought Only Aggregated | C1: Account Quarters | D1: Account Bushels | E1: Account Total Quarters | F1: Bought in Quarters | G1: Bought in Bushels | H1: Total Bought Quarters | I1: Sold Quarters | J1: Sold Bushels | K1: Sold Total Quarters | L1: Total Corn Quantity | M1: Difference Produced+Bought-Sold | N1: Weighted Average Price per Quarter | O1: Non-Weighted Average Price per Quarter | P1: Value of Total Production weighted | Q1: Value of Total Production unweighted
A2: cash deliveries | B2: 0 | C2: 0 | D2: 0 | E2: 0 | F2: 0 | G2: 0 | H2: 0 | I2: 0 | J2: 0 | K2: 0 | L2: 0 | M2: 0
A3: wheat | B3: 0 | C3: 0 | D3: 0 | E3: 0 | F3: 0 | G3: 0 | H3: 0 | I3: 0 | J3: 0 | K3: 0 | L3: 0 | M3: 0
A4: barley | B4: 0 | C4: 0 | D4: 0 | E4: 0 | F4: 0 | G4: 0 | H4: 0 | I4: 0 | J4: 0 | K4: 0 | L4: 0 | M4: 0
A5: oats | B5: 0 | C5: 0 | D5: 0 | E5: 0 | F5: 0 | G5: 0 | H5: 0 | I5: 0 | J5: 0 | K5: 0 | L5: 0 | M5: 0 | O5: 0.18 | Q5: 0
A6: Mancorn | B6: 0 | C6: 0 | D6: 0 | E6: 0 | F6: 0 | G6: 0 | H6: 0 | I6: 0 | J6: 0 | K6: 0 | L6: 0 | M6: 0
A7: Maslin | B7: 0 | C7: 0 | D7: 0 | E7: 0 | F7: 0 | G7: 0 | H7: 0 | I7: 0 | J7: 0 | K7: 0 | L7: 0 | M7: 0
A8: First-grade malt | B8: 0 | C8: 0 | D8: 0 | E8: 0 | F8: 0 | G8: 0 | H8: 0 | I8: 0 | J8: 0 | K8: 0 | L8: 0 | M8: 0
A9: Second-grade malt | B9: 0 | C9: 0 | D9: 0 | E9: 0 | F9: 0 | G9: 0 | H9: 0 | I9: 0 | J9: 0 | K9: 0 | L9: 0 | M9: 0
A10: Peas | B10: 0 | C10: 0 | D10: 0 | E10: 0 | F10: 0 | G10: 0 | H10: 0 | I10: 0 | J10: 0 | K10: 0 | L10: 0 | M10: 0
A11: Oatmeal | B11: 0 | C11: 0 | D11: 0 | E11: 0 | F11: 0 | G11: 0 | H11: 0 | I11: 0 | J11: 0 | K11: 0 | L11: 0 | M11: 0
A12: Vetches | B12: 0 | C12: 0 | D12: 0 | E12: 0 | F12: 0 | G12: 0 | H12: 0 | I12: 0 | J12: 0 | K12: 0 | L12: 0 | M12: 0
A13: Rye | B13: 0 | C13: 0 | D13: 0 | E13: 0 | F13: 0 | G13: 0 | H13: 0 | I13: 0 | J13: 0 | K13: 0 | L13: 0 | M13: 0
A14: Dredge | B14: 0 | C14: 0 | D14: 0 | E14: 0 | F14: 0 | G14: 0 | H14: 0 | I14: 0 | J14: 0 | K14: 0 | L14: 0 | M14: 0
A15: Malt | B15: 0 | C15: 0 | D15: 0 | E15: 0 | F15: 0 | G15: 0 | H15: 0 | I15: 0 | J15: 0 | K15: 0 | L15: 0 | M15: 0
A16: Meal | B16: 0 | C16: 0 | D16: 0 | E16: 0 | F16: 0 | G16: 0 | H16: 0 | I16: 0 | J16: 0 | K16: 0 | L16: 0 | M16: 0
A17: Curall | B17: 0 | C17: 0 | D17: 0 | E17: 0 | F17: 0 | G17: 0 | H17: 0 | I17: 0 | J17: 0 | K17: 0 | L17: 0 | M17: 0

Sheet Sale of Corn Prices
A1: Heading | B1: Sentence | C1: Total in Pounds | D1: Pounds | E1: Shillings | F1: Pence | G1: Corn | H1: Total Quarters Except 1 | I1: Total Bushels Except 1 | J1: Total Corn Cross-Check | K1: Total Corn Manorial Account | L1: Corn Quantity Error | M1: Quarters 0 | N1: Bushels 0 | O1: shilling a quarter 1 | P1: pence a quarter 1 | Q1: shilling a quarter 2 | R1: pence a quarter 2 | S1: shilling a quarter 3 | T1: pence a quarter 3 | U1: shilling a quarter 4 | V1: pence a quarter 4 | W1: £ a quarter 1 | X1: £ a quarter 2 | Y1: £ a quarter 3 | Z1: £ a quarter 4 | AA1: Quarters Sold | AB1: Weighted Average Price per Quarter | AC1: Non-Weighted Average Price per Quarter | AD1: Corn lowercase
A2: sale of corn | B2: and for 1 shilling 10.5pence from 4 bushels' of oats sold, at 5pence a bushels. | C2: 0.09 | D2: 0 | E2: 1 | F2: 10.5 | G2: oats | H2: 0 | I2: 4 | J2: 0.5 | K2: 0.5 | L2: 0 | M2: 0 | N2: 4 | W2: 0.18 | AA2: 0.5 | AC2: 0.18 | AD2: oats
A3: sale of corn | B3: total, 1 shilling 10.5pence. | C3: 0.09 | D3: 0 | E3: 1 | F3: 10.5 | H3: 0 | I3: 0 | J3: 0 | K3: 0 | L3: 0 | M3: 0 | N3: 0 | W3: inf | AA3: 0 | AC3: inf

Sheet Expenses
A1: EASTKNOYLE EXPENSES
A2: Heading | B2: £ | C2: s | D2: d | F2: Total in £ | G2: Error | H2: Notes
A4: Expenses of the steward | B4: 0 | C4: 15 | D4: 4.5 | F4: 0.77
A5: Expenses of the steward | B5: 0 | C5: 15 | D5: 4.5 | F5: 0.77
A6: Expenses of the steward total | F6: 0.77 | G6: 0
A8: Total of all expenses | B8: 3 | C8: 10 | D8: 4.5 | F8: 3.52
A9: Total of all expenses | F9: 0 | G9: -3.52
A11: And he owes | B11: 91 | C11: 1 | D11: 8.5 | F11: 91.09
A12: And he owes total | F12: 91.09 | G12: 0
A14: Cash deliveries | B14: 90 | C14: 11 | D14: 0.5 | F14: 90.55
A15: Cash deliveries total | B15: 90 | C15: 11 | D15: 0.5 | F15: 90.55 | G15: 0
A17: Total of all expenses per account | B17: 3 | C17: 10 | D17: 4.5 | F17: =F8
A18: Total of all expenses (calculated here) | F18: =SUMIF(A1:A7,"* total",F1:F7)
A19: Total fixed investment
A20: Total Demesne fixed investment
