Workbook

Sheet Adderbury Overview
A1: ADDERBURY | B1: Total in £ | C1: Error | D1: Note
A2: CASH ACCOUNT
A3: RECEIPTS
A4: Arrears total
A5: Rents of assize total | B5: ='Adderbury Receipts'!F9
A6: Quittances total | B6: ='Adderbury Receipts'!F22
A7: Defaults of rent total | B7: ='Adderbury Receipts'!F27
A8: Defaults of rent through the pestilence total | B8: ='Adderbury Receipts'!F36
A9: Cotlands defaults total | B9: ='Adderbury Receipts'!F45
A10: Cotlands total | B10: ='Adderbury Receipts'!F54
A11: Total of quittances and defaults of rent total | B11: ='Adderbury Receipts'!F56
A12: Total of rents remaining clear total | B12: ='Adderbury Receipts'!F58
A13: Farms total | B13: ='Adderbury Receipts'!F70
A14: Annual recognizances total | B14: ='Adderbury Receipts'!F90
A15: Issues of the Manor total | B15: ='Adderbury Receipts'!F117
A16: Issues of the tenements in the lord's hands total | B16: ='Adderbury Receipts'!F126
A17: Sale of labour services total | B17: ='Adderbury Receipts'!F135
A18: Sale of corn total | B18: ='Adderbury Receipts'!F138
A19: Entry and marriage fines total | B19: ='Adderbury Receipts'!F166
A20: Pleas & perquisites total | B20: ='Adderbury Receipts'!F173
A21: Forfeited chattels total | B21: ='Adderbury Receipts'!F177
A22: Farm of the demesne land total | B22: ='Adderbury Receipts'!F181
A23: Total of all receipts (calculated here) | B23: ='Adderbury Receipts'!F185
A24: Total of all receipts (calculated here) incl arrears
A25: Total recorded in the accounts excl. arrears | B25: ='Adderbury Receipts'!F184 | C25: =B23-B25
A26: Total recorded in the accounts incl. arrears
A29: EXPENSES
A30: Cost of ploughs total
A31: Purchase of corn total
A32: Cost of carts and wagons total
A33: Cost of dairy total
A34: Purchase of stock total
A35: Sheepcote total
A36: Cost of buildings total | B36: ='Adderbury Expenses'!F26
A37: Threshing total
A38: Barley expenses
A39: Expenses of the harvest total
A40: Necessary expenses
A41: Wages of the bailiff | B41: ='Adderbury Expenses'!F30
A42: Steward's expenses total | B42: ='Adderbury Expenses'!F33
...

Sheet Ivinghoe Stock
A1: IVINGHOE STOCK ACCOUNT
C3: added | G3: subtracted
A4: Livestock | B4: Inherited stock | C4: added | D4: strays | E4: herbage | F4: churchscot | G4: of which in default | H4: sold | I4: in murrain | J4: accounted for elsewhere | K4: End-period stock | L4: cross-check | M4: stock building | N4: raw production | O4: Unit price (£) | P4: Value of stock (£) at given value | Q4: Value of stock (£) at sales prices | R4: Sales in (£) | S4: Value of stock building (£) | T4: Value of production (£) at sales prices | U4: Details
A5: Cart-horses | B5: 0 | C5: 0 | H5: 0 | I5: 0 | L5: =B5+C5-H5 | M5: =L5-B5 | N5: =C5 | O5: 0 | P5: =O5*K5 | R5: 0 | S5: =O5*M5 | T5: =O5*N5
A6: Mares | B6: 0 | C6: 0 | H6: 0 | I6: 0 | L6: =B6+C6-H6 | M6: =L6-B6 | N6: =C6 | O6: 0 | P6: =O6*K6 | R6: 0 | S6: =O6*M6 | T6: =O6*N6
A7: Plough horses | B7: 0 | C7: 0 | H7: 0 | I7: 0 | L7: =B7+C7-H7 | M7: =L7-B7 | N7: =C7 | O7: 0 | P7: =O7*K7 | R7: 0.75 | S7: =O7*M7 | T7: =O7*N7
A8: Colts (unspecified years) | B8: 0 | C8: 0 | H8: 0 | I8: 0 | L8: =B8+C8-H8 | M8: =L8-B8 | N8: =C8 | O8: 0 | P8: =O8*K8 | R8: 0 | S8: =O8*M8 | T8: =O8*N8
A9: Colts (2 years) | B9: 0 | C9: 0 | H9: 0 | I9: 0 | L9: =B9+C9-H9 | M9: =L9-B9 | N9: =C9 | O9: 0 | P9: =O9*K9 | R9: 0 | S9: =O9*M9 | T9: =O9*N9
A10: Colts (1 year) | B10: 0 | C10: 0 | H10: 0 | I10: 0 | L10: =B10+C10-H10 | M10: =L10-B10 | N10: =C10 | O10: 0 | P10: =O10*K10 | R10: 0 | S10: =O10*M10 | T10: =O10*N10
A11: Foals | B11: 0 | C11: 0 | H11: 0 | I11: 0 | L11: =B11+C11-H11 | M11: =L11-B11 | N11: =C11 | O11: 0 | P11: =O11*K11 | R11: 0 | S11: =O11*M11 | T11: =O11*N11
A12: Oxen | B12: 45 | C12: 8 | H12: 7 | I12: 5 | L12: =B12+C12-H12 | M12: =L12-B12 | N12: =C12 | O12: 0.37857143 | P12: =O12*K12 | R12: 2.65 | S12: =O12*M12 | T12: =O12*N12
A13: Bulls | B13: 2 | C13: 0 | H13: 0 | I13: 0 | L13: =B13+C13-H13 | M13: =L13-B13 | N13: =C13 | O13: 0 | P13: =O13*K13 | R13: 0 | S13: =O13*M13 | T13: =O13*N13
A14: Cows | B14: 30 | C14: 15 | H14: 10 | I14: 6 | L14: =B14+C14-H14 | M14: =L14-B14 | N14: =C14 | O14: 0.28 | P14: =O14*K14 | R14: 2.8 | S14: =O14*M14 | T14: =O14*N14
A15: Steers | B15: 5 | C15: 0 | H15: 0 | I15: 0 | L15: =B15+C15-H15 | M15: =L15-B15 | N15: =C15 | O15: 0 | P15: =O15*K15 | R15: 0 | S15: =O15*M15 | T15: =O15*N15
A16: Bullocks | B16: 5 | C16: 0 | H16: 0 | I16: 1 | L16: =B16+C16-H16 | M16: =L16-B16 | N16: =C16 | O16: 0 | P16: =O16*K16 | R16: 0 | S16: =O16*M16 | T16: =O16*N16
... A20: Rams | B20: 5 | C20: 0 | H20: 0 | I20: 1 | L20: =B20+C20-H20 | M20: =L20-B20 | N20: =C20 | O20: 0 | P20: =O20*K20 | R20: 0 | S20: =O20*M20 | T20: =O20*N20
A21: Ewes | B21: 208 | C21: 0 | H21: 20 | I21: 12 | L21: =B21+C21-H21 | M21: =L21-B21 | N21: =C21 | O21: 0.0665 | P21: =O21*K21 | Q21: 0 | R21: 1.33 | S21: =O21*M21 | T21: =O21*N21
A22: Hoggs | B22: 121 | C22: 0 | H22: 19 | I22: 8 | L22: =B22+C22-H22 | M22: =L22-B22 | N22: =C22 | O22: 0.041578947 | P22: =O22*K22 | R22: 0.79 | S22: =O22*M22 | T22: =O22*N22
A23: Lambs | B23: 110 | C23: 177 | H23: 20 | I23: 30 | L23: =B23+C23-H23 | M23: =L23-B23 | N23: =C23 | O23: 0.0265 | P23: =O23*K23 | R23: 0.53 | S23: =O23*M23 | T23: =O23*N23
A24: Boars | B24: 2 | C24: 0 | H24: 0 | I24: 1 | L24: =B24+C24-H24 | M24: =L24-B24 | N24: =C24 | O24: 0 | P24: =O24*K24 | R24: 0 | S24: =O24*M24 | T24: =O24*N24
A25: Sows | B25: 2 | C25: 0 | H25: 0 | I25: 4 | L25: =B25+C25-H25 | M25: =L25-B25 | N25: =C25 | O25: 0 | P25: =O25*K25 | R25: 0 | S25: =O25*M25 | T25: =O25*N25
A26: Pigs | B26: 112 | C26: 0 | H26: 8 | I26: 13 | L26: =B26+C26-H26 | M26: =L26-B26 | N26: =C26 | O26: 0.15 | P26: =O26*K26 | R26: 1.2 | S26: =O26*M26 | T26: =O26*N26
A27: Hoggets | B27: 40 | C27: 0 | H27: 0 | I27: 15 | L27: =B27+C27-H27 | M27: =L27-B27 | N27: =C27 | O27: 0 | P27: =O27*K27 | R27: 0 | S27: =O27*M27 | T27: =O27*N27
A28: Piglets | B28: 40 | C28: 45 | H28: 0 | I28: 1 | L28: =B28+C28-H28 | M28: =L28-B28 | N28: =C28 | O28: 0 | P28: =O28*K28 | R28: 0 | S28: =O28*M28 | T28: =O28*N28
A29: Swans | B29: 0 | C29: 0 | H29: 0 | I29: 0 | L29: =B29+C29-H29 | M29: =L29-B29 | N29: =C29 | O29: 0 | P29: =O29*K29 | R29: 0 | S29: =O29*M29 | T29: =O29*N29
A30: Peacocks | B30: 0 | C30: 0 | H30: 0 | I30: 0 | L30: =B30+C30-H30 | M30: =L30-B30 | N30: =C30 | O30: 0 | P30: =O30*K30 | R30: 0 | S30: =O30*M30 | T30: =O30*N30
A31: Total Value
A34: Wool | B34: 0 | C34: 0 | H34: 0 | I34: 0
A35: Coarse wool | B35: 0 | C35: 0 | H35: 0 | I35: 0
A36: Lamb's wool | B36: 0 | C36: 0 | H36: 0 | I36: 0
A37: Wool locks | B37: 0 | C37: 0 | H37: 0 | I37: 0
A38: Wool sold at shearing | B38: 0 | C38: 0 | H38: 0 | I38: 0
A39: Total wool | B39: 0 | C39: 0 | H39: 0 | I39: 0
B40: 0 | C40: 0 | H40: 0 | I40: 0
B41: 0 | C41: 0 | H41: 0 | I41: 0
A42: Hides | B42: 0 | C42: 0 | H42: 0 | I42: 0
A43: Ox hides | B43: 0 | C43: 0 | H43: 0 | I43: 0
A44: Mare | B44: 0 | C44: 0 | H44: 0 | I44: 0
A45: Steer | B45: 0 | C45: 0 | H45: 0 | I45: 0
A46: calves | B46: 8 | C46: 8 | H46: 0 | I46: 0
...

Sheet raw data
A1: Heading | B1: Sentence | C1: Total in Pounds | D1: Pounds | E1: Shillings | F1: Pence | G1: Corn | H1: Total Quarters Except 1 | I1: Total Bushels Except 1 | J1: Total Corn Cross-Check | K1: Total Corn Manorial Account | L1: Corn Quantity Error | M1: Quarters 1 | N1: Bushels 1 | O1: Quarters 2 | P1: Bushels 2 | Q1: Quarters 3 | R1: Bushels 3 | S1: Quarters 4 | T1: Bushels 4 | U1: Quarters 5 | V1: Bushels 5 | W1: Quarters 6 | X1: Bushels 6 | Y1: Quarters 7 | Z1: Bushels 7 | AA1: Quarters 8 | AB1: Bushels 8 | AC1: Quarters 9 | AD1: Bushels 9 | AE1: Quarters 10 | AF1: Bushels 10 | AG1: shilling a quarter 1 | AH1: pence a quarter 1 | AI1: shilling a quarter 2 | AJ1: pence a quarter 2 | AK1: shilling a quarter 3 | AL1: pence a quarter 3 | AM1: shilling a quarter 4 | AN1: pence a quarter 4 | AO1: shilling a bushel 1 | AP1: pence a bushel 1 | AQ1: shilling a bushel 2 | AR1: pence a bushel 2 | AS1: shilling a bushel 3 | AT1: pence a bushel 3 | AU1: shilling a bushel 4 | AV1: pence a bushel 4
A2: ivinghoe | B2: the account of the same for the sixth year of the translation of henry beaufort', lord bishop of winchester, and the eleventh year of the reign of king henry the fourth after the conquest. | C2: 0 | D2: 0 | E2: 0 | F2: 0 | H2: 0 | I2: 0 | J2: 0 | K2: 0 | L2: 0 | M2: 0 | N2: 0
A3: arrears | B3: richard baldewyn, reeve there, answers for £8 19 shilling 6pence of the arrears of john hoke from his last account of the preceding year. | C3: 8.97 | D3: 8 | E3: 19 | F3: 6 | H3: 0 | I3: 0 | J3: 0 | K3: 0 | L3: 0 | M3: 0 | N3: 0
A4: arrears | B4: total, £8 19 shilling 6pence. | C4: 8.97 | D4: 8 | E4: 19 | F4: 6 | H4: 0 | I4: 0 | J4: 0 | K4: 0 | L4: 0 | M4: 0 | N4: 0
A5: rents of assize | B5: and for £6 14 shilling 11.75pence for all rents of assize at christmas. | C5: 6.75 | D5: 6 | E5: 14 | F5: 11.75 | H5: 0 | I5: 0 | J5: 0 | K5: 0 | L5: 0 | M5: 0 | N5: 0
A6: rents of assize | B6: £6 15 shilling id. at the annunciation (25 march). | C6: 6.75 | D6: 6 | E6: 15 | F6: 0 | H6: 0 | I6: 0 | J6: 0 | K6: 0 | L6: 0 | M6: 0 | N6: 0
A7: rents of assize | B7: £6 14 shilling 113/id. at the nativity of st john the baptist (24 june). | C7: 6.7 | D7: 6 | E7: 14 | F7: 0 | H7: 0 | I7: 0 | J7: 0 | K7: 0 | L7: 0 | M7: 0 | N7: 0
A8: rents of assize | B8: £6 15 shilling 3.25pence at michaelmas (29 september). | C8: 6.76 | D8: 6 | E8: 15 | F8: 3.25 | H8: 0 | I8: 0 | J8: 0 | K8: 0 | L8: 0 | M8: 0 | N8: 0
A9: rents of assize | B9: 1pence for the increment of rent of simon edward' for 1 parcel of land of the lord's waste, 6 feet long and 3 feet wide, in the market of ivinghoe. | C9: 0 | D9: 0 | E9: 0 | F9: 1 | H9: 0 | I9: 0 | J9: 0 | K9: 0 | L9: 0 | M9: 0 | N9: 0
A10: rents of assize | B10: total, £27 3.75pence. | C10: 27.02 | D10: 27 | E10: 0 | F10: 3.75 | H10: 0 | I10: 0 | J10: 0 | K10: 0 | L10: 0 | M10: 0 | N10: 0
A11: quittances of rent | B11: in quittance of rent of 1 reeve for the year 5 shilling. | C11: 0.25 | D11: 0 | E11: 5 | F11: 0 | H11: 0 | I11: 0 | J11: 0 | K11: 0 | L11: 0 | M11: 0 | N11: 0
A12: quittances of rent | B12: 1 swineherd, nothing this year, because he has the lord's livery as made clear elsewhere. | C12: 0 | D12: 0 | E12: 0 | F12: 0 | H12: 0 | I12: 0 | J12: 0 | K12: 0 | L12: 0 | M12: 0 | N12: 0
A13: quittances of rent | B13: 5 customary ploughmen this year 15 shilling, or 3 shilling each. | C13: 0.75 | D13: 0 | E13: 15 | F13: 0 | H13: 0 | I13: 0 | J13: 0 | K13: 0 | L13: 0 | M13: 0 | N13: 0
... A68: issues of the manor | B68: total, £11 7 shilling 3.5pence. | C68: 11.36 | D68: 11 | E68: 7 | F68: 3.5 | H68: 0 | I68: 0 | J68: 0 | K68: 0 | L68: 0 | M68: 0 | N68: 0
A69: sale of corn and malt | B69: and for £8 18 shilling 6pence' from 22 quarters 2.5 bushels of wheat sold, at 8 shilling a quarters, as made clear elsewhere. | C69: 8.93 | D69: 8 | E69: 18 | F69: 6 | G69: wheat | H69: 22 | I69: 2.5 | J69: 22.31 | K69: 22.31 | L69: 0 | M69: 22 | N69: 2.5 | AG69: 8 | AH69: 0
A70: sale of corn and malt | B70: £4 12 shilling 4pence from 34 quarters 5 bushels of oats sold, at 2 shilling 8pence a quarters, as made clear elsewhere, of which 4 quarters 4 bushels sold to the lord's household. | C70: 4.62 | D70: 4 | E70: 12 | F70: 4 | G70: oats | H70: 4 | I70: 4 | J70: 4.5 | K70: 34.62 | L70: -30.12 | M70: 34 | N70: 5 | O70: 4 | P70: 4 | AG70: 2 | AH70: 8
A71: sale of corn and malt | B71: £24 7 shilling 4pence from 80 quarters 3 bushels 1 peck of malt sold, of which 71 quarters sold to the lord's household at esher, at 6. | C71: 24.37 | D71: 24 | E71: 7 | F71: 4 | G71: malt | H71: 71 | I71: 3 | J71: 71.38 | K71: 80.38 | L71: -9 | M71: 80 | N71: 3 | O71: 71 | P71: 0
A72: sale of corn and malt | B72: a quarters, and 9 quarters 3 bushels 1 peck, at 6 shilling 8pence a quarters. | C72: 0.33 | D72: 0 | E72: 6 | F72: 8 | H72: 9 | I72: 3 | J72: 9.38 | K72: 9.38 | L72: 0 | M72: 9 | N72: 3 | AG72: 6 | AH72: 8
A73: sale of corn and malt | B73: total, £37 18 shilling 2pence. | C73: 37.91 | D73: 37 | E73: 18 | F73: 2 | H73: 0 | I73: 0 | J73: 0 | K73: 0 | L73: 0 | M73: 0 | N73: 0
A74: sale of stock | B74: and for 15 shilling from 2 plough-horses sold as made clear elsewhere, at 10 shilling for 1, and 5 shilling for 1. | C74: 0.75 | D74: 0 | E74: 15 | F74: 0 | H74: 0 | I74: 0 | J74: 0 | K74: 0 | L74: 0 | M74: 0 | N74: 0
A75: sale of stock | B75: £2 13 shilling from 7 kebb oxen sold as made clear elsewhere, at 8 shilling each for 6, and 5s, for 1. | C75: 2.65 | D75: 2 | E75: 13 | F75: 0 | H75: 0 | I75: 0 | J75: 0 | K75: 0 | L75: 0 | M75: 0 | N75: 0
A76: sale of stock | B76: £2 16 shilling from 10 kebb cows sold before calving, at 6 shilling each for 6, and 5 shilling each for 4. | C76: 2.8 | D76: 2 | E76: 16 | F76: 0 | H76: 0 | I76: 0 | J76: 0 | K76: 0 | L76: 0 | M76: 0 | N76: 0
A77: sale of stock | B77: £2 5 shilling from 30 kebb wethers sold before shearing as made clear elsewhere, at 1 shilling 6pence each. | C77: 2.25 | D77: 2 | E77: 5 | F77: 0 | H77: 0 | I77: 0 | J77: 0 | K77: 0 | L77: 0 | M77: 0 | N77: 0
A78: sale of stock | B78: £2 from 30 kebb wethers sold after shearing as made clear elsewhere, 2 of them to the lord's household, at 1 shilling 4pence each. | C78: 2 | D78: 2 | E78: 0 | F78: 0 | H78: 0 | I78: 0 | J78: 0 | K78: 0 | L78: 0 | M78: 0 | N78: 0
A79: sale of stock | B79: £1 6 shilling 8pence from 20 kebb ewes sold as made clear elsewhere, at 1 shilling 4pence each. | C79: 1.33 | D79: 1 | E79: 6 | F79: 8 | H79: 0 | I79: 0 | J79: 0 | K79: 0 | L79: 0 | M79: 0 | N79: 0
A80: sale of stock | B80: 15 shilling 10pence from 19 hoggs, removed from stock and rejected for fear of murrain, sold after shearing as made clear elsewhere, at 10pence each. | C80: 0.79 | D80: 0 | E80: 15 | F80: 10 | H80: 0 | I80: 0 | J80: 0 | K80: 0 | L80: 0 | M80: 0 | N80: 0
A81: sale of stock | B81: 10 shilling from 20 lambs sold, removed from stock and rotted, at 6pence each. | C81: 0.53 | D81: 0 | E81: 10 | F81: 6 | H81: 0 | I81: 0 | J81: 0 | K81: 0 | L81: 0 | M81: 0 | N81: 0
A82: sale of stock | B82: £1 4 shilling from 8 pigs sold as made clear elsewhere, at 3 shilling each. | C82: 1.2 | D82: 1 | E82: 4 | F82: 0 | H82: 0 | I82: 0 | J82: 0 | K82: 0 | L82: 0 | M82: 0 | N82: 0
A83: sale of stock | B83: total, £14 5 shilling 6pence. | C83: 14.28 | D83: 14 | E83: 5 | F83: 6 | H83: 0 | I83: 0 | J83: 0 | K83: 0 | L83: 0 | M83: 0 | N83: 0
A84: sale of wood | B84: and for £6 1 shilling 6pence from wood from ivinghoe sold this year. | C84: 6.08 | D84: 6 | E84: 1 | F84: 6 | H84: 0 | I84: 0 | J84: 0 | K84: 0 | L84: 0 | M84: 0 | N84: 0
... A89: farm of the mill | B89: total, £1 4pence. | C89: 1.02 | D89: 1 | E89: 0 | F89: 4 | H89: 0 | I89: 0 | J89: 0 | K89: 0 | L89: 0 | M89: 0 | N89: 0
A90: sale of labour services | B90: and for 21 pence for the labour service of sowing wheat sold this year as made clear elsewhere. | C90: 0.09 | D90: 0 | E90: 0 | F90: 21 | G90: wheat | H90: 0 | I90: 0 | J90: 0 | K90: 0 | L90: 0 | M90: 0 | N90: 0
A91: sale of labour services | B91: £2 9 shilling 2pence for release of the labour services and service of robert palmere for 4 virgates of land at le fourhous, on top of the ancient rent of 17 shilling 6pence. | C91: 2.46 | D91: 2 | E91: 9 | F91: 2 | H91: 0 | I91: 0 | J91: 0 | K91: 0 | L91: 0 | M91: 0 | N91: 0
A92: sale of labour services | B92: total, £2 9 shilling 4.5pence. | C92: 2.47 | D92: 2 | E92: 9 | F92: 4.5 | H92: 0 | I92: 0 | J92: 0 | K92: 0 | L92: 0 | M92: 0 | N92: 0
A93: annual recognizance | B93: and for 2pence for the annual recognizance of robert taillour so that he may dwell within the liberty and come to the tourn of hockday. | C93: 0.01 | D93: 0 | E93: 0 | F93: 2 | H93: 0 | I93: 0 | J93: 0 | K93: 0 | L93: 0 | M93: 0 | N93: 0
A94: annual recognizance | B94: 2pence from hugh graston' for similar. | C94: 0.01 | D94: 0 | E94: 0 | F94: 2 | H94: 0 | I94: 0 | J94: 0 | K94: 0 | L94: 0 | M94: 0 | N94: 0
A95: annual recognizance | B95: 3pence from thomas hale for similar. | C95: 0.01 | D95: 0 | E95: 0 | F95: 3 | H95: 0 | I95: 0 | J95: 0 | K95: 0 | L95: 0 | M95: 0 | N95: 0
A96: annual recognizance | B96: 8pence from robert, son of john hook', the lord's villein, so that he may dwell outside the lord's liberty and come to the toum of hockday for the year and remain the lord's villein as before. | C96: 0.03 | D96: 0 | E96: 0 | F96: 8 | H96: 0 | I96: 0 | J96: 0 | K96: 0 | L96: 0 | M96: 0 | N96: 0
A97: annual recognizance | B97: 8pence from john, son of john sawell', the lord's villein, for the same. | C97: 0.03 | D97: 0 | E97: 0 | F97: 8 | H97: 0 | I97: 0 | J97: 0 | K97: 0 | L97: 0 | M97: 0 | N97: 0
A98: annual recognizance | B98: nothing of the 3pence from robert verdon' because he is dead as established by the court roll. | C98: 0.01 | D98: 0 | E98: 0 | F98: 3 | H98: 0 | I98: 0 | J98: 0 | K98: 0 | L98: 0 | M98: 0 | N98: 0
...

Sheet Receipts
A1: IVINGHOE RECEIPTS
A2: Heading | B2: £ | C2: s | D2: d | F2: Total in £ | G2: Error | H2: Notes | I2: Own notes
A3: Arrears | B3: 8 | C3: 19 | D3: 6 | F3: 8.97 | H3: Richard Baldewyn, reeve there, answers for £8 19 shilling 6pence of the arrears of John Hoke from his last account of the preceding year.
A4: Arrears | B4: 8 | C4: 19 | D4: 6 | F4: 8.97 | H4: Total, £8 19 shilling 6pence.
A5: Arrears total | F5: 8.97 | G5: 0 | H5: Total
A7: Rents of assize | B7: 6 | C7: 14 | D7: 11.75 | F7: 6.75 | H7: And for £6 14 shilling 11.75pence for all rents of assize at Christmas.
A8: Rents of assize | B8: 6 | C8: 15 | D8: 0 | F8: 6.75 | H8: £6 15 shilling Id. at the Annunciation (25 March).
A9: Rents of assize | B9: 6 | C9: 14 | D9: 0 | F9: 6.7 | H9: £6 14 shilling 113/id. at the Nativity of St John the Baptist (24 June).
A10: Rents of assize | B10: 6 | C10: 15 | D10: 3.25 | F10: 6.76 | H10: £6 15 shilling 3.25pence at Michaelmas (29 September).
A11: Rents of assize | B11: 0 | C11: 0 | D11: 1 | F11: 0 | H11: 1pence for the increment of rent of Simon Edward' for 1 parcel of land of the lord's waste, 6 feet long and 3 feet wide, in the market of Ivinghoe.
A12: Rents of assize | B12: 27 | C12: 0 | D12: 3.75 | F12: 27.02 | H12: Total, £27 3.75pence.
A13: Rents of assize total | F13: 26.96 | G13: -0.06 | H13: Total
A15: Defaults of rent | B15: 0 | C15: 18 | D15: 0 | F15: 0.9 | H15: In default of the earl of Salisbury at Gaddesden, 18 shilling for the year, because Bishop Godfrey gave that land with the tenements to the said earl as made clear in the custumal of Ivinghoe.
A16: Defaults of rent | B16: 0 | C16: 18 | D16: 0 | F16: 0.9 | H16: Total, 18 shilling.
A17: Defaults of rent total | F17: 0.9 | G17: 0 | H17: Total
A19: Total of quittances and defaults of rent | B19: 5 | C19: 6 | D19: 11 | F19: 5.35 | H19: Total of quittances and defaults of rent, £5 6 shilling 11pence.
A20: Total of quittances and defaults of rent total | F20: 5.35 | G20: 0 | H20: Total
A22: Total of rents remaining clear | B22: 21 | C22: 13 | D22: 5.75 | F22: 21.67 | H22: Total of rents remaining clear, £21 13 shilling 5.75pence.
A23: Total of rents remaining clear total | F23: 21.67 | G23: 0 | H23: Total
A25: Issues of the manor | B25: 0 | C25: 6 | D25: 0 | F25: 0.3 | H25: And for 6 shilling 7.5d from the pannage of the pigs of the customary tenants at Martinmas.
A26: Issues of the manor | B26: 0 | C26: 0 | D26: 0 | F26: 0 | H26: nothing from the pannage of foreign pigs in the lord’s wood this year because there was no mast.
A27: Issues of the manor | B27: 0 | C27: 0 | D27: 0 | F27: 0 | H27: nothing from ploughing shared out (particat') this year for the reason made clear elsewhere.
A28: Issues of the manor | B28: 0 | C28: 4 | D28: 6 | F28: 0.23 | H28: 4 shilling 6pence from beasts agisted in the pasture and grove between Michaelmas and Martinmas.
A29: Issues of the manor | B29: 0 | C29: 0 | D29: 0 | F29: 0 | H29: nothing from the pasturage of cattle and sheep before theploughing at fallow-time nor from the agistment of cattle in the pasture and grove from Hockday until the Nativity of St John the Baptist because they are grazed with the lord's cattle this year.
A30: Issues of the manor | B30: 0 | C30: 0 | D30: 0 | F30: 0 | H30: nothing from the agistment of cattle there from then until Michaelmas this year.
A31: Issues of the manor | B31: 0 | C31: 2 | D31: 6 | F31: 0.12 | H31: 2 shilling from 4 oxen agisted with the lord's oxen from then until Michaelmas this year, giving 6pence a head.
A32: Issues of the manor | B32: 0 | C32: 2 | D32: 6 | F32: 0.12 | H32: 2 shilling from 4 cows agisted in the pasture and grove with the lord's cows from then until Michaelmas this year, giving 6pence a head.
A33: Issues of the manor | B33: 0 | C33: 0 | D33: 0 | F33: 0 | H33: nothing from the agistment of cows and calves in the barbican nor from cattle in the pasture of Carsewyk' nor from the agistment of lambs in the pasture this year because they are grazed with the lord's lambs and oxen.
A34: Issues of the manor | B34: 0 | C34: 0 | D34: 0 | F34: 0 | H34: nothing from the beadle's pasture this year because it is grazed with the lord's cattle.
A35: Issues of the manor | B35: 0 | C35: 0 | D35: 0 | F35: 0 | H35: nothing from nettles in the garden this year.
A36: Issues of the manor | B36: 0 | C36: 4 | D36: 0 | F36: 0.2 | H36: 4 shilling from hay sold to the lord's household.
... A54: Issues of the manor | B54: 11 | C54: 7 | D54: 3.5 | F54: 11.36 | H54: Total, £11 7 shilling 3.5pence.
A55: Issues of the manor total | F55: 10.98 | G55: -0.38 | H55: Total
A57: Sale of stock | B57: 0 | C57: 15 | D57: 0 | F57: 0.75 | H57: And for 15 shilling from 2 plough-horses sold as made clear elsewhere, at 10 shilling for 1, and 5 shilling for 1.
A58: Sale of stock | B58: 2 | C58: 13 | D58: 0 | F58: 2.65 | H58: £2 13 shilling from 7 kebb oxen sold as made clear elsewhere, at 8 shilling each for 6, and 5s, for 1.
A59: Sale of stock | B59: 2 | C59: 16 | D59: 0 | F59: 2.8 | H59: £2 16 shilling from 10 kebb cows sold before calving, at 6 shilling each for 6, and 5 shilling each for 4.
A60: Sale of stock | B60: 2 | C60: 5 | D60: 0 | F60: 2.25 | H60: £2 5 shilling from 30 kebb wethers sold before shearing as made clear elsewhere, at 1 shilling 6pence each.
A61: Sale of stock | B61: 2 | C61: 0 | D61: 0 | F61: 2 | H61: £2 from 30 kebb wethers sold after shearing as made clear elsewhere, 2 of them to the lord's household, at 1 shilling 4pence each.
A62: Sale of stock | B62: 1 | C62: 6 | D62: 8 | F62: 1.33 | H62: £1 6 shilling 8pence from 20 kebb ewes sold as made clear elsewhere, at 1 shilling 4pence each.
A63: Sale of stock | B63: 0 | C63: 15 | D63: 10 | F63: 0.79 | H63: 15 shilling 10pence from 19 hoggs, removed from stock and rejected for fear of murrain, sold after shearing as made clear elsewhere, at 10pence each.
...

Sheet Stock
A1: Heading | B1: Sentence | C1: Quarters 1 | D1: Bushels 1 | E1: stock | F1: inherited stock | G1: added | H1: murrain | I1: sold
A2: Oats | B2: Total | C2: 0 | D2: 0
A3: Stock | B3: Horses: 8 remain. | C3: 0 | D3: 0 | F3: 8
A4: Stock | B4: 1 bought. | C4: 0 | D4: 0 | G4: 1
A5: Stock | B5: Total, 9. 2 in murrain. | C5: 0 | D5: 0 | H5: 2
A6: Stock | B6: Total, 2. 7 remain, of which 1 is for the horse-mill. | C6: 0 | D6: 0
A7: Stock | B7: Plough-horses: 1 from the heriot of Edward Hastyng'. | C7: 0 | D7: 0 | E7: Plough-horses
A8: Stock | B8: 1 from the heriot of Simon Edward'. | C8: 0 | D8: 0 | E8: Plough-horses
A9: Stock | B9: Total, 2. Sold within. | C9: 0 | D9: 0 | E9: Plough-horses
A10: Stock | B10: none remain. | C10: 0 | D10: 0 | E10: Plough-horses
A11: Stock | B11: Oxen: 45 remain. | C11: 0 | D11: 0 | E11: Oxen | F11: 45
A12: Stock | B12: 1 from the heriot of John Claverley. | C12: 0 | D12: 0 | E12: Oxen
A13: Stock | B13: 1 from the heriot of John Stoneherd'. | C13: 0 | D13: 0 | E13: Oxen
A14: Stock | B14: 8 bought. | C14: 0 | D14: 0 | E14: Oxen | G14: 8
A15: Stock | B15: 2 added from steers. | C15: 0 | D15: 0 | E15: Oxen
A16: Stock | B16: Total, 57. 5 in murrain. | C16: 0 | D16: 0 | E16: Oxen | H16: 5
A17: Stock | B17: 7 kebbs sold within. | C17: 0 | D17: 0 | E17: Oxen | I17: 7
A18: Stock | B18: Total, 12. 45 remain. | C18: 0 | D18: 0 | E18: Oxen
A19: Stock | B19: Bulls: 2 remain. | C19: 0 | D19: 0 | E19: Bulls | F19: 2
A20: Stock | B20: Total, 2. 2 remain. | C20: 0 | D20: 0 | E20: Bulls
A21: Stock | B21: Cows: 30 remain. | C21: 0 | D21: 0 | E21: Cows | F21: 30
A22: Stock | B22: 15 bought. | C22: 0 | D22: 0 | E22: Cows | G22: 15
A23: Stock | B23: nothing here of the 1 cow from the heriot of Thomas Lord because it is in the hands of John Brigford' and is unable to be seized because it is outside the liberty of the lord. | C23: 0 | D23: 0 | E23: Cows
A24: Stock | B24: 3 added from steers. | C24: 0 | D24: 0 | E24: Cows
A25: Stock | B25: Total, 48. 6 in murrain before calving. | C25: 0 | D25: 0 | E25: Cows | H25: 6
A26: Stock | B26: 10 kebbs with calf sold within. | C26: 0 | D26: 0 | E26: Cows | I26: 10
A27: Stock | B27: Total, 16. 221 remain. | C27: 0 | D27: 0 | E27: Cows
A28: Stock | B28: Steers: 5 remain from the bullocks. | C28: 0 | D28: 0 | E28: Steers | F28: 5
A29: Stock | B29: Total, 5. 2 added above to oxen and 3 to cows. | C29: 0 | D29: 0 | E29: Steers
A30: Stock | B30: Total as before. | C30: 0 | D30: 0 | E30: Steers
A31: Stock | B31: None remain. | C31: 0 | D31: 0 | E31: Steers
A32: Stock | B32: Bullocks: 5 remain from the yearlings. | C32: 0 | D32: 0 | E32: Bullocks | F32: 5
A33: Stock | B33: Total, 5. 1 in murrain. | C33: 0 | D33: 0 | E33: Bullocks | H33: 1
A34: Stock | B34: 4 remain. | C34: 0 | D34: 0 | E34: Bullocks
A35: Stock | B35: Yearlings: 8 remain from the calves. | C35: 0 | D35: 0 | E35: Yearlings | F35: 8
A36: Stock | B36: Total, 8. 1 in murrain. | C36: 0 | D36: 0 | E36: Yearlings | H36: 1
A37: Stock | B37: 7 remain. | C37: 0 | D37: 0 | E37: Yearlings
A38: Stock | B38: Calves: 8 bought from the farmer of the dairy. | C38: 0 | D38: 0 | E38: Calves | G38: 8
A39: Stock | B39: Total, 8. 8 remain. | C39: 0 | D39: 0 | E39: Calves | F39: 8
A40: Stock | B40: Wethers: 318 remain. | C40: 0 | D40: 0 | E40: Wethers | F40: 318
...

Sheet Overview

Sheet Issues of the Mills

Sheet Prices

Sheet Labour Rents

Sheet not needed

Sheet Issues of the Grange raw
A1: Heading | B1: Sentence | C1: Quarters 1_x | D1: Bushels 1_x | E1: Sown Quarters | F1: Sown Bushels | G1: Sown Total Quarters | H1: Bought in Quarters | I1: Bought in Bushels | J1: Bought in Total Quarters | K1: Tithe Quarters | L1: Tithe Bushels | M1: Tithe Total Quarters | N1: Manorial servants & livestock Quarters | O1: Manorial servants & livestock Bushels | P1: Manorial servants & livestock Total Quarters | Q1: Sold Quarters | R1: Sold Bushels | S1: Sold Total Quarters | T1: Account Quarters | U1: Account Bushels | V1: Account Total Quarters | W1: bought only | X1: Total Quarters Except 1 | Y1: Total Bushels Except 1 | Z1: Total Corn Cross-Check | AA1: Total Corn Manorial Account | AB1: Corn Quantity Error | AC1: Quarters 1_y | AD1: Bushels 1_y | AE1: Quarters 2 | AF1: Bushels 2 | AG1: Quarters 3 | AH1: Bushels 3 | AI1: Quarters 4 | AJ1: Bushels 4 | AK1: Quarters 5 | AL1: Bushels 5 | AM1: Quarters 6 | AN1: Bushels 6 | AO1: Quarters 7 | AP1: Bushels 7 | AQ1: Quarters 8 | AR1: Bushels 8 | AS1: Quarters 9 | AT1: Bushels 9 | AU1: Quarters 10 | AV1: Bushels 10 | AW1: Total Bought Quarters
A2: and he owes | B2: total | C2: 0 | D2: 0 | E2: 0 | F2: 0 | G2: 0 | H2: 0 | I2: 0 | J2: 0 | K2: 0 | L2: 0 | M2: 0 | N2: 0 | O2: 0 | P2: 0 | Q2: 0 | R2: 0 | S2: 0 | T2: 0 | U2: 0 | V2: 0 | W2: 0 | AW2: 0
A3: wheat | B3: richard baldewyn, reeve there, answers for 34 quarters of wheat from the whole issue of the grange, threshed by piece-work. | C3: 0 | D3: 0 | E3: 0 | F3: 0 | G3: 0 | H3: 0 | I3: 0 | J3: 0 | K3: 0 | L3: 0 | M3: 0 | N3: 0 | O3: 0 | P3: 0 | Q3: 0 | R3: 0 | S3: 0 | T3: 34 | U3: 0 | V3: 34 | W3: 0 | X3: 34 | Y3: 0 | Z3: 34 | AA3: 34 | AB3: 0 | AC3: 34 | AD3: 0 | AW3: 0
A4: wheat | B4: 13 quarters surcharged so that he answers for a 4-fold yield.. | C4: 0 | D4: 0 | E4: 0 | F4: 0 | G4: 0 | H4: 0 | I4: 0 | J4: 0 | K4: 0 | L4: 0 | M4: 0 | N4: 0 | O4: 0 | P4: 0 | Q4: 0 | R4: 0 | S4: 0 | T4: 0 | U4: 0 | V4: 0 | W4: 0 | X4: 13 | Y4: 0 | Z4: 13 | AA4: 13 | AB4: 0 | AC4: 13 | AD4: 0 | AW4: 0
A5: wheat | B5: total, 47 quarters. | C5: 0 | D5: 0 | E5: 0 | F5: 0 | G5: 0 | H5: 0 | I5: 0 | J5: 0 | K5: 0 | L5: 0 | M5: 0 | N5: 0 | O5: 0 | P5: 0 | Q5: 0 | R5: 0 | S5: 0 | T5: 0 | U5: 0 | V5: 0 | W5: 0 | X5: 47 | Y5: 0 | Z5: 47 | AA5: 47 | AB5: 0 | AC5: 47 | AD5: 0 | AW5: 0
A6: wheat | B6: sown over 36.5 acres of land by the perch which lie above le middelfeld', 10 quarters 2 bushels. | C6: 0 | D6: 0 | E6: 10 | F6: 2 | G6: 10.25 | H6: 0 | I6: 0 | J6: 0 | K6: 0 | L6: 0 | M6: 0 | N6: 0 | O6: 0 | P6: 0 | Q6: 0 | R6: 0 | S6: 0 | T6: 0 | U6: 0 | V6: 0 | W6: 0 | X6: 10 | Y6: 2 | Z6: 10.25 | AA6: 10.25 | AB6: 0 | AC6: 10 | AD6: 2 | AW6: 0
A7: wheat | B7: that is, 2 bushels 1 peck an acre, less .5 peck in all. | C7: 0 | D7: 0 | E7: 0 | F7: 0 | G7: 0 | H7: 0 | I7: 0 | J7: 0 | K7: 0 | L7: 0 | M7: 0 | N7: 0 | O7: 0 | P7: 0 | Q7: 0 | R7: 0 | S7: 0 | T7: 0 | U7: 0 | V7: 0 | W7: 0 | X7: 0 | Y7: 2 | Z7: 0.25 | AA7: 0.25 | AB7: 0 | AC7: 0 | AD7: 2 | AW7: 0
A8: wheat | B8: provision of the steward holding the tourns of martinmas and hockday, by 2 sealed bills, 3.5 bushels. | C8: 0 | D8: 0 | E8: 0 | F8: 0 | G8: 0 | H8: 0 | I8: 0 | J8: 0 | K8: 0 | L8: 0 | M8: 0 | N8: 0 | O8: 0 | P8: 0 | Q8: 0 | R8: 0 | S8: 0 | T8: 0 | U8: 0 | V8: 0 | W8: 0 | X8: 0 | Y8: 3.5 | Z8: 0.44 | AA8: 0.44 | AB8: 0 | AC8: 0 | AD8: 3.5 | AW8: 0
A9: wheat | B9: customary payment to the customary tenants mowing the lord's meadow, 1 qr. | C9: 0 | D9: 0 | E9: 0 | F9: 0 | G9: 0 | H9: 0 | I9: 0 | J9: 0 | K9: 0 | L9: 0 | M9: 0 | N9: 0 | O9: 0 | P9: 0 | Q9: 0 | R9: 0 | S9: 0 | T9: 0 | U9: 0 | V9: 0 | W9: 0 | AW9: 0
A10: wheat | B10: sold within, 22 quarters 2.5 bushels. | C10: 0 | D10: 0 | E10: 0 | F10: 0 | G10: 0 | H10: 0 | I10: 0 | J10: 0 | K10: 0 | L10: 0 | M10: 0 | N10: 0 | O10: 0 | P10: 0 | Q10: 22 | R10: 2.5 | S10: 22.31 | T10: 0 | U10: 0 | V10: 0 | W10: 0 | X10: 22 | Y10: 2.5 | Z10: 22.31 | AA10: 22.31 | AB10: 0 | AC10: 22 | AD10: 2.5 | AW10: 0
A11: wheat | B11: sold at the audit, 13 quarters for £4 6 shilling 8pence. | C11: 0 | D11: 0 | E11: 0 | F11: 0 | G11: 0 | H11: 0 | I11: 0 | J11: 0 | K11: 0 | L11: 0 | M11: 0 | N11: 0 | O11: 0 | P11: 0 | Q11: 13 | R11: 0 | S11: 13 | T11: 0 | U11: 0 | V11: 0 | W11: 0 | X11: 13 | Y11: 0 | Z11: 13 | AA11: 13 | AB11: 0 | AC11: 13 | AD11: 0 | AW11: 0
A12: wheat | B12: total as before. | C12: 0 | D12: 0 | E12: 0 | F12: 0 | G12: 0 | H12: 0 | I12: 0 | J12: 0 | K12: 0 | L12: 0 | M12: 0 | N12: 0 | O12: 0 | P12: 0 | Q12: 0 | R12: 0 | S12: 0 | T12: 0 | U12: 0 | V12: 0 | W12: 0 | X12: 0 | Y12: 0 | Z12: 0 | AA12: 0 | AB12: 0 | AC12: 0 | AD12: 0 | AW12: 0
A13: wheat | B13: it balances. | C13: 0 | D13: 0 | E13: 0 | F13: 0 | G13: 0 | H13: 0 | I13: 0 | J13: 0 | K13: 0 | L13: 0 | M13: 0 | N13: 0 | O13: 0 | P13: 0 | Q13: 0 | R13: 0 | S13: 0 | T13: 0 | U13: 0 | V13: 0 | W13: 0 | X13: 0 | Y13: 0 | Z13: 0 | AA13: 0 | AB13: 0 | AC13: 0 | AD13: 0 | AW13: 0
A14: wheat | B14: total | C14: 0 | D14: 0 | E14: 0 | F14: 0 | G14: 0 | H14: 0 | I14: 0 | J14: 0 | K14: 0 | L14: 0 | M14: 0 | N14: 0 | O14: 0 | P14: 0 | Q14: 0 | R14: 0 | S14: 0 | T14: 0 | U14: 0 | V14: 0 | W14: 0 | AW14: 0
A15: barley | B15: and for 68 quarters 2 bushels of barley from the whole issue of the grange, threshed by piece¬work. | C15: 0 | D15: 0 | E15: 0 | F15: 0 | G15: 0 | H15: 0 | I15: 0 | J15: 0 | K15: 0 | L15: 0 | M15: 0 | N15: 0 | O15: 0 | P15: 0 | Q15: 0 | R15: 0 | S15: 0 | T15: 68 | U15: 2 | V15: 68.25 | W15: 0 | X15: 68 | Y15: 2 | Z15: 68.25 | AA15: 68.25 | AB15: 0 | AC15: 68 | AD15: 2 | AW15: 0
A16: barley | B16: 6 quarters bought in the market for sowing. | C16: 0 | D16: 0 | E16: 0 | F16: 0 | G16: 0 | H16: 6 | I16: 0 | J16: 6 | K16: 0 | L16: 0 | M16: 0 | N16: 0 | O16: 0 | P16: 0 | Q16: 0 | R16: 0 | S16: 0 | T16: 0 | U16: 0 | V16: 0 | W16: 0 | X16: 6 | Y16: 0 | Z16: 6 | AA16: 6 | AB16: 0 | AC16: 6 | AD16: 0 | AW16: 0
A17: barley | B17: 12 quarters 6 bushels surcharged so that he answers for a 3-fold yield.. | C17: 0 | D17: 0 | E17: 0 | F17: 0 | G17: 0 | H17: 0 | I17: 0 | J17: 0 | K17: 0 | L17: 0 | M17: 0 | N17: 0 | O17: 0 | P17: 0 | Q17: 0 | R17: 0 | S17: 0 | T17: 0 | U17: 0 | V17: 0 | W17: 0 | X17: 12 | Y17: 6 | Z17: 12.75 | AA17: 12.75 | AB17: 0 | AC17: 12 | AD17: 6 | AW17: 0
A18: barley | B18: total, 87 quarters. | C18: 0 | D18: 0 | E18: 0 | F18: 0 | G18: 0 | H18: 0 | I18: 0 | J18: 0 | K18: 0 | L18: 0 | M18: 0 | N18: 0 | O18: 0 | P18: 0 | Q18: 0 | R18: 0 | S18: 0 | T18: 0 | U18: 0 | V18: 0 | W18: 0 | X18: 87 | Y18: 0 | Z18: 87 | AA18: 87 | AB18: 0 | AC18: 87 | AD18: 0 | AW18: 0
A19: barley | B19: sown over 40 acres of land by the perch which lie in le middelfeld', 20 quarters. | C19: 0 | D19: 0 | E19: 20 | F19: 0 | G19: 20 | H19: 0 | I19: 0 | J19: 0 | K19: 0 | L19: 0 | M19: 0 | N19: 0 | O19: 0 | P19: 0 | Q19: 0 | R19: 0 | S19: 0 | T19: 0 | U19: 0 | V19: 0 | W19: 0 | X19: 20 | Y19: 0 | Z19: 20 | AA19: 20 | AB19: 0 | AC19: 20 | AD19: 0 | AW19: 0
A20: barley | B20: that is, 4 bushels an acre. | C20: 0 | D20: 0 | E20: 0 | F20: 0 | G20: 0 | H20: 0 | I20: 0 | J20: 0 | K20: 0 | L20: 0 | M20: 0 | N20: 0 | O20: 0 | P20: 0 | Q20: 0 | R20: 0 | S20: 0 | T20: 0 | U20: 0 | V20: 0 | W20: 0 | X20: 0 | Y20: 4 | Z20: 0.5 | AA20: 0.5 | AB20: 0 | AC20: 0 | AD20: 4 | AW20: 0
A21: barley | B21: malting, 54 quarters 2 bushels. | C21: 0 | D21: 0 | E21: 0 | F21: 0 | G21: 0 | H21: 0 | I21: 0 | J21: 0 | K21: 0 | L21: 0 | M21: 0 | N21: 0 | O21: 0 | P21: 0 | Q21: 0 | R21: 0 | S21: 0 | T21: 0 | U21: 0 | V21: 0 | W21: 0 | X21: 54 | Y21: 2 | Z21: 54.25 | AA21: 54.25 | AB21: 0 | AC21: 54 | AD21: 2 | AW21: 0
A22: barley | B22: sold at the audit, 12 quarters 6 bushels for £2 18 shilling 9pence. | C22: 0 | D22: 0 | E22: 0 | F22: 0 | G22: 0 | H22: 0 | I22: 0 | J22: 0 | K22: 0 | L22: 0 | M22: 0 | N22: 0 | O22: 0 | P22: 0 | Q22: 12 | R22: 6 | S22: 12.75 | T22: 0 | U22: 0 | V22: 0 | W22: 0 | X22: 12 | Y22: 6 | Z22: 12.75 | AA22: 12.75 | AB22: 0 | AC22: 12 | AD22: 6 | AW22: 0
A23: barley | B23: total as before. | C23: 0 | D23: 0 | E23: 0 | F23: 0 | G23: 0 | H23: 0 | I23: 0 | J23: 0 | K23: 0 | L23: 0 | M23: 0 | N23: 0 | O23: 0 | P23: 0 | Q23: 0 | R23: 0 | S23: 0 | T23: 0 | U23: 0 | V23: 0 | W23: 0 | X23: 0 | Y23: 0 | Z23: 0 | AA23: 0 | AB23: 0 | AC23: 0 | AD23: 0 | AW23: 0
A24: barley | B24: it balances. | C24: 0 | D24: 0 | E24: 0 | F24: 0 | G24: 0 | H24: 0 | I24: 0 | J24: 0 | K24: 0 | L24: 0 | M24: 0 | N24: 0 | O24: 0 | P24: 0 | Q24: 0 | R24: 0 | S24: 0 | T24: 0 | U24: 0 | V24: 0 | W24: 0 | X24: 0 | Y24: 0 | Z24: 0 | AA24: 0 | AB24: 0 | AC24: 0 | AD24: 0 | AW24: 0
A25: barley | B25: total | C25: 0 | D25: 0 | E25: 0 | F25: 0 | G25: 0 | H25: 0 | I25: 0 | J25: 0 | K25: 0 | L25: 0 | M25: 0 | N25: 0 | O25: 0 | P25: 0 | Q25: 0 | R25: 0 | S25: 0 | T25: 0 | U25: 0 | V25: 0 | W25: 0 | AW25: 0
A26: dredge | B26: and for 29 quarters 4 bushels of dredge from the whole issue of the grange, threshed by piece-work. | C26: 0 | D26: 0 | E26: 0 | F26: 0 | G26: 0 | H26: 0 | I26: 0 | J26: 0 | K26: 0 | L26: 0 | M26: 0 | N26: 0 | O26: 0 | P26: 0 | Q26: 0 | R26: 0 | S26: 0 | T26: 29 | U26: 4 | V26: 29.5 | W26: 0 | X26: 29 | Y26: 4 | Z26: 29.5 | AA26: 29.5 | AB26: 0 | AC26: 29 | AD26: 4 | AW26: 0
A27: dredge | B27: 12 quarters 4 bushels surcharged so that he answers for a 4-fold yield. | C27: 0 | D27: 0 | E27: 0 | F27: 0 | G27: 0 | H27: 0 | I27: 0 | J27: 0 | K27: 0 | L27: 0 | M27: 0 | N27: 0 | O27: 0 | P27: 0 | Q27: 0 | R27: 0 | S27: 0 | T27: 0 | U27: 0 | V27: 0 | W27: 0 | X27: 12 | Y27: 4 | Z27: 12.5 | AA27: 12.5 | AB27: 0 | AC27: 12 | AD27: 4 | AW27: 0
A28: dredge | B28: total, 42 quarters. | C28: 0 | D28: 0 | E28: 0 | F28: 0 | G28: 0 | H28: 0 | I28: 0 | J28: 0 | K28: 0 | L28: 0 | M28: 0 | N28: 0 | O28: 0 | P28: 0 | Q28: 0 | R28: 0 | S28: 0 | T28: 0 | U28: 0 | V28: 0 | W28: 0 | X28: 42 | Y28: 0 | Z28: 42 | AA28: 42 | AB28: 0 | AC28: 42 | AD28: 0 | AW28: 0
A29: dredge | B29: sown over 20.5 acres of land by the perch which lie in le malme, 10 quarters 2 bushels. | C29: 0 | D29: 0 | E29: 10 | F29: 2 | G29: 10.25 | H29: 0 | I29: 0 | J29: 0 | K29: 0 | L29: 0 | M29: 0 | N29: 0 | O29: 0 | P29: 0 | Q29: 0 | R29: 0 | S29: 0 | T29: 0 | U29: 0 | V29: 0 | W29: 0 | X29: 10 | Y29: 2 | Z29: 10.25 | AA29: 10.25 | AB29: 0 | AC29: 10 | AD29: 2 | AW29: 0
A30: dredge | B30: that is, 4 bushels an acre. | C30: 0 | D30: 0 | E30: 0 | F30: 0 | G30: 0 | H30: 0 | I30: 0 | J30: 0 | K30: 0 | L30: 0 | M30: 0 | N30: 0 | O30: 0 | P30: 0 | Q30: 0 | R30: 0 | S30: 0 | T30: 0 | U30: 0 | V30: 0 | W30: 0 | X30: 0 | Y30: 4 | Z30: 0.5 | AA30: 0.5 | AB30: 0 | AC30: 0 | AD30: 4 | AW30: 0
A31: dredge | B31: malting, 19 quarters 2 bushels. | C31: 0 | D31: 0 | E31: 0 | F31: 0 | G31: 0 | H31: 0 | I31: 0 | J31: 0 | K31: 0 | L31: 0 | M31: 0 | N31: 0 | O31: 0 | P31: 0 | Q31: 0 | R31: 0 | S31: 0 | T31: 0 | U31: 0 | V31: 0 | W31: 0 | X31: 19 | Y31: 2 | Z31: 19.25 | AA31: 19.25 | AB31: 0 | AC31: 19 | AD31: 2 | AW31: 0
A32: dredge | B32: sold at the audit, 12 quarters 4 bushels for £2 10 shilling. | C32: 0 | D32: 0 | E32: 0 | F32: 0 | G32: 0 | H32: 0 | I32: 0 | J32: 0 | K32: 0 | L32: 0 | M32: 0 | N32: 0 | O32: 0 | P32: 0 | Q32: 12 | R32: 4 | S32: 12.5 | T32: 0 | U32: 0 | V32: 0 | W32: 0 | X32: 12 | Y32: 4 | Z32: 12.5 | AA32: 12.5 | AB32: 0 | AC32: 12 | AD32: 4 | AW32: 0
A33: dredge | B33: total as before. | C33: 0 | D33: 0 | E33: 0 | F33: 0 | G33: 0 | H33: 0 | I33: 0 | J33: 0 | K33: 0 | L33: 0 | M33: 0 | N33: 0 | O33: 0 | P33: 0 | Q33: 0 | R33: 0 | S33: 0 | T33: 0 | U33: 0 | V33: 0 | W33: 0 | X33: 0 | Y33: 0 | Z33: 0 | AA33: 0 | AB33: 0 | AC33: 0 | AD33: 0 | AW33: 0
A34: dredge | B34: it balances. | C34: 0 | D34: 0 | E34: 0 | F34: 0 | G34: 0 | H34: 0 | I34: 0 | J34: 0 | K34: 0 | L34: 0 | M34: 0 | N34: 0 | O34: 0 | P34: 0 | Q34: 0 | R34: 0 | S34: 0 | T34: 0 | U34: 0 | V34: 0 | W34: 0 | X34: 0 | Y34: 0 | Z34: 0 | AA34: 0 | AB34: 0 | AC34: 0 | AD34: 0 | AW34: 0
A35: dredge | B35: total | C35: 0 | D35: 0 | E35: 0 | F35: 0 | G35: 0 | H35: 0 | I35: 0 | J35: 0 | K35: 0 | L35: 0 | M35: 0 | N35: 0 | O35: 0 | P35: 0 | Q35: 0 | R35: 0 | S35: 0 | T35: 0 | U35: 0 | V35: 0 | W35: 0 | AW35: 0
A36: oats | B36: and for 36 quarters of oats from the whole issue of the grange, threshed by piece-work. | C36: 0 | D36: 0 | E36: 0 | F36: 0 | G36: 0 | H36: 0 | I36: 0 | J36: 0 | K36: 0 | L36: 0 | M36: 0 | N36: 0 | O36: 0 | P36: 0 | Q36: 0 | R36: 0 | S36: 0 | T36: 36 | U36: 0 | V36: 36 | W36: 0 | X36: 36 | Y36: 0 | Z36: 36 | AA36: 36 | AB36: 0 | AC36: 36 | AD36: 0 | AW36: 0
A37: oats | B37: 12 quarters from the same issue by estimation in sheaves. | C37: 0 | D37: 0 | E37: 0 | F37: 0 | G37: 0 | H37: 0 | I37: 0 | J37: 0 | K37: 0 | L37: 0 | M37: 0 | N37: 0 | O37: 0 | P37: 0 | Q37: 0 | R37: 0 | S37: 0 | T37: 0 | U37: 0 | V37: 0 | W37: 0 | X37: 12 | Y37: 0 | Z37: 12 | AA37: 12 | AB37: 0 | AC37: 12 | AD37: 0 | AW37: 0
A38: oats | B38: 39 quarters 3 bushels from the vill according to custom at the purification (2 february). | C38: 0 | D38: 0 | E38: 0 | F38: 0 | G38: 0 | H38: 0 | I38: 0 | J38: 0 | K38: 0 | L38: 0 | M38: 0 | N38: 0 | O38: 0 | P38: 0 | Q38: 0 | R38: 0 | S38: 0 | T38: 0 | U38: 0 | V38: 0 | W38: 0 | X38: 39 | Y38: 3 | Z38: 39.38 | AA38: 39.38 | AB38: 0 | AC38: 39 | AD38: 3 | AW38: 0
A39: oats | B39: 6 quarters surcharged so that he answers for a 3-fold yield. | C39: 0 | D39: 0 | E39: 0 | F39: 0 | G39: 0 | H39: 0 | I39: 0 | J39: 0 | K39: 0 | L39: 0 | M39: 0 | N39: 0 | O39: 0 | P39: 0 | Q39: 0 | R39: 0 | S39: 0 | T39: 0 | U39: 0 | V39: 0 | W39: 0 | X39: 6 | Y39: 0 | Z39: 6 | AA39: 6 | AB39: 0 | AC39: 6 | AD39: 0 | AW39: 0
A40: oats | B40: total, 93 quarters 3 bushels. | C40: 0 | D40: 0 | E40: 0 | F40: 0 | G40: 0 | H40: 0 | I40: 0 | J40: 0 | K40: 0 | L40: 0 | M40: 0 | N40: 0 | O40: 0 | P40: 0 | Q40: 0 | R40: 0 | S40: 0 | T40: 0 | U40: 0 | V40: 0 | W40: 0 | X40: 93 | Y40: 3 | Z40: 93.38 | AA40: 93.38 | AB40: 0 | AC40: 93 | AD40: 3 | AW40: 0
...

Sheet Issues of the Grange
A1: Gross Output | B1: Bought Only Aggregated | C1: Account Quarters | D1: Account Bushels | E1: Account Total Quarters | F1: Bought in Quarters | G1: Bought in Bushels | H1: Total Bought Quarters | I1: Sold Quarters | J1: Sold Bushels | K1: Sold Total Quarters | L1: Total Corn Quantity | M1: Difference Produced+Bought-Sold | N1: Weighted Average Price per Quarter | O1: Non-Weighted Average Price per Quarter | P1: Value of Total Production weighted | Q1: Value of Total Production unweighted
A2: and he owes | B2: 0 | C2: 0 | D2: 0 | E2: 0 | F2: 0 | G2: 0 | H2: 0 | I2: 0 | J2: 0 | K2: 0 | L2: 0 | M2: 0
A3: wheat | B3: 0 | C3: 34 | D3: 0 | E3: 34 | F3: 0 | G3: 0 | H3: 0 | I3: 22 | J3: 2.5 | K3: 22.31 | L3: 34 | M3: 11.69 | N3: 0.4 | O3: 0.4 | P3: 13.6 | Q3: 13.6
A4: barley | B4: 0 | C4: 68 | D4: 2 | E4: 68.25 | F4: 0 | G4: 0 | H4: 0 | I4: 12 | J4: 6 | K4: 12.75 | L4: 68.25 | M4: 55.5
A5: dredge | B5: 0 | C5: 29 | D5: 4 | E5: 29.5 | F5: 0 | G5: 0 | H5: 0 | I5: 12 | J5: 4 | K5: 12.5 | L5: 29.5 | M5: 17
A6: oats | B6: 0 | C6: 36 | D6: 0 | E6: 36 | F6: 0 | G6: 0 | H6: 0 | I6: 38 | J6: 9 | K6: 39.12 | L6: 36 | M6: -3.12 | N6: 0.13 | O6: 0.13 | P6: 4.8 | Q6: 4.8
A7: Mancorn | B7: 0 | C7: 0 | D7: 0 | E7: 0 | F7: 0 | G7: 0 | H7: 0 | I7: 0 | J7: 0 | K7: 0 | L7: 0 | M7: 0
A8: Maslin | B8: 0 | C8: 0 | D8: 0 | E8: 0 | F8: 0 | G8: 0 | H8: 0 | I8: 0 | J8: 0 | K8: 0 | L8: 0 | M8: 0
A9: First-grade malt | B9: 0 | C9: 0 | D9: 0 | E9: 0 | F9: 0 | G9: 0 | H9: 0 | I9: 0 | J9: 0 | K9: 0 | L9: 0 | M9: 0
A10: Second-grade malt | B10: 0 | C10: 0 | D10: 0 | E10: 0 | F10: 0 | G10: 0 | H10: 0 | I10: 0 | J10: 0 | K10: 0 | L10: 0 | M10: 0
A11: Peas | B11: 0 | C11: 0 | D11: 0 | E11: 0 | F11: 0 | G11: 0 | H11: 0 | I11: 0 | J11: 0 | K11: 0 | L11: 0 | M11: 0
A12: Oatmeal | B12: 0 | C12: 0 | D12: 0 | E12: 0 | F12: 0 | G12: 0 | H12: 0 | I12: 0 | J12: 0 | K12: 0 | L12: 0 | M12: 0
A13: Vetches | B13: 0 | C13: 0 | D13: 0 | E13: 0 | F13: 0 | G13: 0 | H13: 0 | I13: 0 | J13: 0 | K13: 0 | L13: 0 | M13: 0
A14: Rye | B14: 0 | C14: 0 | D14: 0 | E14: 0 | F14: 0 | G14: 0 | H14: 0 | I14: 0 | J14: 0 | K14: 0 | L14: 0 | M14: 0
A15: Malt | B15: 0 | C15: 0 | D15: 0 | E15: 0 | F15: 0 | G15: 0 | H15: 0 | I15: 0 | J15: 0 | K15: 0 | L15: 0 | M15: 0 | N15: 0.3 | O15: 0.3 | P15: 0 | Q15: 0
A16: Meal | B16: 0 | C16: 0 | D16: 0 | E16: 0 | F16: 0 | G16: 0 | H16: 0 | I16: 0 | J16: 0 | K16: 0 | L16: 0 | M16: 0
A17: Curall | B17: 0 | C17: 0 | D17: 0 | E17: 0 | F17: 0 | G17: 0 | H17: 0 | I17: 0 | J17: 0 | K17: 0 | L17: 0 | M17: 0

Sheet Sale of Corn Prices
A1: Heading | B1: Sentence | C1: Total in Pounds | D1: Pounds | E1: Shillings | F1: Pence | G1: Corn | H1: Total Quarters Except 1 | I1: Total Bushels Except 1 | J1: Total Corn Cross-Check | K1: Total Corn Manorial Account | L1: Corn Quantity Error | M1: Quarters 0 | N1: Bushels 0 | O1: shilling a quarter 1 | P1: pence a quarter 1 | Q1: Quarters 1 | R1: Bushels 1 | S1: shilling a quarter 2 | T1: pence a quarter 2 | U1: Quarters 2 | V1: Bushels 2 | W1: shilling a quarter 3 | X1: pence a quarter 3 | Y1: Quarters 3 | Z1: Bushels 3 | AA1: shilling a quarter 4 | AB1: pence a quarter 4 | AC1: Quarters 4 | AD1: Bushels 4 | AE1: Quarters 5 | AF1: Bushels 5 | AG1: Quarters 6 | AH1: Bushels 6 | AI1: Quarters 7 | AJ1: Bushels 7 | AK1: Quarters 8 | AL1: Bushels 8 | AM1: Quarters 9 | AN1: Bushels 9 | AO1: £ a quarter 1 | AP1: £ a quarter 2 | AQ1: £ a quarter 3 | AR1: £ a quarter 4 | AS1: Quarters Sold | AT1: Weighted Average Price per Quarter | AU1: Non-Weighted Average Price per Quarter | AV1: Corn lowercase
A2: sale of corn and malt | B2: and for £8 18 shilling 6pence' from 22 quarters 2.5 bushels of wheat sold, at 8 shilling a quarters, as made clear elsewhere. | C2: 8.93 | D2: 8 | E2: 18 | F2: 6 | G2: wheat | H2: 22 | I2: 2.5 | J2: 22.31 | K2: 22.31 | L2: 0 | M2: 22 | N2: 2.5 | O2: 8 | P2: 0 | AO2: 0.4 | AS2: 22.31 | AT2: 0.4 | AU2: 0.4 | AV2: wheat
A3: sale of corn and malt | B3: £4 12 shilling 4pence from 34 quarters 5 bushels of oats sold, at 2 shilling 8pence a quarters, as made clear elsewhere, of which 4 quarters 4 bushels sold to the lord's household. | C3: 4.62 | D3: 4 | E3: 12 | F3: 4 | G3: oats | H3: 4 | I3: 4 | J3: 4.5 | K3: 34.62 | L3: -30.12 | M3: 34 | N3: 5 | O3: 2 | P3: 8 | Q3: 4 | R3: 4 | AO3: 0.13 | AS3: 34.62 | AT3: 0.13 | AU3: 0.13 | AV3: oats
A4: sale of corn and malt | B4: £24 7 shilling 4pence from 80 quarters 3 bushels 1 peck of malt sold, of which 71 quarters sold to the lord's household at esher, at 6. | C4: 24.37 | D4: 24 | E4: 7 | F4: 4 | G4: malt | H4: 71 | I4: 3 | J4: 71.38 | K4: 80.38 | L4: -9 | M4: 80 | N4: 3 | Q4: 71 | R4: 0 | AO4: 0.3 | AS4: 80.38 | AT4: 0.3 | AU4: 0.3 | AV4: malt
A5: sale of corn and malt | B5: a quarters, and 9 quarters 3 bushels 1 peck, at 6 shilling 8pence a quarters. | C5: 0.33 | D5: 0 | E5: 6 | F5: 8 | H5: 9 | I5: 3 | J5: 9.38 | K5: 9.38 | L5: 0 | M5: 9 | N5: 3 | O5: 6 | P5: 8 | AO5: 0.33 | AS5: 9.38 | AT5: 0.33 | AU5: 0.33
A6: sale of corn and malt | B6: total, £37 18 shilling 2pence. | C6: 37.91 | D6: 37 | E6: 18 | F6: 2 | H6: 0 | I6: 0 | J6: 0 | K6: 0 | L6: 0 | M6: 0 | N6: 0 | AO6: inf | AS6: 0 | AT6: inf | AU6: inf

Sheet Expenses
A1: IVINGHOE EXPENSES
A2: Heading | B2: £ | C2: s | D2: d | F2: Total in £ | G2: Error | H2: Notes
A4: Cost of ploughs | B4: 1 | C4: 0 | D4: 0 | F4: 1
A5: Cost of ploughs | B5: 0 | C5: 12 | D5: 0 | F5: 0.6
A6: Cost of ploughs | B6: 0 | C6: 2 | D6: 0 | F6: 0.1
A7: Cost of ploughs | B7: 0 | C7: 1 | D7: 0 | F7: 0.05
A8: Cost of ploughs | B8: 0 | C8: 2 | D8: 1 | F8: 0.1
A9: Cost of ploughs | B9: 0 | C9: 5 | D9: 0 | F9: 0.25
A10: Cost of ploughs | B10: 0 | C10: 2 | D10: 8 | F10: 0.13
A11: Cost of ploughs | B11: 0 | C11: 1 | D11: 0 | F11: 0.05
A12: Cost of ploughs | B12: 0 | C12: 1 | D12: 0 | F12: 0.05
A13: Cost of ploughs | B13: 0 | C13: 2 | D13: 6 | F13: 0.12
A14: Cost of ploughs | B14: 0 | C14: 7 | D14: 6 | F14: 0.38
A15: Cost of ploughs | B15: 1 | C15: 0 | D15: 0 | F15: 1
A16: Cost of ploughs | B16: 3 | C16: 16 | D16: 9 | F16: 3.84
A17: Cost of ploughs total | F17: 3.83 | G17: -0.01
A19: Cost of carts | B19: 0 | C19: 2 | D19: 8 | F19: 0.13
A20: Cost of carts | B20: 0 | C20: 8 | D20: 0 | F20: 0.4
A21: Cost of carts | B21: 0 | C21: 4 | D21: 0 | F21: 0.2
A22: Cost of carts | B22: 0 | C22: 2 | D22: 8 | F22: 0.13
A23: Cost of carts | B23: 0 | C23: 1 | D23: 0 | F23: 0.05
A24: Cost of carts | B24: 0 | C24: 1 | D24: 0 | F24: 0.05
A25: Cost of carts | B25: 0 | C25: 2 | D25: 0 | F25: 0.1
A26: Cost of carts | B26: 0 | C26: 1 | D26: 0 | F26: 0.05
A27: Cost of carts | B27: 0 | C27: 1 | D27: 0 | F27: 0.05
A28: Cost of carts | B28: 0 | C28: 2 | D28: 0 | F28: 0.1
A29: Cost of carts | B29: 0 | C29: 0 | D29: 0 | F29: 0
A30: Cost of carts | B30: 0 | C30: 2 | D30: 4 | F30: 0.12
... A38: Cost of carts | B38: 2 | C38: 10 | D38: 6 | F38: 2.52
A39: Cost of carts total | F39: 2.53 | G39: 0.01
A41: Threshing and winnowing | B41: 1 | C41: 6 | D41: 0 | F41: 1.3
A42: Threshing and winnowing | B42: 0 | C42: 16 | D42: 3.5 | F42: 0.81
A43: Threshing and winnowing | B43: 0 | C43: 4 | D43: 6 | F43: 0.23
A44: Threshing and winnowing | B44: 0 | C44: 6 | D44: 7.5 | F44: 0.33
A45: Threshing and winnowing | B45: 2 | C45: 13 | D45: 5 | F45: 2.67
A46: Threshing and winnowing total | F46: 2.67 | G46: 0
A48: Expenses of the steward | B48: 0 | C48: 12 | D48: 11.5 | F48: 0.65
A49: Expenses of the steward | B49: 0 | C49: 12 | D49: 11.5 | F49: 0.65
A50: Expenses of the steward total | F50: 0.65 | G50: 0
A52: Total of all expenses | B52: 70 | C52: 7 | D52: 2.5 | F52: 70.36
...
