Workbook

Sheet BishopsSutton Overview - Completed
A1: BISHOPSSUTTON OVERVIEW - COMPLETED | B1: Total in £ | C1: Error | D1: Note
A2: CASH ACCOUNT
A3: RECEIPTS
A4: Arrears total | B4: 48.38
A5: Rents of assize total | B5: 49
A6: Quittances total | B6: 2.93
A7: Defaults of rent total | B7: 0.92
A8: Defaults of rent through the pestilence total
A9: Cotlands defaults total
A10: Cotlands total
A11: Total of quittances and defaults of rent total | B11: 3.84
A12: Total of rents remaining clear total | B12: 46.1
A13: Farms total
A14: Annual recognizances total | B14: 0.04
A15: Issues of the Manor total | B15: 34.16
A16: Issues of the tenements in the lord's hands total
A17: Sale of labour services total
A18: Sale of corn total
A19: Entry and marriage fines total | B19: 10.09
A20: Pleas & perquisites total
A21: Forfeited chattels total
A22: Farm of the demesne land total
A23: Total of all receipts (calculated here) | B23: =SUM(B5:B22)
A24: Total of all receipts (calculated here) incl arrears | B24: =SUM(B4:B22)
A25: Total recorded in the accounts excl. arrears | B25: 114.64 | C25: =B23-B25
A26: Total recorded in the accounts incl. arrears | B26: =B25+B4
A29: EXPENSES
A30: Cost of ploughs total
A31: Purchase of corn total
A32: Cost of carts and wagons total
A33: Cost of dairy total
A34: Purchase of stock total | B34: 7.89
A35: Sheepcote total
A36: Cost of buildings total
A37: Threshing total
A38: Barley expenses
A39: Expenses of the harvest total
A40: Necessary expenses | B40: 1.95
A41: Wages of the bailiff
A42: Steward's expenses total | B42: 6.7266667
...

Sheet Prices
A1: Meat & Dairy Prices
C2: 1301 | D2: 1302 | E2: Average
A3: Beef | B3: £ per lb | C3: 0.0033351854 | D3: 0.0032608538 | E3: =AVERAGE(C3:D3)
A4: Mutton | B4: £ per lb | C4: 0.0036593977 | D4: 0.0037125513 | E4: =AVERAGE(C4:D4)
A5: Pork | B5: £ per lb | C5: 0.0038431326 | D5: 0.0037574803 | E5: =AVERAGE(C5:D5)
A6: Cheese | B6: £ per lb | C6: 0.0055768754 | D6: 0.0056654898 | E6: =AVERAGE(C6:D6)
A7: Butter | B7: £ per lb | C7: 0.0036626221 | D7: 0.0035935077 | E7: =AVERAGE(C7:D7)
A8: Milk | B8: £ per gallon | C8: 0.0055768754 | D8: 0.0056654898 | E8: =AVERAGE(C8:D8)

Sheet Labour Rents

Sheet Overview
A1: BISHOPS SUTTON | B1: Total in £ | C1: Error | D1: Note
A2: CASH ACCOUNT
A3: RECEIPTS
A4: Arrears total
A5: Rents of assize total
A6: Quittances total
A7: Defaults of rent total
A8: Defaults of rent through the pestilence total
A9: Cotlands defaults total
A10: Cotlands total
A11: Total of quittances and defaults of rent total
A12: Total of rents remaining clear total
A13: Farms total
... A22: Farm of the demesne land total
A23: Total of all receipts (calculated here) | B23: =Receipts!F124
A24: Total of all receipts (calculated here) incl arrears | B24: =Receipts!F125
A25: Total recorded in the accounts excl. arrears | B25: =Receipts!F123 | C25: =B25-B23
A26: Total recorded in the accounts incl. arrears
A29: EXPENSES
A30: Cost of ploughs total
A31: Purchase of corn total
A32: Cost of carts and wagons total
A33: Cost of dairy total
A34: Purchase of stock total
A35: Sheepcote total
A36: Cost of buildings total
A37: Threshing total
A38: Barley expenses
A39: Expenses of the harvest total
... A43: Annual fees
A44: Total of all expenses per account | B44: =Expenses!F115
A45: Total of all expenses (calculated here) | B45: =Expenses!F116
A46: Total fixed investment | B46: =Expenses!F117
A47: Total Demesne fixed investment | B47: =Expenses!F118
A49: Owed by the reeve | B49: =B23-B45
A50: From accounts | B50: =Expenses!F109 | C50: =B50-B49
A52: Allowances
A53: Cash deliveries | B53: =Expenses!F113
A54: Sum of the above | B54: =SUM(B52:B53)
A55: Total of all allowances and cash deliveries in accounts
...

Sheet Receipts
A1: BISHOPS SUTTON RECEIPTS
A2: Heading | B2: £ | C2: s | D2: d | F2: Total in £ | G2: Error | H2: Notes | I2: Own notes
A3: Arrears | B3: 48 | C3: 7 | D3: 7.5 | F3: 48.38 | H3: Nicholas, bailiff, and Walter de Manestrott', reeve, render account for £48 7 shilling 7.5pence of arrears from the previous year.
A4: Arrears | B4: 0 | C4: 0 | D4: 0 | F4: 0 | H4: All delivered to Sir Geoffrey de Farham, treasurer of Wolvesey, and they are quit.
A5: Arrears | F5: 48.38 | G5: =F5-F3 | H5: Total
A7: Rents of assize | B7: 49 | C7: 0 | D7: 0 | F7: 49 | H7: The same render account for £49 for all rents of assize in the manor of Bishops Sutton for the year: £9 7 shilling 3pence at Christmas, £9 7 shilling 2.5pence at Easter (22 April), £9 7 shilling 3.25pence at the feast of St John the Baptist (24 June), £21 17 shilling 1.25pence at Michaelmas (29 September).
A8: Rents of assize | B8: 49 | C8: 18 | D8: 10 | F8: 49.94 | H8: Total, £49 18 shilling 10pence
A9: Rents of assize | F9: =SUM(F7:F7) | G9: =F9-F8 | H9: Total
A11: Quittances | B11: 0 | C11: 5 | D11: 0 | F11: 0.25 | H11: In quittance of 1 reeve for the year 5 shilling.
A12: Quittances | B12: 0 | C12: 3 | D12: 0 | F12: 0.15 | H12: 1 beadle who is hayward for the year 3 shilling.
A13: Quittances | B13: 0 | C13: 2 | D13: 0 | F13: 0.1 | H13: 1 smith for the year 2 shilling.
A14: Quittances | B14: 0 | C14: 2 | D14: 3 | F14: 0.11 | H14: 1 shepherd for three terms because there was no threshing in the fourth term 2 shilling 3pence.
A15: Quittances | B15: 0 | C15: 3 | D15: 0 | F15: 0.15 | H15: 1 shepherd for the year 3 shilling.
A16: Quittances | B16: 0 | C16: 18 | D16: 0 | F16: 0.9 | H16: 6 ploughmen for the year 18 shilling, or 3 shilling each.
A17: Quittances | B17: 0 | C17: 19 | D17: 4.5 | F17: 0.97 | H17: 6 workers working 2 days a week from Michaelmas until Lammas and everyday at harvest-time 19 shilling 4.5pence.
A18: Quittances | B18: 0 | C18: 3 | D18: 0 | F18: 0.15 | H18: 1 cowherd for the year 3 shilling.
A19: Quittances | B19: 0 | C19: 3 | D19: 0 | F19: =B19+C19/20+D19/240 | H19: 1 swineherd 3 shilling
A20: Quittances | B20: 2 | C20: 18 | D20: 7.5 | F20: 2.93 | H20: Total, £2 18 shilling 7.5pence
A21: Quittances | F21: =SUM(F11:F19) | G21: =F21-F20 | H21: Total
A23: Defaults of rent | B23: 0 | C23: 2 | D23: 0 | F23: 0.1 | H23: In default of thel land of Philip [Molendinariusi] drawn into demesne, 2 shilling for the year.
A24: Defaults of rent | B24: 0 | C24: 1 | D24: 0 | F24: 0.05 | H24: the land of Geoffrey Hose given to the canons of Merton Priory for a fishpond 1 shilling.
A25: Defaults of rent | B25: 0 | C25: 0 | D25: 6 | F25: 0.03 | H25: 1 plot which belonged to John le Poleter, 6pence for the year.
A26: Defaults of rent | B26: 0 | C26: 10 | D26: 0 | F26: 0.5 | H26: 1 virgate of land which rbe' iongedl to Adam Bedell' drawn into demesne 10 shilling.
A27: Defaults of rent | B27: 0 | C27: 3 | D27: 3 | F27: 0.16 | H27: 1 messuage pertaining to the mill and 1 plot at the bakehouse pertaining to the same which William Carpenter held 3 shilling 3pence.
A28: Defaults of rent | B28: 0 | C28: 1 | D28: 6 | F28: 0.08 | H28: 3 acres of land which Guy de Hayden' held at la Leygate 1 shilling 6pence
A29: Defaults of rent | B29: 0 | C29: 18 | D29: 3 | F29: =B29+C29/20+D29/240 | H29: Total, 18 shilling 3pence
A30: Defaults of rent | F30: 0.92 | G30: =F30-F29 | H30: Total
A32: Total of quittances and defaults of rent | B32: 3 | C32: 16 | D32: 10.5 | F32: 3.84 | H32: Total of quittances and defaults of rent, £3 16 shilling 10.5pence
A33: Total of quittances and defaults of rent | F33: =F32 | G33: =F33-F32 | H33: Total
A36: Total of rents remaining clear | B36: 46 | C36: 1 | D36: 11.5 | F36: 46.1 | H36: Total of rents remaining clear, £46 1 shilling 11.5pence
A37: Total of rents remaining clear | F37: 46.1 | G37: =F37-F36 | H37: Total
A40: Annual recognizance | B40: 0 | C40: 0 | D40: 3 | F40: 0.01 | H40: The same render account for 3pence from William Syniar' for annual recognizance whilst he wishes to remain on the land of St Swithun's.
A41: Annual recognizance | B41: 0 | C41: 0 | D41: 3 | F41: 0.01 | H41: 3pence from John le Fode so that he may serve and make his profit outside the liberty of the lord and not be challenged for this by the lord, and that he may come to the law-day and remain a villein as before.
A42: Annual recognizance | B42: 0 | C42: 0 | D42: 3 | F42: 0.01 | H42: 3pence from John le Ma3on of Headley not to be prosecuted by the tithing for default at the law-day if he be not present and to be quit of tithingpenny, by the pledge of John ate Brigg'.
A43: Annual recognizance | B43: 0 | C43: 0 | D43: 3 | F43: 0.01 | H43: 3pence from Henry Faber for annual recognizance, by the pledge of Richard ate Putte.
A44: Annual recognizance | B44: 0 | C44: 1 | D44: 0 | F44: 0.05 | H44: Total, 1 shilling
A45: Annual recognizance | F45: 0.04 | G45: -0.01 | H45: Total
A48: Issues of the manor | B48: 1 | C48: 5 | D48: 1 | F48: 1.25 | H48: The same render account for £1 5 shilling 1pence from pannage of pigs of the vill this year.
A49: Issues of the manor | B49: 0 | C49: 18 | D49: 11 | F49: =B49+C49/12+D49/20 | H49: 18 shilling 11pence from foreign pannage.
A50: Issues of the manor | B50: 0 | C50: 10 | D50: 4 | F50: 0.52 | H50: 10 shilling from pannage of the cottars, at 4pence for each working ox, and 3pence for a cow of full age.
...

Sheet Expenses
A1: BISHOPS SUTTON EXPENSES
A2: Heading | B2: £ | C2: s | D2: d | F2: Total in £ | G2: Error | H2: Notes | J2: Fixed investment | K2: Demesne fixed investment
A3: Necessary expenses of ploughs | B3: 0 | C3: 5 | D3: 0 | F3: 0.25 | H3: In ironwork of 3 ploughs this year 5 shilling. | J3: =F3 | K3: =F3
A4: Necessary expenses of ploughs | B4: 0 | C4: 0 | D4: 9 | F4: 0.04 | H4: 2 plough feet bought 9pence Nothing accounted this year for the shoeing of 2 cart-horses because the smith is bound to shoe 2 cart-horses of Bishops Sutton at his own cost, and he will have 1 acre of wheat as it lies for making the iron of the shoes and 3 trunks for charcoal this year, because there were there three ploughs, and other customs are contained on the dorse of the roll. | J4: =F4 | K4: =F4
A5: Necessary expenses of ploughs | B5: 0 | C5: 0 | D5: 6 | F5: 0.03 | H5: 3 ploughs made anew 6pence. | J5: =F5 | K5: =F5
A6: Necessary expenses of ploughs | B6: 0 | C6: 0 | D6: 2 | F6: 0.01 | H6: mending other ploughs 2pence. | J6: =F6 | K6: =F6
A7: Necessary expenses of ploughs | B7: 0 | C7: 0 | D7: 2 | F7: 0.01 | H7: fitting ploughs with iron tyres 2pence. | J7: =F7 | K7: =F7
A8: Necessary expenses of ploughs | B8: 0 | C8: 0 | D8: 6 | F8: 0.03 | H8: 3 pairs of wheels bought 6pence Richard de Manicroft' and John de Puteo ploughed 12 acres in winter and 12 acres in Lent, and they will take nothing. | J8: =F8 | K8: =F8
A9: Necessary expenses of ploughs | B9: 0 | C9: 0 | D9: 3 | F9: 0.01 | H9: 1 harrow made anew and others mended 3pence. | J9: =F9 | K9: =F9
A10: Necessary expenses of ploughs | B10: 0 | C10: 0 | D10: 2.5 | F10: 0.01 | H10: 5 yokes made 2.5pence. | J10: =F10 | K10: =F10
A11: Necessary expenses of ploughs | B11: 1 | C11: 1 | D11: 6 | F11: 1.07 | H11: 2 oxen bought £1 1 shilling 6pence. | J11: =F11 | K11: =F11
A12: Necessary expenses of ploughs | B12: 0 | C12: 10 | D12: 0 | F12: =B12+C12/20+D12/240 | H12: forage bought to support plough-horses, oxen and cows 10 shilling
A13: Necessary expenses of ploughs | B13: 1 | C13: 19 | D13: 0.5 | F13: 1.95 | H13: Total, £1 19 shilling 0.5pence
F14: =SUM(F3:F12) | G14: =F14-F13 | H14: Total
A16: Sowing and fodder | B16: 1 | C16: 11 | D16: 8 | F16: 1.58 | H16: In 15 quarters of oats bought for sowing and fodder £1 11 shilling 8pence, at 1 shilling 8pence a qr for 5 quarters, and 2 shilling 4pence a qr for 10 quarters.
A17: Sowing and fodder | B17: 1 | C17: 11 | D17: 8 | F17: 1.58 | H17: Total, £1 11 shilling 8pence
A18: Sowing and fodder | F18: 1.58 | G18: 0 | H18: Total
A20: Carts | B20: 0 | C20: 0 | D20: 9 | F20: 0.04 | H20: In 1 pair of wheels made from the lord's timber 9pence. | J20: =F20 | K20: =J20
A21: Carts | B21: 0 | C21: 1 | D21: 4 | F21: 0.07 | H21: clouts, nails and grease bought 1 shilling 4pence. | J21: =F21 | K21: =J21
A22: Carts | B22: 0 | C22: 0 | D22: 6 | F22: 0.03 | H22: fitting the cart with axles 6pence. | J22: =F22 | K22: =J22
A23: Carts | B23: 0 | C23: 0 | D23: 6 | F23: 0.03 | H23: 1 collar bought 6pence. | J23: =F23 | K23: =J23
A24: Carts | B24: 0 | C24: 0 | D24: 6 | F24: 0.03 | H24: 1 pair of traces bought 6pence. | J24: =F24 | K24: =J24
A25: Carts | B25: 0 | C25: 1 | D25: 1 | F25: 0.05 | H25: 1 cart-rope bought 1 shilling 1pence. | J25: =F25 | K25: =J25
A26: Carts | B26: 0 | C26: 0 | D26: 10 | F26: 0.04 | H26: white leather bought for harnesses 10pence. | J26: =F26 | K26: =J26
A27: Carts | B27: 0 | C27: 1 | D27: 4 | F27: 0.07 | H27: shoeing 4 plough-horses 1 shilling 4pence. | J27: =F27 | K27: =J27
A28: Carts | B28: 0 | C28: 0 | D28: 1 | F28: 0 | H28: a halter bought 1pence. | J28: =F28 | K28: =J28
A29: Carts | B29: 0 | C29: 3 | D29: 0 | F29: 0.15 | H29: stipend of 1 carter for the year 3 shilling.
A30: Carts | B30: 0 | C30: 0 | D30: 9 | F30: =B30+C30/20+D30/240 | H30: pair of wheels made for dung 9pence | J30: =F30 | K30: =J30
A31: Carts | B31: 0 | C31: 10 | D31: 3 | F31: =B31+C31/20+D31/240 | H31: Total, 10 shilling 3pence
A32: Carts | F32: =SUM(F20:F30) | G32: =F32-F31 | H32: Total
A34: Dairy | B34: 0 | C34: 1 | D34: 3 | F34: 0.06 | H34: bushels 5 of salt bought 1 shilling 3pence. | J34: =F34 | K34: =J34
A35: Dairy | B35: 0 | C35: 0 | D35: 6 | F35: 0.03 | H35: linen and woollen cloth 6pence. | J35: =F35 | K35: =J35
A36: Dairy | B36: 0 | C36: 0 | D36: 2.5 | F36: 0.01 | H36: earthenware pots and pans bought 2.5pence. | J36: =F36 | K36: =J36
A37: Dairy | B37: 0 | C37: 0 | D37: 4 | F37: 0.02 | H37: a press bought 4pence. | J37: =F37 | K37: =J37
A38: Dairy | B38: 0 | C38: 0 | D38: 3 | F38: 0.01 | H38: mending the utensils of the dairy 3pence. | J38: =F38 | K38: =J38
A39: Dairy | B39: 0 | C39: 2 | D39: 3 | F39: 0.11 | H39: 9 ells of canvas bought for packing the coarse wool and lamb's-wool 2 shilling 3pence. | J39: =F39 | K39: =J39
A40: Dairy | B40: 0 | C40: 0 | D40: 2 | F40: 0.01 | H40: packing the same and making sacks 2pence. | J40: =F40 | K40: =J40
A41: Dairy | B41: 0 | C41: 10 | D41: 0 | F41: 0.5 | H41: grease, vinegar and copperas to make well diseased sheep 10 shilling. | J41: =F41 | K41: =J41
A42: Dairy | B42: 0 | C42: 1 | D42: 3 | F42: 0.06 | H42: 30 hurdles made 1 shilling 3pence. | J42: =F42 | K42: =J42
A43: Dairy | B43: 0 | C43: 3 | D43: 9.5 | F43: 0.19 | H43: cratches made anew around the walls in the sheepcote 3 shilling 9.5pence. | J43: =F43 | K43: =J43
...

Sheet Issues of the Grange
A1: Gross Output | B1: Total Quantity | C1: Account Total Quarters | D1: Bought in Total Quarters | E1: Received from churchscot | F1: Sold Total Quarters | G1: Difference Produced+Bought-Sold | H1: Weighted Average Price per Quarter | I1: Value of Total Production weighted
A2: wheat | B2: 88.375 | D2: 0 | F2: 60.5 | G2: =B2-F2 | H2: 0.3 | I2: =H2*B2
A3: curall | B3: 1.25 | D3: 0 | F3: 0.625 | G3: =B3-F3 | H3: 0.23333333 | I3: =H3*B3
A4: barley | B4: 36 | D4: 0 | F4: 7.3125 | G4: =B4-F4 | H4: 0.23333333 | I4: =H4*B4
A5: oats | B5: =C5+D5 | C5: 75 | D5: 15 | F5: 0 | G5: =B5-F5 | H5: 0 | I5: =H5*B5
A6: peas | B6: 1.5 | D6: 0 | F6: 0.5 | G6: =B6-F6 | H6: 0.15 | I6: =H6*B6
A7: vetches | B7: 2.625 | D7: 0 | F7: 0.5 | G7: =B7-F7 | H7: 0.1 | I7: =H7*B7
A9: Total Production
A10: Sales of corn (as recorded in accounts)
A13: Net output | B13: Gross output | C13: Seed quarters | D13: Seed bushels | E13: Seed total quarters | F13: tithe quarters | G13: tithe bushels | H13: tithe total | I13: manorial servants quarters | J13: manorial servants bushels | K13: manorial servants total quarters | L13: output net of tithe, seed, liveries | M13: in stock from last year | N13: Price in £ | O13: Value of net output in £ | P13: Value of sales (in "Sale of Corn") in £
A14: wheat | B14: =B2 | C14: 16 | D14: 1 | E14: =C14+D14/8 | I14: 11 | J14: =4+2 | K14: =I14+J14/8 | L14: =B14-E14-H14-K14 | N14: =H2 | O14: =L14*N14
A15: curall | B15: =B3 | E15: =C15+D15/8 | J15: 5 | K15: =I15+J15/8 | L15: =B15-E15-H15-K15 | N15: =H3 | O15: =L15*N15
A16: barley | B16: =B4 | C16: 11.5 | E16: =C16+D16/8 | I16: =5+2+2 | J16: =1.5+4+2+6 | K16: =I16+J16/8 | L16: =B16-E16-H16-K16 | N16: =H4 | O16: =L16*N16
A17: oats | B17: =B5 | C17: 36 | E17: =C17+D17/8 | I17: =18.5+15+18+2 | J17: =4 | K17: =I17+J17/8 | L17: =B17-E17-H17-K17 | N17: =H5 | O17: =L17*N17
A18: peas | B18: =B6 | C18: 1 | E18: =C18+D18/8 | K18: =I18+J18/8 | L18: =B18-E18-H18-K18 | N18: =H6 | O18: =L18*N18
A19: vetches | B19: =B7 | D19: 5 | E19: =C19+D19/8 | I19: 1 | J19: =1+3 | K19: =I19+J19/8 | L19: =B19-E19-H19-K19 | N19: =H7 | O19: =L19*N19
A21: Total

Sheet Issues of the Mills

Sheet Stock
A1: BISHOPS SUTTON ACCOUNT
C3: added | G3: subtracted
A4: Livestock | B4: Inherited stock | C4: added | D4: strays | E4: herbage | F4: churchscot | G4: of which in default | H4: sold | I4: in murrain | J4: accounted for elsewhere | K4: End-period stock | L4: cross-check | M4: stock building | N4: raw production | O4: Unit price (£) | P4: Value of stock (£) at given value | Q4: Value of stock (£) at sales prices | R4: Sales in (£) | S4: Value of stock building (£) | T4: Value of production (£) at sales prices | U4: Details
A5: Cart-horses | B5: 3 | K5: 3 | L5: =B5+C5+D5+E5+F5-G5-H5-I5-J5 | M5: =K5-B5
A6: Mares | L6: =B6+C6+D6+E6+F6-G6-H6-I6-J6 | M6: =K6-B6
A7: Plough horses | B7: 7 | C7: =2 | H7: 3 | I7: 1 | K7: 5 | L7: =B7+C7+D7+E7+F7-G7-H7-I7-J7 | M7: =K7-B7 | R7: =Receipts!F55
A8: Colts (unspecified years) | L8: =B8+C8+D8+E8+F8-G8-H8-I8-J8 | M8: =K8-B8
A9: Colts (2 years) | B9: 2 | I9: 1 | J9: 1 | K9: 0 | L9: =B9+C9+D9+E9+F9-G9-H9-I9-J9 | M9: =K9-B9
A10: Colts (1 year) | B10: 3 | I10: 1 | K10: 2 | L10: =B10+C10+D10+E10+F10-G10-H10-I10-J10 | M10: =K10-B10
A11: Foals | B11: 2 | K11: 2 | L11: =B11+C11+D11+E11+F11-G11-H11-I11-J11 | M11: =K11-B11
A12: Oxen | B12: 28 | C12: =1+2+2 | H12: 8 | K12: 25 | L12: =B12+C12+D12+E12+F12-G12-H12-I12-J12 | M12: =K12-B12 | R12: =Receipts!F56
A13: Bulls | B13: 2 | H13: 1 | K13: 1 | L13: =B13+C13+D13+E13+F13-G13-H13-I13-J13 | M13: =K13-B13 | R13: =Receipts!F57
A14: Cows | B14: 16 | C14: 4 | H14: 4 | K14: 16 | L14: =B14+C14+D14+E14+F14-G14-H14-I14-J14 | M14: =K14-B14 | R14: =Receipts!F58
A15: Steers | B15: 6 | C15: 29 | H15: 29 | J15: =2+4 | K15: 0 | L15: =B15+C15+D15+E15+F15-G15-H15-I15-J15 | M15: =K15-B15 | R15: =Receipts!F60
A16: Bullocks | B16: 5 | I16: 1 | K16: 4 | L16: =B16+C16+D16+E16+F16-G16-H16-I16-J16 | M16: =K16-B16
A17: Yearlings | B17: 4 | K17: 4 | L17: =B17+C17+D17+E17+F17-G17-H17-I17-J17 | M17: =K17-B17
A18: Calves | C18: 12 | H18: 3 | J18: 1 | K18: 8 | L18: =B18+C18+D18+E18+F18-G18-H18-I18-J18 | M18: =K18-B18 | R18: =Receipts!F59
A19: Wethers | B19: 186 | C19: 24 | H19: 14 | I19: =7+1 | K19: 188 | L19: =B19+C19+D19+E19+F19-G19-H19-I19-J19 | M19: =K19-B19 | R19: =Receipts!F61
A20: Rams | B20: 6 | C20: 2 | K20: 8 | L20: =B20+C20+D20+E20+F20-G20-H20-I20-J20 | M20: =K20-B20
A21: Ewes | B21: 176 | C21: 30 | H21: 14 | I21: =11+2 | J21: =2 | K21: 177 | L21: =B21+C21+D21+E21+F21-G21-H21-I21-J21 | M21: =K21-B21 | R21: =Receipts!F62
A22: Hoggs | B22: 64 | I22: =8 | J22: =24+2+30 | K22: 0 | L22: =B22+C22+D22+E22+F22-G22-H22-I22-J22 | M22: =K22-B22
A23: Lambs | C23: =126+7+20 | H23: 13 | I23: =21+10+4 | J23: =12+3 | K23: 90 | L23: =B23+C23+D23+E23+F23-G23-H23-I23-J23 | M23: =K23-B23 | R23: =Receipts!F64
A24: Boars | L24: =B24+C24+D24+E24+F24-G24-H24-I24-J24 | M24: =K24-B24
A25: Sows | B25: 1 | C25: 1 | K25: 2 | L25: =B25+C25+D25+E25+F25-G25-H25-I25-J25 | M25: =K25-B25
A26: Pigs | B26: 11 | C26: =16+11 | D26: 1 | H26: 4 | K26: 35 | L26: =B26+C26+D26+E26+F26-G26-H26-I26-J26 | M26: =K26-B26 | R26: =Receipts!F63
A27: Hoggets | B27: 16 | J27: 16 | K27: 0 | L27: =B27+C27+D27+E27+F27-G27-H27-I27-J27 | M27: =K27-B27
A28: Piglets | C28: 26 | I28: 5 | J28: =2+3 | K28: 16 | L28: =B28+C28+D28+E28+F28-G28-H28-I28-J28 | M28: =K28-B28
A29: Swans | L29: =B29+C29+D29+E29+F29-G29-H29-I29-J29 | M29: =K29-B29
A30: Peacocks | B30: 12 | C30: 2 | K30: 14 | L30: =B30+C30+D30+E30+F30-G30-H30-I30-J30 | M30: =K30-B30
A31: Total Value | L31: =B31+C31+D31+E31+F31-G31-H31-I31-J31 | M31: =K31-B31 | R31: =SUM(R5:R30)
A34: Wool | L34: =B34+C34+D34+E34+F34-G34-H34-I34-J34 | M34: =K34-B34
A35: Coarse wool | C35: =SUM(C36:C39) | J35: =37+1+338 | K35: 0 | L35: =B35+C35+D35+E35+F35-G35-H35-I35-J35 | M35: =K35-B35 | O35: 0.02 | T35: =O35*J35
A36: from wethers | C36: 165 | L36: =B36+C36+D36+E36+F36-G36-H36-I36-J36 | M36: =K36-B36
A37: from rams | C37: 6 | L37: =B37+C37+D37+E37+F37-G37-H37-I37-J37 | M37: =K37-B37
A38: from ewes | C38: 149 | L38: =B38+C38+D38+E38+F38-G38-H38-I38-J38 | M38: =K38-B38
A39: from hoggs | C39: 56 | L39: =B39+C39+D39+E39+F39-G39-H39-I39-J39 | M39: =K39-B39
A40: Lamb's wool | C40: 94 | J40: 94 | K40: 0 | L40: =B40+C40+D40+E40+F40-G40-H40-I40-J40 | M40: =K40-B40 | O40: 0.01 | T40: =O40*J40
A41: Wool locks | L41: =B41+C41+D41+E41+F41-G41-H41-I41-J41 | M41: =K41-B41
A42: Wool sold at shearing | L42: =B42+C42+D42+E42+F42-G42-H42-I42-J42 | M42: =K42-B42
A43: Total wool | L43: =B43+C43+D43+E43+F43-G43-H43-I43-J43 | M43: =K43-B43 | T43: =SUM(T35:T42)
...

Sheet Issues of the Grange raw
A1: Heading | B1: Sentence | C1: Quarters 1_x | D1: Bushels 1_x | E1: Sown Quarters | F1: Sown Bushels | G1: Sown Total Quarters | H1: Bought in Quarters | I1: Bought in Bushels | J1: Bought in Total Quarters | K1: Tithe Quarters | L1: Tithe Bushels | M1: Tithe Total Quarters | N1: Manorial servants & livestock Quarters | O1: Manorial servants & livestock Bushels | P1: Manorial servants & livestock Total Quarters | Q1: Sold Quarters | R1: Sold Bushels | S1: Sold Total Quarters | T1: Account Quarters | U1: Account Bushels | V1: Account Total Quarters | W1: bought only | X1: Total Quarters Except 1 | Y1: Total Bushels Except 1 | Z1: Total Corn Cross-Check | AA1: Total Corn Manorial Account | AB1: Corn Quantity Error | AC1: Quarters 1_y | AD1: Bushels 1_y | AE1: Quarters 2 | AF1: Bushels 2 | AG1: Quarters 3 | AH1: Bushels 3
A2: Cash deliveries | B2: Total | C2: 0 | D2: 0 | E2: 0 | F2: 0 | G2: 0 | H2: 0 | I2: 0 | J2: 0 | K2: 0 | L2: 0 | M2: 0 | N2: 0 | O2: 0 | P2: 0 | Q2: 0 | R2: 0 | S2: 0 | T2: 0 | U2: 0 | V2: 0 | W2: 0
A3: Wheat | B3: {yield: three-and-a-half-fold less 4 quarters 7 bushels} | C3: 0 | D3: 0 | E3: 0 | F3: 0 | G3: 0 | H3: 0 | I3: 0 | J3: 0 | K3: 0 | L3: 0 | M3: 0 | N3: 0 | O3: 0 | P3: 0 | Q3: 0 | R3: 0 | S3: 0 | T3: 0 | U3: 0 | V3: 0 | W3: 0 | X3: 4 | Y3: 7 | Z3: 4.875 | AA3: 4.875 | AB3: 0 | AC3: 4 | AD3: 7
A4: Wheat | B4: The same render account for 64 quarters 6 bushels from the whole issue of wheat from the grange in the granary without heaped measure. | C4: 0 | D4: 0 | E4: 0 | F4: 0 | G4: 0 | H4: 0 | I4: 0 | J4: 0 | K4: 0 | L4: 0 | M4: 0 | N4: 0 | O4: 0 | P4: 0 | Q4: 0 | R4: 0 | S4: 0 | T4: 64 | U4: 6 | V4: 64.75 | W4: 0 | X4: 64 | Y4: 6 | Z4: 64.75 | AA4: 64.75 | AB4: 0 | AC4: 64 | AD4: 6
A5: Wheat | B5: 23 quarters 5 bushels from churchscot. | C5: 0 | D5: 0 | E5: 0 | F5: 0 | G5: 0 | H5: 0 | I5: 0 | J5: 0 | K5: 0 | L5: 0 | M5: 0 | N5: 0 | O5: 0 | P5: 0 | Q5: 0 | R5: 0 | S5: 0 | T5: 0 | U5: 0 | V5: 0 | W5: 0 | X5: 23 | Y5: 5 | Z5: 23.625 | AA5: 23.625 | AB5: 0 | AC5: 23 | AD5: 5
A6: Wheat | B6: Total, 88 quarters 3 bushels | C6: 0 | D6: 0 | E6: 0 | F6: 0 | G6: 0 | H6: 0 | I6: 0 | J6: 0 | K6: 0 | L6: 0 | M6: 0 | N6: 0 | O6: 0 | P6: 0 | Q6: 0 | R6: 0 | S6: 0 | T6: 0 | U6: 0 | V6: 0 | W6: 0 | X6: 88 | Y6: 3 | Z6: 88.375 | AA6: 88.375 | AB6: 0 | AC6: 88 | AD6: 3
A7: Wheat | B7: Sown over 43 acres in the fields of Rowele, Mol' I and la Rude, 16 quarters 1 bushels. | C7: 0 | D7: 0 | E7: 16 | F7: 1 | G7: 16.125 | H7: 0 | I7: 0 | J7: 0 | K7: 0 | L7: 0 | M7: 0 | N7: 0 | O7: 0 | P7: 0 | Q7: 0 | R7: 0 | S7: 0 | T7: 0 | U7: 0 | V7: 0 | W7: 0 | X7: 16 | Y7: 1 | Z7: 16.125 | AA7: 16.125 | AB7: 0 | AC7: 16 | AD7: 1
A8: Wheat | B8: that is, 3 bushels an acre. | C8: 0 | D8: 0 | E8: 0 | F8: 0 | G8: 0 | H8: 0 | I8: 0 | J8: 0 | K8: 0 | L8: 0 | M8: 0 | N8: 0 | O8: 0 | P8: 0 | Q8: 0 | R8: 0 | S8: 0 | T8: 0 | U8: 0 | V8: 0 | W8: 0 | X8: 0 | Y8: 3 | Z8: 0.375 | AA8: 0.375 | AB8: 0 | AC8: 0 | AD8: 3
A9: Wheat | B9: . | C9: 0 | D9: 0 | E9: 0 | F9: 0 | G9: 0 | H9: 0 | I9: 0 | J9: 0 | K9: 0 | L9: 0 | M9: 0 | N9: 0 | O9: 0 | P9: 0 | Q9: 0 | R9: 0 | S9: 0 | T9: 0 | U9: 0 | V9: 0 | W9: 0 | X9: 0 | Y9: 0 | Z9: 0 | AA9: 0 | AB9: 0 | AC9: 0 | AD9: 0
A10: Wheat | B10: provision of Simon, clerk, for 2 tourns, 4 bushels. | C10: 0 | D10: 0 | E10: 0 | F10: 0 | G10: 0 | H10: 0 | I10: 0 | J10: 0 | K10: 0 | L10: 0 | M10: 0 | N10: 0 | O10: 0 | P10: 0 | Q10: 0 | R10: 0 | S10: 0 | T10: 0 | U10: 0 | V10: 0 | W10: 0 | X10: 0 | Y10: 4 | Z10: 0.5 | AA10: 0.5 | AB10: 0 | AC10: 0 | AD10: 4
A11: Wheat | B11: provision of the bailiff for the year, 11 quarters 2 bushels Sold, 60.5 quarters. | C11: 0 | D11: 0 | E11: 0 | F11: 0 | G11: 0 | H11: 0 | I11: 0 | J11: 0 | K11: 0 | L11: 0 | M11: 0 | N11: 0 | O11: 0 | P11: 0 | Q11: 71.5 | R11: 2 | S11: 71.75 | T11: 0 | U11: 0 | V11: 0 | W11: 0 | X11: 60.5 | Y11: 2 | Z11: 60.75 | AA11: 11.25 | AB11: 49.5 | AC11: 11 | AD11: 2 | AE11: 60.5 | AF11: 0
A12: Wheat | B12: Total | C12: 0 | D12: 0 | E12: 0 | F12: 0 | G12: 0 | H12: 0 | I12: 0 | J12: 0 | K12: 0 | L12: 0 | M12: 0 | N12: 0 | O12: 0 | P12: 0 | Q12: 0 | R12: 0 | S12: 0 | T12: 0 | U12: 0 | V12: 0 | W12: 0
A13: Curall | B13: The same render account for 1 qr 2 bushels from the whole issue of curall from the grange in the granary without heaped measure. | C13: 0 | D13: 0 | E13: 0 | F13: 0 | G13: 0 | H13: 0 | I13: 0 | J13: 0 | K13: 0 | L13: 0 | M13: 0 | N13: 0 | O13: 0 | P13: 0 | Q13: 0 | R13: 0 | S13: 0 | T13: 0 | U13: 0 | V13: 0 | W13: 0
A14: Curall | B14: Mixed with barley for the liveries of the manorial servants, 5 bushels Sold, 5 bushels | C14: 0 | D14: 0 | E14: 0 | F14: 0 | G14: 0 | H14: 0 | I14: 0 | J14: 0 | K14: 0 | L14: 0 | M14: 0 | N14: 0 | O14: 0 | P14: 0 | Q14: 0 | R14: 0 | S14: 0 | T14: 0 | U14: 0 | V14: 0 | W14: 0 | X14: 0 | Y14: 5 | Z14: 0.625 | AA14: 0.625 | AB14: 0 | AC14: 0 | AD14: 5 | AE14: 0 | AF14: 5
A15: Curall | B15: Total | C15: 0 | D15: 0 | E15: 0 | F15: 0 | G15: 0 | H15: 0 | I15: 0 | J15: 0 | K15: 0 | L15: 0 | M15: 0 | N15: 0 | O15: 0 | P15: 0 | Q15: 0 | R15: 0 | S15: 0 | T15: 0 | U15: 0 | V15: 0 | W15: 0
A16: Barley | B16: {yield: three-fold less 5 quarters 2 bushels} | C16: 0 | D16: 0 | E16: 0 | F16: 0 | G16: 0 | H16: 0 | I16: 0 | J16: 0 | K16: 0 | L16: 0 | M16: 0 | N16: 0 | O16: 0 | P16: 0 | Q16: 0 | R16: 0 | S16: 0 | T16: 0 | U16: 0 | V16: 0 | W16: 0 | X16: 5 | Y16: 2 | Z16: 5.25 | AA16: 5.25 | AB16: 0 | AC16: 5 | AD16: 2
A17: Barley | B17: The same render account for 35 quarters 2 bushels from the whole issue of barley from the grange in the granary without heaped measure. | C17: 0 | D17: 0 | E17: 0 | F17: 0 | G17: 0 | H17: 0 | I17: 0 | J17: 0 | K17: 0 | L17: 0 | M17: 0 | N17: 0 | O17: 0 | P17: 0 | Q17: 0 | R17: 0 | S17: 0 | T17: 35 | U17: 2 | V17: 35.25 | W17: 0 | X17: 35 | Y17: 2 | Z17: 35.25 | AA17: 35.25 | AB17: 0 | AC17: 35 | AD17: 2
A18: Barley | B18: 5 bushels of curall received for the liveries of the manorial servants. | C18: 0 | D18: 0 | E18: 0 | F18: 0 | G18: 0 | H18: 0 | I18: 0 | J18: 0 | K18: 0 | L18: 0 | M18: 0 | N18: 0 | O18: 0 | P18: 0 | Q18: 0 | R18: 0 | S18: 0 | T18: 0 | U18: 0 | V18: 0 | W18: 0 | X18: 0 | Y18: 5 | Z18: 0.625 | AA18: 0.625 | AB18: 0 | AC18: 0 | AD18: 5
A19: Barley | B19: 1 bushels of vetches received for the same. | C19: 0 | D19: 0 | E19: 0 | F19: 0 | G19: 0 | H19: 0 | I19: 0 | J19: 0 | K19: 0 | L19: 0 | M19: 0 | N19: 0 | O19: 0 | P19: 0 | Q19: 0 | R19: 0 | S19: 0 | T19: 0 | U19: 0 | V19: 0 | W19: 0 | X19: 0 | Y19: 1 | Z19: 0.125 | AA19: 0.125 | AB19: 0 | AC19: 0 | AD19: 1
A20: Barley | B20: Total, 36 quarters. | C20: 0 | D20: 0 | E20: 0 | F20: 0 | G20: 0 | H20: 0 | I20: 0 | J20: 0 | K20: 0 | L20: 0 | M20: 0 | N20: 0 | O20: 0 | P20: 0 | Q20: 0 | R20: 0 | S20: 0 | T20: 0 | U20: 0 | V20: 0 | W20: 0 | X20: 36 | Y20: 0 | Z20: 36 | AA20: 36 | AB20: 0 | AC20: 36 | AD20: 0
A21: Barley | B21: Sown over 23 acres in the field of Bradewey and beside the sheepcote, 11.5 quarters. | C21: 0 | D21: 0 | E21: 11.5 | F21: 0 | G21: 11.5 | H21: 0 | I21: 0 | J21: 0 | K21: 0 | L21: 0 | M21: 0 | N21: 0 | O21: 0 | P21: 0 | Q21: 0 | R21: 0 | S21: 0 | T21: 0 | U21: 0 | V21: 0 | W21: 0 | X21: 11.5 | Y21: 0 | Z21: 11.5 | AA21: 11.5 | AB21: 0 | AC21: 11.5 | AD21: 0
A22: Barley | B22: that is, .5 qr an acre. | C22: 0 | D22: 0 | E22: 0 | F22: 0 | G22: 0 | H22: 0 | I22: 0 | J22: 0 | K22: 0 | L22: 0 | M22: 0 | N22: 0 | O22: 0 | P22: 0 | Q22: 0 | R22: 0 | S22: 0 | T22: 0 | U22: 0 | V22: 0 | W22: 0
A23: Barley | B23: Delivered to 1 carter for the year, 6.5 quarters, taking a quarter every 8 weeks. | C23: 0 | D23: 0 | E23: 0 | F23: 0 | G23: 0 | H23: 0 | I23: 0 | J23: 0 | K23: 0 | L23: 0 | M23: 0 | N23: 0 | O23: 0 | P23: 0 | Q23: 0 | R23: 0 | S23: 0 | T23: 0 | U23: 0 | V23: 0 | W23: 0 | X23: 6.5 | Y23: 0 | Z23: 6.5 | AA23: 6.5 | AB23: 0 | AC23: 6.5 | AD23: 0
A24: Barley | B24: Delivered to 1 man who is in place of the dairymaid and who makes the cheese and keeps the garden and does other work in the curia, 5 quarters 1.5 bushels, taking a quarter every 10 weeks. | C24: 0 | D24: 0 | E24: 0 | F24: 0 | G24: 0 | H24: 0 | I24: 0 | J24: 0 | K24: 0 | L24: 0 | M24: 0 | N24: 0 | O24: 0 | P24: 0 | Q24: 0 | R24: 0 | S24: 0 | T24: 0 | U24: 0 | V24: 0 | W24: 0 | X24: 5 | Y24: 1.5 | Z24: 5.1875 | AA24: 5.1875 | AB24: 0 | AC24: 5 | AD24: 1.5
A25: Barley | B25: Delivered to 1 harrower, 4 bushels. | C25: 0 | D25: 0 | E25: 0 | F25: 0 | G25: 0 | H25: 0 | I25: 0 | J25: 0 | K25: 0 | L25: 0 | M25: 0 | N25: 0 | O25: 0 | P25: 0 | Q25: 0 | R25: 0 | S25: 0 | T25: 0 | U25: 0 | V25: 0 | W25: 0 | X25: 0 | Y25: 4 | Z25: 0.5 | AA25: 0.5 | AB25: 0 | AC25: 0 | AD25: 4
A26: Barley | B26: provision of the bailiff's attendant, 2 quarters. | C26: 0 | D26: 0 | E26: 0 | F26: 0 | G26: 0 | H26: 0 | I26: 0 | J26: 0 | K26: 0 | L26: 0 | M26: 0 | N26: 0 | O26: 0 | P26: 0 | Q26: 0 | R26: 0 | S26: 0 | T26: 0 | U26: 0 | V26: 0 | W26: 0 | X26: 2 | Y26: 0 | Z26: 2 | AA26: 2 | AB26: 0 | AC26: 2 | AD26: 0
A27: Barley | B27: Delivered to 1 keeper of lambs on Fobedon' with the lambs of Wield for 23 weeks, 2 quarters 2 bushels. | C27: 0 | D27: 0 | E27: 0 | F27: 0 | G27: 0 | H27: 0 | I27: 0 | J27: 0 | K27: 0 | L27: 0 | M27: 0 | N27: 0 | O27: 0 | P27: 0 | Q27: 0 | R27: 0 | S27: 0 | T27: 0 | U27: 0 | V27: 0 | W27: 0 | X27: 2 | Y27: 2 | Z27: 2.25 | AA27: 2.25 | AB27: 0 | AC27: 2 | AD27: 2
A28: Barley | B28: customary payment to the swineherd this year, 6 bushels Sold, 6.5 quarters. | C28: 0 | D28: 0 | E28: 0 | F28: 0 | G28: 0 | H28: 0 | I28: 0 | J28: 0 | K28: 0 | L28: 0 | M28: 0 | N28: 0 | O28: 0 | P28: 0 | Q28: 6.5 | R28: 0 | S28: 6.5 | T28: 0 | U28: 0 | V28: 0 | W28: 0 | X28: 6.5 | Y28: 6 | Z28: 7.25 | AA28: 0.75 | AB28: 6.5 | AC28: 0 | AD28: 6 | AE28: 6.5 | AF28: 0
A29: Barley | B29: Sold at the audit, 6.5 bushels | C29: 0 | D29: 0 | E29: 0 | F29: 0 | G29: 0 | H29: 0 | I29: 0 | J29: 0 | K29: 0 | L29: 0 | M29: 0 | N29: 0 | O29: 0 | P29: 0 | Q29: 0 | R29: 0 | S29: 0 | T29: 0 | U29: 0 | V29: 0 | W29: 0 | X29: 0 | Y29: 6.5 | Z29: 0.8125 | AA29: 0.8125 | AB29: 0 | AC29: 0 | AD29: 6.5
A30: Barley | B30: Total | C30: 0 | D30: 0 | E30: 0 | F30: 0 | G30: 0 | H30: 0 | I30: 0 | J30: 0 | K30: 0 | L30: 0 | M30: 0 | N30: 0 | O30: 0 | P30: 0 | Q30: 0 | R30: 0 | S30: 0 | T30: 0 | U30: 0 | V30: 0 | W30: 0
A31: Oats | B31: {yield: two-fold less 7.5 quarters} | C31: 0 | D31: 0 | E31: 0 | F31: 0 | G31: 0 | H31: 0 | I31: 0 | J31: 0 | K31: 0 | L31: 0 | M31: 0 | N31: 0 | O31: 0 | P31: 0 | Q31: 0 | R31: 0 | S31: 0 | T31: 0 | U31: 0 | V31: 0 | W31: 0 | X31: 7.5 | Y31: 0 | Z31: 7.5 | AA31: 7.5 | AB31: 0 | AC31: 7.5 | AD31: 0
A32: Oats | B32: The same render account for 60 quarters from the whole issue of oats from the grange in the granary without heaped measure. | C32: 0 | D32: 0 | E32: 0 | F32: 0 | G32: 0 | H32: 0 | I32: 0 | J32: 0 | K32: 0 | L32: 0 | M32: 0 | N32: 0 | O32: 0 | P32: 0 | Q32: 0 | R32: 0 | S32: 0 | T32: 60 | U32: 0 | V32: 60 | W32: 0 | X32: 60 | Y32: 0 | Z32: 60 | AA32: 60 | AB32: 0 | AC32: 60 | AD32: 0
A33: Oats | B33: 15 quarters by estimation in sheaves given to oxen. | C33: 0 | D33: 0 | E33: 0 | F33: 0 | G33: 0 | H33: 0 | I33: 0 | J33: 0 | K33: 0 | L33: 0 | M33: 0 | N33: 0 | O33: 0 | P33: 0 | Q33: 0 | R33: 0 | S33: 0 | T33: 0 | U33: 0 | V33: 0 | W33: 0 | X33: 15 | Y33: 0 | Z33: 15 | AA33: 15 | AB33: 0 | AC33: 15 | AD33: 0
A34: Oats | B34: 15 quarters bought. | C34: 0 | D34: 0 | E34: 0 | F34: 0 | G34: 0 | H34: 15 | I34: 0 | J34: 15 | K34: 0 | L34: 0 | M34: 0 | N34: 0 | O34: 0 | P34: 0 | Q34: 0 | R34: 0 | S34: 0 | T34: 0 | U34: 0 | V34: 0 | W34: 0 | X34: 15 | Y34: 0 | Z34: 15 | AA34: 15 | AB34: 0 | AC34: 15 | AD34: 0
A35: Oats | B35: Total, 90 quarters. | C35: 0 | D35: 0 | E35: 0 | F35: 0 | G35: 0 | H35: 0 | I35: 0 | J35: 0 | K35: 0 | L35: 0 | M35: 0 | N35: 0 | O35: 0 | P35: 0 | Q35: 0 | R35: 0 | S35: 0 | T35: 0 | U35: 0 | V35: 0 | W35: 0 | X35: 90 | Y35: 0 | Z35: 90 | AA35: 90 | AB35: 0 | AC35: 90 | AD35: 0
A36: Oats | B36: Sown over 72 acres in the fields of Rowele, Holecumbe and la Rude, 36 quarters. | C36: 0 | D36: 0 | E36: 36 | F36: 0 | G36: 36 | H36: 0 | I36: 0 | J36: 0 | K36: 0 | L36: 0 | M36: 0 | N36: 0 | O36: 0 | P36: 0 | Q36: 0 | R36: 0 | S36: 0 | T36: 0 | U36: 0 | V36: 0 | W36: 0 | X36: 36 | Y36: 0 | Z36: 36 | AA36: 36 | AB36: 0 | AC36: 36 | AD36: 0
A37: Oats | B37: that is, .5 qr an acre. | C37: 0 | D37: 0 | E37: 0 | F37: 0 | G37: 0 | H37: 0 | I37: 0 | J37: 0 | K37: 0 | L37: 0 | M37: 0 | N37: 0 | O37: 0 | P37: 0 | Q37: 0 | R37: 0 | S37: 0 | T37: 0 | U37: 0 | V37: 0 | W37: 0
A38: Oats | B38: . | C38: 0 | D38: 0 | E38: 0 | F38: 0 | G38: 0 | H38: 0 | I38: 0 | J38: 0 | K38: 0 | L38: 0 | M38: 0 | N38: 0 | O38: 0 | P38: 0 | Q38: 0 | R38: 0 | S38: 0 | T38: 0 | U38: 0 | V38: 0 | W38: 0 | X38: 0 | Y38: 0 | Z38: 0 | AA38: 0 | AB38: 0 | AC38: 0 | AD38: 0
A39: Oats | B39: . | C39: 0 | D39: 0 | E39: 0 | F39: 0 | G39: 0 | H39: 0 | I39: 0 | J39: 0 | K39: 0 | L39: 0 | M39: 0 | N39: 0 | O39: 0 | P39: 0 | Q39: 0 | R39: 0 | S39: 0 | T39: 0 | U39: 0 | V39: 0 | W39: 0 | X39: 0 | Y39: 0 | Z39: 0 | AA39: 0 | AB39: 0 | AC39: 0 | AD39: 0
A40: Oats | B40: . | C40: 0 | D40: 0 | E40: 0 | F40: 0 | G40: 0 | H40: 0 | I40: 0 | J40: 0 | K40: 0 | L40: 0 | M40: 0 | N40: 0 | O40: 0 | P40: 0 | Q40: 0 | R40: 0 | S40: 0 | T40: 0 | U40: 0 | V40: 0 | W40: 0 | X40: 0 | Y40: 0 | Z40: 0 | AA40: 0 | AB40: 0 | AC40: 0 | AD40: 0
...

Sheet Sale of Corn Prices
A1: Heading | B1: Sentence | C1: Total in Pounds | D1: Pounds | E1: Shillings | F1: Pence | G1: Corn | H1: Total Quarters Except 1 | I1: Total Bushels Except 1 | J1: Total Corn Cross-Check | K1: Total Corn Manorial Account | L1: Corn Quantity Error | M1: Quarters 0 | N1: Bushels 0 | O1: shilling a quarter 1 | P1: pence a quarter 1 | Q1: Quarters 1 | R1: Bushels 1 | S1: shilling a quarter 2 | T1: pence a quarter 2 | U1: Quarters 2 | V1: Bushels 2 | W1: shilling a quarter 3 | X1: pence a quarter 3 | Y1: shilling a quarter 4 | Z1: pence a quarter 4 | AA1: £ a quarter 1 | AB1: £ a quarter 2 | AC1: £ a quarter 3 | AD1: £ a quarter 4 | AE1: Quarters Sold | AF1: Weighted Average Price per Quarter | AG1: Non-Weighted Average Price per Quarter | AH1: Corn lowercase

Sheet raw data
A1: Heading | B1: Sentence | C1: Total in Pounds | D1: Pounds | E1: Shillings | F1: Pence | G1: Corn | H1: Total Quarters Except 1 | I1: Total Bushels Except 1 | J1: Total Corn Cross-Check | K1: Total Corn Manorial Account | L1: Corn Quantity Error | M1: Quarters 1 | N1: Bushels 1 | O1: Quarters 2 | P1: Bushels 2 | Q1: Quarters 3 | R1: Bushels 3 | S1: shilling a quarter 1 | T1: pence a quarter 1 | U1: shilling a quarter 2 | V1: pence a quarter 2 | W1: shilling a quarter 3 | X1: pence a quarter 3 | Y1: shilling a quarter 4 | Z1: pence a quarter 4 | AA1: shilling a bushel 1 | AB1: pence a bushel 1 | AC1: shilling a bushel 2 | AD1: pence a bushel 2 | AE1: shilling a bushel 3 | AF1: pence a bushel 3 | AG1: shilling a bushel 4 | AH1: pence a bushel 4
A2: Arrears | B2: Nicholas, bailiff, and Walter de Manestrott', reeve, render account for £48 7 shilling 7.5pence of arrears from the previous year. | C2: 48.38 | D2: 48 | E2: 7 | F2: 7.5 | H2: 0 | I2: 0 | J2: 0 | K2: 0 | L2: 0 | M2: 0 | N2: 0
A3: Arrears | B3: All delivered to Sir Geoffrey de Farham, treasurer of Wolvesey, and they are quit. | C3: 0 | D3: 0 | E3: 0 | F3: 0 | H3: 0 | I3: 0 | J3: 0 | K3: 0 | L3: 0 | M3: 0 | N3: 0
A4: Rents of assize | B4: The same render account for £49 for all rents of assize in the manor of Bishops Sutton for the year: £9 7 shilling 3pence at Christmas. | C4: 49 | D4: 49 | E4: 0 | F4: 0 | H4: 0 | I4: 0 | J4: 0 | K4: 0 | L4: 0 | M4: 0 | N4: 0
A5: Rents of assize | B5: £9 7 shilling 2.5pence at Easter (22 April). | C5: 9.36 | D5: 9 | E5: 7 | F5: 2.5 | H5: 0 | I5: 0 | J5: 0 | K5: 0 | L5: 0 | M5: 0 | N5: 0
A6: Rents of assize | B6: £9 7 shilling 3.25pence at the feast of St John the Baptist (24 June). | C6: 9.36 | D6: 9 | E6: 7 | F6: 3.25 | H6: 0 | I6: 0 | J6: 0 | K6: 0 | L6: 0 | M6: 0 | N6: 0
A7: Rents of assize | B7: £21 17 shilling 1.25pence at Michaelmas (29 September). | C7: 21.86 | D7: 21 | E7: 17 | F7: 1.25 | H7: 0 | I7: 0 | J7: 0 | K7: 0 | L7: 0 | M7: 0 | N7: 0
A8: Rents of assize | B8: Total, £49 18 shilling 10pence | C8: 49.94 | D8: 49 | E8: 18 | F8: 10 | H8: 0 | I8: 0 | J8: 0 | K8: 0 | L8: 0 | M8: 0 | N8: 0
A9: Quittances | B9: In quittance of 1 reeve for the year 5 shilling. | C9: 0.25 | D9: 0 | E9: 5 | F9: 0 | H9: 0 | I9: 0 | J9: 0 | K9: 0 | L9: 0 | M9: 0 | N9: 0
A10: Quittances | B10: 1 beadle who is hayward for the year 3 shilling. | C10: 0.15 | D10: 0 | E10: 3 | F10: 0 | H10: 0 | I10: 0 | J10: 0 | K10: 0 | L10: 0 | M10: 0 | N10: 0
A11: Quittances | B11: 1 smith for the year 2 shilling. | C11: 0.1 | D11: 0 | E11: 2 | F11: 0 | H11: 0 | I11: 0 | J11: 0 | K11: 0 | L11: 0 | M11: 0 | N11: 0
A12: Quittances | B12: 1 shepherd for three terms because there was no threshing in the fourth term 2 shilling 3pence. | C12: 0.11 | D12: 0 | E12: 2 | F12: 3 | H12: 0 | I12: 0 | J12: 0 | K12: 0 | L12: 0 | M12: 0 | N12: 0
A13: Quittances | B13: 1 shepherd for the year 3 shilling. | C13: 0.15 | D13: 0 | E13: 3 | F13: 0 | H13: 0 | I13: 0 | J13: 0 | K13: 0 | L13: 0 | M13: 0 | N13: 0
... A65: Issues of the manor | B65: Total, £33 1 shilling 2.25pence | C65: 33.06 | D65: 33 | E65: 1 | F65: 2.25 | H65: 0 | I65: 0 | J65: 0 | K65: 0 | L65: 0 | M65: 0 | N65: 0
A66: Sale of wheat | B66: The same render account for £18 3 shilling from 60.5 quarters of wheat sold, at 6 shilling a quarters. | C66: 18.15 | D66: 18 | E66: 3 | F66: 0 | G66: wheat | H66: 60.5 | I66: 0 | J66: 60.5 | K66: 60.5 | L66: 0 | M66: 60.5 | N66: 0 | S66: 6 | T66: 0
A67: Sale of wheat | B67: 2 shilling 11pence from 5 bushels of curall sold. | C67: 0.15 | D67: 0 | E67: 2 | F67: 11 | G67: curall | H67: 0 | I67: 5 | J67: 0.625 | K67: 0.625 | L67: 0 | M67: 0 | N67: 5
A68: Sale of wheat | B68: £1 10 shilling 4pence from 6.5 quarters of barley sold, at 4 shilling 8pence a quarters. | C68: 1.52 | D68: 1 | E68: 10 | F68: 4 | G68: barley | H68: 6.5 | I68: 0 | J68: 6.5 | K68: 6.5 | L68: 0 | M68: 6.5 | N68: 0 | S68: 4 | T68: 8
A69: Sale of wheat | B69: 1 shilling 6pence from 4 bushels of peas sold. | C69: 0.08 | D69: 0 | E69: 1 | F69: 6 | G69: peas | H69: 0 | I69: 4 | J69: 0.5 | K69: 0.5 | L69: 0 | M69: 0 | N69: 4
A70: Sale of wheat | B70: 1 shilling from 4 bushels of vetches sold. | C70: 0.05 | D70: 0 | E70: 1 | F70: 0 | G70: vetches | H70: 0 | I70: 4 | J70: 0.5 | K70: 0.5 | L70: 0 | M70: 0 | N70: 4
A71: Sale of wheat | B71: 3 shilling 9.5pence from 6.5 bushels of barley sold at the audit. | C71: 0.19 | D71: 0 | E71: 3 | F71: 9.5 | G71: barley | H71: 0 | I71: 6.5 | J71: 0.8125 | K71: 0.8125 | L71: 0 | M71: 0 | N71: 6.5
A72: Sale of wheat | B72: Total, £20 2 shilling 6.5pence | C72: 20.13 | D72: 20 | E72: 2 | F72: 6.5 | H72: 0 | I72: 0 | J72: 0 | K72: 0 | L72: 0 | M72: 0 | N72: 0
A73: Entry and marriage fines with tithingpenny | B73: The same render account for 5 shilling from the tithing of Bishops Sutton for tithingpenny at the hundred-court of Martinmas. | C73: 0.25 | D73: 0 | E73: 5 | F73: 0 | H73: 0 | I73: 0 | J73: 0 | K73: 0 | L73: 0 | M73: 0 | N73: 0
A74: Entry and marriage fines with tithingpenny | B74: 10 shilling from the tithing of Ropley for the same. | C74: 0.5 | D74: 0 | E74: 10 | F74: 0 | H74: 0 | I74: 0 | J74: 0 | K74: 0 | L74: 0 | M74: 0 | N74: 0
A75: Entry and marriage fines with tithingpenny | B75: 4 shilling from the tithing of Bighton for the same. | C75: 0.2 | D75: 0 | E75: 4 | F75: 0 | H75: 0 | I75: 0 | J75: 0 | K75: 0 | L75: 0 | M75: 0 | N75: 0
A76: Entry and marriage fines with tithingpenny | B76: 3 shilling from the tithing of Bramdean for the same. | C76: 0.15 | D76: 0 | E76: 3 | F76: 0 | H76: 0 | I76: 0 | J76: 0 | K76: 0 | L76: 0 | M76: 0 | N76: 0
A77: Entry and marriage fines with tithingpenny | B77: 2 shilling from the tithing of West Tisted for the same. | C77: 0.1 | D77: 0 | E77: 2 | F77: 0 | H77: 0 | I77: 0 | J77: 0 | K77: 0 | L77: 0 | M77: 0 | N77: 0
A78: Entry and marriage fines with tithingpenny | B78: 8 shilling from the tithing of Headley for the same. | C78: 0.4 | D78: 0 | E78: 8 | F78: 0 | H78: 0 | I78: 0 | J78: 0 | K78: 0 | L78: 0 | M78: 0 | N78: 0
A79: Entry and marriage fines with tithingpenny | B79: £1 12 shilling from the same for the same at the hundred-court of Hockday. | C79: 1.6 | D79: 1 | E79: 12 | F79: 0 | H79: 0 | I79: 0 | J79: 0 | K79: 0 | L79: 0 | M79: 0 | N79: 0
A80: Entry and marriage fines with tithingpenny | B80: 4 shilling from Richard Sutore for 1 plot which came into the lord's hands by the death of William le Dudeler'. | C80: 0.2 | D80: 0 | E80: 4 | F80: 0 | H80: 0 | I80: 0 | J80: 0 | K80: 0 | L80: 0 | M80: 0 | N80: 0
A81: Entry and marriage fines with tithingpenny | B81: 13 shilling 4pence from Richard de Graveschate to have the land of his father by surrender of Juliana his mother. | C81: 0.67 | D81: 0 | E81: 13 | F81: 4 | H81: 0 | I81: 0 | J81: 0 | K81: 0 | L81: 0 | M81: 0 | N81: 0
A82: Entry and marriage fines with tithingpenny | B82: 2 shilling from John Gileberd for marrying Agnes his daughter. | C82: 0.1 | D82: 0 | E82: 2 | F82: 0 | H82: 0 | I82: 0 | J82: 0 | K82: 0 | L82: 0 | M82: 0 | N82: 0
A83: Entry and marriage fines with tithingpenny | B83: £1 from Walter Parmehoud to have 1 virgate of land of his inheritance after the death of Seyld his mother. | C83: 1 | D83: 1 | E83: 0 | F83: 0 | H83: 0 | I83: 0 | J83: 0 | K83: 0 | L83: 0 | M83: 0 | N83: 0
... A95: Necessary expenses of ploughs | B95: In ironwork of 3 ploughs this year 5 shilling. | C95: 0.25 | D95: 0 | E95: 5 | F95: 0 | H95: 0 | I95: 0 | J95: 0 | K95: 0 | L95: 0 | M95: 0 | N95: 0
A96: Necessary expenses of ploughs | B96: 2 plough feet bought 9pence Nothing accounted this year for the shoeing of 2 cart-horses because the smith is bound to shoe 2 cart-horses of Bishops Sutton at his own cost, and he will have 1 acre of wheat as it lies for making the iron of the shoes and 3 trunks for charcoal this year, because there were there three ploughs, and other customs are contained on the dorse of the roll. | C96: 0.04 | D96: 0 | E96: 0 | F96: 9 | G96: wheat | H96: 0 | I96: 0 | J96: 0 | K96: 0 | L96: 0 | M96: 0 | N96: 0
A97: Necessary expenses of ploughs | B97: . | C97: 0 | D97: 0 | E97: 0 | F97: 0 | H97: 0 | I97: 0 | J97: 0 | K97: 0 | L97: 0 | M97: 0 | N97: 0
A98: Necessary expenses of ploughs | B98: 3 ploughs made anew 6pence. | C98: 0.03 | D98: 0 | E98: 0 | F98: 6 | H98: 0 | I98: 0 | J98: 0 | K98: 0 | L98: 0 | M98: 0 | N98: 0
A99: Necessary expenses of ploughs | B99: mending other ploughs 2pence. | C99: 0.01 | D99: 0 | E99: 0 | F99: 2 | H99: 0 | I99: 0 | J99: 0 | K99: 0 | L99: 0 | M99: 0 | N99: 0
A100: Necessary expenses of ploughs | B100: fitting ploughs with iron tyres 2pence. | C100: 0.01 | D100: 0 | E100: 0 | F100: 2 | H100: 0 | I100: 0 | J100: 0 | K100: 0 | L100: 0 | M100: 0 | N100: 0
A101: Necessary expenses of ploughs | B101: 3 pairs of wheels bought 6pence Richard de Manicroft' and John de Puteo ploughed 12 acres in winter and 12 acres in Lent, and they will take nothing. | C101: 0.03 | D101: 0 | E101: 0 | F101: 6 | H101: 0 | I101: 0 | J101: 0 | K101: 0 | L101: 0 | M101: 0 | N101: 0
A102: Necessary expenses of ploughs | B102: . | C102: 0 | D102: 0 | E102: 0 | F102: 0 | H102: 0 | I102: 0 | J102: 0 | K102: 0 | L102: 0 | M102: 0 | N102: 0
...
