Workbook

Sheet BishopsFonthill 1301 Overview -
A1: BISHOPSFONTHILL 1301 OVERVIEW - COMPLETED | B1: Total in £ | C1: Error | D1: Note
A2: CASH ACCOUNT
A3: RECEIPTS
A4: Arrears total
A5: Rents of assize total
A6: Quittances total
A7: Defaults of rent total
A8: Defaults of rent through the pestilence total
A9: Cotlands defaults total
A10: Cotlands total
A11: Total of quittances and defaults of rent total
A12: Total of rents remaining clear total
A13: Farms total
... A22: Farm of the demesne land total
A23: Total of all receipts (calculated here) | B23: =SUM(B5:B22) -> 0
A24: Total of all receipts (calculated here) incl arrears | B24: =SUM(B4:B22) -> 0
A25: Total recorded in the accounts excl. arrears | C25: =B23-B25 -> 0
A26: Total recorded in the accounts incl. arrears | B26: =B25+B4 -> 0
A29: EXPENSES
A30: Cost of ploughs total
A31: Purchase of corn total
A32: Cost of carts and wagons total
A33: Cost of dairy total
A34: Purchase of stock total
A35: Sheepcote total
A36: Cost of buildings total
A37: Threshing total
A38: Barley expenses
A39: Expenses of the harvest total
A40: Necessary expenses
... A47: Total Demesne fixed investment
A49: Owed by the reeve | B49: =B23-B45 -> 0
A50: From accounts | B50: 6.8208333
A52: Allowances
A53: Cash deliveries
A54: Sum of the above | B54: =SUM(B52:B53) -> 0
A55: Total of all allowances and cash deliveries in accounts
A57: Net amount owed | B57: =B50-B54 -> 6.8208333
A58: Net amount owed in accounts
A60: GRANGE ACCOUNT | B60: Total Production | D60: Value of total gross production in £ | E60: Value of total net production in £
...

Sheet Issues of the Mills
A1: No mill account for Adderbury

Sheet raw data
A1: Heading | B1: Sentence | C1: Total in Pounds | D1: Pounds | E1: Shillings | F1: Pence | G1: Corn | H1: Total Quarters Except 1 | I1: Total Bushels Except 1 | J1: Total Corn Cross-Check | K1: Total Corn Manorial Account | L1: Corn Quantity Error | M1: Quarters 1 | N1: Bushels 1 | O1: shilling a quarter 1 | P1: pence a quarter 1 | Q1: shilling a quarter 2 | R1: pence a quarter 2 | S1: shilling a quarter 3 | T1: pence a quarter 3 | U1: shilling a quarter 4 | V1: pence a quarter 4 | W1: shilling a bushel 1 | X1: pence a bushel 1 | Y1: shilling a bushel 2 | Z1: pence a bushel 2 | AA1: shilling a bushel 3 | AB1: pence a bushel 3 | AC1: shilling a bushel 4 | AD1: pence a bushel 4
A2: Adderbury | B2: The account2 of William Jakeman, reeve there, for the sixth year of the translation of Henry Beaufort', lord bishop of Winchester, and the eleventh year of the reign of King Henry the Fourth. | C2: 0 | D2: 0 | E2: 0 | F2: 0 | H2: 0 | I2: 0 | J2: 0 | K2: 0 | L2: 0 | M2: 0 | N2: 0
A3: Arrears | B3: None. | C3: 0 | D3: 0 | E3: 0 | F3: 0 | H3: 0 | I3: 0 | J3: 0 | K3: 0 | L3: 0 | M3: 0 | N3: 0
A4: Rents of assize | B4: And for £6 9 shilling 6.25pence for all rents of assize at St Thomas the Apostle (21 December). | C4: 6.48 | D4: 6 | E4: 9 | F4: 6.25 | H4: 0 | I4: 0 | J4: 0 | K4: 0 | L4: 0 | M4: 0 | N4: 0
A5: Rents of assize | B5: £6 9 shilling 8.5pence at Easter (23 March). | C5: 6.49 | D5: 6 | E5: 9 | F5: 8.5 | H5: 0 | I5: 0 | J5: 0 | K5: 0 | L5: 0 | M5: 0 | N5: 0
A6: Rents of assize | B6: £6 9 shilling 6.25pence at the Nativity of St John the Baptist (24 June). | C6: 6.48 | D6: 6 | E6: 9 | F6: 6.25 | H6: 0 | I6: 0 | J6: 0 | K6: 0 | L6: 0 | M6: 0 | N6: 0
A7: Rents of assize | B7: £6 10 shilling 1.5pence at Michaelmas (29 September). | C7: 6.51 | D7: 6 | E7: 10 | F7: 1.5 | H7: 0 | I7: 0 | J7: 0 | K7: 0 | L7: 0 | M7: 0 | N7: 0
A8: Rents of assize | B8: Total, £25 18 shilling 10.5pence. | C8: 25.94 | D8: 25 | E8: 18 | F8: 10.5 | H8: 0 | I8: 0 | J8: 0 | K8: 0 | L8: 0 | M8: 0 | N8: 0
A9: Quittances of rent | B9: In quittance of rent of 1 reeve for the year 5 shilling. | C9: 0.25 | D9: 0 | E9: 5 | F9: 0 | H9: 0 | I9: 0 | J9: 0 | K9: 0 | L9: 0 | M9: 0 | N9: 0
A10: Quittances of rent | B10: nothing this year of the 4 shilling for 1 smith forging the ironwork of 2 ploughs for the year. | C10: 0.2 | D10: 0 | E10: 4 | F10: 0 | H10: 0 | I10: 0 | J10: 0 | K10: 0 | L10: 0 | M10: 0 | N10: 0
A11: Quittances of rent | B11: nothing this year of the 4 shilling for 1 shepherd keeping the lord's wethers for the year. | C11: 0.2 | D11: 0 | E11: 4 | F11: 0 | H11: 0 | I11: 0 | J11: 0 | K11: 0 | L11: 0 | M11: 0 | N11: 0
A12: Quittances of rent | B12: nothing this year of the 4 shilling for 1 swineherd for the year. | C12: 0.2 | D12: 0 | E12: 4 | F12: 0 | H12: 0 | I12: 0 | J12: 0 | K12: 0 | L12: 0 | M12: 0 | N12: 0
A13: Quittances of rent | B13: nothing this year of the 4 shilling for 1 cowherd for the year. | C13: 0.2 | D13: 0 | E13: 4 | F13: 0 | H13: 0 | I13: 0 | J13: 0 | K13: 0 | L13: 0 | M13: 0 | N13: 0
... A149: Cost of buildings | B149: board-nails and clout-nails bought for the same 1 shilling 4pence. | C149: 0.07 | D149: 0 | E149: 1 | F149: 4 | H149: 0 | I149: 0 | J149: 0 | K149: 0 | L149: 0 | M149: 0 | N149: 0
A150: Cost of buildings | B150: 4 quarters 4 bushels of limestone bought at Walton' 5 shilling 3pence, at 1 shilling 2pence a quarters. | C150: 0.26 | D150: 0 | E150: 5 | F150: 3 | H150: 4 | I150: 4 | J150: 4.5 | K150: 4.5 | L150: 0 | M150: 4 | N150: 4 | O150: 1 | P150: 2
A151: Cost of buildings | B151: carrying the same 4pence. | C151: 0.02 | D151: 0 | E151: 0 | F151: 4 | H151: 0 | I151: 0 | J151: 0 | K151: 0 | L151: 0 | M151: 0 | N151: 0
A152: Cost of buildings | B152: 8 quarters of limestone bought at Witney 10 shilling 4pence, at 1 shilling 31 pence a quarters. | C152: 0.52 | D152: 0 | E152: 10 | F152: 4 | H152: 8 | I152: 0 | J152: 8 | K152: 8 | L152: 0 | M152: 8 | N152: 0 | O152: 1 | P152: 31
A153: Cost of buildings | B153: carrying the same from Witney to Adderbury 3 shilling 8pence. | C153: 0.18 | D153: 0 | E153: 3 | F153: 8 | H153: 0 | I153: 0 | J153: 0 | K153: 0 | L153: 0 | M153: 0 | N153: 0
A154: Cost of buildings | B154: 1,500 stone slates bought 6 shilling, at 4 shilling a 1,000.. | C154: 0.3 | D154: 0 | E154: 6 | F154: 0 | H154: 0 | I154: 0 | J154: 0 | K154: 0 | L154: 0 | M154: 0 | N154: 0
A155: Cost of buildings | B155: 500 eaves-stones bought 2 shilling 6pence, at 6pence a 100.. | C155: 0.12 | D155: 0 | E155: 2 | F155: 6 | H155: 0 | I155: 0 | J155: 0 | K155: 0 | L155: 0 | M155: 0 | N155: 0
A156: Cost of buildings | B156: 6,000 pins bought 2 shilling, at 4pence a 1,000.. | C156: 0.12 | D156: 0 | E156: 2 | F156: 4 | H156: 0 | I156: 0 | J156: 0 | K156: 0 | L156: 0 | M156: 0 | N156: 0
A157: Cost of buildings | B157: 50 ridge-tiles bought 6 shilling 3pence, at 1.5pence each. | C157: 0.31 | D157: 0 | E157: 6 | F157: 3 | H157: 0 | I157: 0 | J157: 0 | K157: 0 | L157: 0 | M157: 0 | N157: 0
A158: Cost of buildings | B158: sand bought and dug and quarried at Tadmarton 10pence. | C158: 0.04 | D158: 0 | E158: 0 | F158: 10 | H158: 0 | I158: 0 | J158: 0 | K158: 0 | L158: 0 | M158: 0 | N158: 0
A159: Cost of buildings | B159: stipend of 1 man going to Walton' to quarry lime there 2pence. | C159: 0.01 | D159: 0 | E159: 0 | F159: 2 | H159: 0 | I159: 0 | J159: 0 | K159: 0 | L159: 0 | M159: 0 | N159: 0
A160: Cost of buildings | B160: expenses of 12 men coming for a boon-work with 6 carts to quarry sand at Newotele and carry it to Adderbury, with the digging, 2 shilling 3pence. | C160: 0.11 | D160: 0 | E160: 2 | F160: 3 | H160: 0 | I160: 0 | J160: 0 | K160: 0 | L160: 0 | M160: 0 | N160: 0
A161: Cost of buildings | B161: hiring 1 man to carry sand and lime from the warrener's chamber to the barn by piece-work 4pence. | C161: 0.02 | D161: 0 | E161: 0 | F161: 4 | H161: 0 | I161: 0 | J161: 0 | K161: 0 | L161: 0 | M161: 0 | N161: 0
A162: Cost of buildings | B162: carrying the ridge-tiles bought above 8pence. | C162: 0.03 | D162: 0 | E162: 0 | F162: 8 | H162: 0 | I162: 0 | J162: 0 | K162: 0 | L162: 0 | M162: 0 | N162: 0
A163: Cost of buildings | B163: expenses of various men coming for a boon-work to buy slates at Aynho and carry them to Adderbury with the expenses of 1 man there mending the said slates 2d 1 shilling 9.5pence. | C163: 0.09 | D163: 0 | E163: 1 | F163: 9.5 | H163: 0 | I163: 0 | J163: 0 | K163: 0 | L163: 0 | M163: 0 | N163: 0
A164: Cost of buildings | B164: 1 tine bought 8pence. | C164: 0.03 | D164: 0 | E164: 0 | F164: 8 | H164: 0 | I164: 0 | J164: 0 | K164: 0 | L164: 0 | M164: 0 | N164: 0
... A181: Total of all allowances | B181: Total of all allowances and cash deliveries, £64 19 shilling 11.5pence He is quit. | C181: 65 | D181: 64 | E181: 19 | F181: 11.5 | H181: 0 | I181: 0 | J181: 0 | K181: 0 | L181: 0 | M181: 0 | N181: 0
A182: Wheat | B182: William Jakeman, reeve there, answers for 3 quarters of wheat remaining.. | C182: 0 | D182: 0 | E182: 0 | F182: 0 | G182: wheat | H182: 3 | I182: 0 | J182: 3 | K182: 3 | L182: 0 | M182: 3 | N182: 0
A183: Wheat | B183: Total, 3 quarters.. | C183: 0 | D183: 0 | E183: 0 | F183: 0 | H183: 3 | I183: 0 | J183: 3 | K183: 3 | L183: 0 | M183: 3 | N183: 0
A184: Wheat | B184: 3 quarters remain in the keeping of John Eadburbury, farmer there, to be handed back and restored at the end of his farm of 12 years, this year being the fifth. | C184: 0 | D184: 0 | E184: 0 | F184: 0 | H184: 3 | I184: 0 | J184: 3 | K184: 3 | L184: 0 | M184: 3 | N184: 0
A185: Rye | B185: And for 34 quarters of rye remaining.. | C185: 0 | D185: 0 | E185: 0 | F185: 0 | G185: rye | H185: 34 | I185: 0 | J185: 34 | K185: 34 | L185: 0 | M185: 34 | N185: 0
A186: Rye | B186: Total, 34 quarters.. | C186: 0 | D186: 0 | E186: 0 | F186: 0 | H186: 34 | I186: 0 | J186: 34 | K186: 34 | L186: 0 | M186: 34 | N186: 0
A187: Rye | B187: 34 quarters remain in the keeping of the said John Eadburbury, farmer there, to be handed back and restored at the end of his farm as before. | C187: 0 | D187: 0 | E187: 0 | F187: 0 | H187: 34 | I187: 0 | J187: 34 | K187: 34 | L187: 0 | M187: 34 | N187: 0
A188: Dredge | B188: And for 30 quarters of dredge remaining.. | C188: 0 | D188: 0 | E188: 0 | F188: 0 | G188: dredge | H188: 30 | I188: 0 | J188: 30 | K188: 30 | L188: 0 | M188: 30 | N188: 0
A189: Dredge | B189: Total, 30 quarters.. | C189: 0 | D189: 0 | E189: 0 | F189: 0 | H189: 30 | I189: 0 | J189: 30 | K189: 30 | L189: 0 | M189: 30 | N189: 0
A190: Dredge | B190: 30 quarters remain in the keeping of the said John Eadburbury, farmer there, to be handed back and restored as before. | C190: 0 | D190: 0 | E190: 0 | F190: 0 | H190: 30 | I190: 0 | J190: 30 | K190: 30 | L190: 0 | M190: 30 | N190: 0
A191: Pulses | B191: None remain. | C191: 0 | D191: 0 | E191: 0 | F191: 0 | H191: 0 | I191: 0 | J191: 0 | K191: 0 | L191: 0 | M191: 0 | N191: 0
...

Sheet Prices
A1: Meat & Dairy Prices
C2: 1301 | D2: 1302 | E2: Average
A3: Beef | B3: £ per lb | C3: 0.0033351854 | D3: 0.0032608538 | E3: =AVERAGE(C3:D3) -> 0.0032980196
A4: Mutton | B4: £ per lb | C4: 0.0036593977 | D4: 0.0037125513 | E4: =AVERAGE(C4:D4) -> 0.0036859745
A5: Pork | B5: £ per lb | C5: 0.0038431326 | D5: 0.0037574803 | E5: =AVERAGE(C5:D5) -> 0.0038003065
A6: Cheese | B6: £ per lb | C6: 0.0055768754 | D6: 0.0056654898 | E6: =AVERAGE(C6:D6) -> 0.0056211826
A7: Butter | B7: £ per lb | C7: 0.0036626221 | D7: 0.0035935077 | E7: =AVERAGE(C7:D7) -> 0.0036280649
A8: Milk | B8: £ per gallon | C8: 0.0055768754 | D8: 0.0056654898 | E8: =AVERAGE(C8:D8) -> 0.0056211826

Sheet Labour Rents

Sheet Bishops Fonthill Overview
A1: BISHOPS FONTHILL | B1: £ | C1: s | D1: d | G1: Total in £ | H1: Error
A3: CASH ACCOUNT
A4: RECEIPTS
A5: Arrears | G5: ='Bishops Fonthill Receipts'!F5 -> 11.3875
A6: Rents of assize | G6: ='Bishops Fonthill Receipts'!F14 -> 5.0125
A7: Quittances | G7: ='Bishops Fonthill Receipts'!F24 -> 1.075
A8: Defaults of rent | I8: none
A9: Total of rents remaining | G9: ='Bishops Fonthill Receipts'!F26 -> 3.9375
A10: Annual reconizances | G10: ='Bishops Fonthill Receipts'!F38 -> 0.0375
A11: Issues of the Manor | G11: ='Bishops Fonthill Receipts'!F55 -> 7.7145833
A12: Sale of corn | G12: ='Bishops Fonthill Receipts'!F64 -> 22.63125
A13: Entry and marriage fines | G13: ='Bishops Fonthill Receipts'!F71 -> 0.55
A14: Pleas & Perquisites | G14: ='Bishops Fonthill Receipts'!F76 -> 2.0416667
A15: Sum of the above (incl. arrears) | G15: =G5+G9+G10+G11+G12+G13+G14 -> 48.3
A16: Total recorded in the accounts excl. arrears | G16: ='Bishops Fonthill Receipts'!F80 -> 36.952083
A17: Total recorded in the accounts incl. arrears | I17: not feasible
A20: EXPENSES
A21: Cost of ploughs | G21: ='Bishops Fonthill Expenses'!F14 -> 3.6208333
A22: Purchase of corn
A23: Cost of carts and wagons | G23: ='Bishops Fonthill Expenses'!F29 -> 0.4
A24: Cost of dairy
A25: Purchase of stock
A26: Sheepcote | G26: ='Bishops Fonthill Expenses'!F49 -> 0.39583333
A27: Cost of buildings | G27: ='Bishops Fonthill Expenses'!F40 -> 0.4375
A28: Threshing | G28: ='Bishops Fonthill Expenses'!F58 -> 1.2583333
A29: Expenses of the harvest | G29: ='Bishops Fonthill Expenses'!F66 -> 0.58333333
A30: Stewards expenses | G30: ='Bishops Fonthill Expenses'!F71 -> 0.125
A31: Sum of the above | G31: =SUM(G21:G30) -> 6.8208333
A32: Total of all expenses | G32: ='Bishops Fonthill Expenses'!F73 -> 6.8208333 | H32: =G31-G32 -> 0
A33: Total Demesne fixed investment | G33: ='Bishops Fonthill Expenses'!F78 -> 1.8208333
A35: Owed by the reeve | G35: ='Bishops Fonthill Expenses'!F75 -> 30.13125
A36: From accounts
A38: Cash deliveries | G38: ='Bishops Fonthill Expenses'!F76 -> 21.6
A39: Cash delivers (Hindon Borough)
A40: Sum of the above | B40: =SUM(B38:B39) -> 0 | C40: =SUM(C38:C39) -> 0 | D40: =SUM(D38:D39) -> 0 | E40: =SUM(E38:E39) -> 0 | G40: =SUM(G38:G39) -> 21.6
A41: Total of all allowances and cash deliveries in accounts | B41: n/a
A43: Net amount owed | G43: ='Bishops Fonthill Expenses'!F77 -> 8.53125
A44: Net amount owed in accounts | H44: =G43-G44 -> 8.53125
A46: GRANGE ACCOUNT | B46: Net Production | F46: Value of total gross production in £ | G46: Value of total net production in £
A47: Grange | B47: qrs | C47: bus | F47: £ | G47: £
...

Sheet Bishops Fonthill Receipts
A1: BISHOPS FONTHILL RECEIPTS
B2: £ | C2: s | D2: d | F2: Total in £ | G2: Error | H2: Notes
A4: Arrears
A5: arrears from previous year | B5: 11 | C5: 7 | D5: 9 | F5: =B5+C5/20+D5/240 -> 11.3875
A6: of which delivered to treasurer of Wolvesey | B6: 11 | C6: 7 | D6: 9 | F6: =B6+C6/20+D6/240 -> 11.3875
A8: Rents of assize
A9: Christmas | B9: 1 | C9: 5 | D9: 0.75 | F9: =B9+C9/20+D9/240 -> 1.253125
A10: Easter | B10: 1 | C10: 5 | D10: 0.75 | F10: =B10+C10/20+D10/240 -> 1.253125
A11: Feast of John Baptist | B11: 1 | C11: 5 | D11: 0.75 | F11: =B11+C11/20+D11/240 -> 1.253125
A12: Michaelmas | B12: 1 | C12: 5 | D12: 0.75 | F12: =B12+C12/20+D12/240 -> 1.253125
A13: Total recorded in accounts | B13: 5 | D13: 3 | F13: =B13+C13/20+D13/240 -> 5.0125
A14: Total | B14: =SUM(B9:B12) -> 4 | C14: =SUM(C9:C12) -> 20 | D14: =SUM(D9:D12) -> 3 | F14: =B14+C14/20+D14/240 -> 5.0125 | G14: =F14-F13 -> 0
A16: Quittances
A17: 1 reeve for the year | C17: 2 | F17: =B17+C17/20+D17/240 -> 0.1
A18: 1 bartoner for the year | C18: 2 | F18: =B18+C18/20+D18/240 -> 0.1
A19: 1 smith for the year for ironwork of 3 ploughs | C19: 2 | F19: =B19+C19/20+D19/240 -> 0.1
A20: 1 swineherd for the year who oversees harvest | C20: 2 | F20: =B20+C20/20+D20/240 -> 0.1
A21: 2 shepherds, one keeps sheep in pinfold | C21: 3 | D21: 6 | F21: =B21+C21/20+D21/240 -> 0.175
A22: 5 ploughmen for the year | C22: 10 | F22: =B22+C22/20+D22/240 -> 0.5
A23: Total recorded in accounts | B23: 1 | C23: 1 | D23: 6 | F23: =B23+C23/20+D23/240 -> 1.075
A24: Total | B24: =SUM(B17:B22) -> 0 | C24: =SUM(C17:C22) -> 21 | D24: =SUM(D17:D22) -> 6 | F24: =B24+C24/20+D24/240 -> 1.075 | G24: =F24-F23 -> 0
A26: Total of rents remaining | B26: 3 | C26: 18 | D26: 9 | F26: =B26+C26/20+D26/240 -> 3.9375 | H26: not included in receipts
A28: Wax
F29: =B29+C29/20+D29/240 -> 0
A30: Total recorded in accounts | F30: =B30+C30/20+D30/240 -> 0
A31: Total | B31: =SUM(B29) -> 0 | C31: =SUM(C29) -> 0 | D31: =SUM(D29) -> 0 | F31: =B31+C31/20+D31/240 -> 0 | G31: =F31-F30 -> 0
A33: Annual recognizances
A34: from Thomas Tritur | D34: 3 | F34: =B34+C34/20+D34/240 -> 0.0125
A35: from John le Charectyr | D35: 3 | F35: =B35+C35/20+D35/240 -> 0.0125
A36: from John of Fontel | D36: 3 | F36: =B36+C36/20+D36/240 -> 0.0125
A37: Total recorded in accounts | D37: 9 | F37: =B37+C37/20+D37/240 -> 0.0375
A38: Total | B38: =SUM(B34:B36) -> 0 | C38: =SUM(C34:C36) -> 0 | D38: =SUM(D34:D36) -> 9 | F38: =B38+C38/20+D38/240 -> 0.0375 | G38: =F38-F37 -> 0
A40: Issues of the manor
A41: from pannage of pigs | C41: 2 | D41: 2 | F41: =B41+C41/20+D41/240 -> 0.10833333
A42: from residue of Peter's pence | C42: 1 | D42: 11 | F42: =B42+C42/20+D42/240 -> 0.095833333
A43: from 22 pigs sold | B43: 2 | C43: 18 | D43: 7 | F43: =B43+C43/20+D43/240 -> 2.9291667
A44: from 2 oxen sold | C44: 16 | F44: =B44+C44/20+D44/240 -> 0.8
A45: from 51 wethers sold | B45: 2 | C45: 19 | D45: 6 | F45: =B45+C45/20+D45/240 -> 2.975
A46: from skins of 11 wethers and 1 hogg | C46: 2 | D46: 3.5 | F46: =B46+C46/20+D46/240 -> 0.11458333
A47: from skins of 9 wethers and 1 hogg after shearing | E47: 9.5 | F47: =B47+C47/20+D47/240 -> 0
...

Sheet Bishops Fonthill Expenses
A1: BISHOPS FONTHILL EXPENSES
B2: £ | C2: s | D2: d | F2: Total in £ | G2: Error | H2: Notes
A3: Cost of Ploughs
A4: in iron and steel for 3 ploughs | C4: 10 | D4: 6 | F4: =B4+C4/20+D4/240 -> 0.525
A5: in 3 pairs of wheels bought | C5: 1 | F5: =B5+C5/20+D5/240 -> 0.05
A6: in 9 yokes bought | C6: 1 | F6: =B6+C6/20+D6/240 -> 0.05
A7: in 3 plough feet bought | D7: 9 | F7: =B7+C7/20+D7/240 -> 0.0375
A8: in 2 ploughshares bought | C8: 1 | D8: 8 | F8: =B8+C8/20+D8/240 -> 0.083333333
A9: in stipend of 1 carpenter making 3 ploughs | D9: 6 | F9: =B9+C9/20+D9/240 -> 0.025
A10: given to the smith in place of 2 trunks | C10: 2 | F10: =B10+C10/20+D10/240 -> 0.1
A11: in stipend of 1 oxherd for the year | C11: 3 | F11: =B11+C11/20+D11/240 -> 0.15
A12: in 6 oxen bought for ploughs | B12: 2 | C12: 12 | F12: =B12+C12/20+D12/240 -> 2.6
A13: Total recorded in accounts | B13: 3 | C13: 12 | D13: 5 | F13: =B13+C13/20+D13/240 -> 3.6208333
A14: Total | B14: =SUM(B3:B12) -> 2 | C14: =SUM(C3:C12) -> 30 | D14: =SUM(D3:D12) -> 29 | F14: =B14+C14/20+D14/240 -> 3.6208333 | G14: =F14-F13 -> 0
A15: Total capital expenses | B15: =SUM(B4:B10) -> 0 | C15: =SUM(C4:C10) -> 15 | D15: =SUM(D4:D10) -> 29 | F15: =B15+C15/20+D15/240 -> 0.87083333
A17: Cost of Carts and Wagons
A18: in clouts and nails bought for the cart | D18: 4 | F18: =B18+C18/20+D18/240 -> 0.016666667
A19: in 2 axles bought | D19: 4 | F19: =B19+C19/20+D19/240 -> 0.016666667
A20: in grease | D20: 2 | F20: =B20+C20/20+D20/240 -> 0.0083333333
A21: in stipend of 1 making 2 collars | D21: 3 | F21: =B21+C21/20+D21/240 -> 0.0125
A22: in 2 halters | D22: 2 | F22: =B22+C22/20+D22/240 -> 0.0083333333
A23: in shoeing 2 plough-horses | C23: 3 | F23: =B23+C23/20+D23/240 -> 0.15
A24: in 2 ropes bought for tethering plough horses | D24: 2 | F24: =B24+C24/20+D24/240 -> 0.0083333333
A25: in stipend of 1 carter | C25: 3 | F25: =B25+C25/20+D25/240 -> 0.15
A26: in 1 pair of traces | D26: 6 | F26: =B26+C26/20+D26/240 -> 0.025
A27: in re-covering 1 saddle | D27: 1 | F27: =B27+C27/20+D27/240 -> 0.0041666667
A28: Total recorded in accounts | C28: 8 | F28: =B28+C28/20+D28/240 -> 0.4
A29: Total | B29: =SUM(B18:B27) -> 0 | C29: =SUM(C18:C27) -> 6 | D29: =SUM(D18:D27) -> 24 | F29: =B29+C29/20+D29/240 -> 0.4 | G29: =F29-F28 -> 0
A30: Total capital expenses | B30: =SUM(B18:B24,B26:B27) -> 0 | C30: =SUM(C18:C24,C26:C27) -> 3 | D30: =SUM(D18:D24,D26:D27) -> 24 | F30: =B30+C30/20+D30/240 -> 0.25
A32: Cost of Buildings
A33: in stipend of 1 man re-roofing | C33: 1 | F33: =B33+C33/20+D33/240 -> 0.05
A34: in 1 cask bought and others repaired | C34: 3 | D34: 4.5 | F34: =B34+C34/20+D34/240 -> 0.16875
A35: in stipend of 1 man repairing the press | C35: 2 | F35: =B35+C35/20+D35/240 -> 0.1
A36: in grease bought for the same | D36: 3 | F36: =B36+C36/20+D36/240 -> 0.0125
A37: in stipend of 1 man making anew gate | C37: 2 | F37: =B37+C37/20+D37/240 -> 0.1
A38: in 1 shovel bought | D38: 1.5 | F38: =B38+C38/20+D38/240 -> 0.00625
A39: Total recorded in accounts | C39: 8 | D39: 9 | F39: =B39+C39/20+D39/240 -> 0.4375
A40: Total | B40: =SUM(B33:B38) -> 0 | C40: =SUM(C33:C38) -> 8 | D40: =SUM(D33:D38) -> 9 | F40: =B40+C40/20+D40/240 -> 0.4375 | G40: =F40-F39 -> 0
A41: Total capital expenses | B41: =SUM(B33:B38) -> 0 | C41: =SUM(C33:C38) -> 8 | D41: =SUM(D33:D38) -> 9
A43: Sheepcote
...

Sheet Issues of the Grange
B1: The issue of the grange account gives the total "yield" at the top of each heading in curly brackets, measurements used: fold, qrs, bus
B2: In "Issues of the grange" (p.xx) | G2: In "Sale of Corn" (p.x) | P2: Value of Total Production
A3: Gross output | B3: Quantity | D3: Additional bought-in | F3: Quantity | G3: Quantity noted as sold | J3: Difference Produced vs. Sold | K3: Price 1 | L3: Quantity 1 | M3: Price 2 | N3: Quantity 2 | O3: Unit price | P3: Value
B4: qrs | C4: bus | D4: qrs | E4: bus | F4: qrs | G4: qrs | H4: bus | I4: qrs | K4: £ | L4: qrs | M4: £ | N4: qrs | O4: £ per qr | P4: £
A5: Wheat | B5: 81 | C5: 7 | F5: =B5+D5+C5/8+E5/8 -> 81.875 | G5: 59 | H5: 3 | I5: =G5+H5/8 -> 59.375 | J5: =F5-I5 -> 22.5 | K5: ='Bishops Fonthill Receipts'!F58 -> 14.84375 | L5: =I5 -> 59.375 | O5: =IFERROR((K5+M5)/(L5+N5),0) -> 0.25 | P5: =O5*F5 -> 20.46875
A6: Curall | B6: 1 | C6: 1 | F6: =B6+D6+C6/8+E6/8 -> 1.125 | G6: 1 | H6: 1 | I6: =G6+H6/8 -> 1.125 | J6: =F6-I6 -> 0 | K6: ='Bishops Fonthill Receipts'!F59 -> 0.1125 | L6: =I6 -> 1.125 | O6: =IFERROR((K6+M6)/(L6+N6),0) -> 0.1 | P6: =O6*F6 -> 0.1125
A7: Barley | B7: 64 | F7: =B7+D7+C7/8+E7/8 -> 64 | G7: 29 | H7: 6 | I7: =G7+H7/8 -> 29.75 | J7: =F7-I7 -> 34.25 | K7: ='Bishops Fonthill Receipts'!F60 -> 4.9583333 | L7: =I7 -> 29.75 | O7: =IFERROR((K7+M7)/(L7+N7),0) -> 0.16666667 | P7: =O7*F7 -> 10.666667
A8: Oats | B8: 59 | C8: 6 | F8: =B8+D8+C8/8+E8/8 -> 59.75 | G8: 25 | I8: =G8+H8/8 -> 25 | J8: =F8-I8 -> 34.75 | K8: ='Bishops Fonthill Receipts'!F61 -> 2.4166667 | L8: =I8 -> 25 | O8: =IFERROR((K8+M8)/(L8+N8),0) -> 0.096666667 | P8: =O8*F8 -> 5.7758333
A9: Bere | B9: 10 | F9: =B9+D9+C9/8+E9/8 -> 10 | G9: 0 | H9: 0 | I9: =G9+H9/8 -> 0 | J9: =F9-I9 -> 10 | K9: 0 | L9: =I9 -> 0 | O9: =IFERROR((K9+M9)/(L9+N9),0) -> 0 | P9: =O9*F9 -> 0
A10: Vetches | B10: 6 | C10: 2 | F10: =B10+D10+C10/8+E10/8 -> 6.25 | G10: 3 | I10: =G10+H10/8 -> 3 | J10: =F10-I10 -> 3.25 | K10: ='Bishops Fonthill Receipts'!F62 -> 0.3 | L10: =I10 -> 3 | O10: =IFERROR((K10+M10)/(L10+N10),0) -> 0.1 | P10: =O10*F10 -> 0.625
A12: Total Production | F12: =SUM(F5:F10) -> 223 | I12: =SUM(I5:I10) -> 118.25 | J12: =SUM(J5:J10) -> 104.75 | P12: =SUM(P5:P10) -> 37.64875 | Q12: Production value is significantly more, as much less was sold than what was produced
A13: Sales of corn (as recorded in accounts) | F13: =SUM(K5:K10,M5:M10) -> 22.63125
A16: Net output | B16: Gross output | C16: Seed | F16: tithe | G16: to manorial servants & livestock | J16: Output net of tithe & seed & liveries to manorial servants | K16: in stock from last year | L16: Price | M16: Value of net output | N16: Value of sales (in "Sale of Corn")
B17: qrs | C17: qrs | D17: bus | E17: qrs | F17: qrs | G17: qrs | H17: bus | I17: qrs | J17: qrs | K17: qrs | L17: £ per qr | M17: £ | N17: £
A18: Wheat | B18: =F5 -> 81.875 | C18: 13.5 | E18: =C18+D18/8 -> 13.5 | G18: 8 | H18: 8 | I18: =G18+H18/8 -> 9 | J18: =B18-(E18+F18+I18) -> 59.375 | L18: =O5 -> 0.25 | M18: =L18*J18 -> 14.84375 | N18: =K5 -> 14.84375
A19: Curall | B19: =F6 -> 1.125 | E19: =C19+D19/8 -> 0 | I19: =G19+H19/8 -> 0 | J19: =B19-(E19+F19+I19) -> 1.125 | L19: =O6 -> 0.1 | M19: =L19*J19 -> 0.1125 | N19: =K6 -> 0.1125
A20: Barley | B20: =F7 -> 64 | C20: 13 | E20: =C20+D20/8 -> 13 | G20: 21 | H20: 2 | I20: =G20+H20/8 -> 21.25 | J20: =B20-(E20+F20+I20) -> 29.75 | L20: =O7 -> 0.16666667 | M20: =L20*J20 -> 4.9583333 | N20: =K7 -> 4.9583333
A21: Oats | B21: =F8 -> 59.75 | C21: 26 | D21: 5 | E21: =C21+D21/8 -> 26.625 | G21: 8 | H21: 1 | I21: =G21+H21/8 -> 8.125 | J21: =B21-(E21+F21+I21) -> 25 | L21: =O8 -> 0.096666667 | M21: =L21*J21 -> 2.4166667 | N21: =K8 -> 2.4166667
A22: Bere | B22: =F9 -> 10 | C22: 7 | E22: =C22+D22/8 -> 7 | G22: 3 | I22: =G22+H22/8 -> 3 | J22: =B22-(E22+F22+I22) -> 0 | L22: =O9 -> 0 | M22: =L22*J22 -> 0 | N22: =K9 -> 0
A23: Vetches | B23: =F10 -> 6.25 | C23: 1 | D23: 7 | E23: =C23+D23/8 -> 1.875 | G23: 1 | H23: 3 | I23: =G23+H23/8 -> 1.375 | J23: =B23-(E23+F23+I23) -> 3
A24: Liveries of manorial servants
A25: Total | B25: =SUM(B18:B23) -> 223 | E25: =SUM(E18:E23) -> 62 | J25: =SUM(J18:J23) -> 118.25 | M25: =SUM(M18:M23) -> 22.33125 | N25: =SUM(N18:N22) -> 22.33125

Sheet Stock
A1: EAST KNOYLE STOCK ACCOUNT
A3: Livestock | B3: Inherited stock | C3: bought | D3: produced | E3: strays | F3: herbage | G3: sold | H3: in murrain | I3: accounted for elsewhere | J3: End-period stock | K3: cross-check | L3: price 1 | M3: units 1 | N3: price 2 | O3: units 2 | P3: Weight (weys) | Q3: Unit price (£) | R3: Value of production (£) at sales prices | S3: Sales in (£) | T3: Details
A4: Cart-horses | K4: =B4+C4+D4-E4-F4-G4-H4-I4 -> 0 | Q4: =IFERROR((L4+N4)/(M4+O4),"") | R4: =IFERROR(D4*Q4,"") | S4: =IFERROR(Q4*G4,"")
A5: Mares | K5: =B5+C5+D5-E5-F5-G5-H5-I5 -> 0 | Q5: =IFERROR((L5+N5)/(M5+O5),"") | R5: =IFERROR(D5*Q5,"") | S5: =IFERROR(Q5*G5,"")
A6: Plough horses | B6: 2 | J6: 2 | K6: =B6+C6+D6-E6-F6-G6-H6-I6 -> 2 | Q6: =IFERROR((L6+N6)/(M6+O6),"") | R6: =IFERROR(D6*Q6,"") | S6: =IFERROR(Q6*G6,"")
A7: Colts (2 years) | K7: =B7+C7+D7-E7-F7-G7-H7-I7 -> 0 | Q7: =IFERROR((L7+N7)/(M7+O7),"") | R7: =IFERROR(D7*Q7,"") | S7: =IFERROR(Q7*G7,"")
A8: Colts (2 years) | K8: =B8+C8+D8-E8-F8-G8-H8-I8 -> 0 | Q8: =IFERROR((L8+N8)/(M8+O8),"") | R8: =IFERROR(D8*Q8,"") | S8: =IFERROR(Q8*G8,"")
A9: Colts (1 year) | K9: =B9+C9+D9-E9-F9-G9-H9-I9 -> 0 | Q9: =IFERROR((L9+N9)/(M9+O9),"") | R9: =IFERROR(D9*Q9,"") | S9: =IFERROR(Q9*G9,"")
A10: Foals | K10: =B10+C10+D10-E10-F10-G10-H10-I10 -> 0 | Q10: =IFERROR((L10+N10)/(M10+O10),"") | R10: =IFERROR(D10*Q10,"") | S10: =IFERROR(Q10*G10,"")
A11: Oxen | B11: 24 | C11: 6 | G11: 2 | K11: =B11+C11+D11-E11-F11-G11-H11-I11 -> 28 | L11: ='Bishops Fonthill Receipts'!F44 -> 0.8 | M11: 2 | Q11: =IFERROR((L11+N11)/(M11+O11),"") -> 0.4 | R11: =IFERROR(C11*Q11,"") -> 2.4 | S11: =IFERROR(Q11*G11,"") -> 0.8
A12: Bulls | K12: =B12+C12+D12-E12-F12-G12-H12-I12 -> 0 | Q12: =IFERROR((L12+N12)/(M12+O12),"") | R12: =IFERROR(D12*Q12,"") | S12: =IFERROR(Q12*G12,"")
A13: Cows | K13: =B13+C13+D13-E13-F13-G13-H13-I13 -> 0 | Q13: =IFERROR((L13+N13)/(M13+O13),"") | R13: =IFERROR(D13*Q13,"") | S13: =IFERROR(Q13*G13,"")
A14: Steers | K14: =B14+C14+D14-E14-F14-G14-H14-I14 -> 0 | Q14: =IFERROR((L14+N14)/(M14+O14),"") | R14: =IFERROR(D14*Q14,"") | S14: =IFERROR(Q14*G14,"")
A15: Bullocks | K15: =B15+C15+D15-E15-F15-G15-H15-I15 -> 0 | Q15: =IFERROR((L15+N15)/(M15+O15),"") | R15: =IFERROR(D15*Q15,"") | S15: =IFERROR(Q15*G15,"")
A16: Yearlings | K16: =B16+C16+D16-E16-F16-G16-H16-I16 -> 0 | Q16: =IFERROR((L16+N16)/(M16+O16),"") | R16: =IFERROR(D16*Q16,"") | S16: =IFERROR(Q16*G16,"")
A17: Calves | K17: =B17+C17+D17-E17-F17-G17-H17-I17 -> 0 | Q17: =IFERROR((L17+N17)/(M17+O17),"") | R17: =IFERROR(D17*Q17,"") | S17: =IFERROR(Q17*G17,"")
A18: Wethers | B18: 323 | D18: 34 | G18: 51 | H18: 21 | J18: 285 | K18: =B18+C18+D18-E18-F18-G18-H18-I18 -> 285 | L18: ='Bishops Fonthill Receipts'!F45 -> 2.975 | M18: 51 | Q18: =IFERROR((L18+N18)/(M18+O18),"") -> 0.058333333 | R18: =IFERROR(D18*Q18,"") -> 1.9833333 | S18: =IFERROR(Q18*G18,"") -> 2.975
A19: Rams | K19: =B19+C19+D19-E19-F19-G19-H19-I19 -> 0 | Q19: =IFERROR((L19+N19)/(M19+O19),"") | R19: =IFERROR(D19*Q19,"") | S19: =IFERROR(Q19*G19,"")
A20: Ewes | K20: =B20+C20+D20-E20-F20-G20-H20-I20 -> 0 | Q20: =IFERROR((L20+N20)/(M20+O20),"") | R20: =IFERROR(D20*Q20,"") | S20: =IFERROR(Q20*G20,"")
A21: Hoggs | K21: =B21+C21+D21-E21-F21-G21-H21-I21 -> 0 | Q21: =IFERROR((L21+N21)/(M21+O21),"") | R21: =IFERROR(D21*Q21,"") | S21: =IFERROR(Q21*G21,"")
A22: Lambs | D22: 10 | J22: 10 | K22: =B22+C22+D22-E22-F22-G22-H22-I22 -> 10 | Q22: =IFERROR((L22+N22)/(M22+O22),"") | R22: =IFERROR(D22*Q22,"") | S22: =IFERROR(Q22*G22,"")
A23: Boars | K23: =B23+C23+D23-E23-F23-G23-H23-I23 -> 0 | Q23: =IFERROR((L23+N23)/(M23+O23),"") | R23: =IFERROR(D23*Q23,"") | S23: =IFERROR(Q23*G23,"")
A24: Sows | K24: =B24+C24+D24-E24-F24-G24-H24-I24 -> 0 | Q24: =IFERROR((L24+N24)/(M24+O24),"") | R24: =IFERROR(D24*Q24,"") | S24: =IFERROR(Q24*G24,"")
A25: Pigs | B25: 40 | D25: 24 | G25: 26 | H25: 12 | J25: 26 | K25: =B25+C25+D25-E25-F25-G25-H25-I25 -> 26 | L25: ='Bishops Fonthill Receipts'!F43 -> 2.9291667 | M25: 22 | Q25: =IFERROR((L25+N25)/(M25+O25),"") -> 0.13314394 | R25: =IFERROR(D25*Q25,"") -> 3.1954545 | S25: =IFERROR(Q25*G25,"") -> 3.4617424 | T25: Sold doesn’t match receipts
A26: Hoggets | B26: 28 | H26: 4 | I26: 24 | J26: 0 | K26: =B26+C26+D26-E26-F26-G26-H26-I26 -> 0 | Q26: =IFERROR((L26+N26)/(M26+O26),"") | R26: =IFERROR(D26*Q26,"") | S26: =IFERROR(Q26*G26,"")
A27: Piglets | D27: 33 | H27: 17 | I27: 3 | J27: 13 | K27: =B27+C27+D27-E27-F27-G27-H27-I27 -> 13 | Q27: =IFERROR((L27+N27)/(M27+O27),"") | R27: =IFERROR(D27*Q27,"") | S27: =IFERROR(Q27*G27,"")
A28: Swans | K28: =B28+C28+D28-E28-F28-G28-H28-I28 -> 0 | Q28: =IFERROR((L28+N28)/(M28+O28),"") | R28: =IFERROR(D28*Q28,"") | S28: =IFERROR(Q28*G28,"")
A29: Peacocks | K29: =B29+C29+D29-E29-F29-G29-H29-I29 -> 0 | Q29: =IFERROR((L29+N29)/(M29+O29),"") | R29: =IFERROR(D29*Q29,"") | S29: =IFERROR(Q29*G29,"")
A30: Total | S30: =SUM(S4:S29) -> 7.2367424
K31: =B31+C31+D31-E31-F31-G31-H31-I31 -> 0 | Q31: =IFERROR((L31+N31)/(M31+O31),"") | R31: =IFERROR(D31*Q31,"") | S31: =IFERROR(Q31*G31,"")
K32: =B32+C32+D32-E32-F32-G32-H32-I32 -> 0 | Q32: =IFERROR((L32+N32)/(M32+O32),"") | R32: =IFERROR(D32*Q32,"") | S32: =IFERROR(Q32*G32,"")
A33: Wool | K33: =B33+C33+D33-E33-F33-G33-H33-I33 -> 0 | Q33: =IFERROR((L33+N33)/(M33+O33),"") | R33: =IFERROR(D33*Q33,"") | S33: =IFERROR(Q33*G33,"")
A34: Fleeces | D34: 316 | G34: 312 | I34: 4 | K34: =B34+C34+D34-E34-F34-G34-H34-I34 -> 0 | P34: =2+12*Assumptions!E5 -> 2.48 | Q34: 0.02 | R34: =IFERROR(D34*Q34,"") -> 6.32 | S34: =IFERROR(Q34*G34,"") -> 6.24 | T34: unit price from overview sheet (UnitPricesStocks_averages)
A35: Coarse wool | K35: =B35+C35+D35-E35-F35-G35-H35-I35 -> 0 | Q35: =IFERROR((L35+N35)/(M35+O35),"") | R35: =IFERROR(D35*Q35,"") | S35: =IFERROR(Q35*G35,"")
A36: Lamb's wool | D36: 10 | G36: 10 | K36: =B36+C36+D36-E36-F36-G36-H36-I36 -> 0 | L36: ='Bishops Fonthill Receipts'!F53 -> 0.041666667 | M36: 10 | Q36: =IFERROR((L36+N36)/(M36+O36),"") -> 0.0041666667 | R36: =IFERROR(D36*Q36,"") -> 0.041666667 | S36: =IFERROR(Q36*G36,"") -> 0.041666667
A37: Wool locks | D37: =P37 -> 0.14285714 | G37: =P37 -> 0.14285714 | K37: =B37+C37+D37-E37-F37-G37-H37-I37 -> 0 | L37: ='Bishops Fonthill Receipts'!F52 -> 0.18333333 | M37: =P37 -> 0.14285714 | P37: =2*Assumptions!E7 -> 0.14285714 | Q37: =IFERROR((L37+N37)/(M37+O37),"") -> 1.2833333 | R37: =IFERROR(D37*Q37,"") -> 0.18333333 | S37: =IFERROR(Q37*G37,"") -> 0.18333333
A38: Wool sold at shearing | K38: =B38+C38+D38-E38-F38-G38-H38-I38 -> 0 | Q38: =IFERROR((L38+N38)/(M38+O38),"") | R38: =IFERROR(D38*Q38,"") | S38: =IFERROR(Q38*G38,"")
A39: Total | K39: =B39+C39+D39-E39-F39-G39-H39-I39 -> 0 | Q39: =IFERROR((L39+N39)/(M39+O39),"") | R39: =IFERROR(D39*Q39,"") | S39: =SUM(S34:S38) -> 6.465
K40: =B40+C40+D40-E40-F40-G40-H40-I40 -> 0 | Q40: =IFERROR((L40+N40)/(M40+O40),"") | R40: =IFERROR(D40*Q40,"") | S40: =IFERROR(Q40*G40,"")
K41: =B41+C41+D41-E41-F41-G41-H41-I41 -> 0 | Q41: =IFERROR((L41+N41)/(M41+O41),"") | R41: =IFERROR(D41*Q41,"") | S41: =IFERROR(Q41*G41,"")
...

Sheet Assumptions
A1: ASSUMPTIONS
B3: Weights | C3: Value (in lbs) | D3: Value (in cloves) | E3: Value (in weys) | F3: Value (in stone)
B4: Lbs | C4: 1 | D4: =C4/C5 -> 0.14285714 | E4: =C4/C6 -> 0.0057142857 | F4: =C4/C7 -> 0.08
B5: Cloves | C5: 7 | D5: 1 | E5: =C5/C6 -> 0.04 | F5: =C7/C5 -> 1.7857143
B6: Wey | C6: 175 | D6: =C6/C5 -> 25 | E6: =C6/C6 -> 1 | F6: =C7/C6 -> 0.071428571
B7: Stone | C7: =175/14 -> 12.5 | D7: =C5/C7 -> 0.56 | E7: =C7/C6 -> 0.071428571 | F7: 1
