Workbook

Sheet Bitterne Overview - Completed
A1: BITTERNE OVERVIEW - COMPLETED | B1: Total in £ | C1: Error | D1: Note
A2: CASH ACCOUNT
A3: RECEIPTS
A4: Arrears total | B4: 7.72
A5: Rents of assize total | B5: 9.18
A6: Quittances total | B6: 0.55
A7: Defaults of rent total | B7: 0.1
A8: Defaults of rent through the pestilence total
A9: Cotlands defaults total
A10: Cotlands total
A11: Total of quittances and defaults of rent total | B11: 0.65
A12: Total of rents remaining clear total
A13: Farms total
A14: Annual recognizances total | B14: 0.1
A15: Issues of the Manor total | B15: 8.32
A16: Issues of the tenements in the lord's hands total
A17: Sale of labour services total
A18: Sale of corn total | B18: 4.48
A19: Entry and marriage fines total | B19: 3.51
A20: Pleas & perquisites total
A21: Forfeited chattels total
A22: Farm of the demesne land total
A23: Total of all receipts (calculated here) | B23: =SUM(B5:B22)
A24: Total of all receipts (calculated here) incl arrears | B24: =SUM(B4:B22)
A25: Total recorded in the accounts excl. arrears | B25: 38.31 | C25: =B23-B25
A26: Total recorded in the accounts incl. arrears | B26: =B25+B4
A29: EXPENSES
A30: Cost of ploughs total | B30: 2.0033333
A31: Purchase of corn total
A32: Cost of carts and wagons total
A33: Cost of dairy total
A34: Purchase of stock total
A35: Sheepcote total
A36: Cost of buildings total | B36: 1.46375
A37: Threshing total | B37: 0.68
A38: Barley expenses
A39: Expenses of the harvest total
A40: Necessary expenses
A41: Wages of the bailiff
A42: Steward's expenses total | B42: 3.59
...

Sheet Prices
A1: Meat & Dairy Prices
C2: 1301 | D2: 1302 | E2: Average
A3: Beef | B3: £ per lb | C3: 0.0033351854 | D3: 0.0032608538 | E3: =AVERAGE(C3:D3)
A4: Mutton | B4: £ per lb | C4: 0.0036593977 | D4: 0.0037125513 | E4: =AVERAGE(C4:D4)
A5: Pork | B5: £ per lb | C5: 0.0038431326 | D5: 0.0037574803 | E5: =AVERAGE(C5:D5)
A6: Cheese | B6: £ per lb | C6: 0.0055768754 | D6: 0.0056654898 | E6: =AVERAGE(C6:D6)
A7: Butter | B7: £ per lb | C7: 0.0036626221 | D7: 0.0035935077 | E7: =AVERAGE(C7:D7)
A8: Milk | B8: £ per gallon | C8: 0.0055768754 | D8: 0.0056654898 | E8: =AVERAGE(C8:D8)

Sheet Labour Rents

Sheet Overview
A1: BITTERNE | B1: Total in £ | C1: Error | D1: Note
A2: CASH ACCOUNT
A3: RECEIPTS
A4: Arrears total
A5: Rents of assize total
A6: Quittances total
A7: Defaults of rent total
A8: Defaults of rent through the pestilence total
A9: Cotlands defaults total
A10: Cotlands total
A11: Total of quittances and defaults of rent total
A12: Total of rents remaining clear total
A13: Farms total
... A22: Farm of the demesne land total
A23: Total of all receipts (calculated here) | B23: =Receipts!F120
A24: Total of all receipts (calculated here) incl arrears | B24: =Receipts!F121
A25: Total recorded in the accounts excl. arrears | B25: =Receipts!F119 | C25: =B25-B23
A26: Total recorded in the accounts incl. arrears
A29: EXPENSES
A30: Cost of ploughs total
A31: Purchase of corn total
A32: Cost of carts and wagons total
A33: Cost of dairy total
A34: Purchase of stock total
A35: Sheepcote total
A36: Cost of buildings total
A37: Threshing total
A38: Barley expenses
A39: Expenses of the harvest total
... A43: Annual fees
A44: Total of all expenses per account | B44: =Expenses!F135
A45: Total of all expenses (calculated here) | B45: =Expenses!F136
A46: Total fixed investment | B46: =Expenses!F137
A47: Total Demesne fixed investment | B47: =Expenses!F138
A49: Owed by the reeve
A50: From accounts
A52: Allowances
A53: Cash deliveries
A54: Sum of the above
A55: Total of all allowances and cash deliveries in accounts
...

Sheet Receipts
A1: BITTERNE RECEIPTS
A2: Heading | B2: Pounds | C2: Shillings | D2: Pence | F2: Total in Pounds | G2: Error | H2: Sentence
A3: Arrears | B3: 7 | C3: 14 | D3: 4.5 | F3: 7.72 | H3: William de Worsted', sergeant, and Walter le Parker, reeve, render account for £7 14 shilling 4.5pence of arrears from the previous year.
A4: Arrears | B4: 0 | C4: 0 | D4: 0 | F4: 0 | H4: All delivered to Sir Geoffrey, treasurer of Wolvesey.
A5: Arrears | F5: 7.72 | G5: =F5-F3 | H5: Total
A7: Rents of assize | B7: 2 | C7: 0 | D7: 3 | F7: 2.01 | H7: The same render account for £2 3pence for all rents of assize at Christmas.
A8: Rents of assize | B8: 2 | C8: 0 | D8: 3 | F8: 2.01 | H8: £2 3pence at Easter (22 April).
A9: Rents of assize | B9: 2 | C9: 0 | D9: 3 | F9: 2.01 | H9: £2 3pence at the Nativity of St John the Baptist (24 June).
A10: Rents of assize | B10: 3 | C10: 2 | D10: 11.5 | F10: 3.15 | H10: £3 2 shilling 11.5pence at Michaelmas (29 September).
A11: Rents of assize | B11: 9 | C11: 3 | D11: 8.5 | F11: 9.19 | H11: Total, £9 3 shilling 8.5pence
A12: Rents of assize | F12: 9.18 | G12: -0.01 | H12: Total
A14: Quittances | B14: 0 | C14: 4 | D14: 0 | F14: 0.2 | H14: In quittance of 1 reeve for the year 4 shilling.
A15: Quittances | B15: 0 | C15: 3 | D15: 0 | F15: 0.15 | H15: 2 ploughmen for the year 3 shilling.
A16: Quittances | B16: 0 | C16: 4 | D16: 0 | F16: 0.2 | H16: 1 park-keeper for the year 4 shilling
A17: Quittances | B17: 0 | C17: 11 | D17: 0 | F17: 0.55 | H17: Total, 11 shilling
A18: Quittances | F18: 0.55 | G18: 0 | H18: Total
A20: Defaults of rent | B20: 0 | C20: 2 | D20: 1 | F20: 0.1 | H20: In default of the land of Vyel drawn into demesne, 2 shilling 1pence for the year.
A21: Defaults of rent | B21: 0 | C21: 2 | D21: 1 | F21: 0.1 | H21: Total, 2 shilling 1pence
A22: Defaults of rent | F22: 0.1 | G22: 0 | H22: Total
A24: Total of quittances and defaults of rent | B24: 0 | C24: 13 | D24: 1 | F24: 0.65 | H24: Total of quittances and defaults of rent, 13 shilling 1pence
A25: Total of quittances and defaults of rent | F25: 0.65 | G25: =F25-F24 | H25: Total
A27: Total of rents remaining | B27: 8 | C27: 10 | D27: 7.5 | F27: 8.53 | H27: Total of rents remaining, £8 10 shilling 7.5pence
A28: Total of rents remaining | F28: 8.53 | G28: =F28-F27 | H28: Total
A30: Annual recognizance | B30: 0 | C30: 0 | D30: 6 | F30: 0.03 | H30: The same render account for 6pence from Roger le Saltere for annual recognizance.
A31: Annual recognizance | B31: 0 | C31: 0 | D31: 3 | F31: 0.01 | H31: 3pence from Richard Seuar' for the same.
A32: Annual recognizance | B32: 0 | C32: 0 | D32: 6 | F32: 0.03 | H32: 6pence from William Austyn for the same.
A33: Annual recognizance | B33: 0 | C33: 0 | D33: 6 | F33: 0.03 | H33: 6pence from Robert Clericus of Fawley for the same.
A34: Annual recognizance | B34: 0 | C34: 1 | D34: 9 | F34: 0.09 | H34: Total, 1 shilling 9pence
A35: Annual recognizance | F35: 0.1 | G35: 0.01 | H35: Total
A37: Issues of the manor | B37: 0 | C37: 10 | D37: 0 | F37: 0.5 | H37: The same render account for 10 shilling from pannage of pigs this year.
A38: Issues of the manor | B38: 0 | C38: 9 | D38: 4 | F38: 0.47 | H38: 9 shilling 4pence from the agistment of pigs in the park.
A39: Issues of the manor | B39: 0 | C39: 17 | D39: 6 | F39: 0.88 | H39: 17 shilling 6pence from the agistment of livestock in the park in summer.
A40: Issues of the manor | B40: 0 | C40: 0 | D40: 0 | F40: 0 | H40: nothing from winter pasturage on account of the lord's stock.
A41: Issues of the manor | B41: 0 | C41: 1 | D41: 0 | F41: 0.05 | H41: 1 shilling from the pasturage in Prestemed' sold after mowing.
A42: Issues of the manor | B42: 0 | C42: 0 | D42: 0 | F42: 0 | H42: nothing from winter pasturage for, the lord's stock.
A43: Issues of the manor | B43: 0 | C43: 0 | D43: 0 | F43: 0 | H43: nothing from the pasturage on the land of Bathard and in Pistok this year because it was sown.
A44: Issues of the manor | B44: 0 | C44: 0 | D44: 6 | F44: 0.03 | H44: 6pence from the pasturage in various places sold this year.
A45: Issues of the manor | B45: 0 | C45: 15 | D45: 0 | F45: 0.75 | H45: 15 shilling from 2 cart-horses sold, at 3 shilling for 1 because feeble, and 12 shilling for 1.
A46: Issues of the manor | B46: 0 | C46: 8 | D46: 0 | F46: 0.4 | H46: 8 shilling from 1 old mare sold.
A47: Issues of the manor | B47: 0 | C47: 6 | D47: 0 | F47: 0.3 | H47: 6 shilling from 6 late-born calves sold, at 1 shilling each.
...

Sheet Expenses
A1: BITTERNE EXPENSES
A2: Heading | B2: £ | C2: s | D2: d | F2: Total in £ | G2: Error | H2: Notes | J2: Fixed investment | K2: Demesne fixed investment
A3: Cost of ploughs | B3: 0 | C3: 3 | D3: 1 | F3: 0.15 | H3: In iron and steel bought for 2 ploughs for the year 3 shilling 1pence. | J3: =F3 | K3: =J3
A4: Cost of ploughs | B4: 0 | C4: 0 | D4: 5 | F4: 0.02 | H4: 1 plough foot bought 5pence. | J4: =F4 | K4: =J4
A5: Cost of ploughs | B5: 0 | C5: 0 | D5: 4.5 | F5: 0.02 | H5: 3 wheels bought for ploughs 4.5pence. | J5: =F5 | K5: =J5
A6: Cost of ploughs | B6: 0 | C6: 0 | D6: 9.5 | F6: 0.04 | H6: making a new plough and mending others and harrows 9.5pence. | J6: =F6 | K6: =J6
A7: Cost of ploughs | B7: 0 | C7: 0 | D7: 9 | F7: 0.04 | H7: 1 ploughshare bought 9pence. | J7: =F7 | K7: =J7
A8: Cost of ploughs | B8: 0 | C8: 2 | D8: 4 | F8: 0.12 | H8: stipend of the smith making the ironwork of the ploughs 2 shilling 4pence. | J8: =F8 | K8: =J8/2 | L8: halfed to account for stipend part
A9: Cost of ploughs | B9: 0 | C9: 0 | D9: 3 | F9: 0.01 | H9: fitting the wain with axles 3pence. | J9: =F9 | K9: =J9
A10: Cost of ploughs | B10: 0 | C10: 1 | D10: 5.5 | F10: 0.07 | H10: clouts, nails and grease bought for the same 1 shilling 5.5pence, and so much because it went to the marling for the whole summer. | J10: =F10 | K10: =J10
A11: Cost of ploughs | B11: 0 | C11: 0 | D11: 1.5 | F11: 0.01 | H11: cleaning iron tyres 1.5pence. | J11: =F11 | K11: =J11
A12: Cost of ploughs | B12: 0 | C12: 0 | D12: 5 | F12: 0.02 | H12: 1 rope, 6 halters and 1 pair of traces made from their own canvas 5pence. | J12: =F12 | K12: =J12
A13: Cost of ploughs | B13: 0 | C13: 10 | D13: 0 | F13: 0.5 | H13: 1 ox bought 10 shilling.
A14: Cost of ploughs | B14: 0 | C14: 6 | D14: 0 | F14: 0.3 | H14: stipend of 2 ploughmen for the year 6 shilling.
A15: Cost of ploughs | B15: 0 | C15: 1 | D15: 4 | F15: 0.07 | H15: 4 bushels of beans bought for sowing 1 shilling 4pence.
A16: Cost of ploughs | B16: 0 | C16: 12 | D16: 8 | F16: =B16+C16/20+D16/240 | H16: forage bought for supporting oxen 12 shilling 8pence
A17: Cost of ploughs | B17: 2 | C17: 0 | D17: 0 | F17: 2 | H17: Total, £2.
A18: Cost of ploughs | F18: =SUM(F3:F16) | G18: =F18-F17 | H18: Total
A20: Cost of carts | B20: 0 | C20: 0 | D20: 5.5 | F20: 0.02 | H20: In fitting the cart with axles at various times with axles bought for the same 5.5pence. | J20: =F20 | K20: =J20
A21: Cost of carts | B21: 0 | C21: 0 | D21: 6.5 | F21: 0.03 | H21: clouts, nails, grease bought for the same 6.5pence. | J21: =F21 | K21: =J21
A22: Cost of carts | B22: 0 | C22: 0 | D22: 8 | F22: 0.03 | H22: 1 collar bought 8pence. | J22: =F22 | K22: =J22
A23: Cost of carts | B23: 0 | C23: 0 | D23: 6 | F23: 0.03 | H23: white leather bought for mending harnesses 6pence. | J23: =F23 | K23: =J23
A24: Cost of carts | B24: 0 | C24: 0 | D24: 7 | F24: 0.03 | H24: a broad-axe bought for mending the cart 7pence. | J24: =F24 | K24: =J24
A25: Cost of carts | B25: 0 | C25: 0 | D25: 3 | F25: 0.01 | H25: hooping the hubs of wheels with bands of wood 3pence. | J25: =F25 | K25: =J25
A26: Cost of carts | B26: 0 | C26: 2 | D26: 6 | F26: 0.12 | H26: shoeing 2 cart-horses for the year 2 shilling 6pence. | J26: =F26 | K26: =J26
A27: Cost of carts | B27: 0 | C27: 0 | D27: 8 | F27: 0.03 | H27: shoeing 2 plough-horses going to harrow at both sowings 8pence. | J27: =F27 | K27: =J27
A28: Cost of carts | B28: 0 | C28: 3 | D28: 0 | F28: 0.15 | H28: stipend of 1 carter for the year 3 shilling.
A29: Cost of carts | B29: 0 | C29: 8 | D29: 8 | F29: 0.43 | H29: 4 quarters 2 bushels of oats bought for the fodder of horses 8 shilling 8pence
A30: Cost of carts | B30: 0 | C30: 17 | D30: 8 | F30: =B30+C30/20+D30/240 | H30: Total, 17 shilling 8pence
A31: Cost of carts | F31: 0.88 | G31: =F31-F30 | H31: Total
A33: Cost of the dairy | B33: 0 | C33: 0 | D33: 5 | F33: 0.02 | H33: In woollen and linen cloth bought for the dairy 5pence. | J33: =F33 | K33: =J33
A34: Cost of the dairy | B34: 0 | C34: 1 | D34: 5 | F34: 0.07 | H34: 5 bushels of salt bought 1 shilling .5pence. | J34: =F34 | K34: =J34
A35: Cost of the dairy | B35: 0 | C35: 0 | D35: 2 | F35: 0.01 | H35: earthenware pots and pans bought for the same 2pence. | J35: =F35 | K35: =J35
A36: Cost of the dairy | B36: 0 | C36: 0 | D36: 5 | F36: 0.02 | H36: 1 new bucket bought and another mended 5pence. | J36: =F36 | K36: =J36
A37: Cost of the dairy | B37: 0 | C37: 0 | D37: 3 | F37: 0.01 | H37: a press bought for the same 3pence. | J37: =F37 | K37: =J37
A38: Cost of the dairy | B38: 0 | C38: 1 | D38: 7.5 | F38: 0.08 | H38: 6 ells of canvas bought for putting the wool in 1 shilling7.5pence, at 3.25pence an ell. | J38: =F38 | K38: =J38
A39: Cost of the dairy | B39: 0 | C39: 0 | D39: 2 | F39: 0.01 | H39: packing the wool 2pence. | J39: =F39 | K39: =J39
A40: Cost of the dairy | B40: 0 | C40: 3 | D40: 0 | F40: 0.15 | H40: grease bought for greasing sheep 3 shilling. | J40: =F40 | K40: =J40
A41: Cost of the dairy | B41: 0 | C41: 0 | D41: 4 | F41: 0.02 | H41: 1 mould bought for making cheese 4pence. | J41: =F41 | K41: =J41
A42: Cost of the dairy | B42: 0 | C42: 1 | D42: 6 | F42: 0.08 | H42: stipend of 1 dairymaid for the year 1 shilling 6pence.
...

Sheet Issues of the Grange
A1: Gross Output | B1: Total Quantity | C1: Account Total Quarters | D1: Bought in Total Quarters | E1: Received from churchscot | F1: Sold Total Quarters | G1: Difference Produced+Bought-Sold | H1: Weighted Average Price per Quarter | I1: Value of Total Production weighted
A2: wheat | B2: 18.5 | D2: 0 | F2: 8.75 | G2: =B2-F2 | H2: 0.3 | I2: =H2*B2
A3: curall | B3: 8.625 | D3: 0 | F3: 1.25 | G3: =B3-F3 | H3: 0.21666667 | I3: =H3*B3
A4: rye | B4: 3.5 | D4: 0 | G4: =B4-F4 | I4: =H4*B4
A5: barley | B5: 49.375 | D5: 0 | G5: =B5-F5 | H5: 0.19 | I5: =H5*B5 | J5: price from East Meon
A6: dredge | B6: 14.5 | D6: 0 | F6: =11+7/8 | G6: =B6-F6 | H6: 0.083715013 | I6: =H6*B6
A7: oats | B7: 24.625 | D7: 4.25 | G7: =B7-F7 | H7: 0.10320396 | I7: =H7*B7 | J7: price from East Meon
A8: beans | B8: 0 | D8: 0.5 | G8: =B8-F8 | H8: 0.13 | I8: =H8*B8 | J8: price from East Meon Church
A9: peas | B9: 7.5 | D9: 0 | F9: 1.25 | G9: =B9-F9 | H9: 0.16 | I9: =H9*B9
A10: vetches | B10: 3 | D10: 0 | G10: =B10-F10 | H10: 0.1 | I10: =H10*B10 | J10: price from Bishops Sutton
A13: Total Production
A14: Sales of corn (as recorded in accounts)
A17: Net output | B17: Gross output | C17: Seed quarters | D17: Seed bushels | E17: Seed total quarters | F17: tithe quarters | G17: tithe bushels | H17: tithe total | I17: manorial servants quarters | J17: manorial servants bushels | K17: manorial servants total quarters | L17: output net of tithe, seed, liveries | M17: in stock from last year | N17: Price in £ | O17: Value of net output in £ | P17: Value of sales (in "Sale of Corn") in £
A18: wheat | B18: =B2 | C18: 9.5 | D18: 1 | E18: =C18+D18/8 | J18: 1 | K18: =I18+J18/8 | L18: =B18-E18-H18-K18 | N18: =H2 | O18: =N18*L18
A19: curall | B19: =B3 | E19: =C19+D19/8 | I19: =3+1 | J19: =1+1 | K19: =I19+J19/8 | L19: =B19-E19-H19-K19 | N19: =H3 | O19: =N19*L19
A20: rye | B20: =B4 | C20: 1 | D20: 6 | E20: =C20+D20/8 | I20: 1 | J20: 6 | K20: =I20+J20/8 | L20: =B20-E20-H20-K20 | N20: =H4 | O20: =N20*L20
A21: barley | B21: =B5 | C21: 14 | D21: 2 | E21: =C21+D21/8 | I21: =19.5+4+3+6.5+1 | J21: =2+1+6 | K21: =I21+J21/8 | L21: =B21-E21-H21-K21 | N21: =H5 | O21: =N21*L21
A22: dredge | B22: =B6 | C22: 2 | D22: 5 | E22: =C22+D22/8 | K22: =I22+J22/8 | L22: =B22-E22-H22-K22 | N22: =H6 | O22: =N22*L22
A23: oats | B23: =B7 | C23: 14 | D23: 2 | E23: =C23+D23/8 | I23: =7+2 | J23: =4.5+1.5+5 | K23: =I23+J23/8 | L23: =B23-E23-H23-K23 | N23: =H7 | O23: =N23*L23
A24: beans | B24: =B8 | E24: =C24+D24/8 | K24: =I24+J24/8 | L24: =B24-E24-H24-K24 | N24: =H8 | O24: =N24*L24
A25: peas | B25: =B9 | E25: =C25+D25/8 | I25: 4 | J25: 2 | K25: =I25+J25/8 | L25: =B25-E25-H25-K25 | N25: =H9 | O25: =N25*L25
A26: vetches | B26: =B10 | C26: 1 | D26: 7 | E26: =C26+D26/8 | I26: 1 | J26: 1 | K26: =I26+J26/8 | L26: =B26-E26-H26-K26 | N26: =H10 | O26: =N26*L26

Sheet Issues of the Mills

Sheet Stock
A1: BITTERNE STOCK ACCOUNT
C4: added | G4: subtracted
A5: Livestock | B5: Inherited stock | C5: added | D5: strays | E5: herbage | F5: churchscot | G5: of which in default | H5: sold | I5: in murrain | J5: accounted for elsewhere | K5: End-period stock | L5: cross-check | M5: stock building | N5: raw production | O5: Unit price (£) | P5: Value of stock (£) at given value | Q5: Value of stock (£) at sales prices | R5: Sales in (£) | S5: Value of stock building (£) | T5: Value of production (£) at sales prices | U5: Details
A6: Cart-horses | B6: 5 | H6: 2 | I6: 1 | K6: 2 | L6: =B6+C6+D6+E6+F6-G6-H6-I6-J6 | M6: =K6-B6 | O6: =R6/H6 | R6: =Receipts!F45
A7: Mares | B7: 3 | H7: 1 | K7: 2 | L7: =B7+C7+D7+E7+F7-G7-H7-I7-J7 | M7: =K7-B7 | O7: =R7/H7 | R7: =Receipts!F46
A8: Plough horses | B8: 1 | I8: 1 | K8: 0 | L8: =B8+C8+D8+E8+F8-G8-H8-I8-J8 | M8: =K8-B8
A9: Colts (unspecified years) | L9: =B9+C9+D9+E9+F9-G9-H9-I9-J9 | M9: =K9-B9
A10: Colts (2 years) | L10: =B10+C10+D10+E10+F10-G10-H10-I10-J10 | M10: =K10-B10
A11: Colts (1 year) | B11: 1 | K11: 1 | L11: =B11+C11+D11+E11+F11-G11-H11-I11-J11 | M11: =K11-B11
A12: Foals | B12: 1 | C12: 2 | K12: =1+2 | L12: =B12+C12+D12+E12+F12-G12-H12-I12-J12 | M12: =K12-B12
A13: Oxen | B13: 22 | C13: 1 | I13: 1 | K13: 22 | L13: =B13+C13+D13+E13+F13-G13-H13-I13-J13 | M13: =K13-B13
A14: Bulls | B14: 1 | K14: 1 | L14: =B14+C14+D14+E14+F14-G14-H14-I14-J14 | M14: =K14-B14
A15: Cows | B15: 10 | C15: =1+7 | K15: 18 | L15: =B15+C15+D15+E15+F15-G15-H15-I15-J15 | M15: =K15-B15
A16: Steers | B16: 1 | J16: 1 | K16: 0 | L16: =B16+C16+D16+E16+F16-G16-H16-I16-J16 | M16: =K16-B16
A17: Bullocks | B17: 5 | K17: 5 | L17: =B17+C17+D17+E17+F17-G17-H17-I17-J17 | M17: =K17-B17
A18: Yearlings | B18: 5 | I18: 2 | K18: 3 | L18: =B18+C18+D18+E18+F18-G18-H18-I18-J18 | M18: =K18-B18
A19: Calves | C19: 15 | H19: 6 | I19: 1 | K19: 7 | L19: =B19+C19+D19+E19+F19-G19-H19-I19-J19 | M19: =K19-B19 | O19: =R19/H19 | R19: =Receipts!F47
A20: Wethers | B20: 277 | C20: 1 | H20: 17 | I20: =4+17 | K20: 240 | L20: =B20+C20+D20+E20+F20-G20-H20-I20-J20 | M20: =K20-B20 | O20: =R20/H20 | R20: =Receipts!F48
A21: Rams | L21: =B21+C21+D21+E21+F21-G21-H21-I21-J21 | M21: =K21-B21
A22: Ewes | L22: =B22+C22+D22+E22+F22-G22-H22-I22-J22 | M22: =K22-B22
A23: Hoggs | L23: =B23+C23+D23+E23+F23-G23-H23-I23-J23 | M23: =K23-B23
A24: Lambs | L24: =B24+C24+D24+E24+F24-G24-H24-I24-J24 | M24: =K24-B24
A25: Boars | L25: =B25+C25+D25+E25+F25-G25-H25-I25-J25 | M25: =K25-B25
A26: Sows | B26: 1 | K26: 1 | L26: =B26+C26+D26+E26+F26-G26-H26-I26-J26 | M26: =K26-B26
A27: Pigs | B27: 6 | H27: 4 | K27: 2 | L27: =B27+C27+D27+E27+F27-G27-H27-I27-J27 | M27: =K27-B27 | O27: =R27/H27 | R27: =Receipts!F49
A28: Hoggets | B28: 1 | I28: 1 | K28: 0 | L28: =B28+C28+D28+E28+F28-G28-H28-I28-J28 | M28: =K28-B28
A29: Piglets | C29: 8 | K29: 8 | L29: =B29+C29+D29+E29+F29-G29-H29-I29-J29 | M29: =K29-B29
A30: Swans | M30: =K30-B30
A31: Peacocks | M31: =K31-B31
A32: Total Value | R32: =SUM(R6:R31)
A35: Wool | M35: =K35-B35
A36: Coarse wool | B36: 257 | J36: =26+231 | M36: =K36-B36 | O36: 0.02 | T36: =O36*J36
A37: Lamb's wool | M37: =K37-B37 | O37: 0.01
A38: Wool locks | C38: 3 | M38: =K38-B38 | R38: =Receipts!F70 | T38: =R38 | U38: 3lb of wool locks recorded as sold in issues (not in stock)
A39: Wool sold at shearing | M39: =K39-B39
A40: Total wool | T40: =SUM(T36:T39)
A43: Hides | M43: =K43-B43
A44: Ox hides | C44: 1 | H44: 1 | K44: 0 | L44: =B44+C44+D44+E44+F44-G44-H44-I44-J44 | M44: =K44-B44 | O44: =R44/H44 | R44: =Receipts!F62 | T44: =O44*C44 | U44: no ox hide found in sales, only bullock - potentially a mistake by clerk
A45: cart horse | C45: 1 | H45: 1 | K45: 0 | L45: =B45+C45+D45+E45+F45-G45-H45-I45-J45 | M45: =K45-B45 | O45: =R45/H45 | R45: =Receipts!F60 | T45: =O45*C45
A46: plough horse | C46: 1 | H46: 1 | K46: 0 | L46: =B46+C46+D46+E46+F46-G46-H46-I46-J46 | M46: =K46-B46 | O46: =R46/H46 | R46: =Receipts!F61 | T46: =O46*C46
...

Sheet raw data
A1: Heading | B1: Sentence | C1: Total in Pounds | D1: Pounds | E1: Shillings | F1: Pence | G1: Corn | H1: Total Quarters Except 1 | I1: Total Bushels Except 1 | J1: Total Corn Cross-Check | K1: Total Corn Manorial Account | L1: Corn Quantity Error | M1: Quarters 1 | N1: Bushels 1 | O1: Quarters 2 | P1: Bushels 2 | Q1: Quarters 3 | R1: Bushels 3 | S1: Quarters 4 | T1: Bushels 4 | U1: shilling a quarter 1 | V1: pence a quarter 1 | W1: shilling a quarter 2 | X1: pence a quarter 2 | Y1: shilling a quarter 3 | Z1: pence a quarter 3 | AA1: shilling a quarter 4 | AB1: pence a quarter 4 | AC1: shilling a bushel 1 | AD1: pence a bushel 1 | AE1: shilling a bushel 2 | AF1: pence a bushel 2 | AG1: shilling a bushel 3 | AH1: pence a bushel 3 | AI1: shilling a bushel 4 | AJ1: pence a bushel 4
A2: Arrears | B2: William de Worsted', sergeant, and Walter le Parker, reeve, render account for £7 14 shilling 4.5pence of arrears from the previous year. | C2: 7.72 | D2: 7 | E2: 14 | F2: 4.5 | H2: 0 | I2: 0 | J2: 0 | K2: 0 | L2: 0 | M2: 0 | N2: 0
A3: Arrears | B3: All delivered to Sir Geoffrey, treasurer of Wolvesey. | C3: 0 | D3: 0 | E3: 0 | F3: 0 | H3: 0 | I3: 0 | J3: 0 | K3: 0 | L3: 0 | M3: 0 | N3: 0
A4: Rents of assize | B4: The same render account for £2 3pence for all rents of assize at Christmas. | C4: 2.01 | D4: 2 | E4: 0 | F4: 3 | H4: 0 | I4: 0 | J4: 0 | K4: 0 | L4: 0 | M4: 0 | N4: 0
A5: Rents of assize | B5: £2 3pence at Easter (22 April). | C5: 2.01 | D5: 2 | E5: 0 | F5: 3 | H5: 0 | I5: 0 | J5: 0 | K5: 0 | L5: 0 | M5: 0 | N5: 0
A6: Rents of assize | B6: £2 3pence at the Nativity of St John the Baptist (24 June). | C6: 2.01 | D6: 2 | E6: 0 | F6: 3 | H6: 0 | I6: 0 | J6: 0 | K6: 0 | L6: 0 | M6: 0 | N6: 0
A7: Rents of assize | B7: £3 2 shilling 11.5pence at Michaelmas (29 September). | C7: 3.15 | D7: 3 | E7: 2 | F7: 11.5 | H7: 0 | I7: 0 | J7: 0 | K7: 0 | L7: 0 | M7: 0 | N7: 0
A8: Rents of assize | B8: Total, £9 3 shilling 8.5pence | C8: 9.19 | D8: 9 | E8: 3 | F8: 8.5 | H8: 0 | I8: 0 | J8: 0 | K8: 0 | L8: 0 | M8: 0 | N8: 0
A9: Quittances | B9: In quittance of 1 reeve for the year 4 shilling. | C9: 0.2 | D9: 0 | E9: 4 | F9: 0 | H9: 0 | I9: 0 | J9: 0 | K9: 0 | L9: 0 | M9: 0 | N9: 0
A10: Quittances | B10: 2 ploughmen for the year 3 shilling. | C10: 0.15 | D10: 0 | E10: 3 | F10: 0 | H10: 0 | I10: 0 | J10: 0 | K10: 0 | L10: 0 | M10: 0 | N10: 0
A11: Quittances | B11: 1 park-keeper for the year 4 shilling | C11: 0.2 | D11: 0 | E11: 4 | F11: 0 | H11: 0 | I11: 0 | J11: 0 | K11: 0 | L11: 0 | M11: 0 | N11: 0
A12: Quittances | B12: Total, 11 shilling | C12: 0.55 | D12: 0 | E12: 11 | F12: 0 | H12: 0 | I12: 0 | J12: 0 | K12: 0 | L12: 0 | M12: 0 | N12: 0
A13: Defaults of rent | B13: In default of the land of Vyel drawn into demesne, 2 shilling 1pence for the year. | C13: 0.1 | D13: 0 | E13: 2 | F13: 1 | H13: 0 | I13: 0 | J13: 0 | K13: 0 | L13: 0 | M13: 0 | N13: 0
... A59: Fishery | B59: The same render account for £7 4 shilling from 53 salmon sold, at 4 shilling each for 19, and 2 shilling each for 34. Total, £7 4 shilling | C59: 7.2 | D59: 7 | E59: 4 | F59: 0 | H59: 0 | I59: 0 | J59: 0 | K59: 0 | L59: 0 | M59: 0 | N59: 0
A60: Sale of corn | B60: The same render account for £2 12 shilling 6pence from 8 quarters 6 bushels of wheat sold, at 6 shilling a quarters. | C60: 2.62 | D60: 2 | E60: 12 | F60: 6 | G60: wheat | H60: 8 | I60: 6 | J60: 8.75 | K60: 8.75 | L60: 0 | M60: 8 | N60: 6 | U60: 6 | V60: 0
A61: Sale of corn | B61: 5 shilling 5pence from 1 quarters 2 bushels of curall sold, at 4 shilling 4pence a quarters. | C61: 0.27 | D61: 0 | E61: 5 | F61: 5 | G61: curall | H61: 1 | I61: 2 | J61: 1.25 | K61: 1.25 | L61: 0 | M61: 1 | N61: 2 | U61: 4 | V61: 4
A62: Sale of corn | B62: £1 6 shilling 5pence from 11 quarters 3 bushels of dredge sold, at 2 shilling a quarters for 3 quarters 7 bushels, 2 shilling 4pence a quarters for 4 quarters, and 2 shilling 8pence a quarters for 3.5 quarters. | C62: 1.32 | D62: 1 | E62: 6 | F62: 5 | H62: 10.5 | I62: 7 | J62: 11.375 | K62: 11.375 | L62: 0 | M62: 11 | N62: 3 | O62: 3 | P62: 7 | Q62: 4 | R62: 0 | S62: 3.5 | T62: 0 | U62: 2 | V62: 0 | W62: 2 | X62: 4 | Y62: 2 | Z62: 8
A63: Sale of corn | B63: 1 shilling from .5 quarters of dredge sold at the audit. | C63: 0.05 | D63: 0 | E63: 1 | F63: 0 | H63: 5 | I63: 0 | J63: 5 | K63: 5 | L63: 0 | M63: 5 | N63: 0
A64: Sale of corn | B64: 2 shilling from 4 bushels of peas sold, at 6pence a bushels. | C64: 0.12 | D64: 0 | E64: 2 | F64: 6 | G64: peas | H64: 0 | I64: 4 | J64: 0.5 | K64: 0.5 | L64: 0 | M64: 0 | N64: 4 | AC64: 0 | AD64: 6
A65: Sale of corn | B65: 2 shilling from 6 bushels of peas sold at the audit. | C65: 0.1 | D65: 0 | E65: 2 | F65: 0 | G65: peas | H65: 0 | I65: 6 | J65: 0.75 | K65: 0.75 | L65: 0 | M65: 0 | N65: 6
A66: Sale of corn | B66: Total, £4 9 shilling 4pence | C66: 4.47 | D66: 4 | E66: 9 | F66: 4 | H66: 0 | I66: 0 | J66: 0 | K66: 0 | L66: 0 | M66: 0 | N66: 0
A67: Sale of the mill's corn | B67: The same render account for 10 shilling 3pence from 1 quarters 7 bushels of wheat sold, at 7.5pence a bushels for 2 bushels, 5 shilling 4pence a quarters for 1 quarters 1 bushels, and 9pence a bushels for 4 bushels. | C67: 0.51 | D67: 0 | E67: 10 | F67: 3 | G67: wheat | H67: 1 | I67: 7 | J67: 1.875 | K67: 1.875 | L67: 0 | M67: 1 | N67: 7 | O67: 0 | P67: 2 | Q67: 1 | R67: 1 | S67: 0 | T67: 4 | U67: 5 | V67: 4 | AC67: 0 | AD67: 7.5 | AE67: 0 | AF67: 9
A68: Sale of the mill's corn | B68: £1 15 shilling 10pence from 11 quarters 6 bushels of barley sold, at 2 shilling 8pence a quarters for 3 quarters, 3 shilling a quarters for 4 quarters, and 3 shilling 4pence a quarters for 4 quarters 6 bushels. | C68: 1.79 | D68: 1 | E68: 15 | F68: 10 | G68: barley | H68: 11 | I68: 6 | J68: 11.75 | K68: 11.75 | L68: 0 | M68: 11 | N68: 6 | O68: 3 | P68: 0 | Q68: 4 | R68: 0 | S68: 4 | T68: 6 | U68: 2 | V68: 8 | W68: 3 | X68: 0 | Y68: 3 | Z68: 4
A69: Sale of the mill's corn | B69: 1 1 shilling from 2 quarters 1 bushels of coarse-ground corn sold, at 5 shilling for 1 quarters, and 5 shilling 4pence a quarters for 1 quarters 1 bushels. | C69: 0.07 | D69: 0 | E69: 1 | F69: 4 | H69: 2 | I69: 1 | J69: 2.125 | K69: 2.125 | L69: 0 | M69: 2 | N69: 1 | O69: 1 | P69: 0 | Q69: 1 | R69: 1 | U69: 5 | V69: 4
A70: Sale of the mill's corn | B70: 10 shilling 9pence from 4 quarters 7 bushels of malt sold, at 2 shilling a quarters for 1 quarters 7 bushels, and 2 shilling 4pence a quarters for 3 quarters. | C70: 0.54 | D70: 0 | E70: 10 | F70: 9 | H70: 4 | I70: 7 | J70: 4.875 | K70: 4.875 | L70: 0 | M70: 4 | N70: 7 | O70: 1 | P70: 7 | Q70: 3 | R70: 0 | U70: 2 | V70: 0 | W70: 2 | X70: 4
A71: Sale of the mill's corn | B71: 8pence from 1 bushels of oatmeal sold Total, £3 8 shilling 6pence | C71: 3.42 | D71: 3 | E71: 8 | F71: 6 | G71: oatmeal | H71: 0 | I71: 1 | J71: 0.125 | K71: 0.125 | L71: 0 | M71: 0 | N71: 1
A72: Entry and marriage fines | B72: The same render account for 6 shilling 8pence from the tithing of Bitterne at the hundred-court of Martinmas for tithingpenny. | C72: 0.33 | D72: 0 | E72: 6 | F72: 8 | H72: 0 | I72: 0 | J72: 0 | K72: 0 | L72: 0 | M72: 0 | N72: 0
A73: Entry and marriage fines | B73: 6 shilling 8pence from the tithing of Fawley at the said hundred-court for the same. | C73: 0.33 | D73: 0 | E73: 6 | F73: 8 | H73: 0 | I73: 0 | J73: 0 | K73: 0 | L73: 0 | M73: 0 | N73: 0
A74: Entry and marriage fines | B74: 13 shilling 4pence from the same at the hundred-court of Hockday for the same. | C74: 0.67 | D74: 0 | E74: 13 | F74: 4 | H74: 0 | I74: 0 | J74: 0 | K74: 0 | L74: 0 | M74: 0 | N74: 0
A75: Entry and marriage fines | B75: 1 shilling from John le Careter for marrying Joan his stepdaughter outside. | C75: 0.05 | D75: 0 | E75: 1 | F75: 0 | H75: 0 | I75: 0 | J75: 0 | K75: 0 | L75: 0 | M75: 0 | N75: 0
A76: Entry and marriage fines | B76: 3 shilling from .Havvise, daughter of Austin Mich', to have 1 house and 2 acres of land which belonged to Edith her mother. | C76: 0.15 | D76: 0 | E76: 3 | F76: 0 | H76: 0 | I76: 0 | J76: 0 | K76: 0 | L76: 0 | M76: 0 | N76: 0
A77: Entry and marriage fines | B77: 6 shilling 8pence from Matilda, daughter of Mabel Ace, to have 1 messuage and 1 ferling of land by surrender of Mabel her mother, so that the said Mabel be supported by holding the same land equally with her. | C77: 0.33 | D77: 0 | E77: 6 | F77: 8 | H77: 0 | I77: 0 | J77: 0 | K77: 0 | L77: 0 | M77: 0 | N77: 0
A78: Entry and marriage fines | B78: 6 shilling 8pence from Nicholas le Pyn to have the said Matilda with her land. | C78: 0.33 | D78: 0 | E78: 6 | F78: 8 | H78: 0 | I78: 0 | J78: 0 | K78: 0 | L78: 0 | M78: 0 | N78: 0
A79: Entry and marriage fines | B79: 6 shilling 8pence from Walter le Schepphurd' to have the land which belonged to his mother. | C79: 0.33 | D79: 0 | E79: 6 | F79: 8 | H79: 0 | I79: 0 | J79: 0 | K79: 0 | L79: 0 | M79: 0 | N79: 0
A80: Entry and marriage fines | B80: 13 shilling 4pence from Roger ate Clive to have the land which belonged to Gunilda Gardenir. | C80: 0.67 | D80: 0 | E80: 13 | F80: 4 | H80: 0 | I80: 0 | J80: 0 | K80: 0 | L80: 0 | M80: 0 | N80: 0
A81: Entry and marriage fines | B81: 3 shilling 4pence from Roger Westsyd' to have 1 house and 1 curtilage by surrender of Walter le Schiphurd', and he will relieve the said Walter of 6pence annual rent. | C81: 0.17 | D81: 0 | E81: 3 | F81: 4 | H81: 0 | I81: 0 | J81: 0 | K81: 0 | L81: 0 | M81: 0 | N81: 0
A82: Entry and marriage fines | B82: 1 shilling from Joan Alayn for marrying herself. | C82: 0.05 | D82: 0 | E82: 1 | F82: 0 | H82: 0 | I82: 0 | J82: 0 | K82: 0 | L82: 0 | M82: 0 | N82: 0
A83: Entry and marriage fines | B83: 1 shilling from Margery, daughter of Walter le Schiphurd', for marrying herself. | C83: 0.05 | D83: 0 | E83: 1 | F83: 0 | H83: 0 | I83: 0 | J83: 0 | K83: 0 | L83: 0 | M83: 0 | N83: 0
... A104: Cost of ploughs | B104: stipend of 2 ploughmen for the year 6 shilling. | C104: 0.3 | D104: 0 | E104: 6 | F104: 0 | H104: 0 | I104: 0 | J104: 0 | K104: 0 | L104: 0 | M104: 0 | N104: 0
A105: Cost of ploughs | B105: 4 bushels of beans bought for sowing 1 shilling 4pence. | C105: 0.07 | D105: 0 | E105: 1 | F105: 4 | G105: beans | H105: 0 | I105: 4 | J105: 0.5 | K105: 0.5 | L105: 0 | M105: 0 | N105: 4
...

Sheet Issues of the Grange raw
A1: Heading | B1: Sentence | C1: Quarters 1_x | D1: Bushels 1_x | E1: Sown Quarters | F1: Sown Bushels | G1: Sown Total Quarters | H1: Bought in Quarters | I1: Bought in Bushels | J1: Bought in Total Quarters | K1: Tithe Quarters | L1: Tithe Bushels | M1: Tithe Total Quarters | N1: Manorial servants & livestock Quarters | O1: Manorial servants & livestock Bushels | P1: Manorial servants & livestock Total Quarters | Q1: Sold Quarters | R1: Sold Bushels | S1: Sold Total Quarters | T1: Account Quarters | U1: Account Bushels | V1: Account Total Quarters | W1: bought only | X1: Total Quarters Except 1 | Y1: Total Bushels Except 1 | Z1: Total Corn Cross-Check | AA1: Total Corn Manorial Account | AB1: Corn Quantity Error | AC1: Quarters 1_y | AD1: Bushels 1_y | AE1: Quarters 2 | AF1: Bushels 2 | AG1: Quarters 3 | AH1: Bushels 3 | AI1: Quarters 4 | AJ1: Bushels 4
A2: And thus he owes clear | B2: Total | C2: 0 | D2: 0 | E2: 0 | F2: 0 | G2: 0 | H2: 0 | I2: 0 | J2: 0 | K2: 0 | L2: 0 | M2: 0 | N2: 0 | O2: 0 | P2: 0 | Q2: 0 | R2: 0 | S2: 0 | T2: 0 | U2: 0 | V2: 0 | W2: 0
A3: Wheat | B3: {yield: two-fold plus 1 qr 4 bushels) | C3: 0 | D3: 0 | E3: 0 | F3: 0 | G3: 0 | H3: 0 | I3: 0 | J3: 0 | K3: 0 | L3: 0 | M3: 0 | N3: 0 | O3: 0 | P3: 0 | Q3: 0 | R3: 0 | S3: 0 | T3: 0 | U3: 0 | V3: 0 | W3: 0
A4: Wheat | B4: The same render account for 18.5 quarters from the whole issue of wheat by struck measure. | C4: 0 | D4: 0 | E4: 0 | F4: 0 | G4: 0 | H4: 0 | I4: 0 | J4: 0 | K4: 0 | L4: 0 | M4: 0 | N4: 0 | O4: 0 | P4: 0 | Q4: 0 | R4: 0 | S4: 0 | T4: 18.5 | U4: 0 | V4: 18.5 | W4: 0 | X4: 18.5 | Y4: 0 | Z4: 18.5 | AA4: 18.5 | AB4: 0 | AC4: 18.5 | AD4: 0
A5: Wheat | B5: Sown over 68 acres as they lie in Gildewyneslond', 9.5 quarters 1 bushels. | C5: 0 | D5: 0 | E5: 9.5 | F5: 1 | G5: 9.625 | H5: 0 | I5: 0 | J5: 0 | K5: 0 | L5: 0 | M5: 0 | N5: 0 | O5: 0 | P5: 0 | Q5: 0 | R5: 0 | S5: 0 | T5: 0 | U5: 0 | V5: 0 | W5: 0 | X5: 9.5 | Y5: 1 | Z5: 9.625 | AA5: 9.625 | AB5: 0 | AC5: 9.5 | AD5: 1
A6: Wheat | B6: that is, 1 bushels an acre, plus 1 qr 1 bushels in all. | C6: 0 | D6: 0 | E6: 0 | F6: 0 | G6: 0 | H6: 0 | I6: 0 | J6: 0 | K6: 0 | L6: 0 | M6: 0 | N6: 0 | O6: 0 | P6: 0 | Q6: 0 | R6: 0 | S6: 0 | T6: 0 | U6: 0 | V6: 0 | W6: 0
A7: Wheat | B7: . | C7: 0 | D7: 0 | E7: 0 | F7: 0 | G7: 0 | H7: 0 | I7: 0 | J7: 0 | K7: 0 | L7: 0 | M7: 0 | N7: 0 | O7: 0 | P7: 0 | Q7: 0 | R7: 0 | S7: 0 | T7: 0 | U7: 0 | V7: 0 | W7: 0 | X7: 0 | Y7: 0 | Z7: 0 | AA7: 0 | AB7: 0 | AC7: 0 | AD7: 0
A8: Wheat | B8: provision of the steward for his visits, 1 bushels Sold, 8 quarters 6 bushels | C8: 0 | D8: 0 | E8: 0 | F8: 0 | G8: 0 | H8: 0 | I8: 0 | J8: 0 | K8: 0 | L8: 0 | M8: 0 | N8: 8 | O8: 6 | P8: 8.75 | Q8: 8 | R8: 6 | S8: 8.75 | T8: 0 | U8: 0 | V8: 0 | W8: 0 | X8: 8 | Y8: 6 | Z8: 8.75 | AA8: 0.125 | AB8: 8.625 | AC8: 0 | AD8: 1 | AE8: 8 | AF8: 6
A9: Wheat | B9: Total | C9: 0 | D9: 0 | E9: 0 | F9: 0 | G9: 0 | H9: 0 | I9: 0 | J9: 0 | K9: 0 | L9: 0 | M9: 0 | N9: 0 | O9: 0 | P9: 0 | Q9: 0 | R9: 0 | S9: 0 | T9: 0 | U9: 0 | V9: 0 | W9: 0
A10: Curall | B10: The same render account for 8 quarters .5 bushels from the whole issue of curall from the same wheat by struck measure. | C10: 0 | D10: 0 | E10: 0 | F10: 0 | G10: 0 | H10: 0 | I10: 0 | J10: 0 | K10: 0 | L10: 0 | M10: 0 | N10: 0 | O10: 0 | P10: 0 | Q10: 0 | R10: 0 | S10: 0 | T10: 8 | U10: 0 | V10: 8 | W10: 0 | X10: 8 | Y10: 5 | Z10: 8.625 | AA10: 8 | AB10: 0.625 | AC10: 8 | AD10: 0 | AE10: 0 | AF10: 5
A11: Curall | B11: Mixed with barley for the liveries of the manorial servants, 3 quarters 1 bushels. | C11: 0 | D11: 0 | E11: 0 | F11: 0 | G11: 0 | H11: 0 | I11: 0 | J11: 0 | K11: 0 | L11: 0 | M11: 0 | N11: 3 | O11: 1 | P11: 3.125 | Q11: 0 | R11: 0 | S11: 0 | T11: 0 | U11: 0 | V11: 0 | W11: 0 | X11: 3 | Y11: 1 | Z11: 3.125 | AA11: 3.125 | AB11: 0 | AC11: 3 | AD11: 1
A12: Curall | B12: supporting pigs, 1 qr 1 bushels Sold, 1 qr 2 bushels Total, 5.5 quarters. | C12: 0 | D12: 0 | E12: 0 | F12: 0 | G12: 0 | H12: 0 | I12: 0 | J12: 0 | K12: 0 | L12: 0 | M12: 0 | N12: 0 | O12: 0 | P12: 0 | Q12: 5.5 | R12: 0 | S12: 5.5 | T12: 0 | U12: 0 | V12: 0 | W12: 0
A13: Curall | B13: And 2.5 quarters .5 bushels remain in the granary. | C13: 0 | D13: 0 | E13: 0 | F13: 0 | G13: 0 | H13: 0 | I13: 0 | J13: 0 | K13: 0 | L13: 0 | M13: 0 | N13: 0 | O13: 0 | P13: 0 | Q13: 0 | R13: 0 | S13: 0 | T13: 0 | U13: 0 | V13: 0 | W13: 0 | X13: 2.5 | Y13: 5 | Z13: 3.125 | AA13: 2.5 | AB13: 0.625 | AC13: 2.5 | AD13: 0 | AE13: 0 | AF13: 5
A14: Curall | B14: Total | C14: 0 | D14: 0 | E14: 0 | F14: 0 | G14: 0 | H14: 0 | I14: 0 | J14: 0 | K14: 0 | L14: 0 | M14: 0 | N14: 0 | O14: 0 | P14: 0 | Q14: 0 | R14: 0 | S14: 0 | T14: 0 | U14: 0 | V14: 0 | W14: 0
A15: Rye | B15: {yield: two-and-a-half-fold plus .51} | C15: 0 | D15: 0 | E15: 0 | F15: 0 | G15: 0 | H15: 0 | I15: 0 | J15: 0 | K15: 0 | L15: 0 | M15: 0 | N15: 0 | O15: 0 | P15: 0 | Q15: 0 | R15: 0 | S15: 0 | T15: 0 | U15: 0 | V15: 0 | W15: 0 | X15: 0 | Y15: 0 | Z15: 0 | AA15: 0 | AB15: 0 | AC15: 0 | AD15: 0
A16: Rye | B16: The same render account for 3.5 quarters from the whole issue of rye by struck measure. | C16: 0 | D16: 0 | E16: 0 | F16: 0 | G16: 0 | H16: 0 | I16: 0 | J16: 0 | K16: 0 | L16: 0 | M16: 0 | N16: 0 | O16: 0 | P16: 0 | Q16: 0 | R16: 0 | S16: 0 | T16: 3.5 | U16: 0 | V16: 3.5 | W16: 0 | X16: 3.5 | Y16: 0 | Z16: 3.5 | AA16: 3.5 | AB16: 0 | AC16: 3.5 | AD16: 0
A17: Rye | B17: Sown over 12 acres as they lie in Westbynne, 1 qr 6 bushels. | C17: 0 | D17: 0 | E17: 0 | F17: 0 | G17: 0 | H17: 0 | I17: 0 | J17: 0 | K17: 0 | L17: 0 | M17: 0 | N17: 0 | O17: 0 | P17: 0 | Q17: 0 | R17: 0 | S17: 0 | T17: 0 | U17: 0 | V17: 0 | W17: 0
A18: Rye | B18: that is, 1 bushels an acre, plus 2 bushels in all. | C18: 0 | D18: 0 | E18: 0 | F18: 0 | G18: 0 | H18: 0 | I18: 0 | J18: 0 | K18: 0 | L18: 0 | M18: 0 | N18: 0 | O18: 0 | P18: 0 | Q18: 0 | R18: 0 | S18: 0 | T18: 0 | U18: 0 | V18: 0 | W18: 0 | X18: 0 | Y18: 2 | Z18: 0.25 | AA18: 0.125 | AB18: 0.125 | AC18: 0 | AD18: 1 | AE18: 0 | AF18: 2
A19: Rye | B19: Mixed with barley for the liveries of the manorial servants, 1 qr 6 bushels It balances. | C19: 0 | D19: 0 | E19: 0 | F19: 0 | G19: 0 | H19: 0 | I19: 0 | J19: 0 | K19: 0 | L19: 0 | M19: 0 | N19: 0 | O19: 0 | P19: 0 | Q19: 0 | R19: 0 | S19: 0 | T19: 0 | U19: 0 | V19: 0 | W19: 0
A20: Rye | B20: Total | C20: 0 | D20: 0 | E20: 0 | F20: 0 | G20: 0 | H20: 0 | I20: 0 | J20: 0 | K20: 0 | L20: 0 | M20: 0 | N20: 0 | O20: 0 | P20: 0 | Q20: 0 | R20: 0 | S20: 0 | T20: 0 | U20: 0 | V20: 0 | W20: 0
A21: Barley | B21: {yield: two-and-a-half-fold plus 2 quarters} | C21: 0 | D21: 0 | E21: 0 | F21: 0 | G21: 0 | H21: 0 | I21: 0 | J21: 0 | K21: 0 | L21: 0 | M21: 0 | N21: 0 | O21: 0 | P21: 0 | Q21: 0 | R21: 0 | S21: 0 | T21: 0 | U21: 0 | V21: 0 | W21: 0 | X21: 2 | Y21: 0 | Z21: 2 | AA21: 2 | AB21: 0 | AC21: 2 | AD21: 0
A22: Barley | B22: The same render account for 39 quarters 1 bushels from the whole issue of barley by struck measure. | C22: 0 | D22: 0 | E22: 0 | F22: 0 | G22: 0 | H22: 0 | I22: 0 | J22: 0 | K22: 0 | L22: 0 | M22: 0 | N22: 0 | O22: 0 | P22: 0 | Q22: 0 | R22: 0 | S22: 0 | T22: 39 | U22: 1 | V22: 39.125 | W22: 0 | X22: 39 | Y22: 1 | Z22: 39.125 | AA22: 39.125 | AB22: 0 | AC22: 39 | AD22: 1
A23: Barley | B23: 3 quarters 1 bushels received from curall and mixed with barley for the liveries of the manorial servants. | C23: 0 | D23: 0 | E23: 0 | F23: 0 | G23: 0 | H23: 0 | I23: 0 | J23: 0 | K23: 0 | L23: 0 | M23: 0 | N23: 3 | O23: 1 | P23: 3.125 | Q23: 0 | R23: 0 | S23: 0 | T23: 0 | U23: 0 | V23: 0 | W23: 0 | X23: 3 | Y23: 1 | Z23: 3.125 | AA23: 3.125 | AB23: 0 | AC23: 3 | AD23: 1
A24: Barley | B24: 1 qr 6 bushels received from rye. | C24: 0 | D24: 0 | E24: 0 | F24: 0 | G24: 0 | H24: 0 | I24: 0 | J24: 0 | K24: 0 | L24: 0 | M24: 0 | N24: 0 | O24: 0 | P24: 0 | Q24: 0 | R24: 0 | S24: 0 | T24: 0 | U24: 0 | V24: 0 | W24: 0
A25: Barley | B25: 4 quarters 2 bushels received from peas. | C25: 0 | D25: 0 | E25: 0 | F25: 0 | G25: 0 | H25: 0 | I25: 0 | J25: 0 | K25: 0 | L25: 0 | M25: 0 | N25: 0 | O25: 0 | P25: 0 | Q25: 0 | R25: 0 | S25: 0 | T25: 0 | U25: 0 | V25: 0 | W25: 0 | X25: 4 | Y25: 2 | Z25: 4.25 | AA25: 4.25 | AB25: 0 | AC25: 4 | AD25: 2
A26: Barley | B26: 1 qr 1 bushels received from vetches and mixed for the same. | C26: 0 | D26: 0 | E26: 0 | F26: 0 | G26: 0 | H26: 0 | I26: 0 | J26: 0 | K26: 0 | L26: 0 | M26: 0 | N26: 0 | O26: 0 | P26: 0 | Q26: 0 | R26: 0 | S26: 0 | T26: 0 | U26: 0 | V26: 0 | W26: 0
A27: Barley | B27: Total, 49 quarters 3 bushels Sown over 75 acres as they lie in Bathardefeld', 14 quarters 2 bushels. | C27: 0 | D27: 0 | E27: 63 | F27: 5 | G27: 63.625 | H27: 0 | I27: 0 | J27: 0 | K27: 0 | L27: 0 | M27: 0 | N27: 0 | O27: 0 | P27: 0 | Q27: 0 | R27: 0 | S27: 0 | T27: 0 | U27: 0 | V27: 0 | W27: 0 | X27: 14 | Y27: 2 | Z27: 14.25 | AA27: 49.375 | AB27: -35.125 | AC27: 49 | AD27: 3 | AE27: 14 | AF27: 2
A28: Barley | B28: that is, 1.5 bushels an acre, less 1.5 bushels in all. | C28: 0 | D28: 0 | E28: 0 | F28: 0 | G28: 0 | H28: 0 | I28: 0 | J28: 0 | K28: 0 | L28: 0 | M28: 0 | N28: 0 | O28: 0 | P28: 0 | Q28: 0 | R28: 0 | S28: 0 | T28: 0 | U28: 0 | V28: 0 | W28: 0 | X28: 0 | Y28: 1.5 | Z28: 0.1875 | AA28: 0.1875 | AB28: 0 | AC28: 0 | AD28: 1.5 | AE28: 0 | AF28: 1.5
A29: Barley | B29: Delivered to 1 carter and 2 drovers for the year, 19.5 quarters, taking a quarter every 8 weeks. | C29: 0 | D29: 0 | E29: 0 | F29: 0 | G29: 0 | H29: 0 | I29: 0 | J29: 0 | K29: 0 | L29: 0 | M29: 0 | N29: 0 | O29: 0 | P29: 0 | Q29: 0 | R29: 0 | S29: 0 | T29: 0 | U29: 0 | V29: 0 | W29: 0 | X29: 19.5 | Y29: 0 | Z29: 19.5 | AA29: 19.5 | AB29: 0 | AC29: 19.5 | AD29: 0
A30: Barley | B30: Delivered to 1 cowherd for the year, 4 quarters 2 bushels, taking a quarter every 12 weeks. | C30: 0 | D30: 0 | E30: 0 | F30: 0 | G30: 0 | H30: 0 | I30: 0 | J30: 0 | K30: 0 | L30: 0 | M30: 0 | N30: 0 | O30: 0 | P30: 0 | Q30: 0 | R30: 0 | S30: 0 | T30: 0 | U30: 0 | V30: 0 | W30: 0 | X30: 4 | Y30: 2 | Z30: 4.25 | AA30: 4.25 | AB30: 0 | AC30: 4 | AD30: 2
A31: Barley | B31: Delivered to 1 dairymaid for the year, 3 quarters 1 bushels, taking a quarter every 16 weeks. | C31: 0 | D31: 0 | E31: 0 | F31: 0 | G31: 0 | H31: 0 | I31: 0 | J31: 0 | K31: 0 | L31: 0 | M31: 0 | N31: 0 | O31: 0 | P31: 0 | Q31: 0 | R31: 0 | S31: 0 | T31: 0 | U31: 0 | V31: 0 | W31: 0 | X31: 3 | Y31: 1 | Z31: 3.125 | AA31: 3.125 | AB31: 0 | AC31: 3 | AD31: 1
A32: Barley | B32: Delivered to 1 shepherd for the year, 6.5 quarters, taking a quarter every 8 weeks. | C32: 0 | D32: 0 | E32: 0 | F32: 0 | G32: 0 | H32: 0 | I32: 0 | J32: 0 | K32: 0 | L32: 0 | M32: 0 | N32: 0 | O32: 0 | P32: 0 | Q32: 0 | R32: 0 | S32: 0 | T32: 0 | U32: 0 | V32: 0 | W32: 0 | X32: 6.5 | Y32: 0 | Z32: 6.5 | AA32: 6.5 | AB32: 0 | AC32: 6.5 | AD32: 0
A33: Barley | B33: . | C33: 0 | D33: 0 | E33: 0 | F33: 0 | G33: 0 | H33: 0 | I33: 0 | J33: 0 | K33: 0 | L33: 0 | M33: 0 | N33: 0 | O33: 0 | P33: 0 | Q33: 0 | R33: 0 | S33: 0 | T33: 0 | U33: 0 | V33: 0 | W33: 0 | X33: 0 | Y33: 0 | Z33: 0 | AA33: 0 | AB33: 0 | AC33: 0 | AD33: 0
A34: Barley | B34: customary payment to 1 park-keeper, 1 qr. | C34: 0 | D34: 0 | E34: 0 | F34: 0 | G34: 0 | H34: 0 | I34: 0 | J34: 0 | K34: 0 | L34: 0 | M34: 0 | N34: 0 | O34: 0 | P34: 0 | Q34: 0 | R34: 0 | S34: 0 | T34: 0 | U34: 0 | V34: 0 | W34: 0
A35: Barley | B35: Delivered to 1 harrower at various times at both sowings, 6 bushels It balances. | C35: 0 | D35: 0 | E35: 0 | F35: 0 | G35: 0 | H35: 0 | I35: 0 | J35: 0 | K35: 0 | L35: 0 | M35: 0 | N35: 0 | O35: 0 | P35: 0 | Q35: 0 | R35: 0 | S35: 0 | T35: 0 | U35: 0 | V35: 0 | W35: 0 | X35: 0 | Y35: 6 | Z35: 0.75 | AA35: 0.75 | AB35: 0 | AC35: 0 | AD35: 6
A36: Barley | B36: Total | C36: 0 | D36: 0 | E36: 0 | F36: 0 | G36: 0 | H36: 0 | I36: 0 | J36: 0 | K36: 0 | L36: 0 | M36: 0 | N36: 0 | O36: 0 | P36: 0 | Q36: 0 | R36: 0 | S36: 0 | T36: 0 | U36: 0 | V36: 0 | W36: 0
A37: Dredge | B37: {yield: four-fold less .5 qr} | C37: 0 | D37: 0 | E37: 0 | F37: 0 | G37: 0 | H37: 0 | I37: 0 | J37: 0 | K37: 0 | L37: 0 | M37: 0 | N37: 0 | O37: 0 | P37: 0 | Q37: 0 | R37: 0 | S37: 0 | T37: 0 | U37: 0 | V37: 0 | W37: 0
A38: Dredge | B38: The same render account for 14.5 quarters from the whole issue of dredge by struck measure. | C38: 0 | D38: 0 | E38: 0 | F38: 0 | G38: 0 | H38: 0 | I38: 0 | J38: 0 | K38: 0 | L38: 0 | M38: 0 | N38: 0 | O38: 0 | P38: 0 | Q38: 0 | R38: 0 | S38: 0 | T38: 14.5 | U38: 0 | V38: 14.5 | W38: 0 | X38: 14.5 | Y38: 0 | Z38: 14.5 | AA38: 14.5 | AB38: 0 | AC38: 14.5 | AD38: 0
A39: Dredge | B39: Sown over 18 acres as they lie in Westbune, 2 quarters 5 bushels. | C39: 0 | D39: 0 | E39: 2 | F39: 5 | G39: 2.625 | H39: 0 | I39: 0 | J39: 0 | K39: 0 | L39: 0 | M39: 0 | N39: 0 | O39: 0 | P39: 0 | Q39: 0 | R39: 0 | S39: 0 | T39: 0 | U39: 0 | V39: 0 | W39: 0 | X39: 2 | Y39: 5 | Z39: 2.625 | AA39: 2.625 | AB39: 0 | AC39: 2 | AD39: 5
A40: Dredge | B40: that is, 1 bushels an acre, plus 3 bushels in all. | C40: 0 | D40: 0 | E40: 0 | F40: 0 | G40: 0 | H40: 0 | I40: 0 | J40: 0 | K40: 0 | L40: 0 | M40: 0 | N40: 0 | O40: 0 | P40: 0 | Q40: 0 | R40: 0 | S40: 0 | T40: 0 | U40: 0 | V40: 0 | W40: 0 | X40: 0 | Y40: 3 | Z40: 0.375 | AA40: 0.125 | AB40: 0.25 | AC40: 0 | AD40: 1 | AE40: 0 | AF40: 3
...

Sheet Sale of Corn Prices
A1: Heading | B1: Sentence | C1: Total in Pounds | D1: Pounds | E1: Shillings | F1: Pence | G1: Corn | H1: Total Quarters Except 1 | I1: Total Bushels Except 1 | J1: Total Corn Cross-Check | K1: Total Corn Manorial Account | L1: Corn Quantity Error | M1: Quarters 0 | N1: Bushels 0 | O1: shilling a quarter 1 | P1: pence a quarter 1 | Q1: Quarters 1 | R1: Bushels 1 | S1: shilling a quarter 2 | T1: pence a quarter 2 | U1: Quarters 2 | V1: Bushels 2 | W1: shilling a quarter 3 | X1: pence a quarter 3 | Y1: Quarters 3 | Z1: Bushels 3 | AA1: shilling a quarter 4 | AB1: pence a quarter 4 | AC1: £ a quarter 1 | AD1: £ a quarter 2 | AE1: £ a quarter 3 | AF1: £ a quarter 4 | AG1: Quarters Sold | AH1: Weighted Average Price per Quarter | AI1: Non-Weighted Average Price per Quarter | AJ1: Corn lowercase
A2: Sale of corn | B2: The same render account for £2 12 shilling 6pence from 8 quarters 6 bushels of wheat sold, at 6 shilling a quarters. | C2: 2.62 | D2: 2 | E2: 12 | F2: 6 | G2: wheat | H2: 8 | I2: 6 | J2: 8.75 | K2: 8.75 | L2: 0 | M2: 8 | N2: 6 | O2: 6 | P2: 0 | AC2: 0.3 | AG2: 8.75 | AH2: 0.3 | AI2: 0.3 | AJ2: wheat
A3: Sale of corn | B3: 5 shilling 5pence from 1 quarters 2 bushels of curall sold, at 4 shilling 4pence a quarters. | C3: 0.27 | D3: 0 | E3: 5 | F3: 5 | G3: curall | H3: 1 | I3: 2 | J3: 1.25 | K3: 1.25 | L3: 0 | M3: 1 | N3: 2 | O3: 4 | P3: 4 | AC3: 0.21666667 | AG3: 1.25 | AH3: 0.21666667 | AI3: 0.21666667 | AJ3: curall
A4: Sale of corn | B4: £1 6 shilling 5pence from 11 quarters 3 bushels of dredge sold, at 2 shilling a quarters for 3 quarters 7 bushels, 2 shilling 4pence a quarters for 4 quarters, and 2 shilling 8pence a quarters for 3.5 quarters. | C4: 1.32 | D4: 1 | E4: 6 | F4: 5 | H4: 10.5 | I4: 7 | J4: 11.375 | K4: 11.375 | L4: 0 | M4: 11 | N4: 3 | O4: 2 | P4: 0 | Q4: 3 | R4: 7 | S4: 2 | T4: 4 | U4: 4 | V4: 0 | W4: 2 | X4: 8 | Y4: 3.5 | Z4: 0 | AC4: 0.1 | AD4: 0.11666667 | AE4: 0.13333333 | AG4: 11.375 | AH4: 0.11611722 | AI4: 0.11666667
A5: Sale of corn | B5: 1 shilling from .5 quarters of dredge sold at the audit. | C5: 0.05 | D5: 0 | E5: 1 | F5: 0 | H5: 5 | I5: 0 | J5: 5 | K5: 5 | L5: 0 | M5: 5 | N5: 0 | AC5: 0.01 | AG5: 5 | AH5: 0.01 | AI5: 0.01
A6: Sale of corn | B6: 2 shilling from 4 bushels of peas sold, at 6pence a bushels. | C6: 0.12 | D6: 0 | E6: 2 | F6: 6 | G6: peas | H6: 0 | I6: 4 | J6: 0.5 | K6: 0.5 | L6: 0 | M6: 0 | N6: 4 | AC6: 0.24 | AG6: 0.5 | AH6: 0.24 | AI6: 0.24 | AJ6: peas
A7: Sale of corn | B7: 2 shilling from 6 bushels of peas sold at the audit. | C7: 0.1 | D7: 0 | E7: 2 | F7: 0 | G7: peas | H7: 0 | I7: 6 | J7: 0.75 | K7: 0.75 | L7: 0 | M7: 0 | N7: 6 | AC7: 0.13333333 | AG7: 0.75 | AH7: 0.13333333 | AI7: 0.13333333 | AJ7: peas
A8: Sale of corn | B8: Total, £4 9 shilling 4pence | C8: 4.47 | D8: 4 | E8: 9 | F8: 4 | H8: 0 | I8: 0 | J8: 0 | K8: 0 | L8: 0 | M8: 0 | N8: 0 | AC8: inf | AG8: 0 | AH8: inf | AI8: inf
