Workbook

Sheet Brightwell Overview - Completed
A1: BRIGHTWELL OVERVIEW - COMPLETED | B1: Total in £ | C1: Error | D1: Note
A2: CASH ACCOUNT
A3: RECEIPTS
A4: Arrears total | B4: 25.6
A5: Rents of assize total | B5: 14.45
A6: Quittances total | B6: 3.7129167
A7: Defaults of rent total | B7: 3.7285417
A8: Defaults of rent through the pestilence total
A9: Cotlands defaults total
A10: Cotlands total
A11: Total of quittances and defaults of rent total
A12: Total of rents remaining clear total
A13: Farms total
A14: Annual recognizances total | B14: 0.09
A15: Issues of the Manor total | B15: 6.1333333
A16: Issues of the tenements in the lord's hands total
A17: Sale of labour services total
A18: Sale of corn total | B18: 57.695833
A19: Entry and marriage fines total
A20: Pleas & perquisites total
A21: Forfeited chattels total
A22: Farm of the demesne land total
A23: Total of all receipts (calculated here) | B23: =SUM(B5:B22)
A24: Total of all receipts (calculated here) incl arrears | B24: =SUM(B4:B22)
A25: Total recorded in the accounts excl. arrears | B25: 99.76 | C25: =B23-B25
A26: Total recorded in the accounts incl. arrears | B26: =B25+B4
A29: EXPENSES
A30: Cost of ploughs total | B30: 1.44
A31: Purchase of corn total | B31: 2.6920833
A32: Cost of carts and wagons total
A33: Cost of dairy total
A34: Purchase of stock total | B34: 8.2170833
A35: Sheepcote total
A36: Cost of buildings total
A37: Threshing total | B37: 0.65
A38: Barley expenses
A39: Expenses of the harvest total
A40: Necessary expenses
A41: Wages of the bailiff
A42: Steward's expenses total | B42: 5.8791667
...

Sheet Prices
A1: Meat & Dairy Prices
C2: 1301 | D2: 1302 | E2: Average
A3: Beef | B3: £ per lb | C3: 0.0033351854 | D3: 0.0032608538 | E3: =AVERAGE(C3:D3)
A4: Mutton | B4: £ per lb | C4: 0.0036593977 | D4: 0.0037125513 | E4: =AVERAGE(C4:D4)
A5: Pork | B5: £ per lb | C5: 0.0038431326 | D5: 0.0037574803 | E5: =AVERAGE(C5:D5)
A6: Cheese | B6: £ per lb | C6: 0.0055768754 | D6: 0.0056654898 | E6: =AVERAGE(C6:D6)
A7: Butter | B7: £ per lb | C7: 0.0036626221 | D7: 0.0035935077 | E7: =AVERAGE(C7:D7)
A8: Milk | B8: £ per gallon | C8: 0.0055768754 | D8: 0.0056654898 | E8: =AVERAGE(C8:D8)

Sheet Labour Rents

Sheet Overview
A1: BRIGHTWELL | B1: Total in £ | C1: Error | D1: Note
A2: CASH ACCOUNT
A3: RECEIPTS
A4: Arrears total
A5: Rents of assize total
A6: Quittances total
A7: Defaults of rent total
A8: Defaults of rent through the pestilence total
A9: Cotlands defaults total
A10: Cotlands total
A11: Total of quittances and defaults of rent total
A12: Total of rents remaining clear total
A13: Farms total
... A22: Farm of the demesne land total
A23: Total of all receipts (calculated here) | B23: =Receipts!F176
A24: Total of all receipts (calculated here) incl arrears | B24: =Receipts!F177
A25: Total recorded in the accounts excl. arrears | B25: =Receipts!F175 | C25: =B25-B23
A26: Total recorded in the accounts incl. arrears
A29: EXPENSES
A30: Cost of ploughs total
A31: Purchase of corn total
A32: Cost of carts and wagons total
A33: Cost of dairy total
A34: Purchase of stock total
A35: Sheepcote total
A36: Cost of buildings total
A37: Threshing total
A38: Barley expenses
A39: Expenses of the harvest total
... A43: Annual fees
A44: Total of all expenses per account | B44: =Expenses!F124
A45: Total of all expenses (calculated here) | B45: =Expenses!F125
A46: Total fixed investment | B46: =Expenses!F126
A47: Total Demesne fixed investment | B47: =Expenses!F127
A49: Owed by the reeve
A50: From accounts
A52: Allowances
A53: Cash deliveries
A54: Sum of the above
A55: Total of all allowances and cash deliveries in accounts
...

Sheet Receipts
A1: BRIGHTWELL
A2: Heading | B2: £ | C2: s | D2: d | F2: Total in £ | G2: Error | H2: Notes
A3: Arrears | B3: 25 | C3: 11 | D3: 11 | F3: 25.6 | H3: Roginald de Lynham, bailiff, and Richard E1y3, reeve, render account for £25 11 shilling 11pence of arrears from the last account.
A4: Arrears | B4: 0 | C4: 0 | D4: 0 | F4: 0 | H4: All delivered to Sir Geoffrey, treasurer of Wolvesey, and they are quit.
A5: Arrears | F5: 25.6 | G5: =F5-F3 | H5: Total
A7: Rents | B7: 3 | C7: 0 | D7: 2 | F7: 3.01 | H7: The same render account for £3 2pence for all rents of assize at Christmas.
A8: Rents | B8: 3 | C8: 0 | D8: 2 | F8: 3.01 | H8: £3 2pence at Easter (22 April).
A9: Rents | B9: 3 | C9: 0 | D9: 2 | F9: 3.01 | H9: £3 2pence at the Nativity of the blessed John (24 June).
A10: Rents | B10: 5 | C10: 8 | D10: 4.5 | F10: 5.42 | H10: £5 8 shilling 4.5pence at Michaelmas (29 September).
A11: Rents | B11: 14 | C11: 8 | D11: 10.5 | F11: 14.44 | H11: Total, £14 8 shilling 10.5pence
A12: Rents | F12: 14.45 | G12: 0.01 | H12: Total
A14: Quittances | B14: 0 | C14: 5 | D14: 0 | F14: 0.25 | H14: In quittance of 1 reeve for the year 5 shilling.
A15: Quittances | B15: 0 | C15: 2 | D15: 6 | F15: 0.12 | H15: 1 smith working the iron of 3 ploughs for the year 2 shilling 6pence.
A16: Quittances | B16: 0 | C16: 2 | D16: 0 | F16: 0.1 | H16: 1 overseer of the harvest sowing the land, and keeping the meadow, pasture and corn for the year 2 shilling 24..
A17: Quittances | B17: 0 | C17: 2 | D17: 2 | F17: 0.11 | H17: 1 swineherd for the year 2 shilling 2pence.
A18: Quittances | B18: 0 | C18: 15 | D18: 2 | F18: 0.76 | H18: 7 ploughmen for the year 15 shilling 2pence, or 2 shilling 2pence each.
A19: Quittances | B19: 0 | C19: 15 | D19: 10.5 | F19: 0.79 | H19: 8 virgaters in Brightwell working every other day each week, apart from Saturdays and celebrated feasts, from Michaelmas until the feast of the Apostles Peter and Paul (29 June), that is, for 3 terms, 15 shilling, or 1 shilling 10.5pence each.
A20: Quittances | B20: 0 | C20: 2 | D20: 4 | F20: 0.12 | H20: the same working every day except Saturdays from the said feast of the Apostles Peter and Paul until Michaelmas 2 shilling 4pence, or 3'/ 4. each, and know that there are appointed here 8 half-virgaters where before there were appointed 10, because 2 half-virgates of land were made into 1 whole virgate of land which John Herberd holds by fine made in the steward's court which he answers for from now on and works with the other virgaters of land and is the fifth virgater of land in Brightwell.
A21: Quittances | B21: 0 | C21: 14 | D21: 1 | F21: 0.7 | H21: 13 virgaters of land in Sotwell working every other day each week, except feast-days and Saturdays, for the aforesaid time, 14 shilling 1pence, or 1 shilling Ipence each.
A22: Quittances | B22: 0 | C22: 9 | D22: 4 | F22: 0.47 | H22: 7 virgaters in Mackney working every day apart from Saturdays for the aforesaid time 9 shilling 4pence, or 1 shilling 4pence each.
A23: Quittances | B23: 0 | C23: 5 | D23: 5 | F23: 0.27 | H23: 5 virgaters in Brightwell, to whom the fifth should be added here, working in the same way for the same time 5 shilling 5pence, or 1 shilling1pence each.
A24: Quittances | B24: 0 | C24: 0 | D24: 5.5 | F24: =B24+C24/20+D24/240 | H24: 1 tenant working 2 days a week, that is, Monday and Friday, for the same time, 5.5pence
A25: Quittances | B25: 3 | C25: 13 | D25: 7.5 | F25: 3.68 | H25: Total, £3 13 shilling 7.5pence
A26: Quittances | F26: =SUM(F14:F24) | G26: =F26-F25 | H26: Total
A28: Defaults of rent | B28: 0 | C28: 0 | D28: 3.25 | F28: 0.01 | H28: In default of the land of Andrew de Walingeford' from the old land to the castle ditch 3.25pence
A29: Defaults of rent | D29: 3.75 | F29: =B29+C29/20+D29/240 | H29: Total, 3.75pence
A31: Defaults of rent | B31: 3 | C31: 13 | D31: 11.25 | F31: 3.7 | H31: Total of both, £3 13 shilling 11.25pence
A32: Defaults of rent | F32: =F29+F26 | G32: =F32-F31 | H32: Total
A34: Total of rents remaining | B34: 10 | C34: 14 | D34: 11.25 | F34: 10.75 | H34: Total of rents remaining, £10 14 shilling 11.25pence
A35: Total of rents remaining | F35: 10.75 | G35: =F35-F34 | H35: Total
A37: Annual recognizance | B37: 0 | C37: 0 | D37: 4 | F37: 0.02 | H37: The same render account for 4pence from Thomas Clericus for annual recognizance whilst he wishes to reside within the lord's liberty.
A38: Annual recognizance | B38: 0 | C38: 0 | D38: 6 | F38: 0.03 | H38: 6pence from John Bordel' for the same.
A39: Annual recognizance | B39: 0 | C39: 0 | D39: 10 | F39: 0.04 | H39: nothing from John Longus because he is sold outside the tithing by William de Mackeney his lorpence Total, 10pence
A40: Annual recognizance | F40: 0.09 | G40: 0.05 | H40: Total
A43: Issues of the manor | B43: 0 | C43: 13 | D43: 4 | F43: 0.67 | H43: The same render account for 13 shilling 4pence from the pasturage in the east field sold.
A44: Issues of the manor | B44: 0 | C44: 7 | D44: 1.5 | F44: 0.36 | H44: 7 shilling 1.5pence from pannage of pigs at Martinmas (11 November).
A45: Issues of the manor | B45: 0 | C45: 2 | D45: 0 | F45: 0.1 | H45: 2 shilling from the pasturage in the croft sold, which formerly belonged to William le Fisscher', because it is in the lord's hands through the death of Thomas de Mack' who held that tenement of the lord after the decease of the said William.
A46: Issues of the manor | B46: 0 | C46: 2 | D46: 6.5 | F46: 0.13 | H46: 2 shilling 6.5pence from 29 rowen (relucro) cheeses sold by warrant (per man').
A47: Issues of the manor | B47: 0 | C47: 3 | D47: 5 | F47: 0.17 | H47: 3 shilling .5pence from 36.5 gallons of milk sold for the lambs, at the price made clear.
A48: Issues of the manor | B48: 1 | C48: 18 | D48: 9 | F48: 1.94 | H48: £1 18 shilling 9pence from 117 cheeses, weighing 3.5 weys 41b, sold at 11 shilling a wey.
...

Sheet Expenses
A1: BRIGHTWELL RECEIPTS
A2: Heading | B2: £ | C2: s | D2: d | F2: Total in £ | G2: Error | H2: Notes | J2: Fixed investment | K2: Demesne fixed investment
A3: Cost of ploughs | B3: 0 | C3: 1 | D3: 2 | F3: 0.06 | H3: In 3 pieces of iron bought for the ploughs 1 shilling 2pence. | J3: =F3 | K3: =J3
A4: Cost of ploughs | B4: 0 | C4: 4 | D4: 10 | F4: 0.24 | H4: 6 pieces of steel bought for the same 4 shilling 10pence. | J4: =F4 | K4: =J4
A5: Cost of ploughs | B5: 0 | C5: 1 | D5: 6 | F5: 0.08 | H5: 2 new ploughshares bought for the ploughs with the repair of the same 1 shilling 6pence. | J5: =F5 | K5: =J5
A6: Cost of ploughs | B6: 0 | C6: 1 | D6: 9 | F6: 0.09 | H6: 9 wheels bought for ploughs 1 shilling 9pence. | J6: =F6 | K6: =J6
A7: Cost of ploughs | B7: 0 | C7: 0 | D7: 10.5 | F7: 0.04 | H7: withies bought for the draught-chains (hart') of the ploughs 10.5pence. | J7: =F7 | K7: =J7
A8: Cost of ploughs | B8: 0 | C8: 4 | D8: 0 | F8: 0.2 | H8: stipend of the smith working the iron of 2 ploughs for the year 4 shilling, because 1 acre of wheat was removed from his stipend, and he quits .5 virgate of land through the iron for 2 ploughs. | J8: =F8 | K8: =J8/2
A9: Cost of ploughs | B9: 0 | C9: 0 | D9: 8 | F9: =B9+C9/20+D9/240 | H9: 1 new wheelbarrow bought 8pence | J9: =F9 | K9: =J9
A10: Cost of ploughs | B10: 0 | C10: 14 | D10: 9.5 | F10: =B10+C10/20+D10/240 | H10: Total, 14 shilling 9.5pence
A11: Cost of ploughs | F11: 1.44 | G11: 0.71 | H11: Total
A13: Carts and ironwork | B13: 0 | C13: 1 | D13: 4 | F13: 0.07 | H13: In 2 new horse-collars bought 1 shilling 4pence. | J13: =F13 | K13: =J13
A14: Carts and ironwork | B14: 0 | C14: 1 | D14: 4 | F14: 0.07 | H14: 1 hemp rope bought for tethering the cart at Reading 1 shilling 4pence. | J14: =F14 | K14: =J14
A15: Carts and ironwork | B15: 0 | C15: 0 | D15: 5 | F15: 0.02 | H15: 1 pair of traces bought there 5pence. | J15: =F15 | K15: =J15
A16: Carts and ironwork | B16: 0 | C16: 1 | D16: 8.75 | F16: 0.09 | H16: fitting 1 cart with axles, with axles, white leather, clouts and nails bought for the year, 1 shilling 8.75pence. | J16: =F16 | K16: =J16
A17: Carts and ironwork | B17: 0 | C17: 0 | D17: 2 | F17: 0.01 | H17: frets bought for the cart 2pence. | J17: =F17 | K17: =J17
A18: Carts and ironwork | B18: 0 | C18: 0 | D18: 1 | F18: 0 | H18: 1 metal plate bought for the cart 1pence. | J18: =F18 | K18: =J18
A19: Carts and ironwork | B19: 0 | C19: 0 | D19: 3 | F19: 0.01 | H19: 1 leather halter bought for I cart-horse 3pence. | J19: =F19 | K19: =J19
A20: Carts and ironwork | B20: 0 | C20: 3 | D20: 0 | F20: =B20+C20/20+D20/240 | H20: shoeing 2 cart-horses for the year, for all necessaries which pertain to their provision, together with their removal and fastening, 3 shilling | J20: =F20 | K20: =J20
A21: Carts and ironwork | B21: 0 | C21: 8 | D21: 3.75 | F21: =B21+C21/20+D21/240 | H21: Total, 8 shilling 3.75pence
A22: Carts and ironwork | F22: =SUM(F13:F20) | G22: 0.27 | H22: Total
A24: Small necessaries | B24: 0 | C24: 0 | D24: 0 | F24: 0 | H24: In 12 dishes, 8 pans, 12 saucers. [price ommitted] | J24: =F24 | K24: =J24
A25: Small necessaries | B25: 0 | C25: 1 | D25: 0 | F25: 0.05 | H25: 12 cart-loads of wood felled in the wood of Wargrave 1 shilling. | K25: =J25
A26: Small necessaries | B26: 0 | C26: 0 | D26: 11 | F26: 0.05 | H26: 2.5 bushels of salt bought for the pease pottage of the manorial servants 11pence. | K26: =J26
A27: Small necessaries | B27: 0 | C27: 2 | D27: 6.5 | F27: 0.13 | H27: 4 new sacks bought for corn 2 shilling 6.5pence. | J27: =F27 | K27: =J27
A28: Small necessaries | B28: 0 | C28: 0 | D28: 4 | F28: 0.02 | H28: 1 basket (sporta) bought 4pence. | J28: =F28 | K28: =J28
A29: Small necessaries | B29: 0 | C29: 0 | D29: 7 | F29: 0.03 | H29: castrating 12 male and spaying 9 female piglets 7pence. | K29: =J29
A30: Small necessaries | B30: 0 | C30: 1 | D30: 1.5 | F30: 0.06 | H30: 1.5 bushels of oatmeal bought for pease pottage for the year, 1 shilling 1.5pence this year. | K30: =J30
A31: Small necessaries | B31: 0 | C31: 0 | D31: 2.5 | F31: 0.01 | H31: withies bought for penning oxen in the byre in winter 2.5pence. | J31: =F31 | K31: =J31
A32: Small necessaries | B32: 0 | C32: 0 | D32: 1 | F32: 0 | H32: 1 piece of iron made for a certain shovel out of the demesne iron 1pence. | J32: =F32 | K32: =J32
A33: Small necessaries | B33: 0 | C33: 2 | D33: 6 | F33: 0.12 | H33: hiring a certain man to clean the inside of 2 tuns for putting cider in and moreover hooping them anew and hooping anew 5 tubs by piece-work for 10 days 2 shilling 6pence. | K33: =J33
A34: Small necessaries | B34: 0 | C34: 0 | D34: 7.5 | F34: 0.03 | H34: hiring a certain roofer for 2.5 days to roof over the enclosure between the bishop's chamber and chapel 7.5pence. | K34: =J34
A35: Small necessaries | B35: 0 | C35: 0 | D35: 1 | F35: =B35+C35/20+D35/240 | H35: small nails for fastening laths to the walls of the byre 1pence | J35: =F35 | K35: =J35
A36: Small necessaries | B36: 0 | C36: 11 | D36: 0 | F36: =B36+C36/20+D36/240 | H36: Total, 11 shilling
A37: Small necessaries | F37: =SUM(F24:F35) | G37: =F37-F36 | H37: Total
A39: Threshing and winnowing | B39: 0 | C39: 3 | D39: 2 | F39: 0.16 | H39: In threshing 26 quarters of barley 3 shilling 2pence, at 1.5pence a qr.
A40: Threshing and winnowing | B40: 0 | C40: 0 | D40: 5 | F40: 0.02 | H40: winnowing the said corn 5pence, at 1pence per 5 quarters.
A41: Threshing and winnowing | B41: 0 | C41: 7 | D41: 5.5 | F41: 0.37 | H41: wages of John Touresmere overseeing the threshing and winnowing of corn at various times 7 shilling 5.5pence, taking 1.5pence a day.
A42: Threshing and winnowing | B42: 0 | C42: 2 | D42: 0 | F42: =B42+C42/20+D42/240 | H42: stipend of the same here 2 shilling, because he takes the rest elsewhere up to 10 shilling
A43: Threshing and winnowing | B43: 0 | C43: 13 | D43: 1.5 | F43: =B43+C43/20+D43/240 | H43: Total, 13 shilling 1.5pence
...

Sheet Issues of the Grange
A1: Gross Output | B1: Total Quantity | C1: Account Total Quarters | D1: Bought in Total Quarters | E1: Received from churchscot | F1: Sold Total Quarters | G1: Difference Produced+Bought-Sold | H1: Weighted Average Price per Quarter | I1: Value of Total Production weighted
A2: wheat | B2: 154.4375 | C2: 139.9375 | D2: 7.75 | F2: 105.3125 | G2: =B2-F2 | H2: 0.28333333 | I2: =H2*B2
A3: rye | B3: 73 | C3: 73 | D3: 0 | F3: 29.125 | G3: =B3-F3 | H3: 0.15833333 | I3: =H3*B3
A4: barley | B4: 150.9375 | C4: 0.5 | D4: 0 | F4: 123 | G4: =B4-F4 | H4: 0.16859756 | I4: =H4*B4
A5: dredge | B5: 33.125 | C5: 33.125 | D5: 0 | F5: 16.25 | G5: =B5-F5 | H5: 0.15 | I5: =H5*B5
A6: oats | B6: 19.5 | C6: 8.875 | D6: 10.625 | F6: 5 | G6: =B6-F6 | H6: 0.0066666667 | I6: =H6*B6
A8: Total Production
A9: Sales of corn (as recorded in accounts)
A12: Net output | B12: Gross output | C12: Seed quarters | D12: Seed bushels | E12: Seed total quarters | F12: tithe quarters | G12: tithe bushels | H12: tithe total | I12: manorial servants quarters | J12: manorial servants bushels | K12: manorial servants total quarters | L12: output net of tithe, seed, liveries | M12: in stock from last year | N12: Price in £ | O12: Value of net output in £ | P12: Value of sales (in "Sale of Corn") in £
A13: wheat | B13: =B2 | C13: 38 | D13: 3 | E13: =C13+D13/8 | I13: =1+1+1+0.5+6 | J13: =1+2+1+6 | K13: =I13+J13/8 | L13: =B13-E13-K13 | N13: =H2 | O13: =N13*L13
A14: rye | B14: =B3 | C14: 16 | D14: 3 | E14: =C14+D14/8 | I14: =20+3+3 | J14: =6+6 | K14: =I14+J14/8 | L14: =B14-E14-K14 | N14: =H3 | O14: =N14*L14
A15: barley | B15: =B4 | C15: 31 | E15: =C15+D15/8 | J15: =1 | K15: =I15+J15/8 | L15: =B15-E15-K15 | N15: =H4 | O15: =N15*L15
A16: dredge | B16: =B5 | C16: 15.5 | E16: =C16+D16/8 | I16: 1 | J16: 3 | K16: =I16+J16/8 | L16: =B16-E16-K16 | N16: =H5 | O16: =N16*L16
A17: oats | B17: =B6 | C17: 8 | D17: 1 | E17: =C17+D17/8 | I17: =2+2+7 | J17: =2+1 | K17: =I17+J17/8 | L17: =B17-E17-K17 | N17: =H6 | O17: =N17*L17
A19: Total

Sheet Issues of the Mills

Sheet Stock
A1: BRIGHTWELL STOCK ACCOUNT
C3: added | G3: subtracted
A4: Livestock | B4: Inherited stock | C4: added | D4: strays | E4: herbage | F4: churchscot | G4: of which in default | H4: sold | I4: in murrain | J4: accounted for elsewhere | K4: End-period stock | L4: cross-check | M4: stock building | N4: raw production | O4: Unit price (£) | P4: Value of stock (£) at given value | Q4: Value of stock (£) at sales prices | R4: Sales in (£) | S4: Value of stock building (£) | T4: Value of production (£) at sales prices | U4: Details
A5: Cart-horses | B5: 2 | C5: 1 | K5: 3 | L5: =B5+C5+D5+E5+F5-G5-H5-I5-J5 | M5: =K5-B5
A6: Mares | B6: 1 | C6: 1 | I6: 1 | K6: 1 | L6: =B6+C6+D6+E6+F6-G6-H6-I6-J6 | M6: =K6-B6
A7: Plough horses | B7: 11 | H7: 11 | K7: 0 | L7: =B7+C7+D7+E7+F7-G7-H7-I7-J7 | M7: =K7-B7 | O7: =R7/H7 | R7: =Receipts!F77
A8: Colts (unspecified years) | L8: =B8+C8+D8+E8+F8-G8-H8-I8-J8 | M8: =K8-B8
A9: Colts (2 years) | B9: 1 | J9: 1 | K9: 0 | L9: =B9+C9+D9+E9+F9-G9-H9-I9-J9 | M9: =K9-B9
A10: Colts (1 year) | B10: 3 | K10: 3 | L10: =B10+C10+D10+E10+F10-G10-H10-I10-J10 | M10: =K10-B10
A11: Foals | L11: =B11+C11+D11+E11+F11-G11-H11-I11-J11 | M11: =K11-B11
A12: Oxen | B12: 31 | C12: =2+12 | K12: 45 | L12: =B12+C12+D12+E12+F12-G12-H12-I12-J12 | M12: =K12-B12
A13: Bulls | B13: 1 | H13: 1 | K13: 0 | L13: =B13+C13+D13+E13+F13-G13-H13-I13-J13 | M13: =K13-B13 | O13: =R13/H13 | R13: =Receipts!F60
A14: Cows | B14: 13 | C14: 4 | I14: 1 | K14: 16 | L14: =B14+C14+D14+E14+F14-G14-H14-I14-J14 | M14: =K14-B14
A15: Steers | B15: 6 | J15: 6 | K15: 0 | L15: =B15+C15+D15+E15+F15-G15-H15-I15-J15 | M15: =K15-B15
A16: Bullocks | B16: 6 | K16: 6 | L16: =B16+C16+D16+E16+F16-G16-H16-I16-J16 | M16: =K16-B16
A17: Yearlings | B17: 6 | K17: 6 | L17: =B17+C17+D17+E17+F17-G17-H17-I17-J17 | M17: =K17-B17
A18: Calves | C18: 13 | H18: 5 | J18: 1 | K18: 7 | L18: =B18+C18+D18+E18+F18-G18-H18-I18-J18 | M18: =K18-B18 | O18: =R18/H18 | R18: =Receipts!F57+Receipts!F58+Receipts!F59
A19: Wethers | L19: =B19+C19+D19+E19+F19-G19-H19-I19-J19 | M19: =K19-B19
A20: Rams | L20: =B20+C20+D20+E20+F20-G20-H20-I20-J20 | M20: =K20-B20
A21: Ewes | L21: =B21+C21+D21+E21+F21-G21-H21-I21-J21 | M21: =K21-B21
A22: Hoggs | L22: =B22+C22+D22+E22+F22-G22-H22-I22-J22 | M22: =K22-B22
A23: Lambs | L23: =B23+C23+D23+E23+F23-G23-H23-I23-J23 | M23: =K23-B23
A24: Boars | L24: =B24+C24+D24+E24+F24-G24-H24-I24-J24 | M24: =K24-B24
A25: Sows | B25: 3 | K25: 3 | L25: =B25+C25+D25+E25+F25-G25-H25-I25-J25 | M25: =K25-B25
A26: Pigs | B26: 36 | C26: 33 | H26: 26 | K26: 43 | L26: =B26+C26+D26+E26+F26-G26-H26-I26-J26 | M26: =K26-B26 | O26: =R26/H26 | R26: =Receipts!F91-R27
A27: Hoggets | B27: 34 | H27: 1 | J27: 33 | K27: 0 | L27: =B27+C27+D27+E27+F27-G27-H27-I27-J27 | M27: =K27-B27 | O27: =R27/H27 | R27: =Receipts!F90
A28: Piglets | C28: 43 | J28: =4+1 | K28: 38 | L28: =B28+C28+D28+E28+F28-G28-H28-I28-J28 | M28: =K28-B28
A29: Swans
A30: Peacocks
A31: Total Value | R31: =SUM(R5:R29)
A34: Wool
A35: Coarse wool
A36: Lamb's wool
A37: Wool locks
A38: Wool sold at shearing
A39: Total wool
A42: Hides
A43: Ox hides
A44: Mare | B44: 1 | H44: 1 | O44: =R44/H44 | R44: =Receipts!F53 | T44: =O44*H44
A45: cow | B45: 1 | H45: 1 | O45: =R45/H45 | R45: =Receipts!F54 | T45: =O45*H45
...

Sheet raw data
A1: Heading | B1: Sentence | C1: Total in Pounds | D1: Pounds | E1: Shillings | F1: Pence | G1: Corn | H1: Total Quarters Except 1 | I1: Total Bushels Except 1 | J1: Total Corn Cross-Check | K1: Total Corn Manorial Account | L1: Corn Quantity Error | M1: Quarters 1 | N1: Bushels 1 | O1: Quarters 2 | P1: Bushels 2 | Q1: Quarters 3 | R1: Bushels 3 | S1: Quarters 4 | T1: Bushels 4 | U1: Quarters 5 | V1: Bushels 5 | W1: Quarters 6 | X1: Bushels 6 | Y1: shilling a quarter 1 | Z1: pence a quarter 1 | AA1: shilling a quarter 2 | AB1: pence a quarter 2 | AC1: shilling a quarter 3 | AD1: pence a quarter 3 | AE1: shilling a quarter 4 | AF1: pence a quarter 4 | AG1: shilling a bushel 1 | AH1: pence a bushel 1 | AI1: shilling a bushel 2 | AJ1: pence a bushel 2 | AK1: shilling a bushel 3 | AL1: pence a bushel 3 | AM1: shilling a bushel 4 | AN1: pence a bushel 4
A2: Arrears | B2: Roginald de Lynham, bailiff, and Richard E1y3, reeve, render account for £25 11 shilling 11pence of arrears from the last account. | C2: 25.6 | D2: 25 | E2: 11 | F2: 11 | H2: 0 | I2: 0 | J2: 0 | K2: 0 | L2: 0 | M2: 0 | N2: 0
A3: Arrears | B3: All delivered to Sir Geoffrey, treasurer of Wolvesey, and they are quit. | C3: 0 | D3: 0 | E3: 0 | F3: 0 | H3: 0 | I3: 0 | J3: 0 | K3: 0 | L3: 0 | M3: 0 | N3: 0
A4: Rents | B4: The same render account for £3 2pence for all rents of assize at Christmas. | C4: 3.01 | D4: 3 | E4: 0 | F4: 2 | H4: 0 | I4: 0 | J4: 0 | K4: 0 | L4: 0 | M4: 0 | N4: 0
A5: Rents | B5: £3 2pence at Easter (22 April). | C5: 3.01 | D5: 3 | E5: 0 | F5: 2 | H5: 0 | I5: 0 | J5: 0 | K5: 0 | L5: 0 | M5: 0 | N5: 0
A6: Rents | B6: £3 2pence at the Nativity of the blessed John (24 June). | C6: 3.01 | D6: 3 | E6: 0 | F6: 2 | H6: 0 | I6: 0 | J6: 0 | K6: 0 | L6: 0 | M6: 0 | N6: 0
A7: Rents | B7: £5 8 shilling 4.5pence at Michaelmas (29 September). | C7: 5.42 | D7: 5 | E7: 8 | F7: 4.5 | H7: 0 | I7: 0 | J7: 0 | K7: 0 | L7: 0 | M7: 0 | N7: 0
A8: Rents | B8: Total, £14 8 shilling 10.5pence | C8: 14.44 | D8: 14 | E8: 8 | F8: 10.5 | H8: 0 | I8: 0 | J8: 0 | K8: 0 | L8: 0 | M8: 0 | N8: 0
A9: Quittances | B9: In quittance of 1 reeve for the year 5 shilling. | C9: 0.25 | D9: 0 | E9: 5 | F9: 0 | H9: 0 | I9: 0 | J9: 0 | K9: 0 | L9: 0 | M9: 0 | N9: 0
A10: Quittances | B10: 1 smith working the iron of 3 ploughs for the year 2 shilling 6pence. | C10: 0.12 | D10: 0 | E10: 2 | F10: 6 | H10: 0 | I10: 0 | J10: 0 | K10: 0 | L10: 0 | M10: 0 | N10: 0
A11: Quittances | B11: 1 overseer of the harvest sowing the land, and keeping the meadow, pasture and corn for the year 2 shilling 24.. | C11: 0.1 | D11: 0 | E11: 2 | F11: 0 | H11: 0 | I11: 0 | J11: 0 | K11: 0 | L11: 0 | M11: 0 | N11: 0
A12: Quittances | B12: 1 swineherd for the year 2 shilling 2pence. | C12: 0.11 | D12: 0 | E12: 2 | F12: 2 | H12: 0 | I12: 0 | J12: 0 | K12: 0 | L12: 0 | M12: 0 | N12: 0
A13: Quittances | B13: 7 ploughmen for the year 15 shilling 2pence, or 2 shilling 2pence each. | C13: 0.76 | D13: 0 | E13: 15 | F13: 2 | H13: 0 | I13: 0 | J13: 0 | K13: 0 | L13: 0 | M13: 0 | N13: 0
... A69: Sale of pigs | B69: 5pence from 1 sick hogget sold Total, £4 19 shilling 3pence | C69: 4.96 | D69: 4 | E69: 19 | F69: 3 | H69: 0 | I69: 0 | J69: 0 | K69: 0 | L69: 0 | M69: 0 | N69: 0
A70: Sale of corn | B70: The same render account for £29 16 shilling 9.25pence from 105 quarters 2.5 bushels of wheat sold, at 5 shilling 8pence a quarters, £4 9 shilling 10.25pence from 28 quarters 3 bushels of rye sold, at 3 shilling 2pence a quarters. | C70: 29.84 | D70: 29 | E70: 16 | F70: 9.25 | G70: rye, wheat | H70: 28 | I70: 3 | J70: 28.375 | K70: 105.3125 | L70: -76.9375 | M70: 105 | N70: 2.5 | O70: 28 | P70: 3 | Y70: 5 | Z70: 8 | AA70: 3 | AB70: 2
A71: Sale of corn | B71: £20 16 shilling .75pence from 118 quarters of barley sold, at 3 shilling 6pence a quarters. | C71: 20.8 | D71: 20 | E71: 16 | F71: 0 | G71: barley | H71: 118 | I71: 0 | J71: 118 | K71: 118 | L71: 0 | M71: 118 | N71: 0 | Y71: 3 | Z71: 6
A72: Sale of corn | B72: £2 8 shilling 9pence from 16 quarters 2 bushels of dredge sold, at 3 shilling a quarters, 2 shilling 4.5pence from 6 bushels of rye sold at the audit. | C72: 2.44 | D72: 2 | E72: 8 | F72: 9 | G72: rye | H72: 16 | I72: 6 | J72: 16.75 | K72: 16.25 | L72: 0.5 | M72: 16 | N72: 2 | O72: 0 | P72: 6 | Y72: 3 | Z72: 0
A73: Sale of corn | B73: 1 shilling 9pence from .5 quarters of barley sold at the audit. | C73: 0.09 | D73: 0 | E73: 1 | F73: 9 | G73: barley | H73: 5 | I73: 0 | J73: 5 | K73: 5 | L73: 0 | M73: 5 | N73: 0
A74: Sale of corn | B74: 8pence from .5 quarters of vetches sold at the audit. | C74: 0.03 | D74: 0 | E74: 0 | F74: 8 | G74: vetches | H74: 5 | I74: 0 | J74: 5 | K74: 5 | L74: 0 | M74: 5 | N74: 0
A75: Sale of corn | B75: Total, £57 16 shilling 2.75pence | C75: 57.81 | D75: 57 | E75: 16 | F75: 2.75 | H75: 0 | I75: 0 | J75: 0 | K75: 0 | L75: 0 | M75: 0 | N75: 0
A76: Sale of the mill's corn | B76: The same render account for £2 17 shilling 4pence from 13 quarters .5 bushels of wheat from the mill sold, at 4 shilling a quarters for 4 quarters, 4 shilling 4pence a quarters for 3 quarters, and 4 shilling 8pence a quarters for 6 quarters .5 bushels. | C76: 2.87 | D76: 2 | E76: 17 | F76: 4 | G76: wheat | H76: 13 | I76: 10 | J76: 14.25 | K76: 13 | L76: 1.25 | M76: 13 | N76: 0 | O76: 0 | P76: 5 | Q76: 4 | R76: 0 | S76: 3 | T76: 0 | U76: 6 | V76: 0 | W76: 0 | X76: 5 | Y76: 4 | Z76: 0 | AA76: 4 | AB76: 4 | AC76: 4 | AD76: 8
A77: Sale of the mill's corn | B77: £2 2 shilling 11pence from 17.5 quarters of maslin sold, at 2 shilling a quarters for 5 quarters 5 bushels, and 2 shilling 8pence a quarters for 11 quarters 7 bushels. | C77: 2.15 | D77: 2 | E77: 2 | F77: 11 | G77: maslin | H77: 16 | I77: 12 | J77: 17.5 | K77: 17.5 | L77: 0 | M77: 17.5 | N77: 0 | O77: 5 | P77: 5 | Q77: 11 | R77: 7 | Y77: 2 | Z77: 0 | AA77: 2 | AB77: 8
A78: Sale of the mill's corn | B78: £1 3 shilling 2pence from 5 quarters 2 bushels of coarse-ground corn from the mill sold, at 4 shilling a quarters for 2 quarters, and 4 shilling 8pence a quarters for 3 quarters 2 bushels. | C78: 1.16 | D78: 1 | E78: 3 | F78: 2 | H78: 5 | I78: 2 | J78: 5.25 | K78: 5.25 | L78: 0 | M78: 5 | N78: 2 | O78: 2 | P78: 0 | Q78: 3 | R78: 2 | Y78: 4 | Z78: 0 | AA78: 4 | AB78: 8
A79: Sale of the mill's corn | B79: £3 9 shilling 3pence from 22.5 quarters of second-grade malt sold, at 3 shilling a quarters for 12 quarters, and 3 shilling 2pence a quarters for 10.5 quarters. | C79: 3.46 | D79: 3 | E79: 9 | F79: 3 | G79: second-grade malt | H79: 22.5 | I79: 0 | J79: 22.5 | K79: 22.5 | L79: 0 | M79: 22.5 | N79: 0 | O79: 12 | P79: 0 | Q79: 10.5 | R79: 0 | Y79: 3 | Z79: 0 | AA79: 3 | AB79: 2
A80: Sale of the mill's corn | B80: 5 shilling 4pence from eels sold at various times. | C80: 0.27 | D80: 0 | E80: 5 | F80: 4 | H80: 0 | I80: 0 | J80: 0 | K80: 0 | L80: 0 | M80: 0 | N80: 0
A81: Sale of the mill's corn | B81: Note that there was no more from the issue of the mill this year because for 4 weeks after Christmas and for 2 weeks in Lent it was idle due to torrents. | C81: 0 | D81: 0 | E81: 0 | F81: 0 | H81: 0 | I81: 0 | J81: 0 | K81: 0 | L81: 0 | M81: 0 | N81: 0
A82: Sale of the mill's corn | B82: And for 3pence from 1 bushels of maslin sold at the audit. | C82: 0.01 | D82: 0 | E82: 0 | F82: 3 | G82: maslin | H82: 0 | I82: 1 | J82: 0.125 | K82: 0.125 | L82: 0 | M82: 0 | N82: 1
A83: Sale of the mill's corn | B83: Total, £9 18 shilling 3pence | C83: 9.91 | D83: 9 | E83: 18 | F83: 3 | H83: 0 | I83: 0 | J83: 0 | K83: 0 | L83: 0 | M83: 0 | N83: 0
A84: Fixed payments, entry and marriage fines | B84: The same render account for £1 6 shilling 8pence from fixed payments at the 2 hundred-courts for tithingpenny. | C84: 1.33 | D84: 1 | E84: 6 | F84: 8 | H84: 0 | I84: 0 | J84: 0 | K84: 0 | L84: 0 | M84: 0 | N84: 0
A85: Fixed payments, entry and marriage fines | B85: £2 13 shilling 4pence from the fine of Roger ate Grove to have Agnes, relict of Henry Wys, with .5 virgate of customary land. | C85: 2.67 | D85: 2 | E85: 13 | F85: 4 | H85: 0 | I85: 0 | J85: 0 | K85: 0 | L85: 0 | M85: 0 | N85: 0
A86: Fixed payments, entry and marriage fines | B86: 13 shilling 4pence from the fine of John G 'third to recover a certain cottage which he sold to John Cocus without licence. | C86: 0.67 | D86: 0 | E86: 13 | F86: 4 | H86: 0 | I86: 0 | J86: 0 | K86: 0 | L86: 0 | M86: 0 | N86: 0
A87: Fixed payments, entry and marriage fines | B87: Total, £4 13 shilling 4pence | C87: 4.67 | D87: 4 | E87: 13 | F87: 4 | H87: 0 | I87: 0 | J87: 0 | K87: 0 | L87: 0 | M87: 0 | N87: 0
A88: Perquisites | B88: The same render account for 1 shilling, from Geoffrey de Brighwalton for release from his suit at 2 views. | C88: 0.05 | D88: 0 | E88: 1 | F88: 0 | H88: 0 | I88: 0 | J88: 0 | K88: 0 | L88: 0 | M88: 0 | N88: 0
A89: Perquisites | B89: 1 shilling from Osbert de Nutle fort he same, 6pence from Emma ate Strem’ for trespass of pasture, 6pence from John atte Strem’ for trespass in the curia. | C89: 0.08 | D89: 0 | E89: 1 | F89: 6 | H89: 0 | I89: 0 | J89: 0 | K89: 0 | L89: 0 | M89: 0 | N89: 0
A90: Perquisites | B90: 6pence from John ate Street' William le King3 for trespass with his sheep in the pasture. | C90: 0.03 | D90: 0 | E90: 0 | F90: 6 | H90: 0 | I90: 0 | J90: 0 | K90: 0 | L90: 0 | M90: 0 | N90: 0
A91: Perquisites | B91: 3pence from Juliana de Wodek for the assize of ale. | C91: 0.01 | D91: 0 | E91: 0 | F91: 3 | H91: 0 | I91: 0 | J91: 0 | K91: 0 | L91: 0 | M91: 0 | N91: 0
A92: Perquisites | B92: 3d, from Christina relict of Thomas Amys for the stone. | C92: 0 | D92: 0 | E92: 0 | F92: 0 | H92: 0 | I92: 0 | J92: 0 | K92: 0 | L92: 0 | M92: 0 | N92: 0
A93: Perquisites | B93: 3d, from Alice Poukeput for the same. | C93: 0 | D93: 0 | E93: 0 | F93: 0 | H93: 0 | I93: 0 | J93: 0 | K93: 0 | L93: 0 | M93: 0 | N93: 0
A94: Perquisites | B94: 3pence from Richard the reeve for the same. | C94: 0.01 | D94: 0 | E94: 0 | F94: 3 | H94: 0 | I94: 0 | J94: 0 | K94: 0 | L94: 0 | M94: 0 | N94: 0
... A143: Cost of ploughs | B143: withies bought for the draught-chains (hart') of the ploughs 10.5pence. | C143: 0.04 | D143: 0 | E143: 0 | F143: 10.5 | H143: 0 | I143: 0 | J143: 0 | K143: 0 | L143: 0 | M143: 0 | N143: 0
...

Sheet Issues of the Grange raw
A1: Heading | B1: Sentence | C1: Quarters 1_x | D1: Bushels 1_x | E1: Sown Quarters | F1: Sown Bushels | G1: Sown Total Quarters | H1: Bought in Quarters | I1: Bought in Bushels | J1: Bought in Total Quarters | K1: Tithe Quarters | L1: Tithe Bushels | M1: Tithe Total Quarters | N1: Manorial servants & livestock Quarters | O1: Manorial servants & livestock Bushels | P1: Manorial servants & livestock Total Quarters | Q1: Sold Quarters | R1: Sold Bushels | S1: Sold Total Quarters | T1: Account Quarters | U1: Account Bushels | V1: Account Total Quarters | W1: bought only | X1: Total Quarters Except 1 | Y1: Total Bushels Except 1 | Z1: Total Corn Cross-Check | AA1: Total Corn Manorial Account | AB1: Corn Quantity Error | AC1: Quarters 1_y | AD1: Bushels 1_y | AE1: Quarters 2 | AF1: Bushels 2 | AG1: Quarters 3 | AH1: Bushels 3 | AI1: Quarters 4 | AJ1: Bushels 4 | AK1: Quarters 5 | AL1: Bushels 5 | AM1: Quarters 6 | AN1: Bushels 6
A2: Total of all allowances and cash deliveries | B2: Total | C2: 0 | D2: 0 | E2: 0 | F2: 0 | G2: 0 | H2: 0 | I2: 0 | J2: 0 | K2: 0 | L2: 0 | M2: 0 | N2: 0 | O2: 0 | P2: 0 | Q2: 0 | R2: 0 | S2: 0 | T2: 0 | U2: 0 | V2: 0 | W2: 0
A3: Wheat | B3: (yield: 4.5-fold less 1 qrl 6.5 bushels in all) | C3: 0 | D3: 0 | E3: 0 | F3: 0 | G3: 0 | H3: 0 | I3: 0 | J3: 0 | K3: 0 | L3: 0 | M3: 0 | N3: 0 | O3: 0 | P3: 0 | Q3: 0 | R3: 0 | S3: 0 | T3: 0 | U3: 0 | V3: 0 | W3: 0 | X3: 0 | Y3: 6.5 | Z3: 0.8125 | AA3: 0.8125 | AB3: 0 | AC3: 0 | AD3: 6.5
A4: Wheat | B4: The same render account for 139 quarters 7.5 bushels of wheat from the whole issue of the grange, threshed by labour service by 2 tallies of struck measure. | C4: 0 | D4: 0 | E4: 0 | F4: 0 | G4: 0 | H4: 0 | I4: 0 | J4: 0 | K4: 0 | L4: 0 | M4: 0 | N4: 0 | O4: 0 | P4: 0 | Q4: 0 | R4: 0 | S4: 0 | T4: 139 | U4: 7.5 | V4: 139.9375 | W4: 0 | X4: 139 | Y4: 7.5 | Z4: 139.9375 | AA4: 139.9375 | AB4: 0 | AC4: 139 | AD4: 7.5
A5: Wheat | B5: 6 quarters 6 bushels of wheat by estimation in 5.5 acres given to the manorial servants for their stipends in summer. | C5: 0 | D5: 0 | E5: 0 | F5: 0 | G5: 0 | H5: 0 | I5: 0 | J5: 0 | K5: 0 | L5: 0 | M5: 0 | N5: 0 | O5: 0 | P5: 0 | Q5: 0 | R5: 0 | S5: 0 | T5: 0 | U5: 0 | V5: 0 | W5: 0 | X5: 6 | Y5: 6 | Z5: 6.75 | AA5: 6.75 | AB5: 0 | AC5: 6 | AD5: 6
A6: Wheat | B6: 7 quarters 6 bushels of wheat bought as noted above. | C6: 0 | D6: 0 | E6: 0 | F6: 0 | G6: 0 | H6: 7 | I6: 6 | J6: 7.75 | K6: 0 | L6: 0 | M6: 0 | N6: 0 | O6: 0 | P6: 0 | Q6: 0 | R6: 0 | S6: 0 | T6: 0 | U6: 0 | V6: 0 | W6: 0 | X6: 7 | Y6: 6 | Z6: 7.75 | AA6: 7.75 | AB6: 0 | AC6: 7 | AD6: 6
A7: Wheat | B7: Total, 154 quarters 3.5 bus, clerk. | C7: 0 | D7: 0 | E7: 0 | F7: 0 | G7: 0 | H7: 0 | I7: 0 | J7: 0 | K7: 0 | L7: 0 | M7: 0 | N7: 0 | O7: 0 | P7: 0 | Q7: 0 | R7: 0 | S7: 0 | T7: 0 | U7: 0 | V7: 0 | W7: 0
A8: Wheat | B8: Sown over 103 acres of land as they lie as they lie in the field, 38 quarters 3 bushels by 1. | C8: 0 | D8: 0 | E8: 38 | F8: 3 | G8: 38.375 | H8: 0 | I8: 0 | J8: 0 | K8: 0 | L8: 0 | M8: 0 | N8: 0 | O8: 0 | P8: 0 | Q8: 0 | R8: 0 | S8: 0 | T8: 0 | U8: 0 | V8: 0 | W8: 0 | X8: 38 | Y8: 3 | Z8: 38.375 | AA8: 38.375 | AB8: 0 | AC8: 38 | AD8: 3
A9: Wheat | B9: that is 3 bushels an acre, less 2 bushels in all. | C9: 0 | D9: 0 | E9: 0 | F9: 0 | G9: 0 | H9: 0 | I9: 0 | J9: 0 | K9: 0 | L9: 0 | M9: 0 | N9: 0 | O9: 0 | P9: 0 | Q9: 0 | R9: 0 | S9: 0 | T9: 0 | U9: 0 | V9: 0 | W9: 0 | X9: 0 | Y9: 2 | Z9: 0.25 | AA9: 0.375 | AB9: -0.125 | AC9: 0 | AD9: 3 | AE9: 0 | AF9: 2
A10: Wheat | B10: . | C10: 0 | D10: 0 | E10: 0 | F10: 0 | G10: 0 | H10: 0 | I10: 0 | J10: 0 | K10: 0 | L10: 0 | M10: 0 | N10: 0 | O10: 0 | P10: 0 | Q10: 0 | R10: 0 | S10: 0 | T10: 0 | U10: 0 | V10: 0 | W10: 0 | X10: 0 | Y10: 0 | Z10: 0 | AA10: 0 | AB10: 0 | AC10: 0 | AD10: 0
A11: Wheat | B11: . | C11: 0 | D11: 0 | E11: 0 | F11: 0 | G11: 0 | H11: 0 | I11: 0 | J11: 0 | K11: 0 | L11: 0 | M11: 0 | N11: 0 | O11: 0 | P11: 0 | Q11: 0 | R11: 0 | S11: 0 | T11: 0 | U11: 0 | V11: 0 | W11: 0 | X11: 0 | Y11: 0 | Z11: 0 | AA11: 0 | AB11: 0 | AC11: 0 | AD11: 0
A12: Wheat | B12: . | C12: 0 | D12: 0 | E12: 0 | F12: 0 | G12: 0 | H12: 0 | I12: 0 | J12: 0 | K12: 0 | L12: 0 | M12: 0 | N12: 0 | O12: 0 | P12: 0 | Q12: 0 | R12: 0 | S12: 0 | T12: 0 | U12: 0 | V12: 0 | W12: 0 | X12: 0 | Y12: 0 | Z12: 0 | AA12: 0 | AB12: 0 | AC12: 0 | AD12: 0
A13: Wheat | B13: . | C13: 0 | D13: 0 | E13: 0 | F13: 0 | G13: 0 | H13: 0 | I13: 0 | J13: 0 | K13: 0 | L13: 0 | M13: 0 | N13: 0 | O13: 0 | P13: 0 | Q13: 0 | R13: 0 | S13: 0 | T13: 0 | U13: 0 | V13: 0 | W13: 0 | X13: 0 | Y13: 0 | Z13: 0 | AA13: 0 | AB13: 0 | AC13: 0 | AD13: 0
A14: Wheat | B14: provision of Sir Robert, steward, and Simon, clerk for their visits, that is, in bread baked for their use, 1 qr 1 bushels by 3 tallies with their expenses. | C14: 0 | D14: 0 | E14: 0 | F14: 0 | G14: 0 | H14: 0 | I14: 0 | J14: 0 | K14: 0 | L14: 0 | M14: 0 | N14: 0 | O14: 0 | P14: 0 | Q14: 0 | R14: 0 | S14: 0 | T14: 0 | U14: 0 | V14: 0 | W14: 0
A15: Wheat | B15: . | C15: 0 | D15: 0 | E15: 0 | F15: 0 | G15: 0 | H15: 0 | I15: 0 | J15: 0 | K15: 0 | L15: 0 | M15: 0 | N15: 0 | O15: 0 | P15: 0 | Q15: 0 | R15: 0 | S15: 0 | T15: 0 | U15: 0 | V15: 0 | W15: 0 | X15: 0 | Y15: 0 | Z15: 0 | AA15: 0 | AB15: 0 | AC15: 0 | AD15: 0
A16: Wheat | B16: . | C16: 0 | D16: 0 | E16: 0 | F16: 0 | G16: 0 | H16: 0 | I16: 0 | J16: 0 | K16: 0 | L16: 0 | M16: 0 | N16: 0 | O16: 0 | P16: 0 | Q16: 0 | R16: 0 | S16: 0 | T16: 0 | U16: 0 | V16: 0 | W16: 0 | X16: 0 | Y16: 0 | Z16: 0 | AA16: 0 | AB16: 0 | AC16: 0 | AD16: 0
A17: Wheat | B17: . | C17: 0 | D17: 0 | E17: 0 | F17: 0 | G17: 0 | H17: 0 | I17: 0 | J17: 0 | K17: 0 | L17: 0 | M17: 0 | N17: 0 | O17: 0 | P17: 0 | Q17: 0 | R17: 0 | S17: 0 | T17: 0 | U17: 0 | V17: 0 | W17: 0 | X17: 0 | Y17: 0 | Z17: 0 | AA17: 0 | AB17: 0 | AC17: 0 | AD17: 0
A18: Wheat | B18: . | C18: 0 | D18: 0 | E18: 0 | F18: 0 | G18: 0 | H18: 0 | I18: 0 | J18: 0 | K18: 0 | L18: 0 | M18: 0 | N18: 0 | O18: 0 | P18: 0 | Q18: 0 | R18: 0 | S18: 0 | T18: 0 | U18: 0 | V18: 0 | W18: 0 | X18: 0 | Y18: 0 | Z18: 0 | AA18: 0 | AB18: 0 | AC18: 0 | AD18: 0
A19: Wheat | B19: provision of Walter de Polton after Michaelmas, 1 qr, that is, in bread by 1 tally with his expenses. | C19: 0 | D19: 0 | E19: 0 | F19: 0 | G19: 0 | H19: 0 | I19: 0 | J19: 0 | K19: 0 | L19: 0 | M19: 0 | N19: 0 | O19: 0 | P19: 0 | Q19: 0 | R19: 0 | S19: 0 | T19: 0 | U19: 0 | V19: 0 | W19: 0
A20: Wheat | B20: Given to the steward and constable of Wallingford Castle, 1 qr. | C20: 0 | D20: 0 | E20: 0 | F20: 0 | G20: 0 | H20: 0 | I20: 0 | J20: 0 | K20: 0 | L20: 0 | M20: 0 | N20: 0 | O20: 0 | P20: 0 | Q20: 0 | R20: 0 | S20: 0 | T20: 0 | U20: 0 | V20: 0 | W20: 0
A21: Wheat | B21: . | C21: 0 | D21: 0 | E21: 0 | F21: 0 | G21: 0 | H21: 0 | I21: 0 | J21: 0 | K21: 0 | L21: 0 | M21: 0 | N21: 0 | O21: 0 | P21: 0 | Q21: 0 | R21: 0 | S21: 0 | T21: 0 | U21: 0 | V21: 0 | W21: 0 | X21: 0 | Y21: 0 | Z21: 0 | AA21: 0 | AB21: 0 | AC21: 0 | AD21: 0
A22: Wheat | B22: . | C22: 0 | D22: 0 | E22: 0 | F22: 0 | G22: 0 | H22: 0 | I22: 0 | J22: 0 | K22: 0 | L22: 0 | M22: 0 | N22: 0 | O22: 0 | P22: 0 | Q22: 0 | R22: 0 | S22: 0 | T22: 0 | U22: 0 | V22: 0 | W22: 0 | X22: 0 | Y22: 0 | Z22: 0 | AA22: 0 | AB22: 0 | AC22: 0 | AD22: 0
A23: Wheat | B23: . | C23: 0 | D23: 0 | E23: 0 | F23: 0 | G23: 0 | H23: 0 | I23: 0 | J23: 0 | K23: 0 | L23: 0 | M23: 0 | N23: 0 | O23: 0 | P23: 0 | Q23: 0 | R23: 0 | S23: 0 | T23: 0 | U23: 0 | V23: 0 | W23: 0 | X23: 0 | Y23: 0 | Z23: 0 | AA23: 0 | AB23: 0 | AC23: 0 | AD23: 0
A24: Wheat | B24: . | C24: 0 | D24: 0 | E24: 0 | F24: 0 | G24: 0 | H24: 0 | I24: 0 | J24: 0 | K24: 0 | L24: 0 | M24: 0 | N24: 0 | O24: 0 | P24: 0 | Q24: 0 | R24: 0 | S24: 0 | T24: 0 | U24: 0 | V24: 0 | W24: 0 | X24: 0 | Y24: 0 | Z24: 0 | AA24: 0 | AB24: 0 | AC24: 0 | AD24: 0
A25: Wheat | B25: agreement with Jordan (Joriad') le Carpenter for making the bridge of the mill, 0.5 qr. | C25: 0 | D25: 0 | E25: 0 | F25: 0 | G25: 0 | H25: 0 | I25: 0 | J25: 0 | K25: 0 | L25: 0 | M25: 0 | N25: 0 | O25: 0 | P25: 0 | Q25: 0 | R25: 0 | S25: 0 | T25: 0 | U25: 0 | V25: 0 | W25: 0
A26: Wheat | B26: Given to Sibyl de Morton', 2 bushels. | C26: 0 | D26: 0 | E26: 0 | F26: 0 | G26: 0 | H26: 0 | I26: 0 | J26: 0 | K26: 0 | L26: 0 | M26: 0 | N26: 0 | O26: 0 | P26: 0 | Q26: 0 | R26: 0 | S26: 0 | T26: 0 | U26: 0 | V26: 0 | W26: 0 | X26: 0 | Y26: 2 | Z26: 0.25 | AA26: 0.25 | AB26: 0 | AC26: 0 | AD26: 2
A27: Wheat | B27: customary payment to the overseer of the harvest for his fee, 1 bushels, because it is found to be the custom. | C27: 0 | D27: 0 | E27: 0 | F27: 0 | G27: 0 | H27: 0 | I27: 0 | J27: 0 | K27: 0 | L27: 0 | M27: 0 | N27: 0 | O27: 0 | P27: 0 | Q27: 0 | R27: 0 | S27: 0 | T27: 0 | U27: 0 | V27: 0 | W27: 0 | X27: 0 | Y27: 1 | Z27: 0.125 | AA27: 0.125 | AB27: 0 | AC27: 0 | AD27: 1
A28: Wheat | B28: . | C28: 0 | D28: 0 | E28: 0 | F28: 0 | G28: 0 | H28: 0 | I28: 0 | J28: 0 | K28: 0 | L28: 0 | M28: 0 | N28: 0 | O28: 0 | P28: 0 | Q28: 0 | R28: 0 | S28: 0 | T28: 0 | U28: 0 | V28: 0 | W28: 0 | X28: 0 | Y28: 0 | Z28: 0 | AA28: 0 | AB28: 0 | AC28: 0 | AD28: 0
A29: Wheat | B29: . | C29: 0 | D29: 0 | E29: 0 | F29: 0 | G29: 0 | H29: 0 | I29: 0 | J29: 0 | K29: 0 | L29: 0 | M29: 0 | N29: 0 | O29: 0 | P29: 0 | Q29: 0 | R29: 0 | S29: 0 | T29: 0 | U29: 0 | V29: 0 | W29: 0 | X29: 0 | Y29: 0 | Z29: 0 | AA29: 0 | AB29: 0 | AC29: 0 | AD29: 0
A30: Wheat | B30: . | C30: 0 | D30: 0 | E30: 0 | F30: 0 | G30: 0 | H30: 0 | I30: 0 | J30: 0 | K30: 0 | L30: 0 | M30: 0 | N30: 0 | O30: 0 | P30: 0 | Q30: 0 | R30: 0 | S30: 0 | T30: 0 | U30: 0 | V30: 0 | W30: 0 | X30: 0 | Y30: 0 | Z30: 0 | AA30: 0 | AB30: 0 | AC30: 0 | AD30: 0
A31: Wheat | B31: . | C31: 0 | D31: 0 | E31: 0 | F31: 0 | G31: 0 | H31: 0 | I31: 0 | J31: 0 | K31: 0 | L31: 0 | M31: 0 | N31: 0 | O31: 0 | P31: 0 | Q31: 0 | R31: 0 | S31: 0 | T31: 0 | U31: 0 | V31: 0 | W31: 0 | X31: 0 | Y31: 0 | Z31: 0 | AA31: 0 | AB31: 0 | AC31: 0 | AD31: 0
A32: Wheat | B32: stipend of 1 reeve, 1 overseer of the harvest, 1 carter and 3 ploughmen for their stipends in summer, 6 quarters 6 bushels, that is, in 5.5 acres of wheat delivered to them. | C32: 0 | D32: 0 | E32: 0 | F32: 0 | G32: 0 | H32: 0 | I32: 0 | J32: 0 | K32: 0 | L32: 0 | M32: 0 | N32: 0 | O32: 0 | P32: 0 | Q32: 0 | R32: 0 | S32: 0 | T32: 0 | U32: 0 | V32: 0 | W32: 0 | X32: 6 | Y32: 6 | Z32: 6.75 | AA32: 6.75 | AB32: 0 | AC32: 6 | AD32: 6
A33: Wheat | B33: Sold, 105 quarters 2.5 bushels Total, 154 quarters 3.5 bushels None remains. | C33: 0 | D33: 0 | E33: 0 | F33: 0 | G33: 0 | H33: 0 | I33: 0 | J33: 0 | K33: 0 | L33: 0 | M33: 0 | N33: 0 | O33: 0 | P33: 0 | Q33: 259 | R33: 6 | S33: 259.75 | T33: 0 | U33: 0 | V33: 0 | W33: 0 | X33: 154 | Y33: 3.5 | Z33: 154.4375 | AA33: 105.3125 | AB33: 49.125 | AC33: 105 | AD33: 2.5 | AE33: 154 | AF33: 3.5
A34: Wheat | B34: Total | C34: 0 | D34: 0 | E34: 0 | F34: 0 | G34: 0 | H34: 0 | I34: 0 | J34: 0 | K34: 0 | L34: 0 | M34: 0 | N34: 0 | O34: 0 | P34: 0 | Q34: 0 | R34: 0 | S34: 0 | T34: 0 | U34: 0 | V34: 0 | W34: 0
A35: Rye | B35: {yield: 3.5-fold plus 4 quarters 6 bushels) | C35: 0 | D35: 0 | E35: 0 | F35: 0 | G35: 0 | H35: 0 | I35: 0 | J35: 0 | K35: 0 | L35: 0 | M35: 0 | N35: 0 | O35: 0 | P35: 0 | Q35: 0 | R35: 0 | S35: 0 | T35: 0 | U35: 0 | V35: 0 | W35: 0 | X35: 4 | Y35: 6 | Z35: 4.75 | AA35: 4.75 | AB35: 0 | AC35: 4 | AD35: 6
A36: Rye | B36: The same render account for 73 quarters from the issue of the grange, threshed by labour service by 2 tallies of struck measure. | C36: 0 | D36: 0 | E36: 0 | F36: 0 | G36: 0 | H36: 0 | I36: 0 | J36: 0 | K36: 0 | L36: 0 | M36: 0 | N36: 0 | O36: 0 | P36: 0 | Q36: 0 | R36: 0 | S36: 0 | T36: 73 | U36: 0 | V36: 73 | W36: 0 | X36: 73 | Y36: 0 | Z36: 73 | AA36: 73 | AB36: 0 | AC36: 73 | AD36: 0
A37: Rye | B37: Total, 73 quarters. | C37: 0 | D37: 0 | E37: 0 | F37: 0 | G37: 0 | H37: 0 | I37: 0 | J37: 0 | K37: 0 | L37: 0 | M37: 0 | N37: 0 | O37: 0 | P37: 0 | Q37: 0 | R37: 0 | S37: 0 | T37: 0 | U37: 0 | V37: 0 | W37: 0 | X37: 73 | Y37: 0 | Z37: 73 | AA37: 73 | AB37: 0 | AC37: 73 | AD37: 0
A38: Rye | B38: Sown over 52 acres of land as they lie in the field, 16 quarters 3 bushels by 1 tally. | C38: 0 | D38: 0 | E38: 16 | F38: 3 | G38: 16.375 | H38: 0 | I38: 0 | J38: 0 | K38: 0 | L38: 0 | M38: 0 | N38: 0 | O38: 0 | P38: 0 | Q38: 0 | R38: 0 | S38: 0 | T38: 0 | U38: 0 | V38: 0 | W38: 0 | X38: 16 | Y38: 3 | Z38: 16.375 | AA38: 16.375 | AB38: 0 | AC38: 16 | AD38: 3
A39: Rye | B39: that is, 2.5 bushels an acre, plus 1 bushels in all. | C39: 0 | D39: 0 | E39: 0 | F39: 0 | G39: 0 | H39: 0 | I39: 0 | J39: 0 | K39: 0 | L39: 0 | M39: 0 | N39: 0 | O39: 0 | P39: 0 | Q39: 0 | R39: 0 | S39: 0 | T39: 0 | U39: 0 | V39: 0 | W39: 0 | X39: 0 | Y39: 1 | Z39: 0.125 | AA39: 0.3125 | AB39: -0.1875 | AC39: 0 | AD39: 2.5 | AE39: 0 | AF39: 1
A40: Rye | B40: Delivered to 1 carter and 3 ploughmen for the year, 20 quarters 6 bushels, or 5 quarters 1.5 bushels each, taking a quarter every 10 weeks. | C40: 0 | D40: 0 | E40: 0 | F40: 0 | G40: 0 | H40: 0 | I40: 0 | J40: 0 | K40: 0 | L40: 0 | M40: 0 | N40: 0 | O40: 0 | P40: 0 | Q40: 0 | R40: 0 | S40: 0 | T40: 0 | U40: 0 | V40: 0 | W40: 0 | X40: 5 | Y40: 1.5 | Z40: 5.1875 | AA40: 20.75 | AB40: -15.5625 | AC40: 20 | AD40: 6 | AE40: 5 | AF40: 1.5
...

Sheet Sale of Corn Prices
A1: Heading | B1: Sentence | C1: Total in Pounds | D1: Pounds | E1: Shillings | F1: Pence | G1: Corn | H1: Total Quarters Except 1 | I1: Total Bushels Except 1 | J1: Total Corn Cross-Check | K1: Total Corn Manorial Account | L1: Corn Quantity Error | M1: Quarters 0 | N1: Bushels 0 | O1: shilling a quarter 1 | P1: pence a quarter 1 | Q1: Quarters 1 | R1: Bushels 1 | S1: shilling a quarter 2 | T1: pence a quarter 2 | U1: Quarters 2 | V1: Bushels 2 | W1: shilling a quarter 3 | X1: pence a quarter 3 | Y1: Quarters 3 | Z1: Bushels 3 | AA1: shilling a quarter 4 | AB1: pence a quarter 4 | AC1: Quarters 4 | AD1: Bushels 4 | AE1: Quarters 5 | AF1: Bushels 5 | AG1: £ a quarter 1 | AH1: £ a quarter 2 | AI1: £ a quarter 3 | AJ1: £ a quarter 4 | AK1: Quarters Sold | AL1: Weighted Average Price per Quarter | AM1: Non-Weighted Average Price per Quarter | AN1: Corn lowercase
A2: Sale of corn | B2: The same render account for £29 16 shilling 9.25pence from 105 quarters 2.5 bushels of wheat sold, at 5 shilling 8pence a quarters, £4 9 shilling 10.25pence from 28 quarters 3 bushels of rye sold, at 3 shilling 2pence a quarters. | C2: 29.84 | D2: 29 | E2: 16 | F2: 9.25 | G2: rye, wheat | H2: 28 | I2: 3 | J2: 28.375 | K2: 105.3125 | L2: -76.9375 | M2: 105 | N2: 2.5 | O2: 5 | P2: 8 | Q2: 28 | R2: 3 | S2: 3 | T2: 2 | AG2: 0.28333333 | AH2: 0.15833333 | AK2: 105.3125 | AM2: 0.22083333 | AN2: rye, wheat
A3: Sale of corn | B3: £20 16 shilling .75pence from 118 quarters of barley sold, at 3 shilling 6pence a quarters. | C3: 20.8 | D3: 20 | E3: 16 | F3: 0 | G3: barley | H3: 118 | I3: 0 | J3: 118 | K3: 118 | L3: 0 | M3: 118 | N3: 0 | O3: 3 | P3: 6 | AG3: 0.175 | AK3: 118 | AL3: 0.175 | AM3: 0.175 | AN3: barley
A4: Sale of corn | B4: £2 8 shilling 9pence from 16 quarters 2 bushels of dredge sold, at 3 shilling a quarters, 2 shilling 4.5pence from 6 bushels of rye sold at the audit. | C4: 2.44 | D4: 2 | E4: 8 | F4: 9 | G4: rye | H4: 16 | I4: 6 | J4: 16.75 | K4: 16.25 | L4: 0.5 | M4: 16 | N4: 2 | O4: 3 | P4: 0 | Q4: 0 | R4: 6 | AG4: 0.15 | AK4: 16.25 | AL4: 0.15 | AM4: 0.15 | AN4: rye
A5: Sale of corn | B5: 1 shilling 9pence from .5 quarters of barley sold at the audit. | C5: 0.09 | D5: 0 | E5: 1 | F5: 9 | G5: barley | H5: 5 | I5: 0 | J5: 5 | K5: 5 | L5: 0 | M5: 5 | N5: 0 | AG5: 0.018 | AK5: 5 | AL5: 0.018 | AM5: 0.018 | AN5: barley
A6: Sale of corn | B6: 8pence from .5 quarters of vetches sold at the audit. | C6: 0.03 | D6: 0 | E6: 0 | F6: 8 | G6: vetches | H6: 5 | I6: 0 | J6: 5 | K6: 5 | L6: 0 | M6: 5 | N6: 0 | AG6: 0.006 | AK6: 5 | AL6: 0.006 | AM6: 0.006 | AN6: vetches
A7: Sale of corn | B7: Total, £57 16 shilling 2.75pence | C7: 57.81 | D7: 57 | E7: 16 | F7: 2.75 | H7: 0 | I7: 0 | J7: 0 | K7: 0 | L7: 0 | M7: 0 | N7: 0 | AG7: inf | AK7: 0 | AL7: inf | AM7: inf
