Workbook

Sheet Cams Overview - Completed
A1: CAMS OVERVIEW - COMPLETED | B1: Total in £ | C1: Error | D1: Note
A2: CASH ACCOUNT
A3: RECEIPTS
A4: Arrears total | B4: 0.68
A5: Rents of assize total | B5: 3.5147917
A6: Quittances total
A7: Defaults of rent total
A8: Defaults of rent through the pestilence total
A9: Cotlands defaults total
A10: Cotlands total
A11: Total of quittances and defaults of rent total
A12: Total of rents remaining clear total
A13: Farms total
A14: Annual recognizances total
A15: Issues of the Manor total | B15: 6.6610417
A16: Issues of the tenements in the lord's hands total
A17: Sale of labour services total
A18: Sale of corn total | B18: 24.71
A19: Entry and marriage fines total
A20: Pleas & perquisites total
A21: Forfeited chattels total
A22: Farm of the demesne land total
A23: Total of all receipts (calculated here) | B23: =SUM(B5:B22)
A24: Total of all receipts (calculated here) incl arrears | B24: =SUM(B4:B22)
A25: Total recorded in the accounts excl. arrears | B25: 35.85 | C25: =B23-B25
A26: Total recorded in the accounts incl. arrears | B26: =B25+B4
A29: EXPENSES
A30: Cost of ploughs total | B30: 2.645
A31: Purchase of corn total
A32: Cost of carts and wagons total
A33: Cost of dairy total
A34: Purchase of stock total
A35: Sheepcote total
A36: Cost of buildings total
A37: Threshing total | B37: 1.755625
A38: Barley expenses
A39: Expenses of the harvest total
A40: Necessary expenses
A41: Wages of the bailiff
A42: Steward's expenses total
...

Sheet Prices
A1: Meat & Dairy Prices
C2: 1301 | D2: 1302 | E2: Average
A3: Beef | B3: £ per lb | C3: 0.0033351854 | D3: 0.0032608538 | E3: =AVERAGE(C3:D3)
A4: Mutton | B4: £ per lb | C4: 0.0036593977 | D4: 0.0037125513 | E4: =AVERAGE(C4:D4)
A5: Pork | B5: £ per lb | C5: 0.0038431326 | D5: 0.0037574803 | E5: =AVERAGE(C5:D5)
A6: Cheese | B6: £ per lb | C6: 0.0055768754 | D6: 0.0056654898 | E6: =AVERAGE(C6:D6)
A7: Butter | B7: £ per lb | C7: 0.0036626221 | D7: 0.0035935077 | E7: =AVERAGE(C7:D7)
A8: Milk | B8: £ per gallon | C8: 0.0055768754 | D8: 0.0056654898 | E8: =AVERAGE(C8:D8)

Sheet Labour Rents

Sheet Overview
A1: CAMS | B1: Total in £ | C1: Error | D1: Note
A2: CASH ACCOUNT
A3: RECEIPTS
A4: Arrears total
A5: Rents of assize total
A6: Quittances total
A7: Defaults of rent total
A8: Defaults of rent through the pestilence total
A9: Cotlands defaults total
A10: Cotlands total
A11: Total of quittances and defaults of rent total
A12: Total of rents remaining clear total
A13: Farms total
... A22: Farm of the demesne land total
A23: Total of all receipts (calculated here) | B23: =Receipts!F63
A24: Total of all receipts (calculated here) incl arrears | B24: =Receipts!F64
A25: Total recorded in the accounts excl. arrears | B25: =Receipts!F62
A26: Total recorded in the accounts incl. arrears
A29: EXPENSES
A30: Cost of ploughs total
A31: Purchase of corn total
A32: Cost of carts and wagons total
A33: Cost of dairy total
A34: Purchase of stock total
A35: Sheepcote total
A36: Cost of buildings total
A37: Threshing total
A38: Barley expenses
A39: Expenses of the harvest total
... A43: Annual fees
A44: Total of all expenses per account | B44: =Expenses!F100
A45: Total of all expenses (calculated here) | B45: =Expenses!F101
A46: Total fixed investment | B46: =Expenses!F102
A47: Total Demesne fixed investment | B47: =Expenses!F103
A49: Owed by the reeve
A50: From accounts
A52: Allowances
A53: Cash deliveries
A54: Sum of the above
A55: Total of all allowances and cash deliveries in accounts
...

Sheet Receipts
A1: CAM RECEIPTS
A2: Heading | B2: £ | C2: s | D2: d | F2: Total in £ | G2: Error | H2: Sentence
A3: Arrears | B3: 0 | C3: 13 | D3: 7 | F3: 0.68 | H3: Robert de' renders account for 13 shilling 7pence of arrears from the previous year.
A4: Arrears | B4: 0 | C4: 0 | D4: 0 | F4: 0 | H4: All delivered to Sir Geoffrey, treasurer of Wolvesey.
A5: Arrears | B5: 0 | C5: 0 | D5: 0 | F5: 0 | H5: He is quit.
A6: Arrears | F6: 0.68 | G6: =F6-F3 | H6: Total
A8: Rents of assize | B8: 0 | C8: 8 | D8: 1 | F8: 0.4 | H8: The same renders account for 8 shilling 1pence for rents of assize at Christmas.
A9: Rents of assize | B9: 1 | C9: 6 | D9: 3.75 | F9: 1.32 | H9: £1 6 shilling 3.75pence at Easter (22 April).
A10: Rents of assize | B10: 0 | C10: 8 | D10: 1 | F10: 0.4 | H10: 8 shilling 1pence at St John the Baptist (24 June).
A11: Rents of assize | B11: 1 | C11: 7 | D11: 10.75 | F11: =B11+C11/20+D11/240 | H11: £1 7 shilling 10.75 pence at Michaelmas (29 September).
A12: Rents of assize | B12: 3 | C12: 10 | D12: 4.5 | F12: 3.52 | H12: Total, £3 10 shilling 4.5pence
A13: Rents of assize | F13: =SUM(F8:F11) | G13: =F13-F12 | H13: Total
A15: Increment | B15: 0 | C15: 0 | D15: 1 | F15: 0 | H15: The same renders account for 1pence for the increment of rent of Thomas Godwyn' to have the moiety of 1 day-work beside his house.
A16: Increment | B16: 0 | C16: 0 | D16: 1 | F16: 0 | H16: Total, 1pence
A17: Increment | F17: 0 | G17: 0 | H17: Total
A19: Total of rents with increment | B19: 3 | C19: 10 | D19: 4.5 | F19: 3.52 | H19: Total of rents with increment, £3 10 shilling 4.5pence3
A20: Total of rents with increment | F20: 3.52 | G20: =F20-F19 | H20: Total
A22: Issues of the manor | B22: 0 | C22: 1 | D22: 2 | F22: 0.06 | H22: The same renders account for 1 shilling 2pence from pannage of pigs.
A23: Issues of the manor | B23: 0 | C23: 8 | D23: 0 | F23: 0.4 | H23: 8 shilling from 1 cart-horse sold.
A24: Issues of the manor | B24: 0 | C24: 12 | D24: 0 | F24: 0.6 | H24: 12 shilling from 2 feeble plough-horses sold.
A25: Issues of the manor | B25: 0 | C25: 16 | D25: 4 | F25: 0.82 | H25: 16 shilling 4pence from 14 wethers sold at Martinmas (11 November), at 1 shilling 2pence each.
A26: Issues of the manor | B26: 0 | C26: 6 | D26: 8 | F26: 0.33 | H26: 6 shilling 8pence from 8 ewes sold at the same feast, at 10pence each.
A27: Issues of the manor | B27: 1 | C27: 0 | D27: 0 | F27: 1 | H27: £1 from 8 pigs sold at the feast of St Andrew (30 November), at 2 shilling 6pence each.
A28: Issues of the manor | B28: 0 | C28: 12 | D28: 0 | F28: =B28+C28/20+D28/240 | H28: 12 shilling from 8 pigs sold at the same feast, at 1 shilling 6pence each.
A29: Issues of the manor | B29: 0 | C29: 6 | D29: 0 | F29: 0.3 | H29: 6 shilling from 6 piglets sold, at 1 shilling each.
A30: Issues of the manor | B30: 0 | C30: 0 | D30: 0 | F30: 0 | H30: nothing from coarse wool and lamb's-wool here because it is sent to Wolvesey.
A31: Issues of the manor | B31: 0 | C31: 8 | D31: 10 | F31: 0.44 | H31: 8 shilling 10pence from 1 wey and 1 clove of summer cheese sold.
A32: Issues of the manor | B32: 0 | C32: 0 | D32: 10 | F32: 0.04 | H32: 10pence from the skins sold of 4 ewes in murrain before shearing, at 2.5pence a skin.
A33: Issues of the manor | B33: 0 | C33: 0 | D33: 1.5 | F33: 0.01 | H33: 1.5pence from the skin sold of 1 ewe in murrain after shearing.
A34: Issues of the manor | B34: 0 | C34: 0 | D34: 3 | F34: 0.01 | H34: 3pence from the skins sold of 4 lambs in murrain before weaning.
A35: Issues of the manor | B35: 0 | C35: 0 | D35: 0.25 | F35: =B35+C35/20+D35/240 | H35: .25pence from the skin sold of 1 lamb in murrain after shearing.
A36: Issues of the manor | B36: 0 | C36: 2 | D36: 0 | F36: 0.1 | H36: 2 shilling from the pasturage sold at Alnet'.
A37: Issues of the manor | B37: 0 | C37: 2 | D37: 6 | F37: 0.12 | H37: 2 shilling 6pence from the pasturage sold at Ostrewod'.
A38: Issues of the manor | B38: 0 | C38: 0 | D38: 6 | F38: 0.03 | H38: 6pence from the pasturage sold in 2 crofts beside the garden.
A39: Issues of the manor | B39: 0 | C39: 2 | D39: 0 | F39: 0.1 | H39: 2 shilling from stubble sold.
A40: Issues of the manor | B40: 0 | C40: 2 | D40: 6 | F40: 0.12 | H40: 2 shilling 6pence from 30 men for I harvest boon-work.
A41: Issues of the manor | B41: 0 | C41: 14 | D41: 0 | F41: 0.7 | H41: 14 shilling from 7 pigs sold after the harvest.
A42: Issues of the manor | B42: 0 | C42: 10 | D42: 3 | F42: 0.51 | H42: 10 shilling from 8 piglets sold after the harvest, at 1 shilling 3pence each.
A43: Issues of the manor | B43: 0 | C43: 6 | D43: 8 | F43: 0.33 | H43: 6 shilling 8pence from 8 piglets sold after the harvest, at 10pence each.
A44: Issues of the manor | B44: 0 | C44: 0 | D44: 9.5 | F44: 0.04 | H44: 9.5pence from 2 cloves 5 lb of butter sold, at 3.5pence a clove.
...

Sheet Expenses
A1: CAMS EXPENSES
A2: Heading | B2: £ | C2: s | D2: d | F2: Total in £ | G2: Error | H2: Notes | J2: Fixed investment | K2: Demesne fixed investment
A3: Cost of ploughs | B3: 0 | C3: 6 | D3: 8 | F3: 0.33 | H3: In iron and steel bought for the ironwork of 2 ploughs for the year 6 shilling 8pence, with the stipend of the smith. | J3: =F3 | K3: =J3
A4: Cost of ploughs | B4: 0 | C4: 0 | D4: 9 | F4: 0.04 | H4: 1 ploughshare bought 9pence. | J4: =F4 | K4: =J4
A5: Cost of ploughs | B5: 0 | C5: 1 | D5: 0 | F5: 0.05 | H5: 2 plough feet bought 1 shilling. | J5: =F5 | K5: =J5
A6: Cost of ploughs | B6: 0 | C6: 0 | D6: 10 | F6: 0.04 | H6: 1 new plough made with the other ploughs mended 10pence. | J6: =F6 | K6: =J6
A7: Cost of ploughs | B7: 0 | C7: 0 | D7: 8 | F7: 0.03 | H7: 2 pairs of wheels bought 8pence. | J7: =F7 | K7: =J7
A8: Cost of ploughs | B8: 0 | C8: 0 | D8: 1.5 | F8: 0.01 | H8: fitting 1 plough with iron tyres 1.5pence. | J8: =F8 | K8: =J8
A9: Cost of ploughs | B9: 0 | C9: 1 | D9: 0 | F9: 0.05 | H9: shoeing 2 plough-horses for 1 term 1 shilling. | J9: =F9 | K9: =J9
A10: Cost of ploughs | B10: 0 | C10: 2 | D10: 0 | F10: 0.1 | H10: boon-works of 8 ploughmen in winter and 4 in Lent 2 shilling.
A11: Cost of ploughs | B11: 0 | C11: 3 | D11: 0 | F11: 0.15 | H11: hiring 1 man to plough from Easter until Michaelmas, working for 72 days when they ploughed, 3 shilling, at 0.5pence a day. | K11: =J11
A12: Cost of ploughs | B12: 0 | C12: 1 | D12: 0 | F12: 0.05 | H12: 2 sacks bought 1 shilling. | J12: =F12 | K12: =J12
A13: Cost of ploughs | B13: 0 | C13: 14 | D13: 7 | F13: 0.73 | H13: forage bought 14 shilling 7pence.
A14: Cost of ploughs | B14: 0 | C14: 8 | D14: 0 | F14: 0.4 | H14: stipend of 2 ploughmen for the year 8 shilling.
A15: Cost of ploughs | B15: 0 | C15: 1 | D15: 6 | F15: 0.08 | H15: stipend of 1 ploughman from Michaelmas until Easter 1 shilling 6pence, because thereafter a third ploughman was hired by the day and a fourth ploughman held a plough for his lanpence.
A16: Cost of ploughs | B16: 0 | C16: 11 | D16: 3 | F16: 0.56 | H16: 2 quarters 2 bushels of wheat bought for sowing 11 shilling 3pence, at 5 shilling a qr.
A17: Cost of ploughs | B17: 0 | C17: 0 | D17: 6 | F17: =B17+C17/20+D17/240 | H17: shoeing oxen 6pence | J17: =F17 | K17: =J17
A18: Cost of ploughs | B18: 2 | C18: 11 | D18: 10.5 | F18: 2.59 | H18: Total, £2 11 shilling 10.5pence
A19: Cost of ploughs | F19: =SUM(F3:F17) | G19: =F19-F18 | H19: Total
A21: Cost of carts | B21: 0 | C21: 0 | D21: 10 | F21: 0.04 | H21: In 1 cart mended with large nails bought for the same 10pence. | J21: =F21 | K21: =F21
A22: Cost of carts | B22: 0 | C22: 0 | D22: 5 | F22: 0.02 | H22: fitting the cart with axles with axles bought for the same 5pence. | J22: =F22 | K22: =F22
A23: Cost of carts | B23: 0 | C23: 0 | D23: 11 | F23: 0.05 | H23: clouts, nails and grease bought 11pence. | J23: =F23 | K23: =F23
A24: Cost of carts | B24: 0 | C24: 0 | D24: 3.5 | F24: 0.01 | H24: 1 pair of traces bought 3.5pence. | J24: =F24 | K24: =F24
A25: Cost of carts | B25: 0 | C25: 1 | D25: 1 | F25: 0.05 | H25: 1 collar and 1 pair of saddle-pads bought 1 shilling 1pence. | J25: =F25 | K25: =F25
A26: Cost of carts | B26: 0 | C26: 4 | D26: 6 | F26: 0.23 | H26: shoeing 3 cart-horses for the year 4 shilling 6pence. | J26: =F26 | K26: =F26
A27: Cost of carts | B27: 0 | C27: 0 | D27: 4 | F27: 0.02 | H27: 3 halters bought 4pence. | J27: =F27 | K27: =F27
A28: Cost of carts | B28: 0 | C28: 5 | D28: 0 | F28: 0.25 | H28: stipend of 1 carter for the year 5 shilling.
A29: Cost of carts | B29: 0 | C29: 6 | D29: 8 | F29: 0.33 | H29: stipend of 1 hayward from the Purification (2 February) until Michaelmas (29 September), 6 shilling 8pence this year.
A30: Cost of carts | B30: 0 | C30: 1 | D30: 10 | F30: 0.09 | H30: hay bought 1 shilling 10pence.
A31: Cost of carts | B31: 0 | C31: 0 | D31: 3.5 | F31: 0.01 | H31: white leather bought for harnesses 3.5pence. | J31: =F31 | K31: =J31
A32: Cost of carts | B32: 0 | C32: 0 | D32: 2.5 | F32: =B32+C32/20+D32/240 | H32: a crupper and girths bought 2.5pence | J32: =F32 | K32: =J32
A33: Cost of carts | B33: 1 | C33: 2 | D33: 4.5 | F33: 1.12 | H33: Total, £1 2 shilling 4.5pence
A34: Cost of carts | F34: =SUM(F21:F32) | G34: =F34-F33 | H34: Total
A36: Cost of the dairy | B36: 0 | C36: 0 | D36: 10.5 | F36: 0.04 | H36: In 3.5 bushels of salt bought 10.5pence. | J36: =F36 | K36: =J36
A37: Cost of the dairy | B37: 0 | C37: 0 | D37: 1 | F37: 0 | H37: a press bought 1pence. | J37: =F37 | K37: =J37
A38: Cost of the dairy | B38: 0 | C38: 0 | D38: 6 | F38: 0.03 | H38: 12 hurdles made from their own withies 6pence. | J38: =F38 | K38: =J38
A39: Cost of the dairy | B39: 0 | C39: 0 | D39: 2 | F39: 0.01 | H39: stubble collected for wattling the fold 2pence. | J39: =F39 | K39: =J39
A40: Cost of the dairy | B40: 0 | C40: 2 | D40: 6 | F40: 0.12 | H40: grease bought for greasing sheep 2 shilling 6pence. | J40: =F40 | K40: =J40
A41: Cost of the dairy | B41: 0 | C41: 2 | D41: 8 | F41: 0.13 | H41: meal bought for the pottage of the manorial servants 2 shilling 8pence. | J41: =F41 | K41: =J41
A42: Cost of the dairy | B42: 0 | C42: 0 | D42: 3 | F42: 0.01 | H42: earthenware pots bought 3pence. | J42: =F42 | K42: =J42
...

Sheet Issues of the Grange
A1: Gross Output | B1: Total Quantity | C1: Account Total Quarters | D1: Bought in Total Quarters | E1: Received from churchscot | F1: Sold Total Quarters | G1: Difference Produced+Bought-Sold | H1: Weighted Average Price per Quarter | I1: Value of Total Production weighted
A2: wheat | B2: 93.6875 | D2: 2.25 | F2: 58.125 | G2: =B2-F2 | H2: 0.28916033 | I2: =H2*B2
A3: curall | B3: 10.625 | D3: 0 | F3: 10.625 | G3: =B3-F3 | H3: 0.089215686 | I3: =H3*B3
A4: barley | B4: 39.625 | D4: 0 | F4: 8.8125 | G4: =B4-F4 | H4: 0.2 | I4: =H4*B4
A5: dredge | B5: 8.1875 | D5: 0 | F5: 4.9375 | G5: =B5-F5 | H5: 0.15 | I5: =H5*B5
A6: oats | B6: 93.875 | D6: 0 | F6: 30.75 | G6: =B6-F6 | H6: 0.11300813 | I6: =H6*B6
A7: peas | B7: 14.4375 | D7: 0 | F7: 7.625 | G7: =B7-F7 | H7: 0.10766962 | I7: =H7*B7
A8: vetches | B8: 19.25 | D8: 0 | F8: 3.75 | G8: =B8-F8 | H8: 0.1 | I8: =H8*B8
A13: Net output | B13: Gross output | C13: Seed quarters | D13: Seed bushels | E13: Seed total quarters | F13: tithe quarters | G13: tithe bushels | H13: tithe total | I13: manorial servants quarters | J13: manorial servants bushels | K13: manorial servants total quarters | L13: output net of tithe, seed, liveries | M13: in stock from last year | N13: Price in £ | O13: Value of net output in £ | P13: Value of sales (in "Sale of Corn") in £
A14: wheat | B14: =B2 | C14: 33 | D14: 2 | E14: =C14+D14/8 | I14: =1.5+1 | K14: =I14+J14/8 | L14: =B14-E14-H14-K14 | N14: =H2 | O14: =N14*L14
A15: curall | B15: =B3 | E15: =C15+D15/8 | K15: =I15+J15/8 | L15: =B15-E15-H15-K15 | N15: =H3 | O15: =N15*L15
A16: barley | B16: =B4 | C16: 9.5 | D16: 3 | E16: =C16+D16/8 | I16: =1.5+5+8+2.5+4+3 | J16: =3+1.5+5+2.5+2+3 | K16: =I16+J16/8 | L16: =B16-E16-H16-K16 | N16: =H4 | O16: =N16*L16
A17: dredge | B17: =B5 | C17: 3 | D17: 2 | E17: =C17+D17/8 | K17: =I17+J17/8 | L17: =B17-E17-H17-K17 | N17: =H5 | O17: =N17*L17
A18: oats | B18: =B6 | C18: 40 | D18: 7 | E18: =C18+D18/8 | I18: =11.5+10.5 | J18: 2 | K18: =I18+J18/8 | L18: =B18-E18-H18-K18 | N18: =H6 | O18: =N18*L18
A19: peas | B19: =B7 | C19: 7 | D19: 3 | E19: =C19+D19/8 | K19: =I19+J19/8 | L19: =B19-E19-H19-K19 | N19: =H7 | O19: =N19*L19
A20: vetches | B20: =B8 | C20: 9.5 | E20: =C20+D20/8 | I20: 6 | K20: =I20+J20/8 | L20: =B20-E20-H20-K20 | N20: =H8 | O20: =N20*L20

Sheet Issues of the Mills

Sheet Stock
A1: CAMS STOCK ACCOUNT
C3: added | G3: subtracted
A4: Livestock | B4: Inherited stock | C4: added | D4: strays | E4: herbage | F4: churchscot | G4: of which in default | H4: sold | I4: in murrain | J4: accounted for elsewhere | K4: End-period stock | L4: cross-check | M4: stock building | N4: raw production | O4: Unit price (£) | P4: Value of stock (£) at given value | Q4: Value of stock (£) at sales prices | R4: Sales in (£) | S4: Value of stock building (£) | T4: Value of production (£) at sales prices | U4: Details
A5: Cart-horses | B5: 4 | H5: 1 | K5: 3 | R5: =Receipts!F23
A6: Mares | B6: 2 | H6: 2 | R6: =Receipts!F24
A7: Plough horses
A8: Colts (unspecified years)
A9: Colts (2 years)
A10: Colts (1 year)
A11: Foals
A12: Oxen | B12: 20 | K12: 20
A13: Bulls
A14: Cows
A15: Steers
A16: Bullocks
A17: Yearlings
A18: Calves
A19: Wethers | B19: 86 | C19: 33 | H19: 14 | K19: 105 | R19: =Receipts!F25
A20: Rams | B20: 71 | C20: =25+1 | H20: 8 | I20: =4+1 | K20: 84 | R20: =Receipts!F26
A21: Ewes
A22: Hoggs | B22: 58 | J22: =33+25 | K22: 0
A23: Lambs | B23: 58 | I23: =4+1 | J23: 5 | K23: 48
A24: Boars
A25: Sows
A26: Pigs | B26: =8 | H26: 8 | K26: 0 | R26: =Receipts!F28
A27: Young pigs | B27: 8 | H27: 8
A28: Hoggets
A29: Piglets | B29: 6 | H29: 6 | R29: =Receipts!F29
A30: Swans
A31: Peacocks
A32: Total Value | R32: =SUM(R5:R31)
A35: Wool
A36: Coarse wool | C36: 190 | J36: =19+171 | O36: 0.02 | T36: =O36*J36
A37: Lamb's wool | C37: 49 | O37: 0.01 | T37: =O37*C37
A38: Wool locks
A39: Wool sold at shearing
A40: Total wool | T40: =SUM(T36:T39)
A43: Hides
A44: Ox hides
A45: Mare
...

Sheet Issues of the Grange raw
A1: Heading | B1: Sentence | C1: Quarters 1_x | D1: Bushels 1_x | E1: Sown Quarters | F1: Sown Bushels | G1: Sown Total Quarters | H1: Bought in Quarters | I1: Bought in Bushels | J1: Bought in Total Quarters | K1: Tithe Quarters | L1: Tithe Bushels | M1: Tithe Total Quarters | N1: Manorial servants & livestock Quarters | O1: Manorial servants & livestock Bushels | P1: Manorial servants & livestock Total Quarters | Q1: Sold Quarters | R1: Sold Bushels | S1: Sold Total Quarters | T1: Account Quarters | U1: Account Bushels | V1: Account Total Quarters | W1: bought only | X1: Total Quarters Except 1 | Y1: Total Bushels Except 1 | Z1: Total Corn Cross-Check | AA1: Total Corn Manorial Account | AB1: Corn Quantity Error | AC1: Quarters 1_y | AD1: Bushels 1_y | AE1: Quarters 2 | AF1: Bushels 2 | AG1: Quarters 3 | AH1: Bushels 3 | AI1: Quarters 4 | AJ1: Bushels 4 | AK1: Quarters 5 | AL1: Bushels 5 | AM1: Quarters 6 | AN1: Bushels 6
A2: And thus he owes clear | B2: Total | C2: 0 | D2: 0 | E2: 0 | F2: 0 | G2: 0 | H2: 0 | I2: 0 | J2: 0 | K2: 0 | L2: 0 | M2: 0 | N2: 0 | O2: 0 | P2: 0 | Q2: 0 | R2: 0 | S2: 0 | T2: 0 | U2: 0 | V2: 0 | W2: 0
A3: Wheat | B3: (yield: three-fold plus 6 quarters' bushels}The same renders account for 91 quarters 3.5 bushels from the whole issue of wheat by struck measure. | C3: 0 | D3: 0 | E3: 0 | F3: 0 | G3: 0 | H3: 0 | I3: 0 | J3: 0 | K3: 0 | L3: 0 | M3: 0 | N3: 0 | O3: 0 | P3: 0 | Q3: 0 | R3: 0 | S3: 0 | T3: 97 | U3: 3.5 | V3: 97.4375 | W3: 0 | X3: 91 | Y3: 3.5 | Z3: 91.4375 | AA3: 6 | AB3: 85.4375 | AC3: 6 | AD3: 0 | AE3: 91 | AF3: 3.5
A4: Wheat | B4: 2 quarters 2 bushels bought. | C4: 0 | D4: 0 | E4: 0 | F4: 0 | G4: 0 | H4: 2 | I4: 2 | J4: 2.25 | K4: 0 | L4: 0 | M4: 0 | N4: 0 | O4: 0 | P4: 0 | Q4: 0 | R4: 0 | S4: 0 | T4: 0 | U4: 0 | V4: 0 | W4: 0 | X4: 2 | Y4: 2 | Z4: 2.25 | AA4: 2.25 | AB4: 0 | AC4: 2 | AD4: 2
A5: Wheat | B5: Total, 93.5 quarters 1.5 bushels | C5: 0 | D5: 0 | E5: 0 | F5: 0 | G5: 0 | H5: 0 | I5: 0 | J5: 0 | K5: 0 | L5: 0 | M5: 0 | N5: 0 | O5: 0 | P5: 0 | Q5: 0 | R5: 0 | S5: 0 | T5: 0 | U5: 0 | V5: 0 | W5: 0 | X5: 93.5 | Y5: 1.5 | Z5: 93.6875 | AA5: 93.6875 | AB5: 0 | AC5: 93.5 | AD5: 1.5
A6: Wheat | B6: Sown over 89 acres measured by the perch which lie at Alnetum, Vinecrofte, in burgages, in crofts outside the gate, in Estfeld' in various places, and on Brondes-bury, 33 quarters 2 bushels. | C6: 0 | D6: 0 | E6: 33 | F6: 2 | G6: 33.25 | H6: 0 | I6: 0 | J6: 0 | K6: 0 | L6: 0 | M6: 0 | N6: 0 | O6: 0 | P6: 0 | Q6: 0 | R6: 0 | S6: 0 | T6: 0 | U6: 0 | V6: 0 | W6: 0 | X6: 33 | Y6: 2 | Z6: 33.25 | AA6: 33.25 | AB6: 0 | AC6: 33 | AD6: 2
A7: Wheat | B7: that is, 3 bushels an acre, less 1 bushels in all. | C7: 0 | D7: 0 | E7: 0 | F7: 0 | G7: 0 | H7: 0 | I7: 0 | J7: 0 | K7: 0 | L7: 0 | M7: 0 | N7: 0 | O7: 0 | P7: 0 | Q7: 0 | R7: 0 | S7: 0 | T7: 0 | U7: 0 | V7: 0 | W7: 0 | X7: 0 | Y7: 1 | Z7: 0.125 | AA7: 0.375 | AB7: -0.25 | AC7: 0 | AD7: 3 | AE7: 0 | AF7: 1
A8: Wheat | B8: Delivered to 1 hayward from the Purification (2 Febraury) until Lammas (1 August) and from the decollation of St John the Baptist (29 August) until Michaelmas (29 September), for 30 weeks, 1.5 quarters 3 bushels, because in between times he was at table for 4 weeks, and because he took the rest in barley, taking a quarter every 8 weeks. | C8: 0 | D8: 0 | E8: 0 | F8: 0 | G8: 0 | H8: 0 | I8: 0 | J8: 0 | K8: 0 | L8: 0 | M8: 0 | N8: 0 | O8: 0 | P8: 0 | Q8: 0 | R8: 0 | S8: 0 | T8: 0 | U8: 0 | V8: 0 | W8: 0 | X8: 1.5 | Y8: 3 | Z8: 1.875 | AA8: 1.875 | AB8: 0 | AC8: 1.5 | AD8: 3
A9: Wheat | B9: Consumed by the household at harvest-time, 1 qr. | C9: 0 | D9: 0 | E9: 0 | F9: 0 | G9: 0 | H9: 0 | I9: 0 | J9: 0 | K9: 0 | L9: 0 | M9: 0 | N9: 0 | O9: 0 | P9: 0 | Q9: 0 | R9: 0 | S9: 0 | T9: 0 | U9: 0 | V9: 0 | W9: 0
A10: Wheat | B10: Sold, 57.5 quarters 0.5 bushels | C10: 0 | D10: 0 | E10: 0 | F10: 0 | G10: 0 | H10: 0 | I10: 0 | J10: 0 | K10: 0 | L10: 0 | M10: 0 | N10: 0 | O10: 0 | P10: 0 | Q10: 57.5 | R10: 0.5 | S10: 57.5625 | T10: 0 | U10: 0 | V10: 0 | W10: 0 | X10: 57.5 | Y10: 0.5 | Z10: 57.5625 | AA10: 57.5625 | AB10: 0 | AC10: 57.5 | AD10: 0.5
A11: Wheat | B11: Total | C11: 0 | D11: 0 | E11: 0 | F11: 0 | G11: 0 | H11: 0 | I11: 0 | J11: 0 | K11: 0 | L11: 0 | M11: 0 | N11: 0 | O11: 0 | P11: 0 | Q11: 0 | R11: 0 | S11: 0 | T11: 0 | U11: 0 | V11: 0 | W11: 0
A12: Curall | B12: The same renders account for 10 quarters 5 bushels from the whole issue of curall by struck measure. | C12: 0 | D12: 0 | E12: 0 | F12: 0 | G12: 0 | H12: 0 | I12: 0 | J12: 0 | K12: 0 | L12: 0 | M12: 0 | N12: 0 | O12: 0 | P12: 0 | Q12: 0 | R12: 0 | S12: 0 | T12: 10 | U12: 5 | V12: 10.625 | W12: 0 | X12: 10 | Y12: 5 | Z12: 10.625 | AA12: 10.625 | AB12: 0 | AC12: 10 | AD12: 5
A13: Curall | B13: Sold, 10 quarters 5 bushels | C13: 0 | D13: 0 | E13: 0 | F13: 0 | G13: 0 | H13: 0 | I13: 0 | J13: 0 | K13: 0 | L13: 0 | M13: 0 | N13: 0 | O13: 0 | P13: 0 | Q13: 10 | R13: 5 | S13: 10.625 | T13: 0 | U13: 0 | V13: 0 | W13: 0 | X13: 10 | Y13: 5 | Z13: 10.625 | AA13: 10.625 | AB13: 0 | AC13: 10 | AD13: 5
A14: Curall | B14: Total | C14: 0 | D14: 0 | E14: 0 | F14: 0 | G14: 0 | H14: 0 | I14: 0 | J14: 0 | K14: 0 | L14: 0 | M14: 0 | N14: 0 | O14: 0 | P14: 0 | Q14: 0 | R14: 0 | S14: 0 | T14: 0 | U14: 0 | V14: 0 | W14: 0
A15: Barley | B15: {yield: two-and-a-half-fold less 3 quarters 3 bushels} | C15: 0 | D15: 0 | E15: 0 | F15: 0 | G15: 0 | H15: 0 | I15: 0 | J15: 0 | K15: 0 | L15: 0 | M15: 0 | N15: 0 | O15: 0 | P15: 0 | Q15: 0 | R15: 0 | S15: 0 | T15: 0 | U15: 0 | V15: 0 | W15: 0 | X15: 3 | Y15: 3 | Z15: 3.375 | AA15: 3.375 | AB15: 0 | AC15: 3 | AD15: 3
A16: Barley | B16: The same renders account for 38.5 quarters 2.5 bushels of barley by struck measure. | C16: 0 | D16: 0 | E16: 0 | F16: 0 | G16: 0 | H16: 0 | I16: 0 | J16: 0 | K16: 0 | L16: 0 | M16: 0 | N16: 0 | O16: 0 | P16: 0 | Q16: 0 | R16: 0 | S16: 0 | T16: 38.5 | U16: 2.5 | V16: 38.8125 | W16: 0 | X16: 38.5 | Y16: 2.5 | Z16: 38.8125 | AA16: 38.8125 | AB16: 0 | AC16: 38.5 | AD16: 2.5
A17: Barley | B17: 6 quarters received from vetches. | C17: 0 | D17: 0 | E17: 0 | F17: 0 | G17: 0 | H17: 0 | I17: 0 | J17: 0 | K17: 0 | L17: 0 | M17: 0 | N17: 0 | O17: 0 | P17: 0 | Q17: 0 | R17: 0 | S17: 0 | T17: 0 | U17: 0 | V17: 0 | W17: 0 | X17: 6 | Y17: 0 | Z17: 6 | AA17: 6 | AB17: 0 | AC17: 6 | AD17: 0
A18: Barley | B18: Total, 44 quarters 6.5 bushels | C18: 0 | D18: 0 | E18: 0 | F18: 0 | G18: 0 | H18: 0 | I18: 0 | J18: 0 | K18: 0 | L18: 0 | M18: 0 | N18: 0 | O18: 0 | P18: 0 | Q18: 0 | R18: 0 | S18: 0 | T18: 0 | U18: 0 | V18: 0 | W18: 0 | X18: 44 | Y18: 6.5 | Z18: 44.8125 | AA18: 44.8125 | AB18: 0 | AC18: 44 | AD18: 6.5
A19: Barley | B19: Sown over 16 acres measured by the perch as they lie in Estfeld' in various places, 9.5 quarters 3 bushels. | C19: 0 | D19: 0 | E19: 9.5 | F19: 3 | G19: 9.875 | H19: 0 | I19: 0 | J19: 0 | K19: 0 | L19: 0 | M19: 0 | N19: 0 | O19: 0 | P19: 0 | Q19: 0 | R19: 0 | S19: 0 | T19: 0 | U19: 0 | V19: 0 | W19: 0 | X19: 9.5 | Y19: 3 | Z19: 9.875 | AA19: 9.875 | AB19: 0 | AC19: 9.5 | AD19: 3
A20: Barley | B20: that is, 5 bushels an acre, less 1 bushels in all. | C20: 0 | D20: 0 | E20: 0 | F20: 0 | G20: 0 | H20: 0 | I20: 0 | J20: 0 | K20: 0 | L20: 0 | M20: 0 | N20: 0 | O20: 0 | P20: 0 | Q20: 0 | R20: 0 | S20: 0 | T20: 0 | U20: 0 | V20: 0 | W20: 0 | X20: 0 | Y20: 1 | Z20: 0.125 | AA20: 0.625 | AB20: -0.5 | AC20: 0 | AD20: 5 | AE20: 0 | AF20: 1
A21: Barley | B21: Delivered to 1 hayward from the Purification until Lammas and from the decollation of St John until Michaelmas, for 30 weeks, 1.5 quarters 3 bushels, because in between times he was at table for 4 weeks, taking a quarter every 8 weeks and taking the rest in wheat. {Henceforth the harrower should not have so great a livery because he is overseer of the harvest and carter there} Delivered to 1 carter for the year, 5 quarters 1.5 bushels, and taking a quarter every 10 weeks. | C21: 0 | D21: 0 | E21: 0 | F21: 0 | G21: 0 | H21: 0 | I21: 0 | J21: 0 | K21: 0 | L21: 0 | M21: 0 | N21: 0 | O21: 0 | P21: 0 | Q21: 0 | R21: 0 | S21: 0 | T21: 0 | U21: 0 | V21: 0 | W21: 0 | X21: 5 | Y21: 1.5 | Z21: 5.1875 | AA21: 1.875 | AB21: 3.3125 | AC21: 1.5 | AD21: 3 | AE21: 5 | AF21: 1.5
A22: Barley | B22: Delivered to 2 drovers for the year, 8 quarters 5 bushels, and taking a quarter every 12 weeks. | C22: 0 | D22: 0 | E22: 0 | F22: 0 | G22: 0 | H22: 0 | I22: 0 | J22: 0 | K22: 0 | L22: 0 | M22: 0 | N22: 0 | O22: 0 | P22: 0 | Q22: 0 | R22: 0 | S22: 0 | T22: 0 | U22: 0 | V22: 0 | W22: 0 | X22: 8 | Y22: 5 | Z22: 8.625 | AA22: 8.625 | AB22: 0 | AC22: 8 | AD22: 5
A23: Barley | B23: Delivered to 1 ploughman from Michaelmas until Easter, for 30 weeks, 2.5 quarters, and taking a quarter every 12 weeks. | C23: 0 | D23: 0 | E23: 0 | F23: 0 | G23: 0 | H23: 0 | I23: 0 | J23: 0 | K23: 0 | L23: 0 | M23: 0 | N23: 0 | O23: 0 | P23: 0 | Q23: 0 | R23: 0 | S23: 0 | T23: 0 | U23: 0 | V23: 0 | W23: 0 | X23: 2.5 | Y23: 0 | Z23: 2.5 | AA23: 2.5 | AB23: 0 | AC23: 2.5 | AD23: 0
A24: Barley | B24: Delivered to 1 shepherd for the year, 4 quarters 2.5 bushels, and taking as before. | C24: 0 | D24: 0 | E24: 0 | F24: 0 | G24: 0 | H24: 0 | I24: 0 | J24: 0 | K24: 0 | L24: 0 | M24: 0 | N24: 0 | O24: 0 | P24: 0 | Q24: 0 | R24: 0 | S24: 0 | T24: 0 | U24: 0 | V24: 0 | W24: 0 | X24: 4 | Y24: 2.5 | Z24: 4.3125 | AA24: 4.3125 | AB24: 0 | AC24: 4 | AD24: 2.5
A25: Barley | B25: Delivered to 1 attendant making the pottage of the manorial servants, going to the harrowing, and keeping the birds away from the curia and the corn for the year, 3 quarters 2 bushels, and taking a quarter every 16 weeks. | C25: 0 | D25: 0 | E25: 0 | F25: 0 | G25: 0 | H25: 0 | I25: 0 | J25: 0 | K25: 0 | L25: 0 | M25: 0 | N25: 0 | O25: 0 | P25: 0 | Q25: 0 | R25: 0 | S25: 0 | T25: 0 | U25: 0 | V25: 0 | W25: 0 | X25: 3 | Y25: 2 | Z25: 3.25 | AA25: 3.25 | AB25: 0 | AC25: 3 | AD25: 2
A26: Barley | B26: Consumed by the household at harvest-time, 3 bushels Sold, 8.5 quarters 2.5 bushels | C26: 0 | D26: 0 | E26: 0 | F26: 0 | G26: 0 | H26: 0 | I26: 0 | J26: 0 | K26: 0 | L26: 0 | M26: 0 | N26: 0 | O26: 0 | P26: 0 | Q26: 8.5 | R26: 2.5 | S26: 8.8125 | T26: 0 | U26: 0 | V26: 0 | W26: 0 | X26: 8.5 | Y26: 2.5 | Z26: 8.8125 | AA26: 0.375 | AB26: 8.4375 | AC26: 0 | AD26: 3 | AE26: 8.5 | AF26: 2.5
A27: Barley | B27: Total | C27: 0 | D27: 0 | E27: 0 | F27: 0 | G27: 0 | H27: 0 | I27: 0 | J27: 0 | K27: 0 | L27: 0 | M27: 0 | N27: 0 | O27: 0 | P27: 0 | Q27: 0 | R27: 0 | S27: 0 | T27: 0 | U27: 0 | V27: 0 | W27: 0
A28: Dredge | B28: {yield: 5-fold plus 0.5 qr} | C28: 0 | D28: 0 | E28: 0 | F28: 0 | G28: 0 | H28: 0 | I28: 0 | J28: 0 | K28: 0 | L28: 0 | M28: 0 | N28: 0 | O28: 0 | P28: 0 | Q28: 0 | R28: 0 | S28: 0 | T28: 0 | U28: 0 | V28: 0 | W28: 0
A29: Dredge | B29: The same renders account for 8 quarters 1.5 bushels from the whole issue of dredge by struck measure. | C29: 0 | D29: 0 | E29: 0 | F29: 0 | G29: 0 | H29: 0 | I29: 0 | J29: 0 | K29: 0 | L29: 0 | M29: 0 | N29: 0 | O29: 0 | P29: 0 | Q29: 0 | R29: 0 | S29: 0 | T29: 8 | U29: 1.5 | V29: 8.1875 | W29: 0 | X29: 8 | Y29: 1.5 | Z29: 8.1875 | AA29: 8.1875 | AB29: 0 | AC29: 8 | AD29: 1.5
A30: Dredge | B30: Sown over 5 acres measured by the perch which lie in Annerescrofte and in Westfeld', 3 quarters 2 bushels. | C30: 0 | D30: 0 | E30: 3 | F30: 2 | G30: 3.25 | H30: 0 | I30: 0 | J30: 0 | K30: 0 | L30: 0 | M30: 0 | N30: 0 | O30: 0 | P30: 0 | Q30: 0 | R30: 0 | S30: 0 | T30: 0 | U30: 0 | V30: 0 | W30: 0 | X30: 3 | Y30: 2 | Z30: 3.25 | AA30: 3.25 | AB30: 0 | AC30: 3 | AD30: 2
A31: Dredge | B31: that is, 5 bushels an acre, plus 1 bushels in all. | C31: 0 | D31: 0 | E31: 0 | F31: 0 | G31: 0 | H31: 0 | I31: 0 | J31: 0 | K31: 0 | L31: 0 | M31: 0 | N31: 0 | O31: 0 | P31: 0 | Q31: 0 | R31: 0 | S31: 0 | T31: 0 | U31: 0 | V31: 0 | W31: 0 | X31: 0 | Y31: 1 | Z31: 0.125 | AA31: 0.625 | AB31: -0.5 | AC31: 0 | AD31: 5 | AE31: 0 | AF31: 1
A32: Dredge | B32: Sold, 4.5 quarters 3.5 bushels | C32: 0 | D32: 0 | E32: 0 | F32: 0 | G32: 0 | H32: 0 | I32: 0 | J32: 0 | K32: 0 | L32: 0 | M32: 0 | N32: 0 | O32: 0 | P32: 0 | Q32: 4.5 | R32: 3.5 | S32: 4.9375 | T32: 0 | U32: 0 | V32: 0 | W32: 0 | X32: 4.5 | Y32: 3.5 | Z32: 4.9375 | AA32: 4.9375 | AB32: 0 | AC32: 4.5 | AD32: 3.5
A33: Dredge | B33: Total | C33: 0 | D33: 0 | E33: 0 | F33: 0 | G33: 0 | H33: 0 | I33: 0 | J33: 0 | K33: 0 | L33: 0 | M33: 0 | N33: 0 | O33: 0 | P33: 0 | Q33: 0 | R33: 0 | S33: 0 | T33: 0 | U33: 0 | V33: 0 | W33: 0
A34: Oats | B34: {yield: two-fold less 1 qr 1 bushels} | C34: 0 | D34: 0 | E34: 0 | F34: 0 | G34: 0 | H34: 0 | I34: 0 | J34: 0 | K34: 0 | L34: 0 | M34: 0 | N34: 0 | O34: 0 | P34: 0 | Q34: 0 | R34: 0 | S34: 0 | T34: 0 | U34: 0 | V34: 0 | W34: 0
A35: Oats | B35: The same renders account for 83 quarters from the whole issue of oats by struck measure. | C35: 0 | D35: 0 | E35: 0 | F35: 0 | G35: 0 | H35: 0 | I35: 0 | J35: 0 | K35: 0 | L35: 0 | M35: 0 | N35: 0 | O35: 0 | P35: 0 | Q35: 0 | R35: 0 | S35: 0 | T35: 83 | U35: 0 | V35: 83 | W35: 0 | X35: 83 | Y35: 0 | Z35: 83 | AA35: 83 | AB35: 0 | AC35: 83 | AD35: 0
A36: Oats | B36: 10.5 quarters 2 bushels by estimation in sheaves given to oxen. | C36: 0 | D36: 0 | E36: 0 | F36: 0 | G36: 0 | H36: 0 | I36: 0 | J36: 0 | K36: 0 | L36: 0 | M36: 0 | N36: 0 | O36: 0 | P36: 0 | Q36: 0 | R36: 0 | S36: 0 | T36: 0 | U36: 0 | V36: 0 | W36: 0 | X36: 10.5 | Y36: 2 | Z36: 10.75 | AA36: 10.75 | AB36: 0 | AC36: 10.5 | AD36: 2
A37: Oats | B37: Total, 93 quarters 7 bushels Sown over 59 acres measured by the perch which lie at Alnetum, in 3 crofts beside the garden, in Westfeud' in various places, and in Lambham, 40 quarters 7 bushels. | C37: 0 | D37: 0 | E37: 133 | F37: 14 | G37: 134.75 | H37: 0 | I37: 0 | J37: 0 | K37: 0 | L37: 0 | M37: 0 | N37: 0 | O37: 0 | P37: 0 | Q37: 0 | R37: 0 | S37: 0 | T37: 0 | U37: 0 | V37: 0 | W37: 0 | X37: 40 | Y37: 7 | Z37: 40.875 | AA37: 93.875 | AB37: -53 | AC37: 93 | AD37: 7 | AE37: 40 | AF37: 7
A38: Oats | B38: that is, 5.5 bushels an acre, less 2.5 bushels in all. | C38: 0 | D38: 0 | E38: 0 | F38: 0 | G38: 0 | H38: 0 | I38: 0 | J38: 0 | K38: 0 | L38: 0 | M38: 0 | N38: 0 | O38: 0 | P38: 0 | Q38: 0 | R38: 0 | S38: 0 | T38: 0 | U38: 0 | V38: 0 | W38: 0 | X38: 0 | Y38: 2.5 | Z38: 0.3125 | AA38: 0.6875 | AB38: -0.375 | AC38: 0 | AD38: 5.5 | AE38: 0 | AF38: 2.5
A39: Oats | B39: . | C39: 0 | D39: 0 | E39: 0 | F39: 0 | G39: 0 | H39: 0 | I39: 0 | J39: 0 | K39: 0 | L39: 0 | M39: 0 | N39: 0 | O39: 0 | P39: 0 | Q39: 0 | R39: 0 | S39: 0 | T39: 0 | U39: 0 | V39: 0 | W39: 0 | X39: 0 | Y39: 0 | Z39: 0 | AA39: 0 | AB39: 0 | AC39: 0 | AD39: 0
A40: Oats | B40: fodder of 3 cart-horses for the year, 11.5 quarters. | C40: 0 | D40: 0 | E40: 0 | F40: 0 | G40: 0 | H40: 0 | I40: 0 | J40: 0 | K40: 0 | L40: 0 | M40: 0 | N40: 11.5 | O40: 0 | P40: 11.5 | Q40: 0 | R40: 0 | S40: 0 | T40: 0 | U40: 0 | V40: 0 | W40: 0 | X40: 11.5 | Y40: 0 | Z40: 11.5 | AA40: 11.5 | AB40: 0 | AC40: 11.5 | AD40: 0
...

Sheet Sale of Corn Prices
A1: Heading | B1: Sentence | C1: Total in Pounds | D1: Pounds | E1: Shillings | F1: Pence | G1: Corn | H1: Total Quarters Except 1 | I1: Total Bushels Except 1 | J1: Total Corn Cross-Check | K1: Total Corn Manorial Account | L1: Corn Quantity Error | M1: Quarters 0 | N1: Bushels 0 | O1: shilling a quarter 1 | P1: pence a quarter 1 | Q1: Quarters 1 | R1: Bushels 1 | S1: shilling a quarter 2 | T1: pence a quarter 2 | U1: Quarters 2 | V1: Bushels 2 | W1: shilling a quarter 3 | X1: pence a quarter 3 | Y1: Quarters 3 | Z1: Bushels 3 | AA1: shilling a quarter 4 | AB1: pence a quarter 4 | AC1: Quarters 4 | AD1: Bushels 4 | AE1: Quarters 5 | AF1: Bushels 5 | AG1: £ a quarter 1 | AH1: £ a quarter 2 | AI1: £ a quarter 3 | AJ1: £ a quarter 4 | AK1: Quarters Sold | AL1: Weighted Average Price per Quarter | AM1: Non-Weighted Average Price per Quarter | AN1: Corn lowercase
A2: Sale of corn | B2: The same renders account for £16 12 shilling 10.75pence from 57.5 quarters .5 bushels of wheat sold, at 4 shilling 6pence a quarters for 6.5 quarters, 5 shilling a quarters for 16 quarters 0.5 bushels, 6 shilling a quarters for 15 quarters, and 6 shilling 8pence a quarters for 20 quarters. | C2: 16.64 | D2: 16 | E2: 12 | F2: 10.75 | G2: wheat | H2: 57.5 | I2: 5.5 | J2: 58.1875 | K2: 57.5 | L2: 0.6875 | M2: 57.5 | N2: 0 | O2: 4 | P2: 6 | Q2: 0 | R2: 5 | S2: 5 | T2: 0 | U2: 6.5 | V2: 0 | W2: 6 | X2: 0 | Y2: 16 | Z2: 0.5 | AA2: 6 | AB2: 8 | AC2: 15 | AD2: 0 | AE2: 20 | AF2: 0 | AG2: 0.225 | AH2: 0.25 | AI2: 0.3 | AJ2: 0.33333333 | AK2: 57.5 | AL2: 0.30335516 | AM2: 0.27708333 | AN2: wheat
A3: Sale of corn | B3: 18 shilling 11.5pence from 10 quarters 5 bushels of curall sold, at 1 shilling 8pence a quarters for 9 quarters 3 bushels, and 2 shilling 8pence a quarters for 1 quarters 2 bushels. | C3: 0.95 | D3: 0 | E3: 18 | F3: 11.5 | G3: curall | H3: 10 | I3: 5 | J3: 10.625 | K3: 10.625 | L3: 0 | M3: 10 | N3: 5 | O3: 1 | P3: 8 | Q3: 9 | R3: 3 | S3: 2 | T3: 8 | U3: 1 | V3: 2 | AG3: 0.083333333 | AH3: 0.13333333 | AK3: 10.625 | AL3: 0.089215686 | AM3: 0.10833333 | AN3: curall
A4: Sale of corn | B4: £1 15 shilling 3pence from 8.5 quarters 2.5 bushels of barley sold, at 4 shilling a quarters. | C4: 1.76 | D4: 1 | E4: 15 | F4: 3 | G4: barley | H4: 8.5 | I4: 2.5 | J4: 8.8125 | K4: 8.8125 | L4: 0 | M4: 8.5 | N4: 2.5 | O4: 4 | P4: 0 | AG4: 0.2 | AK4: 8.8125 | AL4: 0.2 | AM4: 0.2 | AN4: barley
A5: Sale of corn | B5: 14 shilling 9.75pence from 4.5 quarters 3.5 bushels of dredge sold, at 3 shilling a quarters. | C5: 0.74 | D5: 0 | E5: 14 | F5: 9.75 | H5: 4.5 | I5: 3.5 | J5: 4.9375 | K5: 4.9375 | L5: 0 | M5: 4.5 | N5: 3.5 | O5: 3 | P5: 0 | AG5: 0.15 | AK5: 4.9375 | AL5: 0.15 | AM5: 0.15
A6: Sale of corn | B6: £3 9 shilling 6pence from 30.5 quarters 2 bushels of oats sold, at 2 shilling a quarters for 14 quarters 6 bushels, 2 shilling 4pence a quarters for 8 quarters, and 2 shilling 8pence a quarters for 8 quarters. | C6: 3.48 | D6: 3 | E6: 9 | F6: 6 | G6: oats | H6: 30 | I6: 6 | J6: 30.75 | K6: 30.75 | L6: 0 | M6: 30.5 | N6: 2 | O6: 2 | P6: 0 | Q6: 14 | R6: 6 | S6: 2 | T6: 4 | U6: 8 | V6: 0 | W6: 2 | X6: 8 | Y6: 8 | Z6: 0 | AG6: 0.1 | AH6: 0.11666667 | AI6: 0.13333333 | AK6: 30.75 | AL6: 0.11300813 | AM6: 0.11666667 | AN6: oats
A7: Sale of corn | B7: 15 shilling 2.5pence from 7 quarters .5 bushels of peas sold, at 2 shilling a quarters for 3 quarters 6.5 bushels, and 2 shilling 4pence a quarters for 3 quarters 2 bushels. | C7: 0.76 | D7: 0 | E7: 15 | F7: 2.5 | G7: peas | H7: 6 | I7: 13.5 | J7: 7.6875 | K7: 7 | L7: 0.6875 | M7: 7 | N7: 0 | O7: 2 | P7: 0 | Q7: 0 | R7: 5 | S7: 2 | T7: 4 | U7: 3 | V7: 6.5 | Y7: 3 | Z7: 2 | AG7: 0.1 | AH7: 0.11666667 | AK7: 7 | AL7: 0.11431925 | AM7: 0.10833333 | AN7: peas
A8: Sale of corn | B8: 7 shilling 6pence from 3 quarters 6 bushels of vetches sold, at 2 shilling a quarters. | C8: 0.38 | D8: 0 | E8: 7 | F8: 6 | G8: vetches | H8: 3 | I8: 6 | J8: 3.75 | K8: 3.75 | L8: 0 | M8: 3 | N8: 6 | O8: 2 | P8: 0 | AG8: 0.1 | AK8: 3.75 | AL8: 0.1 | AM8: 0.1 | AN8: vetches
A9: Sale of corn | B9: Total, £24 14 shilling 1.5pence | C9: 24.71 | D9: 24 | E9: 14 | F9: 1.5 | H9: 0 | I9: 0 | J9: 0 | K9: 0 | L9: 0 | M9: 0 | N9: 0 | AG9: inf | AK9: 0 | AL9: inf | AM9: inf

Sheet raw data
A1: Heading | B1: Sentence | C1: Total in Pounds | D1: Pounds | E1: Shillings | F1: Pence | G1: Corn | H1: Total Quarters Except 1 | I1: Total Bushels Except 1 | J1: Total Corn Cross-Check | K1: Total Corn Manorial Account | L1: Corn Quantity Error | M1: Quarters 1 | N1: Bushels 1 | O1: Quarters 2 | P1: Bushels 2 | Q1: Quarters 3 | R1: Bushels 3 | S1: Quarters 4 | T1: Bushels 4 | U1: Quarters 5 | V1: Bushels 5 | W1: Quarters 6 | X1: Bushels 6 | Y1: shilling a quarter 1 | Z1: pence a quarter 1 | AA1: shilling a quarter 2 | AB1: pence a quarter 2 | AC1: shilling a quarter 3 | AD1: pence a quarter 3 | AE1: shilling a quarter 4 | AF1: pence a quarter 4 | AG1: shilling a bushel 1 | AH1: pence a bushel 1 | AI1: shilling a bushel 2 | AJ1: pence a bushel 2 | AK1: shilling a bushel 3 | AL1: pence a bushel 3 | AM1: shilling a bushel 4 | AN1: pence a bushel 4
A2: Arrears | B2: Robert de' renders account for 13 shilling 7pence of arrears from the previous year. | C2: 0.68 | D2: 0 | E2: 13 | F2: 7 | H2: 0 | I2: 0 | J2: 0 | K2: 0 | L2: 0 | M2: 0 | N2: 0
A3: Arrears | B3: All delivered to Sir Geoffrey, treasurer of Wolvesey. | C3: 0 | D3: 0 | E3: 0 | F3: 0 | H3: 0 | I3: 0 | J3: 0 | K3: 0 | L3: 0 | M3: 0 | N3: 0
A4: Arrears | B4: He is quit. | C4: 0 | D4: 0 | E4: 0 | F4: 0 | H4: 0 | I4: 0 | J4: 0 | K4: 0 | L4: 0 | M4: 0 | N4: 0
A5: Rents of assize | B5: The same renders account for 8 shilling 1pence for rents of assize at Christmas. | C5: 0.4 | D5: 0 | E5: 8 | F5: 1 | H5: 0 | I5: 0 | J5: 0 | K5: 0 | L5: 0 | M5: 0 | N5: 0
A6: Rents of assize | B6: £1 6 shilling 3.75pence at Easter (22 April). | C6: 1.32 | D6: 1 | E6: 6 | F6: 3.75 | H6: 0 | I6: 0 | J6: 0 | K6: 0 | L6: 0 | M6: 0 | N6: 0
A7: Rents of assize | B7: 8 shilling 1pence at St John the Baptist (24 June). | C7: 0.4 | D7: 0 | E7: 8 | F7: 1 | H7: 0 | I7: 0 | J7: 0 | K7: 0 | L7: 0 | M7: 0 | N7: 0
A8: Rents of assize | B8: £1 7 shilling 10.751. at Michaelmas (29 September). | C8: 1.35 | D8: 1 | E8: 7 | F8: 0 | H8: 0 | I8: 0 | J8: 0 | K8: 0 | L8: 0 | M8: 0 | N8: 0
A9: Rents of assize | B9: Total, £3 10 shilling 4.5pence | C9: 3.52 | D9: 3 | E9: 10 | F9: 4.5 | H9: 0 | I9: 0 | J9: 0 | K9: 0 | L9: 0 | M9: 0 | N9: 0
A10: Increment | B10: The same renders account for 1pence for the increment of rent of Thomas Godwyn' to have the moiety of 1 day-work beside his house. | C10: 0 | D10: 0 | E10: 0 | F10: 1 | H10: 0 | I10: 0 | J10: 0 | K10: 0 | L10: 0 | M10: 0 | N10: 0
A11: Increment | B11: Total, 1pence | C11: 0 | D11: 0 | E11: 0 | F11: 1 | H11: 0 | I11: 0 | J11: 0 | K11: 0 | L11: 0 | M11: 0 | N11: 0
A12: Total of rents with increment | B12: Total of rents with increment, £3 10 shilling 4.5pence3 | C12: 3.52 | D12: 3 | E12: 10 | F12: 4.5 | H12: 0 | I12: 0 | J12: 0 | K12: 0 | L12: 0 | M12: 0 | N12: 0
A13: Issues of the manor | B13: The same renders account for 1 shilling 2pence from pannage of pigs. | C13: 0.06 | D13: 0 | E13: 1 | F13: 2 | H13: 0 | I13: 0 | J13: 0 | K13: 0 | L13: 0 | M13: 0 | N13: 0
... A36: Issues of the manor | B36: Total, £6 13 shilling 2.5pence | C36: 6.66 | D36: 6 | E36: 13 | F36: 2.5 | H36: 0 | I36: 0 | J36: 0 | K36: 0 | L36: 0 | M36: 0 | N36: 0
A37: Sale of corn | B37: The same renders account for £16 12 shilling 10.75pence from 57.5 quarters .5 bushels of wheat sold, at 4 shilling 6pence a quarters for 6.5 quarters, 5 shilling a quarters for 16 quarters 0.5 bushels, 6 shilling a quarters for 15 quarters, and 6 shilling 8pence a quarters for 20 quarters. | C37: 16.64 | D37: 16 | E37: 12 | F37: 10.75 | G37: wheat | H37: 57.5 | I37: 5.5 | J37: 58.1875 | K37: 57.5 | L37: 0.6875 | M37: 57.5 | N37: 0 | O37: 0 | P37: 5 | Q37: 6.5 | R37: 0 | S37: 16 | T37: 0.5 | U37: 15 | V37: 0 | W37: 20 | X37: 0 | Y37: 4 | Z37: 6 | AA37: 5 | AB37: 0 | AC37: 6 | AD37: 0 | AE37: 6 | AF37: 8
A38: Sale of corn | B38: 18 shilling 11.5pence from 10 quarters 5 bushels of curall sold, at 1 shilling 8pence a quarters for 9 quarters 3 bushels, and 2 shilling 8pence a quarters for 1 quarters 2 bushels. | C38: 0.95 | D38: 0 | E38: 18 | F38: 11.5 | G38: curall | H38: 10 | I38: 5 | J38: 10.625 | K38: 10.625 | L38: 0 | M38: 10 | N38: 5 | O38: 9 | P38: 3 | Q38: 1 | R38: 2 | Y38: 1 | Z38: 8 | AA38: 2 | AB38: 8
A39: Sale of corn | B39: £1 15 shilling 3pence from 8.5 quarters 2.5 bushels of barley sold, at 4 shilling a quarters. | C39: 1.76 | D39: 1 | E39: 15 | F39: 3 | G39: barley | H39: 8.5 | I39: 2.5 | J39: 8.8125 | K39: 8.8125 | L39: 0 | M39: 8.5 | N39: 2.5 | Y39: 4 | Z39: 0
A40: Sale of corn | B40: 14 shilling 9.75pence from 4.5 quarters 3.5 bushels of dredge sold, at 3 shilling a quarters. | C40: 0.74 | D40: 0 | E40: 14 | F40: 9.75 | H40: 4.5 | I40: 3.5 | J40: 4.9375 | K40: 4.9375 | L40: 0 | M40: 4.5 | N40: 3.5 | Y40: 3 | Z40: 0
A41: Sale of corn | B41: £3 9 shilling 6pence from 30.5 quarters 2 bushels of oats sold, at 2 shilling a quarters for 14 quarters 6 bushels, 2 shilling 4pence a quarters for 8 quarters, and 2 shilling 8pence a quarters for 8 quarters. | C41: 3.48 | D41: 3 | E41: 9 | F41: 6 | G41: oats | H41: 30 | I41: 6 | J41: 30.75 | K41: 30.75 | L41: 0 | M41: 30.5 | N41: 2 | O41: 14 | P41: 6 | Q41: 8 | R41: 0 | S41: 8 | T41: 0 | Y41: 2 | Z41: 0 | AA41: 2 | AB41: 4 | AC41: 2 | AD41: 8
A42: Sale of corn | B42: 15 shilling 2.5pence from 7 quarters .5 bushels of peas sold, at 2 shilling a quarters for 3 quarters 6.5 bushels, and 2 shilling 4pence a quarters for 3 quarters 2 bushels. | C42: 0.76 | D42: 0 | E42: 15 | F42: 2.5 | G42: peas | H42: 6 | I42: 13.5 | J42: 7.6875 | K42: 7 | L42: 0.6875 | M42: 7 | N42: 0 | O42: 0 | P42: 5 | Q42: 3 | R42: 6.5 | S42: 3 | T42: 2 | Y42: 2 | Z42: 0 | AA42: 2 | AB42: 4
A43: Sale of corn | B43: 7 shilling 6pence from 3 quarters 6 bushels of vetches sold, at 2 shilling a quarters. | C43: 0.38 | D43: 0 | E43: 7 | F43: 6 | G43: vetches | H43: 3 | I43: 6 | J43: 3.75 | K43: 3.75 | L43: 0 | M43: 3 | N43: 6 | Y43: 2 | Z43: 0
A44: Sale of corn | B44: Total, £24 14 shilling 1.5pence | C44: 24.71 | D44: 24 | E44: 14 | F44: 1.5 | H44: 0 | I44: 0 | J44: 0 | K44: 0 | L44: 0 | M44: 0 | N44: 0
A45: Perquisites | B45: The same renders account for 6 shilling from the amercements of 2 courts. | C45: 0.3 | D45: 0 | E45: 6 | F45: 0 | H45: 0 | I45: 0 | J45: 0 | K45: 0 | L45: 0 | M45: 0 | N45: 0
A46: Perquisites | B46: 13 shilling 4pence from Oliver Stak' to receive 4 acres of land whilst the manor of Cams is in the wardship of the lorpence Total, 19 shilling 4pence | C46: 0.67 | D46: 0 | E46: 13 | F46: 4 | H46: 0 | I46: 0 | J46: 0 | K46: 0 | L46: 0 | M46: 0 | N46: 0
A47: Total of all receipts | B47: Total of all receipts, £35 17 shilling 0.25pence | C47: 35.85 | D47: 35 | E47: 17 | F47: 0.25 | H47: 0 | I47: 0 | J47: 0 | K47: 0 | L47: 0 | M47: 0 | N47: 0
A48: Cost of ploughs | B48: In iron and steel bought for the ironwork of 2 ploughs for the year 6 shilling 8pence, with the stipend of the smith. | C48: 0.33 | D48: 0 | E48: 6 | F48: 8 | H48: 0 | I48: 0 | J48: 0 | K48: 0 | L48: 0 | M48: 0 | N48: 0
A49: Cost of ploughs | B49: . | C49: 0 | D49: 0 | E49: 0 | F49: 0 | H49: 0 | I49: 0 | J49: 0 | K49: 0 | L49: 0 | M49: 0 | N49: 0
A50: Cost of ploughs | B50: 1 ploughshare bought 9pence. | C50: 0.04 | D50: 0 | E50: 0 | F50: 9 | H50: 0 | I50: 0 | J50: 0 | K50: 0 | L50: 0 | M50: 0 | N50: 0
A51: Cost of ploughs | B51: 2 plough feet bought 1 shilling. | C51: 0.05 | D51: 0 | E51: 1 | F51: 0 | H51: 0 | I51: 0 | J51: 0 | K51: 0 | L51: 0 | M51: 0 | N51: 0
A52: Cost of ploughs | B52: 1 new plough made with the other ploughs mended 10pence. | C52: 0.04 | D52: 0 | E52: 0 | F52: 10 | H52: 0 | I52: 0 | J52: 0 | K52: 0 | L52: 0 | M52: 0 | N52: 0
A53: Cost of ploughs | B53: 2 pairs of wheels bought 8pence. | C53: 0.03 | D53: 0 | E53: 0 | F53: 8 | H53: 0 | I53: 0 | J53: 0 | K53: 0 | L53: 0 | M53: 0 | N53: 0
A54: Cost of ploughs | B54: fitting 1 plough with iron tyres 1.5pence. | C54: 0.01 | D54: 0 | E54: 0 | F54: 1.5 | H54: 0 | I54: 0 | J54: 0 | K54: 0 | L54: 0 | M54: 0 | N54: 0
A55: Cost of ploughs | B55: shoeing 2 plough-horses for 1 term 1 shilling. | C55: 0.05 | D55: 0 | E55: 1 | F55: 0 | H55: 0 | I55: 0 | J55: 0 | K55: 0 | L55: 0 | M55: 0 | N55: 0
... A62: Cost of ploughs | B62: stipend of 1 ploughman from Michaelmas until Easter 1 shilling 6pence, because thereafter a third ploughman was hired by the day and a fourth ploughman held a plough for his lanpence. | C62: 0.08 | D62: 0 | E62: 1 | F62: 6 | H62: 0 | I62: 0 | J62: 0 | K62: 0 | L62: 0 | M62: 0 | N62: 0
A63: Cost of ploughs | B63: 2 quarters 2 bushels of wheat bought for sowing 11 shilling 3pence, at 5 shilling a quarters. | C63: 0.56 | D63: 0 | E63: 11 | F63: 3 | G63: wheat | H63: 2 | I63: 2 | J63: 2.25 | K63: 2.25 | L63: 0 | M63: 2 | N63: 2 | Y63: 5 | Z63: 0
A64: Cost of ploughs | B64: . | C64: 0 | D64: 0 | E64: 0 | F64: 0 | H64: 0 | I64: 0 | J64: 0 | K64: 0 | L64: 0 | M64: 0 | N64: 0
A65: Cost of ploughs | B65: shoeing oxen 6pence Total, £2 11 shilling 10.5pence | C65: 2.59 | D65: 2 | E65: 11 | F65: 10.5 | H65: 0 | I65: 0 | J65: 0 | K65: 0 | L65: 0 | M65: 0 | N65: 0
A66: Cost of carts | B66: In 1 cart mended with large nails bought for the same 10pence. | C66: 0.04 | D66: 0 | E66: 0 | F66: 10 | H66: 0 | I66: 0 | J66: 0 | K66: 0 | L66: 0 | M66: 0 | N66: 0
A67: Cost of carts | B67: fitting the cart with axles with axles bought for the same 5pence. | C67: 0.02 | D67: 0 | E67: 0 | F67: 5 | H67: 0 | I67: 0 | J67: 0 | K67: 0 | L67: 0 | M67: 0 | N67: 0
A68: Cost of carts | B68: clouts, nails and grease bought 11pence. | C68: 0.05 | D68: 0 | E68: 0 | F68: 11 | H68: 0 | I68: 0 | J68: 0 | K68: 0 | L68: 0 | M68: 0 | N68: 0
...
