Workbook

Sheet Crawley 1301 Overview - Completed
A1: CRAWLEY 1301 OVERVIEW - COMPLETED | B1: Total in £ | C1: Error | D1: Note
A2: CASH ACCOUNT
A3: RECEIPTS
A4: Arrears total | B4: 7.4333333
A5: Rents of assize total | B5: 14.079167
A6: Quittances total | B6: 2.7833333
A7: Defaults of rent total | B7: 1.0166667
A8: Defaults of rent through the pestilence total
A9: Cotlands defaults total
A10: Cotlands total
A11: Total of quittances and defaults of rent total
A12: Total of rents remaining clear total
A13: Farms total
A14: Annual recognizances total | B14: 0.0875
A15: Issues of the Manor total | B15: 19.945833
A16: Issues of the tenements in the lord's hands total
A17: Sale of labour services total
A18: Sale of corn total | B18: 23.983333
A19: Entry and marriage fines total | B19: 0.86666667
A20: Pleas & perquisites total | B20: 0.99583333
A21: Forfeited chattels total
A22: Farm of the demesne land total
A23: Total of all receipts (calculated here) | B23: =SUM(B5:B22)
A24: Total of all receipts (calculated here) incl arrears | B24: =SUM(B4:B22)
A25: Total recorded in the accounts excl. arrears | C25: =B23-B25
A26: Total recorded in the accounts incl. arrears | B26: =B25+B4
A29: EXPENSES
A30: Cost of ploughs total | B30: 3.553125
A31: Purchase of corn total | B31: 0.84166667
A32: Cost of carts and wagons total | B32: 0.81875
A33: Cost of dairy total | B33: 3.9729167
A34: Purchase of stock total
A35: Sheepcote total
A36: Cost of buildings total | B36: 0.321875
A37: Threshing total | B37: 1.0208333
A38: Barley expenses
A39: Expenses of the harvest total | B39: 1.6916667
A40: Necessary expenses
A41: Wages of the bailiff
A42: Steward's expenses total
...

Sheet Issues of the Mills
A1: No mill account for Adderbury

Sheet raw data
A1: Heading | B1: Sentence | C1: Total in Pounds | D1: Pounds | E1: Shillings | F1: Pence | G1: Corn | H1: Total Quarters Except 1 | I1: Total Bushels Except 1 | J1: Total Corn Cross-Check | K1: Total Corn Manorial Account | L1: Corn Quantity Error | M1: Quarters 1 | N1: Bushels 1 | O1: shilling a quarter 1 | P1: pence a quarter 1 | Q1: shilling a quarter 2 | R1: pence a quarter 2 | S1: shilling a quarter 3 | T1: pence a quarter 3 | U1: shilling a quarter 4 | V1: pence a quarter 4 | W1: shilling a bushel 1 | X1: pence a bushel 1 | Y1: shilling a bushel 2 | Z1: pence a bushel 2 | AA1: shilling a bushel 3 | AB1: pence a bushel 3 | AC1: shilling a bushel 4 | AD1: pence a bushel 4
A2: Adderbury | B2: The account2 of William Jakeman, reeve there, for the sixth year of the translation of Henry Beaufort', lord bishop of Winchester, and the eleventh year of the reign of King Henry the Fourth. | C2: 0 | D2: 0 | E2: 0 | F2: 0 | H2: 0 | I2: 0 | J2: 0 | K2: 0 | L2: 0 | M2: 0 | N2: 0
A3: Arrears | B3: None. | C3: 0 | D3: 0 | E3: 0 | F3: 0 | H3: 0 | I3: 0 | J3: 0 | K3: 0 | L3: 0 | M3: 0 | N3: 0
A4: Rents of assize | B4: And for £6 9 shilling 6.25pence for all rents of assize at St Thomas the Apostle (21 December). | C4: 6.48 | D4: 6 | E4: 9 | F4: 6.25 | H4: 0 | I4: 0 | J4: 0 | K4: 0 | L4: 0 | M4: 0 | N4: 0
A5: Rents of assize | B5: £6 9 shilling 8.5pence at Easter (23 March). | C5: 6.49 | D5: 6 | E5: 9 | F5: 8.5 | H5: 0 | I5: 0 | J5: 0 | K5: 0 | L5: 0 | M5: 0 | N5: 0
A6: Rents of assize | B6: £6 9 shilling 6.25pence at the Nativity of St John the Baptist (24 June). | C6: 6.48 | D6: 6 | E6: 9 | F6: 6.25 | H6: 0 | I6: 0 | J6: 0 | K6: 0 | L6: 0 | M6: 0 | N6: 0
A7: Rents of assize | B7: £6 10 shilling 1.5pence at Michaelmas (29 September). | C7: 6.51 | D7: 6 | E7: 10 | F7: 1.5 | H7: 0 | I7: 0 | J7: 0 | K7: 0 | L7: 0 | M7: 0 | N7: 0
A8: Rents of assize | B8: Total, £25 18 shilling 10.5pence. | C8: 25.94 | D8: 25 | E8: 18 | F8: 10.5 | H8: 0 | I8: 0 | J8: 0 | K8: 0 | L8: 0 | M8: 0 | N8: 0
A9: Quittances of rent | B9: In quittance of rent of 1 reeve for the year 5 shilling. | C9: 0.25 | D9: 0 | E9: 5 | F9: 0 | H9: 0 | I9: 0 | J9: 0 | K9: 0 | L9: 0 | M9: 0 | N9: 0
A10: Quittances of rent | B10: nothing this year of the 4 shilling for 1 smith forging the ironwork of 2 ploughs for the year. | C10: 0.2 | D10: 0 | E10: 4 | F10: 0 | H10: 0 | I10: 0 | J10: 0 | K10: 0 | L10: 0 | M10: 0 | N10: 0
A11: Quittances of rent | B11: nothing this year of the 4 shilling for 1 shepherd keeping the lord's wethers for the year. | C11: 0.2 | D11: 0 | E11: 4 | F11: 0 | H11: 0 | I11: 0 | J11: 0 | K11: 0 | L11: 0 | M11: 0 | N11: 0
A12: Quittances of rent | B12: nothing this year of the 4 shilling for 1 swineherd for the year. | C12: 0.2 | D12: 0 | E12: 4 | F12: 0 | H12: 0 | I12: 0 | J12: 0 | K12: 0 | L12: 0 | M12: 0 | N12: 0
A13: Quittances of rent | B13: nothing this year of the 4 shilling for 1 cowherd for the year. | C13: 0.2 | D13: 0 | E13: 4 | F13: 0 | H13: 0 | I13: 0 | J13: 0 | K13: 0 | L13: 0 | M13: 0 | N13: 0
... A149: Cost of buildings | B149: board-nails and clout-nails bought for the same 1 shilling 4pence. | C149: 0.07 | D149: 0 | E149: 1 | F149: 4 | H149: 0 | I149: 0 | J149: 0 | K149: 0 | L149: 0 | M149: 0 | N149: 0
A150: Cost of buildings | B150: 4 quarters 4 bushels of limestone bought at Walton' 5 shilling 3pence, at 1 shilling 2pence a quarters. | C150: 0.26 | D150: 0 | E150: 5 | F150: 3 | H150: 4 | I150: 4 | J150: 4.5 | K150: 4.5 | L150: 0 | M150: 4 | N150: 4 | O150: 1 | P150: 2
A151: Cost of buildings | B151: carrying the same 4pence. | C151: 0.02 | D151: 0 | E151: 0 | F151: 4 | H151: 0 | I151: 0 | J151: 0 | K151: 0 | L151: 0 | M151: 0 | N151: 0
A152: Cost of buildings | B152: 8 quarters of limestone bought at Witney 10 shilling 4pence, at 1 shilling 31 pence a quarters. | C152: 0.52 | D152: 0 | E152: 10 | F152: 4 | H152: 8 | I152: 0 | J152: 8 | K152: 8 | L152: 0 | M152: 8 | N152: 0 | O152: 1 | P152: 31
A153: Cost of buildings | B153: carrying the same from Witney to Adderbury 3 shilling 8pence. | C153: 0.18 | D153: 0 | E153: 3 | F153: 8 | H153: 0 | I153: 0 | J153: 0 | K153: 0 | L153: 0 | M153: 0 | N153: 0
A154: Cost of buildings | B154: 1,500 stone slates bought 6 shilling, at 4 shilling a 1,000.. | C154: 0.3 | D154: 0 | E154: 6 | F154: 0 | H154: 0 | I154: 0 | J154: 0 | K154: 0 | L154: 0 | M154: 0 | N154: 0
A155: Cost of buildings | B155: 500 eaves-stones bought 2 shilling 6pence, at 6pence a 100.. | C155: 0.12 | D155: 0 | E155: 2 | F155: 6 | H155: 0 | I155: 0 | J155: 0 | K155: 0 | L155: 0 | M155: 0 | N155: 0
A156: Cost of buildings | B156: 6,000 pins bought 2 shilling, at 4pence a 1,000.. | C156: 0.12 | D156: 0 | E156: 2 | F156: 4 | H156: 0 | I156: 0 | J156: 0 | K156: 0 | L156: 0 | M156: 0 | N156: 0
A157: Cost of buildings | B157: 50 ridge-tiles bought 6 shilling 3pence, at 1.5pence each. | C157: 0.31 | D157: 0 | E157: 6 | F157: 3 | H157: 0 | I157: 0 | J157: 0 | K157: 0 | L157: 0 | M157: 0 | N157: 0
A158: Cost of buildings | B158: sand bought and dug and quarried at Tadmarton 10pence. | C158: 0.04 | D158: 0 | E158: 0 | F158: 10 | H158: 0 | I158: 0 | J158: 0 | K158: 0 | L158: 0 | M158: 0 | N158: 0
A159: Cost of buildings | B159: stipend of 1 man going to Walton' to quarry lime there 2pence. | C159: 0.01 | D159: 0 | E159: 0 | F159: 2 | H159: 0 | I159: 0 | J159: 0 | K159: 0 | L159: 0 | M159: 0 | N159: 0
A160: Cost of buildings | B160: expenses of 12 men coming for a boon-work with 6 carts to quarry sand at Newotele and carry it to Adderbury, with the digging, 2 shilling 3pence. | C160: 0.11 | D160: 0 | E160: 2 | F160: 3 | H160: 0 | I160: 0 | J160: 0 | K160: 0 | L160: 0 | M160: 0 | N160: 0
A161: Cost of buildings | B161: hiring 1 man to carry sand and lime from the warrener's chamber to the barn by piece-work 4pence. | C161: 0.02 | D161: 0 | E161: 0 | F161: 4 | H161: 0 | I161: 0 | J161: 0 | K161: 0 | L161: 0 | M161: 0 | N161: 0
A162: Cost of buildings | B162: carrying the ridge-tiles bought above 8pence. | C162: 0.03 | D162: 0 | E162: 0 | F162: 8 | H162: 0 | I162: 0 | J162: 0 | K162: 0 | L162: 0 | M162: 0 | N162: 0
A163: Cost of buildings | B163: expenses of various men coming for a boon-work to buy slates at Aynho and carry them to Adderbury with the expenses of 1 man there mending the said slates 2d 1 shilling 9.5pence. | C163: 0.09 | D163: 0 | E163: 1 | F163: 9.5 | H163: 0 | I163: 0 | J163: 0 | K163: 0 | L163: 0 | M163: 0 | N163: 0
A164: Cost of buildings | B164: 1 tine bought 8pence. | C164: 0.03 | D164: 0 | E164: 0 | F164: 8 | H164: 0 | I164: 0 | J164: 0 | K164: 0 | L164: 0 | M164: 0 | N164: 0
... A181: Total of all allowances | B181: Total of all allowances and cash deliveries, £64 19 shilling 11.5pence He is quit. | C181: 65 | D181: 64 | E181: 19 | F181: 11.5 | H181: 0 | I181: 0 | J181: 0 | K181: 0 | L181: 0 | M181: 0 | N181: 0
A182: Wheat | B182: William Jakeman, reeve there, answers for 3 quarters of wheat remaining.. | C182: 0 | D182: 0 | E182: 0 | F182: 0 | G182: wheat | H182: 3 | I182: 0 | J182: 3 | K182: 3 | L182: 0 | M182: 3 | N182: 0
A183: Wheat | B183: Total, 3 quarters.. | C183: 0 | D183: 0 | E183: 0 | F183: 0 | H183: 3 | I183: 0 | J183: 3 | K183: 3 | L183: 0 | M183: 3 | N183: 0
A184: Wheat | B184: 3 quarters remain in the keeping of John Eadburbury, farmer there, to be handed back and restored at the end of his farm of 12 years, this year being the fifth. | C184: 0 | D184: 0 | E184: 0 | F184: 0 | H184: 3 | I184: 0 | J184: 3 | K184: 3 | L184: 0 | M184: 3 | N184: 0
A185: Rye | B185: And for 34 quarters of rye remaining.. | C185: 0 | D185: 0 | E185: 0 | F185: 0 | G185: rye | H185: 34 | I185: 0 | J185: 34 | K185: 34 | L185: 0 | M185: 34 | N185: 0
A186: Rye | B186: Total, 34 quarters.. | C186: 0 | D186: 0 | E186: 0 | F186: 0 | H186: 34 | I186: 0 | J186: 34 | K186: 34 | L186: 0 | M186: 34 | N186: 0
A187: Rye | B187: 34 quarters remain in the keeping of the said John Eadburbury, farmer there, to be handed back and restored at the end of his farm as before. | C187: 0 | D187: 0 | E187: 0 | F187: 0 | H187: 34 | I187: 0 | J187: 34 | K187: 34 | L187: 0 | M187: 34 | N187: 0
A188: Dredge | B188: And for 30 quarters of dredge remaining.. | C188: 0 | D188: 0 | E188: 0 | F188: 0 | G188: dredge | H188: 30 | I188: 0 | J188: 30 | K188: 30 | L188: 0 | M188: 30 | N188: 0
A189: Dredge | B189: Total, 30 quarters.. | C189: 0 | D189: 0 | E189: 0 | F189: 0 | H189: 30 | I189: 0 | J189: 30 | K189: 30 | L189: 0 | M189: 30 | N189: 0
A190: Dredge | B190: 30 quarters remain in the keeping of the said John Eadburbury, farmer there, to be handed back and restored as before. | C190: 0 | D190: 0 | E190: 0 | F190: 0 | H190: 30 | I190: 0 | J190: 30 | K190: 30 | L190: 0 | M190: 30 | N190: 0
A191: Pulses | B191: None remain. | C191: 0 | D191: 0 | E191: 0 | F191: 0 | H191: 0 | I191: 0 | J191: 0 | K191: 0 | L191: 0 | M191: 0 | N191: 0
...

Sheet Prices
A1: Meat & Dairy Prices
C2: 1301 | D2: 1302 | E2: Average
A3: Beef | B3: £ per lb | C3: 0.0033351854 | D3: 0.0032608538 | E3: =AVERAGE(C3:D3)
A4: Mutton | B4: £ per lb | C4: 0.0036593977 | D4: 0.0037125513 | E4: =AVERAGE(C4:D4)
A5: Pork | B5: £ per lb | C5: 0.0038431326 | D5: 0.0037574803 | E5: =AVERAGE(C5:D5)
A6: Cheese | B6: £ per lb | C6: 0.0055768754 | D6: 0.0056654898 | E6: =AVERAGE(C6:D6)
A7: Butter | B7: £ per lb | C7: 0.0036626221 | D7: 0.0035935077 | E7: =AVERAGE(C7:D7)
A8: Milk | B8: £ per gallon | C8: 0.0055768754 | D8: 0.0056654898 | E8: =AVERAGE(C8:D8)

Sheet Labour Rents

Sheet Crawley Overview
A1: CRAWLEY | B1: £ | C1: s | D1: d | G1: Total in £ | H1: Error
A3: CASH ACCOUNT
A4: RECEIPTS
A5: Arrears total | G5: =IF(INDEX('Crawley Receipts'!$A$4:$F$110,MATCH('Crawley Overview'!$A5,'Crawley Receipts'!$A$4:$A$110,0),6)=0,"",INDEX('Crawley Receipts'!$A$4:$F$110,MATCH('Crawley Overview'!$A5,'Crawley Receipts'!$A$4:$A$110,0),6))
A6: Rents of assize total | G6: =IF(INDEX('Crawley Receipts'!$A$4:$F$110,MATCH('Crawley Overview'!$A6,'Crawley Receipts'!$A$4:$A$110,0),6)=0,"",INDEX('Crawley Receipts'!$A$4:$F$110,MATCH('Crawley Overview'!$A6,'Crawley Receipts'!$A$4:$A$110,0),6))
A7: Quittances total | G7: =IF(INDEX('Crawley Receipts'!$A$4:$F$110,MATCH('Crawley Overview'!$A7,'Crawley Receipts'!$A$4:$A$110,0),6)=0,"",INDEX('Crawley Receipts'!$A$4:$F$110,MATCH('Crawley Overview'!$A7,'Crawley Receipts'!$A$4:$A$110,0),6))
A8: Defaults of rent total | G8: =IF(INDEX('Crawley Receipts'!$A$4:$F$110,MATCH('Crawley Overview'!$A8,'Crawley Receipts'!$A$4:$A$110,0),6)=0,"",INDEX('Crawley Receipts'!$A$4:$F$110,MATCH('Crawley Overview'!$A8,'Crawley Receipts'!$A$4:$A$110,0),6))
A9: Total of rents remaining | G9: ='Crawley Receipts'!F36
A10: Annual recognizances total | G10: =IF(INDEX('Crawley Receipts'!$A$4:$F$110,MATCH('Crawley Overview'!$A10,'Crawley Receipts'!$A$4:$A$110,0),6)=0,"",INDEX('Crawley Receipts'!$A$4:$F$110,MATCH('Crawley Overview'!$A10,'Crawley Receipts'!$A$4:$A$110,0),6))
A11: Issues of the Manor total | G11: =IF(INDEX('Crawley Receipts'!$A$4:$F$110,MATCH('Crawley Overview'!$A11,'Crawley Receipts'!$A$4:$A$110,0),6)=0,"",INDEX('Crawley Receipts'!$A$4:$F$110,MATCH('Crawley Overview'!$A11,'Crawley Receipts'!$A$4:$A$110,0),6))
A12: Sale of corn total | G12: =IF(INDEX('Crawley Receipts'!$A$4:$F$110,MATCH('Crawley Overview'!$A12,'Crawley Receipts'!$A$4:$A$110,0),6)=0,"",INDEX('Crawley Receipts'!$A$4:$F$110,MATCH('Crawley Overview'!$A12,'Crawley Receipts'!$A$4:$A$110,0),6))
A13: Entry and marriage fines total | G13: =IF(INDEX('Crawley Receipts'!$A$4:$F$110,MATCH('Crawley Overview'!$A13,'Crawley Receipts'!$A$4:$A$110,0),6)=0,"",INDEX('Crawley Receipts'!$A$4:$F$110,MATCH('Crawley Overview'!$A13,'Crawley Receipts'!$A$4:$A$110,0),6))
A14: Pleas & perquisites total | G14: =IF(INDEX('Crawley Receipts'!$A$4:$F$110,MATCH('Crawley Overview'!$A14,'Crawley Receipts'!$A$4:$A$110,0),6)=0,"",INDEX('Crawley Receipts'!$A$4:$F$110,MATCH('Crawley Overview'!$A14,'Crawley Receipts'!$A$4:$A$110,0),6))
A15: Sum of the above (incl. arrears) | G15: =G5+G9+G10+G11+G12+G13+G14
A16: Total recorded in the accounts excl. arrears | G16: ='Crawley Receipts'!F110 | H16: matches excl. arrear sum
A17: Total recorded in the accounts incl. arrears
A20: EXPENSES
A21: Cost of ploughs total | G21: =IF(INDEX('Crawley Expenses'!$A$2:$F$108,MATCH('Crawley Overview'!$A21,'Crawley Expenses'!$A$2:$A$108,0),6)=0,"",INDEX('Crawley Expenses'!$A$2:$F$108,MATCH('Crawley Overview'!$A21,'Crawley Expenses'!$A$2:$A$108,0),6))
A22: Purchase of corn total | G22: =IF(INDEX('Crawley Expenses'!$A$2:$F$108,MATCH('Crawley Overview'!$A22,'Crawley Expenses'!$A$2:$A$108,0),6)=0,"",INDEX('Crawley Expenses'!$A$2:$F$108,MATCH('Crawley Overview'!$A22,'Crawley Expenses'!$A$2:$A$108,0),6))
A23: Cost of carts and wagons total | G23: =IF(INDEX('Crawley Expenses'!$A$2:$F$108,MATCH('Crawley Overview'!$A23,'Crawley Expenses'!$A$2:$A$108,0),6)=0,"",INDEX('Crawley Expenses'!$A$2:$F$108,MATCH('Crawley Overview'!$A23,'Crawley Expenses'!$A$2:$A$108,0),6))
A24: Cost of dairy total | G24: =IF(INDEX('Crawley Expenses'!$A$2:$F$108,MATCH('Crawley Overview'!$A24,'Crawley Expenses'!$A$2:$A$108,0),6)=0,"",INDEX('Crawley Expenses'!$A$2:$F$108,MATCH('Crawley Overview'!$A24,'Crawley Expenses'!$A$2:$A$108,0),6))
A25: Cost of buildings total | G25: =IF(INDEX('Crawley Expenses'!$A$2:$F$108,MATCH('Crawley Overview'!$A25,'Crawley Expenses'!$A$2:$A$108,0),6)=0,"",INDEX('Crawley Expenses'!$A$2:$F$108,MATCH('Crawley Overview'!$A25,'Crawley Expenses'!$A$2:$A$108,0),6))
A26: Threshing total | G26: =IF(INDEX('Crawley Expenses'!$A$2:$F$108,MATCH('Crawley Overview'!$A26,'Crawley Expenses'!$A$2:$A$108,0),6)=0,"",INDEX('Crawley Expenses'!$A$2:$F$108,MATCH('Crawley Overview'!$A26,'Crawley Expenses'!$A$2:$A$108,0),6))
A27: Expenses of the harvest total | G27: =IF(INDEX('Crawley Expenses'!$A$2:$F$108,MATCH('Crawley Overview'!$A27,'Crawley Expenses'!$A$2:$A$108,0),6)=0,"",INDEX('Crawley Expenses'!$A$2:$F$108,MATCH('Crawley Overview'!$A27,'Crawley Expenses'!$A$2:$A$108,0),6))
A28: Steward's expenses total | G28: =IF(INDEX('Crawley Expenses'!$A$2:$F$108,MATCH('Crawley Overview'!$A28,'Crawley Expenses'!$A$2:$A$108,0),6)=0,"",INDEX('Crawley Expenses'!$A$2:$F$108,MATCH('Crawley Overview'!$A28,'Crawley Expenses'!$A$2:$A$108,0),6))
A29: Sum of the above | G29: =SUM(G21:G28)
A30: Total of all expenses | G30: ='Crawley Expenses'!F103 | H30: =G29-G30
A31: Total Demesne fixed investment | G31: ='Crawley Expenses'!F108
A33: Owed by the reeve | G33: ='Crawley Expenses'!F105
A34: From accounts
A36: Cash deliveries | G36: ='Crawley Expenses'!F106
A37: Total of all allowances and cash deliveries in accounts | B37: n/a
A39: Net amount owed | G39: =G33-G36
A40: Net amount owed in accounts | G40: ='Crawley Expenses'!F107 | H40: =G39-G40
A42: GRANGE ACCOUNT | B42: Net Production
A43: Grange | B43: qrs | G43: £ | I43: Note: Columns indexed are hardcoded, do not alter number of columns in issues of grange
A44: Net wheat | B44: =IF(INDEX('Issues of the Grange'!$A$2:$P$26,MATCH('Crawley Overview'!$A44,'Issues of the Grange'!$A$2:$A$26,0),10)=0,"",INDEX('Issues of the Grange'!$A$2:$P$26,MATCH('Crawley Overview'!$A44,'Issues of the Grange'!$A$2:$A$26,0),10)) | G44: =IF(INDEX('Issues of the Grange'!$A$2:$P$26,MATCH('Crawley Overview'!$A44,'Issues of the Grange'!$A$2:$A$26,0),13)=0,"",INDEX('Issues of the Grange'!$A$2:$P$26,MATCH('Crawley Overview'!$A44,'Issues of the Grange'!$A$2:$A$26,0),13))
A45: Net curall | B45: =IF(INDEX('Issues of the Grange'!$A$2:$P$26,MATCH('Crawley Overview'!$A45,'Issues of the Grange'!$A$2:$A$26,0),10)=0,"",INDEX('Issues of the Grange'!$A$2:$P$26,MATCH('Crawley Overview'!$A45,'Issues of the Grange'!$A$2:$A$26,0),10)) | G45: =IF(INDEX('Issues of the Grange'!$A$2:$P$26,MATCH('Crawley Overview'!$A45,'Issues of the Grange'!$A$2:$A$26,0),13)=0,"",INDEX('Issues of the Grange'!$A$2:$P$26,MATCH('Crawley Overview'!$A45,'Issues of the Grange'!$A$2:$A$26,0),13))
A46: Net Bere | B46: =IF(INDEX('Issues of the Grange'!$A$2:$P$26,MATCH('Crawley Overview'!$A46,'Issues of the Grange'!$A$2:$A$26,0),10)=0,"",INDEX('Issues of the Grange'!$A$2:$P$26,MATCH('Crawley Overview'!$A46,'Issues of the Grange'!$A$2:$A$26,0),10)) | G46: =IF(INDEX('Issues of the Grange'!$A$2:$P$26,MATCH('Crawley Overview'!$A46,'Issues of the Grange'!$A$2:$A$26,0),13)=0,"",INDEX('Issues of the Grange'!$A$2:$P$26,MATCH('Crawley Overview'!$A46,'Issues of the Grange'!$A$2:$A$26,0),13))
A47: Net barley | B47: =IF(INDEX('Issues of the Grange'!$A$2:$P$26,MATCH('Crawley Overview'!$A47,'Issues of the Grange'!$A$2:$A$26,0),10)=0,"",INDEX('Issues of the Grange'!$A$2:$P$26,MATCH('Crawley Overview'!$A47,'Issues of the Grange'!$A$2:$A$26,0),10)) | G47: =IF(INDEX('Issues of the Grange'!$A$2:$P$26,MATCH('Crawley Overview'!$A47,'Issues of the Grange'!$A$2:$A$26,0),13)=0,"",INDEX('Issues of the Grange'!$A$2:$P$26,MATCH('Crawley Overview'!$A47,'Issues of the Grange'!$A$2:$A$26,0),13))
...

Sheet Crawley Receipts
A1: CRAWLEY RECEIPTS
B2: £ | C2: s | D2: d | F2: Total in £ | G2: Error | H2: Notes
A4: Arrears
A5: Arrears total | B5: 7 | C5: 8 | D5: 8 | F5: =B5+C5/20+D5/240
A6: of which delivered to treasurer of Wolvesey | B6: 7 | C6: 8 | D6: 8 | F6: =B6+C6/20+D6/240
A8: Rents of assize
A9: Christmas | B9: 3 | C9: 1 | D9: 4 | F9: =B9+C9/20+D9/240
A10: Easter | B10: 3 | C10: 1 | D10: 4 | F10: =B10+C10/20+D10/240
A11: John the Baptist | B11: 3 | C11: 1 | D11: 4 | F11: =B11+C11/20+D11/240
A12: Michaelmas | B12: 4 | C12: 17 | D12: 7 | F12: =B12+C12/20+D12/240
A13: Total recorded in accounts | B13: 14 | C13: 1 | D13: 7 | F13: =B13+C13/20+D13/240
A14: Rents of assize total | B14: =SUM(B9:B12) | C14: =SUM(C9:C12) | D14: =SUM(D9:D12) | F14: =B14+C14/20+D14/240 | G14: =F14-F13
A16: Quittances
A17: 1 reeve for the year | C17: 5 | F17: =B17+C17/20+D17/240
A18: 6 ploughmen 1 smith for the year | C18: 18 | D18: 8 | F18: =B18+C18/20+D18/240
A19: 2 shepherds for the year | C19: 5 | D19: 4 | F19: =B19+C19/20+D19/240
A20: 8 workers | B20: 1 | C20: 1 | D20: 4 | F20: =B20+C20/20+D20/240
A21: 1 swineherd and 1 cowherd | C21: 5 | D21: 4 | F21: =B21+C21/20+D21/240
A22: Total recorded in accounts | B22: 2 | C22: 15 | D22: 8 | F22: =B22+C22/20+D22/240
A23: Quittances total | B23: =SUM(B17:B21) | C23: =SUM(C17:C21) | D23: =SUM(D17:D21) | F23: =B23+C23/20+D23/240 | G23: =F23-F22
A25: Defaults of rent
A26: in default of le stronge into demesne | C26: 2 | F26: =B26+C26/20+D26/240
A27: land of william | C27: 2 | D27: 8 | F27: =B27+C27/20+D27/240
A28: land of Alebrok | C28: 5 | F28: =B28+C28/20+D28/240
A29: land of Robert | C29: 2 | D29: 8 | F29: =B29+C29/20+D29/240
A30: land of Robert Coye | C30: 2 | D30: 8 | F30: =B30+C30/20+D30/240
A31: land of Roger le Pokyr | C31: 2 | D31: 8 | F31: =B31+C31/20+D31/240
A32: land of Richard Vaccar | C32: 2 | D32: 8 | F32: =B32+C32/20+D32/240
A33: Total recorded in accounts | B33: 1 | D33: 4 | F33: =B33+C33/20+D33/240
A34: Defaults of rent total | B34: =SUM(B26:B32) | C34: =SUM(C26:C32) | D34: =SUM(D26:D32) | F34: =B34+C34/20+D34/240 | G34: =F34-F33
A36: Total of rents remaining | B36: 10 | C36: 5 | D36: 7 | F36: =B36+C36/20+D36/240 | H36: not included in receipts
A38: Annual recognizances
A39: from Walter | D39: 6 | F39: =B39+C39/20+D39/240
A40: from Robert | D40: 6 | F40: =B40+C40/20+D40/240
A41: from Robert le Pottere | D41: 6 | F41: =B41+C41/20+D41/240
A42: from John | D42: 3 | F42: =B42+C42/20+D42/240
A43: Total recorded in accounts | C43: 1 | D43: 9 | F43: =B43+C43/20+D43/240
A44: Annual recognizances total | B44: =SUM(B39:B42) | C44: =SUM(C39:C42) | D44: =SUM(D39:D42) | F44: =B44+C44/20+D44/240 | G44: =F44-F43
A46: Issues of the manor
A47: panage of pigs | C47: 6 | D47: 2.5 | F47: =B47+C47/20+D47/240
...

Sheet Crawley Expenses
A1: CRAWLEY EXPENSES
B2: £ | C2: s | D2: d | F2: Total in £ | G2: Error | H2: Notes
A3: Cost of Ploughs
A4: in iron and steel bought for 4 ploughs | C4: 9 | F4: =B4+C4/20+D4/240
A5: in 2 ploughshares bought | C5: 1 | D5: 8 | F5: =B5+C5/20+D5/240
A6: in 1 coulter mended | D6: 2 | F6: =B6+C6/20+D6/240
A7: in 2 plough feet bought | D7: 7.5 | F7: =B7+C7/20+D7/240
A8: in 4 pairs of wheels bought | C8: 1 | D8: 4 | F8: =B8+C8/20+D8/240
A9: in 2 ploughs made anew and other mending | C9: 1 | D9: 3 | F9: =B9+C9/20+D9/240
A10: in fitting ploughs with iron tyres | D10: 2.5 | F10: =B10+C10/20+D10/240
A11: in shoeing 6 plough-horses | C11: 3 | D11: 11 | F11: =B11+C11/20+D11/240
A12: in boon-works of 9 ploughmen | D12: 9 | F12: =B12+C12/20+D12/240
A13: in 5 halters made from the horeses own hair | D13: 1.75 | F13: =B13+C13/20+D13/240
A14: in stipend of 2 ploughmen for the year | C14: 6 | F14: =B14+C14/20+D14/240
A15: in 5 oxen bought | B15: 2 | C15: 6 | F15: =B15+C15/20+D15/240
A16: Total recorded in accounts | B16: 3 | C16: 11 | D16: 0.25 | F16: =B16+C16/20+D16/240
A17: Cost of ploughs total | B17: =SUM(B4:B15) | C17: =SUM(C4:C15) | D17: =SUM(D4:D15) | F17: =B17+C17/20+D17/240 | G17: =F17-F16
A18: Total capital expenses | B18: =SUM(B15,B13,B4:B11) | C18: =SUM(C15,C13,C4:C11) | D18: =SUM(D15,D13,D4:D11) | F18: =B18+C18/20+D18/240
A20: Purchase of Corn
A21: in 6 bus of wheat bought for sowing | C21: 4 | D21: 6 | F21: =B21+C21/20+D21/240
A22: in 3 qrs 6 bus of barley bought | C22: 12 | D22: 4 | F22: =B22+C22/20+D22/240
A23: Total recorded in accounts | C23: 16 | D23: 10 | F23: =B23+C23/20+D23/240
A24: Purchase of corn total | B24: =SUM(B21:B22) | C24: =SUM(C21:C22) | D24: =SUM(D21:D22) | F24: =B24+C24/20+D24/240 | G24: =F24-F23
A26: Cost of Carts and Wagons
A27: in 1 pair of wheels bought | C27: 3 | D27: 4 | F27: =B27+C27/20+D27/240
A28: in 1 old binding renewed and fitted | C28: 3 | F28: =B28+C28/20+D28/240
A29: in fitting the cart with axles | D29: 8 | F29: =B29+C29/20+D29/240
A30: in clouts nails and grease bought for the same | C30: 1 | F30: =B30+C30/20+D30/240
A31: in 1 pair of traces bought | D31: 5.5 | F31: =B31+C31/20+D31/240
A32: in 1 rope bought | D32: 2 | F32: =B32+C32/20+D32/240
A33: in shoeing 2 cart horses | C33: 2 | D33: 6 | F33: =B33+C33/20+D33/240
A34: in white leather bought | D34: 4 | F34: =B34+C34/20+D34/240
A35: in mending old harnesses | D35: 2 | F35: =B35+C35/20+D35/240
A36: in 1 collar bought | D36: 7 | F36: =B36+C36/20+D36/240
A37: in stipend of 1 carter | C37: 3 | F37: =B37+C37/20+D37/240
A38: in mending the cart at various times | D38: 2 | F38: =B38+C38/20+D38/240
A39: in 1 new cart-body bought | C39: 1 | F39: =B39+C39/20+D39/240
A40: Total recorded in accounts | C40: 16 | D40: 4.5 | F40: =B40+C40/20+D40/240
A41: Cost of carts and wagons total | B41: =SUM(B27:B39) | C41: =SUM(C27:C39) | D41: =SUM(D27:D39) | F41: =B41+C41/20+D41/240 | G41: =F41-F40
A42: Total capital expenses | B42: =SUM(B38:B39,B27:B36) | C42: =SUM(C38:C39,C27:C36) | D42: =SUM(D38:D39,D27:D36) | F42: =B42+C42/20+D42/240
...

Sheet Issues of the Grange
B1: The issue of the grange account gives the total "yield" at the top of each heading in curly brackets, measurements used: fold, qrs, bus
B2: In "Issues of the grange" (p.xx) | G2: In "Sale of Corn" (p.x) | P2: Value of Total Production
A3: Gross output | B3: Quantity | D3: Additional bought-in | F3: Quantity | G3: Quantity noted as sold | J3: Difference Produced vs. Sold | K3: Price 1 | L3: Quantity 1 | M3: Price 2 | N3: Quantity 2 | O3: Unit price | P3: Value
B4: qrs | C4: bus | D4: qrs | E4: bus | F4: qrs | G4: qrs | H4: bus | I4: qrs | K4: £ | L4: qrs | M4: £ | N4: qrs | O4: £ per qr | P4: £
A5: Wheat | B5: 58 | C5: 6 | E5: 6 | F5: =B5+D5+C5/8+E5/8 | G5: 40 | I5: =G5+H5/8 | J5: =F5-I5 | K5: ='Crawley Receipts'!F82 | L5: 40 | O5: =IFERROR((K5+M5)/(L5+N5),0) | P5: =O5*F5
A6: Curall | B6: 12 | C6: 0.5 | F6: =B6+D6+C6/8+E6/8 | G6: 12 | H6: 0.5 | I6: =G6+H6/8 | J6: =F6-I6 | K6: ='Crawley Receipts'!F83 | L6: =I6 | O6: =IFERROR((K6+M6)/(L6+N6),0) | P6: =O6*F6
A7: Bere | B7: 4 | C7: 2 | F7: =B7+D7+C7/8+E7/8 | I7: =G7+H7/8 | J7: =F7-I7 | O7: =IFERROR((K7+M7)/(L7+N7),0) | P7: =O7*F7
A8: Barley | B8: 91 | C8: 5 | D8: 3 | E8: 6 | F8: =B8+D8+C8/8+E8/8 | G8: 21.5 | H8: 6 | I8: =G8+H8/8 | J8: =F8-I8 | K8: ='Crawley Receipts'!F84 | L8: =21+6/8 | M8: ='Crawley Receipts'!F88 | N8: 0.5 | O8: =IFERROR((K8+M8)/(L8+N8),0) | P8: =O8*F8
A9: Oats | B9: 170 | F9: =B9+D9+C9/8+E9/8 | G9: 43 | I9: =G9+H9/8 | J9: =F9-I9 | K9: ='Crawley Receipts'!F85 | L9: 43 | O9: =IFERROR((K9+M9)/(L9+N9),0) | P9: =O9*F9
A10: Peas | B10: 6.5 | F10: =B10+D10+C10/8+E10/8 | G10: 3 | H10: 1 | I10: =G10+H10/8 | J10: =F10-I10 | K10: ='Crawley Receipts'!F86 | L10: =I10 | O10: =IFERROR((K10+M10)/(L10+N10),0) | P10: =O10*F10
A11: Vetches | B11: 7 | C11: 6 | F11: =B11+D11+C11/8+E11/8 | G11: 4.5 | I11: =G11+H11/8 | J11: =F11-I11 | K11: ='Crawley Receipts'!F87 | L11: 4.5 | O11: =IFERROR((K11+M11)/(L11+N11),0) | P11: =O11*F11
A13: Total Production | F13: =SUM(F5:F11) | P13: =SUM(P5:P11) | Q13: Production value is significantly more, as much less was sold than what was produced
A14: Sales of corn (as recorded in accounts) | F14: =SUM(I5:I11) | P14: =SUM(K5:K11,M5:M11)
A17: Net output | B17: Gross output | C17: Seed | F17: tithe | G17: to manorial servants & livestock | J17: Output net of tithe & seed & liveries to manorial servants | K17: in stock from last year | L17: Price | M17: Value of net output | N17: Value of sales (in "Sale of Corn")
B18: qrs | C18: qrs | D18: bus | E18: qrs | F18: qrs | G18: qrs | H18: bus | I18: qrs | J18: qrs | K18: qrs | L18: £ per qr | M18: £ | N18: £
A19: Net wheat | B19: =F5 | C19: 16 | D19: 5 | E19: =C19+D19/8 | G19: 2 | H19: 7 | I19: =G19+H19/8 | J19: =B19-(E19+F19+I19) | L19: =O5 | M19: =L19*J19 | N19: =O5*I5
A20: Net curall | B20: =F6 | E20: =C20+D20/8 | I20: =G20+H20/8 | J20: =B20-(E20+F20+I20) | L20: =O6 | M20: =L20*J20 | N20: =O6*I6
A21: Net Bere | B21: =F7 | E21: =C21+D21/8 | G21: 4 | H21: 2 | I21: =G21+H21/8 | J21: =B21-(E21+F21+I21) | L21: =O7 | M21: =L21*J21 | N21: =O7*I7
A22: Net barley | B22: =F8 | C22: 43 | D22: 2 | E22: =C22+D22/8 | G22: =19.5+0.5+2+3+2+0.5 | H22: =6.5+6+7 | I22: =G22+H22/8 | J22: =B22-(E22+F22+I22) | L22: =O8 | M22: =L22*J22 | N22: =O8*I8
A23: Net oats | B23: =F9 | C23: 83 | D23: 3 | E23: =C23+D23/8 | G23: =6+4+12+20 | H23: =6+2+5 | I23: =G23+H23/8 | J23: =B23-(E23+F23+I23) | L23: =O9 | M23: =L23*J23 | N23: =O9*I9
A24: Net peas | B24: =F10 | C24: 3 | E24: =C24+D24/8 | H24: 3 | I24: =G24+H24/8 | J24: =B24-(E24+F24+I24) | L24: =O10 | M24: =L24*J24 | N24: =O10*I10
A25: Net vetches | B25: =F11 | C25: 3 | D25: 2 | E25: =C25+D25/8 | I25: =G25+H25/8 | J25: =B25-(E25+F25+I25) | L25: =O11 | M25: =L25*J25 | N25: =O11*I11
A26: Total | B26: =SUM(B19:B25) | E26: =SUM(E19:E25) | J26: =SUM(J19:J25) | M26: =SUM(M19:M25) | N26: =SUM(N19:N25)

Sheet Stock
A1: EAST KNOYLE STOCK ACCOUNT
A3: Livestock | B3: Inherited stock | C3: Bought | D3: Produced | E3: strays | F3: herbage | G3: sold | H3: in murrain | I3: accounted for elsewhere | J3: End-period stock | K3: cross-check | L3: price 1 | M3: units 1 | N3: price 2 | O3: units 2 | P3: Weight (weys) | Q3: Unit price (£) | R3: Value of production (£) at sales prices | S3: Sales in (£) | T3: Details
A4: Cart-horses | B4: 2 | J4: 2 | K4: =B4+C4+D4+E4-F4-G4-H4-I4 | Q4: =IFERROR((L4+N4)/(M4+O4),"") | R4: =IFERROR(D4*Q4,"") | S4: =IFERROR(Q4*G4,"")
A5: Mares | K5: =B5+C5+D5+E5-F5-G5-H5-I5 | Q5: =IFERROR((L5+N5)/(M5+O5),"") | R5: =IFERROR(D5*Q5,"") | S5: =IFERROR(Q5*G5,"")
A6: Plough horses | B6: 5 | C6: 1 | D6: 1 | H6: 1 | J6: 6 | K6: =B6+C6+D6+E6-F6-G6-H6-I6 | Q6: =IFERROR((L6+N6)/(M6+O6),"") | R6: =IFERROR(D6*Q6,"") | S6: =IFERROR(Q6*G6,"")
A7: Colts (2 years) | K7: =B7+C7+D7+E7-F7-G7-H7-I7 | Q7: =IFERROR((L7+N7)/(M7+O7),"") | R7: =IFERROR(D7*Q7,"") | S7: =IFERROR(Q7*G7,"")
A8: Colts (2 years) | K8: =B8+C8+D8+E8-F8-G8-H8-I8 | Q8: =IFERROR((L8+N8)/(M8+O8),"") | R8: =IFERROR(D8*Q8,"") | S8: =IFERROR(Q8*G8,"")
A9: Colts (1 year) | K9: =B9+C9+D9+E9-F9-G9-H9-I9 | Q9: =IFERROR((L9+N9)/(M9+O9),"") | R9: =IFERROR(D9*Q9,"") | S9: =IFERROR(Q9*G9,"")
A10: Foals | K10: =B10+C10+D10+E10-F10-G10-H10-I10 | Q10: =IFERROR((L10+N10)/(M10+O10),"") | R10: =IFERROR(D10*Q10,"") | S10: =IFERROR(Q10*G10,"")
A11: Oxen | B11: 30 | C11: 5 | D11: 1 | E11: 1 | H11: 2 | J11: 35 | K11: =B11+C11+D11+E11-F11-G11-H11-I11 | Q11: =IFERROR((L11+N11)/(M11+O11),"") | R11: =IFERROR(D11*Q11,"") | S11: =IFERROR(Q11*G11,"")
A12: Bulls | B12: 1 | J12: 1 | K12: =B12+C12+D12+E12-F12-G12-H12-I12 | Q12: =IFERROR((L12+N12)/(M12+O12),"") | R12: =IFERROR(D12*Q12,"") | S12: =IFERROR(Q12*G12,"")
A13: Cows | B13: 17 | D13: 2 | J13: 19 | K13: =B13+C13+D13+E13-F13-G13-H13-I13 | Q13: =IFERROR((L13+N13)/(M13+O13),"") | R13: =IFERROR(D13*Q13,"") | S13: =IFERROR(Q13*G13,"")
A14: Steers | B14: 4 | H14: 1 | I14: 3 | J14: 0 | K14: =B14+C14+D14+E14-F14-G14-H14-I14 | Q14: =IFERROR((L14+N14)/(M14+O14),"") | R14: =IFERROR(D14*Q14,"") | S14: =IFERROR(Q14*G14,"")
A15: Bullocks | B15: 5 | H15: 1 | J15: 4 | K15: =B15+C15+D15+E15-F15-G15-H15-I15 | Q15: =IFERROR((L15+N15)/(M15+O15),"") | R15: =IFERROR(D15*Q15,"") | S15: =IFERROR(Q15*G15,"")
A16: Yearlings | B16: 6 | H16: 1 | J16: 5 | K16: =B16+C16+D16+E16-F16-G16-H16-I16 | Q16: =IFERROR((L16+N16)/(M16+O16),"") | R16: =IFERROR(D16*Q16,"") | S16: =IFERROR(Q16*G16,"")
A17: Calves | D17: 13 | G17: 5 | H17: 1 | I17: 1 | J17: 6 | K17: =B17+C17+D17+E17-F17-G17-H17-I17 | L17: ='Crawley Receipts'!F54 | M17: 5 | Q17: =IFERROR((L17+N17)/(M17+O17),"") | R17: =IFERROR(D17*Q17,"") | S17: =IFERROR(Q17*G17,"")
A18: Wethers | B18: 383 | D18: 132 | G18: 47 | H18: 35 | J18: 433 | K18: =B18+C18+D18+E18-F18-G18-H18-I18 | L18: ='Crawley Receipts'!F55 | M18: 47 | Q18: =IFERROR((L18+N18)/(M18+O18),"") | R18: =IFERROR(D18*Q18,"") | S18: =IFERROR(Q18*G18,"")
A19: Rams | K19: =B19+C19+D19+E19-F19-G19-H19-I19 | Q19: =IFERROR((L19+N19)/(M19+O19),"") | R19: =IFERROR(D19*Q19,"") | S19: =IFERROR(Q19*G19,"")
A20: Ewes | B20: 536 | D20: 131 | G20: 55 | H20: 37 | J20: 575 | K20: =B20+C20+D20+E20-F20-G20-H20-I20 | L20: ='Crawley Receipts'!F56 | M20: 55 | Q20: =IFERROR((L20+N20)/(M20+O20),"") | R20: =IFERROR(D20*Q20,"") | S20: =IFERROR(Q20*G20,"")
A21: Hoggs | B21: 286 | H21: 23 | I21: 263 | J21: 0 | K21: =B21+C21+D21+E21-F21-G21-H21-I21 | Q21: =IFERROR((L21+N21)/(M21+O21),"") | R21: =IFERROR(D21*Q21,"") | S21: =IFERROR(Q21*G21,"")
A22: Lambs | D22: 392 | H22: 88 | I22: 36 | J22: 268 | K22: =B22+C22+D22+E22-F22-G22-H22-I22 | Q22: =IFERROR((L22+N22)/(M22+O22),"") | R22: =IFERROR(D22*Q22,"") | S22: =IFERROR(Q22*G22,"") | T22: Accounted for elsewhere is tithe
A23: Boars | B23: 1 | J23: 1 | K23: =B23+C23+D23+E23-F23-G23-H23-I23 | Q23: =IFERROR((L23+N23)/(M23+O23),"") | R23: =IFERROR(D23*Q23,"") | S23: =IFERROR(Q23*G23,"")
A24: Sows | K24: =B24+C24+D24+E24-F24-G24-H24-I24 | Q24: =IFERROR((L24+N24)/(M24+O24),"") | R24: =IFERROR(D24*Q24,"") | S24: =IFERROR(Q24*G24,"")
A25: Pigs | B25: 27 | D25: 29 | G25: 26 | J25: 30 | K25: =B25+C25+D25+E25-F25-G25-H25-I25 | L25: ='Crawley Receipts'!F57 | M25: 26 | Q25: =IFERROR((L25+N25)/(M25+O25),"") | R25: =IFERROR(D25*Q25,"") | S25: =IFERROR(Q25*G25,"")
A26: Hoggets | B26: 29 | I26: 29 | J26: 0 | K26: =B26+C26+D26+E26-F26-G26-H26-I26 | Q26: =IFERROR((L26+N26)/(M26+O26),"") | R26: =IFERROR(D26*Q26,"") | S26: =IFERROR(Q26*G26,"")
A27: Piglets | D27: 32 | E27: 2 | H27: 8 | I27: 3 | J27: 23 | K27: =B27+C27+D27+E27-F27-G27-H27-I27 | Q27: =IFERROR((L27+N27)/(M27+O27),"") | R27: =IFERROR(D27*Q27,"") | S27: =IFERROR(Q27*G27,"") | T27: Accounted for elsewhere is tithe
A28: Swans | K28: =B28+C28+D28+E28-F28-G28-H28-I28 | Q28: =IFERROR((L28+N28)/(M28+O28),"") | R28: =IFERROR(D28*Q28,"") | S28: =IFERROR(Q28*G28,"")
A29: Peacocks | K29: =B29+C29+D29+E29-F29-G29-H29-I29 | Q29: =IFERROR((L29+N29)/(M29+O29),"") | R29: =IFERROR(D29*Q29,"") | S29: =IFERROR(Q29*G29,"")
A30: Total | S30: =SUM(S4:S29)
K31: =B31+C31+D31+E31-F31-G31-H31-I31 | Q31: =IFERROR((L31+N31)/(M31+O31),"") | R31: =IFERROR(D31*Q31,"") | S31: =IFERROR(Q31*G31,"")
K32: =B32+C32+D32+E32-F32-G32-H32-I32 | Q32: =IFERROR((L32+N32)/(M32+O32),"") | R32: =IFERROR(D32*Q32,"") | S32: =IFERROR(Q32*G32,"")
A33: Wool | K33: =B33+C33+D33+E33-F33-G33-H33-I33 | Q33: =IFERROR((L33+N33)/(M33+O33),"") | R33: =IFERROR(D33*Q33,"") | S33: =IFERROR(Q33*G33,"")
A34: Fleeces | K34: =B34+C34+D34+E34-F34-G34-H34-I34 | Q34: =IFERROR((L34+N34)/(M34+O34),"") | R34: =IFERROR(D34*Q34,"") | S34: =IFERROR(Q34*G34,"")
A35: Coarse wool | D35: 1035 | G35: 929 | I35: 106 | J35: 0 | K35: =B35+C35+D35+E35-F35-G35-H35-I35 | L35: 0 | P35: =6.5+3*0.04 | Q35: 0.02 | R35: =IFERROR(D35*Q35,"") | S35: =IFERROR(Q35*G35,"") | T35: unit price from overview sheet (UnitPricesStocks_averages)
A36: Lamb's wool | D36: 283 | G36: 283 | J36: 0 | K36: =B36+C36+D36+E36-F36-G36-H36-I36 | L36: 0 | P36: =15*0.04 | Q36: 0.01 | R36: =IFERROR(D36*Q36,"") | S36: =IFERROR(Q36*G36,"") | T36: unit price from overview sheet (UnitPricesStocks_averages)
A37: Wool locks | D37: =5*0.04 | G37: =5*0.04 | K37: =B37+C37+D37+E37-F37-G37-H37-I37 | L37: ='Crawley Receipts'!F76 | M37: =5*0.04 | P37: =5*0.04 | Q37: =IFERROR((L37+N37)/(M37+O37),"") | R37: =IFERROR(D37*Q37,"") | S37: =IFERROR(Q37*G37,"")
A38: Wool sold at shearing | K38: =B38+C38+D38+E38-F38-G38-H38-I38 | Q38: =IFERROR((L38+N38)/(M38+O38),"") | R38: =IFERROR(D38*Q38,"") | S38: =IFERROR(Q38*G38,"")
A39: Total | K39: =B39+C39+D39+E39-F39-G39-H39-I39 | Q39: =IFERROR((L39+N39)/(M39+O39),"") | R39: =IFERROR(D39*Q39,"") | S39: =SUM(S35:S38)
K40: =B40+C40+D40+E40-F40-G40-H40-I40 | Q40: =IFERROR((L40+N40)/(M40+O40),"") | R40: =IFERROR(D40*Q40,"") | S40: =IFERROR(Q40*G40,"")
K41: =B41+C41+D41+E41-F41-G41-H41-I41 | Q41: =IFERROR((L41+N41)/(M41+O41),"") | R41: =IFERROR(D41*Q41,"") | S41: =IFERROR(Q41*G41,"")
...

Sheet Assumptions
A1: ASSUMPTIONS
B3: Weights | C3: Value (in lbs) | D3: Value (in cloves) | E3: Value (in weys) | F3: Value (in stone)
B4: Lbs | C4: 1 | D4: =C4/C5 | E4: =C4/C6 | F4: =C4/C7
B5: Cloves | C5: 7 | D5: 1 | E5: =C5/C6 | F5: =C7/C5
B6: Wey | C6: 175 | D6: =C6/C5 | E6: =C6/C6 | F6: =C7/C6
B7: Stone | C7: =175/14 | D7: =C5/C7 | E7: =C7/C6 | F7: 1
