Workbook

Sheet Culham Overview - Completed
A1: CULHAM OVERVIEW - COMPLETED | B1: Total in £ | C1: Error | D1: Note
A2: CASH ACCOUNT
A3: RECEIPTS
A4: Arrears total
A5: Rents of assize total | B5: 4.1
A6: Quittances total | B6: 0.135
A7: Defaults of rent total
A8: Defaults of rent through the pestilence total
A9: Cotlands defaults total
A10: Cotlands total
A11: Total of quittances and defaults of rent total
A12: Total of rents remaining clear total
A13: Farms total
A14: Annual recognizances total | B14: 0.03
A15: Issues of the Manor total | B15: 10.75
A16: Issues of the tenements in the lord's hands total
A17: Sale of labour services total
A18: Sale of corn total | B18: 6.89
A19: Entry and marriage fines total | B19: 1.32
A20: Pleas & perquisites total
A21: Forfeited chattels total
A22: Farm of the demesne land total
A23: Total of all receipts (calculated here) | B23: =SUM(B5:B22)
A24: Total of all receipts (calculated here) incl arrears | B24: =SUM(B4:B22)
A25: Total recorded in the accounts excl. arrears | B25: 24.95 | C25: =B23-B25
A26: Total recorded in the accounts incl. arrears | B26: =B25+B4
A29: EXPENSES
A30: Cost of ploughs total
A31: Purchase of corn total
A32: Cost of carts and wagons total
A33: Cost of dairy total
A34: Purchase of stock total
A35: Sheepcote total
A36: Cost of buildings total | B36: 0.15416667
A37: Threshing total | B37: 0.27
A38: Barley expenses
A39: Expenses of the harvest total
A40: Necessary expenses
A41: Wages of the bailiff
A42: Steward's expenses total
...

Sheet Prices
A1: Meat & Dairy Prices
C2: 1301 | D2: 1302 | E2: Average
A3: Beef | B3: £ per lb | C3: 0.0033351854 | D3: 0.0032608538 | E3: =AVERAGE(C3:D3)
A4: Mutton | B4: £ per lb | C4: 0.0036593977 | D4: 0.0037125513 | E4: =AVERAGE(C4:D4)
A5: Pork | B5: £ per lb | C5: 0.0038431326 | D5: 0.0037574803 | E5: =AVERAGE(C5:D5)
A6: Cheese | B6: £ per lb | C6: 0.0055768754 | D6: 0.0056654898 | E6: =AVERAGE(C6:D6)
A7: Butter | B7: £ per lb | C7: 0.0036626221 | D7: 0.0035935077 | E7: =AVERAGE(C7:D7)
A8: Milk | B8: £ per gallon | C8: 0.0055768754 | D8: 0.0056654898 | E8: =AVERAGE(C8:D8)

Sheet Labour Rents

Sheet Overview
A1: CULHAM | B1: Total in £ | C1: Error | D1: Note
A2: CASH ACCOUNT
A3: RECEIPTS
A4: Arrears total
A5: Rents of assize total
A6: Quittances total
A7: Defaults of rent total
A8: Defaults of rent through the pestilence total
A9: Cotlands defaults total
A10: Cotlands total
A11: Total of quittances and defaults of rent total
A12: Total of rents remaining clear total
A13: Farms total
... A22: Farm of the demesne land total
A23: Total of all receipts (calculated here) | B23: =Receipts!F103
A24: Total of all receipts (calculated here) incl arrears | B24: =Receipts!F104
A25: Total recorded in the accounts excl. arrears | B25: =Receipts!F101 | C25: =B25-B23
A26: Total recorded in the accounts incl. arrears
A29: EXPENSES
A30: Cost of ploughs total
A31: Purchase of corn total
A32: Cost of carts and wagons total
A33: Cost of dairy total
A34: Purchase of stock total
A35: Sheepcote total
A36: Cost of buildings total
A37: Threshing total
A38: Barley expenses
A39: Expenses of the harvest total
... A43: Annual fees
A44: Total of all expenses per account | B44: =Expenses!F63
A45: Total of all expenses (calculated here) | B45: =Expenses!F64
A46: Total fixed investment | B46: =Expenses!F65
A47: Total Demesne fixed investment | B47: =Expenses!F66
A49: Owed by the reeve
A50: From accounts
A52: Allowances
A53: Cash deliveries
A54: Sum of the above
A55: Total of all allowances and cash deliveries in accounts
...

Sheet Receipts
A1: CULHAM RECEIPTS
A2: Heading | B2: £ | C2: s | D2: d | F2: Total in £ | G2: Error | H2: Notes
A3: Rents of assize | B3: 2 | C3: 1 | D3: 0 | F3: 2.05 | H3: James de North', bailiff, and William Kepe, reeve, render account for £2 1 shilling.5pence for all rents of assize at Easter (22 April).
A4: Rents of assize | B4: 2 | C4: 1 | D4: 0 | F4: 2.05 | H4: £2 1 shilling .5pence at Michaelmas (29 September).
A5: Rents of assize | B5: 4 | C5: 2 | D5: 1 | F5: 4.1 | H5: Total, £4 2 shilling 1pence
A6: Rents of assize | F6: 4.1 | G6: 0 | H6: Total
A8: Increment | B8: 0 | C8: 0 | D8: 0 | F8: 0 | H8: Nothing this year from increment of rent.
A9: Increment | F9: 0 | G9: 0 | H9: Total
A11: Quittances | B11: 0 | C11: 1 | D11: 0 | F11: 0.05 | H11: In quittance of 1 reeve for the year 1 shilling.
A12: Quittances | B12: 0 | C12: 0 | D12: 6 | F12: 0.03 | H12: 1 carter for the year 6pence.
A13: Quittances | B13: 0 | C13: 0 | D13: 6 | F13: 0.03 | H13: 1 shepherd for the year 6pence.
A14: Quittances | B14: 0 | C14: 0 | D14: 6 | F14: =B14+C14/20+D14/240 | H14: 1 hayward for the year 6pence
A15: Quittances | B15: 0 | C15: 2 | D15: 6 | F15: =B15+C15/20+D15/240 | H15: Total, 2 shilling 6pence
A16: Quittances | F16: =SUM(F11:F14) | G16: =F16-F15 | H16: Total
A18: Total of rents remaining | B18: 3 | C18: 19 | D18: 7 | F18: 3.98 | H18: Total of rents remaining, £3 19 shilling 7pence
A19: Total of rents remaining | F19: 3.98 | G19: =F19-F18 | H19: Total
A21: Annual gifts | B21: 0 | C21: 9 | D21: 0.5 | F21: 0.45 | H21: The same render account for 9 shilling 0.5pence from annual gifts at Easter.
A22: Annual gifts | B22: 0 | C22: 9 | D22: 0.5 | F22: 0.45 | H22: 9 shilling 0.5pence at Michaelmas.
A23: Annual gifts | B23: 0 | C23: 18 | D23: 1 | F23: 0.9 | H23: Total, 18 shilling 1pence
A24: Annual gifts | F24: 0.9 | G24: 0 | H24: Total
A26: Annual recognizance | B26: 0 | C26: 0 | D26: 6 | F26: 0.03 | H26: The same render account for 6pence from the annual recognizance of William Piscator' of Culham so that he may remain outside the manor and pay suit to the tithing.
A27: Annual recognizance | B27: 0 | C27: 0 | D27: 6 | F27: 0.03 | H27: Total, 6pence
A28: Annual recognizance | F28: 0.03 | G28: 0 | H28: Total
A30: Issues of the manor | B30: 0 | C30: 3 | D30: 0.5 | F30: 0.15 | H30: The same render account for 3 shilling 0.5pence from common pannage of pigs, that is, from 27 pigs, 19 piglets, at 1pence a pig over a year old, and .5pence a piglet.
A31: Issues of the manor | B31: 0 | C31: 9 | D31: 6 | F31: 0.48 | H31: 9 shilling 6pence from pannage of Kylhamfryth', from 42 pigs and 30 piglets agisted in the wood of Kylhamfryth', at 2pence a pig, 1pence a piglet.
A32: Issues of the manor | B32: 1 | C32: 0 | D32: 8 | F32: 1.03 | H32: £1 8pence from 3 oxen sold, at 7 shilling each for 2, and 6 shilling 8pence for 1.
A33: Issues of the manor | B33: 0 | C33: 16 | D33: 0 | F33: 0.8 | H33: 16 shilling from 2 cows sold together.
A34: Issues of the manor | B34: 0 | C34: 16 | D34: 8 | F34: 0.83 | H34: 16 shilling 8pence from 14 calves sold together.
A35: Issues of the manor | B35: 1 | C35: 0 | D35: 6 | F35: 1.02 | H35: £1 6pence from 20 old kebb wethers sold at Martinmas.
A36: Issues of the manor | B36: 0 | C36: 1 | D36: 7 | F36: 0.08 | H36: 1 shilling 7pence from the hide sold of 1 cow in murrain.
A37: Issues of the manor | B37: 0 | C37: 2 | D37: 3 | F37: 0.11 | H37: 2 shilling 3pence from the hides sold of 3 bullocks and 3 yearlings in murrain.
A38: Issues of the manor | B38: 0 | C38: 0 | D38: 1 | F38: 0 | H38: 1pence from the hide sold of 1 calf in murrain.
A39: Issues of the manor | B39: 0 | C39: 1 | D39: 5.5 | F39: 0.07 | H39: 1 shilling 5.5pence from the skins of 5 wethers in murrain before shearing.
A40: Issues of the manor | B40: 0 | C40: 0 | D40: 9 | F40: 0.04 | H40: 9pence from the skins sold of 6 wethers in murrain after shearing.
A41: Issues of the manor | B41: 0 | C41: 3 | D41: 11 | F41: 0.2 | H41: 3 shilling 11pence from 12 cloves of winter cheese sold.
... A50: Issues of the manor | B50: 10 | C50: 17 | D50: 0 | F50: 10.85 | H50: Total, £10 17 shilling
A51: Issues of the manor | F51: 10.75 | G51: -0.1 | H51: Total
A53: Sale of corn | B53: 1 | C53: 7 | D53: 7.5 | F53: 1.38 | H53: The same render account for £1 7 shilling 7.5pence from 6 quarters 3 bushels of wheat sold, at 4 shilling 4pence a qr.
A54: Sale of corn | B54: 3 | C54: 10 | D54: 11.25 | F54: 3.55 | H54: £3 10 shilling 11.25pence from 28 quarters 3 bushels of mancorn sold, at 2 shilling 6pence a qr.
A55: Sale of corn | B55: 0 | C55: 0 | D55: 3.75 | F55: 0.02 | H55: 3.75pence from 1 bushels sold at the audit.
...

Sheet Expenses
A1: CULHAM EXPENSES
A2: Heading | B2: £ | C2: s | D2: d | F2: Total in £ | G2: Error | H2: Notes | J2: Fixed investment | K2: Demesne fixed investment
A3: Expenses for ploughs | B3: 0 | C3: 7 | D3: 5 | F3: 0.37 | H3: In steel for ploughs 7 shilling 5pence. | J3: =F3 | K3: =J3
A4: Expenses for ploughs | B4: 0 | C4: 3 | D4: 0 | F4: 0.15 | H4: stipend of the smith repairing ironwork 3 shilling. | J4: =F4 | K4: =J4
A5: Expenses for ploughs | B5: 0 | C5: 9 | D5: 8 | F5: 0.48 | H5: shoeing 7 horses for the year 9 shilling 8pence. | J5: =F5 | K5: =J5
A6: Expenses for ploughs | B6: 0 | C6: 1 | D6: 5 | F6: 0.07 | H6: 2 ploughshares bought 1 shilling 5pence. | J6: =F6 | K6: =J6
A7: Expenses for ploughs | B7: 0 | C7: 1 | D7: 0 | F7: 0.05 | H7: 4 plough-irons bought 1 shilling. | J7: =F7 | K7: =J7
A8: Expenses for ploughs | B8: 0 | C8: 0 | D8: 6 | F8: 0.03 | H8: 2 pairs of wheels bought 6pence. | J8: =F8 | K8: =J8
A9: Expenses for ploughs | B9: 0 | C9: 0 | D9: 2.5 | F9: 0.01 | H9: 7 halters and 1 rope made from hair 2.5pence. | J9: =F9 | K9: =J9
A10: Expenses for ploughs | B10: 0 | C10: 4 | D10: 6 | F10: 0.23 | H10: stipend of 1 drover for the year 4 shilling 6pence.
A11: Expenses for ploughs | B11: 0 | C11: 0 | D11: 9 | F11: =B11+C11/20+D11/240 | H11: 1 sack bought 9pence | J11: =F11 | K11: =J11
A12: Expenses for ploughs | B12: 1 | C12: 8 | D12: 5.5 | F12: =B12+C12/20+D12/240 | H12: Total, £1 8 shilling 5.5pence
A13: Expenses for ploughs | F13: =SUM(F3:F11) | G13: =F13-F12 | H13: Total
A15: Carts | B15: 0 | C15: 2 | D15: 2 | F15: 0.11 | H15: in 1 pair of wheels bought for the cart 2 shilling 2pence. | J15: =F15 | K15: =J15
A16: Carts | B16: 0 | C16: 0 | D16: 10.5 | F16: 0.04 | H16: clouts with nails bought 10.5pence, and so much because it was at Farnham in order to collect timber and talwood at the water (quesivit taluerud' ad aq'). | J16: =F16 | K16: =J16
A17: Carts | B17: 0 | C17: 0 | D17: 5 | F17: 0.02 | H17: grease for the cart 5pence. | J17: =F17 | K17: =J17
A18: Carts | B18: 0 | C18: 0 | D18: 3 | F18: 0.01 | H18: fitting the cart with axles 3pence. | J18: =F18 | K18: =J18
A19: Carts | B19: 0 | C19: 0 | D19: 4.5 | F19: 0.02 | H19: 1 pair of cart-shafts made from their own timber 4.5pence. | J19: =F19 | K19: =J19
A20: Carts | B20: 0 | C20: 0 | D20: 6 | F20: =B20+C20/20+D20/240 | H20: 1 pair of saddle-pads bought 6pence | J20: =F20 | K20: =J20
A21: Carts | B21: 0 | C21: 4 | D21: 7 | F21: =B21+C21/20+D21/240 | H21: Total, 4 shilling 7pence
A22: Carts | F22: =SUM(F15:F20) | G22: =F22-F21 | H22: Total
A24: Cost of buildings | B24: 0 | C24: 1 | D24: 4 | F24: 0.07 | H24: In roofing the byre at various times 1 shilling 4pence. | J24: =F24 | K24: =J24
A25: Cost of buildings | B25: 0 | C25: 0 | D25: 7 | F25: 0.03 | H25: roofing the barn in places 7pence. | J25: =F25 | K25: =J25
A26: Cost of buildings | B26: 0 | C26: 0 | D26: 9.5 | F26: 0.04 | H26: mending the walls of the byre at various times 9.5pence. | J26: =F26 | K26: =J26
A27: Cost of buildings | B27: 0 | C27: 0 | D27: 2 | F27: 0.01 | H27: mending 1 barrow 2pence. | J27: =F27 | K27: =J27
A28: Cost of buildings | D28: 1 | F28: =B28+C28/20+D28/240 | H28: 1 shovel bought 1pence | J28: =F28 | K28: =J28
A29: Cost of buildings | B29: 0 | C29: 2 | D29: 11.5 | F29: =B29+C29/20+D29/240 | H29: Total, 2 shilling 11.5pence
A30: Cost of buildings | F30: =SUM(F24:F28) | G30: =F30-F29 | H30: Total
A32: Dairy | B32: 0 | C32: 0 | D32: 4 | F32: 0.02 | H32: In small cloths bought for the dairy 4pence. | J32: =F32 | K32: =J32
A33: Dairy | B33: 0 | C33: 1 | D33: 8 | F33: 0.08 | H33: 5 bushels of salt bought 1 shilling 8pence. | J33: =F33 | K33: =J33
A34: Dairy | B34: 0 | C34: 0 | D34: 4 | F34: 0.02 | H34: earthenware pots and pans bought 4pence. | J34: =F34 | K34: =J34
A35: Dairy | B35: 0 | C35: 1 | D35: 4 | F35: 0.07 | H35: a press bought 1 shilling 4pence. | J35: =F35 | K35: =J35
A36: Dairy | B36: 0 | C36: 0 | D36: 4 | F36: 0.02 | H36: 2 buckets bought 4pence. | J36: =F36 | K36: =J36
A37: Dairy | B37: 0 | C37: 6 | D37: 0.5 | F37: 0.3 | H37: grease, copperas and verdigris bought 6 shilling 0.5pence. | J37: =F37 | K37: =J37
A38: Dairy | B38: 0 | C38: 4 | D38: 4 | F38: 0.22 | H38: forage bought to support the livestock and cows 4 shilling 4pence.
A39: Dairy | B39: 1 | C39: 0 | D39: 2.5 | F39: 1.01 | H39: 2 cows bought before calving £1 2.5pence, at 9 shilling 1.5pence for 1..
A40: Dairy | B40: 0 | C40: 9 | D40: 0 | F40: 0.45 | H40: a cow bought after calving 9 shilling. | J40: =F40 | K40: =J40
A41: Dairy | B41: 0 | C41: 3 | D41: 0 | F41: =B41+C41/20+D41/240 | H41: stipend of 1 dairymaid for the year 3 shilling
A42: Dairy | B42: 2 | C42: 6 | D42: 7 | F42: 2.33 | H42: Total, £2 6 shilling 7pence
A43: Dairy | F43: =SUM(F32:F41) | G43: =F43-F42 | H43: Total
...

Sheet Issues of the Grange
A1: Gross Output | B1: Total Quantity | C1: Account Total Quarters | D1: Bought in Total Quarters | E1: Received from churchscot | F1: Sold Total Quarters | G1: Difference Produced+Bought-Sold | H1: Weighted Average Price per Quarter | I1: Value of Total Production weighted
A2: wheat | B2: 9.75 | C2: 8.75 | D2: 1 | F2: 6.375 | G2: =B2-F2 | H2: 0.21666667 | I2: =H2*C2
A3: mancorn | B3: 58.875 | C3: 39.5 | D3: 19 | F3: 28.375 | G3: =B3-F3 | H3: 0.125 | I3: =H3*C3
A4: barley | B4: 19 | C4: 19 | D4: 0 | F4: 0.125 | G4: =B4-F4 | H4: 0.125 | I4: =H4*C4
A5: oats | B5: 20 | C5: 20 | D5: 0 | F5: 11.625 | G5: =B5-F5 | H5: 0.16666667 | I5: =H5*C5
A9: Total Production
A10: Sales of corn (as recorded in accounts)
A13: Net output | B13: Gross output | C13: Seed quarters | D13: Seed bushels | E13: Seed total quarters | F13: tithe quarters | G13: tithe bushels | H13: tithe total | I13: manorial servants quarters | J13: manorial servants bushels | K13: manorial servants total quarters | L13: output net of tithe, seed, liveries | M13: in stock from last year | N13: Price in £ | O13: Value of net output in £ | P13: Value of sales (in "Sale of Corn") in £
A14: wheat | B14: =B2 | C14: 3 | D14: 3 | E14: =C14+D14/8 | K14: =I14+J14/8 | L14: =B14-E14-H14-K14 | N14: =H2 | O14: =N14*L14
A15: mancorn | B15: =B3 | C15: 19 | E15: =C15+D15/8 | I15: =10 | J15: =3+5 | K15: =I15+J15/8 | L15: =B15-E15-H15-K15 | N15: =H3 | O15: =N15*L15
A16: barley | B16: =B4 | C16: 7 | D16: 3 | E16: =C16+D16/8 | K16: =I16+J16/8 | L16: =B16-E16-H16-K16 | N16: =H4 | O16: =N16*L16
A17: oats | B17: =B5 | C17: 15.5 | D17: 3 | E17: =C17+D17/8 | I17: 4 | J17: 1 | K17: =I17+J17/8 | L17: =B17-E17-H17-K17 | N17: =H5 | O17: =N17*L17
A19: Total

Sheet Issues of the Mills

Sheet Stock
A1: CULHAM STOCK ACCOUNT
C3: added | G3: subtracted
A4: Livestock | B4: Inherited stock | C4: added | D4: strays | E4: herbage | F4: churchscot | G4: of which in default | H4: sold | I4: in murrain | J4: accounted for elsewhere | K4: End-period stock | L4: cross-check | M4: stock building | N4: raw production | O4: Unit price (£) | P4: Value of stock (£) at given value | Q4: Value of stock (£) at sales prices | R4: Sales in (£) | S4: Value of stock building (£) | T4: Value of production (£) at sales prices | U4: Details
A5: Cart-horses
A6: Mares
A7: Plough horses | B7: 7 | K7: 7
A8: Colts (unspecified years)
A9: Colts (2 years)
A10: Colts (1 year)
A11: Foals
A12: Oxen | B12: 3 | C12: 2 | H12: 3 | K12: 2 | O12: =R12/H12 | R12: =Receipts!F32
A13: Bulls | B13: 1 | K13: 1
A14: Cows | B14: 23 | C14: =2+3 | H14: 2 | I14: =1 | K14: 25 | O14: =R14/H14 | R14: =Receipts!F33
A15: Steers | B15: 4 | J15: 4 | K15: 0
A16: Bullocks | B16: 9 | I16: 3 | K16: 6
A17: Yearlings | B17: 6 | I17: 3 | K17: 3
A18: Calves | B18: 22 | H18: 14 | I18: 1 | J18: =2 | K18: 5 | O18: =R18/H18 | R18: =Receipts!F34
A19: Wethers | B19: 112 | H19: 20 | I19: =5+6+1 | K19: 80 | O19: =R19/H19 | R19: =Receipts!F35
A20: Rams
A21: Ewes
A22: Hoggs
A23: Lambs
A24: Boars
A25: Sows
A26: Pigs
A27: Hoggets
A28: Piglets
A29: Swans
A30: Peacocks
A31: Total Value | R31: =SUM(R5:R29)
A34: Wool
A35: fleeces | C35: 87 | J35: =8+79 | K35: 0 | O35: 0.02 | T35: =O35*J35
A36: Coarse wool
A37: Lamb's wool
A38: Wool locks
A39: Wool sold at shearing
A40: Total wool | T40: =SUM(T35:T39)
A43: Hides
A44: Ox hides
A45: Mare
...

Sheet raw data
A1: Heading | B1: Sentence | C1: Total in Pounds | D1: Pounds | E1: Shillings | F1: Pence | G1: Corn | H1: Total Quarters Except 1 | I1: Total Bushels Except 1 | J1: Total Corn Cross-Check | K1: Total Corn Manorial Account | L1: Corn Quantity Error | M1: Quarters 1 | N1: Bushels 1 | O1: Quarters 2 | P1: Bushels 2 | Q1: Quarters 3 | R1: Bushels 3 | S1: Quarters 4 | T1: Bushels 4 | U1: Quarters 5 | V1: Bushels 5 | W1: shilling a quarter 1 | X1: pence a quarter 1 | Y1: shilling a quarter 2 | Z1: pence a quarter 2 | AA1: shilling a quarter 3 | AB1: pence a quarter 3 | AC1: shilling a quarter 4 | AD1: pence a quarter 4 | AE1: shilling a bushel 1 | AF1: pence a bushel 1 | AG1: shilling a bushel 2 | AH1: pence a bushel 2 | AI1: shilling a bushel 3 | AJ1: pence a bushel 3 | AK1: shilling a bushel 4 | AL1: pence a bushel 4
A2: Rents of assize | B2: James de North', bailiff, and William Kepe, reeve, render account for £2 1 shilling.5pence for all rents of assize at Easter (22 April). | C2: 2.05 | D2: 2 | E2: 1 | F2: 0 | H2: 0 | I2: 0 | J2: 0 | K2: 0 | L2: 0 | M2: 0 | N2: 0
A3: Rents of assize | B3: £2 1 shilling .5pence at Michaelmas (29 September). | C3: 2.05 | D3: 2 | E3: 1 | F3: 0 | H3: 0 | I3: 0 | J3: 0 | K3: 0 | L3: 0 | M3: 0 | N3: 0
A4: Rents of assize | B4: Total, £4 2 shilling 1pence | C4: 4.1 | D4: 4 | E4: 2 | F4: 1 | H4: 0 | I4: 0 | J4: 0 | K4: 0 | L4: 0 | M4: 0 | N4: 0
A5: Increment | B5: Nothing this year from increment of rent. | C5: 0 | D5: 0 | E5: 0 | F5: 0 | H5: 0 | I5: 0 | J5: 0 | K5: 0 | L5: 0 | M5: 0 | N5: 0
A6: Quittances | B6: In quittance of 1 reeve for the year 1 shilling. | C6: 0.05 | D6: 0 | E6: 1 | F6: 0 | H6: 0 | I6: 0 | J6: 0 | K6: 0 | L6: 0 | M6: 0 | N6: 0
A7: Quittances | B7: 1 carter for the year 6pence. | C7: 0.03 | D7: 0 | E7: 0 | F7: 6 | H7: 0 | I7: 0 | J7: 0 | K7: 0 | L7: 0 | M7: 0 | N7: 0
A8: Quittances | B8: 1 shepherd for the year 6pence. | C8: 0.03 | D8: 0 | E8: 0 | F8: 6 | H8: 0 | I8: 0 | J8: 0 | K8: 0 | L8: 0 | M8: 0 | N8: 0
A9: Quittances | B9: 1 hayward for the year 6pence Total, 2 shilling 6pence | C9: 0.12 | D9: 0 | E9: 2 | F9: 6 | H9: 0 | I9: 0 | J9: 0 | K9: 0 | L9: 0 | M9: 0 | N9: 0
A10: Total of rents remaining | B10: Total of rents remaining, £3 19 shilling 7pence | C10: 3.98 | D10: 3 | E10: 19 | F10: 7 | H10: 0 | I10: 0 | J10: 0 | K10: 0 | L10: 0 | M10: 0 | N10: 0
A11: Annual gifts | B11: The same render account for 9 shilling 0.5pence from annual gifts at Easter. | C11: 0.45 | D11: 0 | E11: 9 | F11: 0.5 | H11: 0 | I11: 0 | J11: 0 | K11: 0 | L11: 0 | M11: 0 | N11: 0
A12: Annual gifts | B12: 9 shilling 0.5pence at Michaelmas. | C12: 0.45 | D12: 0 | E12: 9 | F12: 0.5 | H12: 0 | I12: 0 | J12: 0 | K12: 0 | L12: 0 | M12: 0 | N12: 0
A13: Annual gifts | B13: Total, 18 shilling 1pence | C13: 0.9 | D13: 0 | E13: 18 | F13: 1 | H13: 0 | I13: 0 | J13: 0 | K13: 0 | L13: 0 | M13: 0 | N13: 0
... A36: Issues of the manor | B36: Total, £10 17 shilling | C36: 10.85 | D36: 10 | E36: 17 | F36: 0 | H36: 0 | I36: 0 | J36: 0 | K36: 0 | L36: 0 | M36: 0 | N36: 0
A37: Sale of corn | B37: The same render account for £1 7 shilling 7.5pence from 6 quarters 3 bushels of wheat sold, at 4 shilling 4pence a quarters. | C37: 1.38 | D37: 1 | E37: 7 | F37: 7.5 | G37: wheat | H37: 6 | I37: 3 | J37: 6.375 | K37: 6.375 | L37: 0 | M37: 6 | N37: 3 | W37: 4 | X37: 4
A38: Sale of corn | B38: £3 10 shilling 11.25pence from 28 quarters 3 bushels of mancorn sold, at 2 shilling 6pence a quarters. | C38: 3.55 | D38: 3 | E38: 10 | F38: 11.25 | G38: mancorn | H38: 28 | I38: 3 | J38: 28.375 | K38: 28.375 | L38: 0 | M38: 28 | N38: 3 | W38: 2 | X38: 6
A39: Sale of corn | B39: 3.75pence from 1 bushels sold at the audit. | C39: 0.02 | D39: 0 | E39: 0 | F39: 3.75 | H39: 0 | I39: 1 | J39: 0.125 | K39: 0.125 | L39: 0 | M39: 0 | N39: 1
A40: Sale of corn | B40: £1 18 shilling 9pence from 11.5 quarters 1 bushels of barley sold, at 3 shilling 4pence a quarters. | C40: 1.94 | D40: 1 | E40: 18 | F40: 9 | G40: barley | H40: 11.5 | I40: 1 | J40: 11.625 | K40: 11.625 | L40: 0 | M40: 11.5 | N40: 1 | W40: 3 | X40: 4
A41: Sale of corn | B41: Total, £6 17 shilling 7.5pence | C41: 6.88 | D41: 6 | E41: 17 | F41: 7.5 | H41: 0 | I41: 0 | J41: 0 | K41: 0 | L41: 0 | M41: 0 | N41: 0
A42: Entry and marriage fines | B42: The same render account for 3 shilling 0.5pence for tithingpenny at the hundred-court of Martinmas. | C42: 0.15 | D42: 0 | E42: 3 | F42: 0.5 | H42: 0 | I42: 0 | J42: 0 | K42: 0 | L42: 0 | M42: 0 | N42: 0
A43: Entry and marriage fines | B43: 3 shilling 0.5pence at the hundred-court of Hockday. | C43: 0.15 | D43: 0 | E43: 3 | F43: 0.5 | H43: 0 | I43: 0 | J43: 0 | K43: 0 | L43: 0 | M43: 0 | N43: 0
A44: Entry and marriage fines | B44: 13 shilling 4pence from William, son of Walter Molendinarius, to have 4.5 acres of land which belonged to Walter his father. | C44: 0.67 | D44: 0 | E44: 13 | F44: 4 | H44: 0 | I44: 0 | J44: 0 | K44: 0 | L44: 0 | M44: 0 | N44: 0
A45: Entry and marriage fines | B45: 2 shilling from Alice, who was wife of Nicholas Nel, to have 1 messuage .5 virgate of land which belonged to Nicholas her husband. | C45: 0.1 | D45: 0 | E45: 2 | F45: 0 | H45: 0 | I45: 0 | J45: 0 | K45: 0 | L45: 0 | M45: 0 | N45: 0
A46: Entry and marriage fines | B46: 3 shilling from John, son of John Boul', to have 1 acre of purpresture by surrender of the said John his father. | C46: 0.15 | D46: 0 | E46: 3 | F46: 0 | H46: 0 | I46: 0 | J46: 0 | K46: 0 | L46: 0 | M46: 0 | N46: 0
A47: Entry and marriage fines | B47: 2 shilling from William le Walays for marrying Matilda his daughter outside the demesne. | C47: 0.1 | D47: 0 | E47: 2 | F47: 0 | H47: 0 | I47: 0 | J47: 0 | K47: 0 | L47: 0 | M47: 0 | N47: 0
A48: Entry and marriage fines | B48: Total, £1 6 shilling 5pence | C48: 1.32 | D48: 1 | E48: 6 | F48: 5 | H48: 0 | I48: 0 | J48: 0 | K48: 0 | L48: 0 | M48: 0 | N48: 0
A49: Perquisites | B49: The same render account for 1 shilling from Alice Croyll', Walter Ryd', John Gay, Agnes ate Strod' for breaking the assize of ale. | C49: 0.05 | D49: 0 | E49: 1 | F49: 0 | H49: 0 | I49: 0 | J49: 0 | K49: 0 | L49: 0 | M49: 0 | N49: 0
A50: Perquisites | B50: 3pence from Thomas Buthory for trespass. | C50: 0.01 | D50: 0 | E50: 0 | F50: 3 | H50: 0 | I50: 0 | J50: 0 | K50: 0 | L50: 0 | M50: 0 | N50: 0
A51: Perquisites | B51: 3pence from Thomas ate Wod' for trespass. | C51: 0.01 | D51: 0 | E51: 0 | F51: 3 | H51: 0 | I51: 0 | J51: 0 | K51: 0 | L51: 0 | M51: 0 | N51: 0
A52: Perquisites | B52: 3pence from Justina Juveni for the same. | C52: 0.01 | D52: 0 | E52: 0 | F52: 3 | H52: 0 | I52: 0 | J52: 0 | K52: 0 | L52: 0 | M52: 0 | N52: 0
... A87: Expenses for ploughs | B87: 1 sack bought 9pence Total, £1 8 shilling 5.5pence | C87: 1.42 | D87: 1 | E87: 8 | F87: 5.5 | H87: 0 | I87: 0 | J87: 0 | K87: 0 | L87: 0 | M87: 0 | N87: 0
A88: Expenses for sowing and liveries | B88: In 1 quarters of wheat bought 4 shilling 4pence. | C88: 0.22 | D88: 0 | E88: 4 | F88: 4 | G88: wheat | H88: 1 | I88: 0 | J88: 1 | K88: 1 | L88: 0 | M88: 1 | N88: 0
A89: Expenses for sowing and liveries | B89: 19 quarters of mancorn bought for sowing £2 13 shilling, at 2 shilling 6pence a quarters for 8 quarters, and 3 shilling a quarters for 11 quarters. | C89: 2.65 | D89: 2 | E89: 13 | F89: 0 | G89: mancorn | H89: 19 | I89: 0 | J89: 19 | K89: 19 | L89: 0 | M89: 19 | N89: 0 | O89: 8 | P89: 0 | Q89: 11 | R89: 0 | W89: 2 | X89: 6 | Y89: 3 | Z89: 0
A90: Expenses for sowing and liveries | B90: Total, £2 17 shilling 4pence | C90: 2.87 | D90: 2 | E90: 17 | F90: 4 | H90: 0 | I90: 0 | J90: 0 | K90: 0 | L90: 0 | M90: 0 | N90: 0
A91: Carts | B91: in 1 pair of wheels bought for the cart 2 shilling 2pence. | C91: 0.11 | D91: 0 | E91: 2 | F91: 2 | H91: 0 | I91: 0 | J91: 0 | K91: 0 | L91: 0 | M91: 0 | N91: 0
A92: Carts | B92: clouts with nails bought 10.5pence, and so much because it was at Farnham in order to collect timber and talwood at the water (quesivit taluerud' ad aq'). | C92: 0.04 | D92: 0 | E92: 0 | F92: 10.5 | H92: 0 | I92: 0 | J92: 0 | K92: 0 | L92: 0 | M92: 0 | N92: 0
A93: Carts | B93: . | C93: 0 | D93: 0 | E93: 0 | F93: 0 | H93: 0 | I93: 0 | J93: 0 | K93: 0 | L93: 0 | M93: 0 | N93: 0
A94: Carts | B94: grease for the cart 5pence. | C94: 0.02 | D94: 0 | E94: 0 | F94: 5 | H94: 0 | I94: 0 | J94: 0 | K94: 0 | L94: 0 | M94: 0 | N94: 0
A95: Carts | B95: fitting the cart with axles 3pence. | C95: 0.01 | D95: 0 | E95: 0 | F95: 3 | H95: 0 | I95: 0 | J95: 0 | K95: 0 | L95: 0 | M95: 0 | N95: 0
A96: Carts | B96: 1 pair of cart-shafts made from their own timber 4.5pence. | C96: 0.02 | D96: 0 | E96: 0 | F96: 4.5 | H96: 0 | I96: 0 | J96: 0 | K96: 0 | L96: 0 | M96: 0 | N96: 0
...

Sheet Issues of the Grange raw
A1: Heading | B1: Sentence | C1: Quarters 1_x | D1: Bushels 1_x | E1: Sown Quarters | F1: Sown Bushels | G1: Sown Total Quarters | H1: Bought in Quarters | I1: Bought in Bushels | J1: Bought in Total Quarters | K1: Tithe Quarters | L1: Tithe Bushels | M1: Tithe Total Quarters | N1: Manorial servants & livestock Quarters | O1: Manorial servants & livestock Bushels | P1: Manorial servants & livestock Total Quarters | Q1: Sold Quarters | R1: Sold Bushels | S1: Sold Total Quarters | T1: Account Quarters | U1: Account Bushels | V1: Account Total Quarters | W1: bought only | X1: Total Quarters Except 1 | Y1: Total Bushels Except 1 | Z1: Total Corn Cross-Check | AA1: Total Corn Manorial Account | AB1: Corn Quantity Error | AC1: Quarters 1_y | AD1: Bushels 1_y | AE1: Quarters 2 | AF1: Bushels 2 | AG1: Quarters 3 | AH1: Bushels 3 | AI1: Quarters 4 | AJ1: Bushels 4 | AK1: Quarters 5 | AL1: Bushels 5
A2: Reeve | B2: Total | C2: 0 | D2: 0 | E2: 0 | F2: 0 | G2: 0 | H2: 0 | I2: 0 | J2: 0 | K2: 0 | L2: 0 | M2: 0 | N2: 0 | O2: 0 | P2: 0 | Q2: 0 | R2: 0 | S2: 0 | T2: 0 | U2: 0 | V2: 0 | W2: 0
A3: Wheat | B3: (yield: two-fold less 6 bushels} | C3: 0 | D3: 0 | E3: 0 | F3: 0 | G3: 0 | H3: 0 | I3: 0 | J3: 0 | K3: 0 | L3: 0 | M3: 0 | N3: 0 | O3: 0 | P3: 0 | Q3: 0 | R3: 0 | S3: 0 | T3: 0 | U3: 0 | V3: 0 | W3: 0 | X3: 0 | Y3: 6 | Z3: 0.75 | AA3: 0.75 | AB3: 0 | AC3: 0 | AD3: 6
A4: Wheat | B4: The same render account for 8.5 quarters 2 bushels from the whole issue of wheat from the grange with the increment of the granary. | C4: 0 | D4: 0 | E4: 0 | F4: 0 | G4: 0 | H4: 0 | I4: 0 | J4: 0 | K4: 0 | L4: 0 | M4: 0 | N4: 0 | O4: 0 | P4: 0 | Q4: 0 | R4: 0 | S4: 0 | T4: 8.5 | U4: 2 | V4: 8.75 | W4: 0 | X4: 8.5 | Y4: 2 | Z4: 8.75 | AA4: 8.75 | AB4: 0 | AC4: 8.5 | AD4: 2
A5: Wheat | B5: 1 qr bought. | C5: 0 | D5: 0 | E5: 0 | F5: 0 | G5: 0 | H5: 0 | I5: 0 | J5: 0 | K5: 0 | L5: 0 | M5: 0 | N5: 0 | O5: 0 | P5: 0 | Q5: 0 | R5: 0 | S5: 0 | T5: 0 | U5: 0 | V5: 0 | W5: 0
A6: Wheat | B6: Total, 9.5 quarters 2 bushels | C6: 0 | D6: 0 | E6: 0 | F6: 0 | G6: 0 | H6: 0 | I6: 0 | J6: 0 | K6: 0 | L6: 0 | M6: 0 | N6: 0 | O6: 0 | P6: 0 | Q6: 0 | R6: 0 | S6: 0 | T6: 0 | U6: 0 | V6: 0 | W6: 0 | X6: 9.5 | Y6: 2 | Z6: 9.75 | AA6: 9.75 | AB6: 0 | AC6: 9.5 | AD6: 2
A7: Wheat | B7: Sown over 9 acres measured by the perch which lie in the field upon the heath, 3 quarters 3 bushels Sold as noted above, 6 quarters 3 bushels | C7: 0 | D7: 0 | E7: 9 | F7: 6 | G7: 9.75 | H7: 0 | I7: 0 | J7: 0 | K7: 0 | L7: 0 | M7: 0 | N7: 0 | O7: 0 | P7: 0 | Q7: 9 | R7: 6 | S7: 9.75 | T7: 0 | U7: 0 | V7: 0 | W7: 0 | X7: 6 | Y7: 6 | Z7: 6.75 | AA7: 3 | AB7: 3.75 | AC7: 3 | AD7: 0 | AE7: 0 | AF7: 3 | AG7: 6 | AH7: 3
A8: Wheat | B8: Total | C8: 0 | D8: 0 | E8: 0 | F8: 0 | G8: 0 | H8: 0 | I8: 0 | J8: 0 | K8: 0 | L8: 0 | M8: 0 | N8: 0 | O8: 0 | P8: 0 | Q8: 0 | R8: 0 | S8: 0 | T8: 0 | U8: 0 | V8: 0 | W8: 0
A9: Mancorn | B9: {yield: two-and-a-half-fold plus 2 quarters} The same render account for 39.5 quarters from the whole issue of mancom from the grange with the increment of the granary. | C9: 0 | D9: 0 | E9: 0 | F9: 0 | G9: 0 | H9: 0 | I9: 0 | J9: 0 | K9: 0 | L9: 0 | M9: 0 | N9: 0 | O9: 0 | P9: 0 | Q9: 0 | R9: 0 | S9: 0 | T9: 41.5 | U9: 0 | V9: 41.5 | W9: 0 | X9: 39.5 | Y9: 0 | Z9: 39.5 | AA9: 2 | AB9: 37.5 | AC9: 2 | AD9: 0 | AE9: 39.5 | AF9: 0
A10: Mancorn | B10: 19 quarters bought. | C10: 0 | D10: 0 | E10: 0 | F10: 0 | G10: 0 | H10: 19 | I10: 0 | J10: 19 | K10: 0 | L10: 0 | M10: 0 | N10: 0 | O10: 0 | P10: 0 | Q10: 0 | R10: 0 | S10: 0 | T10: 0 | U10: 0 | V10: 0 | W10: 0 | X10: 19 | Y10: 0 | Z10: 19 | AA10: 19 | AB10: 0 | AC10: 19 | AD10: 0
A11: Mancorn | B11: Total, 58.5 quarters. | C11: 0 | D11: 0 | E11: 0 | F11: 0 | G11: 0 | H11: 0 | I11: 0 | J11: 0 | K11: 0 | L11: 0 | M11: 0 | N11: 0 | O11: 0 | P11: 0 | Q11: 0 | R11: 0 | S11: 0 | T11: 0 | U11: 0 | V11: 0 | W11: 0 | X11: 58.5 | Y11: 0 | Z11: 58.5 | AA11: 58.5 | AB11: 0 | AC11: 58.5 | AD11: 0
A12: Mancorn | B12: Sown over 51 acres measured by the perch as they lief in the field upon the heath, 19 quarters. | C12: 0 | D12: 0 | E12: 19 | F12: 0 | G12: 19 | H12: 0 | I12: 0 | J12: 0 | K12: 0 | L12: 0 | M12: 0 | N12: 0 | O12: 0 | P12: 0 | Q12: 0 | R12: 0 | S12: 0 | T12: 0 | U12: 0 | V12: 0 | W12: 0 | X12: 19 | Y12: 0 | Z12: 19 | AA12: 19 | AB12: 0 | AC12: 19 | AD12: 0
A13: Mancorn | B13: that is, 3 bushels an acre, less 1 bushels in all. | C13: 0 | D13: 0 | E13: 0 | F13: 0 | G13: 0 | H13: 0 | I13: 0 | J13: 0 | K13: 0 | L13: 0 | M13: 0 | N13: 0 | O13: 0 | P13: 0 | Q13: 0 | R13: 0 | S13: 0 | T13: 0 | U13: 0 | V13: 0 | W13: 0 | X13: 0 | Y13: 1 | Z13: 0.125 | AA13: 0.375 | AB13: -0.25 | AC13: 0 | AD13: 3 | AE13: 0 | AF13: 1
A14: Mancorn | B14: Delivered to 1 drover and 1 dairymaid for the year, 10 quarters 3 bushels, because they take a quarter every 10 weeks. | C14: 0 | D14: 0 | E14: 0 | F14: 0 | G14: 0 | H14: 0 | I14: 0 | J14: 0 | K14: 0 | L14: 0 | M14: 0 | N14: 0 | O14: 0 | P14: 0 | Q14: 0 | R14: 0 | S14: 0 | T14: 0 | U14: 0 | V14: 0 | W14: 0 | X14: 10 | Y14: 3 | Z14: 10.375 | AA14: 10.375 | AB14: 0 | AC14: 10 | AD14: 3
A15: Mancorn | B15: . | C15: 0 | D15: 0 | E15: 0 | F15: 0 | G15: 0 | H15: 0 | I15: 0 | J15: 0 | K15: 0 | L15: 0 | M15: 0 | N15: 0 | O15: 0 | P15: 0 | Q15: 0 | R15: 0 | S15: 0 | T15: 0 | U15: 0 | V15: 0 | W15: 0 | X15: 0 | Y15: 0 | Z15: 0 | AA15: 0 | AB15: 0 | AC15: 0 | AD15: 0
A16: Mancorn | B16: customary payment for the mowing of the meadows, 5 bushels Sold, 28 quarters 3 bushels Sold at the audit, 1 bushels | C16: 0 | D16: 0 | E16: 0 | F16: 0 | G16: 0 | H16: 0 | I16: 0 | J16: 0 | K16: 0 | L16: 0 | M16: 0 | N16: 0 | O16: 0 | P16: 0 | Q16: 28 | R16: 3 | S16: 28.375 | T16: 0 | U16: 0 | V16: 0 | W16: 0 | X16: 28 | Y16: 4 | Z16: 28.5 | AA16: 0.625 | AB16: 27.875 | AC16: 0 | AD16: 5 | AE16: 28 | AF16: 3 | AG16: 0 | AH16: 1
A17: Mancorn | B17: Total | C17: 0 | D17: 0 | E17: 0 | F17: 0 | G17: 0 | H17: 0 | I17: 0 | J17: 0 | K17: 0 | L17: 0 | M17: 0 | N17: 0 | O17: 0 | P17: 0 | Q17: 0 | R17: 0 | S17: 0 | T17: 0 | U17: 0 | V17: 0 | W17: 0
A18: Barley | B18: {yield: three-fold less 1 bushels} | C18: 0 | D18: 0 | E18: 0 | F18: 0 | G18: 0 | H18: 0 | I18: 0 | J18: 0 | K18: 0 | L18: 0 | M18: 0 | N18: 0 | O18: 0 | P18: 0 | Q18: 0 | R18: 0 | S18: 0 | T18: 0 | U18: 0 | V18: 0 | W18: 0 | X18: 0 | Y18: 1 | Z18: 0.125 | AA18: 0.125 | AB18: 0 | AC18: 0 | AD18: 1
A19: Barley | B19: The same render account for 19 quarters from the whole issue of the grange with the increment of the granary. | C19: 0 | D19: 0 | E19: 0 | F19: 0 | G19: 0 | H19: 0 | I19: 0 | J19: 0 | K19: 0 | L19: 0 | M19: 0 | N19: 0 | O19: 0 | P19: 0 | Q19: 0 | R19: 0 | S19: 0 | T19: 19 | U19: 0 | V19: 19 | W19: 0 | X19: 19 | Y19: 0 | Z19: 19 | AA19: 19 | AB19: 0 | AC19: 19 | AD19: 0
A20: Barley | B20: Sown over 15 acres which lie in the field of la Doun', 7 quarters 3 bushels. | C20: 0 | D20: 0 | E20: 7 | F20: 3 | G20: 7.375 | H20: 0 | I20: 0 | J20: 0 | K20: 0 | L20: 0 | M20: 0 | N20: 0 | O20: 0 | P20: 0 | Q20: 0 | R20: 0 | S20: 0 | T20: 0 | U20: 0 | V20: 0 | W20: 0 | X20: 7 | Y20: 3 | Z20: 7.375 | AA20: 7.375 | AB20: 0 | AC20: 7 | AD20: 3
A21: Barley | B21: that is, 4 bushels an acre, less 1 bushels in all. | C21: 0 | D21: 0 | E21: 0 | F21: 0 | G21: 0 | H21: 0 | I21: 0 | J21: 0 | K21: 0 | L21: 0 | M21: 0 | N21: 0 | O21: 0 | P21: 0 | Q21: 0 | R21: 0 | S21: 0 | T21: 0 | U21: 0 | V21: 0 | W21: 0 | X21: 0 | Y21: 1 | Z21: 0.125 | AA21: 0.5 | AB21: -0.375 | AC21: 0 | AD21: 4 | AE21: 0 | AF21: 1
A22: Barley | B22: Sold, 11.5 quarters 1 bushels | C22: 0 | D22: 0 | E22: 0 | F22: 0 | G22: 0 | H22: 0 | I22: 0 | J22: 0 | K22: 0 | L22: 0 | M22: 0 | N22: 0 | O22: 0 | P22: 0 | Q22: 11.5 | R22: 1 | S22: 11.625 | T22: 0 | U22: 0 | V22: 0 | W22: 0 | X22: 11.5 | Y22: 1 | Z22: 11.625 | AA22: 11.625 | AB22: 0 | AC22: 11.5 | AD22: 1
A23: Barley | B23: Total | C23: 0 | D23: 0 | E23: 0 | F23: 0 | G23: 0 | H23: 0 | I23: 0 | J23: 0 | K23: 0 | L23: 0 | M23: 0 | N23: 0 | O23: 0 | P23: 0 | Q23: 0 | R23: 0 | S23: 0 | T23: 0 | U23: 0 | V23: 0 | W23: 0
A24: Oats | B24: {yield: 2 bushels more than sown} | C24: 0 | D24: 0 | E24: 0 | F24: 0 | G24: 0 | H24: 0 | I24: 0 | J24: 0 | K24: 0 | L24: 0 | M24: 0 | N24: 0 | O24: 0 | P24: 0 | Q24: 0 | R24: 0 | S24: 0 | T24: 0 | U24: 0 | V24: 0 | W24: 0 | X24: 0 | Y24: 2 | Z24: 0.25 | AA24: 0.25 | AB24: 0 | AC24: 0 | AD24: 2
A25: Oats | B25: The same render account for 20 quarters from the whole issue of oats from the grange with the increment of the granary. | C25: 0 | D25: 0 | E25: 0 | F25: 0 | G25: 0 | H25: 0 | I25: 0 | J25: 0 | K25: 0 | L25: 0 | M25: 0 | N25: 0 | O25: 0 | P25: 0 | Q25: 0 | R25: 0 | S25: 0 | T25: 20 | U25: 0 | V25: 20 | W25: 0 | X25: 20 | Y25: 0 | Z25: 20 | AA25: 20 | AB25: 0 | AC25: 20 | AD25: 0
A26: Oats | B26: Sown over 26 acres measured by the perch as they lie in the fields of la Doun' and Stanlych', 15.5 quarters 3 bushels. | C26: 0 | D26: 0 | E26: 15.5 | F26: 3 | G26: 15.875 | H26: 0 | I26: 0 | J26: 0 | K26: 0 | L26: 0 | M26: 0 | N26: 0 | O26: 0 | P26: 0 | Q26: 0 | R26: 0 | S26: 0 | T26: 0 | U26: 0 | V26: 0 | W26: 0 | X26: 15.5 | Y26: 3 | Z26: 15.875 | AA26: 15.875 | AB26: 0 | AC26: 15.5 | AD26: 3
A27: Oats | B27: that is, 5 bushels an acre, plus 2 bushels in all. | C27: 0 | D27: 0 | E27: 0 | F27: 0 | G27: 0 | H27: 0 | I27: 0 | J27: 0 | K27: 0 | L27: 0 | M27: 0 | N27: 0 | O27: 0 | P27: 0 | Q27: 0 | R27: 0 | S27: 0 | T27: 0 | U27: 0 | V27: 0 | W27: 0 | X27: 0 | Y27: 2 | Z27: 0.25 | AA27: 0.625 | AB27: -0.375 | AC27: 0 | AD27: 5 | AE27: 0 | AF27: 2
A28: Oats | B28: . | C28: 0 | D28: 0 | E28: 0 | F28: 0 | G28: 0 | H28: 0 | I28: 0 | J28: 0 | K28: 0 | L28: 0 | M28: 0 | N28: 0 | O28: 0 | P28: 0 | Q28: 0 | R28: 0 | S28: 0 | T28: 0 | U28: 0 | V28: 0 | W28: 0 | X28: 0 | Y28: 0 | Z28: 0 | AA28: 0 | AB28: 0 | AC28: 0 | AD28: 0
A29: Oats | B29: fodder of 7 plough-horses, 4 quarters 1 bushels | C29: 0 | D29: 0 | E29: 0 | F29: 0 | G29: 0 | H29: 0 | I29: 0 | J29: 0 | K29: 0 | L29: 0 | M29: 0 | N29: 4 | O29: 1 | P29: 4.125 | Q29: 0 | R29: 0 | S29: 0 | T29: 0 | U29: 0 | V29: 0 | W29: 0 | X29: 4 | Y29: 1 | Z29: 4.125 | AA29: 4.125 | AB29: 0 | AC29: 4 | AD29: 1

Sheet Sale of Corn Prices
A1: Heading | B1: Sentence | C1: Total in Pounds | D1: Pounds | E1: Shillings | F1: Pence | G1: Corn | H1: Total Quarters Except 1 | I1: Total Bushels Except 1 | J1: Total Corn Cross-Check | K1: Total Corn Manorial Account | L1: Corn Quantity Error | M1: Quarters 0 | N1: Bushels 0 | O1: shilling a quarter 1 | P1: pence a quarter 1 | Q1: Quarters 1 | R1: Bushels 1 | S1: shilling a quarter 2 | T1: pence a quarter 2 | U1: Quarters 2 | V1: Bushels 2 | W1: shilling a quarter 3 | X1: pence a quarter 3 | Y1: Quarters 3 | Z1: Bushels 3 | AA1: shilling a quarter 4 | AB1: pence a quarter 4 | AC1: Quarters 4 | AD1: Bushels 4 | AE1: £ a quarter 1 | AF1: £ a quarter 2 | AG1: £ a quarter 3 | AH1: £ a quarter 4 | AI1: Quarters Sold | AJ1: Weighted Average Price per Quarter | AK1: Non-Weighted Average Price per Quarter | AL1: Corn lowercase
A2: Sale of corn | B2: The same render account for £1 7 shilling 7.5pence from 6 quarters 3 bushels of wheat sold, at 4 shilling 4pence a quarters. | C2: 1.38 | D2: 1 | E2: 7 | F2: 7.5 | G2: wheat | H2: 6 | I2: 3 | J2: 6.375 | K2: 6.375 | L2: 0 | M2: 6 | N2: 3 | O2: 4 | P2: 4 | AE2: 0.21666667 | AI2: 6.375 | AJ2: 0.21666667 | AK2: 0.21666667 | AL2: wheat
A3: Sale of corn | B3: £3 10 shilling 11.25pence from 28 quarters 3 bushels of mancorn sold, at 2 shilling 6pence a quarters. | C3: 3.55 | D3: 3 | E3: 10 | F3: 11.25 | G3: mancorn | H3: 28 | I3: 3 | J3: 28.375 | K3: 28.375 | L3: 0 | M3: 28 | N3: 3 | O3: 2 | P3: 6 | AE3: 0.125 | AI3: 28.375 | AJ3: 0.125 | AK3: 0.125 | AL3: mancorn
A4: Sale of corn | B4: 3.75pence from 1 bushels sold at the audit. | C4: 0.02 | D4: 0 | E4: 0 | F4: 3.75 | H4: 0 | I4: 1 | J4: 0.125 | K4: 0.125 | L4: 0 | M4: 0 | N4: 1 | AE4: 0.16 | AI4: 0.125 | AJ4: 0.16 | AK4: 0.16
A5: Sale of corn | B5: £1 18 shilling 9pence from 11.5 quarters 1 bushels of barley sold, at 3 shilling 4pence a quarters. | C5: 1.94 | D5: 1 | E5: 18 | F5: 9 | G5: barley | H5: 11.5 | I5: 1 | J5: 11.625 | K5: 11.625 | L5: 0 | M5: 11.5 | N5: 1 | O5: 3 | P5: 4 | AE5: 0.16666667 | AI5: 11.625 | AJ5: 0.16666667 | AK5: 0.16666667 | AL5: barley
A6: Sale of corn | B6: Total, £6 17 shilling 7.5pence | C6: 6.88 | D6: 6 | E6: 17 | F6: 7.5 | H6: 0 | I6: 0 | J6: 0 | K6: 0 | L6: 0 | M6: 0 | N6: 0 | AE6: inf | AI6: 0 | AJ6: inf | AK6: inf
