Workbook

Sheet Droxford Overview - Completed
A1: DROXFORD OVERVIEW - COMPLETED | B1: Total in £ | C1: Error | D1: Note
A2: CASH ACCOUNT
A3: RECEIPTS
A4: Arrears total | B4: 25.94
A5: Rents of assize total | B5: 24.77
A6: Quittances total | B6: 0.425625
A7: Defaults of rent total | B7: 0.5
A8: Defaults of rent through the pestilence total
A9: Cotlands defaults total
A10: Cotlands total
A11: Total of quittances and defaults of rent total | B11: 0.92
A12: Total of rents remaining clear total
A13: Farms total
A14: Annual recognizances total | B14: 0.1
A15: Issues of the Manor total | B15: 22.057083
A16: Issues of the tenements in the lord's hands total
A17: Sale of labour services total
A18: Sale of corn total | B18: 27.96
A19: Entry and marriage fines total | B19: 2.18
A20: Pleas & perquisites total
A21: Forfeited chattels total
A22: Farm of the demesne land total
A23: Total of all receipts (calculated here) | B23: =SUM(B5:B22)
A24: Total of all receipts (calculated here) incl arrears | B24: =SUM(B4:B22)
A25: Total recorded in the accounts excl. arrears | B25: 80.0875 | C25: =B23-B25
A26: Total recorded in the accounts incl. arrears | B26: =B25+B4
A29: EXPENSES
A30: Cost of ploughs total | B30: 3.69
A31: Purchase of corn total
A32: Cost of carts and wagons total
A33: Cost of dairy total
A34: Purchase of stock total
A35: Sheepcote total | B35: 1.0141667
A36: Cost of buildings total | B36: 2.2
A37: Threshing total | B37: 1.6704167
A38: Barley expenses
A39: Expenses of the harvest total
A40: Necessary expenses
A41: Wages of the bailiff
A42: Steward's expenses total | B42: 0.51
...

Sheet Prices
A1: Meat & Dairy Prices
C2: 1301 | D2: 1302 | E2: Average
A3: Beef | B3: £ per lb | C3: 0.0033351854 | D3: 0.0032608538 | E3: =AVERAGE(C3:D3)
A4: Mutton | B4: £ per lb | C4: 0.0036593977 | D4: 0.0037125513 | E4: =AVERAGE(C4:D4)
A5: Pork | B5: £ per lb | C5: 0.0038431326 | D5: 0.0037574803 | E5: =AVERAGE(C5:D5)
A6: Cheese | B6: £ per lb | C6: 0.0055768754 | D6: 0.0056654898 | E6: =AVERAGE(C6:D6)
A7: Butter | B7: £ per lb | C7: 0.0036626221 | D7: 0.0035935077 | E7: =AVERAGE(C7:D7)
A8: Milk | B8: £ per gallon | C8: 0.0055768754 | D8: 0.0056654898 | E8: =AVERAGE(C8:D8)

Sheet Labour Rents

Sheet Overview
A1: DROXFORD
A2: CASH ACCOUNT | B2: Total in £ | C2: Error | D2: Note
A3: RECEIPTS
A4: Arrears total
A5: Rents of assize total
A6: Quittances total
A7: Defaults of rent total
A8: Defaults of rent through the pestilence total
A9: Cotlands defaults total
A10: Cotlands total
A11: Total of quittances and defaults of rent total
A12: Total of rents remaining clear total
A13: Farms total
A14: Annual recognizances total
... A22: Farm of the demesne land total
A23: Total of all receipts (calculated here) | B23: =Receipts!F126
A24: Total of all receipts (calculated here) incl arrears | B24: =Receipts!F127
A25: Total recorded in the accounts excl. arrears | B25: =Receipts!F125 | C25: =B25-B23
A26: Total recorded in the accounts incl. arrears
A29: EXPENSES
A30: Cost of ploughs total
A31: Purchase of corn total
A32: Cost of carts and wagons total
A33: Cost of dairy total
A34: Purchase of stock total
A35: Sheepcote total
A36: Cost of buildings total
A37: Threshing total
A38: Barley expenses
A39: Expenses of the harvest total
... A43: Annual fees
A44: Total of all expenses per account | B44: =Expenses!F104
A45: Total of all expenses (calculated here) | B45: =Expenses!F105
A46: Total fixed investment | B46: =Expenses!F106
A47: Total Demesne fixed investment | B47: =Expenses!F107
A49: Owed by the reeve
A50: From accounts
A52: Allowances
A53: Cash deliveries
A54: Sum of the above
...

Sheet Receipts
A1: DROXFORD RECEIPTS
A2: Heading | B2: £ | C2: s | D2: d | F2: Total in £ | G2: Error | H2: Notes
A3: Arrears | B3: 25 | C3: 18 | D3: 9.75 | F3: 25.94 | H3: Robert de Froyle, bailiff, and William ate Hatth', reeve, render account for £25 18 shilling 9.75pence of arrears from the previous year.
A4: Arrears | B4: 0 | C4: 0 | D4: 0 | F4: 0 | H4: All delivered to Sir Geoffrey, treasurer of Wolvesey, by 1 tally.
A5: Arrears | B5: 0 | C5: 0 | D5: 0 | F5: 0 | H5: They are quit.
A6: Arrears | F6: 25.94 | G6: 25.94 | H6: Total
A8: Rents of assize | B8: 2 | C8: 18 | D8: 5 | F8: 2.92 | H8: The same render account for £2 18 shilling 5pence from ox-gavel (oxeye) at the feast of St Thomas the Apostle (21 December).
A9: Rents of assize | B9: 0 | C9: 17 | D9: 10.5 | F9: 0.89 | H9: 17 shilling 10.5pence from wood-gavel (wodegavel) at Lammas (1 August).
A10: Rents of assize | B10: 20 | C10: 19 | D10: 3.5 | F10: 20.96 | H10: £20 19 shilling 3.5pence for rents of assize at Michaelmas (29 September).
A11: Rents of assize | B11: 24 | C11: 15 | D11: 7.5 | F11: 24.78 | H11: Total, £24 15 shilling 7.5pence
A12: Rents of assize | F12: 24.77 | G12: -0.01 | H12: Total
A14: Quittances | B14: 0 | C14: 7 | D14: 6 | F14: 0.38 | H14: In quittance of 3 ploughmen, 2 shepherds and 1 smith for the year 7 shilling 6pence, or 1 shilling 3pence each.
A15: Quittances | B15: 0 | C15: 0 | D15: 6 | F15: 0.03 | H15: the same for ox-gavel 6pence.
A16: Quittances | B16: 0 | C16: 0 | D16: 3.75 | F16: =B16+C16/20+D16/240 | H16: 1 keeper of lambs from the Nativity of St John the Baptist to Michaelmas, for 1 term, 3.75pence
B17: 0 | C17: 8 | D17: 3.75 | F17: 0.42 | H17: Total, 8 shilling 3.75pence
A18: Quittances | F18: =SUM(F14:F16) | G18: =F18-F17 | H18: Total
A20: Defaults of rent | B20: 0 | C20: 0 | D20: 7 | F20: 0.03 | H20: In default of the land of William de Swanemere for ox-gavel because he is made free 7pence.
A21: Defaults of rent | B21: 0 | C21: 1 | D21: 0 | F21: 0.05 | H21: the land of Horn for the same 1 shilling.
A22: Defaults of rent | B22: 0 | C22: 2 | D22: 4 | F22: 0.12 | H22: the land of Thomas de la Steple for the same 2 shilling 4pence.
A23: Defaults of rent | B23: 0 | C23: 5 | D23: 0 | F23: 0.25 | H23: the land of Boarhunt which is called Wolfrenelond' 5 shilling.
A24: Defaults of rent | B24: 0 | C24: 0 | D24: 2.5 | F24: 0.01 | H24: the chief tenement formerly of John de Molendino for ox-gavel 2.5pence, because it should in fact be put in the increment of rent by charter of the lord.
A25: Defaults of rent | B25: 0 | C25: 0 | D25: 3.5 | F25: 0.01 | H25: the other tenement which the same John held, which he took on according to custom from St Swithun's whilst the manor was in their hands, for ox-gavel, 3.5pence, for the reason as before.
A26: Defaults of rent | B26: 0 | C26: 0 | D26: 7 | F26: 0.03 | H26: a certain tenement which the same John held which was formerly a relief 7pence, for the reason as before.
A27: Defaults of rent | B27: 0 | C27: 10 | D27: 0 | F27: 0.5 | H27: Total, 10 shilling
A28: Defaults of rent | F28: 0.5 | G28: 0 | H28: Total
A30: Total of quittances and defaults of rent | B30: 0 | C30: 18 | D30: 3.75 | F30: 0.92 | H30: Total of quittances and defaults of rent, 18 shilling 3.75pence
A31: Total of quittances and defaults of rent | F31: 0.92 | G31: =F31-F30 | H31: Total
A33: Total of rents remaining | B33: 23 | C33: 17 | D33: 3.75 | F33: 23.87 | H33: Total of rents remaining, £23 17 shilling 3.75pence
A34: Total of rents remaining | F34: 23.87 | G34: =F34-F33 | H34: Total
A36: Farm of the mill | B36: 3 | C36: 0 | D36: 0 | F36: 3 | H36: The same render account for £3 for the rent of the mill let at fee-farm.
A37: Farm of the mill | B37: 3 | C37: 0 | D37: 0 | F37: 3 | H37: Total, £3.
A38: Farm of the mill | F38: 3 | G38: 0 | H38: Total
A40: Annual recognizance | B40: 0 | C40: 0 | D40: 3 | F40: 0.01 | H40: The same render account for 3pence from Walter Molendinarius for annual recognizance.
A41: Annual recognizance | B41: 0 | C41: 0 | D41: 6 | F41: 0.03 | H41: 6pence from William le Careter for the same.
A42: Annual recognizance | B42: 0 | C42: 0 | D42: 6 | F42: 0.03 | H42: 6pence from William.
A43: Annual recognizance | B43: 0 | C43: 0 | D43: 6 | F43: 0.03 | H43: 6pence from William le YI so that he may serve outside the manor, and yet pay suit to his tithing at the steward's tourns as a villein as before.
A44: Annual recognizance | B44: 0 | C44: 1 | D44: 3 | F44: 0.06 | H44: Total, 1 shilling 3pence
A45: Annual recognizance | F45: 0.1 | G45: 0.04 | H45: Total
A47: Cumin | B47: 0 | C47: 0 | D47: 0 | F47: 0 | H47: The same render account for 1 lb of cumin from the rent of John, son of Henry le Careter.
A48: Cumin | B48: 0 | C48: 0 | D48: 0 | F48: 0 | H48: delivered to Wolvesey.
...

Sheet Expenses
A1: DROXFORD EXPENSES
A2: Heading | B2: £ | C2: s | D2: d | F2: Total in £ | G2: Error | H2: Notes | J2: Fixed investment | K2: Demesne fixed investment
A3: Cost of ploughs | B3: 0 | C3: 6 | D3: 10.5 | F3: 0.34 | H3: In iron and steel bought for 2 ploughs for the year and three ploughs for 1 term 6 shilling 10.5pence. | J3: =F3 | K3: =J3
A4: Cost of ploughs | B4: 0 | C4: 0 | D4: 9 | F4: 0.04 | H4: 1 ploughshare bought 9pence. | J4: =F4 | K4: =J4
A5: Cost of ploughs | B5: 0 | C5: 0 | D5: 5 | F5: 0.02 | H5: 1 plough made anew and others mended 5pence. | J5: =F5 | K5: =J5
A6: Cost of ploughs | B6: 0 | C6: 0 | D6: 3 | F6: 0.01 | H6: trimming timber 3pence. | J6: =F6 | K6: =J6
A7: Cost of ploughs | B7: 0 | C7: 1 | D7: 3 | F7: 0.06 | H7: 3 plough feet bought 1 shilling 3pence. | J7: =F7 | K7: =J7
A8: Cost of ploughs | B8: 0 | C8: 0 | D8: 1.5 | F8: 0.01 | H8: fitting the said plough with iron tyres 1.5pence. | J8: =F8 | K8: =J8
A9: Cost of ploughs | B9: 0 | C9: 1 | D9: 0 | F9: 0.05 | H9: 3 pairs of wheels bought for the same 1 shilling. | J9: =F9 | K9: =J9
A10: Cost of ploughs | B10: 0 | C10: 0 | D10: 0.75 | F10: 0 | H10: 3 halters made from the horses' own hair (de proprio pilo) 0.75pence. | J10: =F10 | K10: =J10
A11: Cost of ploughs | B11: 0 | C11: 2 | D11: 6 | F11: 0.12 | H11: shoeing 2 plough-horses 2 shilling 6pence, because the smith shoes 2 according to custom. | J11: =F11 | K11: =J11
A12: Cost of ploughs | B12: 0 | C12: 1 | D12: 4 | F12: 0.07 | H12: spreading dung 1 shilling 4pence. | J12: =F12 | K12: =J12
A13: Cost of ploughs | B13: 0 | C13: 0 | D13: 4 | F13: 0.02 | H13: 2 harrows made anew with others mended 4pence. | J13: =F13 | K13: =J13
A14: Cost of ploughs | B14: 0 | C14: 3 | D14: 0 | F14: 0.15 | H14: stipend of 1 drover for the year 3 shilling.
A15: Cost of ploughs | B15: 0 | C15: 0 | D15: 9 | F15: 0.04 | H15: stipend of 1 drover for 1 term 9pence.
A16: Cost of ploughs | B16: 0 | C16: 6 | D16: 0 | F16: 0.3 | H16: stipend of 2 ploughmen who are sometimes carters for the year 6 shilling.
A17: Cost of ploughs | B17: 2 | C17: 1 | D17: 3 | F17: 2.06 | H17: 4 oxen £2 1 shilling 3pence, at 10 shilling each for 3, and 11 shilling 3pence for 1..
A18: Cost of ploughs | B18: 0 | C18: 8 | D18: 0 | F18: =B18+C18/20+D18/240 | H18: forage bought 8 shilling
A19: Cost of ploughs | B19: 3 | C19: 13 | D19: 10.75 | F19: 3.69 | H19: Total, £3 13 shilling 10.75pence
A20: Cost of ploughs | F20: =SUM(F3:F18) | G20: =F20-F19 | H20: Total
A22: Cost of carts | B22: 0 | C22: 1 | D22: 10 | F22: 0.09 | H22: In 1 pair of wheels bought for clearing dung 1 shilling 10pence. | J22: =F22 | K22: =J22
A23: Cost of carts | B23: 0 | C23: 1 | D23: 2.5 | F23: 0.06 | H23: large nails bought for mending the cart 1 shilling 2.5pence. | J23: =F23 | K23: =J23
A24: Cost of carts | B24: 0 | C24: 0 | D24: 7 | F24: 0.03 | H24: fitting the cart with axles with axles bought for the same 7pence. | J24: =F24 | K24: =J24
A25: Cost of carts | B25: 0 | C25: 1 | D25: 2 | F25: 0.06 | H25: 2 collars bought 1 shilling 2pence. | J25: =F25 | K25: =J25
A26: Cost of carts | B26: 0 | C26: 0 | D26: 6 | F26: 0.03 | H26: 1 pair of saddle-pads 6pence. | J26: =F26 | K26: =J26
A27: Cost of carts | B27: 0 | C27: 0 | D27: 9.5 | F27: 0.04 | H27: clouts, nails and grease bought 9.5pence. | J27: =F27 | K27: =J27
A28: Cost of carts | B28: 0 | C28: 0 | D28: 4.5 | F28: 0.02 | H28: 1 pair of traces bought 4.5pencetethering. | J28: =F28 | K28: =J28
A29: Cost of carts | B29: 0 | C29: 0 | D29: 3 | F29: 0.01 | H29: 1 rope bought for horses in the pasture 3pence. | J29: =F29 | K29: =J29
A30: Cost of carts | B30: 0 | C30: 0 | D30: 3 | F30: 0.01 | H30: 2 halters bought 3pence. | J30: =F30 | K30: =J30
A31: Cost of carts | B31: 0 | C31: 3 | D31: 6 | F31: 0.17 | H31: shoeing 2 cart-horses for the year 3 shilling 6pence. | J31: =F31 | K31: =J31
A32: Cost of carts | B32: 0 | C32: 19 | D32: 1 | F32: 0.95 | H32: 1 cart-horse bought 19 shilling 1 pence.
A33: Cost of carts | B33: 0 | C33: 0 | D33: 6 | F33: =B33+C33/20+D33/240 | H33: 3 pieces of iron for 3 shovels 6pence | J33: =F33 | K33: =J33
A34: Cost of carts | B34: 1 | C34: 10 | D34: 0.5 | F34: 1.5 | H34: Total, £1 10 shilling 0.5pence
A35: Cost of carts | F35: =SUM(F22:F33) | G35: =F35-F34 | H35: Total
A37: Dairy | B37: 0 | C37: 1 | D37: 9 | F37: 0.09 | H37: In 7 bushels of salt bought for the dairy, 1 shilling 9pence this year, with the expenses of the harvest. | J37: =F37 | K37: =J37
A38: Dairy | B38: 0 | C38: 0 | D38: 4 | F38: 0.02 | H38: earthenware pots and pans bought for the same 4pence. | J38: =F38 | K38: =J38
A39: Dairy | B39: 0 | C39: 0 | D39: 9 | F39: 0.04 | H39: woollen and linen cloth 9pence. | J39: =F39 | K39: =J39
A40: Dairy | B40: 0 | C40: 0 | D40: 5 | F40: 0.02 | H40: a press bought 5pence. | J40: =F40 | K40: =J40
A41: Dairy | B41: 0 | C41: 0 | D41: 4 | F41: 0.02 | H41: 1 stall made anew for bullocks 4pence. | J41: =F41 | K41: =J41
A42: Dairy | B42: 0 | C42: 4 | D42: 4.5 | F42: 0.22 | H42: 15 ells of canvas bought for putting wool in 4 shilling 4.5pence, at 3.5pence an ell. | J42: =F42 | K42: =J42
...

Sheet Issues of the Grange
A1: Gross Output | B1: Total Quantity | C1: Account Total Quarters | D1: Bought in Total Quarters | E1: Received from churchscot | F1: Sold Total Quarters | G1: Difference Produced+Bought-Sold | H1: Weighted Average Price per Quarter | I1: Value of Total Production weighted
A2: wheat | B2: 58.125 | C2: 58.125 | D2: 0 | F2: 42.3125 | G2: =B2-F2 | H2: 0.28024876 | I2: =H2*B2
A3: curall | B3: 6.375 | C3: 6.375 | D3: 0 | F3: 6.375 | G3: =B3-F3 | H3: 0.16666667 | I3: =H3*B3
A4: rye | B4: 2.0625 | D4: 0 | E4: 2.0625 | G4: =B4-F4 | I4: =H4*B4
A5: maslin | B5: 7.625 | C5: 7.625 | D5: 0 | F5: 0.5 | G5: =B5-F5 | H5: 0.13333333 | I5: =H5*B5
A6: bere | B6: 25.25 | C6: 25.25 | D6: 0 | F6: 11 | G6: =B6-F6 | H6: 0.16666667 | I6: =H6*B6
A7: barley | B7: 93.125 | C7: 93.125 | D7: 0 | F7: 34.125 | G7: =B7-F7 | H7: 0.19010989 | I7: =H7*B7
A8: oats | B8: 108.25 | C8: 108.25 | D8: 0 | F8: 34.75 | G8: =B8-F8 | H8: 0.11966427 | I8: =H8*B8
A9: peas | B9: 11.875 | C9: 11.875 | D9: 0 | F9: 9.625 | G9: =B9-F9 | H9: 0.10779221 | I9: =H9*B9
A10: vetches | B10: 19.875 | C10: 19.875 | D10: 0 | F10: 14.375 | G10: =B10-F10 | H10: 0.066666667 | I10: =H10*B10
A12: Total Production
A13: Sales of corn (as recorded in accounts)
A16: Net output | B16: Gross output | C16: Seed quarters | D16: Seed bushels | E16: Seed total quarters | F16: tithe quarters | G16: tithe bushels | H16: tithe total | I16: manorial servants quarters | J16: manorial servants bushels | K16: manorial servants total quarters | L16: output net of tithe, seed, liveries | M16: in stock from last year | N16: Price in £ | O16: Value of net output in £ | P16: Value of sales (in "Sale of Corn") in £
A17: wheat | B17: =B2 | C17: 14.5 | E17: =C17+D17/8 | J17: =1+6+2+1.5+0.5+0.5 | K17: =I17+J17/8 | L17: =B17-E17-K17 | N17: =H2 | O17: =N17*L17
A18: curall | B18: =B3 | E18: =C18+D18/8 | K18: =I18+J18/8 | L18: =B18-E18-K18 | N18: =H3 | O18: =N18*L18
A19: rye | B19: =B4 | E19: =C19+D19/8 | K19: =I19+J19/8 | L19: =B19-E19-K19 | N19: =H4 | O19: =N19*L19
A20: maslin | B20: =B5 | E20: =C20+D20/8 | I20: 7 | J20: 1 | K20: =I20+J20/8 | L20: =B20-E20-K20 | N20: =H5 | O20: =N20*L20
A21: bere | B21: =B6 | C21: 5 | D21: 2 | E21: =C21+D21/8 | I21: 9 | K21: =I21+J21/8 | L21: =B21-E21-K21 | N21: =H6 | O21: =N21*L21
A22: barley | B22: =B7 | C22: 16 | D22: 1 | E22: =C22+D22/8 | I22: =6+17+4+2+7.5 | J22: =3+3+2+2 | K22: =I22+J22/8 | L22: =B22-E22-K22 | N22: =H7 | O22: =N22*L22
A23: oats | B23: =B8 | C23: 42 | D23: 1 | E23: =C23+D23/8 | I23: =15.5+14.5 | J23: =1+3+2+5 | K23: =I23+J23/8 | L23: =B23-E23-K23 | N23: =H8 | O23: =N23*L23
A24: peas | B24: =B9 | C24: 2 | D24: 2 | E24: =C24+D24/8 | K24: =I24+J24/8 | L24: =B24-E24-K24 | N24: =H9 | O24: =N24*L24
A25: vetches | B25: =B10 | C25: 2 | D25: 1 | E25: =C25+D25/8 | I25: 3 | J25: 3 | K25: =I25+J25/8 | L25: =B25-E25-K25 | N25: =H10 | O25: =N25*L25
A27: Total

Sheet Issues of the Mills

Sheet Stock
A1: DROXFORD STOCK ACCOUNT
C3: added | G3: subtracted
A4: Livestock | B4: Inherited stock | C4: added | D4: strays | E4: herbage | F4: churchscot | G4: of which in default | H4: sold | I4: in murrain | J4: accounted for elsewhere | K4: End-period stock | L4: cross-check | M4: stock building | N4: raw production | O4: Unit price (£) | P4: Value of stock (£) at given value | Q4: Value of stock (£) at sales prices | R4: Sales in (£) | S4: Value of stock building (£) | T4: Value of production (£) at sales prices | U4: Details
A5: Cart-horses | B5: 2 | C5: =1+1 | H5: 1 | J5: 1 | K5: 2 | O5: =R5/H5 | R5: =Receipts!F75
A6: Mares
A7: Plough horses | B7: 4 | C7: =1+1 | H7: 2 | K7: 4 | O7: =R7/H7 | R7: =Receipts!F76
A8: Colts (unspecified years)
A9: Colts (2 years)
A10: Colts (1 year)
A11: Foals
A12: Oxen | B12: 17 | C12: =4+4+1 | H12: 1 | I12: 1 | K12: 24 | O12: =R12/H12 | R12: =Receipts!F77
A13: Bulls | B13: 1 | K13: 1
A14: Cows | B14: 21 | C14: 2 | H14: 4 | K14: 19 | O14: =R14/H14 | R14: =Receipts!F78
A15: Steers | B15: 6 | J15: 6 | K15: 0
A16: Bullocks | B16: 6 | I16: 1 | K16: 5
A17: Yearlings | B17: 5 | K17: 5
A18: Calves | B18: 13 | H18: 6 | J18: 1 | K18: 6 | O18: =R18/H18 | R18: =Receipts!F79
A19: Wethers | B19: 280 | C19: 22 | H19: 34 | I19: =18+13 | K19: 243 | O19: =R19/H19 | R19: =Receipts!F80
A20: Rams | B20: 10 | K20: 10
A21: Ewes | B21: 380 | C21: 34 | H21: 40 | I21: =13+4+5 | J21: =7 | K21: 353 | O21: =R21/H21 | R21: =Receipts!F81
A22: Hoggs | B22: 75 | I22: =19 | J22: =22+34 | K22: 0
A23: Lambs | B23: 299 | H23: 48 | I23: =29+21+12 | J23: =27+2 | K23: 160 | O23: =R23/H23
A24: Boars
A25: Sows | B25: 3 | I25: 1 | K25: 2
A26: Pigs | B26: 33 | C26: =20+1 | H26: 25 | I26: 9 | K26: 20 | O26: =R26/H26 | R26: =Receipts!F82
A27: Hoggets | B27: 20 | J27: 20 | K27: 0
A28: Piglets | B28: 25 | C28: 1 | I28: 4 | J28: 2 | K28: 20
A29: Swans
A30: Peacocks
A31: Total Value | R31: =SUM(R5:R29)
A34: Wool
A35: Coarse wool | C35: 624 | J35: =2+622 | K35: 0 | O35: 0.02 | T35: =O35*J35
A36: Lamb's wool | C36: 172 | J36: 172 | K36: 0 | O36: 0.01 | T36: =O36*J36
A37: Wool locks | C37: 7 | H37: 7 | K37: 0 | O37: 0.04375 | T37: =O37*H37 | U37: measured in cloves
A38: Wool sold at shearing
A39: Total wool | T39: =SUM(T35:T38)
A42: Hides
A43: Ox hides | C43: 1 | H43: 1 | K43: 0 | O43: =R43/H43 | R43: =Receipts!F91 | T43: =O43*C43
A44: bullock | C44: 1 | H44: 1 | K44: 0 | O44: =R44/H44 | R44: =Receipts!F92 | T44: =O44*C44
A45: Mare | T45: =O45*C45
...

Sheet raw data
A1: Heading | B1: Sentence | C1: Total in Pounds | D1: Pounds | E1: Shillings | F1: Pence | G1: Corn | H1: Total Quarters Except 1 | I1: Total Bushels Except 1 | J1: Total Corn Cross-Check | K1: Total Corn Manorial Account | L1: Corn Quantity Error | M1: Quarters 1 | N1: Bushels 1 | O1: Quarters 2 | P1: Bushels 2 | Q1: Quarters 3 | R1: Bushels 3 | S1: Quarters 4 | T1: Bushels 4 | U1: shilling a quarter 1 | V1: pence a quarter 1 | W1: shilling a quarter 2 | X1: pence a quarter 2 | Y1: shilling a quarter 3 | Z1: pence a quarter 3 | AA1: shilling a quarter 4 | AB1: pence a quarter 4 | AC1: shilling a bushel 1 | AD1: pence a bushel 1 | AE1: shilling a bushel 2 | AF1: pence a bushel 2 | AG1: shilling a bushel 3 | AH1: pence a bushel 3 | AI1: shilling a bushel 4 | AJ1: pence a bushel 4
A2: Arrears | B2: Robert de Froyle, bailiff, and William ate Hatth', reeve, render account for £25 18 shilling 9.75pence of arrears from the previous year. | C2: 25.94 | D2: 25 | E2: 18 | F2: 9.75 | H2: 0 | I2: 0 | J2: 0 | K2: 0 | L2: 0 | M2: 0 | N2: 0
A3: Arrears | B3: All delivered to Sir Geoffrey, treasurer of Wolvesey, by 1 tally. | C3: 0 | D3: 0 | E3: 0 | F3: 0 | H3: 0 | I3: 0 | J3: 0 | K3: 0 | L3: 0 | M3: 0 | N3: 0
A4: Arrears | B4: They are quit. | C4: 0 | D4: 0 | E4: 0 | F4: 0 | H4: 0 | I4: 0 | J4: 0 | K4: 0 | L4: 0 | M4: 0 | N4: 0
A5: Rents of assize | B5: The same render account for £2 18 shilling 5pence from ox-gavel (oxeye) at the feast of St Thomas the Apostle (21 December). | C5: 2.92 | D5: 2 | E5: 18 | F5: 5 | H5: 0 | I5: 0 | J5: 0 | K5: 0 | L5: 0 | M5: 0 | N5: 0
A6: Rents of assize | B6: 17 shilling 10.5pence from wood-gavel (wodegavel) at Lammas (1 August). | C6: 0.89 | D6: 0 | E6: 17 | F6: 10.5 | H6: 0 | I6: 0 | J6: 0 | K6: 0 | L6: 0 | M6: 0 | N6: 0
A7: Rents of assize | B7: £20 19 shilling 3.5pence for rents of assize at Michaelmas (29 September). | C7: 20.96 | D7: 20 | E7: 19 | F7: 3.5 | H7: 0 | I7: 0 | J7: 0 | K7: 0 | L7: 0 | M7: 0 | N7: 0
A8: Rents of assize | B8: Total, £24 15 shilling 7.5pence | C8: 24.78 | D8: 24 | E8: 15 | F8: 7.5 | H8: 0 | I8: 0 | J8: 0 | K8: 0 | L8: 0 | M8: 0 | N8: 0
A9: Quittances | B9: In quittance of 3 ploughmen, 2 shepherds and 1 smith for the year 7 shilling 6pence, or 1 shilling 3pence each. | C9: 0.38 | D9: 0 | E9: 7 | F9: 6 | H9: 0 | I9: 0 | J9: 0 | K9: 0 | L9: 0 | M9: 0 | N9: 0
A10: Quittances | B10: the same for ox-gavel 6pence. | C10: 0.03 | D10: 0 | E10: 0 | F10: 6 | H10: 0 | I10: 0 | J10: 0 | K10: 0 | L10: 0 | M10: 0 | N10: 0
A11: Quittances | B11: 1 keeper of lambs from the Nativity of St John the Baptist to Michaelmas, for 1 term, 3.75pence Total, 8 shilling 3.75pence | C11: 0.42 | D11: 0 | E11: 8 | F11: 3.75 | H11: 0 | I11: 0 | J11: 0 | K11: 0 | L11: 0 | M11: 0 | N11: 0
A12: Defaults of rent | B12: In default of the land of William de Swanemere for ox-gavel because he is made free 7pence. | C12: 0.03 | D12: 0 | E12: 0 | F12: 7 | H12: 0 | I12: 0 | J12: 0 | K12: 0 | L12: 0 | M12: 0 | N12: 0
A13: Defaults of rent | B13: the land of Horn for the same 1 shilling. | C13: 0.05 | D13: 0 | E13: 1 | F13: 0 | H13: 0 | I13: 0 | J13: 0 | K13: 0 | L13: 0 | M13: 0 | N13: 0
... A46: Issues of the manor | B46: 4 shilling 9.25pence from Fyslod'. | C46: 0.24 | D46: 0 | E46: 4 | F46: 9.25 | H46: 0 | I46: 0 | J46: 0 | K46: 0 | L46: 0 | M46: 0 | N46: 0
A47: Issues of the manor | B47: 12 shilling 4.5pence from 2 quarters .5 bushels of rye from churchscot sold. | C47: 0.62 | D47: 0 | E47: 12 | F47: 4.5 | G47: rye | H47: 2 | I47: 5 | J47: 2.625 | K47: 2 | L47: 0.625 | M47: 2 | N47: 0 | O47: 0 | P47: 5
A48: Issues of the manor | B48: 5 shilling 1.5pence for release from carrying wood felled in preparation for Christmas this year. | C48: 0.26 | D48: 0 | E48: 5 | F48: 1.5 | H48: 0 | I48: 0 | J48: 0 | K48: 0 | L48: 0 | M48: 0 | N48: 0
A49: Issues of the manor | B49: 14 shilling 3pence from transport-service sold this year. | C49: 0.71 | D49: 0 | E49: 14 | F49: 3 | H49: 0 | I49: 0 | J49: 0 | K49: 0 | L49: 0 | M49: 0 | N49: 0
A50: Issues of the manor | B50: 3 shilling 11 pence from dairy produce sold at the audit. | C50: 0.2 | D50: 0 | E50: 3 | F50: 11 | H50: 0 | I50: 0 | J50: 0 | K50: 0 | L50: 0 | M50: 0 | N50: 0
A51: Issues of the manor | B51: Total, £5 15 shilling 1.5pence And for 10 shilling from 1 old cart-horse sold. | C51: 5.76 | D51: 5 | E51: 15 | F51: 1.5 | H51: 0 | I51: 0 | J51: 0 | K51: 0 | L51: 0 | M51: 0 | N51: 0
A52: Issues of the manor | B52: 9 shilling from 2 old plough-horses sold, at 3 shilling for 1, and 6 shilling for 1. | C52: 0.45 | D52: 0 | E52: 9 | F52: 0 | H52: 0 | I52: 0 | J52: 0 | K52: 0 | L52: 0 | M52: 0 | N52: 0
A53: Issues of the manor | B53: 9 shilling from 1 old ox sold. | C53: 0.45 | D53: 0 | E53: 9 | F53: 0 | H53: 0 | I53: 0 | J53: 0 | K53: 0 | L53: 0 | M53: 0 | N53: 0
A54: Issues of the manor | B54: £1 12 shilling 6pence from 4 old cows sold, at 7s .3pence each for 2, and 9 shilling each for 2. | C54: 1.62 | D54: 1 | E54: 12 | F54: 6 | H54: 0 | I54: 0 | J54: 0 | K54: 0 | L54: 0 | M54: 0 | N54: 0
A55: Issues of the manor | B55: 6 shilling from 6 late-born calves sold, at 1 shilling each. | C55: 0.3 | D55: 0 | E55: 6 | F55: 0 | H55: 0 | I55: 0 | J55: 0 | K55: 0 | L55: 0 | M55: 0 | N55: 0
A56: Issues of the manor | B56: £1 14 shilling from 34 wethers sold at Martinmas, at 1 shilling each. | C56: 1.7 | D56: 1 | E56: 14 | F56: 0 | H56: 0 | I56: 0 | J56: 0 | K56: 0 | L56: 0 | M56: 0 | N56: 0
A57: Issues of the manor | B57: £2 from 40 ewes sold. | C57: 2 | D57: 2 | E57: 0 | F57: 0 | H57: 0 | I57: 0 | J57: 0 | K57: 0 | L57: 0 | M57: 0 | N57: 0
A58: Issues of the manor | B58: £3 3 shilling 4pence from 25 pigs sold at Martinmas, at 2 shilling 4pence each for 10, and 2 shilling 8pence each for 15. | C58: 3.17 | D58: 3 | E58: 3 | F58: 4 | H58: 0 | I58: 0 | J58: 0 | K58: 0 | L58: 0 | M58: 0 | N58: 0
A59: Issues of the manor | B59: 10 shilling from 48 feeble lambs sold, at 2.5pence each. | C59: 0.51 | D59: 0 | E59: 10 | F59: 2.5 | H59: 0 | I59: 0 | J59: 0 | K59: 0 | L59: 0 | M59: 0 | N59: 0
... A72: Issues of the manor | B72: 4 shilling 6.5pence from 0.5 wey 1 clove of butter solpence Total, £16 5 shilling 4.75pence | C72: 16.27 | D72: 16 | E72: 5 | F72: 4.75 | H72: 0 | I72: 0 | J72: 0 | K72: 0 | L72: 0 | M72: 0 | N72: 0
A73: Sale of corn | B73: The same render account for £12 1 shilling 3.5pence from 42 quarters 2.5 bushels of wheat sold, at 4 shilling 8d a quarters for 5.5 quarters, 5 shilling a quarters for 17.5 quarters 3 bushels, and 6 shilling 8pence a quarters for 18.5 quarters. | C73: 12.06 | D73: 12 | E73: 1 | F73: 3.5 | G73: wheat | H73: 41.5 | I73: 3 | J73: 41.875 | K73: 42.3125 | L73: -0.4375 | M73: 42 | N73: 2.5 | O73: 5.5 | P73: 0 | Q73: 17.5 | R73: 3 | S73: 18.5 | T73: 0 | U73: 5 | V73: 0 | W73: 6 | X73: 8
A74: Sale of corn | B74: £1 1 shilling 3pence from 6 quarters 3 bushels of curall sold, at 3 shilling 4pence a quarters. | C74: 1.06 | D74: 1 | E74: 1 | F74: 3 | G74: curall | H74: 6 | I74: 3 | J74: 6.375 | K74: 6.375 | L74: 0 | M74: 6 | N74: 3 | U74: 3 | V74: 4
A75: Sale of corn | B75: 1 shilling 4pence from 4 bushels of maslin sold. | C75: 0.07 | D75: 0 | E75: 1 | F75: 4 | G75: maslin | H75: 0 | I75: 4 | J75: 0.5 | K75: 0.5 | L75: 0 | M75: 0 | N75: 4
A76: Sale of corn | B76: £1 16 shilling 8pence from 11 quarters of bere sold, at 3 shilling 4pence a quarters. | C76: 1.83 | D76: 1 | E76: 16 | F76: 8 | H76: 11 | I76: 0 | J76: 11 | K76: 11 | L76: 0 | M76: 11 | N76: 0 | U76: 3 | V76: 4
A77: Sale of corn | B77: £6 9 shilling 9pence from 34 quarters 1 bushels of barley sold, at 3 shilling 4pence a quarters for 10 quarters 1 bushels, and 4 shilling a quarters for 24 quarters. | C77: 6.49 | D77: 6 | E77: 9 | F77: 9 | G77: barley | H77: 34 | I77: 1 | J77: 34.125 | K77: 34.125 | L77: 0 | M77: 34 | N77: 1 | O77: 10 | P77: 1 | Q77: 24 | R77: 0 | U77: 3 | V77: 4 | W77: 4 | X77: 0
A78: Sale of corn | B78: £4 3 shilling 2pence from 34.5 quarters 2 bushels of oats sold, at 2 shilling a quarters for 14 quarters 2 bushels, and 2 shilling 8pence a quarters for 20.5. | C78: 4.16 | D78: 4 | E78: 3 | F78: 2 | G78: oats | H78: 14 | I78: 2 | J78: 14.25 | K78: 34.75 | L78: -20.5 | M78: 34.5 | N78: 2 | O78: 14 | P78: 2 | U78: 2 | V78: 0 | W78: 2 | X78: 8
A79: Sale of corn | B79: £1 9pence from 9.5quarters 1 bushels of peas sold, at 2 shilling a quarters for 7 quarters 3 bushels, and 2 shilling 8pence a quarters for 2 quarters 2 bushels. | C79: 1.04 | D79: 1 | E79: 0 | F79: 9 | G79: peas | H79: 9 | I79: 5 | J79: 9.625 | K79: 9.625 | L79: 0 | M79: 9.5 | N79: 1 | O79: 7 | P79: 3 | Q79: 2 | R79: 2 | U79: 2 | V79: 0 | W79: 2 | X79: 8
A80: Sale of corn | B80: £1 5 shilling 6.5 from 14 quarters 3 bushels of vetches sold, at 1 shilling 4pence a quarters for 8 quarters for 6 quarters 3 bushels Total, £27 19 shilling 9pence | C80: 1.25 | D80: 1 | E80: 5 | F80: 0 | G80: vetches | H80: 14 | I80: 3 | J80: 14.375 | K80: 14.375 | L80: 0 | M80: 14 | N80: 3 | O80: 8 | P80: 0 | Q80: 6 | R80: 3 | U80: 1 | V80: 4
A81: Entry and marriage fines | B81: The same render account for 10 shilling from Alice, relict of Cuppyng Breton, to retain 1 messuage and' virgate of land which belonged to her husband. | C81: 0.5 | D81: 0 | E81: 10 | F81: 0 | H81: 0 | I81: 0 | J81: 0 | K81: 0 | L81: 0 | M81: 0 | N81: 0
A82: Entry and marriage fines | B82: £1 from John Seyle to have 1 messuage and 0.5 virgate of land which belonged to Isabel his mother whose heir he is. | C82: 1 | D82: 1 | E82: 0 | F82: 0 | H82: 0 | I82: 0 | J82: 0 | K82: 0 | L82: 0 | M82: 0 | N82: 0
A83: Entry and marriage fines | B83: 2 shilling from William le Y1 to have 1 messuage and 1 ferling which belonged to Alice his mother whose heir he is. | C83: 0.1 | D83: 0 | E83: 2 | F83: 0 | H83: 0 | I83: 0 | J83: 0 | K83: 0 | L83: 0 | M83: 0 | N83: 0
A84: Entry and marriage fines | B84: 4 shilling from Joan la Hore to have 1 messuage and .5 virgate of land which belonged to John, son of her uncle, whose heir she is. | C84: 0.2 | D84: 0 | E84: 4 | F84: 0 | H84: 0 | I84: 0 | J84: 0 | K84: 0 | L84: 0 | M84: 0 | N84: 0
...

Sheet Issues of the Grange raw
A1: Heading | B1: Sentence | C1: Quarters 1_x | D1: Bushels 1_x | E1: Sown Quarters | F1: Sown Bushels | G1: Sown Total Quarters | H1: Bought in Quarters | I1: Bought in Bushels | J1: Bought in Total Quarters | K1: Tithe Quarters | L1: Tithe Bushels | M1: Tithe Total Quarters | N1: Manorial servants & livestock Quarters | O1: Manorial servants & livestock Bushels | P1: Manorial servants & livestock Total Quarters | Q1: Sold Quarters | R1: Sold Bushels | S1: Sold Total Quarters | T1: Account Quarters | U1: Account Bushels | V1: Account Total Quarters | W1: bought only | X1: Total Quarters Except 1 | Y1: Total Bushels Except 1 | Z1: Total Corn Cross-Check | AA1: Total Corn Manorial Account | AB1: Corn Quantity Error | AC1: Quarters 1_y | AD1: Bushels 1_y | AE1: Quarters 2 | AF1: Bushels 2 | AG1: Quarters 3 | AH1: Bushels 3 | AI1: Quarters 4 | AJ1: Bushels 4
A2: And he owes | B2: Total | C2: 0 | D2: 0 | E2: 0 | F2: 0 | G2: 0 | H2: 0 | I2: 0 | J2: 0 | K2: 0 | L2: 0 | M2: 0 | N2: 0 | O2: 0 | P2: 0 | Q2: 0 | R2: 0 | S2: 0 | T2: 0 | U2: 0 | V2: 0 | W2: 0
A3: Wheat | B3: {yield: 1 qr 5 bushels} | C3: 0 | D3: 0 | E3: 0 | F3: 0 | G3: 0 | H3: 0 | I3: 0 | J3: 0 | K3: 0 | L3: 0 | M3: 0 | N3: 0 | O3: 0 | P3: 0 | Q3: 0 | R3: 0 | S3: 0 | T3: 0 | U3: 0 | V3: 0 | W3: 0
A4: Wheat | B4: The same render account for 47.5 quarters from the whole issue of wheat by struck measure. | C4: 0 | D4: 0 | E4: 0 | F4: 0 | G4: 0 | H4: 0 | I4: 0 | J4: 0 | K4: 0 | L4: 0 | M4: 0 | N4: 0 | O4: 0 | P4: 0 | Q4: 0 | R4: 0 | S4: 0 | T4: 47.5 | U4: 0 | V4: 47.5 | W4: 0 | X4: 47.5 | Y4: 0 | Z4: 47.5 | AA4: 47.5 | AB4: 0 | AC4: 47.5 | AD4: 0
A5: Wheat | B5: 10.5 quarters 2.5 bushels from churchscot. | C5: 0 | D5: 0 | E5: 0 | F5: 0 | G5: 0 | H5: 0 | I5: 0 | J5: 0 | K5: 0 | L5: 0 | M5: 0 | N5: 0 | O5: 0 | P5: 0 | Q5: 0 | R5: 0 | S5: 0 | T5: 0 | U5: 0 | V5: 0 | W5: 0 | X5: 10.5 | Y5: 2.5 | Z5: 10.8125 | AA5: 10.8125 | AB5: 0 | AC5: 10.5 | AD5: 2.5
A6: Wheat | B6: Total, 58 quarters 2.5 bushels | C6: 0 | D6: 0 | E6: 0 | F6: 0 | G6: 0 | H6: 0 | I6: 0 | J6: 0 | K6: 0 | L6: 0 | M6: 0 | N6: 0 | O6: 0 | P6: 0 | Q6: 0 | R6: 0 | S6: 0 | T6: 0 | U6: 0 | V6: 0 | W6: 0 | X6: 58 | Y6: 2.5 | Z6: 58.3125 | AA6: 58.3125 | AB6: 0 | AC6: 58 | AD6: 2.5
A7: Wheat | B7: Sown over 154.5 acres which lie in le Sorelond', Tonforlong', le Suthemestecrofte, and Fomden', 14.5 quarters. | C7: 0 | D7: 0 | E7: 14.5 | F7: 0 | G7: 14.5 | H7: 0 | I7: 0 | J7: 0 | K7: 0 | L7: 0 | M7: 0 | N7: 0 | O7: 0 | P7: 0 | Q7: 0 | R7: 0 | S7: 0 | T7: 0 | U7: 0 | V7: 0 | W7: 0 | X7: 14.5 | Y7: 0 | Z7: 14.5 | AA7: 14.5 | AB7: 0 | AC7: 14.5 | AD7: 0
A8: Wheat | B8: that is, 1.5 bushels over 2 acres. | C8: 0 | D8: 0 | E8: 0 | F8: 0 | G8: 0 | H8: 0 | I8: 0 | J8: 0 | K8: 0 | L8: 0 | M8: 0 | N8: 0 | O8: 0 | P8: 0 | Q8: 0 | R8: 0 | S8: 0 | T8: 0 | U8: 0 | V8: 0 | W8: 0 | X8: 0 | Y8: 1.5 | Z8: 0.1875 | AA8: 0.1875 | AB8: 0 | AC8: 0 | AD8: 1.5
A9: Wheat | B9: . | C9: 0 | D9: 0 | E9: 0 | F9: 0 | G9: 0 | H9: 0 | I9: 0 | J9: 0 | K9: 0 | L9: 0 | M9: 0 | N9: 0 | O9: 0 | P9: 0 | Q9: 0 | R9: 0 | S9: 0 | T9: 0 | U9: 0 | V9: 0 | W9: 0 | X9: 0 | Y9: 0 | Z9: 0 | AA9: 0 | AB9: 0 | AC9: 0 | AD9: 0
A10: Wheat | B10: . | C10: 0 | D10: 0 | E10: 0 | F10: 0 | G10: 0 | H10: 0 | I10: 0 | J10: 0 | K10: 0 | L10: 0 | M10: 0 | N10: 0 | O10: 0 | P10: 0 | Q10: 0 | R10: 0 | S10: 0 | T10: 0 | U10: 0 | V10: 0 | W10: 0 | X10: 0 | Y10: 0 | Z10: 0 | AA10: 0 | AB10: 0 | AC10: 0 | AD10: 0
A11: Wheat | B11: customary payment to 1 sower, 1 bushels. | C11: 0 | D11: 0 | E11: 0 | F11: 0 | G11: 0 | H11: 0 | I11: 0 | J11: 0 | K11: 0 | L11: 0 | M11: 0 | N11: 0 | O11: 0 | P11: 0 | Q11: 0 | R11: 0 | S11: 0 | T11: 0 | U11: 0 | V11: 0 | W11: 0 | X11: 0 | Y11: 1 | Z11: 0.125 | AA11: 0.125 | AB11: 0 | AC11: 0 | AD11: 1
A12: Wheat | B12: provision of 1 reeve, 1 hayward keeping the woods and pasture, and 1 beadle, from Lammas until the Decollation of St John the Baptist, for 4 weeks, 6 bushels Nothing for the provison of the steward this year. | C12: 0 | D12: 0 | E12: 0 | F12: 0 | G12: 0 | H12: 0 | I12: 0 | J12: 0 | K12: 0 | L12: 0 | M12: 0 | N12: 0 | O12: 0 | P12: 0 | Q12: 0 | R12: 0 | S12: 0 | T12: 0 | U12: 0 | V12: 0 | W12: 0 | X12: 0 | Y12: 6 | Z12: 0.75 | AA12: 0.75 | AB12: 0 | AC12: 0 | AD12: 6
A13: Wheat | B13: . | C13: 0 | D13: 0 | E13: 0 | F13: 0 | G13: 0 | H13: 0 | I13: 0 | J13: 0 | K13: 0 | L13: 0 | M13: 0 | N13: 0 | O13: 0 | P13: 0 | Q13: 0 | R13: 0 | S13: 0 | T13: 0 | U13: 0 | V13: 0 | W13: 0 | X13: 0 | Y13: 0 | Z13: 0 | AA13: 0 | AB13: 0 | AC13: 0 | AD13: 0
A14: Wheat | B14: . | C14: 0 | D14: 0 | E14: 0 | F14: 0 | G14: 0 | H14: 0 | I14: 0 | J14: 0 | K14: 0 | L14: 0 | M14: 0 | N14: 0 | O14: 0 | P14: 0 | Q14: 0 | R14: 0 | S14: 0 | T14: 0 | U14: 0 | V14: 0 | W14: 0 | X14: 0 | Y14: 0 | Z14: 0 | AA14: 0 | AB14: 0 | AC14: 0 | AD14: 0
A15: Wheat | B15: default of the land of Horn for churchscot, 2 bushels. | C15: 0 | D15: 0 | E15: 0 | F15: 0 | G15: 0 | H15: 0 | I15: 0 | J15: 0 | K15: 0 | L15: 0 | M15: 0 | N15: 0 | O15: 0 | P15: 0 | Q15: 0 | R15: 0 | S15: 0 | T15: 0 | U15: 0 | V15: 0 | W15: 0 | X15: 0 | Y15: 2 | Z15: 0.25 | AA15: 0.25 | AB15: 0 | AC15: 0 | AD15: 2
... A19: Wheat | B19: Sold, 42 quarters 2.5 bushels It balances. | C19: 0 | D19: 0 | E19: 0 | F19: 0 | G19: 0 | H19: 0 | I19: 0 | J19: 0 | K19: 0 | L19: 0 | M19: 0 | N19: 0 | O19: 0 | P19: 0 | Q19: 42 | R19: 2.5 | S19: 42.3125 | T19: 0 | U19: 0 | V19: 0 | W19: 0 | X19: 42 | Y19: 2.5 | Z19: 42.3125 | AA19: 42.3125 | AB19: 0 | AC19: 42 | AD19: 2.5
A20: Wheat | B20: Total | C20: 0 | D20: 0 | E20: 0 | F20: 0 | G20: 0 | H20: 0 | I20: 0 | J20: 0 | K20: 0 | L20: 0 | M20: 0 | N20: 0 | O20: 0 | P20: 0 | Q20: 0 | R20: 0 | S20: 0 | T20: 0 | U20: 0 | V20: 0 | W20: 0
A21: Curall | B21: The same render account for 6 quarters 3 bushels from the whole issue of curall by struck measure. | C21: 0 | D21: 0 | E21: 0 | F21: 0 | G21: 0 | H21: 0 | I21: 0 | J21: 0 | K21: 0 | L21: 0 | M21: 0 | N21: 0 | O21: 0 | P21: 0 | Q21: 0 | R21: 0 | S21: 0 | T21: 6 | U21: 3 | V21: 6.375 | W21: 0 | X21: 6 | Y21: 3 | Z21: 6.375 | AA21: 6.375 | AB21: 0 | AC21: 6 | AD21: 3
A22: Curall | B22: Sold, 6 quarters 3 bushels | C22: 0 | D22: 0 | E22: 0 | F22: 0 | G22: 0 | H22: 0 | I22: 0 | J22: 0 | K22: 0 | L22: 0 | M22: 0 | N22: 0 | O22: 0 | P22: 0 | Q22: 6 | R22: 3 | S22: 6.375 | T22: 0 | U22: 0 | V22: 0 | W22: 0 | X22: 6 | Y22: 3 | Z22: 6.375 | AA22: 6.375 | AB22: 0 | AC22: 6 | AD22: 3
A23: Curall | B23: Total | C23: 0 | D23: 0 | E23: 0 | F23: 0 | G23: 0 | H23: 0 | I23: 0 | J23: 0 | K23: 0 | L23: 0 | M23: 0 | N23: 0 | O23: 0 | P23: 0 | Q23: 0 | R23: 0 | S23: 0 | T23: 0 | U23: 0 | V23: 0 | W23: 0
A24: Rye | B24: The same render account for 2 quarters 0.5 bushels of rye from churchscot. | C24: 0 | D24: 0 | E24: 0 | F24: 0 | G24: 0 | H24: 0 | I24: 0 | J24: 0 | K24: 0 | L24: 0 | M24: 0 | N24: 0 | O24: 0 | P24: 0 | Q24: 0 | R24: 0 | S24: 0 | T24: 2 | U24: 0.5 | V24: 2.0625 | W24: 0 | X24: 2 | Y24: 0.5 | Z24: 2.0625 | AA24: 2.0625 | AB24: 0 | AC24: 2 | AD24: 0.5
A25: Rye | B25: Sold, 2 quarters 0.5 bushels | C25: 0 | D25: 0 | E25: 0 | F25: 0 | G25: 0 | H25: 0 | I25: 0 | J25: 0 | K25: 0 | L25: 0 | M25: 0 | N25: 0 | O25: 0 | P25: 0 | Q25: 2 | R25: 0.5 | S25: 2.0625 | T25: 0 | U25: 0 | V25: 0 | W25: 0 | X25: 2 | Y25: 0.5 | Z25: 2.0625 | AA25: 2.0625 | AB25: 0 | AC25: 2 | AD25: 0.5
A26: Rye | B26: Total | C26: 0 | D26: 0 | E26: 0 | F26: 0 | G26: 0 | H26: 0 | I26: 0 | J26: 0 | K26: 0 | L26: 0 | M26: 0 | N26: 0 | O26: 0 | P26: 0 | Q26: 0 | R26: 0 | S26: 0 | T26: 0 | U26: 0 | V26: 0 | W26: 0
A27: Maslin | B27: {yield: two-fold plus . . . 1 bushels} | C27: 0 | D27: 0 | E27: 0 | F27: 0 | G27: 0 | H27: 0 | I27: 0 | J27: 0 | K27: 0 | L27: 0 | M27: 0 | N27: 0 | O27: 0 | P27: 0 | Q27: 0 | R27: 0 | S27: 0 | T27: 0 | U27: 0 | V27: 0 | W27: 0 | X27: 0 | Y27: 1 | Z27: 0.125 | AA27: 0.125 | AB27: 0 | AC27: 0 | AD27: 1
A28: Maslin | B28: The same render account for 7.5 quarters 1 bushels from the whole issue of maslin by struck measure. | C28: 0 | D28: 0 | E28: 0 | F28: 0 | G28: 0 | H28: 0 | I28: 0 | J28: 0 | K28: 0 | L28: 0 | M28: 0 | N28: 0 | O28: 0 | P28: 0 | Q28: 0 | R28: 0 | S28: 0 | T28: 7.5 | U28: 1 | V28: 7.625 | W28: 0 | X28: 7.5 | Y28: 1 | Z28: 7.625 | AA28: 7.625 | AB28: 0 | AC28: 7.5 | AD28: 1
A29: Maslin | B29: Mixed with barley, 7 quarters 1 bushels Sold, 4 bushels | C29: 0 | D29: 0 | E29: 0 | F29: 0 | G29: 0 | H29: 0 | I29: 0 | J29: 0 | K29: 0 | L29: 0 | M29: 0 | N29: 0 | O29: 0 | P29: 0 | Q29: 7 | R29: 1 | S29: 7.125 | T29: 0 | U29: 0 | V29: 0 | W29: 0 | X29: 7 | Y29: 4 | Z29: 7.5 | AA29: 7.125 | AB29: 0.375 | AC29: 7 | AD29: 1 | AE29: 0 | AF29: 4
A30: Maslin | B30: Total | C30: 0 | D30: 0 | E30: 0 | F30: 0 | G30: 0 | H30: 0 | I30: 0 | J30: 0 | K30: 0 | L30: 0 | M30: 0 | N30: 0 | O30: 0 | P30: 0 | Q30: 0 | R30: 0 | S30: 0 | T30: 0 | U30: 0 | V30: 0 | W30: 0
A31: Barley | B31: (yield: 5-fold . 1 qr 1 bushels) | C31: 0 | D31: 0 | E31: 0 | F31: 0 | G31: 0 | H31: 0 | I31: 0 | J31: 0 | K31: 0 | L31: 0 | M31: 0 | N31: 0 | O31: 0 | P31: 0 | Q31: 0 | R31: 0 | S31: 0 | T31: 0 | U31: 0 | V31: 0 | W31: 0
A32: Barley | B32: The same render account for 73.5 quarters 1 bushels from the whole issue of barley by struck measure. | C32: 0 | D32: 0 | E32: 0 | F32: 0 | G32: 0 | H32: 0 | I32: 0 | J32: 0 | K32: 0 | L32: 0 | M32: 0 | N32: 0 | O32: 0 | P32: 0 | Q32: 0 | R32: 0 | S32: 0 | T32: 73.5 | U32: 1 | V32: 73.625 | W32: 0 | X32: 73.5 | Y32: 1 | Z32: 73.625 | AA32: 73.625 | AB32: 0 | AC32: 73.5 | AD32: 1
A33: Barley | B33: 7 quarters 1 bushels received above from maslin. | C33: 0 | D33: 0 | E33: 0 | F33: 0 | G33: 0 | H33: 0 | I33: 0 | J33: 0 | K33: 0 | L33: 0 | M33: 0 | N33: 0 | O33: 0 | P33: 0 | Q33: 0 | R33: 0 | S33: 0 | T33: 0 | U33: 0 | V33: 0 | W33: 0 | X33: 7 | Y33: 1 | Z33: 7.125 | AA33: 7.125 | AB33: 0 | AC33: 7 | AD33: 1
A34: Barley | B34: 9 quarters received above from bere. | C34: 0 | D34: 0 | E34: 0 | F34: 0 | G34: 0 | H34: 0 | I34: 0 | J34: 0 | K34: 0 | L34: 0 | M34: 0 | N34: 0 | O34: 0 | P34: 0 | Q34: 0 | R34: 0 | S34: 0 | T34: 0 | U34: 0 | V34: 0 | W34: 0 | X34: 9 | Y34: 0 | Z34: 9 | AA34: 9 | AB34: 0 | AC34: 9 | AD34: 0
A35: Barley | B35: 3 quarters 3 bus, received from vetches for the liveries of the manorial servants. | C35: 0 | D35: 0 | E35: 0 | F35: 0 | G35: 0 | H35: 0 | I35: 0 | J35: 0 | K35: 0 | L35: 0 | M35: 0 | N35: 3 | O35: 0 | P35: 3 | Q35: 0 | R35: 0 | S35: 0 | T35: 0 | U35: 0 | V35: 0 | W35: 0
A36: Barley | B36: Total, 93 quarters 1 bushels | C36: 0 | D36: 0 | E36: 0 | F36: 0 | G36: 0 | H36: 0 | I36: 0 | J36: 0 | K36: 0 | L36: 0 | M36: 0 | N36: 0 | O36: 0 | P36: 0 | Q36: 0 | R36: 0 | S36: 0 | T36: 0 | U36: 0 | V36: 0 | W36: 0 | X36: 93 | Y36: 1 | Z36: 93.125 | AA36: 93.125 | AB36: 0 | AC36: 93 | AD36: 1
A37: Barley | B37: Sown over 86 acres as they lie in le Harnesgate, le Grove, and Tonforlong' behind the garden, 16 quarters 1 bushels. | C37: 0 | D37: 0 | E37: 16 | F37: 1 | G37: 16.125 | H37: 0 | I37: 0 | J37: 0 | K37: 0 | L37: 0 | M37: 0 | N37: 0 | O37: 0 | P37: 0 | Q37: 0 | R37: 0 | S37: 0 | T37: 0 | U37: 0 | V37: 0 | W37: 0 | X37: 16 | Y37: 1 | Z37: 16.125 | AA37: 16.125 | AB37: 0 | AC37: 16 | AD37: 1
A38: Barley | B38: that is, 1.5 bushels an acre. | C38: 0 | D38: 0 | E38: 0 | F38: 0 | G38: 0 | H38: 0 | I38: 0 | J38: 0 | K38: 0 | L38: 0 | M38: 0 | N38: 0 | O38: 0 | P38: 0 | Q38: 0 | R38: 0 | S38: 0 | T38: 0 | U38: 0 | V38: 0 | W38: 0 | X38: 0 | Y38: 1.5 | Z38: 0.1875 | AA38: 0.1875 | AB38: 0 | AC38: 0 | AD38: 1.5
A39: Barley | B39: . | C39: 0 | D39: 0 | E39: 0 | F39: 0 | G39: 0 | H39: 0 | I39: 0 | J39: 0 | K39: 0 | L39: 0 | M39: 0 | N39: 0 | O39: 0 | P39: 0 | Q39: 0 | R39: 0 | S39: 0 | T39: 0 | U39: 0 | V39: 0 | W39: 0 | X39: 0 | Y39: 0 | Z39: 0 | AA39: 0 | AB39: 0 | AC39: 0 | AD39: 0
A40: Barley | B40: . | C40: 0 | D40: 0 | E40: 0 | F40: 0 | G40: 0 | H40: 0 | I40: 0 | J40: 0 | K40: 0 | L40: 0 | M40: 0 | N40: 0 | O40: 0 | P40: 0 | Q40: 0 | R40: 0 | S40: 0 | T40: 0 | U40: 0 | V40: 0 | W40: 0 | X40: 0 | Y40: 0 | Z40: 0 | AA40: 0 | AB40: 0 | AC40: 0 | AD40: 0
A41: Barley | B41: . | C41: 0 | D41: 0 | E41: 0 | F41: 0 | G41: 0 | H41: 0 | I41: 0 | J41: 0 | K41: 0 | L41: 0 | M41: 0 | N41: 0 | O41: 0 | P41: 0 | Q41: 0 | R41: 0 | S41: 0 | T41: 0 | U41: 0 | V41: 0 | W41: 0 | X41: 0 | Y41: 0 | Z41: 0 | AA41: 0 | AB41: 0 | AC41: 0 | AD41: 0
A42: Barley | B42: customary payment to 1 sower, 1 bushels. | C42: 0 | D42: 0 | E42: 0 | F42: 0 | G42: 0 | H42: 0 | I42: 0 | J42: 0 | K42: 0 | L42: 0 | M42: 0 | N42: 0 | O42: 0 | P42: 0 | Q42: 0 | R42: 0 | S42: 0 | T42: 0 | U42: 0 | V42: 0 | W42: 0 | X42: 0 | Y42: 1 | Z42: 0.125 | AA42: 0.125 | AB42: 0 | AC42: 0 | AD42: 1
A43: Barley | B43: customary payment to 1 smith, 3 bushels. | C43: 0 | D43: 0 | E43: 0 | F43: 0 | G43: 0 | H43: 0 | I43: 0 | J43: 0 | K43: 0 | L43: 0 | M43: 0 | N43: 0 | O43: 0 | P43: 0 | Q43: 0 | R43: 0 | S43: 0 | T43: 0 | U43: 0 | V43: 0 | W43: 0 | X43: 0 | Y43: 3 | Z43: 0.375 | AA43: 0.375 | AB43: 0 | AC43: 0 | AD43: 3
...

Sheet Sale of Corn Prices
A1: Heading | B1: Sentence | C1: Total in Pounds | D1: Pounds | E1: Shillings | F1: Pence | G1: Corn | H1: Total Quarters Except 1 | I1: Total Bushels Except 1 | J1: Total Corn Cross-Check | K1: Total Corn Manorial Account | L1: Corn Quantity Error | M1: Quarters 0 | N1: Bushels 0 | O1: shilling a quarter 1 | P1: pence a quarter 1 | Q1: Quarters 1 | R1: Bushels 1 | S1: shilling a quarter 2 | T1: pence a quarter 2 | U1: Quarters 2 | V1: Bushels 2 | W1: shilling a quarter 3 | X1: pence a quarter 3 | Y1: Quarters 3 | Z1: Bushels 3 | AA1: shilling a quarter 4 | AB1: pence a quarter 4 | AC1: £ a quarter 1 | AD1: £ a quarter 2 | AE1: £ a quarter 3 | AF1: £ a quarter 4 | AG1: Quarters Sold | AH1: Weighted Average Price per Quarter | AI1: Non-Weighted Average Price per Quarter | AJ1: Corn lowercase
A2: Sale of corn | B2: The same render account for £12 1 shilling 3.5pence from 42 quarters 2.5 bushels of wheat sold, at 4 shilling 8d a quarters for 5.5 quarters, 5 shilling a quarters for 17.5 quarters 3 bushels, and 6 shilling 8pence a quarters for 18.5 quarters. | C2: 12.06 | D2: 12 | E2: 1 | F2: 3.5 | G2: wheat | H2: 41.5 | I2: 3 | J2: 41.875 | K2: 42.3125 | L2: -0.4375 | M2: 42 | N2: 2.5 | O2: 5 | P2: 0 | Q2: 5.5 | R2: 0 | S2: 6 | T2: 8 | U2: 17.5 | V2: 3 | Y2: 18.5 | Z2: 0 | AC2: 0.25 | AD2: 0.33333333 | AG2: 42.3125 | AH2: 0.31372549 | AI2: 0.29166667 | AJ2: wheat
A3: Sale of corn | B3: £1 1 shilling 3pence from 6 quarters 3 bushels of curall sold, at 3 shilling 4pence a quarters. | C3: 1.06 | D3: 1 | E3: 1 | F3: 3 | G3: curall | H3: 6 | I3: 3 | J3: 6.375 | K3: 6.375 | L3: 0 | M3: 6 | N3: 3 | O3: 3 | P3: 4 | AC3: 0.16666667 | AG3: 6.375 | AH3: 0.16666667 | AI3: 0.16666667 | AJ3: curall
A4: Sale of corn | B4: 1 shilling 4pence from 4 bushels of maslin sold. | C4: 0.07 | D4: 0 | E4: 1 | F4: 4 | G4: maslin | H4: 0 | I4: 4 | J4: 0.5 | K4: 0.5 | L4: 0 | M4: 0 | N4: 4 | AC4: 0.14 | AG4: 0.5 | AH4: 0.14 | AI4: 0.14 | AJ4: maslin
A5: Sale of corn | B5: £1 16 shilling 8pence from 11 quarters of bere sold, at 3 shilling 4pence a quarters. | C5: 1.83 | D5: 1 | E5: 16 | F5: 8 | H5: 11 | I5: 0 | J5: 11 | K5: 11 | L5: 0 | M5: 11 | N5: 0 | O5: 3 | P5: 4 | AC5: 0.16666667 | AG5: 11 | AH5: 0.16666667 | AI5: 0.16666667
A6: Sale of corn | B6: £6 9 shilling 9pence from 34 quarters 1 bushels of barley sold, at 3 shilling 4pence a quarters for 10 quarters 1 bushels, and 4 shilling a quarters for 24 quarters. | C6: 6.49 | D6: 6 | E6: 9 | F6: 9 | G6: barley | H6: 34 | I6: 1 | J6: 34.125 | K6: 34.125 | L6: 0 | M6: 34 | N6: 1 | O6: 3 | P6: 4 | Q6: 10 | R6: 1 | S6: 4 | T6: 0 | U6: 24 | V6: 0 | AC6: 0.16666667 | AD6: 0.2 | AG6: 34.125 | AH6: 0.19010989 | AI6: 0.18333333 | AJ6: barley
A7: Sale of corn | B7: £4 3 shilling 2pence from 34.5 quarters 2 bushels of oats sold, at 2 shilling a quarters for 14 quarters 2 bushels, and 2 shilling 8pence a quarters for 20.5. | C7: 4.16 | D7: 4 | E7: 3 | F7: 2 | G7: oats | H7: 14 | I7: 2 | J7: 14.25 | K7: 34.75 | L7: -20.5 | M7: 34.5 | N7: 2 | O7: 2 | P7: 0 | Q7: 14 | R7: 2 | S7: 2 | T7: 8 | AC7: 0.1 | AD7: 0.13333333 | AG7: 34.75 | AI7: 0.11666667 | AJ7: oats
A8: Sale of corn | B8: £1 9pence from 9.5quarters 1 bushels of peas sold, at 2 shilling a quarters for 7 quarters 3 bushels, and 2 shilling 8pence a quarters for 2 quarters 2 bushels. | C8: 1.04 | D8: 1 | E8: 0 | F8: 9 | G8: peas | H8: 9 | I8: 5 | J8: 9.625 | K8: 9.625 | L8: 0 | M8: 9.5 | N8: 1 | O8: 2 | P8: 0 | Q8: 7 | R8: 3 | S8: 2 | T8: 8 | U8: 2 | V8: 2 | AC8: 0.1 | AD8: 0.13333333 | AG8: 9.625 | AH8: 0.10779221 | AI8: 0.11666667 | AJ8: peas
A9: Sale of corn | B9: £1 5 shilling 6.5 from 14 quarters 3 bushels of vetches sold, at 1 shilling 4pence a quarters for 8 quarters for 6 quarters 3 bushels Total, £27 19 shilling 9pence | C9: 1.25 | D9: 1 | E9: 5 | F9: 0 | G9: vetches | H9: 14 | I9: 3 | J9: 14.375 | K9: 14.375 | L9: 0 | M9: 14 | N9: 3 | O9: 1 | P9: 4 | Q9: 8 | R9: 0 | U9: 6 | V9: 3 | AC9: 0.066666667 | AG9: 14.375 | AH9: 0.066666667 | AI9: 0.066666667 | AJ9: vetches
