Workbook

Sheet EastMeon Overview - Completed
A1: EASTMEON OVERVIEW - COMPLETED | B1: Total in £ | C1: Error | D1: Note
A2: CASH ACCOUNT
A3: RECEIPTS
A4: Arrears total | B4: 94.24
A5: Rents of assize total | B5: 97.34
A6: Quittances total | B6: 2.125
A7: Defaults of rent total | B7: 9.6066667
A8: Defaults of rent through the pestilence total
A9: Cotlands defaults total
A10: Cotlands total
A11: Total of quittances and defaults of rent total | B11: 11.73
A12: Total of rents remaining clear total
A13: Farms total
A14: Annual recognizances total | B14: 0.1
A15: Issues of the Manor total | B15: 26.363125
A16: Issues of the tenements in the lord's hands total
A17: Sale of labour services total
A18: Sale of corn total | B18: 111.81
A19: Entry and marriage fines total | B19: 23.41
A20: Pleas & perquisites total
A21: Forfeited chattels total
A22: Farm of the demesne land total
A23: Total of all receipts (calculated here) | B23: =SUM(B5:B22)
A24: Total of all receipts (calculated here) incl arrears | B24: =SUM(B4:B22)
A25: Total recorded in the accounts excl. arrears | B25: 270.1 | C25: =B23-B25
A26: Total recorded in the accounts incl. arrears | B26: =B25+B4
A29: EXPENSES
A30: Cost of ploughs total | B30: 15.36
A31: Purchase of corn total
A32: Cost of carts and wagons total
A33: Cost of dairy total
A34: Purchase of stock total
A35: Sheepcote total
A36: Cost of buildings total | B36: 0.63333333
A37: Threshing total | B37: 5.3645833
A38: Barley expenses
A39: Expenses of the harvest total
A40: Necessary expenses
A41: Wages of the bailiff
A42: Steward's expenses total | B42: 7.5104167
...

Sheet Prices
A1: Meat & Dairy Prices
C2: 1301 | D2: 1302 | E2: Average
A3: Beef | B3: £ per lb | C3: 0.0033351854 | D3: 0.0032608538 | E3: =AVERAGE(C3:D3)
A4: Mutton | B4: £ per lb | C4: 0.0036593977 | D4: 0.0037125513 | E4: =AVERAGE(C4:D4)
A5: Pork | B5: £ per lb | C5: 0.0038431326 | D5: 0.0037574803 | E5: =AVERAGE(C5:D5)
A6: Cheese | B6: £ per lb | C6: 0.0055768754 | D6: 0.0056654898 | E6: =AVERAGE(C6:D6)
A7: Butter | B7: £ per lb | C7: 0.0036626221 | D7: 0.0035935077 | E7: =AVERAGE(C7:D7)
A8: Milk | B8: £ per gallon | C8: 0.0055768754 | D8: 0.0056654898 | E8: =AVERAGE(C8:D8)

Sheet Labour Rents

Sheet Overview
A1: EAST MEON | B1: Total in £ | C1: Error | D1: Note
A2: CASH ACCOUNT
A3: RECEIPTS
A4: Arrears total
A5: Rents of assize total
A6: Quittances total
A7: Defaults of rent total
A8: Defaults of rent through the pestilence total
A9: Cotlands defaults total
A10: Cotlands total
A11: Total of quittances and defaults of rent total
A12: Total of rents remaining clear total
A13: Farms total
... A22: Farm of the demesne land total
A23: Total of all receipts (calculated here) | B23: =Receipts!F206
A24: Total of all receipts (calculated here) incl arrears | B24: =Receipts!F207
A25: Total recorded in the accounts excl. arrears | B25: =Receipts!F205
A26: Total recorded in the accounts incl. arrears
A29: EXPENSES
A30: Cost of ploughs total
A31: Purchase of corn total
A32: Cost of carts and wagons total
A33: Cost of dairy total
A34: Purchase of stock total
A35: Sheepcote total
A36: Cost of buildings total
A37: Threshing total
A38: Barley expenses
A39: Expenses of the harvest total
... A43: Annual fees
A44: Total of all expenses per account | B44: =Expenses!F109
A45: Total of all expenses (calculated here) | B45: =Expenses!F110
A46: Total fixed investment | B46: =Expenses!F111
A47: Total Demesne fixed investment | B47: =Expenses!F112
A49: Owed by the reeve
A50: From accounts
A52: Allowances
A53: Cash deliveries
A54: Sum of the above
A55: Total of all allowances and cash deliveries in accounts
...

Sheet Receipts
A1: EAST MEON RECEIPTS
A2: Heading | B2: £ | C2: s | D2: d | F2: Total in £ | G2: Error | H2: Notes
A3: Arrears | B3: 94 | C3: 4 | D3: 10.5 | F3: 94.24 | H3: Nicholas de Ychen', bailiff, and Richard Pokepole and Adam de Cumbe, reeves, render account for £94 4 shilling 10.5pence of arrears from the previous year.
A4: Arrears | B4: 0 | C4: 0 | D4: 0 | F4: 0 | H4: All delivered to Sir Geoffrey, treasurer of Wolvesey, by 1 tally.
A5: Arrears | B5: 0 | C5: 0 | D5: 0 | F5: 0 | H5: They are quit.
A6: Arrears | F6: 94.24 | G6: 94.24 | H6: Total
A8: Rents of assize | B8: 23 | C8: 2 | D8: 8.5 | F8: 23.14 | H8: The same render account for £23 2 shilling 8.5pence for all rents of assize at Christmas.
A9: Rents of assize | B9: 23 | C9: 2 | D9: 8.5 | F9: 23.14 | H9: £23 2 shilling 8.5pence at Easter (22 April).
A10: Rents of assize | B10: 23 | C10: 2 | D10: 8.5 | F10: 23.14 | H10: £23 2 shilling 8.5pence at the feast of St John the Baptist (24 June).
A11: Rents of assize | B11: 27 | C11: 18 | D11: 4 | F11: 27.92 | H11: £27 18 shilling 4pence at Michaelmas (29 September).
A12: Rents of assize | B12: 97 | C12: 6 | D12: 5.5 | F12: 97.32 | H12: Total, £97 6 shilling 5.5pence
A13: Rents of assize | F13: 97.34 | G13: 0.02 | H13: Total
A15: Increment | B15: 0 | C15: 0 | D15: 5 | F15: 0.02 | H15: The same render account for .5pence from John Miles for the increment of rent for a certain purpresture which before he encroached upon without licence of the lorpence
A16: Increment | B16: 0 | C16: 0 | D16: 0 | F16: 0 | H16: Total the same.
A17: Increment | F17: 0.02 | G17: 0 | H17: Total
A19: Quittances | B19: 0 | C19: 5 | D19: 0 | F19: 0.25 | H19: In quittance of 1 reeve for the year 5 shilling.
A20: Quittances | B20: 1 | C20: 10 | D20: 0 | F20: 1.5 | H20: 8 ploughmen, 3 shepherds and 1 swineherd for the year £1 10 shilling, or 2 shilling 6pence each.
A21: Quittances | B21: 0 | C21: 7 | D21: 6 | F21: =B21+C21/20+D21/240 | H21: 3 ploughmen for the year who replaced 3 drovers who were at liberty 7 shilling 6pence
A22: Quittances | B22: 2 | C22: 2 | D22: 6 | F22: 2.12 | H22: Total, £2 2 shilling 6pence
A23: Quittances | F23: =SUM(F19:F21) | G23: =F23-F22 | H23: Total
A25: Defaults of rent | B25: 1 | C25: 1 | D25: 7.5 | F25: 1.08 | H25: In default of the land drawn into demesne, £1 1 shilling 7.5pence for the year.
A26: Defaults of rent | B26: 5 | C26: 0 | D26: 0 | F26: 5 | H26: the land of Rethecumbe given to the canons of Newark Priory by Bishop Godfrey, £5 for the year.
A27: Defaults of rent | B27: 2 | C27: 0 | D27: 0 | F27: 2 | H27: the pasture and wood of Balluns which belonged to Thomas de Cumbe drawn into demesne, £2 for the year.
A28: Defaults of rent | B28: 1 | C28: 0 | D28: 0 | F28: 1 | H28: the mill which Robert Molendinarius sometimes held drawn into demesne, £1 for the year.
A29: Defaults of rent | B29: 0 | C29: 3 | D29: 0 | F29: 0.15 | H29: 8 acres of land which Deodatus (Deudoenis) le Hayward sometimes held drawn into demesne, 3 shilling for the year.
A30: Defaults of rent | B30: 0 | C30: 3 | D30: 5 | F30: 0.17 | H30: the land which the Abbot of Durford held drawn into demesne, 3 shilling 5pence for the year.
A31: Defaults of rent | B31: 0 | C31: 3 | D31: 2 | F31: 0.16 | H31: the land of Barlych' drawn into the park, 3 shilling 2pence for the year.
A32: Defaults of rent | B32: 0 | C32: 0 | D32: 6 | F32: 0.03 | H32: 1 purpresture which belonged to William Gibbe drawn into demesne, 6pence for the year.
A33: Defaults of rent | B33: 0 | C33: 0 | D33: 4 | F33: =B33+C33/20+D33/240 | H33: 1 plot beside the marl-pit of Wetham which H. de Borden' held, 4pence, because it was a nuisance to the neighbourhood.
A34: Defaults of rent | B34: 9 | C34: 12 | D34: 0.5 | F34: =B34+C34/20+D34/240 | H34: Total, £9 12 shilling .5pence
A35: Defaults of rent | F35: =SUM(F25:F33) | G35: =F35-F34 | H35: Total
A37: Total of quittances and defaults of rent | B37: 11 | C37: 14 | D37: 6.5 | F37: 11.73 | H37: Total of quittances and defaults of rent, £11 14 shilling 6.5pence
A38: Total of quittances and defaults of rent | F38: 11.73 | G38: =F38-F37 | H38: Total
A40: Total of rents remaining | B40: 85 | C40: 11 | D40: 11.5 | F40: 85.6 | H40: Total of rents remaining, £85 11 shilling 11.5pence
A41: Total of rents remaining | F41: 85.6 | G41: =F41-F40 | H41: Total
A43: Cumin | B43: 0 | C43: 0 | D43: 0 | F43: 0 | H43: The same render account for .5 lb of cumin from the rent of William ate Bere.
A44: Cumin | B44: 0 | C44: 0 | D44: 0 | F44: 0 | H44: 1 lb of cumin from Andrew de Holeweye for annual recognizance.
A45: Cumin | B45: 0 | C45: 0 | D45: 0 | F45: 0 | H45: Total, 1.5 lbs.
A46: Cumin | F46: 0 | G46: 0 | H46: Total
A48: Gloves | B48: 0 | C48: 0 | D48: 0 | F48: 0 | H48: The same render account for 1 pair of gloves from the rent of William Gilberd'.
...

Sheet Expenses
A1: EAST MEON EXPENSES
A2: Heading | B2: £ | C2: s | D2: d | F2: Total in £ | G2: Error | H2: Notes | J2: Fixed investment | K2: Demesne fixed investment
A3: Cost of ploughs | B3: 0 | C3: 14 | D3: 3 | F3: 0.71 | H3: In ironwork of 5 ox-ploughs and 3 horse-ploughs (caruc' affr') for the year and 1 horse-plough (caruc' equin') at the Lenten sowing, 14 shilling 3pence this year, on account of the excessive drought. | J3: =F3 | K3: =J3
A4: Cost of ploughs | B4: 0 | C4: 8 | D4: 0 | F4: 0.4 | H4: stipend of the smith forging the ironwork of the said ploughs for the year, 8 shilling by fixed agreement. | J4: =F4 | K4: =J4/2
A5: Cost of ploughs | B5: 0 | C5: 3 | D5: 9 | F5: 0.19 | H5: 5 ploughshares bought 3 shilling 9pence. | J5: =F5 | K5: =J5
A6: Cost of ploughs | B6: 0 | C6: 0 | D6: 0 | F6: 0 | H6: 2 coulters mended 44.. | J6: =F6 | K6: =J6/2
A7: Cost of ploughs | B7: 0 | C7: 2 | D7: 11 | F7: 0.15 | H7: 7 plough feet bought 2 shilling 11pence, at 5pence each. | J7: =F7 | K7: =J7
A8: Cost of ploughs | B8: 0 | C8: 7 | D8: 4 | F8: 0.37 | H8: a new plough and harrow made and others mended for the year, 7 shilling 4pence by fixed agreement, and so much because the worker was not at the bailiff's table. | J8: =F8 | K8: =J8/2
A9: Cost of ploughs | B9: 0 | C9: 0 | D9: 6 | F9: 0.03 | H9: fitting the ploughs with iron tyres 6pence. | J9: =F9 | K9: =J9
A10: Cost of ploughs | B10: 0 | C10: 2 | D10: 0 | F10: 0.1 | H10: 6 pairs of wheels bought for the ploughs 2 shilling. | J10: =F10 | K10: =J10/2
A11: Cost of ploughs | B11: 0 | C11: 1 | D11: 6 | F11: 0.08 | H11: shoeing 18 plough-horses for the year 1 shilling 6pence. | J11: =F11 | K11: =J11
A12: Cost of ploughs | B12: 0 | C12: 0 | D12: 4 | F12: 0.02 | H12: fastening the same 4pence. | J12: =F12 | K12: =J12/2
A13: Cost of ploughs | B13: 0 | C13: 2 | D13: 2 | F13: 0.11 | H13: stipend of 1 harrower at both sowings 2 shilling 2pence. | J13: =F13 | K13: =J13
A14: Cost of ploughs | B14: 0 | C14: 0 | D14: 4 | F14: 0.02 | H14: 16 halters made from the horses' own hair 4pence. | J14: =F14 | K14: =J14/2
A15: Cost of ploughs | B15: 0 | C15: 0 | D15: 1.5 | F15: 0.01 | H15: 1 seed-basket bought 1.5pence. | J15: =F15 | K15: =J15
A16: Cost of ploughs | B16: 0 | C16: 9 | D16: 0 | F16: 0.45 | H16: stipend of 3 drovers for the year 9 shilling.
A17: Cost of ploughs | B17: 0 | C17: 10 | D17: 0 | F17: 0.5 | H17: stipend of 2 drovers for the year 10 shilling.
A18: Cost of ploughs | B18: 0 | C18: 3 | D18: 0 | F18: 0.15 | H18: stipend of 1 hayward for the year 3 shilling.
A19: Cost of ploughs | B19: 0 | C19: 3 | D19: 0 | F19: 0.15 | H19: stipend of 1 cowherd for the year 3 shilling.
A20: Cost of ploughs | B20: 0 | C20: 3 | D20: 0 | F20: 0.15 | H20: stipend of 1 keeper of lambs and hoggs for the year 3 shilling.
A21: Cost of ploughs | B21: 0 | C21: 0 | D21: 1 | F21: 0 | H21: ploughing boon-works in winter or Lent, nothing this year, that is, they are bound to plough 26 acres for landrihf in winter and 26 acres in Lent, because the land which William le Fissar' holds is commuted as made clear above, and those who plough for landrihe in winter are bound to thresh seed for 1 acre or give 1pence for the threshing at the lord's will.
A22: Cost of ploughs | B22: 0 | C22: 0 | D22: 3 | F22: 0.01 | H22: blood-letting of oxen 3pence.
A23: Cost of ploughs | B23: 0 | C23: 1 | D23: 0 | F23: 0.05 | H23: hiring men for the ploughs when they plough after dinner 1 shilling.
A24: Cost of ploughs | B24: 5 | C24: 6 | D24: 1.5 | F24: 5.31 | H24: 11 plough-horses bought for the ploughs £5 6 shilling 1.5pence, at 9 shilling each for 3, 9 shilling 6pence each for 2, and 10 shilling each for 6, plus 1.5pence in all.
A25: Cost of ploughs | B25: 6 | C25: 7 | D25: 0 | F25: 6.35 | H25: 10 oxen bought for ploughs £6 7 shilling .25pence, at 12 shilling .25pence for 1, 12 shilling 6pence each for 4, and 13 shilling each for 5..
A26: Cost of ploughs | B26: 0 | C26: 1 | D26: 0 | F26: =B26+C26/20+D26/240 | H26: 2 sacks bought 1 shilling
A27: Cost of ploughs | B27: 15 | C27: 6 | D27: 11.25 | F27: 15.35 | H27: Total, £15 6 shilling 11.25pence
A28: Cost of ploughs | F28: =SUM(F3:F26) | G28: =F28-F27 | H28: Total
A30: Cost of carts | B30: 0 | C30: 0 | D30: 10 | F30: 0.04 | H30: In 1 pair of wheels made from the lord's timber 10pence. | J30: =F30 | K30: =J30
A31: Cost of carts | B31: 0 | C31: 4 | D31: 2.5 | F31: 0.21 | H31: an old binding fitted to the said wheels, with clamps and large and small nails bought for the same, and with the stipend of the smith, 4 shilling 2.5pence. | J31: =F31 | K31: =J31
A32: Cost of carts | B32: 0 | C32: 0 | D32: 2 | F32: 0.01 | H32: hooping the hubs of the cart with iron 2pence. | J32: =F32 | K32: =J32
A33: Cost of carts | B33: 0 | C33: 0 | D33: 6 | F33: 0.03 | H33: fitting the cart with axles for the year 6pence. | J33: =F33 | K33: =J33
A34: Cost of carts | B34: 0 | C34: 2 | D34: 10 | F34: 0.14 | H34: clouts, nails and grease bought for the same, 2 shilling 10pence this year, for carrying timber to the chapel. | J34: =F34 | K34: =J34
A35: Cost of carts | B35: 0 | C35: 0 | D35: 6 | F35: 0.03 | H35: white leather bought for mending harnesses 6pence. | J35: =F35 | K35: =J35
A36: Cost of carts | B36: 0 | C36: 0 | D36: 7 | F36: 0.03 | H36: 1 pair of traces bought 7pence. | J36: =F36 | K36: =J36
A37: Cost of carts | B37: 0 | C37: 0 | D37: 6.5 | F37: 0.03 | H37: 1 collar 6.5pence. | J37: =F37 | K37: =J37
A38: Cost of carts | B38: 0 | C38: 0 | D38: 2 | F38: 0.01 | H38: 2 halters bought 2pence. | J38: =F38 | K38: =J38
A39: Cost of carts | B39: 0 | C39: 0 | D39: 8 | F39: 0.03 | H39: 1 cart-body and 1 cart-rail made anew 8pence. | J39: =F39 | K39: =J39
A40: Cost of carts | B40: 0 | C40: 0 | D40: 8 | F40: 0.03 | H40: mending the old cart at various times 8pence in doctoring horses 4pence. | J40: =F40 | K40: =J40
A41: Cost of carts | B41: 0 | C41: 2 | D41: 0 | F41: 0.1 | H41: shoeing 2 cart-horses for the year 2 shilling. | J41: =F41 | K41: =J41
...

Sheet Issues of the Grange
A1: Gross Output | B1: Total Quantity | C1: Account Total Quarters | D1: Bought in Total Quarters | E1: Received from churchscot | F1: Sold Total Quarters | G1: Difference Produced+Bought-Sold | H1: Weighted Average Price per Quarter | I1: Value of Total Production weighted
A2: wheat | B2: 357.875 | D2: 0 | F2: 274.25 | G2: =B2-F2 | H2: 0.27537223 | I2: =H2*B2
A3: curall | B3: 14 | D3: 0 | F3: 14 | G3: =B3-F3 | H3: 0.16666667 | I3: =H3*B3
A4: barley | B4: 115.6875 | D4: 0 | F4: 28.625 | G4: =B4-F4 | H4: 0.19366812 | I4: =H4*B4
A5: oats | B5: 616.5625 | D5: 0 | F5: 275.375 | G5: =B5-F5 | H5: 0.10320396 | I5: =H5*B5
A8: Total Production
A9: Sales of corn (as recorded in accounts)
A12: Net output | B12: Gross output | C12: Seed quarters | D12: Seed bushels | E12: Seed total quarters | F12: tithe quarters | G12: tithe bushels | H12: tithe total | I12: manorial servants quarters | J12: manorial servants bushels | K12: manorial servants total quarters | L12: output net of tithe, seed, liveries | M12: in stock from last year | N12: Price in £ | O12: Value of net output in £ | P12: Value of sales (in "Sale of Corn") in £
A13: wheat | B13: =B2 | C13: 67 | D13: 6 | E13: =C13+D13/8 | I13: =8+10+5 | J13: =2+7 | K13: =I13+J13/8 | L13: =B13-E13-H13-K13 | N13: =H2 | O13: =N13*L13
A14: curall | B14: =B3 | E14: =C14+D14/8 | K14: =I14+J14/8 | L14: =B14-E14-H14-K14 | N14: =H3 | O14: =N14*L14
A15: barley | B15: =B4 | C15: 26.5 | D15: 4.5 | E15: =C15+D15/8 | I15: =32.5+10+5+4+4+3 | J15: =3+1.5+2.5+5 | K15: =I15+J15/8 | L15: =B15-E15-H15-K15 | N15: =H4 | O15: =N15*L15
A16: oats | B16: =B5 | C16: 190 | E16: =C16+D16/8 | I16: =18+52.5+5+42+10.5+1.5+20 | K16: =I16+J16/8 | L16: =B16-E16-H16-K16 | N16: =H5 | O16: =N16*L16
A18: Total

Sheet Issues of the Mills

Sheet Stock
A1: EAST MEON STOCK ACCOUNT
C3: added | G3: subtracted
A4: Livestock | B4: Inherited stock | C4: added | D4: strays | E4: herbage | F4: churchscot | G4: of which in default | H4: sold | I4: in murrain | J4: accounted for elsewhere | K4: End-period stock | L4: cross-check | M4: stock building | N4: raw production | O4: Unit price (£) | P4: Value of stock (£) at given value | Q4: Value of stock (£) at sales prices | R4: Sales in (£) | S4: Value of stock building (£) | T4: Value of production (£) at sales prices | U4: Details
A5: Cart-horses | B5: 2 | K5: 2
A6: Mares
A7: Plough horses | B7: 18 | C7: 11 | H7: 3 | I7: 9 | K7: 17 | R7: =Receipts!F134
A8: Colts (unspecified years) | B8: 2 | I8: 2 | K8: 0
A9: Colts (2 years) | B9: 1 | K9: 1
A10: Colts (1 year)
A11: Foals | B11: 2 | I11: 1 | K11: 1
A12: Oxen | B12: 57 | C12: =8+3+10 | H12: 7 | I12: 5 | K12: 66 | R12: =Receipts!F135
A13: Bulls | B13: 1 | K13: 1
A14: Cows | B14: 18 | C14: =4+1 | H14: 1 | K14: 22 | R14: =Receipts!F136
A15: Steers | B15: 11 | C15: 1 | J15: =8+4 | K15: 0
A16: Bullocks | B16: 9 | K16: 9
A17: Yearlings | B17: 6 | K17: 6
A18: Calves | B18: 22 | H18: 8 | I18: 1 | K18: 13 | R18: =Receipts!F137
A19: Wethers | B19: 450 | C19: 129 | H19: 21 | I19: =43+26 | J19: 3 | K19: 486 | R19: =Receipts!F138
A20: Rams
A21: Ewes | B21: 797 | C21: =184+6 | H21: =100 | I21: =12+26+9 | J21: =9 | K21: 831 | R21: =Receipts!F139
A22: Hoggs | B22: 402 | H22: 9 | I22: =30 | J22: =129+184+50 | K22: 0 | R22: =Receipts!F140
A23: Lambs | B23: 555 | C23: =9+29 | I23: =134+23+9+3 | K23: 424
A24: Boars
A25: Sows | B25: 2 | C25: 2 | I25: 2 | K25: 2
A26: Pigs | B26: 35 | C26: 28 | H26: 19 | I26: 4 | K26: 50 | R26: =Receipts!F141
A27: Hoggets | B27: 50 | I27: 10 | J27: =2+38 | K27: 0
A28: Piglets | C28: =45+8 | I28: 9 | K28: 44
A29: Swans | B29: 3 | C29: 2 | I29: 1 | K29: 4
A30: Peacocks | B30: 6 | I30: 1 | K30: 5
A31: Total Value | R31: =SUM(R5:R30)
A34: Wool
A35: Coarse wool | C35: 1405 | J35: 1405 | K35: 0 | O35: 0.02 | T35: =O35*J35
A36: Lamb's wool | C36: 433 | J36: 433 | K36: 0 | O36: 0.01 | T36: =O36*J36
A37: Wool locks | C37: 20 cloves 5 lb | H37: 20 cloves 5 lb | R37: =Receipts!F110 | T37: =R37
A38: Wool sold at shearing
A39: Total wool | R39: =R37 | T39: =SUM(T35:T38)
A42: Hides
A43: Ox hides | C43: 5
A44: plough horses | C44: 9
A45: colts | C45: 2
...

Sheet raw data
A1: Heading | B1: Sentence | C1: Total in Pounds | D1: Pounds | E1: Shillings | F1: Pence | G1: Corn | H1: Total Quarters Except 1 | I1: Total Bushels Except 1 | J1: Total Corn Cross-Check | K1: Total Corn Manorial Account | L1: Corn Quantity Error | M1: Quarters 1 | N1: Bushels 1 | O1: Quarters 2 | P1: Bushels 2 | Q1: Quarters 3 | R1: Bushels 3 | S1: Quarters 4 | T1: Bushels 4 | U1: Quarters 5 | V1: Bushels 5 | W1: Quarters 6 | X1: Bushels 6 | Y1: shilling a quarter 1 | Z1: pence a quarter 1 | AA1: shilling a quarter 2 | AB1: pence a quarter 2 | AC1: shilling a quarter 3 | AD1: pence a quarter 3 | AE1: shilling a quarter 4 | AF1: pence a quarter 4 | AG1: shilling a quarter 5 | AH1: pence a quarter 5 | AI1: shilling a bushel 1 | AJ1: pence a bushel 1 | AK1: shilling a bushel 2 | AL1: pence a bushel 2 | AM1: shilling a bushel 3 | AN1: pence a bushel 3 | AO1: shilling a bushel 4 | AP1: pence a bushel 4
A2: Arrears | B2: Nicholas de Ychen', bailiff, and Richard Pokepole and Adam de Cumbe, reeves, render account for £94 4 shilling 10.5pence of arrears from the previous year. | C2: 94.24 | D2: 94 | E2: 4 | F2: 10.5 | H2: 0 | I2: 0 | J2: 0 | K2: 0 | L2: 0 | M2: 0 | N2: 0
A3: Arrears | B3: All delivered to Sir Geoffrey, treasurer of Wolvesey, by 1 tally. | C3: 0 | D3: 0 | E3: 0 | F3: 0 | H3: 0 | I3: 0 | J3: 0 | K3: 0 | L3: 0 | M3: 0 | N3: 0
A4: Arrears | B4: They are quit. | C4: 0 | D4: 0 | E4: 0 | F4: 0 | H4: 0 | I4: 0 | J4: 0 | K4: 0 | L4: 0 | M4: 0 | N4: 0
A5: Rents of assize | B5: The same render account for £23 2 shilling 8.5pence for all rents of assize at Christmas. | C5: 23.14 | D5: 23 | E5: 2 | F5: 8.5 | H5: 0 | I5: 0 | J5: 0 | K5: 0 | L5: 0 | M5: 0 | N5: 0
A6: Rents of assize | B6: £23 2 shilling 8.5pence at Easter (22 April). | C6: 23.14 | D6: 23 | E6: 2 | F6: 8.5 | H6: 0 | I6: 0 | J6: 0 | K6: 0 | L6: 0 | M6: 0 | N6: 0
A7: Rents of assize | B7: £23 2 shilling 8.5pence at the feast of St John the Baptist (24 June). | C7: 23.14 | D7: 23 | E7: 2 | F7: 8.5 | H7: 0 | I7: 0 | J7: 0 | K7: 0 | L7: 0 | M7: 0 | N7: 0
A8: Rents of assize | B8: £27 18 shilling 4pence at Michaelmas (29 September). | C8: 27.92 | D8: 27 | E8: 18 | F8: 4 | H8: 0 | I8: 0 | J8: 0 | K8: 0 | L8: 0 | M8: 0 | N8: 0
A9: Rents of assize | B9: Total, £97 6 shilling 5.5pence | C9: 97.32 | D9: 97 | E9: 6 | F9: 5.5 | H9: 0 | I9: 0 | J9: 0 | K9: 0 | L9: 0 | M9: 0 | N9: 0
A10: Increment | B10: The same render account for .5pence from John Miles for the increment of rent for a certain purpresture which before he encroached upon without licence of the lorpence Total the same. | C10: 0.02 | D10: 0 | E10: 0 | F10: 5 | H10: 0 | I10: 0 | J10: 0 | K10: 0 | L10: 0 | M10: 0 | N10: 0
A11: Total of all rents with increment | B11: Total of all rents with increment, £97 6 shilling 6pence | C11: 97.33 | D11: 97 | E11: 6 | F11: 6 | H11: 0 | I11: 0 | J11: 0 | K11: 0 | L11: 0 | M11: 0 | N11: 0
A12: Quittances | B12: In quittance of 1 reeve for the year 5 shilling. | C12: 0.25 | D12: 0 | E12: 5 | F12: 0 | H12: 0 | I12: 0 | J12: 0 | K12: 0 | L12: 0 | M12: 0 | N12: 0
A13: Quittances | B13: 8 ploughmen, 3 shepherds and 1 swineherd for the year £1 10 shilling, or 2 shilling 6pence each. | C13: 1.5 | D13: 1 | E13: 10 | F13: 0 | H13: 0 | I13: 0 | J13: 0 | K13: 0 | L13: 0 | M13: 0 | N13: 0
... A78: Issues of the manor | B78: 8 shilling 5pence from pinfolding sheep this year, at 1pence per 5 sheep, unless they have 20 sheep, because then they give the twentieth sheep. | C78: 0.42 | D78: 0 | E78: 8 | F78: 5 | H78: 0 | I78: 0 | J78: 0 | K78: 0 | L78: 0 | M78: 0 | N78: 0
A79: Issues of the manor | B79: 2 shilling 2pence from 26 customary tenants because the land of William le Fissar' is commuted, each of whom ploughs for landrihe and everyone is bound to thresh separately 3 bushels of wheat for sowing over 1 acre in winter or give 1pence at the lord's will for the threshing. | C79: 0.11 | D79: 0 | E79: 2 | F79: 2 | G79: wheat | H79: 0 | I79: 3 | J79: 0.375 | K79: 0.375 | L79: 0 | M79: 0 | N79: 3
A80: Issues of the manor | B80: £3 4 shilling 9pence from 448 labour services by the perch sold this year, at 2pence each for 329, and 1pence each for 119. | C80: 3.24 | D80: 3 | E80: 4 | F80: 9 | H80: 0 | I80: 0 | J80: 0 | K80: 0 | L80: 0 | M80: 0 | N80: 0
A81: Issues of the manor | B81: nothing from Avice de Quorteslod' separately because she worked with the others. | C81: 0 | D81: 0 | E81: 0 | F81: 0 | H81: 0 | I81: 0 | J81: 0 | K81: 0 | L81: 0 | M81: 0 | N81: 0
A82: Issues of the manor | B82: 1 shilling from William Ramwyle for release from labour service for the year. | C82: 0.05 | D82: 0 | E82: 1 | F82: 0 | H82: 0 | I82: 0 | J82: 0 | K82: 0 | L82: 0 | M82: 0 | N82: 0
A83: Issues of the manor | B83: nothing from John de Halewell' because he worked with the others. | C83: 0 | D83: 0 | E83: 0 | F83: 0 | H83: 0 | I83: 0 | J83: 0 | K83: 0 | L83: 0 | M83: 0 | N83: 0
A84: Issues of the manor | B84: nothing from coarse wool and lamb's-wool here because it is sent to Wolvesey. | C84: 0 | D84: 0 | E84: 0 | F84: 0 | H84: 0 | I84: 0 | J84: 0 | K84: 0 | L84: 0 | M84: 0 | N84: 0
A85: Issues of the manor | B85: 18 shilling 1.5pence from 20 cloves 5 lb of wool locks sold, at 10.5pence a clove. | C85: 0.91 | D85: 0 | E85: 18 | F85: 1.5 | H85: 0 | I85: 0 | J85: 0 | K85: 0 | L85: 0 | M85: 0 | N85: 0
A86: Issues of the manor | B86: £1 3 shilling 10pence from 286 hens from churchscot sold. | C86: 1.19 | D86: 1 | E86: 3 | F86: 10 | H86: 0 | I86: 0 | J86: 0 | K86: 0 | L86: 0 | M86: 0 | N86: 0
A87: Issues of the manor | B87: 6 shilling from the hides sold of 9 plough-horses in murrain, at 8pence each. | C87: 0.33 | D87: 0 | E87: 6 | F87: 8 | H87: 0 | I87: 0 | J87: 0 | K87: 0 | L87: 0 | M87: 0 | N87: 0
A88: Issues of the manor | B88: 1 shilling from the hides of 2 colts sold. | C88: 0.05 | D88: 0 | E88: 1 | F88: 0 | H88: 0 | I88: 0 | J88: 0 | K88: 0 | L88: 0 | M88: 0 | N88: 0
A89: Issues of the manor | B89: 5 shilling 6pence from the hides and flesh sold of 2 oxen in murrain. | C89: 0.28 | D89: 0 | E89: 5 | F89: 6 | H89: 0 | I89: 0 | J89: 0 | K89: 0 | L89: 0 | M89: 0 | N89: 0
A90: Issues of the manor | B90: 6 shilling from the hides sold of 3 oxen in murrain. | C90: 0.3 | D90: 0 | E90: 6 | F90: 0 | H90: 0 | I90: 0 | J90: 0 | K90: 0 | L90: 0 | M90: 0 | N90: 0
A91: Issues of the manor | B91: 1pence from the hide sold of 1 calf in murrain. | C91: 0 | D91: 0 | E91: 0 | F91: 1 | H91: 0 | I91: 0 | J91: 0 | K91: 0 | L91: 0 | M91: 0 | N91: 0
... A115: Sale of stock | B115: Total, £15 3 shilling 6pence | C115: 15.18 | D115: 15 | E115: 3 | F115: 6 | H115: 0 | I115: 0 | J115: 0 | K115: 0 | L115: 0 | M115: 0 | N115: 0
A116: Sale of corn | B116: The same render account for £75 10 shilling 5pence from 274 quarters 2 bushels of wheat sold, at 4 shilling a quarters for 29 quarters 2 bushels, 5 shilling a quarters for 70 quarters 6 bushels, 5 shilling 4pence a quarters for 82 quarters 3 bushels, 6 shilling a quarters for 18 quarters 2 bushels, and 6 shilling 8pence a quarters for 73 quarters 5 bushels. | C116: 75.52 | D116: 75 | E116: 10 | F116: 5 | G116: wheat | H116: 272 | I116: 18 | J116: 274.25 | K116: 274.25 | L116: 0 | M116: 274 | N116: 2 | O116: 29 | P116: 2 | Q116: 70 | R116: 6 | S116: 82 | T116: 3 | U116: 18 | V116: 2 | W116: 73 | X116: 5 | Y116: 4 | Z116: 0 | AA116: 5 | AB116: 0 | AC116: 5 | AD116: 4 | AE116: 6 | AF116: 0 | AG116: 6 | AH116: 8
A117: Sale of corn | B117: £2 6 shilling 8pence from 14 quarters of curall sold, at 3 shilling 4pence a quarters. | C117: 2.33 | D117: 2 | E117: 6 | F117: 8 | G117: curall | H117: 14 | I117: 0 | J117: 14 | K117: 14 | L117: 0 | M117: 14 | N117: 0 | Y117: 3 | Z117: 4
A118: Sale of corn | B118: £5 10 shilling 10.5pence from 28 quarters 5 bushels of barley sold, at 4 shilling a quarters for 25 quarters, and 3 shilling a quarters for 3 quarters 5 bushels. | C118: 5.54 | D118: 5 | E118: 10 | F118: 10.5 | G118: barley | H118: 28 | I118: 5 | J118: 28.625 | K118: 28.625 | L118: 0 | M118: 28 | N118: 5 | O118: 25 | P118: 0 | Q118: 3 | R118: 5 | Y118: 4 | Z118: 0 | AA118: 3 | AB118: 0
A119: Sale of corn | B119: £28 8 shilling 4.75pence from 275 quarters 3 bushels of oats sold, at 1 shilling 8pence a quarters for 55 quarters 3 bushels, 2 shilling a quarters for 86 quarters 3 bushels, 2 shilling 2pence a quarters for 50 quarters 5 bushels, and 2 shilling 4pence a quarters for 83 quarters. | C119: 28.42 | D119: 28 | E119: 8 | F119: 4.75 | G119: oats | H119: 274 | I119: 11 | J119: 275.375 | K119: 275.375 | L119: 0 | M119: 275 | N119: 3 | O119: 55 | P119: 3 | Q119: 86 | R119: 3 | S119: 50 | T119: 5 | U119: 83 | V119: 0 | Y119: 1 | Z119: 8 | AA119: 2 | AB119: 0 | AC119: 2 | AD119: 2 | AE119: 2 | AF119: 4
A120: Sale of corn | B120: Total of all corn sold, £111 16 shilling 4.25pence | C120: 111.82 | D120: 111 | E120: 16 | F120: 4.25 | H120: 0 | I120: 0 | J120: 0 | K120: 0 | L120: 0 | M120: 0 | N120: 0
A121: Farm of the mill | B121: The same render account for £1 15 shilling from the mill let at farm this year. | C121: 1.75 | D121: 1 | E121: 15 | F121: 0 | H121: 0 | I121: 0 | J121: 0 | K121: 0 | L121: 0 | M121: 0 | N121: 0
A122: Farm of the mill | B122: Total, £1 15 shilling | C122: 1.75 | D122: 1 | E122: 15 | F122: 0 | H122: 0 | I122: 0 | J122: 0 | K122: 0 | L122: 0 | M122: 0 | N122: 0
A123: Entry and marriage fines with tithingpenny | B123: The same render account for £3 6 shilling 8pence from all the tithings of the hundred for tithingpenny at the hundred-court of Martinmas. | C123: 3.33 | D123: 3 | E123: 6 | F123: 8 | H123: 0 | I123: 0 | J123: 0 | K123: 0 | L123: 0 | M123: 0 | N123: 0
A124: Entry and marriage fines with tithingpenny | B124: £3 6 shilling 8pence from the same tithings at the hundred-court of Hockday. | C124: 3.33 | D124: 3 | E124: 6 | F124: 8 | H124: 0 | I124: 0 | J124: 0 | K124: 0 | L124: 0 | M124: 0 | N124: 0
A125: Entry and marriage fines with tithingpenny | B125: £2 10 shilling from Nicholas, son and heir of Nicholas de Langriss', for fine to have all the lands and tenements which belonged to his father in the manor of East Meon. | C125: 2.5 | D125: 2 | E125: 10 | F125: 0 | H125: 0 | I125: 0 | J125: 0 | K125: 0 | L125: 0 | M125: 0 | N125: 0
A126: Entry and marriage fines with tithingpenny | B126: 13 shilling 4pence from Cecilia, relict of Gilbert ate Brok', to retain 1 messuage and 0.5 virgate of land which belonged to her husband. | C126: 0.67 | D126: 0 | E126: 13 | F126: 4 | H126: 0 | I126: 0 | J126: 0 | K126: 0 | L126: 0 | M126: 0 | N126: 0
A127: Entry and marriage fines with tithingpenny | B127: 4 shilling from William de Radesole to have 1.5 acres of land by surrender of Richard ate Burgh, and the aforesaid William will relieve the said Richard of 5.5pence annual rent. | C127: 0.22 | D127: 0 | E127: 4 | F127: 5.5 | H127: 0 | I127: 0 | J127: 0 | K127: 0 | L127: 0 | M127: 0 | N127: 0
...

Sheet Issues of the Grange raw
A1: Heading | B1: Sentence | C1: Quarters 1_x | D1: Bushels 1_x | E1: Sown Quarters | F1: Sown Bushels | G1: Sown Total Quarters | H1: Bought in Quarters | I1: Bought in Bushels | J1: Bought in Total Quarters | K1: Tithe Quarters | L1: Tithe Bushels | M1: Tithe Total Quarters | N1: Manorial servants & livestock Quarters | O1: Manorial servants & livestock Bushels | P1: Manorial servants & livestock Total Quarters | Q1: Sold Quarters | R1: Sold Bushels | S1: Sold Total Quarters | T1: Account Quarters | U1: Account Bushels | V1: Account Total Quarters | W1: bought only | X1: Total Quarters Except 1 | Y1: Total Bushels Except 1 | Z1: Total Corn Cross-Check | AA1: Total Corn Manorial Account | AB1: Corn Quantity Error | AC1: Quarters 1_y | AD1: Bushels 1_y | AE1: Quarters 2 | AF1: Bushels 2 | AG1: Quarters 3 | AH1: Bushels 3 | AI1: Quarters 4 | AJ1: Bushels 4 | AK1: Quarters 5 | AL1: Bushels 5 | AM1: Quarters 6 | AN1: Bushels 6
A2: Cash deliveries | B2: Total | C2: 0 | D2: 0 | E2: 0 | F2: 0 | G2: 0 | H2: 0 | I2: 0 | J2: 0 | K2: 0 | L2: 0 | M2: 0 | N2: 0 | O2: 0 | P2: 0 | Q2: 0 | R2: 0 | S2: 0 | T2: 0 | U2: 0 | V2: 0 | W2: 0
A3: Wheat | B3: {yield: 6-fold plus 13 quarters 5 bushels} | C3: 0 | D3: 0 | E3: 0 | F3: 0 | G3: 0 | H3: 0 | I3: 0 | J3: 0 | K3: 0 | L3: 0 | M3: 0 | N3: 0 | O3: 0 | P3: 0 | Q3: 0 | R3: 0 | S3: 0 | T3: 0 | U3: 0 | V3: 0 | W3: 0 | X3: 13 | Y3: 5 | Z3: 13.625 | AA3: 13.625 | AB3: 0 | AC3: 13 | AD3: 5
A4: Wheat | B4: The same render account for 14 quarters of wheat remaining in the granary from the previous year. | C4: 0 | D4: 0 | E4: 0 | F4: 0 | G4: 0 | H4: 0 | I4: 0 | J4: 0 | K4: 0 | L4: 0 | M4: 0 | N4: 0 | O4: 0 | P4: 0 | Q4: 0 | R4: 0 | S4: 0 | T4: 14 | U4: 0 | V4: 14 | W4: 0 | X4: 14 | Y4: 0 | Z4: 14 | AA4: 14 | AB4: 0 | AC4: 14 | AD4: 0
A5: Wheat | B5: 340 quarters 7 bushels from the whole issue of the grange by struck measure. | C5: 0 | D5: 0 | E5: 0 | F5: 0 | G5: 0 | H5: 0 | I5: 0 | J5: 0 | K5: 0 | L5: 0 | M5: 0 | N5: 0 | O5: 0 | P5: 0 | Q5: 0 | R5: 0 | S5: 0 | T5: 340 | U5: 7 | V5: 340.875 | W5: 0 | X5: 340 | Y5: 7 | Z5: 340.875 | AA5: 340.875 | AB5: 0 | AC5: 340 | AD5: 7
A6: Wheat | B6: 3 quarters from churchscot. | C6: 0 | D6: 0 | E6: 0 | F6: 0 | G6: 0 | H6: 0 | I6: 0 | J6: 0 | K6: 0 | L6: 0 | M6: 0 | N6: 0 | O6: 0 | P6: 0 | Q6: 0 | R6: 0 | S6: 0 | T6: 0 | U6: 0 | V6: 0 | W6: 0 | X6: 3 | Y6: 0 | Z6: 3 | AA6: 3 | AB6: 0 | AC6: 3 | AD6: 0
A7: Wheat | B7: Total, 357 quarters 7 bushels | C7: 0 | D7: 0 | E7: 0 | F7: 0 | G7: 0 | H7: 0 | I7: 0 | J7: 0 | K7: 0 | L7: 0 | M7: 0 | N7: 0 | O7: 0 | P7: 0 | Q7: 0 | R7: 0 | S7: 0 | T7: 0 | U7: 0 | V7: 0 | W7: 0 | X7: 357 | Y7: 7 | Z7: 357.875 | AA7: 357.875 | AB7: 0 | AC7: 357 | AD7: 7
A8: Wheat | B8: Sown over 608 acres as they lie in Selescumbe, Stonyelond', and Pykes, 67 quarters 6 bushels. | C8: 0 | D8: 0 | E8: 67 | F8: 6 | G8: 67.75 | H8: 0 | I8: 0 | J8: 0 | K8: 0 | L8: 0 | M8: 0 | N8: 0 | O8: 0 | P8: 0 | Q8: 0 | R8: 0 | S8: 0 | T8: 0 | U8: 0 | V8: 0 | W8: 0 | X8: 67 | Y8: 6 | Z8: 67.75 | AA8: 67.75 | AB8: 0 | AC8: 67 | AD8: 6
A9: Wheat | B9: that is, 1 bushels an acre, less 8 quarters 2 bushels in all. | C9: 0 | D9: 0 | E9: 0 | F9: 0 | G9: 0 | H9: 0 | I9: 0 | J9: 0 | K9: 0 | L9: 0 | M9: 0 | N9: 0 | O9: 0 | P9: 0 | Q9: 0 | R9: 0 | S9: 0 | T9: 0 | U9: 0 | V9: 0 | W9: 0 | X9: 8 | Y9: 2 | Z9: 8.25 | AA9: 0.125 | AB9: 8.125 | AC9: 0 | AD9: 1 | AE9: 8 | AF9: 2
A10: Wheat | B10: . | C10: 0 | D10: 0 | E10: 0 | F10: 0 | G10: 0 | H10: 0 | I10: 0 | J10: 0 | K10: 0 | L10: 0 | M10: 0 | N10: 0 | O10: 0 | P10: 0 | Q10: 0 | R10: 0 | S10: 0 | T10: 0 | U10: 0 | V10: 0 | W10: 0 | X10: 0 | Y10: 0 | Z10: 0 | AA10: 0 | AB10: 0 | AC10: 0 | AD10: 0
A11: Wheat | B11: provision of the steward for his visits by 1 tally, 7 bushels. | C11: 0 | D11: 0 | E11: 0 | F11: 0 | G11: 0 | H11: 0 | I11: 0 | J11: 0 | K11: 0 | L11: 0 | M11: 0 | N11: 0 | O11: 0 | P11: 0 | Q11: 0 | R11: 0 | S11: 0 | T11: 0 | U11: 0 | V11: 0 | W11: 0 | X11: 0 | Y11: 7 | Z11: 0.875 | AA11: 0.875 | AB11: 0 | AC11: 0 | AD11: 7
A12: Wheat | B12: provision of the bailiff for the year, 10 quarters, because he takes the rest from East Meon Church. | C12: 0 | D12: 0 | E12: 0 | F12: 0 | G12: 0 | H12: 0 | I12: 0 | J12: 0 | K12: 0 | L12: 0 | M12: 0 | N12: 0 | O12: 0 | P12: 0 | Q12: 0 | R12: 0 | S12: 0 | T12: 0 | U12: 0 | V12: 0 | W12: 0 | X12: 10 | Y12: 0 | Z12: 10 | AA12: 10 | AB12: 0 | AC12: 10 | AD12: 0
A13: Wheat | B13: Delivered to the vicar for his carrying-service, 5 quarters. | C13: 0 | D13: 0 | E13: 0 | F13: 0 | G13: 0 | H13: 0 | I13: 0 | J13: 0 | K13: 0 | L13: 0 | M13: 0 | N13: 0 | O13: 0 | P13: 0 | Q13: 0 | R13: 0 | S13: 0 | T13: 0 | U13: 0 | V13: 0 | W13: 0 | X13: 5 | Y13: 0 | Z13: 5 | AA13: 5 | AB13: 0 | AC13: 5 | AD13: 0
A14: Wheat | B14: Sold, 274 quarters 2 bushels | C14: 0 | D14: 0 | E14: 0 | F14: 0 | G14: 0 | H14: 0 | I14: 0 | J14: 0 | K14: 0 | L14: 0 | M14: 0 | N14: 0 | O14: 0 | P14: 0 | Q14: 274 | R14: 2 | S14: 274.25 | T14: 0 | U14: 0 | V14: 0 | W14: 0 | X14: 274 | Y14: 2 | Z14: 274.25 | AA14: 274.25 | AB14: 0 | AC14: 274 | AD14: 2
A15: Wheat | B15: Total | C15: 0 | D15: 0 | E15: 0 | F15: 0 | G15: 0 | H15: 0 | I15: 0 | J15: 0 | K15: 0 | L15: 0 | M15: 0 | N15: 0 | O15: 0 | P15: 0 | Q15: 0 | R15: 0 | S15: 0 | T15: 0 | U15: 0 | V15: 0 | W15: 0
A16: Curall | B16: The same render account for 14 quarters from the whole issue of curall from the same wheat by struck measure. | C16: 0 | D16: 0 | E16: 0 | F16: 0 | G16: 0 | H16: 0 | I16: 0 | J16: 0 | K16: 0 | L16: 0 | M16: 0 | N16: 0 | O16: 0 | P16: 0 | Q16: 0 | R16: 0 | S16: 0 | T16: 14 | U16: 0 | V16: 14 | W16: 0 | X16: 14 | Y16: 0 | Z16: 14 | AA16: 14 | AB16: 0 | AC16: 14 | AD16: 0
A17: Curall | B17: Sold, 14 quarters. | C17: 0 | D17: 0 | E17: 0 | F17: 0 | G17: 0 | H17: 0 | I17: 0 | J17: 0 | K17: 0 | L17: 0 | M17: 0 | N17: 0 | O17: 0 | P17: 0 | Q17: 14 | R17: 0 | S17: 14 | T17: 0 | U17: 0 | V17: 0 | W17: 0 | X17: 14 | Y17: 0 | Z17: 14 | AA17: 14 | AB17: 0 | AC17: 14 | AD17: 0
A18: Curall | B18: Total | C18: 0 | D18: 0 | E18: 0 | F18: 0 | G18: 0 | H18: 0 | I18: 0 | J18: 0 | K18: 0 | L18: 0 | M18: 0 | N18: 0 | O18: 0 | P18: 0 | Q18: 0 | R18: 0 | S18: 0 | T18: 0 | U18: 0 | V18: 0 | W18: 0
A19: Barley | B19: {yield: three-and-a-half-fold less 3 quarters 7 bushels} | C19: 0 | D19: 0 | E19: 0 | F19: 0 | G19: 0 | H19: 0 | I19: 0 | J19: 0 | K19: 0 | L19: 0 | M19: 0 | N19: 0 | O19: 0 | P19: 0 | Q19: 0 | R19: 0 | S19: 0 | T19: 0 | U19: 0 | V19: 0 | W19: 0 | X19: 3 | Y19: 7 | Z19: 3.875 | AA19: 3.875 | AB19: 0 | AC19: 3 | AD19: 7
A20: Barley | B20: The same render account for 14 quarters of barley remaining from the previous year in the granary. | C20: 0 | D20: 0 | E20: 0 | F20: 0 | G20: 0 | H20: 0 | I20: 0 | J20: 0 | K20: 0 | L20: 0 | M20: 0 | N20: 0 | O20: 0 | P20: 0 | Q20: 0 | R20: 0 | S20: 0 | T20: 14 | U20: 0 | V20: 14 | W20: 0 | X20: 14 | Y20: 0 | Z20: 14 | AA20: 14 | AB20: 0 | AC20: 14 | AD20: 0
A21: Barley | B21: 101 quarters 1 bushels from the whole issue of barley this year by struck measure. | C21: 0 | D21: 0 | E21: 0 | F21: 0 | G21: 0 | H21: 0 | I21: 0 | J21: 0 | K21: 0 | L21: 0 | M21: 0 | N21: 0 | O21: 0 | P21: 0 | Q21: 0 | R21: 0 | S21: 0 | T21: 101 | U21: 1 | V21: 101.125 | W21: 0 | X21: 101 | Y21: 1 | Z21: 101.125 | AA21: 101.125 | AB21: 0 | AC21: 101 | AD21: 1
A22: Barley | B22: Total, 115 quarters 1 bushels | C22: 0 | D22: 0 | E22: 0 | F22: 0 | G22: 0 | H22: 0 | I22: 0 | J22: 0 | K22: 0 | L22: 0 | M22: 0 | N22: 0 | O22: 0 | P22: 0 | Q22: 0 | R22: 0 | S22: 0 | T22: 0 | U22: 0 | V22: 0 | W22: 0 | X22: 115 | Y22: 1 | Z22: 115.125 | AA22: 115.125 | AB22: 0 | AC22: 115 | AD22: 1
A23: Barley | B23: Sown over 95 acres as they lie in the field of la Chapele, 26.5 quarters. | C23: 0 | D23: 0 | E23: 26.5 | F23: 0 | G23: 26.5 | H23: 0 | I23: 0 | J23: 0 | K23: 0 | L23: 0 | M23: 0 | N23: 0 | O23: 0 | P23: 0 | Q23: 0 | R23: 0 | S23: 0 | T23: 0 | U23: 0 | V23: 0 | W23: 0 | X23: 26.5 | Y23: 0 | Z23: 26.5 | AA23: 26.5 | AB23: 0 | AC23: 26.5 | AD23: 0
A24: Barley | B24: that is, 4.5 bushels over 2 acres, less 1.5 bushels in all. | C24: 0 | D24: 0 | E24: 0 | F24: 0 | G24: 0 | H24: 0 | I24: 0 | J24: 0 | K24: 0 | L24: 0 | M24: 0 | N24: 0 | O24: 0 | P24: 0 | Q24: 0 | R24: 0 | S24: 0 | T24: 0 | U24: 0 | V24: 0 | W24: 0 | X24: 0 | Y24: 1.5 | Z24: 0.1875 | AA24: 0.5625 | AB24: -0.375 | AC24: 0 | AD24: 4.5 | AE24: 0 | AF24: 1.5
A25: Barley | B25: Delivered to 1 carter, 3 stot-keepers, and 1 keeper of hoggs and lambs for the year, 32.5 quarters, taking a quarter every 8 weeks. | C25: 0 | D25: 0 | E25: 0 | F25: 0 | G25: 0 | H25: 0 | I25: 0 | J25: 0 | K25: 0 | L25: 0 | M25: 0 | N25: 0 | O25: 0 | P25: 0 | Q25: 0 | R25: 0 | S25: 0 | T25: 0 | U25: 0 | V25: 0 | W25: 0 | X25: 32.5 | Y25: 0 | Z25: 32.5 | AA25: 32.5 | AB25: 0 | AC25: 32.5 | AD25: 0
A26: Barley | B26: Delivered to 2 oxherds for the year, because 3 customary tenants were drovers for the whole year to the advantage of the lord, 10 quarters 3 bushels, taking a quarter every 10 weeks. | C26: 0 | D26: 0 | E26: 0 | F26: 0 | G26: 0 | H26: 0 | I26: 0 | J26: 0 | K26: 0 | L26: 0 | M26: 0 | N26: 0 | O26: 0 | P26: 0 | Q26: 0 | R26: 0 | S26: 0 | T26: 0 | U26: 0 | V26: 0 | W26: 0 | X26: 10 | Y26: 3 | Z26: 10.375 | AA26: 10.375 | AB26: 0 | AC26: 10 | AD26: 3
A27: Barley | B27: Delivered to 1 dairymaid for the year, 5 quarters 1.5 bushels Delivered to 1 cowherd for the year, who takes a quarter every 12 weeks, 4 quarters 2.5 bushels Delivered to 3 keepers of lambs this year, 4 quarters 5 bushels. | C27: 0 | D27: 0 | E27: 0 | F27: 0 | G27: 0 | H27: 0 | I27: 0 | J27: 0 | K27: 0 | L27: 0 | M27: 0 | N27: 0 | O27: 0 | P27: 0 | Q27: 0 | R27: 0 | S27: 0 | T27: 0 | U27: 0 | V27: 0 | W27: 0 | X27: 8 | Y27: 7.5 | Z27: 8.9375 | AA27: 5.1875 | AB27: 3.75 | AC27: 5 | AD27: 1.5 | AE27: 4 | AF27: 2.5 | AG27: 4 | AH27: 5
A28: Barley | B28: provision of the bailiff's attendant, 3 quarters. | C28: 0 | D28: 0 | E28: 0 | F28: 0 | G28: 0 | H28: 0 | I28: 0 | J28: 0 | K28: 0 | L28: 0 | M28: 0 | N28: 0 | O28: 0 | P28: 0 | Q28: 0 | R28: 0 | S28: 0 | T28: 0 | U28: 0 | V28: 0 | W28: 0 | X28: 3 | Y28: 0 | Z28: 3 | AA28: 3 | AB28: 0 | AC28: 3 | AD28: 0
A29: Barley | B29: Sold, 28 quarters 5 bushels | C29: 0 | D29: 0 | E29: 0 | F29: 0 | G29: 0 | H29: 0 | I29: 0 | J29: 0 | K29: 0 | L29: 0 | M29: 0 | N29: 0 | O29: 0 | P29: 0 | Q29: 28 | R29: 5 | S29: 28.625 | T29: 0 | U29: 0 | V29: 0 | W29: 0 | X29: 28 | Y29: 5 | Z29: 28.625 | AA29: 28.625 | AB29: 0 | AC29: 28 | AD29: 5
A30: Barley | B30: Total | C30: 0 | D30: 0 | E30: 0 | F30: 0 | G30: 0 | H30: 0 | I30: 0 | J30: 0 | K30: 0 | L30: 0 | M30: 0 | N30: 0 | O30: 0 | P30: 0 | Q30: 0 | R30: 0 | S30: 0 | T30: 0 | U30: 0 | V30: 0 | W30: 0
A31: Oats | B31: {yield: two-fold less 40 quarters 1 bushels) | C31: 0 | D31: 0 | E31: 0 | F31: 0 | G31: 0 | H31: 0 | I31: 0 | J31: 0 | K31: 0 | L31: 0 | M31: 0 | N31: 0 | O31: 0 | P31: 0 | Q31: 0 | R31: 0 | S31: 0 | T31: 0 | U31: 0 | V31: 0 | W31: 0 | X31: 40 | Y31: 1 | Z31: 40.125 | AA31: 40.125 | AB31: 0 | AC31: 40 | AD31: 1
A32: Oats | B32: The same render account for 572 quarters 7 bushels from the whole issue of oats by struck measure. | C32: 0 | D32: 0 | E32: 0 | F32: 0 | G32: 0 | H32: 0 | I32: 0 | J32: 0 | K32: 0 | L32: 0 | M32: 0 | N32: 0 | O32: 0 | P32: 0 | Q32: 0 | R32: 0 | S32: 0 | T32: 572 | U32: 7 | V32: 572.875 | W32: 0 | X32: 572 | Y32: 7 | Z32: 572.875 | AA32: 572.875 | AB32: 0 | AC32: 572 | AD32: 7
A33: Oats | B33: 42 quarters by estimation in sheaves. | C33: 0 | D33: 0 | E33: 0 | F33: 0 | G33: 0 | H33: 0 | I33: 0 | J33: 0 | K33: 0 | L33: 0 | M33: 0 | N33: 0 | O33: 0 | P33: 0 | Q33: 0 | R33: 0 | S33: 0 | T33: 0 | U33: 0 | V33: 0 | W33: 0 | X33: 42 | Y33: 0 | Z33: 42 | AA33: 42 | AB33: 0 | AC33: 42 | AD33: 0
A34: Oats | B34: Total, 614 quarters 7 bushels | C34: 0 | D34: 0 | E34: 0 | F34: 0 | G34: 0 | H34: 0 | I34: 0 | J34: 0 | K34: 0 | L34: 0 | M34: 0 | N34: 0 | O34: 0 | P34: 0 | Q34: 0 | R34: 0 | S34: 0 | T34: 0 | U34: 0 | V34: 0 | W34: 0 | X34: 614 | Y34: 7 | Z34: 614.875 | AA34: 614.875 | AB34: 0 | AC34: 614 | AD34: 7
A35: Oats | B35: Sown over 685 acres as they lie in the fields of la Chapele, Ponfaldesgore, and Crembe, 190 quarters. | C35: 0 | D35: 0 | E35: 190 | F35: 0 | G35: 190 | H35: 0 | I35: 0 | J35: 0 | K35: 0 | L35: 0 | M35: 0 | N35: 0 | O35: 0 | P35: 0 | Q35: 0 | R35: 0 | S35: 0 | T35: 0 | U35: 0 | V35: 0 | W35: 0 | X35: 190 | Y35: 0 | Z35: 190 | AA35: 190 | AB35: 0 | AC35: 190 | AD35: 0
A36: Oats | B36: that is, 4.5 bushels over 2 acres, less 2 quarters 5 bushels in all. | C36: 0 | D36: 0 | E36: 0 | F36: 0 | G36: 0 | H36: 0 | I36: 0 | J36: 0 | K36: 0 | L36: 0 | M36: 0 | N36: 0 | O36: 0 | P36: 0 | Q36: 0 | R36: 0 | S36: 0 | T36: 0 | U36: 0 | V36: 0 | W36: 0 | X36: 2 | Y36: 5 | Z36: 2.625 | AA36: 0.5625 | AB36: 2.0625 | AC36: 0 | AD36: 4.5 | AE36: 2 | AF36: 5
A37: Oats | B37: . | C37: 0 | D37: 0 | E37: 0 | F37: 0 | G37: 0 | H37: 0 | I37: 0 | J37: 0 | K37: 0 | L37: 0 | M37: 0 | N37: 0 | O37: 0 | P37: 0 | Q37: 0 | R37: 0 | S37: 0 | T37: 0 | U37: 0 | V37: 0 | W37: 0 | X37: 0 | Y37: 0 | Z37: 0 | AA37: 0 | AB37: 0 | AC37: 0 | AD37: 0
A38: Oats | B38: . | C38: 0 | D38: 0 | E38: 0 | F38: 0 | G38: 0 | H38: 0 | I38: 0 | J38: 0 | K38: 0 | L38: 0 | M38: 0 | N38: 0 | O38: 0 | P38: 0 | Q38: 0 | R38: 0 | S38: 0 | T38: 0 | U38: 0 | V38: 0 | W38: 0 | X38: 0 | Y38: 0 | Z38: 0 | AA38: 0 | AB38: 0 | AC38: 0 | AD38: 0
A39: Oats | B39: . | C39: 0 | D39: 0 | E39: 0 | F39: 0 | G39: 0 | H39: 0 | I39: 0 | J39: 0 | K39: 0 | L39: 0 | M39: 0 | N39: 0 | O39: 0 | P39: 0 | Q39: 0 | R39: 0 | S39: 0 | T39: 0 | U39: 0 | V39: 0 | W39: 0 | X39: 0 | Y39: 0 | Z39: 0 | AA39: 0 | AB39: 0 | AC39: 0 | AD39: 0
A40: Oats | B40: . | C40: 0 | D40: 0 | E40: 0 | F40: 0 | G40: 0 | H40: 0 | I40: 0 | J40: 0 | K40: 0 | L40: 0 | M40: 0 | N40: 0 | O40: 0 | P40: 0 | Q40: 0 | R40: 0 | S40: 0 | T40: 0 | U40: 0 | V40: 0 | W40: 0 | X40: 0 | Y40: 0 | Z40: 0 | AA40: 0 | AB40: 0 | AC40: 0 | AD40: 0
...

Sheet Sale of Corn Prices
A1: Heading | B1: Sentence | C1: Total in Pounds | D1: Pounds | E1: Shillings | F1: Pence | G1: Corn | H1: Total Quarters Except 1 | I1: Total Bushels Except 1 | J1: Total Corn Cross-Check | K1: Total Corn Manorial Account | L1: Corn Quantity Error | M1: Quarters 0 | N1: Bushels 0 | O1: shilling a quarter 1 | P1: pence a quarter 1 | Q1: Quarters 1 | R1: Bushels 1 | S1: shilling a quarter 2 | T1: pence a quarter 2 | U1: Quarters 2 | V1: Bushels 2 | W1: shilling a quarter 3 | X1: pence a quarter 3 | Y1: Quarters 3 | Z1: Bushels 3 | AA1: shilling a quarter 4 | AB1: pence a quarter 4 | AC1: Quarters 4 | AD1: Bushels 4 | AE1: shilling a quarter 5 | AF1: pence a quarter 5 | AG1: Quarters 5 | AH1: Bushels 5 | AI1: £ a quarter 1 | AJ1: £ a quarter 2 | AK1: £ a quarter 3 | AL1: £ a quarter 4 | AM1: £ a quarter 5 | AN1: Quarters Sold | AO1: Weighted Average Price per Quarter | AP1: Non-Weighted Average Price per Quarter | AQ1: Corn lowercase
A2: Sale of corn | B2: The same render account for £75 10 shilling 5pence from 274 quarters 2 bushels of wheat sold, at 4 shilling a quarters for 29 quarters 2 bushels, 5 shilling a quarters for 70 quarters 6 bushels, 5 shilling 4pence a quarters for 82 quarters 3 bushels, 6 shilling a quarters for 18 quarters 2 bushels, and 6 shilling 8pence a quarters for 73 quarters 5 bushels. | C2: 75.52 | D2: 75 | E2: 10 | F2: 5 | G2: wheat | H2: 272 | I2: 18 | J2: 274.25 | K2: 274.25 | L2: 0 | M2: 274 | N2: 2 | O2: 4 | P2: 0 | Q2: 29 | R2: 2 | S2: 5 | T2: 0 | U2: 70 | V2: 6 | W2: 5 | X2: 4 | Y2: 82 | Z2: 3 | AA2: 6 | AB2: 0 | AC2: 18 | AD2: 2 | AE2: 6 | AF2: 8 | AG2: 73 | AH2: 5 | AI2: 0.2 | AJ2: 0.25 | AK2: 0.26666667 | AL2: 0.3 | AM2: 0.33333333 | AN2: 274.25 | AO2: 0.27537223 | AP2: 0.27 | AQ2: wheat
A3: Sale of corn | B3: £2 6 shilling 8pence from 14 quarters of curall sold, at 3 shilling 4pence a quarters. | C3: 2.33 | D3: 2 | E3: 6 | F3: 8 | G3: curall | H3: 14 | I3: 0 | J3: 14 | K3: 14 | L3: 0 | M3: 14 | N3: 0 | O3: 3 | P3: 4 | AI3: 0.16666667 | AN3: 14 | AO3: 0.16666667 | AP3: 0.16666667 | AQ3: curall
A4: Sale of corn | B4: £5 10 shilling 10.5pence from 28 quarters 5 bushels of barley sold, at 4 shilling a quarters for 25 quarters, and 3 shilling a quarters for 3 quarters 5 bushels. | C4: 5.54 | D4: 5 | E4: 10 | F4: 10.5 | G4: barley | H4: 28 | I4: 5 | J4: 28.625 | K4: 28.625 | L4: 0 | M4: 28 | N4: 5 | O4: 4 | P4: 0 | Q4: 25 | R4: 0 | S4: 3 | T4: 0 | U4: 3 | V4: 5 | AI4: 0.2 | AJ4: 0.15 | AN4: 28.625 | AO4: 0.19366812 | AP4: 0.175 | AQ4: barley
A5: Sale of corn | B5: £28 8 shilling 4.75pence from 275 quarters 3 bushels of oats sold, at 1 shilling 8pence a quarters for 55 quarters 3 bushels, 2 shilling a quarters for 86 quarters 3 bushels, 2 shilling 2pence a quarters for 50 quarters 5 bushels, and 2 shilling 4pence a quarters for 83 quarters. | C5: 28.42 | D5: 28 | E5: 8 | F5: 4.75 | G5: oats | H5: 274 | I5: 11 | J5: 275.375 | K5: 275.375 | L5: 0 | M5: 275 | N5: 3 | O5: 1 | P5: 8 | Q5: 55 | R5: 3 | S5: 2 | T5: 0 | U5: 86 | V5: 3 | W5: 2 | X5: 2 | Y5: 50 | Z5: 5 | AA5: 2 | AB5: 4 | AC5: 83 | AD5: 0 | AI5: 0.083333333 | AJ5: 0.1 | AK5: 0.10833333 | AL5: 0.11666667 | AN5: 275.375 | AO5: 0.10320396 | AP5: 0.10208333 | AQ5: oats
A6: Sale of corn | B6: Total of all corn sold, £111 16 shilling 4.25pence | C6: 111.82 | D6: 111 | E6: 16 | F6: 4.25 | H6: 0 | I6: 0 | J6: 0 | K6: 0 | L6: 0 | M6: 0 | N6: 0 | AI6: inf | AN6: 0 | AO6: inf | AP6: inf
