Workbook

Sheet Gosport Overview - Completed
A1: GOSPORT OVERVIEW - COMPLETED | B1: Total in £ | C1: Error | D1: Note
A2: CASH ACCOUNT
A3: RECEIPTS
A4: Arrears total
A5: Rents of assize total | B5: 6.54
A6: Quittances total
A7: Defaults of rent total | B7: 0.4125
A8: Defaults of rent through the pestilence total
A9: Cotlands defaults total
A10: Cotlands total
A11: Total of quittances and defaults of rent total
A12: Total of rents remaining clear total
A13: Farms total
A14: Annual recognizances total
A15: Issues of the Manor total
A16: Issues of the tenements in the lord's hands total
A17: Sale of labour services total
A18: Sale of corn total
A19: Entry and marriage fines total
... A22: Farm of the demesne land total
A23: Total of all receipts (calculated here) | B23: =SUM(B5:B22) -> 6.9525
A24: Total of all receipts (calculated here) incl arrears | B24: =SUM(B4:B22) -> 6.9525
A25: Total recorded in the accounts excl. arrears | C25: =B23-B25 -> 6.9525
A26: Total recorded in the accounts incl. arrears | B26: =B25+B4 -> 0
A29: EXPENSES
A30: Cost of ploughs total
A31: Purchase of corn total
A32: Cost of carts and wagons total
A33: Cost of dairy total
A34: Purchase of stock total
A35: Sheepcote total
A36: Cost of buildings total
A37: Threshing total
A38: Barley expenses
A39: Expenses of the harvest total
A40: Necessary expenses
... A47: Total Demesne fixed investment
A49: Owed by the reeve | B49: =B23-B45 -> 6.9525
A50: From accounts
A52: Allowances
...

Sheet Labour Rents

Sheet Overview
A1: GOSPORT | B1: Total in £ | C1: Error | D1: Note
A2: CASH ACCOUNT
A3: RECEIPTS
A4: Arrears total
A5: Rents of assize total
A6: Quittances total
A7: Defaults of rent total
A8: Defaults of rent through the pestilence total
A9: Cotlands defaults total
A10: Cotlands total
A11: Total of quittances and defaults of rent total
A12: Total of rents remaining clear total
A13: Farms total
... A183: % of capital expenses as calculated previously

Sheet Receipts
A1: GOSPORT RECEIPTS
A2: Heading | B2: £ | C2: s | D2: d | F2: Total in £ | G2: Error | H2: Notes | I2: Own notes
A3: Rents | B3: 6 | C3: 10 | D3: 8.5 | F3: 6.54 | H3: John Pulayn renders account for £6 10 shilling 8.5pence for all rents of assize for the year.
A4: Rents | B4: 6 | C4: 10 | D4: 8.5 | F4: 6.54 | H4: Total, £6 10 shilling 8.5pence
A5: Rents | F5: 6.54 | G5: 0 | H5: Total
A7: Defaults of rent | B7: 0 | C7: 0 | D7: 9 | F7: 0.04 | H7: In default of 1.5 plots which belonged to Amice, relict of the cobbler, inundated by the sea 9pence.
A8: Defaults of rent | B8: 0 | C8: 0 | D8: 6 | F8: 0.03 | H8: 1 plot of land which belonged to Henry Curtays inundated by the sea 6pence.
A9: Defaults of rent | B9: 0 | C9: 0 | D9: 6 | F9: 0.03 | H9: 1 plot of land which belonged to Thomas Poyn inundated by the sea 6pence.
A10: Defaults of rent | B10: 0 | C10: 0 | D10: 3 | F10: 0.01 | H10: 0.5 plot of land which belonged to John Davel inundated by the sea 3pence.
A11: Defaults of rent | B11: 0 | C11: 0 | D11: 6 | F11: 0.03 | H11: 1 plot of land which belonged to Agnes Mulet inundated by the sea 6pence.
A12: Defaults of rent | B12: 0 | C12: 0 | D12: 9 | F12: 0.04 | H12: 1.5 plots of land which belonged to Henry Fossadam' inundated by the sea 9pence.
A13: Defaults of rent | B13: 0 | C13: 1 | D13: 0 | F13: 0.05 | H13: 2 plots which belonged to Bartholomew Bonekar' inundated by the sea 1 shilling.
A14: Defaults of rent | B14: 0 | C14: 0 | D14: 6 | F14: 0.03 | H14: 1 plot of land which belonged to John Hendel inundated by the sea 6pence.
A15: Defaults of rent | B15: 0 | C15: 0 | D15: 6 | F15: 0.03 | H15: 1 plot of land which belonged to Sibyl Lablto inundated by the sea 6pence.
A16: Defaults of rent | B16: 0 | C16: 0 | D16: 6 | F16: 0.03 | H16: 1 plot of land which belonged to Rose Swole inundated the sea 6pence.
A17: Defaults of rent | B17: 0 | C17: 0 | D17: 0 | F17: 0 | H17: 1 plot of land which belonged to Richard Trut inundated by the sea 6d.
A18: Defaults of rent | B18: 0 | C18: 0 | D18: 3 | F18: 0.01 | H18: 0.5 plot of land which belonged to Thomas Edward' inundated by the sea 3pence.
... A21: Defaults of rent | B21: 0 | C21: 0 | D21: 6 | F21: 0.03 | H21: 1 plot of land which belonged to Laurence le Blak' inundated by the sea 6pence.
A22: Defaults of rent | B22: 0 | C22: 0 | D22: 3 | F22: =B22+C22/20+D22/240 -> 0.0125 | H22: 0.5 plot of land which belonged to Matilda de Schale inundated by the sea 3pence
A23: Defaults of rent | B23: 0 | C23: 8 | D23: 0 | F23: =B23+C23/20+D23/240 -> 0.4 | H23: Total, 8 shilling
A24: Defaults of rent | F24: =SUM(F7:F22) -> 0.4125 | G24: =F24-F23 -> 0.0125 | H24: Total
A26: Total of rents remaining | B26: 6 | C26: 2 | D26: 8.5 | F26: 6.14 | H26: Total of rents remaining, £6 2 shilling 8.5pence
A27: Total of rents remaining | F27: 6.14 | G27: =F27-F26 -> 0 | H27: Total
A29: Reliefs | B29: 0 | C29: 0 | D29: 4 | F29: 0.02 | H29: The same render account for 4pence from Robert de Forton for relief for 1 acre of land by the legacy of John his brother.
A30: Reliefs | B30: 0 | C30: 4 | D30: 1 | F30: 0.2 | H30: 4 shilling 1pence from Bartholomew Hendel for relief for 12 acres and 1 perch of land and tenements which belonged to William Hendel his father.
A31: Reliefs | B31: 0 | C31: 1 | D31: 0 | F31: 0.05 | H31: 1 shilling from William Hendel for relief for 3 acres of land by the legacy of William Hendel his father.
A32: Reliefs | B32: 0 | C32: 0 | D32: 10 | F32: 0.04 | H32: 10pence from John, Richard, John, Henry, Alice, Matilda and Emma Hendel for relief for 2.5 acres which belonged to William le Hendel their father by legacy.
A33: Reliefs | B33: 0 | C33: 0 | D33: 8 | F33: 0.03 | H33: 8pence from Alice and Agnes, daughters of Adam Bild', for relief for 2 acres of land and tenements which belonged to Adam Bild' their father.
A34: Reliefs | B34: 0 | C34: 6 | D34: 11 | F34: 0.35 | H34: Total, 6 shilling 11pence
A35: Reliefs | F35: 0.34 | G35: -0.01 | H35: Total
A37: Perquisites | B37: 0 | C37: 0 | D37: 3 | F37: 0.01 | H37: The same render account for 3pence from William le Kyngt for transgression against Alice, relict of William le Kynge.
A38: Perquisites | B38: 0 | C38: 0 | D38: 3 | F38: 0.01 | H38: 3pence from Thomas Durant for transgression against John de la Frith'.
A39: Perquisites | B39: 0 | C39: 0 | D39: 3 | F39: 0.01 | H39: 3pence from John Reynold' for breaking the assize of ale.
A40: Perquisites | B40: 0 | C40: 0 | D40: 3 | F40: 0.01 | H40: 3pence from John Franceys for the same.
A41: Perquisites | B41: 0 | C41: 0 | D41: 3 | F41: 0.01 | H41: 3pence from Henry Walter for the same.
A42: Perquisites | B42: 0 | C42: 0 | D42: 3 | F42: 0.01 | H42: 3pence from Alice le Tug for the same.
A43: Perquisites | B43: 0 | C43: 0 | D43: 3 | F43: 0.01 | H43: 3pence from John Aze for the same.
A44: Perquisites | B44: 0 | C44: 0 | D44: 3 | F44: 0.01 | H44: 3pence from Alice Schynnyld for the same.
A45: Perquisites | B45: 0 | C45: 0 | D45: 3 | F45: 0.01 | H45: 3pence from Thomas Edward for the same.
A46: Perquisites | B46: 0 | C46: 0 | D46: 3 | F46: 0.01 | H46: 3pence from John Prevet for the same.
...

Sheet Expenses
A1: GOSPORT EXPENSES
A2: Heading | B2: £ | C2: s | D2: d | F2: Total in £ | G2: Error | H2: Notes
A3: And he owes | B3: 0 | C3: 0 | D3: 0 | F3: 0 | H3: And he owes it all.
A4: And he owes | B4: 5 | C4: 0 | D4: 0 | F4: 5 | H4: Delivered to Sir Geoffrey, treasurer of Wolvesey, by 1 tally, £5.
A5: And he owes | F5: 5 | G5: 0 | H5: Total
A7: And thus he owes clear | B7: 1 | C7: 17 | D7: 10.5 | F7: 1.89 | H7: And thus he owes clear, £1 17 shilling 10.5pence
A8: And thus he owes clear | F8: 1.89 | G8: 0 | H8: Total

Sheet Issues of the Grange
A1: no grange

Sheet Issues of the Mills
A1: no mills

Sheet Stock
A1: no stock

Sheet Prices

Sheet raw data
A1: Heading | B1: Sentence | C1: Total in Pounds | D1: Pounds | E1: Shillings | F1: Pence | G1: Corn | H1: Total Quarters Except 1 | I1: Total Bushels Except 1 | J1: Total Corn Cross-Check | K1: Total Corn Manorial Account | L1: Corn Quantity Error | M1: Quarters 1 | N1: Bushels 1 | O1: shilling a quarter 1 | P1: pence a quarter 1 | Q1: shilling a quarter 2 | R1: pence a quarter 2 | S1: shilling a quarter 3 | T1: pence a quarter 3 | U1: shilling a quarter 4 | V1: pence a quarter 4 | W1: shilling a bushel 1 | X1: pence a bushel 1 | Y1: shilling a bushel 2 | Z1: pence a bushel 2 | AA1: shilling a bushel 3 | AB1: pence a bushel 3 | AC1: shilling a bushel 4 | AD1: pence a bushel 4
A2: Rents | B2: John Pulayn renders account for £6 10 shilling 8.5pence for all rents of assize for the year. | C2: 6.54 | D2: 6 | E2: 10 | F2: 8.5 | H2: 0 | I2: 0 | J2: 0 | K2: 0 | L2: 0 | M2: 0 | N2: 0
A3: Rents | B3: Total, £6 10 shilling 8.5pence | C3: 6.54 | D3: 6 | E3: 10 | F3: 8.5 | H3: 0 | I3: 0 | J3: 0 | K3: 0 | L3: 0 | M3: 0 | N3: 0
A4: Defaults of rent | B4: In default of 1.5 plots which belonged to Amice, relict of the cobbler, inundated by the sea 9pence. | C4: 0.04 | D4: 0 | E4: 0 | F4: 9 | H4: 0 | I4: 0 | J4: 0 | K4: 0 | L4: 0 | M4: 0 | N4: 0
A5: Defaults of rent | B5: 1 plot of land which belonged to Henry Curtays inundated by the sea 6pence. | C5: 0.03 | D5: 0 | E5: 0 | F5: 6 | H5: 0 | I5: 0 | J5: 0 | K5: 0 | L5: 0 | M5: 0 | N5: 0
A6: Defaults of rent | B6: 1 plot of land which belonged to Thomas Poyn inundated by the sea 6pence. | C6: 0.03 | D6: 0 | E6: 0 | F6: 6 | H6: 0 | I6: 0 | J6: 0 | K6: 0 | L6: 0 | M6: 0 | N6: 0
A7: Defaults of rent | B7: 0.5 plot of land which belonged to John Davel inundated by the sea 3pence. | C7: 0.01 | D7: 0 | E7: 0 | F7: 3 | H7: 0 | I7: 0 | J7: 0 | K7: 0 | L7: 0 | M7: 0 | N7: 0
A8: Defaults of rent | B8: 1 plot of land which belonged to Agnes Mulet inundated by the sea 6pence. | C8: 0.03 | D8: 0 | E8: 0 | F8: 6 | H8: 0 | I8: 0 | J8: 0 | K8: 0 | L8: 0 | M8: 0 | N8: 0
A9: Defaults of rent | B9: 1.5 plots of land which belonged to Henry Fossadam' inundated by the sea 9pence. | C9: 0.04 | D9: 0 | E9: 0 | F9: 9 | H9: 0 | I9: 0 | J9: 0 | K9: 0 | L9: 0 | M9: 0 | N9: 0
A10: Defaults of rent | B10: 2 plots which belonged to Bartholomew Bonekar' inundated by the sea 1 shilling. | C10: 0.05 | D10: 0 | E10: 1 | F10: 0 | H10: 0 | I10: 0 | J10: 0 | K10: 0 | L10: 0 | M10: 0 | N10: 0
A11: Defaults of rent | B11: 1 plot of land which belonged to John Hendel inundated by the sea 6pence. | C11: 0.03 | D11: 0 | E11: 0 | F11: 6 | H11: 0 | I11: 0 | J11: 0 | K11: 0 | L11: 0 | M11: 0 | N11: 0
A12: Defaults of rent | B12: 1 plot of land which belonged to Sibyl Lablto inundated by the sea 6pence. | C12: 0.03 | D12: 0 | E12: 0 | F12: 6 | H12: 0 | I12: 0 | J12: 0 | K12: 0 | L12: 0 | M12: 0 | N12: 0
A13: Defaults of rent | B13: 1 plot of land which belonged to Rose Swole inundated the sea 6pence. | C13: 0.03 | D13: 0 | E13: 0 | F13: 6 | H13: 0 | I13: 0 | J13: 0 | K13: 0 | L13: 0 | M13: 0 | N13: 0
... A56: And thus he owes clear | B56: And thus he owes clear, £1 17 shilling 10.5pence | C56: 1.89 | D56: 1 | E56: 17 | F56: 10.5 | H56: 0 | I56: 0 | J56: 0 | K56: 0 | L56: 0 | M56: 0 | N56: 0
