Workbook

Sheet Hambledon Overview - Completed
A1: HAMBLEDON OVERVIEW - COMPLETED | B1: Total in £ | C1: Error | D1: Note
A2: CASH ACCOUNT
A3: RECEIPTS
A4: Arrears total | B4: 68.63
A5: Rents of assize total | B5: 32.394792
A6: Quittances total | B6: 0.9
A7: Defaults of rent total | B7: 0.44
A8: Defaults of rent through the pestilence total
A9: Cotlands defaults total
A10: Cotlands total
A11: Total of quittances and defaults of rent total
A12: Total of rents remaining clear total
A13: Farms total
A14: Annual recognizances total | B14: 0.16
A15: Issues of the Manor total | B15: 42.17
A16: Issues of the tenements in the lord's hands total
A17: Sale of labour services total
A18: Sale of corn total | B18: 24.16
A19: Entry and marriage fines total | B19: 3.7
A20: Pleas & perquisites total
A21: Forfeited chattels total
A22: Farm of the demesne land total
A23: Total of all receipts (calculated here) | B23: =SUM(B5:B22)
A24: Total of all receipts (calculated here) incl arrears | B24: =SUM(B4:B22)
A25: Total recorded in the accounts excl. arrears | B25: 107.03 | C25: =B23-B25
A26: Total recorded in the accounts incl. arrears | B26: =B25+B4
A29: EXPENSES
A30: Cost of ploughs total | B30: 3.1025
A31: Purchase of corn total | B31: 0.87
A32: Cost of carts and wagons total
A33: Cost of dairy total
A34: Purchase of stock total | B34: 13.73
A35: Sheepcote total | B35: 0.1275
A36: Cost of buildings total
A37: Threshing total | B37: 1.545
A38: Barley expenses
A39: Expenses of the harvest total
A40: Necessary expenses
A41: Wages of the bailiff
A42: Steward's expenses total | B42: 0.48
...

Sheet Prices
A1: Meat & Dairy Prices
C2: 1301 | D2: 1302 | E2: Average
A3: Beef | B3: £ per lb | C3: 0.0033351854 | D3: 0.0032608538 | E3: =AVERAGE(C3:D3)
A4: Mutton | B4: £ per lb | C4: 0.0036593977 | D4: 0.0037125513 | E4: =AVERAGE(C4:D4)
A5: Pork | B5: £ per lb | C5: 0.0038431326 | D5: 0.0037574803 | E5: =AVERAGE(C5:D5)
A6: Cheese | B6: £ per lb | C6: 0.0055768754 | D6: 0.0056654898 | E6: =AVERAGE(C6:D6)
A7: Butter | B7: £ per lb | C7: 0.0036626221 | D7: 0.0035935077 | E7: =AVERAGE(C7:D7)
A8: Milk | B8: £ per gallon | C8: 0.0055768754 | D8: 0.0056654898 | E8: =AVERAGE(C8:D8)

Sheet Labour Rents

Sheet Overview
A1: HAMBLEDON | B1: Total in £ | C1: Error | D1: Note
A2: CASH ACCOUNT
A3: RECEIPTS
A4: Arrears total
A5: Rents of assize total
A6: Quittances total
A7: Defaults of rent total
A8: Defaults of rent through the pestilence total
A9: Cotlands defaults total
A10: Cotlands total
A11: Total of quittances and defaults of rent total
A12: Total of rents remaining clear total
A13: Farms total
... A22: Farm of the demesne land total
A23: Total of all receipts (calculated here) | B23: =Receipts!F168
A24: Total of all receipts (calculated here) incl arrears | B24: =Receipts!F169
A25: Total recorded in the accounts excl. arrears | B25: =Receipts!F167 | C25: =B25-B23
A26: Total recorded in the accounts incl. arrears
A29: EXPENSES
A30: Cost of ploughs total
A31: Purchase of corn total
A32: Cost of carts and wagons total
A33: Cost of dairy total
A34: Purchase of stock total
A35: Sheepcote total
A36: Cost of buildings total
A37: Threshing total
A38: Barley expenses
A39: Expenses of the harvest total
... A43: Annual fees
A44: Total of all expenses per account | B44: =Expenses!F122
A45: Total of all expenses (calculated here) | B45: =Expenses!F123
A46: Total fixed investment | B46: =Expenses!F124
A47: Total Demesne fixed investment | B47: =Expenses!F125
A49: Owed by the reeve
A50: From accounts
A52: Allowances
A53: Cash deliveries
A54: Sum of the above
A55: Total of all allowances and cash deliveries in accounts
...

Sheet Receipts
A1: HAMBLEDON RECEIPTS
A2: Heading | B2: £ | C2: s | D2: d | F2: Total in £ | G2: Error | H2: Notes | I2: Own notes
A3: Arrears | B3: 68 | C3: 12 | D3: 7.25 | F3: 68.63 | H3: Nicholas, bailiff, and William Bouelych', reeve, render account for £68 12 shilling 7.25pence of arrears from the previous year.
A4: Arrears | B4: 0 | C4: 0 | D4: 0 | F4: 0 | H4: All delivered to Sir Geoffrey, treasurer of Wolvesey.
A5: Arrears | B5: 0 | C5: 0 | D5: 0 | F5: 0 | H5: They are quit.
A6: Arrears | F6: 68.63 | G6: =F6-F3 | H6: Total
A8: Rents of assize | B8: 6 | C8: 13 | D8: 11.25 | F8: 6.7 | H8: The same render account for £6 13 shilling 11.25pence for rents of assize at Christmas.
A9: Rents of assize | B9: 7 | C9: 9 | D9: 1 | F9: 7.45 | H9: £7 9 shilling 1pence at Easter (22 April).
A10: Rents of assize | B10: 6 | C10: 13 | D10: 11.25 | F10: 6.7 | H10: £6 13 shilling 11.25pence at St John the Baptist (24 June).
A11: Rents of assize | B11: 11 | C11: 10 | D11: 10.75 | F11: =B11+C11/20+D11/240 | H11: £11 10 shilling 10.75pence at Michaelmas (29 September).
A12: Rents of assize | B12: 32 | C12: 7 | D12: 10.25 | F12: 32.39 | H12: Total, £32 7 shilling 10.25pence
A13: Rents of assize | F13: =SUM(F8:F11) | G13: =F13-F12 | H13: Total
A15: Increment | B15: 0 | C15: 0 | D15: 1 | F15: =B15+C15/20+D15/240 | H15: The same render account for 1pence for the increment of rent from Robert Faber to have 1 plot of land, 12 feet long and 5 feet wide, in the vill of Hambledon.
A16: Increment | B16: 0 | C16: 0 | D16: 1 | F16: =B16+C16/20+D16/240 | H16: Total, 1pence
A17: Increment | F17: =B17+C17/20+D17/240 | G17: =F17-F16 | H17: Total
A19: Total Rents | B19: 32 | C19: 7 | D19: 11.25 | F19: 32.4 | H19: Total of rents with increment, £32 7 shilling 11.25pence
A20: Total Rents | F20: =F13+F17 | G20: =F20-F19 | H20: Total
A22: Quittances | B22: 0 | C22: 2 | D22: 6 | F22: 0.12 | H22: In quittance of 1 reeve for the year 2 shilling 6pence.
A23: Quittances | B23: 0 | C23: 2 | D23: 6 | F23: 0.12 | H23: 1 bartoner for the year 2 shilling 6pence.
A24: Quittances | B24: 0 | C24: 5 | D24: 0 | F24: 0.25 | H24: 3 ploughmen for the year 5 shilling.
A25: Quittances | B25: 0 | C25: 5 | D25: 0 | F25: 0.25 | H25: 2 shepherds and 1 smith for the year 5 shilling.
A26: Quittances | B26: 0 | C26: 1 | D26: 8 | F26: 0.08 | H26: 1 cowherd for the year 1 shilling 8pence.
A27: Quittances | B27: 0 | C27: 1 | D27: 8 | F27: 0.08 | H27: 1 swineherd for the year 1 shilling 8pence
A28: Quittances | B28: 0 | C28: 18 | D28: 4 | F28: =B28+C28/20+D28/240 | H28: Total, 18 shilling 4pence
A29: Quittances | F29: 0.9 | G29: =F29-F28 | H29: Total
A31: Defaults of rent | B31: 0 | C31: 1 | D31: 6 | F31: 0.08 | H31: In default of the wood which Herbert' de Chidden' holds drawn into demesne, 1 shilling 6pence for the year.
A32: Defaults of rent | B32: 0 | C32: 0 | D32: 6 | F32: 0.03 | H32: the land of Shortelond', 6pence for the year.
A33: Defaults of rent | B33: 0 | C33: 0 | D33: 6 | F33: 0.03 | H33: 1 grove of Vineys drawn into demesne, 6pence for the year.
A34: Defaults of rent | B34: 0 | C34: 6 | D34: 0 | F34: =B34+C34/20+D34/240 | H34: the wood of Mannely which is in demesne through the death of the holder 6 shilling
A35: Defaults of rent | B35: 0 | C35: 8 | D35: 6 | F35: =B35+C35/20+D35/240 | H35: Total, 8 shilling 6pence
A36: Defaults of rent | F36: =SUM(F31:F34) | G36: =F36-F35 | H36: Total
A38: Total of rents remaining | B38: 31 | C38: 1 | D38: 1.25 | F38: 31.06 | H38: Total of rents remaining, £31 1 shilling 1.25pence
A39: Total of rents remaining | F39: 31.06 | G39: =F39-F38 | H39: Total
A41: Annual recognizance | B41: 0 | C41: 0 | D41: 3 | F41: 0.01 | H41: The same render account for 3pence from Walter ate Greve for recognizance.
A42: Annual recognizance | B42: 0 | C42: 0 | D42: 3 | F42: 0.01 | H42: 3pence from Stephen Blaysut to be able to remain in the hundred of East Meon.
A43: Annual recognizance | B43: 0 | C43: 0 | D43: 3 | F43: 0.01 | H43: 3pence from William le Boys for annual recognizance.
A44: Annual recognizance | B44: 0 | C44: 0 | D44: 3 | F44: 0.01 | H44: 3pence from Henry Faber for the same.
A45: Annual recognizance | B45: 0 | C45: 0 | D45: 4 | F45: 0.02 | H45: 4pence from Adam le Cauz for the same.
A46: Annual recognizance | B46: 0 | C46: 0 | D46: 3 | F46: 0.01 | H46: 3pence from Robert Buly for the same.
A47: Annual recognizance | B47: 0 | C47: 0 | D47: 3 | F47: 0.01 | H47: 3pence from William Tassor' for the same and henceforth nothing from the same because he is dead.
...

Sheet Expenses
A1: HAMBLEDON RECEIPTS
A2: Heading | B2: £ | C2: s | D2: d | F2: Total in £ | G2: Error | H2: Notes | I2: Own notes | K2: Fixed investment | L2: Demesne fixed investment
A3: Cost of ploughs | B3: 0 | C3: 0 | D3: 0 | F3: 0 | H3: (henceforth the ploughs of the customary tenants should not be taken if a profit is able to be made).
A4: Cost of ploughs | B4: 0 | C4: 11 | D4: 0 | F4: 0.55 | H4: iron and steel bought for 3 ploughs for the year 11 shilling. | K4: =F4 | L4: =K4
A5: Cost of ploughs | B5: 0 | C5: 1 | D5: 3 | F5: 0.06 | H5: 3 plough feet bought 1 shilling 3pence. | K5: =F5 | L5: =K5
A6: Cost of ploughs | B6: 0 | C6: 1 | D6: 6 | F6: 0.08 | H6: 2 ploughshares bought 1 shilling 6pence. | K6: =F6 | L6: =K6
A7: Cost of ploughs | B7: 0 | C7: 2 | D7: 3 | F7: 0.11 | H7: 5 ploughs made anew and others mended at various times, with timber felled and trimmed for the same, 2 shilling 3pence. | K7: =F7 | L7: =K7
A8: Cost of ploughs | B8: 0 | C8: 0 | D8: 6 | F8: 0.03 | H8: 2 pairs of wheels bought 6pence. | K8: =F8 | L8: =K8
A9: Cost of ploughs | B9: 0 | C9: 0 | D9: 6 | F9: 0.03 | H9: 3 harrows made anew 6pence. | K9: =F9 | L9: =K9
A10: Cost of ploughs | B10: 0 | C10: 0 | D10: 1.5 | F10: 0.01 | H10: fitting ploughs with iron tyres 1.5pence. | K10: =F10 | L10: =K10
A11: Cost of ploughs | B11: 0 | C11: 5 | D11: 6 | F11: 0.28 | H11: shoeing 6 plough-horses hauling ploughs at the time of both sowings and hauling dung when it was necessary until Lammas, because thereafter they were at the church, 5 shilling 6pence. | K11: =F11 | L11: =K11
A12: Cost of ploughs | B12: 1 | C12: 0 | D12: 0 | F12: 1 | H12: 32 ploughmen in winter and 32 in Lent, £1 according to custom, of whom each ploughman ploughed and harrowed 1 acre in winter and 1 acre in Lent.
A13: Cost of ploughs | B13: 0 | C13: 6 | D13: 9 | F13: 0.34 | H13: stipend of 3 ploughmen from Michaelmas until Lammas, because thereafter they were at the church, 6 shilling 9pence.
A14: Cost of ploughs | B14: 0 | C14: 12 | D14: 3 | F14: =B14+C14/20+D14/240 | H14: 1 plough-horse bought 12 shilling 3pence
A15: Cost of ploughs | B15: 3 | C15: 1 | D15: 7.5 | F15: 3.08 | H15: Total, £3 1 shilling 7.5pence
A16: Cost of ploughs | F16: =SUM(F3:F14) | G16: =F16-F15 | H16: Total
A18: Purchase of corn | B18: 0 | C18: 17 | D18: 4 | F18: 0.87 | H18: In 6.5 quarters of barley bought for the liveries of the manorial servants 17 shilling 4pence, at 2 shilling 8pence a qr.
A19: Purchase of corn | B19: 0 | C19: 17 | D19: 4 | F19: 0.87 | H19: Total, 17 shilling 4pence
A20: Purchase of corn | F20: 0.87 | G20: 0 | H20: Total
A22: Cost of carts | B22: 0 | C22: 0 | D22: 9 | F22: 0.04 | H22: in 1 pair of wheels made anew from the lord's timber 9pence. | K22: =F22 | L22: =K22
A23: Cost of carts | B23: 0 | C23: 2 | D23: 6 | F23: 0.12 | H23: mending 1 old binding and putting it on the said wheels with the stipend of the smith 2 shilling 6pence. | K23: =F23 | L23: =K23
A24: Cost of carts | B24: 0 | C24: 1 | D24: 9 | F24: 0.09 | H24: clouts, nails and grease bought 1 shilling 9pence. | K24: =F24 | L24: =K24
A25: Cost of carts | B25: 0 | C25: 0 | D25: 8 | F25: 0.03 | H25: mending the axles of the cart at various times 8pence, on account of the manor of Kilmeston. | K25: =F25 | L25: =K25
A26: Cost of carts | B26: 0 | C26: 3 | D26: 6 | F26: 0.17 | H26: shoeing 2 cart-horses 3 shilling 6pence. | K26: =F26 | L26: =K26
A27: Cost of carts | B27: 0 | C27: 0 | D27: 10 | F27: 0.04 | H27: 2 collars bought 10pence. | K27: =F27 | L27: =K27
A28: Cost of carts | B28: 0 | C28: 0 | D28: 9 | F28: 0.04 | H28: 2 pairs of traces bought 9pence. | K28: =F28 | L28: =K28
A29: Cost of carts | B29: 0 | C29: 1 | D29: 2 | F29: 0.06 | H29: 1 rope bought for the cart 1 shilling 2pence. | K29: =F29 | L29: =K29
A30: Cost of carts | B30: 0 | C30: 0 | D30: 1.5 | F30: 0.01 | H30: 2 halters bought 1.5pence. | K30: =F30 | L30: =K30
A31: Cost of carts | B31: 0 | C31: 2 | D31: 3 | F31: 0.11 | H31: stipend of 1 carter from Michaelmas until Lammas, because thereafter he was at the church, 2 shilling 3pence
A32: Cost of carts | B32: 0 | C32: 14 | D32: 3.5 | F32: =B32+C32/20+D32/240 | H32: Total, 14 shilling 3.5pence
A33: Cost of carts | F33: 0.71 | G33: =F33-F32 | H33: Total
A35: Repair of buildings | B35: 0 | C35: 3 | D35: 4 | F35: 0.17 | H35: In 2,000 slates bought 3 shilling 4pence. | K35: =F35
A36: Repair of buildings | B36: 0 | C36: 10 | D36: 6 | F36: 0.53 | H36: re-roofing the hall, lord's chamber, clerks' chamber and kitchen, which had been unroofed several times by the wind, 10 shilling 6pence. | K36: =F36
A37: Repair of buildings | B37: 0 | C37: 0 | D37: 8 | F37: 0.03 | H37: nails and pegs bought for the same 8pence. | K37: =F37
A38: Repair of buildings | B38: 0 | C38: 4 | D38: 4 | F38: 0.22 | H38: re-roofing the barn and other buildings in places 4 shilling 4pence. | K38: =F38 | L38: =K38
A39: Repair of buildings | B39: 0 | C39: 0 | D39: 5 | F39: 0.02 | H39: laying 100 shingles in places on the barn with nails bought for the same 5pence. | K39: =F39 | L39: =K39
A40: Repair of buildings | B40: 0 | C40: 2 | D40: 8 | F40: 0.13 | H40: building anew 1 palisade between the hall and kitchen 2 shilling 8pence. | K40: =F40
A41: Repair of buildings | B41: 0 | C41: 2 | D41: 2 | F41: 0.11 | H41: building 1 palisade between the hall and dairy and 1 new garden-gate 2 shilling 2pence. | K41: =F41 | L41: =K41
A42: Repair of buildings | B42: 0 | C42: 0 | D42: 9 | F42: 0.04 | H42: felling and sawing timber for the same 9pence. | K42: =F42 | L42: =K42
A43: Repair of buildings | B43: 0 | C43: 3 | D43: 6 | F43: 0.17 | H43: mending the byre in part and making anew a fodder-rack for the byre 3 shilling 6pence. | K43: =F43 | L43: =K43
...

Sheet Issues of the Grange
A1: Gross Output | B1: Total Quantity | C1: Account Total Quarters | D1: Bought in Total Quarters | E1: Received from churchscot | F1: Sold Total Quarters | G1: Difference Produced+Bought-Sold | H1: Weighted Average Price per Quarter | I1: Value of Total Production weighted
A2: wheat | B2: 73.25 | C2: 73.25 | D2: 0 | F2: 46.3125 | G2: =B2-F2 | H2: 0.27813765 | I2: =H2*B2
A3: curall | B3: 13.125 | C3: 13.125 | D3: 0 | F3: 13.125 | G3: =B3-F3 | H3: 0.13333333 | I3: =H3*B3
A4: barley | B4: 76.5 | C4: 69.25 | D4: 6.625 | F4: 23.9375 | G4: =B4-F4 | H4: 0.2 | I4: =H4*B4
A5: oats | B5: 178.875 | C5: 178.875 | D5: 0 | F5: 31.5 | G5: =B5-F5 | H5: 0.10443122 | I5: =H5*B5
A6: peas | B6: 6.75 | C6: 6.75 | D6: 0 | F6: 5 | G6: =B6-F6 | H6: 0.125 | I6: =H6*B6
A7: vetches | B7: 8.25 | C7: 8.25 | D7: 0 | F7: 8 | G7: =B7-F7 | H7: 0.1 | I7: =H7*B7
A9: Total Production
A10: Sales of corn (as recorded in accounts)
A13: Net output | B13: Gross output | C13: Seed quarters | D13: Seed bushels | E13: Seed total quarters | F13: tithe quarters | G13: tithe bushels | H13: tithe total | I13: manorial servants quarters | J13: manorial servants bushels | K13: manorial servants total quarters | L13: output net of tithe, seed, liveries | M13: in stock from last year | N13: Price in £ | O13: Value of net output in £ | P13: Value of sales (in "Sale of Corn") in £
A14: wheat | B14: =B2 | C14: 23 | D14: 3.5 | E14: =C14+D14/8 | J14: =6+6 | K14: =I14+J14/8 | L14: =B14-E14-K14 | N14: =H2 | O14: =N14*L14
A15: curall | B15: =B3 | E15: =C15+D15/8 | K15: =I15+J15/8 | L15: =B15-E15-K15 | N15: =H3 | O15: =N15*L15
A16: barley | B16: =B4 | C16: 20.5 | E16: =C16+D16/8 | I16: =1+6.5+19.5+2+1 | J16: =4+6.5+1 | K16: =I16+J16/8 | L16: =B16-E16-K16 | N16: =H4 | O16: =N16*L16
A17: oats | B17: =B5 | C17: 82 | E17: =C17+D17/8 | I17: =19.5+16+6+18+3+2 | J17: =1+2+3 | K17: =I17+J17/8 | L17: =B17-E17-K17 | N17: =H5 | O17: =N17*L17
A18: peas | B18: =B6 | D18: 2 | E18: =C18+D18/8 | I18: 1.5 | K18: =I18+J18/8 | L18: =B18-E18-K18 | N18: =H6 | O18: =N18*L18
A19: vetches | B19: =B7 | E19: =C19+D19/8 | K19: =I19+J19/8 | L19: =B19-E19-K19 | N19: =H7 | O19: =N19*L19
A21: Total

Sheet Issues of the Mills

Sheet Stock
A1: HAMBLEDON STOCK ACCOUNT
C3: added | G3: subtracted
A4: Livestock | B4: Inherited stock | C4: added | D4: strays | E4: herbage | F4: churchscot | G4: of which in default | H4: sold | I4: in murrain | J4: accounted for elsewhere | K4: End-period stock | L4: cross-check | M4: stock building | N4: raw production | O4: Unit price (£) | P4: Value of stock (£) at given value | Q4: Value of stock (£) at sales prices | R4: Sales in (£) | S4: Value of stock building (£) | T4: Value of production (£) at sales prices | U4: Details
A5: Cart-horses | B5: 2 | K5: 2
A6: Mares
A7: Plough horses | B7: 8 | C7: 1 | H7: 1 | I7: 1 | K7: 7 | O7: =R7/H7 | R7: =Receipts!F98 | T7: =O7*C7
A8: Colts (unspecified years)
A9: Colts (2 years)
A10: Colts (1 year)
A11: Foals
A12: Oxen | B12: 26 | C12: =1+5 | H12: 4 | K12: 28 | O12: =R12/H12 | R12: =Receipts!F85 | T12: =O12*C12
A13: Bulls | B13: 2 | K13: 2
A14: Cows | B14: 21 | C14: =1 | H14: 3 | K14: 19 | O14: =R14/H14 | R14: =Receipts!F86 | T14: =O14*C14
A15: Steers | B15: 5 | C15: 39 | H15: 39 | J15: =5 | K15: 0 | O15: =R15/H15 | R15: =Receipts!F116 | T15: =O15*C15
A16: Bullocks | B16: 5 | K16: 5
A17: Yearlings | B17: 7 | I17: 1 | K17: 6
A18: Calves | B18: 15 | H18: 6 | I18: 2 | J18: =1 | K18: 6 | O18: =R18/H18 | R18: =Receipts!F93 | T18: =O18*C18
A19: Wethers | B19: 354 | C19: =77+3 | H19: 16 | I19: =24+12 | K19: 382 | O19: =R19/H19 | R19: =Receipts!F94 | T19: =O19*C19
A20: Rams | B20: 13 | C20: 3 | I20: =1 | K20: 15
A21: Ewes | B21: 339 | C21: =94+2 | H21: 14 | I21: =24+8+7 | K21: 381 | O21: =R21/H21 | R21: =Receipts!F95 | T21: =O21*C21
A22: Hoggs | B22: 188 | I22: =14 | J22: =77+3+94 | K22: 0 | T22: =O22*C22
A23: Lambs | C23: =255+80 | H23: 38 | I23: =57+19 | J23: =25+3 | K23: 193 | O23: =R23/H23 | R23: =Receipts!F96 | T23: =O23*C23
A24: Boars | B24: 1 | K24: 1 | T24: =O24*C24
A25: Sows | B25: 2 | K25: 2 | T25: =O25*C25
A26: Pigs | B26: 43 | C26: =24 | H26: 19 | I26: 3 | K26: 45 | O26: =R26/H26 | R26: =Receipts!F97 | T26: =O26*C26
A27: Hoggets | B27: 27 | H27: 19 | I27: 3 | J27: 24 | K27: 0 | O27: =R27/H27 | U27: not found in issues
A28: Piglets | C28: 51 | J28: =5+3 | K28: 43
A29: Swans
A30: Peacocks
A31: Total Value | R31: =SUM(R7:R29) | T31: =SUM(T5:T26)
A34: Wool
A35: Coarse wool | C35: 812 | J35: =81+2+729 | K35: 0 | O35: 0.02 | T35: =O35*J35 | U35: unit price from overview sheet (UnitPricesStocks_averages)
A36: Lamb's wool | C36: 193 | J36: 193 | O36: 0.01 | T36: =O36*J36 | U36: unit price from overview sheet (UnitPricesStocks_averages)
A37: Wool locks | H37: 7 | R37: =Receipts!F105 | U37: sales only recorded in issues; recorded in cloves
A38: Wool sold at shearing
A39: Total wool | R39: =SUM(R35:R38) | T39: =SUM(T35:T36)+R37
A42: Hides
A43: Ox hides
A44: plough horse | C44: 1 | H44: 1 | O44: =R44/H44 | R44: =Receipts!F98 | T44: =O44*C44
A45: yearling | C45: 1 | H45: 1 | O45: =R45/H45 | R45: =Receipts!F99 | T45: =O45*C45
...

Sheet raw data
A1: Heading | B1: Sentence | C1: Total in Pounds | D1: Pounds | E1: Shillings | F1: Pence | G1: Corn | H1: Total Quarters Except 1 | I1: Total Bushels Except 1 | J1: Total Corn Cross-Check | K1: Total Corn Manorial Account | L1: Corn Quantity Error | M1: Quarters 1 | N1: Bushels 1 | O1: Quarters 2 | P1: Bushels 2 | Q1: Quarters 3 | R1: Bushels 3 | S1: shilling a quarter 1 | T1: pence a quarter 1 | U1: shilling a quarter 2 | V1: pence a quarter 2 | W1: shilling a quarter 3 | X1: pence a quarter 3 | Y1: shilling a quarter 4 | Z1: pence a quarter 4 | AA1: shilling a bushel 1 | AB1: pence a bushel 1 | AC1: shilling a bushel 2 | AD1: pence a bushel 2 | AE1: shilling a bushel 3 | AF1: pence a bushel 3 | AG1: shilling a bushel 4 | AH1: pence a bushel 4
A2: Arrears | B2: Nicholas, bailiff, and William Bouelych', reeve, render account for £68 12 shilling 7.25pence of arrears from the previous year. | C2: 68.63 | D2: 68 | E2: 12 | F2: 7.25 | H2: 0 | I2: 0 | J2: 0 | K2: 0 | L2: 0 | M2: 0 | N2: 0
A3: Arrears | B3: All delivered to Sir Geoffrey, treasurer of Wolvesey. | C3: 0 | D3: 0 | E3: 0 | F3: 0 | H3: 0 | I3: 0 | J3: 0 | K3: 0 | L3: 0 | M3: 0 | N3: 0
A4: Arrears | B4: They are quit. | C4: 0 | D4: 0 | E4: 0 | F4: 0 | H4: 0 | I4: 0 | J4: 0 | K4: 0 | L4: 0 | M4: 0 | N4: 0
A5: Rents of assize | B5: The same render account for £6 13 shilling 11.25pence for rents of assize at Christmas. | C5: 6.7 | D5: 6 | E5: 13 | F5: 11.25 | H5: 0 | I5: 0 | J5: 0 | K5: 0 | L5: 0 | M5: 0 | N5: 0
A6: Rents of assize | B6: £7 9 shilling 1pence at Easter (22 April). | C6: 7.45 | D6: 7 | E6: 9 | F6: 1 | H6: 0 | I6: 0 | J6: 0 | K6: 0 | L6: 0 | M6: 0 | N6: 0
A7: Rents of assize | B7: £6 13 shilling 11.25pence at St John the Baptist (24 June). | C7: 6.7 | D7: 6 | E7: 13 | F7: 11.25 | H7: 0 | I7: 0 | J7: 0 | K7: 0 | L7: 0 | M7: 0 | N7: 0
A8: Rents of assize | B8: £11 10 shilling 110.75pence1 at Michaelmas (29 September). | C8: 11.96 | D8: 11 | E8: 10 | F8: 110.75 | H8: 0 | I8: 0 | J8: 0 | K8: 0 | L8: 0 | M8: 0 | N8: 0
A9: Rents of assize | B9: Total, £32 7 shilling 10.25pence | C9: 32.39 | D9: 32 | E9: 7 | F9: 10.25 | H9: 0 | I9: 0 | J9: 0 | K9: 0 | L9: 0 | M9: 0 | N9: 0
A10: Increment | B10: The same render account for 1pence for the increment of rent from Robert Faber to have 1 plot of land, 12 feet long and 5 feet wide, in the vill of Hambledon. | C10: 0 | D10: 0 | E10: 0 | F10: 1 | H10: 0 | I10: 0 | J10: 0 | K10: 0 | L10: 0 | M10: 0 | N10: 0
A11: Increment | B11: Total, 1pence Total of rents with increment, £32 7 shilling 11.25pence | C11: 32.4 | D11: 32 | E11: 7 | F11: 11.25 | H11: 0 | I11: 0 | J11: 0 | K11: 0 | L11: 0 | M11: 0 | N11: 0
A12: Quittances | B12: In quittance of 1 reeve for the year 2 shilling 6pence. | C12: 0.12 | D12: 0 | E12: 2 | F12: 6 | H12: 0 | I12: 0 | J12: 0 | K12: 0 | L12: 0 | M12: 0 | N12: 0
A13: Quittances | B13: 1 bartoner for the year 2 shilling 6pence. | C13: 0.12 | D13: 0 | E13: 2 | F13: 6 | H13: 0 | I13: 0 | J13: 0 | K13: 0 | L13: 0 | M13: 0 | N13: 0
... A85: Issues of the manor | B85: 10 shilling from 5 quarters of salt sold. | C85: 0.5 | D85: 0 | E85: 10 | F85: 0 | H85: 5 | I85: 0 | J85: 5 | K85: 5 | L85: 0 | M85: 5 | N85: 0
A86: Issues of the manor | B86: 1 shilling 3pence from 15 workers who are bound to thresh 2 bushels of wheat and 4 bushels of oats. | C86: 0.06 | D86: 0 | E86: 1 | F86: 3 | G86: oats, wheat | H86: 0 | I86: 4 | J86: 0.5 | K86: 0.25 | L86: 0.25 | M86: 0 | N86: 2 | O86: 0 | P86: 4
A87: Issues of the manor | B87: nothing from labour services sold this year. | C87: 0 | D87: 0 | E87: 0 | F87: 0 | H87: 0 | I87: 0 | J87: 0 | K87: 0 | L87: 0 | M87: 0 | N87: 0
A88: Issues of the manor | B88: nothing from the turbary on la Crith this year. | C88: 0 | D88: 0 | E88: 0 | F88: 0 | H88: 0 | I88: 0 | J88: 0 | K88: 0 | L88: 0 | M88: 0 | N88: 0
A89: Issues of the manor | B89: nothing from the pasturage beside Parkgate this year for the lord's animals. | C89: 0 | D89: 0 | E89: 0 | F89: 0 | H89: 0 | I89: 0 | J89: 0 | K89: 0 | L89: 0 | M89: 0 | N89: 0
A90: Issues of the manor | B90: 3 shilling 9pence from dairy produce sold at the audit. | C90: 0.19 | D90: 0 | E90: 3 | F90: 9 | H90: 0 | I90: 0 | J90: 0 | K90: 0 | L90: 0 | M90: 0 | N90: 0
A91: Issues of the manor | B91: £17 2 shilling 6pence from 39 animals sold which were bought to agist in the pasture. | C91: 17.12 | D91: 17 | E91: 2 | F91: 6 | H91: 0 | I91: 0 | J91: 0 | K91: 0 | L91: 0 | M91: 0 | N91: 0
A92: Issues of the manor | B92: Total, £42 3 shilling 4pence | C92: 42.17 | D92: 42 | E92: 3 | F92: 4 | H92: 0 | I92: 0 | J92: 0 | K92: 0 | L92: 0 | M92: 0 | N92: 0
A93: Farm of the mill | B93: The same render account for £1 16 shilling for the farm of the mill this year. | C93: 1.8 | D93: 1 | E93: 16 | F93: 0 | H93: 0 | I93: 0 | J93: 0 | K93: 0 | L93: 0 | M93: 0 | N93: 0
A94: Farm of the mill | B94: Total, £1 16 shilling | C94: 1.8 | D94: 1 | E94: 16 | F94: 0 | H94: 0 | I94: 0 | J94: 0 | K94: 0 | L94: 0 | M94: 0 | N94: 0
A95: Sale of corn | B95: The same render account for £12 14 shilling 3pence from 45 quarters 6 bushels of wheat sold, at 5 shilling a quarters for 20 quarters 2 bushels, and 6 shilling a quarters for 25.5 quarters. | C95: 12.71 | D95: 12 | E95: 14 | F95: 3 | G95: wheat | H95: 45.5 | I95: 2 | J95: 45.75 | K95: 45.75 | L95: 0 | M95: 45 | N95: 6 | O95: 20 | P95: 2 | Q95: 25.5 | R95: 0 | S95: 5 | T95: 0 | U95: 6 | V95: 0
A96: Sale of corn | B96: £1 15 shilling from 13 quarters 1 bushels of curall sold, at 2 shilling 8pence a quarters. | C96: 1.75 | D96: 1 | E96: 15 | F96: 0 | G96: curall | H96: 13 | I96: 1 | J96: 13.125 | K96: 13.125 | L96: 0 | M96: 13 | N96: 1 | S96: 2 | T96: 8
A97: Sale of corn | B97: £4 13 shilling from 23 quarters 2 bushels of barley sold, at 4 shilling a quarters. | C97: 4.65 | D97: 4 | E97: 13 | F97: 0 | G97: barley | H97: 23 | I97: 2 | J97: 23.25 | K97: 23.25 | L97: 0 | M97: 23 | N97: 2 | S97: 4 | T97: 0
A98: Sale of corn | B98: £3 5 shilling 9.5pence from 31.5 quarters of oats sold, at 2 shilling a quarters for 14 quarters 6 bushels, and 2 shilling 2pence a quarters for 16 quarters 6 bushels. | C98: 3.29 | D98: 3 | E98: 5 | F98: 9.5 | G98: oats | H98: 30 | I98: 12 | J98: 31.5 | K98: 31.5 | L98: 0 | M98: 31.5 | N98: 0 | O98: 14 | P98: 6 | Q98: 16 | R98: 6 | S98: 2 | T98: 0 | U98: 2 | V98: 2
A99: Sale of corn | B99: 12 shilling 6pence from 5 quarters of peas sold, at 2 shilling 6pence a quarters. | C99: 0.62 | D99: 0 | E99: 12 | F99: 6 | G99: peas | H99: 5 | I99: 0 | J99: 5 | K99: 5 | L99: 0 | M99: 5 | N99: 0 | S99: 2 | T99: 6
A100: Sale of corn | B100: 16 shilling 6pence from 8 quarters of vetches sold, at 2 shilling a quarters. | C100: 0.83 | D100: 0 | E100: 16 | F100: 6 | G100: vetches | H100: 8 | I100: 0 | J100: 8 | K100: 8 | L100: 0 | M100: 8 | N100: 0 | S100: 2 | T100: 0
A101: Sale of corn | B101: 3 shilling 4.5pence from 4.5 bushels of wheat sold at the audit. | C101: 0.17 | D101: 0 | E101: 3 | F101: 4.5 | G101: wheat | H101: 0 | I101: 4.5 | J101: 0.5625 | K101: 0.5625 | L101: 0 | M101: 0 | N101: 4.5
A102: Sale of corn | B102: 2 shilling 9pence from 5.5 bushels of barley sold at the audit. | C102: 0.14 | D102: 0 | E102: 2 | F102: 9 | G102: barley | H102: 0 | I102: 5.5 | J102: 0.6875 | K102: 0.6875 | L102: 0 | M102: 0 | N102: 5.5
A103: Sale of corn | B103: Total, £24 3 shilling 2pence | C103: 24.16 | D103: 24 | E103: 3 | F103: 2 | H103: 0 | I103: 0 | J103: 0 | K103: 0 | L103: 0 | M103: 0 | N103: 0
A104: Entry and marriage fines with tithingpenny | B104: The same render account for 5 shilling from the tithing of Chidden for tithingpenny at the hundred-court of Martinmas (11 November). | C104: 0.25 | D104: 0 | E104: 5 | F104: 0 | H104: 0 | I104: 0 | J104: 0 | K104: 0 | L104: 0 | M104: 0 | N104: 0
A105: Entry and marriage fines with tithingpenny | B105: 5 shilling from the tithing of Denmead for the same. | C105: 0.25 | D105: 0 | E105: 5 | F105: 0 | H105: 0 | I105: 0 | J105: 0 | K105: 0 | L105: 0 | M105: 0 | N105: 0
A106: Entry and marriage fines with tithingpenny | B106: 5 shilling from the tithing of la Lygh' for the same. | C106: 0.25 | D106: 0 | E106: 5 | F106: 0 | H106: 0 | I106: 0 | J106: 0 | K106: 0 | L106: 0 | M106: 0 | N106: 0
A107: Entry and marriage fines with tithingpenny | B107: 5 shilling from the tithing of Gludden for the same. | C107: 0.25 | D107: 0 | E107: 5 | F107: 0 | H107: 0 | I107: 0 | J107: 0 | K107: 0 | L107: 0 | M107: 0 | N107: 0
A108: Entry and marriage fines with tithingpenny | B108: £1 from the same tithings at the hundred-court of Hockday (1 May). | C108: 1 | D108: 1 | E108: 0 | F108: 0 | H108: 0 | I108: 0 | J108: 0 | K108: 0 | L108: 0 | M108: 0 | N108: 0
A109: Entry and marriage fines with tithingpenny | B109: 5 shilling from the relict of Thomas le Cog' to retain 1 cotland which belonged to her husband. | C109: 0.25 | D109: 0 | E109: 5 | F109: 0 | H109: 0 | I109: 0 | J109: 0 | K109: 0 | L109: 0 | M109: 0 | N109: 0
A110: Entry and marriage fines with tithingpenny | B110: 10 shilling from Adam Coker to have .5 virgate of land which belonged to Stephen his father. | C110: 0.5 | D110: 0 | E110: 10 | F110: 0 | H110: 0 | I110: 0 | J110: 0 | K110: 0 | L110: 0 | M110: 0 | N110: 0
A111: Entry and marriage fines with tithingpenny | B111: 2 shilling from William Bouelych' to have 2 acres of land by surrender of Adam Bythewod'. | C111: 0.1 | D111: 0 | E111: 2 | F111: 0 | H111: 0 | I111: 0 | J111: 0 | K111: 0 | L111: 0 | M111: 0 | N111: 0
...

Sheet Issues of the Grange raw
A1: Heading | B1: Sentence | C1: Quarters 1_x | D1: Bushels 1_x | E1: Sown Quarters | F1: Sown Bushels | G1: Sown Total Quarters | H1: Bought in Quarters | I1: Bought in Bushels | J1: Bought in Total Quarters | K1: Tithe Quarters | L1: Tithe Bushels | M1: Tithe Total Quarters | N1: Manorial servants & livestock Quarters | O1: Manorial servants & livestock Bushels | P1: Manorial servants & livestock Total Quarters | Q1: Sold Quarters | R1: Sold Bushels | S1: Sold Total Quarters | T1: Account Quarters | U1: Account Bushels | V1: Account Total Quarters | W1: bought only | X1: Total Quarters Except 1 | Y1: Total Bushels Except 1 | Z1: Total Corn Cross-Check | AA1: Total Corn Manorial Account | AB1: Corn Quantity Error | AC1: Quarters 1_y | AD1: Bushels 1_y | AE1: Quarters 2 | AF1: Bushels 2 | AG1: Quarters 3 | AH1: Bushels 3
A2: And thus he owes | B2: Total | C2: 0 | D2: 0 | E2: 0 | F2: 0 | G2: 0 | H2: 0 | I2: 0 | J2: 0 | K2: 0 | L2: 0 | M2: 0 | N2: 0 | O2: 0 | P2: 0 | Q2: 0 | R2: 0 | S2: 0 | T2: 0 | U2: 0 | V2: 0 | W2: 0
A3: Wheat | B3: {yield: 4.5-fold less .5 qr} | C3: 0 | D3: 0 | E3: 0 | F3: 0 | G3: 0 | H3: 0 | I3: 0 | J3: 0 | K3: 0 | L3: 0 | M3: 0 | N3: 0 | O3: 0 | P3: 0 | Q3: 0 | R3: 0 | S3: 0 | T3: 0 | U3: 0 | V3: 0 | W3: 0
A4: Wheat | B4: The same render account for 71 quarters 6 bushels from the whole issue of wheat by struck measure. | C4: 0 | D4: 0 | E4: 0 | F4: 0 | G4: 0 | H4: 0 | I4: 0 | J4: 0 | K4: 0 | L4: 0 | M4: 0 | N4: 0 | O4: 0 | P4: 0 | Q4: 0 | R4: 0 | S4: 0 | T4: 71 | U4: 6 | V4: 71.75 | W4: 0 | X4: 71 | Y4: 6 | Z4: 71.75 | AA4: 71.75 | AB4: 0 | AC4: 71 | AD4: 6
A5: Wheat | B5: 1.5 quarters from churchscot. | C5: 0 | D5: 0 | E5: 0 | F5: 0 | G5: 0 | H5: 0 | I5: 0 | J5: 0 | K5: 0 | L5: 0 | M5: 0 | N5: 0 | O5: 0 | P5: 0 | Q5: 0 | R5: 0 | S5: 0 | T5: 0 | U5: 0 | V5: 0 | W5: 0 | X5: 1.5 | Y5: 0 | Z5: 1.5 | AA5: 1.5 | AB5: 0 | AC5: 1.5 | AD5: 0
A6: Wheat | B6: Total, 73 quarters 2 bushels | C6: 0 | D6: 0 | E6: 0 | F6: 0 | G6: 0 | H6: 0 | I6: 0 | J6: 0 | K6: 0 | L6: 0 | M6: 0 | N6: 0 | O6: 0 | P6: 0 | Q6: 0 | R6: 0 | S6: 0 | T6: 0 | U6: 0 | V6: 0 | W6: 0 | X6: 73 | Y6: 2 | Z6: 73.25 | AA6: 73.25 | AB6: 0 | AC6: 73 | AD6: 2
A7: Wheat | B7: Sown over 75 acres which lie in la Garston', Slade and Vyneys, 23 quarters 3.5 bushels. | C7: 0 | D7: 0 | E7: 23 | F7: 3.5 | G7: 23.4375 | H7: 0 | I7: 0 | J7: 0 | K7: 0 | L7: 0 | M7: 0 | N7: 0 | O7: 0 | P7: 0 | Q7: 0 | R7: 0 | S7: 0 | T7: 0 | U7: 0 | V7: 0 | W7: 0 | X7: 23 | Y7: 3.5 | Z7: 23.4375 | AA7: 23.4375 | AB7: 0 | AC7: 23 | AD7: 3.5
A8: Wheat | B8: that is, 2.5 bushels an acre. | C8: 0 | D8: 0 | E8: 0 | F8: 0 | G8: 0 | H8: 0 | I8: 0 | J8: 0 | K8: 0 | L8: 0 | M8: 0 | N8: 0 | O8: 0 | P8: 0 | Q8: 0 | R8: 0 | S8: 0 | T8: 0 | U8: 0 | V8: 0 | W8: 0 | X8: 0 | Y8: 2.5 | Z8: 0.3125 | AA8: 0.3125 | AB8: 0 | AC8: 0 | AD8: 2.5
A9: Wheat | B9: . | C9: 0 | D9: 0 | E9: 0 | F9: 0 | G9: 0 | H9: 0 | I9: 0 | J9: 0 | K9: 0 | L9: 0 | M9: 0 | N9: 0 | O9: 0 | P9: 0 | Q9: 0 | R9: 0 | S9: 0 | T9: 0 | U9: 0 | V9: 0 | W9: 0 | X9: 0 | Y9: 0 | Z9: 0 | AA9: 0 | AB9: 0 | AC9: 0 | AD9: 0
A10: Wheat | B10: provision of Simon, clerk, for 2 tourns, 6 bushels. | C10: 0 | D10: 0 | E10: 0 | F10: 0 | G10: 0 | H10: 0 | I10: 0 | J10: 0 | K10: 0 | L10: 0 | M10: 0 | N10: 0 | O10: 0 | P10: 0 | Q10: 0 | R10: 0 | S10: 0 | T10: 0 | U10: 0 | V10: 0 | W10: 0 | X10: 0 | Y10: 6 | Z10: 0.75 | AA10: 0.75 | AB10: 0 | AC10: 0 | AD10: 6
A11: Wheat | B11: provision of the bailiff for his visits, 2 quarters 6 bushels Sold, 45 quarters 6 bushels Sold at the audit, 4.5 bushels | C11: 0 | D11: 0 | E11: 0 | F11: 0 | G11: 0 | H11: 0 | I11: 0 | J11: 0 | K11: 0 | L11: 0 | M11: 0 | N11: 0 | O11: 0 | P11: 0 | Q11: 47 | R11: 12 | S11: 48.5 | T11: 0 | U11: 0 | V11: 0 | W11: 0 | X11: 45 | Y11: 10.5 | Z11: 46.3125 | AA11: 2.75 | AB11: 43.5625 | AC11: 2 | AD11: 6 | AE11: 45 | AF11: 6 | AG11: 0 | AH11: 4.5
A12: Wheat | B12: Total | C12: 0 | D12: 0 | E12: 0 | F12: 0 | G12: 0 | H12: 0 | I12: 0 | J12: 0 | K12: 0 | L12: 0 | M12: 0 | N12: 0 | O12: 0 | P12: 0 | Q12: 0 | R12: 0 | S12: 0 | T12: 0 | U12: 0 | V12: 0 | W12: 0
A13: Curall | B13: The same render account for 13 quarters 1 bushels from the issue of curall by struck measure. | C13: 0 | D13: 0 | E13: 0 | F13: 0 | G13: 0 | H13: 0 | I13: 0 | J13: 0 | K13: 0 | L13: 0 | M13: 0 | N13: 0 | O13: 0 | P13: 0 | Q13: 0 | R13: 0 | S13: 0 | T13: 13 | U13: 1 | V13: 13.125 | W13: 0 | X13: 13 | Y13: 1 | Z13: 13.125 | AA13: 13.125 | AB13: 0 | AC13: 13 | AD13: 1
A14: Curall | B14: all solpence | C14: 0 | D14: 0 | E14: 0 | F14: 0 | G14: 0 | H14: 0 | I14: 0 | J14: 0 | K14: 0 | L14: 0 | M14: 0 | N14: 0 | O14: 0 | P14: 0 | Q14: 0 | R14: 0 | S14: 0 | T14: 0 | U14: 0 | V14: 0 | W14: 0 | X14: 0 | Y14: 0 | Z14: 0 | AA14: 0 | AB14: 0 | AC14: 0 | AD14: 0
A15: Curall | B15: Total | C15: 0 | D15: 0 | E15: 0 | F15: 0 | G15: 0 | H15: 0 | I15: 0 | J15: 0 | K15: 0 | L15: 0 | M15: 0 | N15: 0 | O15: 0 | P15: 0 | Q15: 0 | R15: 0 | S15: 0 | T15: 0 | U15: 0 | V15: 0 | W15: 0
A16: Barley | B16: (yield: 4-fold less 3 quarters 2 bushels) | C16: 0 | D16: 0 | E16: 0 | F16: 0 | G16: 0 | H16: 0 | I16: 0 | J16: 0 | K16: 0 | L16: 0 | M16: 0 | N16: 0 | O16: 0 | P16: 0 | Q16: 0 | R16: 0 | S16: 0 | T16: 0 | U16: 0 | V16: 0 | W16: 0 | X16: 3 | Y16: 2 | Z16: 3.25 | AA16: 3.25 | AB16: 0 | AC16: 3 | AD16: 2
A17: Barley | B17: The same render account for 69 quarters 2 bushels from the whole issue of barley by struck measure. | C17: 0 | D17: 0 | E17: 0 | F17: 0 | G17: 0 | H17: 0 | I17: 0 | J17: 0 | K17: 0 | L17: 0 | M17: 0 | N17: 0 | O17: 0 | P17: 0 | Q17: 0 | R17: 0 | S17: 0 | T17: 69 | U17: 2 | V17: 69.25 | W17: 0 | X17: 69 | Y17: 2 | Z17: 69.25 | AA17: 69.25 | AB17: 0 | AC17: 69 | AD17: 2
A18: Barley | B18: 6 quarters 5 bushels bought. | C18: 0 | D18: 0 | E18: 0 | F18: 0 | G18: 0 | H18: 6 | I18: 5 | J18: 6.625 | K18: 0 | L18: 0 | M18: 0 | N18: 0 | O18: 0 | P18: 0 | Q18: 0 | R18: 0 | S18: 0 | T18: 0 | U18: 0 | V18: 0 | W18: 0 | X18: 6 | Y18: 5 | Z18: 6.625 | AA18: 6.625 | AB18: 0 | AC18: 6 | AD18: 5
A19: Barley | B19: Total, 75 quarters 7 bushels | C19: 0 | D19: 0 | E19: 0 | F19: 0 | G19: 0 | H19: 0 | I19: 0 | J19: 0 | K19: 0 | L19: 0 | M19: 0 | N19: 0 | O19: 0 | P19: 0 | Q19: 0 | R19: 0 | S19: 0 | T19: 0 | U19: 0 | V19: 0 | W19: 0 | X19: 75 | Y19: 7 | Z19: 75.875 | AA19: 75.875 | AB19: 0 | AC19: 75 | AD19: 7
A20: Barley | B20: Sown over 33 acres which lie at Parkgate and la Rugg', 20.5 quarters. | C20: 0 | D20: 0 | E20: 20.5 | F20: 0 | G20: 20.5 | H20: 0 | I20: 0 | J20: 0 | K20: 0 | L20: 0 | M20: 0 | N20: 0 | O20: 0 | P20: 0 | Q20: 0 | R20: 0 | S20: 0 | T20: 0 | U20: 0 | V20: 0 | W20: 0 | X20: 20.5 | Y20: 0 | Z20: 20.5 | AA20: 20.5 | AB20: 0 | AC20: 20.5 | AD20: 0
A21: Barley | B21: that is, 5 bushels an acre, less 2 bushels in all. | C21: 0 | D21: 0 | E21: 0 | F21: 0 | G21: 0 | H21: 0 | I21: 0 | J21: 0 | K21: 0 | L21: 0 | M21: 0 | N21: 0 | O21: 0 | P21: 0 | Q21: 0 | R21: 0 | S21: 0 | T21: 0 | U21: 0 | V21: 0 | W21: 0 | X21: 0 | Y21: 2 | Z21: 0.25 | AA21: 0.625 | AB21: -0.375 | AC21: 0 | AD21: 5 | AE21: 0 | AF21: 2
A22: Barley | B22: Delivered to 1 park-keeper for the year, 1 qr according to custom. | C22: 0 | D22: 0 | E22: 0 | F22: 0 | G22: 0 | H22: 0 | I22: 0 | J22: 0 | K22: 0 | L22: 0 | M22: 0 | N22: 0 | O22: 0 | P22: 0 | Q22: 0 | R22: 0 | S22: 0 | T22: 0 | U22: 0 | V22: 0 | W22: 0
A23: Barley | B23: . | C23: 0 | D23: 0 | E23: 0 | F23: 0 | G23: 0 | H23: 0 | I23: 0 | J23: 0 | K23: 0 | L23: 0 | M23: 0 | N23: 0 | O23: 0 | P23: 0 | Q23: 0 | R23: 0 | S23: 0 | T23: 0 | U23: 0 | V23: 0 | W23: 0 | X23: 0 | Y23: 0 | Z23: 0 | AA23: 0 | AB23: 0 | AC23: 0 | AD23: 0
A24: Barley | B24: customary payment to 1 keeper of lambs until the feast of St John the Baptist, 4 bushels Delivered to 1 carter, 6.5 quarters, taking a quarter every 8 weeks. | C24: 0 | D24: 0 | E24: 0 | F24: 0 | G24: 0 | H24: 0 | I24: 0 | J24: 0 | K24: 0 | L24: 0 | M24: 0 | N24: 0 | O24: 0 | P24: 0 | Q24: 0 | R24: 0 | S24: 0 | T24: 0 | U24: 0 | V24: 0 | W24: 0 | X24: 6.5 | Y24: 4 | Z24: 7 | AA24: 0.5 | AB24: 6.5 | AC24: 0 | AD24: 4 | AE24: 6.5 | AF24: 0
A25: Barley | B25: Delivered to 3 ploughmen for the year, 19.5 quarters. | C25: 0 | D25: 0 | E25: 0 | F25: 0 | G25: 0 | H25: 0 | I25: 0 | J25: 0 | K25: 0 | L25: 0 | M25: 0 | N25: 0 | O25: 0 | P25: 0 | Q25: 0 | R25: 0 | S25: 0 | T25: 0 | U25: 0 | V25: 0 | W25: 0 | X25: 19.5 | Y25: 0 | Z25: 19.5 | AA25: 19.5 | AB25: 0 | AC25: 19.5 | AD25: 0
A26: Barley | B26: Delivered to 1 dairymaid from the purification until Michaelmas, 2 quarters 6.5 bushels, taking a quarter every 12 weeks. | C26: 0 | D26: 0 | E26: 0 | F26: 0 | G26: 0 | H26: 0 | I26: 0 | J26: 0 | K26: 0 | L26: 0 | M26: 0 | N26: 0 | O26: 0 | P26: 0 | Q26: 0 | R26: 0 | S26: 0 | T26: 0 | U26: 0 | V26: 0 | W26: 0 | X26: 2 | Y26: 6.5 | Z26: 2.8125 | AA26: 2.8125 | AB26: 0 | AC26: 2 | AD26: 6.5
A27: Barley | B27: Delivered to 1 keeper of lambs from the feast of St John the Baptist until Michaelmas, for 13 weeks, 1 qr 1 bushels {Henceforth the keeper of lambs should take for 12 weeks} Sold, 23 quarters 2 bushels Sold at the audit, 5.5 bushels | C27: 0 | D27: 0 | E27: 0 | F27: 0 | G27: 0 | H27: 0 | I27: 0 | J27: 0 | K27: 0 | L27: 0 | M27: 0 | N27: 0 | O27: 0 | P27: 0 | Q27: 23 | R27: 2 | S27: 23.25 | T27: 0 | U27: 0 | V27: 0 | W27: 0
A28: Barley | B28: Total | C28: 0 | D28: 0 | E28: 0 | F28: 0 | G28: 0 | H28: 0 | I28: 0 | J28: 0 | K28: 0 | L28: 0 | M28: 0 | N28: 0 | O28: 0 | P28: 0 | Q28: 0 | R28: 0 | S28: 0 | T28: 0 | U28: 0 | V28: 0 | W28: 0
A29: Oats | B29: (yield: two-fold plus 7 bushels) | C29: 0 | D29: 0 | E29: 0 | F29: 0 | G29: 0 | H29: 0 | I29: 0 | J29: 0 | K29: 0 | L29: 0 | M29: 0 | N29: 0 | O29: 0 | P29: 0 | Q29: 0 | R29: 0 | S29: 0 | T29: 0 | U29: 0 | V29: 0 | W29: 0 | X29: 0 | Y29: 7 | Z29: 0.875 | AA29: 0.875 | AB29: 0 | AC29: 0 | AD29: 7
A30: Oats | B30: The same render account for 160 quarters 7 bushels from the whole issue of oats by struck measure. | C30: 0 | D30: 0 | E30: 0 | F30: 0 | G30: 0 | H30: 0 | I30: 0 | J30: 0 | K30: 0 | L30: 0 | M30: 0 | N30: 0 | O30: 0 | P30: 0 | Q30: 0 | R30: 0 | S30: 0 | T30: 160 | U30: 7 | V30: 160.875 | W30: 0 | X30: 160 | Y30: 7 | Z30: 160.875 | AA30: 160.875 | AB30: 0 | AC30: 160 | AD30: 7
A31: Oats | B31: 18 quarters by estimation in sheaves. | C31: 0 | D31: 0 | E31: 0 | F31: 0 | G31: 0 | H31: 0 | I31: 0 | J31: 0 | K31: 0 | L31: 0 | M31: 0 | N31: 0 | O31: 0 | P31: 0 | Q31: 0 | R31: 0 | S31: 0 | T31: 0 | U31: 0 | V31: 0 | W31: 0 | X31: 18 | Y31: 0 | Z31: 18 | AA31: 18 | AB31: 0 | AC31: 18 | AD31: 0
A32: Oats | B32: Total, 178 quarters 7 bushels | C32: 0 | D32: 0 | E32: 0 | F32: 0 | G32: 0 | H32: 0 | I32: 0 | J32: 0 | K32: 0 | L32: 0 | M32: 0 | N32: 0 | O32: 0 | P32: 0 | Q32: 0 | R32: 0 | S32: 0 | T32: 0 | U32: 0 | V32: 0 | W32: 0 | X32: 178 | Y32: 7 | Z32: 178.875 | AA32: 178.875 | AB32: 0 | AC32: 178 | AD32: 7
A33: Oats | B33: Sown over 131 acres and 1 rood which lie at la Worth', Brechlond' and la Vyneys, 82 quarters. | C33: 0 | D33: 0 | E33: 82 | F33: 0 | G33: 82 | H33: 0 | I33: 0 | J33: 0 | K33: 0 | L33: 0 | M33: 0 | N33: 0 | O33: 0 | P33: 0 | Q33: 0 | R33: 0 | S33: 0 | T33: 0 | U33: 0 | V33: 0 | W33: 0 | X33: 82 | Y33: 0 | Z33: 82 | AA33: 82 | AB33: 0 | AC33: 82 | AD33: 0
A34: Oats | B34: that is, 5 bushels an acre. | C34: 0 | D34: 0 | E34: 0 | F34: 0 | G34: 0 | H34: 0 | I34: 0 | J34: 0 | K34: 0 | L34: 0 | M34: 0 | N34: 0 | O34: 0 | P34: 0 | Q34: 0 | R34: 0 | S34: 0 | T34: 0 | U34: 0 | V34: 0 | W34: 0 | X34: 0 | Y34: 5 | Z34: 0.625 | AA34: 0.625 | AB34: 0 | AC34: 0 | AD34: 5
A35: Oats | B35: . | C35: 0 | D35: 0 | E35: 0 | F35: 0 | G35: 0 | H35: 0 | I35: 0 | J35: 0 | K35: 0 | L35: 0 | M35: 0 | N35: 0 | O35: 0 | P35: 0 | Q35: 0 | R35: 0 | S35: 0 | T35: 0 | U35: 0 | V35: 0 | W35: 0 | X35: 0 | Y35: 0 | Z35: 0 | AA35: 0 | AB35: 0 | AC35: 0 | AD35: 0
A36: Oats | B36: . | C36: 0 | D36: 0 | E36: 0 | F36: 0 | G36: 0 | H36: 0 | I36: 0 | J36: 0 | K36: 0 | L36: 0 | M36: 0 | N36: 0 | O36: 0 | P36: 0 | Q36: 0 | R36: 0 | S36: 0 | T36: 0 | U36: 0 | V36: 0 | W36: 0 | X36: 0 | Y36: 0 | Z36: 0 | AA36: 0 | AB36: 0 | AC36: 0 | AD36: 0
A37: Oats | B37: . | C37: 0 | D37: 0 | E37: 0 | F37: 0 | G37: 0 | H37: 0 | I37: 0 | J37: 0 | K37: 0 | L37: 0 | M37: 0 | N37: 0 | O37: 0 | P37: 0 | Q37: 0 | R37: 0 | S37: 0 | T37: 0 | U37: 0 | V37: 0 | W37: 0 | X37: 0 | Y37: 0 | Z37: 0 | AA37: 0 | AB37: 0 | AC37: 0 | AD37: 0
A38: Oats | B38: . | C38: 0 | D38: 0 | E38: 0 | F38: 0 | G38: 0 | H38: 0 | I38: 0 | J38: 0 | K38: 0 | L38: 0 | M38: 0 | N38: 0 | O38: 0 | P38: 0 | Q38: 0 | R38: 0 | S38: 0 | T38: 0 | U38: 0 | V38: 0 | W38: 0 | X38: 0 | Y38: 0 | Z38: 0 | AA38: 0 | AB38: 0 | AC38: 0 | AD38: 0
A39: Oats | B39: fodder of 2 cart-horses from Michaelmas until Lammas, because thereafter they were at the church, 19.5 quarters. | C39: 0 | D39: 0 | E39: 0 | F39: 0 | G39: 0 | H39: 0 | I39: 0 | J39: 0 | K39: 0 | L39: 0 | M39: 0 | N39: 19.5 | O39: 0 | P39: 19.5 | Q39: 0 | R39: 0 | S39: 0 | T39: 0 | U39: 0 | V39: 0 | W39: 0 | X39: 19.5 | Y39: 0 | Z39: 19.5 | AA39: 19.5 | AB39: 0 | AC39: 19.5 | AD39: 0
A40: Oats | B40: . | C40: 0 | D40: 0 | E40: 0 | F40: 0 | G40: 0 | H40: 0 | I40: 0 | J40: 0 | K40: 0 | L40: 0 | M40: 0 | N40: 0 | O40: 0 | P40: 0 | Q40: 0 | R40: 0 | S40: 0 | T40: 0 | U40: 0 | V40: 0 | W40: 0 | X40: 0 | Y40: 0 | Z40: 0 | AA40: 0 | AB40: 0 | AC40: 0 | AD40: 0
...

Sheet Sale of Corn Prices
A1: Heading | B1: Sentence | C1: Total in Pounds | D1: Pounds | E1: Shillings | F1: Pence | G1: Corn | H1: Total Quarters Except 1 | I1: Total Bushels Except 1 | J1: Total Corn Cross-Check | K1: Total Corn Manorial Account | L1: Corn Quantity Error | M1: Quarters 0 | N1: Bushels 0 | O1: shilling a quarter 1 | P1: pence a quarter 1 | Q1: Quarters 1 | R1: Bushels 1 | S1: shilling a quarter 2 | T1: pence a quarter 2 | U1: Quarters 2 | V1: Bushels 2 | W1: shilling a quarter 3 | X1: pence a quarter 3 | Y1: shilling a quarter 4 | Z1: pence a quarter 4 | AA1: £ a quarter 1 | AB1: £ a quarter 2 | AC1: £ a quarter 3 | AD1: £ a quarter 4 | AE1: Quarters Sold | AF1: Weighted Average Price per Quarter | AG1: Non-Weighted Average Price per Quarter | AH1: Corn lowercase
A2: Sale of corn | B2: The same render account for £12 14 shilling 3pence from 45 quarters 6 bushels of wheat sold, at 5 shilling a quarters for 20 quarters 2 bushels, and 6 shilling a quarters for 25.5 quarters. | C2: 12.71 | D2: 12 | E2: 14 | F2: 3 | G2: wheat | H2: 45.5 | I2: 2 | J2: 45.75 | K2: 45.75 | L2: 0 | M2: 45 | N2: 6 | O2: 5 | P2: 0 | Q2: 20 | R2: 2 | S2: 6 | T2: 0 | U2: 25.5 | V2: 0 | AA2: 0.25 | AB2: 0.3 | AE2: 45.75 | AF2: 0.27786885 | AG2: 0.275 | AH2: wheat
A3: Sale of corn | B3: £1 15 shilling from 13 quarters 1 bushels of curall sold, at 2 shilling 8pence a quarters. | C3: 1.75 | D3: 1 | E3: 15 | F3: 0 | G3: curall | H3: 13 | I3: 1 | J3: 13.125 | K3: 13.125 | L3: 0 | M3: 13 | N3: 1 | O3: 2 | P3: 8 | AA3: 0.13333333 | AE3: 13.125 | AF3: 0.13333333 | AG3: 0.13333333 | AH3: curall
A4: Sale of corn | B4: £4 13 shilling from 23 quarters 2 bushels of barley sold, at 4 shilling a quarters. | C4: 4.65 | D4: 4 | E4: 13 | F4: 0 | G4: barley | H4: 23 | I4: 2 | J4: 23.25 | K4: 23.25 | L4: 0 | M4: 23 | N4: 2 | O4: 4 | P4: 0 | AA4: 0.2 | AE4: 23.25 | AF4: 0.2 | AG4: 0.2 | AH4: barley
A5: Sale of corn | B5: £3 5 shilling 9.5pence from 31.5 quarters of oats sold, at 2 shilling a quarters for 14 quarters 6 bushels, and 2 shilling 2pence a quarters for 16 quarters 6 bushels. | C5: 3.29 | D5: 3 | E5: 5 | F5: 9.5 | G5: oats | H5: 30 | I5: 12 | J5: 31.5 | K5: 31.5 | L5: 0 | M5: 31.5 | N5: 0 | O5: 2 | P5: 0 | Q5: 14 | R5: 6 | S5: 2 | T5: 2 | U5: 16 | V5: 6 | AA5: 0.1 | AB5: 0.10833333 | AE5: 31.5 | AF5: 0.10443122 | AG5: 0.10416667 | AH5: oats
A6: Sale of corn | B6: 12 shilling 6pence from 5 quarters of peas sold, at 2 shilling 6pence a quarters. | C6: 0.62 | D6: 0 | E6: 12 | F6: 6 | G6: peas | H6: 5 | I6: 0 | J6: 5 | K6: 5 | L6: 0 | M6: 5 | N6: 0 | O6: 2 | P6: 6 | AA6: 0.125 | AE6: 5 | AF6: 0.125 | AG6: 0.125 | AH6: peas
A7: Sale of corn | B7: 16 shilling 6pence from 8 quarters of vetches sold, at 2 shilling a quarters. | C7: 0.83 | D7: 0 | E7: 16 | F7: 6 | G7: vetches | H7: 8 | I7: 0 | J7: 8 | K7: 8 | L7: 0 | M7: 8 | N7: 0 | O7: 2 | P7: 0 | AA7: 0.1 | AE7: 8 | AF7: 0.1 | AG7: 0.1 | AH7: vetches
A8: Sale of corn | B8: 3 shilling 4.5pence from 4.5 bushels of wheat sold at the audit. | C8: 0.17 | D8: 0 | E8: 3 | F8: 4.5 | G8: wheat | H8: 0 | I8: 4.5 | J8: 0.5625 | K8: 0.5625 | L8: 0 | M8: 0 | N8: 4.5 | AA8: 0.30222222 | AE8: 0.5625 | AF8: 0.30222222 | AG8: 0.30222222 | AH8: wheat
A9: Sale of corn | B9: 2 shilling 9pence from 5.5 bushels of barley sold at the audit. | C9: 0.14 | D9: 0 | E9: 2 | F9: 9 | G9: barley | H9: 0 | I9: 5.5 | J9: 0.6875 | K9: 0.6875 | L9: 0 | M9: 0 | N9: 5.5 | AA9: 0.20363636 | AE9: 0.6875 | AF9: 0.20363636 | AG9: 0.20363636 | AH9: barley
A10: Sale of corn | B10: Total, £24 3 shilling 2pence | C10: 24.16 | D10: 24 | E10: 3 | F10: 2 | H10: 0 | I10: 0 | J10: 0 | K10: 0 | L10: 0 | M10: 0 | N10: 0 | AA10: inf | AE10: 0 | AF10: inf | AG10: inf
