Workbook

Sheet Highclere Overview - Completed
A1: HIGHCLERE OVERVIEW - COMPLETED | B1: Total in £ | C1: Error | D1: Note
A2: CASH ACCOUNT
A3: RECEIPTS
A4: Arrears total | B4: 1.4
A5: Rents of assize total | B5: 22.40625
A6: Quittances total | B6: 1.0416667
A7: Defaults of rent total | B7: 2.0375
A8: Defaults of rent through the pestilence total
A9: Cotlands defaults total
A10: Cotlands total
A11: Total of quittances and defaults of rent total
A12: Total of rents remaining clear total
A13: Farms total
A14: Annual recognizances total | B14: 0.05
A15: Issues of the Manor total | B15: 26.477083
A16: Issues of the tenements in the lord's hands total
A17: Sale of labour services total
A18: Sale of corn total | B18: 10.634375
A19: Entry and marriage fines total | B19: 2.3416667
A20: Pleas & perquisites total | B20: 1.0375
A21: Forfeited chattels total
A22: Farm of the demesne land total
A23: Total of all receipts (calculated here) | B23: =SUM(B5:B22)
A24: Total of all receipts (calculated here) incl arrears | B24: =SUM(B4:B22)
A25: Total recorded in the accounts excl. arrears | C25: =B23-B25
A26: Total recorded in the accounts incl. arrears | B26: =B25+B4
A29: EXPENSES
A30: Cost of ploughs total | B30: 9.8291667
A31: Purchase of corn total | B31: 0
A32: Cost of carts and wagons total | B32: 0.53958333
A33: Cost of dairy total | B33: 0.33333333
A34: Purchase of stock total | B34: 0
A35: Sheepcote total | B35: 4.275
A36: Cost of buildings total | B36: 6.3854167
A37: Threshing total | B37: 0.415625
A38: Barley expenses
A39: Expenses of the harvest total | B39: 0.67708333
A40: Necessary expenses
A41: Wages of the bailiff
A42: Steward's expenses total
...

Sheet Issues of the Mills
A1: No mill account for Adderbury

Sheet raw data
A1: Heading | B1: Sentence | C1: Total in Pounds | D1: Pounds | E1: Shillings | F1: Pence | G1: Corn | H1: Total Quarters Except 1 | I1: Total Bushels Except 1 | J1: Total Corn Cross-Check | K1: Total Corn Manorial Account | L1: Corn Quantity Error | M1: Quarters 1 | N1: Bushels 1 | O1: shilling a quarter 1 | P1: pence a quarter 1 | Q1: shilling a quarter 2 | R1: pence a quarter 2 | S1: shilling a quarter 3 | T1: pence a quarter 3 | U1: shilling a quarter 4 | V1: pence a quarter 4 | W1: shilling a bushel 1 | X1: pence a bushel 1 | Y1: shilling a bushel 2 | Z1: pence a bushel 2 | AA1: shilling a bushel 3 | AB1: pence a bushel 3 | AC1: shilling a bushel 4 | AD1: pence a bushel 4
A2: Adderbury | B2: The account2 of William Jakeman, reeve there, for the sixth year of the translation of Henry Beaufort', lord bishop of Winchester, and the eleventh year of the reign of King Henry the Fourth. | C2: 0 | D2: 0 | E2: 0 | F2: 0 | H2: 0 | I2: 0 | J2: 0 | K2: 0 | L2: 0 | M2: 0 | N2: 0
A3: Arrears | B3: None. | C3: 0 | D3: 0 | E3: 0 | F3: 0 | H3: 0 | I3: 0 | J3: 0 | K3: 0 | L3: 0 | M3: 0 | N3: 0
A4: Rents of assize | B4: And for £6 9 shilling 6.25pence for all rents of assize at St Thomas the Apostle (21 December). | C4: 6.48 | D4: 6 | E4: 9 | F4: 6.25 | H4: 0 | I4: 0 | J4: 0 | K4: 0 | L4: 0 | M4: 0 | N4: 0
A5: Rents of assize | B5: £6 9 shilling 8.5pence at Easter (23 March). | C5: 6.49 | D5: 6 | E5: 9 | F5: 8.5 | H5: 0 | I5: 0 | J5: 0 | K5: 0 | L5: 0 | M5: 0 | N5: 0
A6: Rents of assize | B6: £6 9 shilling 6.25pence at the Nativity of St John the Baptist (24 June). | C6: 6.48 | D6: 6 | E6: 9 | F6: 6.25 | H6: 0 | I6: 0 | J6: 0 | K6: 0 | L6: 0 | M6: 0 | N6: 0
A7: Rents of assize | B7: £6 10 shilling 1.5pence at Michaelmas (29 September). | C7: 6.51 | D7: 6 | E7: 10 | F7: 1.5 | H7: 0 | I7: 0 | J7: 0 | K7: 0 | L7: 0 | M7: 0 | N7: 0
A8: Rents of assize | B8: Total, £25 18 shilling 10.5pence. | C8: 25.94 | D8: 25 | E8: 18 | F8: 10.5 | H8: 0 | I8: 0 | J8: 0 | K8: 0 | L8: 0 | M8: 0 | N8: 0
A9: Quittances of rent | B9: In quittance of rent of 1 reeve for the year 5 shilling. | C9: 0.25 | D9: 0 | E9: 5 | F9: 0 | H9: 0 | I9: 0 | J9: 0 | K9: 0 | L9: 0 | M9: 0 | N9: 0
A10: Quittances of rent | B10: nothing this year of the 4 shilling for 1 smith forging the ironwork of 2 ploughs for the year. | C10: 0.2 | D10: 0 | E10: 4 | F10: 0 | H10: 0 | I10: 0 | J10: 0 | K10: 0 | L10: 0 | M10: 0 | N10: 0
A11: Quittances of rent | B11: nothing this year of the 4 shilling for 1 shepherd keeping the lord's wethers for the year. | C11: 0.2 | D11: 0 | E11: 4 | F11: 0 | H11: 0 | I11: 0 | J11: 0 | K11: 0 | L11: 0 | M11: 0 | N11: 0
A12: Quittances of rent | B12: nothing this year of the 4 shilling for 1 swineherd for the year. | C12: 0.2 | D12: 0 | E12: 4 | F12: 0 | H12: 0 | I12: 0 | J12: 0 | K12: 0 | L12: 0 | M12: 0 | N12: 0
A13: Quittances of rent | B13: nothing this year of the 4 shilling for 1 cowherd for the year. | C13: 0.2 | D13: 0 | E13: 4 | F13: 0 | H13: 0 | I13: 0 | J13: 0 | K13: 0 | L13: 0 | M13: 0 | N13: 0
... A149: Cost of buildings | B149: board-nails and clout-nails bought for the same 1 shilling 4pence. | C149: 0.07 | D149: 0 | E149: 1 | F149: 4 | H149: 0 | I149: 0 | J149: 0 | K149: 0 | L149: 0 | M149: 0 | N149: 0
A150: Cost of buildings | B150: 4 quarters 4 bushels of limestone bought at Walton' 5 shilling 3pence, at 1 shilling 2pence a quarters. | C150: 0.26 | D150: 0 | E150: 5 | F150: 3 | H150: 4 | I150: 4 | J150: 4.5 | K150: 4.5 | L150: 0 | M150: 4 | N150: 4 | O150: 1 | P150: 2
A151: Cost of buildings | B151: carrying the same 4pence. | C151: 0.02 | D151: 0 | E151: 0 | F151: 4 | H151: 0 | I151: 0 | J151: 0 | K151: 0 | L151: 0 | M151: 0 | N151: 0
A152: Cost of buildings | B152: 8 quarters of limestone bought at Witney 10 shilling 4pence, at 1 shilling 31 pence a quarters. | C152: 0.52 | D152: 0 | E152: 10 | F152: 4 | H152: 8 | I152: 0 | J152: 8 | K152: 8 | L152: 0 | M152: 8 | N152: 0 | O152: 1 | P152: 31
A153: Cost of buildings | B153: carrying the same from Witney to Adderbury 3 shilling 8pence. | C153: 0.18 | D153: 0 | E153: 3 | F153: 8 | H153: 0 | I153: 0 | J153: 0 | K153: 0 | L153: 0 | M153: 0 | N153: 0
A154: Cost of buildings | B154: 1,500 stone slates bought 6 shilling, at 4 shilling a 1,000.. | C154: 0.3 | D154: 0 | E154: 6 | F154: 0 | H154: 0 | I154: 0 | J154: 0 | K154: 0 | L154: 0 | M154: 0 | N154: 0
A155: Cost of buildings | B155: 500 eaves-stones bought 2 shilling 6pence, at 6pence a 100.. | C155: 0.12 | D155: 0 | E155: 2 | F155: 6 | H155: 0 | I155: 0 | J155: 0 | K155: 0 | L155: 0 | M155: 0 | N155: 0
A156: Cost of buildings | B156: 6,000 pins bought 2 shilling, at 4pence a 1,000.. | C156: 0.12 | D156: 0 | E156: 2 | F156: 4 | H156: 0 | I156: 0 | J156: 0 | K156: 0 | L156: 0 | M156: 0 | N156: 0
A157: Cost of buildings | B157: 50 ridge-tiles bought 6 shilling 3pence, at 1.5pence each. | C157: 0.31 | D157: 0 | E157: 6 | F157: 3 | H157: 0 | I157: 0 | J157: 0 | K157: 0 | L157: 0 | M157: 0 | N157: 0
A158: Cost of buildings | B158: sand bought and dug and quarried at Tadmarton 10pence. | C158: 0.04 | D158: 0 | E158: 0 | F158: 10 | H158: 0 | I158: 0 | J158: 0 | K158: 0 | L158: 0 | M158: 0 | N158: 0
A159: Cost of buildings | B159: stipend of 1 man going to Walton' to quarry lime there 2pence. | C159: 0.01 | D159: 0 | E159: 0 | F159: 2 | H159: 0 | I159: 0 | J159: 0 | K159: 0 | L159: 0 | M159: 0 | N159: 0
A160: Cost of buildings | B160: expenses of 12 men coming for a boon-work with 6 carts to quarry sand at Newotele and carry it to Adderbury, with the digging, 2 shilling 3pence. | C160: 0.11 | D160: 0 | E160: 2 | F160: 3 | H160: 0 | I160: 0 | J160: 0 | K160: 0 | L160: 0 | M160: 0 | N160: 0
A161: Cost of buildings | B161: hiring 1 man to carry sand and lime from the warrener's chamber to the barn by piece-work 4pence. | C161: 0.02 | D161: 0 | E161: 0 | F161: 4 | H161: 0 | I161: 0 | J161: 0 | K161: 0 | L161: 0 | M161: 0 | N161: 0
A162: Cost of buildings | B162: carrying the ridge-tiles bought above 8pence. | C162: 0.03 | D162: 0 | E162: 0 | F162: 8 | H162: 0 | I162: 0 | J162: 0 | K162: 0 | L162: 0 | M162: 0 | N162: 0
A163: Cost of buildings | B163: expenses of various men coming for a boon-work to buy slates at Aynho and carry them to Adderbury with the expenses of 1 man there mending the said slates 2d 1 shilling 9.5pence. | C163: 0.09 | D163: 0 | E163: 1 | F163: 9.5 | H163: 0 | I163: 0 | J163: 0 | K163: 0 | L163: 0 | M163: 0 | N163: 0
A164: Cost of buildings | B164: 1 tine bought 8pence. | C164: 0.03 | D164: 0 | E164: 0 | F164: 8 | H164: 0 | I164: 0 | J164: 0 | K164: 0 | L164: 0 | M164: 0 | N164: 0
... A181: Total of all allowances | B181: Total of all allowances and cash deliveries, £64 19 shilling 11.5pence He is quit. | C181: 65 | D181: 64 | E181: 19 | F181: 11.5 | H181: 0 | I181: 0 | J181: 0 | K181: 0 | L181: 0 | M181: 0 | N181: 0
A182: Wheat | B182: William Jakeman, reeve there, answers for 3 quarters of wheat remaining.. | C182: 0 | D182: 0 | E182: 0 | F182: 0 | G182: wheat | H182: 3 | I182: 0 | J182: 3 | K182: 3 | L182: 0 | M182: 3 | N182: 0
A183: Wheat | B183: Total, 3 quarters.. | C183: 0 | D183: 0 | E183: 0 | F183: 0 | H183: 3 | I183: 0 | J183: 3 | K183: 3 | L183: 0 | M183: 3 | N183: 0
A184: Wheat | B184: 3 quarters remain in the keeping of John Eadburbury, farmer there, to be handed back and restored at the end of his farm of 12 years, this year being the fifth. | C184: 0 | D184: 0 | E184: 0 | F184: 0 | H184: 3 | I184: 0 | J184: 3 | K184: 3 | L184: 0 | M184: 3 | N184: 0
A185: Rye | B185: And for 34 quarters of rye remaining.. | C185: 0 | D185: 0 | E185: 0 | F185: 0 | G185: rye | H185: 34 | I185: 0 | J185: 34 | K185: 34 | L185: 0 | M185: 34 | N185: 0
A186: Rye | B186: Total, 34 quarters.. | C186: 0 | D186: 0 | E186: 0 | F186: 0 | H186: 34 | I186: 0 | J186: 34 | K186: 34 | L186: 0 | M186: 34 | N186: 0
A187: Rye | B187: 34 quarters remain in the keeping of the said John Eadburbury, farmer there, to be handed back and restored at the end of his farm as before. | C187: 0 | D187: 0 | E187: 0 | F187: 0 | H187: 34 | I187: 0 | J187: 34 | K187: 34 | L187: 0 | M187: 34 | N187: 0
A188: Dredge | B188: And for 30 quarters of dredge remaining.. | C188: 0 | D188: 0 | E188: 0 | F188: 0 | G188: dredge | H188: 30 | I188: 0 | J188: 30 | K188: 30 | L188: 0 | M188: 30 | N188: 0
A189: Dredge | B189: Total, 30 quarters.. | C189: 0 | D189: 0 | E189: 0 | F189: 0 | H189: 30 | I189: 0 | J189: 30 | K189: 30 | L189: 0 | M189: 30 | N189: 0
A190: Dredge | B190: 30 quarters remain in the keeping of the said John Eadburbury, farmer there, to be handed back and restored as before. | C190: 0 | D190: 0 | E190: 0 | F190: 0 | H190: 30 | I190: 0 | J190: 30 | K190: 30 | L190: 0 | M190: 30 | N190: 0
A191: Pulses | B191: None remain. | C191: 0 | D191: 0 | E191: 0 | F191: 0 | H191: 0 | I191: 0 | J191: 0 | K191: 0 | L191: 0 | M191: 0 | N191: 0
...

Sheet Prices
A1: Meat & Dairy Prices
C2: 1301 | D2: 1302 | E2: Average
A3: Beef | B3: £ per lb | C3: 0.0033351854 | D3: 0.0032608538 | E3: =AVERAGE(C3:D3)
A4: Mutton | B4: £ per lb | C4: 0.0036593977 | D4: 0.0037125513 | E4: =AVERAGE(C4:D4)
A5: Pork | B5: £ per lb | C5: 0.0038431326 | D5: 0.0037574803 | E5: =AVERAGE(C5:D5)
A6: Cheese | B6: £ per lb | C6: 0.0055768754 | D6: 0.0056654898 | E6: =AVERAGE(C6:D6)
A7: Butter | B7: £ per lb | C7: 0.0036626221 | D7: 0.0035935077 | E7: =AVERAGE(C7:D7)
A8: Milk | B8: £ per gallon | C8: 0.0055768754 | D8: 0.0056654898 | E8: =AVERAGE(C8:D8)

Sheet Labour Rents

Sheet Highclere Overview
A1: Highclere | B1: £ | C1: s | D1: d | G1: Total in £ | H1: Error
A3: CASH ACCOUNT
A4: RECEIPTS
A5: Arrears total | G5: =IF(INDEX('Highclere Receipts'!$A$4:$F$136,MATCH('Highclere Overview'!$A5,'Highclere Receipts'!$A$4:$A$136,0),6)=0,"",INDEX('Highclere Receipts'!$A$4:$F$136,MATCH('Highclere Overview'!$A5,'Highclere Receipts'!$A$4:$A$136,0),6))
A6: Rents of assize total | G6: =IF(INDEX('Highclere Receipts'!$A$4:$F$136,MATCH('Highclere Overview'!$A6,'Highclere Receipts'!$A$4:$A$136,0),6)=0,"",INDEX('Highclere Receipts'!$A$4:$F$136,MATCH('Highclere Overview'!$A6,'Highclere Receipts'!$A$4:$A$136,0),6))
A7: Quittances total | G7: =IF(INDEX('Highclere Receipts'!$A$4:$F$136,MATCH('Highclere Overview'!$A7,'Highclere Receipts'!$A$4:$A$136,0),6)=0,"",INDEX('Highclere Receipts'!$A$4:$F$136,MATCH('Highclere Overview'!$A7,'Highclere Receipts'!$A$4:$A$136,0),6))
A8: Defaults of rent total | G8: =IF(INDEX('Highclere Receipts'!$A$4:$F$136,MATCH('Highclere Overview'!$A8,'Highclere Receipts'!$A$4:$A$136,0),6)=0,"",INDEX('Highclere Receipts'!$A$4:$F$136,MATCH('Highclere Overview'!$A8,'Highclere Receipts'!$A$4:$A$136,0),6))
A9: Rents remaining | G9: ='Highclere Receipts'!F39
A10: Annual recognizances total | G10: =IF(INDEX('Highclere Receipts'!$A$4:$F$136,MATCH('Highclere Overview'!$A10,'Highclere Receipts'!$A$4:$A$136,0),6)=0,"",INDEX('Highclere Receipts'!$A$4:$F$136,MATCH('Highclere Overview'!$A10,'Highclere Receipts'!$A$4:$A$136,0),6))
A11: Issues of the Manor total | G11: =IF(INDEX('Highclere Receipts'!$A$4:$F$136,MATCH('Highclere Overview'!$A11,'Highclere Receipts'!$A$4:$A$136,0),6)=0,"",INDEX('Highclere Receipts'!$A$4:$F$136,MATCH('Highclere Overview'!$A11,'Highclere Receipts'!$A$4:$A$136,0),6))
A12: Sale of corn total | G12: =IF(INDEX('Highclere Receipts'!$A$4:$F$136,MATCH('Highclere Overview'!$A12,'Highclere Receipts'!$A$4:$A$136,0),6)=0,"",INDEX('Highclere Receipts'!$A$4:$F$136,MATCH('Highclere Overview'!$A12,'Highclere Receipts'!$A$4:$A$136,0),6))
A13: Entry and marriage fines total | G13: =IF(INDEX('Highclere Receipts'!$A$4:$F$136,MATCH('Highclere Overview'!$A13,'Highclere Receipts'!$A$4:$A$136,0),6)=0,"",INDEX('Highclere Receipts'!$A$4:$F$136,MATCH('Highclere Overview'!$A13,'Highclere Receipts'!$A$4:$A$136,0),6))
A14: Pleas & perquisites total | G14: =IF(INDEX('Highclere Receipts'!$A$4:$F$136,MATCH('Highclere Overview'!$A14,'Highclere Receipts'!$A$4:$A$136,0),6)=0,"",INDEX('Highclere Receipts'!$A$4:$F$136,MATCH('Highclere Overview'!$A14,'Highclere Receipts'!$A$4:$A$136,0),6))
A15: Sum of the above (incl. arrears) | G15: =G5+G9+G10+G11+G12+G13+G14
A16: Total recorded in the accounts excl. arrears | G16: ='Highclere Receipts'!F135 | H16: =G15-G16
A17: Total recorded in the accounts incl. arrears | G17: ='Highclere Receipts'!F136 | I17: not recorded
A20: EXPENSES
A21: Cost of ploughs total | G21: =IF(INDEX('Highclere Expenses'!$A$2:$F$148,MATCH('Highclere Overview'!$A21,'Highclere Expenses'!$A$2:$A$148,0),6)=0,"",INDEX('Highclere Expenses'!$A$2:$F$148,MATCH('Highclere Overview'!$A21,'Highclere Expenses'!$A$2:$A$148,0),6))
A22: Purchase of corn total | G22: =IF(INDEX('Highclere Expenses'!$A$2:$F$148,MATCH('Highclere Overview'!$A22,'Highclere Expenses'!$A$2:$A$148,0),6)=0,"",INDEX('Highclere Expenses'!$A$2:$F$148,MATCH('Highclere Overview'!$A22,'Highclere Expenses'!$A$2:$A$148,0),6))
A23: Cost of carts and wagons total | G23: =IF(INDEX('Highclere Expenses'!$A$2:$F$148,MATCH('Highclere Overview'!$A23,'Highclere Expenses'!$A$2:$A$148,0),6)=0,"",INDEX('Highclere Expenses'!$A$2:$F$148,MATCH('Highclere Overview'!$A23,'Highclere Expenses'!$A$2:$A$148,0),6))
A24: Cost of dairy total | G24: =IF(INDEX('Highclere Expenses'!$A$2:$F$148,MATCH('Highclere Overview'!$A24,'Highclere Expenses'!$A$2:$A$148,0),6)=0,"",INDEX('Highclere Expenses'!$A$2:$F$148,MATCH('Highclere Overview'!$A24,'Highclere Expenses'!$A$2:$A$148,0),6))
A25: Purchase of stock total | G25: =IF(INDEX('Highclere Expenses'!$A$2:$F$148,MATCH('Highclere Overview'!$A25,'Highclere Expenses'!$A$2:$A$148,0),6)=0,"",INDEX('Highclere Expenses'!$A$2:$F$148,MATCH('Highclere Overview'!$A25,'Highclere Expenses'!$A$2:$A$148,0),6))
A26: Sheepcote total | G26: =IF(INDEX('Highclere Expenses'!$A$2:$F$148,MATCH('Highclere Overview'!$A26,'Highclere Expenses'!$A$2:$A$148,0),6)=0,"",INDEX('Highclere Expenses'!$A$2:$F$148,MATCH('Highclere Overview'!$A26,'Highclere Expenses'!$A$2:$A$148,0),6))
A27: Cost of buildings total | G27: =IF(INDEX('Highclere Expenses'!$A$2:$F$148,MATCH('Highclere Overview'!$A27,'Highclere Expenses'!$A$2:$A$148,0),6)=0,"",INDEX('Highclere Expenses'!$A$2:$F$148,MATCH('Highclere Overview'!$A27,'Highclere Expenses'!$A$2:$A$148,0),6))
A28: Threshing total | G28: =IF(INDEX('Highclere Expenses'!$A$2:$F$148,MATCH('Highclere Overview'!$A28,'Highclere Expenses'!$A$2:$A$148,0),6)=0,"",INDEX('Highclere Expenses'!$A$2:$F$148,MATCH('Highclere Overview'!$A28,'Highclere Expenses'!$A$2:$A$148,0),6))
A29: Expenses of the harvest total | G29: =IF(INDEX('Highclere Expenses'!$A$2:$F$148,MATCH('Highclere Overview'!$A29,'Highclere Expenses'!$A$2:$A$148,0),6)=0,"",INDEX('Highclere Expenses'!$A$2:$F$148,MATCH('Highclere Overview'!$A29,'Highclere Expenses'!$A$2:$A$148,0),6))
A30: Steward's expenses total | G30: =IF(INDEX('Highclere Expenses'!$A$2:$F$148,MATCH('Highclere Overview'!$A30,'Highclere Expenses'!$A$2:$A$148,0),6)=0,"",INDEX('Highclere Expenses'!$A$2:$F$148,MATCH('Highclere Overview'!$A30,'Highclere Expenses'!$A$2:$A$148,0),6))
A31: Total of all expenses calculated | G31: ='Highclere Expenses'!F141
A32: Total of all expenses in account | G32: ='Highclere Expenses'!F140 | H32: =G31-G32
A33: Capital Expenses | G33: ='Highclere Expenses'!F148
A35: Owed by the reeve | G35: =G15-G31
A36: From accounts | G36: ='Highclere Expenses'!F143 | H36: =G36-G35
A38: Cash deliveries
A39: Total of all allowances and cash deliveries in accounts | G39: n/a
A41: Net amount owed | G41: n/a
A42: Net amount owed in accounts | G42: ='Highclere Expenses'!F146
A44: GRANGE ACCOUNT | B44: Net Production
A45: Grange | B45: qrs | G45: Value of total gross production in £ | H45: Value of total net production in £
A46: Net wheat | B46: ='Issues of the Grange'!J19 | G46: ='Issues of the Grange'!P5 | H46: ='Issues of the Grange'!M19
A47: Net bere | B47: ='Issues of the Grange'!J20 | G47: ='Issues of the Grange'!P6 | H47: ='Issues of the Grange'!M20
...

Sheet Highclere Receipts
A1: Highclere RECEIPTS
B2: £ | C2: s | D2: d | F2: Total in £ | G2: Error | H2: Notes
A4: Arrears
A5: Arrears total | B5: 1 | C5: 8 | F5: =B5+C5/20+D5/240
A6: of which delivered to treasurer of Wolvesey | B6: 1 | C6: 8 | F6: =B6+C6/20+D6/240
A8: Rents of assize
A9: Christmas | B9: 1 | C9: 14 | F9: =B9+C9/20+D9/240
A10: Easter | B10: 3 | C10: 6 | F10: =B10+C10/20+D10/240
A11: Nativity | B11: 2 | F11: =B11+C11/20+D11/240
A12: Michaelmas | B12: 15 | C12: 8 | D12: 1.5 | F12: =B12+C12/20+D12/240
A13: Total recorded in accounts | B13: 22 | C13: 8 | D13: 1.5 | F13: =B13+C13/20+D13/240
A14: Rents of assize total | B14: =SUM(B9:B12) | C14: =SUM(C9:C12) | D14: =SUM(D9:D12) | F14: =B14+C14/20+D14/240 | G14: =F14-F13
A16: Quittances
A17: quittance of 1 reeve | C17: 4 | F17: =B17+C17/20+D17/240
A18: 1 hayward for the year | C18: 2 | F18: =B18+C18/20+D18/240
A19: 1 woodward of Holehurst | C19: 2 | D19: 4 | F19: =B19+C19/20+D19/240
A20: 3 ploughmen | C20: 6 | F20: =B20+C20/20+D20/240
A21: 1 ploughman | C21: 1 | D21: 3 | F21: =B21+C21/20+D21/240
A22: 1 smith making the ironwork of the ploughs | C22: 2 | F22: =B22+C22/20+D22/240
A23: 1 keeper of ewes | C23: 1 | D23: 3 | F23: =B23+C23/20+D23/240
A24: 1 cowherd | C24: 2 | F24: =B24+C24/20+D24/240
A25: Total recorded in accounts | B25: 1 | D25: 10 | F25: =B25+C25/20+D25/240
A26: Quittances total | B26: =SUM(B17:B24) | C26: =SUM(C17:C25) | D26: =SUM(D17:D24) | F26: =B26+C26/20+D26/240 | G26: =F26-F25
A28: Defaults of rent
A29: in default of 24 acres of land | D29: 10 | F29: =B29+C29/20+D29/240
A30: 10 virgates | C30: 13 | D30: 4 | F30: =B30+C30/20+D30/240
A31: the land of the skinner | C31: 1 | F31: =B31+C31/20+D31/240
A32: the land which belonged Benedict Clericus | C32: 4 | D32: 6 | F32: =B32+C32/20+D32/240
A33: land which belonged to Alexander ly Rych | C33: 17 | D33: 9 | F33: =B33+C33/20+D33/240
A34: rent of Hawkley | C34: 3 | F34: =B34+C34/20+D34/240
A35: Nicholas atte Zele | D35: 4 | F35: =B35+C35/20+D35/240
A36: Total recorded in accounts | B36: 2 | D36: 9 | F36: =B36+C36/20+D36/240
A37: Defaults of rent total | B37: =SUM(B29:B35) | C37: =SUM(C29:C35) | D37: =SUM(D29:D35) | F37: =B37+C37/20+D37/240 | G37: =F37-F36
A39: Total of rents remaining | B39: 19 | C39: 6 | D39: 6.5 | F39: =B39+C39/20+D39/240
A41: Wax
A42: nothing | F42: =B42+C42/20+D42/240
A43: Total recorded in accounts | F43: =B43+C43/20+D43/240
A44: Wax total | B44: =SUM(B42) | C44: =SUM(C42) | D44: =SUM(D42) | F44: =B44+C44/20+D44/240 | G44: =F44-F43
A46: Annual recognizances
A47: from Elias Snow | C47: 1 | F47: =B47+C47/20+D47/240
...

Sheet Highclere Expenses
A1: Highclere EXPENSES
B2: £ | C2: s | D2: d | F2: Total in £ | G2: Error | H2: Notes
A3: Cost of Ploughs
A4: ironworks for 2 ploughs | C4: 2 | D4: 10 | F4: =B4+C4/20+D4/240
A5: 2 plough irons bought | D5: 7 | F5: =B5+C5/20+D5/240
A6: 1 plougshare bought | D6: 10 | F6: =B6+C6/20+D6/240
A7: mending and fitting the ploughs | D7: 4.5 | F7: =B7+C7/20+D7/240
A8: fitting 1 plough with iron tyres | D8: 2.5 | F8: =B8+C8/20+D8/240
A9: 2 pairs of wheels bought | D9: 8 | F9: =B9+C9/20+D9/240
A10: trimming and treating timber for ploughs | C10: 2 | D10: 1.5 | F10: =B10+C10/20+D10/240
A11: in ploughing boon-works of 15 ploughmen | C11: 5 | F11: =B11+C11/20+D11/240
A12: reward of 3 ploughmen for the year for their Saturday ploughings | C12: 16 | D12: 10.5 | F12: =B12+C12/20+D12/240
A13: in stipend of 1 oxherd for 1.5 terms | D13: 9 | F13: =B13+C13/20+D13/240
A14: in 9 oxen bought for ploughs | B14: 5 | C14: 1 | D14: 3 | F14: =B14+C14/20+D14/240
A15: in wheat bought | B15: 1 | C15: 14 | D15: 4.5 | F15: =B15+C15/20+D15/240
A16: in bere bought for sowing and liveries | B16: 1 | C16: 10 | D16: 8.5 | F16: =B16+C16/20+D16/240
A17: Total recorded in accounts | B17: 9 | C17: 16 | D17: 7 | F17: =B17+C17/20+D17/240
A18: Cost of ploughs total | B18: =SUM(B3:B16) | C18: =SUM(C3:C16) | D18: =SUM(D3:D16) | F18: =B18+C18/20+D18/240 | G18: =F18-F17
A19: Total capital expenses | F19: =F4+F5+F6+F7+F8+F9+F10
A21: Purchase of Corn
F22: =B22+C22/20+D22/240 | H22: for some reason recorded with cost of ploughs
A23: Total recorded in accounts | F23: =B23+C23/20+D23/240
A24: Purchase of corn total | B24: =SUM(B22) | C24: =SUM(C22) | D24: =SUM(D22) | F24: =B24+C24/20+D24/240 | G24: =F24-F23
A26: Cost of Carts and Wagons
A27: clouts, nails, grease and white leather bought and in fitting 3 carts with axles | C27: 1 | D27: 10 | F27: =B27+C27/20+D27/240
A28: in 1 pair of tie-beams | D28: 6 | F28: =B28+C28/20+D28/240
A29: in 1 cart saddle | D29: 4 | F29: =B29+C29/20+D29/240
A30: in 1 pair of traces | D30: 6.5 | F30: =B30+C30/20+D30/240
A31: in 1 cart rope | C31: 1 | D31: 2 | F31: =B31+C31/20+D31/240
A32: in 1 cart-body made anew | D32: 6 | F32: =B32+C32/20+D32/240
A33: in mending the ironwork of the old dung-cart | D33: 3 | F33: =B33+C33/20+D33/240
A34: in 2 halters bought | D34: 4 | F34: =B34+C34/20+D34/240
A35: in shoeing 2 cart-horses | C35: 2 | D35: 2 | F35: =B35+C35/20+D35/240
A36: stipend of 1 carter for the year | C36: 3 | F36: =B36+C36/20+D36/240
A37: Total recorded in accounts | C37: 11 | D37: 2 | F37: =B37+C37/20+D37/240
A38: Cost of carts and wagons total | B38: =SUM(B27:B36) | C38: =SUM(C27:C36) | D38: =SUM(D27:D37) | F38: =B38+C38/20+D38/240 | G38: =F38-F37
A39: Total capital expenses | F39: =F27+F28+F29+F30+F31+F32+F33+F34+F35
A41: Cost of Dairy
A42: linen and woollen cloth | C42: 1 | D42: 2 | F42: =B42+C42/20+D42/240
A43: 1 new bucket | D43: 10.5 | F43: =B43+C43/20+D43/240
...

Sheet Issues of the Grange
B1: The issue of the grange account gives the total "yield" at the top of each heading in curly brackets, measurements used: fold, qrs, bus
B2: In "Issues of the grange" (p.xx) | G2: In "Sale of Corn" (p.x) | P2: Value of Total Production
A3: Gross output | B3: Quantity | D3: Additional bought-in | F3: Quantity | G3: Quantity noted as sold | J3: Difference Produced vs. Sold | K3: Price 1 | L3: Quantity 1 | M3: Price 2 | N3: Quantity 2 | O3: Unit price | P3: Value
B4: qrs | C4: bus | D4: qrs | E4: bus | F4: qrs | G4: qrs | H4: bus | I4: qrs | K4: £ | L4: qrs | M4: £ | N4: qrs | O4: £ per qr | P4: £
A5: Wheat | B5: =27+1 | C5: 6 | D5: 6.5 | E5: 3 | F5: =B5+D5+C5/8+E5/8 | G5: 25 | H5: 2 | I5: =G5+H5/8 | J5: =F5-I5 | K5: =6/20 | L5: 1 | O5: =IFERROR((K5+M5)/(L5+N5),0) | P5: =O5*F5
A6: Bere | B6: 17 | C6: 1 | D6: 10 | E6: =6+4 | F6: =B6+D6+C6/8+E6/8 | I6: =G6+H6/8 | J6: =F6-I6 | O6: =IFERROR((K6+M6)/(L6+N6),0) | Q6: not feasible to estimate because no sales prices
A7: Curall | F7: =B7+D7+C7/8+E7/8 | I7: =G7+H7/8 | J7: =F7-I7 | O7: =IFERROR((K7+M7)/(L7+N7),0) | P7: =O7*F7
A8: Barley | B8: 15 | F8: =B8+D8+C8/8+E8/8 | G8: 8 | H8: 2 | I8: =G8+H8/8 | J8: =F8-I8 | K8: =4/20 | L8: 1 | O8: =IFERROR((K8+M8)/(L8+N8),0) | P8: =O8*F8
A9: Oats | B9: 43 | C9: 0.5 | F9: =B9+D9+C9/8+E9/8 | G9: 4 | H9: 7 | I9: =G9+H9/8 | J9: =F9-I9 | K9: =2/20+6/240 | L9: 1 | O9: =IFERROR((K9+M9)/(L9+N9),0) | P9: =O9*F9
A10: Peas | D10: 0.5 | F10: =B10+D10+C10/8+E10/8 | I10: =G10+H10/8 | J10: =F10-I10 | O10: =IFERROR((K10+M10)/(L10+N10),0) | P10: =O10*F10
A11: Vetches | F11: =B11+D11+C11/8+E11/8 | I11: =G11+H11/8 | J11: =F11-I11 | O11: =IFERROR((K11+M11)/(L11+N11),0) | P11: =O11*F11
A13: Total Production | F13: =SUM(F5:F11) | P13: =SUM(P5:P11) | Q13: Production value is significantly more, as much less was sold than what was produced
A14: Sales of corn (as recorded in accounts) | F14: =SUM(I5:I11) | P14: =(O5*I5)+(O8*I8)+(O9*I9)
A17: Net output | B17: Gross output | C17: Seed | F17: tithe | G17: to manorial servants & livestock | J17: Output net of tithe & seed & liveries to manorial servants | K17: in stock from last year | L17: Price | M17: Value of net output | N17: Value of sales (in "Sale of Corn")
B18: qrs | C18: qrs | D18: bus | E18: qrs | F18: qrs | G18: qrs | H18: bus | I18: qrs | J18: qrs | K18: qrs | L18: £ per qr | M18: £ | N18: £
A19: Net wheat | B19: =F5 | C19: 8 | D19: =3+5 | E19: =C19+D19/8 | G19: =1 | H19: =1+2 | I19: =G19+H19/8 | J19: =B19-(E19+F19+I19) | L19: =O5 | M19: =L19*J19 | N19: =O5*I5
A20: Net bere | B20: =F6 | C20: 15 | D20: 1 | E20: =C20+D20/8 | G20: =5+2+1+4 | H20: =0.5+1+6+2.5 | I20: =G20+H20/8 | J20: =B20-(E20+F20+I20)
A21: Net curall | B21: =F7 | E21: =C21+D21/8 | I21: =G21+H21/8 | J21: =B21-(E21+F21+I21) | L21: =O7 | M21: =L21*J21 | N21: =O7*I7
A22: Net barley | B22: =F8 | C22: 6 | D22: 5 | E22: =C22+D22/8 | I22: =G22+H22/8 | J22: =B22-(E22+F22+I22) | L22: =O8 | M22: =L22*J22 | N22: =O8*I8
A23: Net oats | B23: =F9 | C23: 21 | D23: 1 | E23: =C23+D23/8 | G23: =7+8+1 | H23: =1+5+2+0.5 | I23: =G23+H23/8 | J23: =B23-(E23+F23+I23) | L23: =O9 | M23: =L23*J23 | N23: =O9*I9
A24: Net peas | B24: =F10 | D24: 2 | E24: =C24+D24/8 | H24: 2 | I24: =G24+H24/8 | J24: =B24-(E24+F24+I24) | L24: =O10 | M24: =L24*J24 | N24: =O10*I10
A25: Net vetches | B25: =F11 | E25: =C25+D25/8 | I25: =G25+H25/8 | J25: =B25-(E25+F25+I25) | L25: =O11 | M25: =L25*J25 | N25: =O11*I11
A26: Total | B26: =SUM(B19:B25) | E26: =SUM(E19:E25) | J26: =SUM(J19:J25) | M26: =SUM(M19:M25) | N26: =SUM(N19:N25)

Sheet Stock
A1: EAST KNOYLE STOCK ACCOUNT
A3: Livestock | B3: Inherited stock | C3: Bought | D3: Produced | E3: received fromother manors | F3: strays/heriot | G3: herbage | H3: sold | I3: in murrain | J3: accounted for elsewhere | K3: End-period stock | L3: cross-check | M3: price 1 | N3: units 1 | O3: price 2 | P3: units 2 | Q3: Weight (weys) | R3: Unit price (£) | S3: Value of production (£) at sales prices | T3: Sales in (£) | U3: Details
A4: Cart-horses | B4: 2 | K4: 2 | L4: =B4+C4+D4+F4-G4-H4-I4-J4 | R4: =IFERROR((M4+O4)/(N4+P4),"") | S4: =IFERROR(D4*R4,"") | T4: =IFERROR(R4*H4,"")
A5: Mares | L5: =B5+C5+D5+F5-G5-H5-I5-J5 | R5: =IFERROR((M5+O5)/(N5+P5),"") | S5: =IFERROR(D5*R5,"") | T5: =IFERROR(R5*H5,"")
A6: Plough horses | L6: =B6+C6+D6+F6-G6-H6-I6-J6 | R6: =IFERROR((M6+O6)/(N6+P6),"") | S6: =IFERROR(D6*R6,"") | T6: =IFERROR(R6*H6,"")
A7: Colts (2 years) | L7: =B7+C7+D7+F7-G7-H7-I7-J7 | R7: =IFERROR((M7+O7)/(N7+P7),"") | S7: =IFERROR(D7*R7,"") | T7: =IFERROR(R7*H7,"")
A8: Colts (2 years) | L8: =B8+C8+D8+F8-G8-H8-I8-J8 | R8: =IFERROR((M8+O8)/(N8+P8),"") | S8: =IFERROR(D8*R8,"") | T8: =IFERROR(R8*H8,"")
A9: Colts (1 year) | L9: =B9+C9+D9+F9-G9-H9-I9-J9 | R9: =IFERROR((M9+O9)/(N9+P9),"") | S9: =IFERROR(D9*R9,"") | T9: =IFERROR(R9*H9,"")
A10: Foals | L10: =B10+C10+D10+F10-G10-H10-I10-J10 | R10: =IFERROR((M10+O10)/(N10+P10),"") | S10: =IFERROR(D10*R10,"") | T10: =IFERROR(R10*H10,"")
A11: Oxen | B11: 21 | C11: 9 | H11: 8 | I11: 1 | J11: 3 | K11: 18 | L11: =B11+C11+D11+F11-G11-H11-I11-J11 | R11: =T11/H11 | S11: =D11*R11 | T11: ='Highclere Receipts'!F58
A12: Bulls | B12: 1 | D12: 1 | K12: 2 | L12: =B12+C12+D12+F12-G12-H12-I12-J12 | S12: =D12*R12 | T12: =IFERROR(R12*H12,"")
A13: Cows | B13: 50 | D13: 1 | H13: 7 | I13: 1 | K13: 43 | L13: =B13+C13+D13+F13-G13-H13-I13-J13 | R13: =T13/H13 | S13: =D13*R13 | T13: ='Highclere Receipts'!F59+('Highclere Receipts'!F60)
A14: Steers | B14: 4 | F14: 1 | H14: 1 | I14: 1 | J14: =1+1+1 | K14: 0 | L14: =B14+C14+D14+F14-G14-H14-I14-J14 | R14: =T14/H14 | S14: =D14*R14 | T14: ='Highclere Receipts'!F61
A15: Bullocks | B15: 15 | J15: 4 | K15: 11 | L15: =B15+C15+D15+F15-G15-H15-I15-J15 | S15: =D15*R15 | T15: =IFERROR(R15*H15,"")
A16: Yearlings | B16: 18 | I16: 2 | K16: 16 | L16: =B16+C16+D16+F16-G16-H16-I16-J16 | S16: =D16*R16 | T16: =IFERROR(R16*H16,"")
A17: Calves | D17: 36 | H17: =7+17 | I17: =1+2 | J17: =1+3 | K17: 14 | L17: =B17+C17+D17+F17-G17-H17-I17-J17 | R17: =T17/17 | S17: =D17*R17 | T17: ='Highclere Receipts'!F62 | U17: accounting does not add up, sales only record 17 sales
A18: Wethers | L18: =B18+C18+D18+F18-G18-H18-I18-J18 | S18: =D18*R18 | T18: =IFERROR(R18*H18,"")
A19: Rams | B19: 15 | I19: 1 | J19: 4 | K19: 10 | L19: =B19+C19+D19+F19-G19-H19-I19-J19 | S19: =D19*R19 | T19: =IFERROR(R19*H19,"")
A20: Ewes | B20: 383 | C20: 59 | D20: 48 | H20: 39 | I20: =6+3+2 | J20: 1 | K20: 449 | L20: =B20+C20+D20+F20-G20-H20-I20-J20 | R20: =T20/H20 | S20: =D20*R20 | T20: ='Highclere Receipts'!F63
A21: Hoggs | L21: =B21+C21+D21+F21-G21-H21-I21-J21 | S21: =D21*R21 | T21: =IFERROR(R21*H21,"")
A22: Lambs | D22: 324 | I22: =37 | J22: =28+4+225 | K22: 0 | L22: =B22+C22+D22+F22-G22-H22-I22-J22 | S22: =D22*R22 | T22: =IFERROR(R22*H22,"")
A23: Boars | L23: =B23+C23+D23+F23-G23-H23-I23-J23 | S23: =D23*R23 | T23: =IFERROR(R23*H23,"")
A24: Sows | L24: =B24+C24+D24+F24-G24-H24-I24-J24 | S24: =D24*R24 | T24: =IFERROR(R24*H24,"")
A25: Pigs | C25: 3 | H25: 3 | K25: 0 | L25: =B25+C25+D25+F25-G25-H25-I25-J25 | R25: =T25/H25 | S25: =D25*R25 | T25: ='Highclere Receipts'!F81
A26: Hoggets | L26: =B26+C26+D26+F26-G26-H26-I26-J26 | S26: =D26*R26 | T26: =IFERROR(R26*H26,"")
A27: Piglets | L27: =B27+C27+D27+F27-G27-H27-I27-J27 | R27: =IFERROR((M27+O27)/(N27+P27),"") | T27: =IFERROR(R27*H27,"")
A28: Swans | L28: =B28+C28+D28+F28-G28-H28-I28-J28 | R28: =IFERROR((M28+O28)/(N28+P28),"") | T28: =IFERROR(R28*H28,"")
A29: Peacocks | B29: 15 | I29: 2 | J29: 6 | K29: 7 | L29: =B29+C29+D29+F29-G29-H29-I29-J29 | R29: =IFERROR((M29+O29)/(N29+P29),"") | T29: =IFERROR(R29*H29,"")
A30: Total | L30: =B30+C30+D30+F30-G30-H30-I30-J30 | R30: =IFERROR((M30+O30)/(N30+P30),"") | S30: =SUM(S11:S26) | T30: =SUM(T4:T29)
R31: =IFERROR((M31+O31)/(N31+P31),"") | T31: =IFERROR(R31*H31,"")
A32: Wool | R32: =IFERROR((M32+O32)/(N32+P32),"") | T32: =IFERROR(R32*H32,"")
A33: Fleeces | L33: =B33+C33+D33+F33-G33-H33-I33-J33 | R33: =IFERROR((M33+O33)/(N33+P33),"") | T33: =IFERROR(R33*H33,"")
A34: Coarse wool | D34: =335+10 | E34: =237+570+320 | J34: =34+1+1437 | K34: 0 | L34: =B34+C34+D34+F34+E34-G34-H34-I34-J34 | R34: 0.02 | S34: =R34*J34 | T34: =IFERROR(R34*H34,"")
A35: Lamb's wool | E35: =243+249 | J35: =243+249 | K35: 0 | L35: =B35+C35+D35+F35+E35-G35-H35-I35-J35 | R35: 0.01 | S35: =R35*J35 | T35: =IFERROR(R35*H35,"")
A36: Wool locks | L36: =B36+C36+D36+F36+E36-G36-H36-I36-J36 | R36: =IFERROR((M36+O36)/(N36+P36),"") | T36: ='Highclere Receipts'!F78 | U36: no woollocks in stock account but they appear as being sold in receipts
A37: Wool sold at shearing | L37: =B37+C37+D37+F37+E37-G37-H37-I37-J37 | R37: =IFERROR((M37+O37)/(N37+P37),"") | T37: =IFERROR(R37*H37,"")
A38: Total | L38: =B38+C38+D38+F38+E38-G38-H38-I38-J38 | R38: =IFERROR((M38+O38)/(N38+P38),"") | S38: =S34+S35+T36 | T38: =SUM(T33:T37)
R39: =IFERROR((M39+O39)/(N39+P39),"") | T39: =IFERROR(R39*H39,"")
R40: =IFERROR((M40+O40)/(N40+P40),"") | T40: =IFERROR(R40*H40,"")
A41: Hides | R41: =IFERROR((M41+O41)/(N41+P41),"") | T41: =IFERROR(R41*H41,"")
...

Sheet Assumptions
A1: ASSUMPTIONS
B3: Weights | C3: Value (in lbs) | D3: Value (in cloves) | E3: Value (in weys) | F3: Value (in stone)
B4: Lbs | C4: 1 | D4: =C4/C5 | E4: =C4/C6 | F4: =C4/C7
B5: Cloves | C5: 7 | D5: 1 | E5: =C5/C6 | F5: =C7/C5
B6: Wey | C6: 175 | D6: =C6/C5 | E6: =C6/C6 | F6: =C7/C6
B7: Stone | C7: =175/14 | D7: =C5/C7 | E7: =C7/C6 | F7: 1
