Workbook

Sheet Ivinghoe Overview - Completed
A1: IVINGHOE OVERVIEW - COMPLETED | B1: Total in £ | C1: Error | D1: Note
A2: CASH ACCOUNT
A3: RECEIPTS
A4: Arrears total | B4: 4.5
A5: Rents of assize total | B5: 25.96
A6: Quittances total | B6: 2.29
A7: Defaults of rent total | B7: 0.9
A8: Defaults of rent through the pestilence total
A9: Cotlands defaults total
A10: Cotlands total
A11: Total of quittances and defaults of rent total | B11: 3.2
A12: Total of rents remaining clear total
A13: Farms total
A14: Annual recognizances total | B14: 0.17
A15: Issues of the Manor total | B15: 12.75
A16: Issues of the tenements in the lord's hands total
A17: Sale of labour services total
A18: Sale of corn total
A19: Entry and marriage fines total | B19: 9.18
A20: Pleas & perquisites total
A21: Forfeited chattels total
A22: Farm of the demesne land total
A23: Total of all receipts (calculated here) | B23: =SUM(B5:B22)
A24: Total of all receipts (calculated here) incl arrears | B24: =SUM(B4:B22)
A25: Total recorded in the accounts excl. arrears | B25: 125.81 | C25: =B23-B25
A26: Total recorded in the accounts incl. arrears | B26: =B25+B4
A29: EXPENSES
A30: Cost of ploughs total
A31: Purchase of corn total
A32: Cost of carts and wagons total
A33: Cost of dairy total
A34: Purchase of stock total | B34: 2.43
A35: Sheepcote total
A36: Cost of buildings total
A37: Threshing total | B37: 1.85
A38: Barley expenses
A39: Expenses of the harvest total
A40: Necessary expenses
A41: Wages of the bailiff
A42: Steward's expenses total | B42: 1.1941667
...

Sheet Prices
A1: Meat & Dairy Prices
C2: 1301 | D2: 1302 | E2: Average
A3: Beef | B3: £ per lb | C3: 0.0033351854 | D3: 0.0032608538 | E3: =AVERAGE(C3:D3)
A4: Mutton | B4: £ per lb | C4: 0.0036593977 | D4: 0.0037125513 | E4: =AVERAGE(C4:D4)
A5: Pork | B5: £ per lb | C5: 0.0038431326 | D5: 0.0037574803 | E5: =AVERAGE(C5:D5)
A6: Cheese | B6: £ per lb | C6: 0.0055768754 | D6: 0.0056654898 | E6: =AVERAGE(C6:D6)
A7: Butter | B7: £ per lb | C7: 0.0036626221 | D7: 0.0035935077 | E7: =AVERAGE(C7:D7)
A8: Milk | B8: £ per gallon | C8: 0.0055768754 | D8: 0.0056654898 | E8: =AVERAGE(C8:D8)

Sheet Labour Rents

Sheet Overview
A1: IVINGHOE | B1: Total in £ | C1: Error | D1: Note
A2: CASH ACCOUNT
A3: RECEIPTS
A4: Arrears total
A5: Rents of assize total
A6: Quittances total
A7: Defaults of rent total
A8: Defaults of rent through the pestilence total
A9: Cotlands defaults total
A10: Cotlands total
A11: Total of quittances and defaults of rent total
A12: Total of rents remaining clear total
A13: Farms total
... A22: Farm of the demesne land total
A23: Total of all receipts (calculated here) | B23: =Receipts!F134
A24: Total of all receipts (calculated here) incl arrears | B24: =Receipts!F135
A25: Total recorded in the accounts excl. arrears | B25: =Receipts!F133 | C25: =B25-B23
A26: Total recorded in the accounts incl. arrears
A29: EXPENSES
A30: Cost of ploughs total
A31: Purchase of corn total
A32: Cost of carts and wagons total
A33: Cost of dairy total
A34: Purchase of stock total
A35: Sheepcote total
A36: Cost of buildings total
A37: Threshing total
A38: Barley expenses
A39: Expenses of the harvest total
... A43: Annual fees
A44: Total of all expenses per account | B44: =Expenses!F100
A45: Total of all expenses (calculated here) | B45: =Expenses!F101
A46: Total fixed investment | B46: =Expenses!F102
A47: Total Demesne fixed investment | B47: =Expenses!F103
A49: Owed by the reeve
A50: From accounts
A52: Allowances
A53: Cash deliveries
A54: Sum of the above
A55: Total of all allowances and cash deliveries in accounts
...

Sheet Receipts
A1: IVINGHOE RECEIPTS
A2: Heading | B2: £ | C2: s | D2: d | F2: Total in £ | G2: Error | H2: Notes | I2: Own notes
A3: Arrears | B3: 2 | C3: 5 | D3: 1 | F3: 2.25 | H3: William, bailiff, and William, reeve, render account for £2 5 shilling 1pence of arrears from the previous year.
A4: Arrears | B4: 2 | C4: 5 | D4: 1 | F4: 2.25 | H4: Delivered to Sir Geoffrey, treasurer of Wolvesey, £2 5 shilling 1pence by 1 tally.
A5: Arrears | B5: 0 | C5: 0 | D5: 0 | F5: 0 | H5: They are quit.
A6: Arrears | F6: 4.5 | G6: 4.5 | H6: Total
A8: Rents of assize | B8: 6 | C8: 9 | D8: 10.5 | F8: 6.49 | H8: The same render account for £6 9 shilling 10.5pence for all rents of assize at Christmas.
A9: Rents of assize | B9: 6 | C9: 9 | D9: 10.5 | F9: 6.49 | H9: £6 9 shilling 10.5pence at the Annunciation (25 March).
A10: Rents of assize | B10: 6 | C10: 9 | D10: 10.5 | F10: 6.49 | H10: £6 9 shilling 10.5pence at the Nativity of the blessed John the Baptist (24 June).
A11: Rents of assize | B11: 6 | C11: 9 | D11: 10.75 | F11: 6.49 | H11: £6 9 shilling 10.75pence at Michaelmas (29 September).
A12: Rents of assize | B12: 25 | C12: 19 | D12: 6.25 | F12: 25.98 | H12: Total of all rents for the year, £25 19 shilling 6.25pence
A13: Rents of assize | F13: 25.96 | G13: -0.02 | H13: Total
A15: Quittances | B15: 0 | C15: 5 | D15: 0 | F15: 0.25 | H15: In quittance of 1 reeve for the year 5 shilling.
A16: Quittances | B16: 0 | C16: 2 | D16: 0 | F16: 0.1 | H16: 1 beadle who is hayward and sowed corn for the year 2 shilling.
A17: Quittances | B17: 0 | C17: 2 | D17: 2 | F17: 0.11 | H17: 1 forester who kept Cherlewod' and Cumbe for the year 2 shilling 2pence.
A18: Quittances | B18: 0 | C18: 2 | D18: 0 | F18: 0.1 | H18: 1 swineherd for the year 2 shilling.
A19: Quittances | B19: 0 | C19: 15 | D19: 0 | F19: 0.75 | H19: 5 of the lord's ploughmen for the year 15 shilling, or 3 shilling each.
A20: Quittances | B20: 0 | C20: 3 | D20: 10 | F20: 0.19 | H20: 4 workers working every day apart from Saturday from Michaelmas until Christmas who, together with the cart-horses of the curia, harrowed lands for wheat and drained water from the same, 3 shilling 10pence, of whom I was quit of 1 shilling 3pence, 1 of 1 shilling, 1 of 10pence, and 1 of 9pence.
A21: Quittances | B21: 0 | C21: 3 | D21: 10 | F21: 0.19 | H21: 4 workers working the same between Christmas and the Annunciation who, together with the cart-horses of the curia, harrowed lands for oats, 3 shilling 10pence, of whom 3 were each quit of 1 shilling, and 1 of 10pence.
A22: Quittances | B22: 0 | C22: 1 | D22: 10.5 | F22: 0.09 | H22: 2 workers working the same between the Annunciation and the Nativity of the blessed John the Baptist who harrowed lands for barley and enclosed with hedges, 1 shilling 10.5pence, of whom 1 was quit of 1 shilling, and 1 of 10.5pence.
A23: Quittances | B23: 0 | C23: 10 | D23: 3 | F23: 0.51 | H23: 10 workers working the same between the feast of St John the Baptist and Michaelmas who weeded corn, mowed and gathered hay, and carried corn, 10 shilling 3pence, of whom 1 was quit of 1 shilling 3pence, and 9 of 1 shilling each.
A24: Quittances | B24: 2 | C24: 5 | D24: 11.5 | F24: 2.3 | H24: Total of quittances, £2 5 shilling 11.5pence
A25: Quittances | F25: 2.29 | G25: -0.01 | H25: Total
A27: Defaults of rent | B27: 0 | C27: 18 | D27: 0 | F27: 0.9 | H27: In default of the land of the earl of Salisbury at Gaddesden 18 shilling
A28: Defaults of rent | B28: 0 | C28: 18 | D28: 0 | F28: 0.9 | H28: Total of defaults of rent, 18 shilling
A29: Defaults of rent | F29: 0.9 | G29: 0 | H29: Total
A31: Total of quittances and defaults of rent | B31: 3 | C31: 3 | D31: 11.5 | F31: 3.2 | H31: Total of quittances and defaults of rent, £3 3 shilling 11.5pence
A32: Total of quittances and defaults of rent | F32: 3.2 | G32: =F32-F31 | H32: Total
A34: Issues of the manor | B34: 0 | C34: 9 | D34: 8 | F34: 0.48 | H34: The same render account for 9 shilling 8pence from pannage of pigs of the whole vill.
A35: Issues of the manor | B35: 0 | C35: 0 | D35: 0 | F35: 0 | H35: nothing from foreign pannage because there was no mast.
A36: Issues of the manor | B36: 1 | C36: 0 | D36: 0 | F36: 1 | H36: £1 from dead wood blown down by the wind in Cherlewod'.
A37: Issues of the manor | B37: 0 | C37: 10 | D37: 6 | F37: 0.53 | H37: 10 shilling from winter ploughing this year, that is, 6pence a ploughman from 20 ploughmen.
A38: Issues of the manor | B38: 0 | C38: 0 | D38: 0 | F38: 0 | H38: nothing from Lenten ploughing because it was ploughed.
A39: Issues of the manor | B39: 0 | C39: 5 | D39: 6 | F39: 0.28 | H39: 5 shilling from 10 ploughmen for release from summer ploughing, at 6pence a ploughman.
A40: Issues of the manor | B40: 1 | C40: 10 | D40: 3 | F40: 1.51 | H40: £1 10 shilling 3pence from 60.5 virgates of land for release from transport-service this year, at 6pence a virgate, because no transport-service was done to London or elsewhere.
A41: Issues of the manor | B41: 0 | C41: 12 | D41: 6 | F41: 0.62 | H41: 12 shilling from the agistment of 6 old beasts (av') and 18 bullocks in the pasture of the grove for the summer, at 6pence an old beast and 4pence a bullock.
A42: Issues of the manor | B42: 0 | C42: 0 | D42: 0 | F42: 0 | H42: nothing from coarse wool this year because it is sent to Wolvesey.
A43: Issues of the manor | B43: 0 | C43: 0 | D43: 0 | F43: 0 | H43: nothing from lambs' fleeces this year because the lambs were not sheared.
A44: Issues of the manor | B44: 0 | C44: 1 | D44: 3 | F44: 0.06 | H44: 1 shilling 3pence from wool locks this year.
A45: Issues of the manor | B45: 0 | C45: 3 | D45: 1 | F45: 0.15 | H45: 3 shilling 1pence from winter cheese sold.
...

Sheet Expenses
A1: IVINGHOE EXPENSES
A2: Heading | B2: £ | C2: s | D2: d | F2: Total in £ | G2: Error | H2: Notes | I2: Own notes | K2: Fixed investment | L2: Demesne fixed investment
A3: Expenses for ploughs | B3: 0 | C3: 7 | D3: 10 | F3: 0.39 | H3: In ironwork of 5 ploughs for the year 7 shilling 10pence. | K3: =F3 | L3: =F3
A4: Expenses for ploughs | B4: 0 | C4: 1 | D4: 6 | F4: 0.08 | H4: 2 ploughshares bought 1 shilling 6pence Moreover they have 1 ploughshare as made clear above. | K4: =F4 | L4: =F4
A5: Expenses for ploughs | B5: 0 | C5: 0 | D5: 0 | F5: 0 | H5: Nothing accounted for forging the said ironwork because the smith takes 2 acres of wheat as they lie in the field for forging the same when the ploughmen are ploughing for the whole year. | K5: =F5 | L5: =F5
A6: Expenses for ploughs | B6: 0 | C6: 0 | D6: 8 | F6: 0.03 | H6: 4 iron spurs bought 8pence. | K6: =F6 | L6: =F6
A7: Expenses for ploughs | B7: 0 | C7: 3 | D7: 2 | F7: 0.16 | H7: stipend of 1 carpenter making new ploughs, repairing old ploughs, and making harrows and yokes from the lord's timber 3 shilling 2pence, because the manorial servant who by custom made these is deapence. | K7: =F7 | L7: =K7/2
A8: Expenses for ploughs | B8: 8 | C8: 18 | D8: 2 | F8: 8.91 | H8: 15 oxen bought £8 18 shilling 2pence, at 13 shilling 5pence each for 2, 12 shilling 6pence each for 4, 12 shilling each for 3, 11 shilling 5pence each for 3, 10 shilling 6.51. each for 2, and 10 shilling for 1..
A9: Expenses for ploughs | B9: 2 | C9: 4 | D9: 11 | F9: 2.25 | H9: 12 quarters 2 bushels of wheat bought for sowing £2 4 shilling 11pence, at 3 shilling 8pence a quarters.
A10: Expenses for ploughs | B10: 4 | C10: 4 | D10: 0 | F10: 4.2 | H10: 34 quarters of maslin bought for the liveries of the manorial servants £4 4 shilling, at 3 shilling a quarters for 8 quarters, 2 shilling 8pence a quarters for 12 quarters, and 2 shilling a quarters for 14 quarters.
A11: Expenses for ploughs | B11: 0 | C11: 6 | D11: 9 | F11: 0.34 | H11: 4.5 quarters of oats bought for fodder of horses 6 shilling 9pence, at 1 shilling 6pence a quarters.
A12: Expenses for ploughs | B12: 1 | C12: 0 | D12: 0 | F12: 1 | H12: hay bought £1, because hay was taken for the queen's use.
A13: Expenses for ploughs | B13: 1 | C13: 16 | D13: 0 | F13: 1.8 | H13: forage bought for stock £1 16 shilling Ipence.
A14: Expenses for ploughs | B14: 0 | C14: 6 | D14: 8 | F14: =B14+C14/20+D14/240 | H14: stipend of 5 oxherds for .5 year in winter 6 shilling 8pence, or 1 shilling 4pence each, because each manorial servant takes corn at harvest-time for the other .5 year in summer, that is,' acre of wheat and .5 acre of oats as they lie in the fie1pence
A15: Expenses for ploughs | B15: 19 | C15: 8 | D15: 3 | F15: 19.41 | H15: Total, £19 8 shilling 3pence
A16: Expenses for ploughs | F16: =SUM(F3:F14) | G16: =F16-F15 | H16: Total
A18: Expenses for carts and wagons | B18: 0 | C18: 1 | D18: 2 | F18: 0.06 | H18: In clouts and nails for the cart for the year 1 shilling 2pence. | K18: =F18 | L18: =K18
A19: Expenses for carts and wagons | B19: 0 | C19: 1 | D19: 1 | F19: 0.05 | H19: white leather for mending harnesses of the cart 1 shilling 1pence. | K19: =F19 | L19: =K19
A20: Expenses for carts and wagons | B20: 0 | C20: 0 | D20: 4 | F20: 0.02 | H20: grease bought for the year 4pence. | K20: =F20 | L20: =K20
A21: Expenses for carts and wagons | B21: 0 | C21: 0 | D21: 1 | F21: 0 | H21: 5 halters for plough-horses made from their own hair 1pence. | K21: =F21 | L21: =K21
A22: Expenses for carts and wagons | B22: 0 | C22: 0 | D22: 1.5 | F22: 0.01 | H22: mending saddle-pads 1.5pence. | K22: =F22 | L22: =K22
A23: Expenses for carts and wagons | B23: 0 | C23: 0 | D23: 6 | F23: 0.03 | H23: 1 collar bought 6pence. | K23: =F23 | L23: =K23
A24: Expenses for carts and wagons | B24: 0 | C24: 0 | D24: 1.5 | F24: 0.01 | H24: a wooden base for 1 cart-saddle 1.5pence. | K24: =F24 | L24: =K24
A25: Expenses for carts and wagons | B25: 0 | C25: 0 | D25: 1 | F25: 0 | H25: repairing old collars 1pence. | K25: =F25 | L25: =K25
A26: Expenses for carts and wagons | B26: 0 | C26: 0 | D26: 7 | F26: 0.03 | H26: 1 pair of traces bought 7pence. | K26: =F26 | L26: =K26
A27: Expenses for carts and wagons | B27: 0 | C27: 0 | D27: 0 | F27: 0 | H27: making 2 pairs of wheels from the lord's timber for the cart with iron tyres and for clearing dung. | K27: =F27 | L27: =K27
A28: Expenses for carts and wagons | B28: 0 | C28: 6 | D28: 2 | F28: 0.31 | H28: new large nails and clamps and frets with the stipend of the smith fitting 1 pair of wheels with old iron tyres 6 shilling 2pence. | K28: =F28 | L28: =K28
A29: Expenses for carts and wagons | B29: 0 | C29: 0 | D29: 4 | F29: 0.02 | H29: fitting the cart with axles for the year 4pence. | K29: =F29 | L29: =K29
A30: Expenses for carts and wagons | B30: 0 | C30: 2 | D30: 0 | F30: 0.1 | H30: shoeing 2 cart-horses for the year by piece-work 2 shilling. | K30: =F30 | L30: =K30
A31: Expenses for carts and wagons | B31: 0 | C31: 1 | D31: 4 | F31: 0.07 | H31: stipend of 1 carter for' year in winter 1 shilling 4pence, because for the other .5 year he takes corn in the field like the rest of the manorial servants. | K31: =F31 | L31: =K31/2
A32: Expenses for carts and wagons | B32: 0 | C32: 0 | D32: 6 | F32: 0.03 | H32: clouts and nails bought for wagons 6pence. | K32: =F32 | L32: =K32
A33: Expenses for carts and wagons | B33: 0 | C33: 0 | D33: 2 | F33: =B33+C33/20+D33/240 | H33: grease and tallow bought for the same 2pence | K33: =F33 | L33: =K33
A34: Expenses for carts and wagons | B34: 0 | C34: 15 | D34: 2 | F34: 0.76 | H34: Total, 15 shilling 5pence
A35: Expenses for carts and wagons | F35: =SUM(F18:F33) | G35: =F35-F34 | H35: Total
A37: Dairy | B37: 0 | C37: 0 | D37: 3 | F37: 0.01 | H37: In linen cloth for the dairy 3pence. | K37: =F37 | L37: =F37
A38: Dairy | B38: 0 | C38: 0 | D38: 3.5 | F38: 0.01 | H38: earthenware pots and pans bought 3.5pence. | K38: =F38 | L38: =F38
A39: Dairy | B39: 0 | C39: 0 | D39: 3 | F39: 0.01 | H39: a press 3pence. | K39: =F39 | L39: =F39
A40: Dairy | B40: 0 | C40: 1 | D40: 10 | F40: 0.09 | H40: .5 qr of salt bought 1 shilling 10pence, at 7pence for 1 bushels, and 5pence each for 3 bushels. | K40: =F40 | L40: =F40
A41: Dairy | B41: 0 | C41: 0 | D41: 1.5 | F41: 0.01 | H41: 1 colander bought 1.5pence. | K41: =F41 | L41: =F41
A42: Dairy | B42: 0 | C42: 5 | D42: 3 | F42: 0.26 | H42: vinegar and pigs' fat for greasing sick sheep 5 shilling 3pence. | K42: =F42 | L42: =F42
...

Sheet Issues of the Grange
A1: Gross Output | B1: Total Quantity | C1: Account Total Quarters | D1: Bought in Total Quarters | E1: Received from churchscot | F1: Sold Total Quarters | G1: Difference Produced+Bought-Sold | H1: Weighted Average Price per Quarter | I1: Value of Total Production weighted
A2: wheat | B2: 220.375 | C2: 201.625 | D2: 12.25 | F2: 177.75 | G2: =B2-F2 | H2: 0.24648383 | I2: =H2*B2
A3: curall | B3: 10.375 | C3: 10.375 | D3: 0 | F3: 0 | G3: =B3-F3 | I3: =H3*B3
A4: mancorn | B4: 0 | C4: 0 | D4: 0 | F4: 0 | G4: =B4-F4 | I4: =H4*B4
A5: barley | B5: 74 | C5: =19.75+20.25 | D5: 34 | F5: 10.4375 | G5: =B5-F5 | H5: 0.16666667 | I5: =H5*B5
A6: oats | B6: =216+2/8 | C6: =B6-D6 | D6: =4.5 | F6: 99.875 | G6: =B6-F6 | H6: 0.089987484 | I6: =H6*B6
A7: beans | B7: 20.125 | C7: 20.125 | D7: 0 | F7: 6.125 | G7: =B7-F7 | H7: 0.1 | I7: =H7*B7
A9: Total Production
A10: Sales of corn (as recorded in accounts)
A13: Net output | B13: Gross output | C13: Seed quarters | D13: Seed bushels | E13: Seed total quarters | F13: tithe quarters | G13: tithe bushels | H13: tithe total | I13: manorial servants quarters | J13: manorial servants bushels | K13: manorial servants total quarters | L13: output net of tithe, seed, liveries | M13: in stock from last year | N13: Price in £ | O13: Value of net output in £ | P13: Value of sales (in "Sale of Corn") in £
A14: wheat | B14: =B2 | C14: 32 | D14: 2 | E14: =C14+D14/8 | I14: =1.5+6.5+0.5 | J14: =6+3+3+3 | K14: =I14+J14/8 | L14: =B14-E14-K14 | N14: =H2 | O14: =N14*L14
A15: curall | B15: =B3 | E15: =C15+D15/8 | I15: 10 | J15: 3 | K15: =I15+J15/8 | L15: =B15-E15-K15 | N15: =H3 | O15: =N15*L15
A16: mancorn | B16: =B4 | E16: =C16+D16/8 | K16: =I16+J16/8 | L16: =B16-E16-K16 | N16: =H4 | O16: =N16*L16
A17: barley | B17: =B5 | C17: 4 | D17: 3 | E17: =C17+D17/8 | I17: =39+18+1 | J17: =6.5+3 | K17: =I17+J17/8 | L17: =B17-E17-K17 | N17: =H5 | O17: =N17*L17
A18: oats | B18: =B6 | C18: 90 | D18: 5 | E18: =C18+D18/8 | I18: =15+0.5+1+4.5+0.5+2 | J18: =7+2+5 | K18: =I18+J18/8 | L18: =B18-E18-K18 | N18: =H6 | O18: =N18*L18
A19: beans | B19: =B7 | C19: 4 | D19: 1 | E19: =C19+D19/8 | I19: 9 | J19: 7 | K19: =I19+J19/8 | L19: =B19-E19-K19 | N19: =H7 | O19: =N19*L19
A21: Total

Sheet Issues of the Mills

Sheet Stock
A1: IVINGHOE STOCK ACCOUNT
C3: added | G3: subtracted
A4: Livestock | B4: Inherited stock | C4: added | D4: strays | E4: herbage | F4: churchscot | G4: of which in default | H4: sold | I4: in murrain | J4: accounted for elsewhere | K4: End-period stock | L4: cross-check | M4: stock building | N4: raw production | O4: Unit price (£) | P4: Value of stock (£) at given value | Q4: Value of stock (£) at sales prices | R4: Sales in (£) | S4: Value of stock building (£) | T4: Value of production (£) at sales prices | U4: Details
A5: Cart-horses | B5: 2 | K5: 2
A6: Mares
A7: Plough horses | B7: 10 | H7: 6 | K7: 4 | O7: =R7/H7 | R7: =Receipts!F67 | T7: =O7*C7
A8: Colts (unspecified years) | T8: =O8*C8
A9: Colts (2 years) | T9: =O9*C9
A10: Colts (1 year) | T10: =O10*C10
A11: Foals | T11: =O11*C11
A12: Oxen | B12: 32 | C12: =2+1+1+15 | H12: =1+7 | I12: =1 | K12: 42 | O12: =R12/H12 | R12: =Receipts!F68 | T12: =O12*C12
A13: Bulls | B13: 2 | H13: 1 | K13: 1 | O13: =R13/H13 | R13: =Receipts!F69 | T13: =O13*C13
A14: Cows | B14: 22 | C14: =5+1 | H14: =1+3 | K14: 24 | O14: =R14/H14 | R14: =Receipts!F70 | T14: =O14*C14
A15: Steers | B15: 8 | H15: =1 | J15: =2+5 | K15: 0 | O15: =R15/H15 | R15: =Receipts!F71 | T15: =O15*C15
A16: Bullocks | B16: 3 | K16: 3 | T16: =O16*C16
A17: Yearlings | B17: 5 | I17: 2 | K17: 3 | T17: =O17*C17
A18: Calves | C18: =21+2 | H18: =11+2 | K18: 6 | O18: =R18/H18 | R18: =Receipts!F72 | T18: =O18*C18
A19: Wethers | B19: 175 | C19: =16+28 | H19: =54+26 | I19: =40+1 | J19: =1 | K19: 97 | O19: =R19/H19 | R19: =Receipts!F75+Receipts!F81 | T19: =O19*C19
A20: Rams | T20: =O20*C20
A21: Ewes | B21: 85 | C21: 11 | I21: =33+5+4 | K21: 54 | T21: =O21*C21
A22: Hoggs | B22: 56 | I22: =29+16+11 | K22: 0 | T22: =O22*C22
A23: Lambs | C23: 34 | H23: =4 | I23: =33+5 | J23: =3 | K23: 26 | O23: =R23/H23 | R23: 0.02 | T23: =O23*C23 | U23: taken from lamb price in composite sale
A24: Boars | B24: 1 | K24: 1 | T24: =O24*C24
A25: Sows | B25: 2 | K25: 2 | T25: =O25*C25
A26: Pigs | B26: 36 | C26: 24 | H26: 30 | K26: 30 | O26: =R26/H26 | R26: =Receipts!F79 | T26: =O26*C26
A27: Hoggets | B27: 25 | I27: =1 | J27: 24 | K27: 0 | T27: =O27*C27
A28: Piglets | C28: =18+13 | J28: =3+1 | K28: 27 | T28: =O28*C28
A29: Swans | T29: =O29*C29
A30: Peacocks | B30: 8 | H30: 3 | J30: 2 | K30: 3 | O30: =R30/H30 | R30: =Receipts!F78 | T30: =O30*C30
A31: Total Value | R31: =SUM(R5:R30) | T31: =SUM(T7:T30)
A34: Wool
A35: Coarse wool | C35: 158 | J35: =13+1+144 | O35: 0.02 | T35: =O35*J35
A36: Lamb's wool
A37: Wool locks
A38: Wool sold at shearing
A39: Total wool | T39: =SUM(T35:T38)
A42: Hides
A43: Ox hides
A44: Mare
A45: Steer
...

Sheet raw data
A1: Heading | B1: Sentence | C1: Total in Pounds | D1: Pounds | E1: Shillings | F1: Pence | G1: Corn | H1: Total Quarters Except 1 | I1: Total Bushels Except 1 | J1: Total Corn Cross-Check | K1: Total Corn Manorial Account | L1: Corn Quantity Error | M1: Quarters 1 | N1: Bushels 1 | O1: Quarters 2 | P1: Bushels 2 | Q1: Quarters 3 | R1: Bushels 3 | S1: Quarters 4 | T1: Bushels 4 | U1: shilling a quarter 1 | V1: pence a quarter 1 | W1: shilling a quarter 2 | X1: pence a quarter 2 | Y1: shilling a quarter 3 | Z1: pence a quarter 3 | AA1: shilling a quarter 4 | AB1: pence a quarter 4 | AC1: shilling a bushel 1 | AD1: pence a bushel 1 | AE1: shilling a bushel 2 | AF1: pence a bushel 2 | AG1: shilling a bushel 3 | AH1: pence a bushel 3 | AI1: shilling a bushel 4 | AJ1: pence a bushel 4
A2: Arrears | B2: William, bailiff, and William, reeve, render account for £2 5 shilling 1pence of arrears from the previous year. | C2: 2.25 | D2: 2 | E2: 5 | F2: 1 | H2: 0 | I2: 0 | J2: 0 | K2: 0 | L2: 0 | M2: 0 | N2: 0
A3: Arrears | B3: Delivered to Sir Geoffrey, treasurer of Wolvesey, £2 5 shilling 1pence by 1 tally. | C3: 2.25 | D3: 2 | E3: 5 | F3: 1 | H3: 0 | I3: 0 | J3: 0 | K3: 0 | L3: 0 | M3: 0 | N3: 0
A4: Arrears | B4: They are quit. | C4: 0 | D4: 0 | E4: 0 | F4: 0 | H4: 0 | I4: 0 | J4: 0 | K4: 0 | L4: 0 | M4: 0 | N4: 0
A5: Rents of assize | B5: The same render account for £6 9 shilling 10.5pence for all rents of assize at Christmas. | C5: 6.49 | D5: 6 | E5: 9 | F5: 10.5 | H5: 0 | I5: 0 | J5: 0 | K5: 0 | L5: 0 | M5: 0 | N5: 0
A6: Rents of assize | B6: £6 9 shilling 10.5pence at the Annunciation (25 March). | C6: 6.49 | D6: 6 | E6: 9 | F6: 10.5 | H6: 0 | I6: 0 | J6: 0 | K6: 0 | L6: 0 | M6: 0 | N6: 0
A7: Rents of assize | B7: £6 9 shilling 10.5pence at the Nativity of the blessed John the Baptist (24 June). | C7: 6.49 | D7: 6 | E7: 9 | F7: 10.5 | H7: 0 | I7: 0 | J7: 0 | K7: 0 | L7: 0 | M7: 0 | N7: 0
A8: Rents of assize | B8: £6 9 shilling 10.75pence at Michaelmas (29 September). | C8: 6.49 | D8: 6 | E8: 9 | F8: 10.75 | H8: 0 | I8: 0 | J8: 0 | K8: 0 | L8: 0 | M8: 0 | N8: 0
A9: Rents of assize | B9: Total of all rents for the year, £25 19 shilling 6.25pence | C9: 25.98 | D9: 25 | E9: 19 | F9: 6.25 | H9: 0 | I9: 0 | J9: 0 | K9: 0 | L9: 0 | M9: 0 | N9: 0
A10: Quittances | B10: In quittance of 1 reeve for the year 5 shilling. | C10: 0.25 | D10: 0 | E10: 5 | F10: 0 | H10: 0 | I10: 0 | J10: 0 | K10: 0 | L10: 0 | M10: 0 | N10: 0
A11: Quittances | B11: 1 beadle who is hayward and sowed corn for the year 2 shilling. | C11: 0.1 | D11: 0 | E11: 2 | F11: 0 | H11: 0 | I11: 0 | J11: 0 | K11: 0 | L11: 0 | M11: 0 | N11: 0
A12: Quittances | B12: 1 forester who kept Cherlewod' and Cumbe for the year 2 shilling 2pence. | C12: 0.11 | D12: 0 | E12: 2 | F12: 2 | H12: 0 | I12: 0 | J12: 0 | K12: 0 | L12: 0 | M12: 0 | N12: 0
A13: Quittances | B13: 1 swineherd for the year 2 shilling. | C13: 0.1 | D13: 0 | E13: 2 | F13: 0 | H13: 0 | I13: 0 | J13: 0 | K13: 0 | L13: 0 | M13: 0 | N13: 0
A14: Quittances | B14: 5 of the lord's ploughmen for the year 15 shilling, or 3 shilling each. | C14: 0.75 | D14: 0 | E14: 15 | F14: 0 | H14: 0 | I14: 0 | J14: 0 | K14: 0 | L14: 0 | M14: 0 | N14: 0
A15: Quittances | B15: 4 workers working every day apart from Saturday from Michaelmas until Christmas who, together with the cart-horses of the curia, harrowed lands for wheat and drained water from the same, 3 shilling 10pence, of whom I was quit of 1 shilling 3pence, 1 of 1 shilling, 1 of 10pence, and 1 of 9pence. | C15: 0.19 | D15: 0 | E15: 3 | F15: 10 | G15: wheat | H15: 0 | I15: 0 | J15: 0 | K15: 0 | L15: 0 | M15: 0 | N15: 0
A16: Quittances | B16: 4 workers working the same between Christmas and the Annunciation who, together with the cart-horses of the curia, harrowed lands for oats, 3 shilling 10pence, of whom 3 were each quit of 1 shilling, and 1 of 10pence. | C16: 0.19 | D16: 0 | E16: 3 | F16: 10 | G16: oats | H16: 0 | I16: 0 | J16: 0 | K16: 0 | L16: 0 | M16: 0 | N16: 0
A17: Quittances | B17: 2 workers working the same between the Annunciation and the Nativity of the blessed John the Baptist who harrowed lands for barley and enclosed with hedges, 1 shilling 10.5pence, of whom 1 was quit of 1 shilling, and 1 of 10.5pence. | C17: 0.09 | D17: 0 | E17: 1 | F17: 10.5 | G17: barley | H17: 0 | I17: 0 | J17: 0 | K17: 0 | L17: 0 | M17: 0 | N17: 0
A18: Quittances | B18: 10 workers working the same between the feast of St John the Baptist and Michaelmas who weeded corn, mowed and gathered hay, and carried corn, 10 shilling 3pence, of whom 1 was quit of 1 shilling 3pence, and 9 of 1 shilling each. | C18: 0.51 | D18: 0 | E18: 10 | F18: 3 | H18: 0 | I18: 0 | J18: 0 | K18: 0 | L18: 0 | M18: 0 | N18: 0
A19: Quittances | B19: Total of quittances, £2 5 shilling 11.5pence | C19: 2.3 | D19: 2 | E19: 5 | F19: 11.5 | H19: 0 | I19: 0 | J19: 0 | K19: 0 | L19: 0 | M19: 0 | N19: 0
A20: Defaults of rent | B20: In default of the land of the earl of Salisbury at Gaddesden 18 shilling Total of defaults of rent, 18 shilling | C20: 0.9 | D20: 0 | E20: 18 | F20: 0 | H20: 0 | I20: 0 | J20: 0 | K20: 0 | L20: 0 | M20: 0 | N20: 0
A21: Total of quittances and defaults of rent | B21: Total of quittances and defaults of rent, £3 3 shilling 11.5pence | C21: 3.2 | D21: 3 | E21: 3 | F21: 11.5 | H21: 0 | I21: 0 | J21: 0 | K21: 0 | L21: 0 | M21: 0 | N21: 0
A22: Total remaining | B22: Total remaining, £22 15 shilling 6.25pence | C22: 22.78 | D22: 22 | E22: 15 | F22: 6.25 | H22: 0 | I22: 0 | J22: 0 | K22: 0 | L22: 0 | M22: 0 | N22: 0
A23: Issues of the manor | B23: The same render account for 9 shilling 8pence from pannage of pigs of the whole vill. | C23: 0.48 | D23: 0 | E23: 9 | F23: 8 | H23: 0 | I23: 0 | J23: 0 | K23: 0 | L23: 0 | M23: 0 | N23: 0
A24: Issues of the manor | B24: nothing from foreign pannage because there was no mast. | C24: 0 | D24: 0 | E24: 0 | F24: 0 | H24: 0 | I24: 0 | J24: 0 | K24: 0 | L24: 0 | M24: 0 | N24: 0
A25: Issues of the manor | B25: £1 from dead wood blown down by the wind in Cherlewod'. | C25: 1 | D25: 1 | E25: 0 | F25: 0 | H25: 0 | I25: 0 | J25: 0 | K25: 0 | L25: 0 | M25: 0 | N25: 0
A26: Issues of the manor | B26: 10 shilling from winter ploughing this year, that is, 6pence a ploughman from 20 ploughmen. | C26: 0.53 | D26: 0 | E26: 10 | F26: 6 | H26: 0 | I26: 0 | J26: 0 | K26: 0 | L26: 0 | M26: 0 | N26: 0
A27: Issues of the manor | B27: nothing from Lenten ploughing because it was ploughed. | C27: 0 | D27: 0 | E27: 0 | F27: 0 | H27: 0 | I27: 0 | J27: 0 | K27: 0 | L27: 0 | M27: 0 | N27: 0
A28: Issues of the manor | B28: 5 shilling from 10 ploughmen for release from summer ploughing, at 6pence a ploughman. | C28: 0.28 | D28: 0 | E28: 5 | F28: 6 | H28: 0 | I28: 0 | J28: 0 | K28: 0 | L28: 0 | M28: 0 | N28: 0
A29: Issues of the manor | B29: £1 10 shilling 3pence from 60.5 virgates of land for release from transport-service this year, at 6pence a virgate, because no transport-service was done to London or elsewhere. | C29: 1.51 | D29: 1 | E29: 10 | F29: 3 | H29: 0 | I29: 0 | J29: 0 | K29: 0 | L29: 0 | M29: 0 | N29: 0
... A79: Annual recognizance | B79: Total, 3 shilling 3pence | C79: 0.16 | D79: 0 | E79: 3 | F79: 3 | H79: 0 | I79: 0 | J79: 0 | K79: 0 | L79: 0 | M79: 0 | N79: 0
A80: Corn and malt mill' | B80: The same render account for £2 19 shilling 11pence from 23 quarters 5 bushels of corn from the whole issue of the mill sold, at 3 shilling a quarters for 8 quarters, 2 shilling 8pence a quarters for 7 quarters, and 2 shilling a quarters for 8 quarters 5 bushels. | C80: 3 | D80: 2 | E80: 19 | F80: 11 | H80: 23 | I80: 5 | J80: 23.625 | K80: 23.625 | L80: 0 | M80: 23 | N80: 5 | O80: 8 | P80: 0 | Q80: 7 | R80: 0 | S80: 8 | T80: 5 | U80: 3 | V80: 0 | W80: 2 | X80: 8 | Y80: 2 | Z80: 0
A81: Corn and malt mill' | B81: 10 shilling 4pence from 3 quarters 5 bushels of malfsold, at 3 shilling a quarters for 2 quarters, and 2 shilling 8pence a quarters for 1 quarters 5 bushels Total, £3 10 shilling 3pence | C81: 3.51 | D81: 3 | E81: 10 | F81: 3 | H81: 3 | I81: 5 | J81: 3.625 | K81: 3.625 | L81: 0 | M81: 3 | N81: 5 | O81: 2 | P81: 0 | Q81: 1 | R81: 5 | U81: 3 | V81: 0 | W81: 2 | X81: 8
A82: Wheat, barley, oats and beans sold | B82: The same render account for £41 14 shilling from 168 quarters of wheat sold, at 5 shilling a quarters for 162 quarters, and 4 shilling a quarters for 6 quarters. | C82: 41.7 | D82: 41 | E82: 14 | F82: 0 | G82: wheat | H82: 168 | I82: 0 | J82: 168 | K82: 168 | L82: 0 | M82: 168 | N82: 0 | O82: 162 | P82: 0 | Q82: 6 | R82: 0 | U82: 5 | V82: 0 | W82: 4 | X82: 0
A83: Wheat, barley, oats and beans sold | B83: £2 2 shilling 3pence from 9 quarters 6 bushels of wheat sold for the queen's use, at 4 shilling 4pence a quarters. | C83: 2.11 | D83: 2 | E83: 2 | F83: 3 | G83: wheat | H83: 9 | I83: 6 | J83: 9.75 | K83: 9.75 | L83: 0 | M83: 9 | N83: 6 | U83: 4 | V83: 4
A84: Wheat, barley, oats and beans sold | B84: £1 13 shilling 4pence from 10 quarters of barley sold, at 3 shilling 4pence a quarters. | C84: 1.67 | D84: 1 | E84: 13 | F84: 4 | G84: barley | H84: 10 | I84: 0 | J84: 10 | K84: 10 | L84: 0 | M84: 10 | N84: 0 | U84: 3 | V84: 4
A85: Wheat, barley, oats and beans sold | B85: £5 1 shilling from 60.5 quarters of oats from the demesne sold, at 2 shilling a quarters for 20.5 quarters, and 1 shilling 6pence a quarters for 40 quarters. | C85: 5.05 | D85: 5 | E85: 1 | F85: 0 | G85: oats | H85: 60.5 | I85: 0 | J85: 60.5 | K85: 60.5 | L85: 0 | M85: 60.5 | N85: 0 | O85: 20.5 | P85: 0 | Q85: 40 | R85: 0 | U85: 2 | V85: 0 | W85: 1 | X85: 6
A86: Wheat, barley, oats and beans sold | B86: £3 18 shilling 9pence from 39 quarters 3 bushels of oats from the vill sold according to custom, at 2 shilling a quarters. | C86: 3.94 | D86: 3 | E86: 18 | F86: 9 | G86: oats | H86: 39 | I86: 3 | J86: 39.375 | K86: 39.375 | L86: 0 | M86: 39 | N86: 3 | U86: 2 | V86: 0
A87: Wheat, barley, oats and beans sold | B87: 12 shilling 3pence from 6 quarters 1 bushels of beans sold, at 2 shilling a quarters. | C87: 0.61 | D87: 0 | E87: 12 | F87: 3 | G87: beans | H87: 6 | I87: 1 | J87: 6.125 | K87: 6.125 | L87: 0 | M87: 6 | N87: 1 | U87: 2 | V87: 0
A88: Wheat, barley, oats and beans sold | B88: 1 shilling 5.5pence from 3.5 bushels of barley sold at the audit, at 5pence a bushels Total of all corn sold, £55 3 shilling 0.5pence | C88: 55.15 | D88: 55 | E88: 3 | F88: 0.5 | G88: barley | H88: 0 | I88: 3.5 | J88: 0.4375 | K88: 0.4375 | L88: 0 | M88: 0 | N88: 3.5 | AC88: 0 | AD88: 5
A89: Entry and marriage fines | B89: The same render account for 2 shilling from Geoffrey atte Slade for marrying Matilda his daughter outside. | C89: 0.1 | D89: 0 | E89: 2 | F89: 0 | H89: 0 | I89: 0 | J89: 0 | K89: 0 | L89: 0 | M89: 0 | N89: 0
...

Sheet Issues of the Grange raw
A1: Heading | B1: Sentence | C1: Quarters 1_x | D1: Bushels 1_x | E1: Sown Quarters | F1: Sown Bushels | G1: Sown Total Quarters | H1: Bought in Quarters | I1: Bought in Bushels | J1: Bought in Total Quarters | K1: Tithe Quarters | L1: Tithe Bushels | M1: Tithe Total Quarters | N1: Manorial servants & livestock Quarters | O1: Manorial servants & livestock Bushels | P1: Manorial servants & livestock Total Quarters | Q1: Sold Quarters | R1: Sold Bushels | S1: Sold Total Quarters | T1: Account Quarters | U1: Account Bushels | V1: Account Total Quarters | W1: bought only | X1: Total Quarters Except 1 | Y1: Total Bushels Except 1 | Z1: Total Corn Cross-Check | AA1: Total Corn Manorial Account | AB1: Corn Quantity Error | AC1: Quarters 1_y | AD1: Bushels 1_y | AE1: Quarters 2 | AF1: Bushels 2 | AG1: Quarters 3 | AH1: Bushels 3 | AI1: Quarters 4 | AJ1: Bushels 4
A2: Cash deliveries | B2: Total | C2: 0 | D2: 0 | E2: 0 | F2: 0 | G2: 0 | H2: 0 | I2: 0 | J2: 0 | K2: 0 | L2: 0 | M2: 0 | N2: 0 | O2: 0 | P2: 0 | Q2: 0 | R2: 0 | S2: 0 | T2: 0 | U2: 0 | V2: 0 | W2: 0
A3: Wheat | B3: (yield: 5-fold less . . . quarters 2 bushels} | C3: 0 | D3: 0 | E3: 0 | F3: 0 | G3: 0 | H3: 0 | I3: 0 | J3: 0 | K3: 0 | L3: 0 | M3: 0 | N3: 0 | O3: 0 | P3: 0 | Q3: 0 | R3: 0 | S3: 0 | T3: 0 | U3: 0 | V3: 0 | W3: 0 | X3: 0 | Y3: 2 | Z3: 0.25 | AA3: 0.25 | AB3: 0 | AC3: 0 | AD3: 2
A4: Wheat | B4: The same render account for 201 quarters 5 bushels of wheat from the whole issue of the grange in the granary by struck measure. | C4: 0 | D4: 0 | E4: 0 | F4: 0 | G4: 0 | H4: 0 | I4: 0 | J4: 0 | K4: 0 | L4: 0 | M4: 0 | N4: 0 | O4: 0 | P4: 0 | Q4: 0 | R4: 0 | S4: 0 | T4: 201 | U4: 5 | V4: 201.625 | W4: 0 | X4: 201 | Y4: 5 | Z4: 201.625 | AA4: 201.625 | AB4: 0 | AC4: 201 | AD4: 5
A5: Wheat | B5: 6.5 quarters by estimation given to the manorial servants in acres as they lie in the field. | C5: 0 | D5: 0 | E5: 0 | F5: 0 | G5: 0 | H5: 0 | I5: 0 | J5: 0 | K5: 0 | L5: 0 | M5: 0 | N5: 0 | O5: 0 | P5: 0 | Q5: 0 | R5: 0 | S5: 0 | T5: 0 | U5: 0 | V5: 0 | W5: 0 | X5: 6.5 | Y5: 0 | Z5: 6.5 | AA5: 6.5 | AB5: 0 | AC5: 6.5 | AD5: 0
A6: Wheat | B6: 12 quarters 2 bushels bought. | C6: 0 | D6: 0 | E6: 0 | F6: 0 | G6: 0 | H6: 12 | I6: 2 | J6: 12.25 | K6: 0 | L6: 0 | M6: 0 | N6: 0 | O6: 0 | P6: 0 | Q6: 0 | R6: 0 | S6: 0 | T6: 0 | U6: 0 | V6: 0 | W6: 0 | X6: 12 | Y6: 2 | Z6: 12.25 | AA6: 12.25 | AB6: 0 | AC6: 12 | AD6: 2
A7: Wheat | B7: Total, 220 quarters 3 bushels Sown over 84 acres measured by the perch which lie in the middle field, 32 quarters 2 bushels. | C7: 0 | D7: 0 | E7: 252 | F7: 5 | G7: 252.625 | H7: 0 | I7: 0 | J7: 0 | K7: 0 | L7: 0 | M7: 0 | N7: 0 | O7: 0 | P7: 0 | Q7: 0 | R7: 0 | S7: 0 | T7: 0 | U7: 0 | V7: 0 | W7: 0 | X7: 32 | Y7: 2 | Z7: 32.25 | AA7: 220.375 | AB7: -188.125 | AC7: 220 | AD7: 3 | AE7: 32 | AF7: 2
A8: Wheat | B8: that 3 bushels an acre, plus 6 bushels in all, because the sowing season was showery and miry. | C8: 0 | D8: 0 | E8: 0 | F8: 0 | G8: 0 | H8: 0 | I8: 0 | J8: 0 | K8: 0 | L8: 0 | M8: 0 | N8: 0 | O8: 0 | P8: 0 | Q8: 0 | R8: 0 | S8: 0 | T8: 0 | U8: 0 | V8: 0 | W8: 0 | X8: 0 | Y8: 6 | Z8: 0.75 | AA8: 0.375 | AB8: 0.375 | AC8: 0 | AD8: 3 | AE8: 0 | AF8: 6
A9: Wheat | B9: and know that two roods were sown by workers with their own seepence. | C9: 0 | D9: 0 | E9: 0 | F9: 0 | G9: 0 | H9: 0 | I9: 0 | J9: 0 | K9: 0 | L9: 0 | M9: 0 | N9: 0 | O9: 0 | P9: 0 | Q9: 0 | R9: 0 | S9: 0 | T9: 0 | U9: 0 | V9: 0 | W9: 0 | X9: 0 | Y9: 0 | Z9: 0 | AA9: 0 | AB9: 0 | AC9: 0 | AD9: 0
A10: Wheat | B10: customary payment for the mowing of the meadows, 6 bushels. | C10: 0 | D10: 0 | E10: 0 | F10: 0 | G10: 0 | H10: 0 | I10: 0 | J10: 0 | K10: 0 | L10: 0 | M10: 0 | N10: 0 | O10: 0 | P10: 0 | Q10: 0 | R10: 0 | S10: 0 | T10: 0 | U10: 0 | V10: 0 | W10: 0 | X10: 0 | Y10: 6 | Z10: 0.75 | AA10: 0.75 | AB10: 0 | AC10: 0 | AD10: 6
A11: Wheat | B11: provision of the steward at the hundred-court of Martinmas, 3 bushels. | C11: 0 | D11: 0 | E11: 0 | F11: 0 | G11: 0 | H11: 0 | I11: 0 | J11: 0 | K11: 0 | L11: 0 | M11: 0 | N11: 0 | O11: 0 | P11: 0 | Q11: 0 | R11: 0 | S11: 0 | T11: 0 | U11: 0 | V11: 0 | W11: 0 | X11: 0 | Y11: 3 | Z11: 0.375 | AA11: 0.375 | AB11: 0 | AC11: 0 | AD11: 3
A12: Wheat | B12: provision of the same at the hundred-court of Hockday in bread, 3 bushels. | C12: 0 | D12: 0 | E12: 0 | F12: 0 | G12: 0 | H12: 0 | I12: 0 | J12: 0 | K12: 0 | L12: 0 | M12: 0 | N12: 0 | O12: 0 | P12: 0 | Q12: 0 | R12: 0 | S12: 0 | T12: 0 | U12: 0 | V12: 0 | W12: 0 | X12: 0 | Y12: 3 | Z12: 0.375 | AA12: 0.375 | AB12: 0 | AC12: 0 | AD12: 3
A13: Wheat | B13: provision of the bailiff from Michaelmas until the feast of St Thomas the Apostle (21 December) in bread, 1.5 quarters, because he took the rest at West Wycombe. | C13: 0 | D13: 0 | E13: 0 | F13: 0 | G13: 0 | H13: 0 | I13: 0 | J13: 0 | K13: 0 | L13: 0 | M13: 0 | N13: 0 | O13: 0 | P13: 0 | Q13: 0 | R13: 0 | S13: 0 | T13: 0 | U13: 0 | V13: 0 | W13: 0 | X13: 1.5 | Y13: 0 | Z13: 1.5 | AA13: 1.5 | AB13: 0 | AC13: 1.5 | AD13: 0
A14: Wheat | B14: Given to the manorial servants for their stipend by estimation in acres as they lie in the field, 6.5 quarters. | C14: 0 | D14: 0 | E14: 0 | F14: 0 | G14: 0 | H14: 0 | I14: 0 | J14: 0 | K14: 0 | L14: 0 | M14: 0 | N14: 0 | O14: 0 | P14: 0 | Q14: 0 | R14: 0 | S14: 0 | T14: 0 | U14: 0 | V14: 0 | W14: 0 | X14: 6.5 | Y14: 0 | Z14: 6.5 | AA14: 6.5 | AB14: 0 | AC14: 6.5 | AD14: 0
A15: Wheat | B15: that is, 2 quarters to 1 smith for the year, 4.5 quarters to 1 carter, 5 ploughmen, 1 miller, 1 cowherd and 1 shepherd for 0.5 year in summer. (Henceforth the manorial servants should be hired for money just like the [other] workers in the manor and the corn be reserved for the use of the lord). | C15: 0 | D15: 0 | E15: 0 | F15: 0 | G15: 0 | H15: 0 | I15: 0 | J15: 0 | K15: 0 | L15: 0 | M15: 0 | N15: 0 | O15: 0 | P15: 0 | Q15: 0 | R15: 0 | S15: 0 | T15: 0 | U15: 0 | V15: 0 | W15: 0 | X15: 4.5 | Y15: 0 | Z15: 4.5 | AA15: 2 | AB15: 2.5 | AC15: 2 | AD15: 0 | AE15: 4.5 | AF15: 0
A16: Wheat | B16: provision of the sheriff for his 1 visit about the feast of St Vincent (22 January) in bread, 3 bushels Given to a certain marshal purveying for the Lord Edward, son of the king, in preparation for the tournament at Dunstable, to have his favour, 0.5 qr of oats and hay. | C16: 0 | D16: 0 | E16: 0 | F16: 0 | G16: 0 | H16: 0 | I16: 0 | J16: 0 | K16: 0 | L16: 0 | M16: 0 | N16: 0 | O16: 0 | P16: 0 | Q16: 0 | R16: 0 | S16: 0 | T16: 0 | U16: 0 | V16: 0 | W16: 0
A17: Wheat | B17: Sold as noted above, 177 quarters 6 bushels | C17: 0 | D17: 0 | E17: 0 | F17: 0 | G17: 0 | H17: 0 | I17: 0 | J17: 0 | K17: 0 | L17: 0 | M17: 0 | N17: 0 | O17: 0 | P17: 0 | Q17: 177 | R17: 6 | S17: 177.75 | T17: 0 | U17: 0 | V17: 0 | W17: 0 | X17: 177 | Y17: 6 | Z17: 177.75 | AA17: 177.75 | AB17: 0 | AC17: 177 | AD17: 6
A18: Wheat | B18: Total | C18: 0 | D18: 0 | E18: 0 | F18: 0 | G18: 0 | H18: 0 | I18: 0 | J18: 0 | K18: 0 | L18: 0 | M18: 0 | N18: 0 | O18: 0 | P18: 0 | Q18: 0 | R18: 0 | S18: 0 | T18: 0 | U18: 0 | V18: 0 | W18: 0
A19: Curall | B19: The same render account for 10 quarters 3 bushels from the whole issue of curall, of the same wheat, from the grange in the granary by struck measure. | C19: 0 | D19: 0 | E19: 0 | F19: 0 | G19: 0 | H19: 0 | I19: 0 | J19: 0 | K19: 0 | L19: 0 | M19: 0 | N19: 0 | O19: 0 | P19: 0 | Q19: 0 | R19: 0 | S19: 0 | T19: 10 | U19: 3 | V19: 10.375 | W19: 0 | X19: 10 | Y19: 3 | Z19: 10.375 | AA19: 10.375 | AB19: 0 | AC19: 10 | AD19: 3
A20: Curall | B20: all mixed below with barley for the liveries of the manorial servants. | C20: 0 | D20: 0 | E20: 0 | F20: 0 | G20: 0 | H20: 0 | I20: 0 | J20: 0 | K20: 0 | L20: 0 | M20: 0 | N20: 0 | O20: 0 | P20: 0 | Q20: 0 | R20: 0 | S20: 0 | T20: 0 | U20: 0 | V20: 0 | W20: 0 | X20: 0 | Y20: 0 | Z20: 0 | AA20: 0 | AB20: 0 | AC20: 0 | AD20: 0
A21: Curall | B21: Total | C21: 0 | D21: 0 | E21: 0 | F21: 0 | G21: 0 | H21: 0 | I21: 0 | J21: 0 | K21: 0 | L21: 0 | M21: 0 | N21: 0 | O21: 0 | P21: 0 | Q21: 0 | R21: 0 | S21: 0 | T21: 0 | U21: 0 | V21: 0 | W21: 0
A22: Mancorn | B22: Nothing from mancorn this year because the white field (albus camp') is not sown. | C22: 0 | D22: 0 | E22: 0 | F22: 0 | G22: 0 | H22: 0 | I22: 0 | J22: 0 | K22: 0 | L22: 0 | M22: 0 | N22: 0 | O22: 0 | P22: 0 | Q22: 0 | R22: 0 | S22: 0 | T22: 0 | U22: 0 | V22: 0 | W22: 0 | X22: 0 | Y22: 0 | Z22: 0 | AA22: 0 | AB22: 0 | AC22: 0 | AD22: 0
A23: Mancorn | B23: Total | C23: 0 | D23: 0 | E23: 0 | F23: 0 | G23: 0 | H23: 0 | I23: 0 | J23: 0 | K23: 0 | L23: 0 | M23: 0 | N23: 0 | O23: 0 | P23: 0 | Q23: 0 | R23: 0 | S23: 0 | T23: 0 | U23: 0 | V23: 0 | W23: 0
A24: Barley | B24: (yield: 4-fold plus 1 qr 6 bushels) | C24: 0 | D24: 0 | E24: 0 | F24: 0 | G24: 0 | H24: 0 | I24: 0 | J24: 0 | K24: 0 | L24: 0 | M24: 0 | N24: 0 | O24: 0 | P24: 0 | Q24: 0 | R24: 0 | S24: 0 | T24: 0 | U24: 0 | V24: 0 | W24: 0
A25: Barley | B25: The same render account for 19 quarters 6 bushels from the whole issue of barley from the grange in the granary by struck measure. | C25: 0 | D25: 0 | E25: 0 | F25: 0 | G25: 0 | H25: 0 | I25: 0 | J25: 0 | K25: 0 | L25: 0 | M25: 0 | N25: 0 | O25: 0 | P25: 0 | Q25: 0 | R25: 0 | S25: 0 | T25: 19 | U25: 6 | V25: 19.75 | W25: 0 | X25: 19 | Y25: 6 | Z25: 19.75 | AA25: 19.75 | AB25: 0 | AC25: 19 | AD25: 6
A26: Barley | B26: 10 quarters 3 bushels of curall received above and mixed with that for the liveries of the manorial servants. | C26: 0 | D26: 0 | E26: 0 | F26: 0 | G26: 0 | H26: 0 | I26: 0 | J26: 0 | K26: 0 | L26: 0 | M26: 0 | N26: 10 | O26: 3 | P26: 10.375 | Q26: 0 | R26: 0 | S26: 0 | T26: 0 | U26: 0 | V26: 0 | W26: 0 | X26: 10 | Y26: 3 | Z26: 10.375 | AA26: 10.375 | AB26: 0 | AC26: 10 | AD26: 3
A27: Barley | B27: 9 quarters 7 bushels of beans received below and mixed with barley for the same. | C27: 0 | D27: 0 | E27: 0 | F27: 0 | G27: 0 | H27: 0 | I27: 0 | J27: 0 | K27: 0 | L27: 0 | M27: 0 | N27: 0 | O27: 0 | P27: 0 | Q27: 0 | R27: 0 | S27: 0 | T27: 0 | U27: 0 | V27: 0 | W27: 0 | X27: 9 | Y27: 7 | Z27: 9.875 | AA27: 9.875 | AB27: 0 | AC27: 9 | AD27: 7
A28: Barley | B28: 34 quarters of maslin bought above and mixed with that for the same. | C28: 0 | D28: 0 | E28: 0 | F28: 0 | G28: 0 | H28: 34 | I28: 0 | J28: 34 | K28: 0 | L28: 0 | M28: 0 | N28: 0 | O28: 0 | P28: 0 | Q28: 0 | R28: 0 | S28: 0 | T28: 0 | U28: 0 | V28: 0 | W28: 0 | X28: 34 | Y28: 0 | Z28: 34 | AA28: 34 | AB28: 0 | AC28: 34 | AD28: 0
A29: Barley | B29: Total, 74 quarters. | C29: 0 | D29: 0 | E29: 0 | F29: 0 | G29: 0 | H29: 0 | I29: 0 | J29: 0 | K29: 0 | L29: 0 | M29: 0 | N29: 0 | O29: 0 | P29: 0 | Q29: 0 | R29: 0 | S29: 0 | T29: 0 | U29: 0 | V29: 0 | W29: 0 | X29: 74 | Y29: 0 | Z29: 74 | AA29: 74 | AB29: 0 | AC29: 74 | AD29: 0
A30: Barley | B30: Sown over 8.5 acres and 1 rood measured by the perch which lie above Benam, 4 quarters 3 bushels. | C30: 0 | D30: 0 | E30: 4 | F30: 3 | G30: 4.375 | H30: 0 | I30: 0 | J30: 0 | K30: 0 | L30: 0 | M30: 0 | N30: 0 | O30: 0 | P30: 0 | Q30: 0 | R30: 0 | S30: 0 | T30: 0 | U30: 0 | V30: 0 | W30: 0 | X30: 4 | Y30: 3 | Z30: 4.375 | AA30: 4.375 | AB30: 0 | AC30: 4 | AD30: 3
A31: Barley | B31: that is, .5 qr an acre. | C31: 0 | D31: 0 | E31: 0 | F31: 0 | G31: 0 | H31: 0 | I31: 0 | J31: 0 | K31: 0 | L31: 0 | M31: 0 | N31: 0 | O31: 0 | P31: 0 | Q31: 0 | R31: 0 | S31: 0 | T31: 0 | U31: 0 | V31: 0 | W31: 0
A32: Barley | B32: Delivered to 1 carter, 5 ploughmen, who each take a quarter every 8 weeks for the year, 39 quarters. | C32: 0 | D32: 0 | E32: 0 | F32: 0 | G32: 0 | H32: 0 | I32: 0 | J32: 0 | K32: 0 | L32: 0 | M32: 0 | N32: 0 | O32: 0 | P32: 0 | Q32: 0 | R32: 0 | S32: 0 | T32: 0 | U32: 0 | V32: 0 | W32: 0 | X32: 39 | Y32: 0 | Z32: 39 | AA32: 39 | AB32: 0 | AC32: 39 | AD32: 0
A33: Barley | B33: Delivered to 1 miller, 1 shepherd, 1 cowherd and 1 dairymaid, who each take a quarter every 10 weeks for the year, except the dairymaid who takes one every 12 weeks, 18 quarters 6.5 bushels, because there was no dairymaid for 13 weeks for a want of milking. | C33: 0 | D33: 0 | E33: 0 | F33: 0 | G33: 0 | H33: 0 | I33: 0 | J33: 0 | K33: 0 | L33: 0 | M33: 0 | N33: 0 | O33: 0 | P33: 0 | Q33: 0 | R33: 0 | S33: 0 | T33: 0 | U33: 0 | V33: 0 | W33: 0 | X33: 18 | Y33: 6.5 | Z33: 18.8125 | AA33: 18.8125 | AB33: 0 | AC33: 18 | AD33: 6.5
A34: Barley | B34: Delivered to 1 keeper of lambs for the time of their weaning, that is, from Wednesday the feast of St Mark the Evangelist (25 April) until Wedenesday before the feast of St Barnabas the Apostle (6 June), for 6 weeks, 3 bushels. | C34: 0 | D34: 0 | E34: 0 | F34: 0 | G34: 0 | H34: 0 | I34: 0 | J34: 0 | K34: 0 | L34: 0 | M34: 0 | N34: 0 | O34: 0 | P34: 0 | Q34: 0 | R34: 0 | S34: 0 | T34: 0 | U34: 0 | V34: 0 | W34: 0 | X34: 0 | Y34: 3 | Z34: 0.375 | AA34: 0.375 | AB34: 0 | AC34: 0 | AD34: 3
A35: Barley | B35: supporting pigs and piglets in winter, 1 qr. | C35: 0 | D35: 0 | E35: 0 | F35: 0 | G35: 0 | H35: 0 | I35: 0 | J35: 0 | K35: 0 | L35: 0 | M35: 0 | N35: 0 | O35: 0 | P35: 0 | Q35: 0 | R35: 0 | S35: 0 | T35: 0 | U35: 0 | V35: 0 | W35: 0
A36: Barley | B36: Sold as noted above, 10 quarters. | C36: 0 | D36: 0 | E36: 0 | F36: 0 | G36: 0 | H36: 0 | I36: 0 | J36: 0 | K36: 0 | L36: 0 | M36: 0 | N36: 0 | O36: 0 | P36: 0 | Q36: 10 | R36: 0 | S36: 10 | T36: 0 | U36: 0 | V36: 0 | W36: 0 | X36: 10 | Y36: 0 | Z36: 10 | AA36: 10 | AB36: 0 | AC36: 10 | AD36: 0
A37: Barley | B37: Sold at the audit, 3.5 bushels | C37: 0 | D37: 0 | E37: 0 | F37: 0 | G37: 0 | H37: 0 | I37: 0 | J37: 0 | K37: 0 | L37: 0 | M37: 0 | N37: 0 | O37: 0 | P37: 0 | Q37: 0 | R37: 0 | S37: 0 | T37: 0 | U37: 0 | V37: 0 | W37: 0 | X37: 0 | Y37: 3.5 | Z37: 0.4375 | AA37: 0.4375 | AB37: 0 | AC37: 0 | AD37: 3.5
A38: Barley | B38: Total | C38: 0 | D38: 0 | E38: 0 | F38: 0 | G38: 0 | H38: 0 | I38: 0 | J38: 0 | K38: 0 | L38: 0 | M38: 0 | N38: 0 | O38: 0 | P38: 0 | Q38: 0 | R38: 0 | S38: 0 | T38: 0 | U38: 0 | V38: 0 | W38: 0
A39: Beans | B39: {yield: six-fold plus 1 bushels} | C39: 0 | D39: 0 | E39: 0 | F39: 0 | G39: 0 | H39: 0 | I39: 0 | J39: 0 | K39: 0 | L39: 0 | M39: 0 | N39: 0 | O39: 0 | P39: 0 | Q39: 0 | R39: 0 | S39: 0 | T39: 0 | U39: 0 | V39: 0 | W39: 0 | X39: 0 | Y39: 1 | Z39: 0.125 | AA39: 0.125 | AB39: 0 | AC39: 0 | AD39: 1
A40: Beans | B40: The same render account for 20 quarters 1 bushels from the whole issue of beans from the grange in the granary by struck measure. | C40: 0 | D40: 0 | E40: 0 | F40: 0 | G40: 0 | H40: 0 | I40: 0 | J40: 0 | K40: 0 | L40: 0 | M40: 0 | N40: 0 | O40: 0 | P40: 0 | Q40: 0 | R40: 0 | S40: 0 | T40: 20 | U40: 1 | V40: 20.125 | W40: 0 | X40: 20 | Y40: 1 | Z40: 20.125 | AA40: 20.125 | AB40: 0 | AC40: 20 | AD40: 1
...

Sheet Sale of Corn Prices
A1: Heading | B1: Sentence | C1: Total in Pounds | D1: Pounds | E1: Shillings | F1: Pence | G1: Corn | H1: Total Quarters Except 1 | I1: Total Bushels Except 1 | J1: Total Corn Cross-Check | K1: Total Corn Manorial Account | L1: Corn Quantity Error | M1: Quarters 0 | N1: Bushels 0 | O1: shilling a quarter 1 | P1: pence a quarter 1 | Q1: Quarters 1 | R1: Bushels 1 | S1: shilling a quarter 2 | T1: pence a quarter 2 | U1: Quarters 2 | V1: Bushels 2 | W1: shilling a quarter 3 | X1: pence a quarter 3 | Y1: Quarters 3 | Z1: Bushels 3 | AA1: shilling a quarter 4 | AB1: pence a quarter 4 | AC1: £ a quarter 1 | AD1: £ a quarter 2 | AE1: £ a quarter 3 | AF1: £ a quarter 4 | AG1: Quarters Sold | AH1: Weighted Average Price per Quarter | AI1: Non-Weighted Average Price per Quarter | AJ1: Corn lowercase
