Workbook

Sheet Merdon 1301 Overview - Completed
A1: MERDON 1301 OVERVIEW - COMPLETED | B1: Total in £ | C1: Error | D1: Note
A2: CASH ACCOUNT
A3: RECEIPTS
A4: Arrears total | B4: 40.36875
A5: Rents of assize total | B5: 38.876042
A6: Quittances total | B6: 1.875
A7: Defaults of rent total | B7: 0.275
A8: Defaults of rent through the pestilence total
A9: Cotlands defaults total
A10: Cotlands total
A11: Total of quittances and defaults of rent total
A12: Total of rents remaining clear total
A13: Farms total
A14: Annual recognizances total | B14: 0.1125
A15: Issues of the Manor total | B15: 40.347917
A16: Issues of the tenements in the lord's hands total
A17: Sale of labour services total
A18: Sale of corn total | B18: 104.03333
A19: Entry and marriage fines total | B19: 6.9666667
A20: Pleas & perquisites total | B20: 6.4416667
A21: Forfeited chattels total
A22: Farm of the demesne land total
A23: Total of all receipts (calculated here) | B23: =SUM(B5:B22)
A24: Total of all receipts (calculated here) incl arrears | B24: =SUM(B4:B22)
A25: Total recorded in the accounts excl. arrears | C25: =B23-B25
A26: Total recorded in the accounts incl. arrears | B26: =B25+B4
A29: EXPENSES
A30: Cost of ploughs total | B30: 9.6083333
A31: Purchase of corn total | B31: 12.042708
A32: Cost of carts and wagons total | B32: 1.8583333
A33: Cost of dairy total | B33: 10.972917
A34: Purchase of stock total
A35: Sheepcote total
A36: Cost of buildings total | B36: 0.93333333
A37: Threshing total | B37: 0.83958333
A38: Barley expenses
A39: Expenses of the harvest total | B39: 0.775
A40: Necessary expenses
A41: Wages of the bailiff
A42: Steward's expenses total
...

Sheet Issues of the Mills
A1: No mill account for Adderbury

Sheet raw data
A1: Heading | B1: Sentence | C1: Total in Pounds | D1: Pounds | E1: Shillings | F1: Pence | G1: Corn | H1: Total Quarters Except 1 | I1: Total Bushels Except 1 | J1: Total Corn Cross-Check | K1: Total Corn Manorial Account | L1: Corn Quantity Error | M1: Quarters 1 | N1: Bushels 1 | O1: shilling a quarter 1 | P1: pence a quarter 1 | Q1: shilling a quarter 2 | R1: pence a quarter 2 | S1: shilling a quarter 3 | T1: pence a quarter 3 | U1: shilling a quarter 4 | V1: pence a quarter 4 | W1: shilling a bushel 1 | X1: pence a bushel 1 | Y1: shilling a bushel 2 | Z1: pence a bushel 2 | AA1: shilling a bushel 3 | AB1: pence a bushel 3 | AC1: shilling a bushel 4 | AD1: pence a bushel 4
A2: Adderbury | B2: The account2 of William Jakeman, reeve there, for the sixth year of the translation of Henry Beaufort', lord bishop of Winchester, and the eleventh year of the reign of King Henry the Fourth. | C2: 0 | D2: 0 | E2: 0 | F2: 0 | H2: 0 | I2: 0 | J2: 0 | K2: 0 | L2: 0 | M2: 0 | N2: 0
A3: Arrears | B3: None. | C3: 0 | D3: 0 | E3: 0 | F3: 0 | H3: 0 | I3: 0 | J3: 0 | K3: 0 | L3: 0 | M3: 0 | N3: 0
A4: Rents of assize | B4: And for £6 9 shilling 6.25pence for all rents of assize at St Thomas the Apostle (21 December). | C4: 6.48 | D4: 6 | E4: 9 | F4: 6.25 | H4: 0 | I4: 0 | J4: 0 | K4: 0 | L4: 0 | M4: 0 | N4: 0
A5: Rents of assize | B5: £6 9 shilling 8.5pence at Easter (23 March). | C5: 6.49 | D5: 6 | E5: 9 | F5: 8.5 | H5: 0 | I5: 0 | J5: 0 | K5: 0 | L5: 0 | M5: 0 | N5: 0
A6: Rents of assize | B6: £6 9 shilling 6.25pence at the Nativity of St John the Baptist (24 June). | C6: 6.48 | D6: 6 | E6: 9 | F6: 6.25 | H6: 0 | I6: 0 | J6: 0 | K6: 0 | L6: 0 | M6: 0 | N6: 0
A7: Rents of assize | B7: £6 10 shilling 1.5pence at Michaelmas (29 September). | C7: 6.51 | D7: 6 | E7: 10 | F7: 1.5 | H7: 0 | I7: 0 | J7: 0 | K7: 0 | L7: 0 | M7: 0 | N7: 0
A8: Rents of assize | B8: Total, £25 18 shilling 10.5pence. | C8: 25.94 | D8: 25 | E8: 18 | F8: 10.5 | H8: 0 | I8: 0 | J8: 0 | K8: 0 | L8: 0 | M8: 0 | N8: 0
A9: Quittances of rent | B9: In quittance of rent of 1 reeve for the year 5 shilling. | C9: 0.25 | D9: 0 | E9: 5 | F9: 0 | H9: 0 | I9: 0 | J9: 0 | K9: 0 | L9: 0 | M9: 0 | N9: 0
A10: Quittances of rent | B10: nothing this year of the 4 shilling for 1 smith forging the ironwork of 2 ploughs for the year. | C10: 0.2 | D10: 0 | E10: 4 | F10: 0 | H10: 0 | I10: 0 | J10: 0 | K10: 0 | L10: 0 | M10: 0 | N10: 0
A11: Quittances of rent | B11: nothing this year of the 4 shilling for 1 shepherd keeping the lord's wethers for the year. | C11: 0.2 | D11: 0 | E11: 4 | F11: 0 | H11: 0 | I11: 0 | J11: 0 | K11: 0 | L11: 0 | M11: 0 | N11: 0
A12: Quittances of rent | B12: nothing this year of the 4 shilling for 1 swineherd for the year. | C12: 0.2 | D12: 0 | E12: 4 | F12: 0 | H12: 0 | I12: 0 | J12: 0 | K12: 0 | L12: 0 | M12: 0 | N12: 0
A13: Quittances of rent | B13: nothing this year of the 4 shilling for 1 cowherd for the year. | C13: 0.2 | D13: 0 | E13: 4 | F13: 0 | H13: 0 | I13: 0 | J13: 0 | K13: 0 | L13: 0 | M13: 0 | N13: 0
... A149: Cost of buildings | B149: board-nails and clout-nails bought for the same 1 shilling 4pence. | C149: 0.07 | D149: 0 | E149: 1 | F149: 4 | H149: 0 | I149: 0 | J149: 0 | K149: 0 | L149: 0 | M149: 0 | N149: 0
A150: Cost of buildings | B150: 4 quarters 4 bushels of limestone bought at Walton' 5 shilling 3pence, at 1 shilling 2pence a quarters. | C150: 0.26 | D150: 0 | E150: 5 | F150: 3 | H150: 4 | I150: 4 | J150: 4.5 | K150: 4.5 | L150: 0 | M150: 4 | N150: 4 | O150: 1 | P150: 2
A151: Cost of buildings | B151: carrying the same 4pence. | C151: 0.02 | D151: 0 | E151: 0 | F151: 4 | H151: 0 | I151: 0 | J151: 0 | K151: 0 | L151: 0 | M151: 0 | N151: 0
A152: Cost of buildings | B152: 8 quarters of limestone bought at Witney 10 shilling 4pence, at 1 shilling 31 pence a quarters. | C152: 0.52 | D152: 0 | E152: 10 | F152: 4 | H152: 8 | I152: 0 | J152: 8 | K152: 8 | L152: 0 | M152: 8 | N152: 0 | O152: 1 | P152: 31
A153: Cost of buildings | B153: carrying the same from Witney to Adderbury 3 shilling 8pence. | C153: 0.18 | D153: 0 | E153: 3 | F153: 8 | H153: 0 | I153: 0 | J153: 0 | K153: 0 | L153: 0 | M153: 0 | N153: 0
A154: Cost of buildings | B154: 1,500 stone slates bought 6 shilling, at 4 shilling a 1,000.. | C154: 0.3 | D154: 0 | E154: 6 | F154: 0 | H154: 0 | I154: 0 | J154: 0 | K154: 0 | L154: 0 | M154: 0 | N154: 0
A155: Cost of buildings | B155: 500 eaves-stones bought 2 shilling 6pence, at 6pence a 100.. | C155: 0.12 | D155: 0 | E155: 2 | F155: 6 | H155: 0 | I155: 0 | J155: 0 | K155: 0 | L155: 0 | M155: 0 | N155: 0
A156: Cost of buildings | B156: 6,000 pins bought 2 shilling, at 4pence a 1,000.. | C156: 0.12 | D156: 0 | E156: 2 | F156: 4 | H156: 0 | I156: 0 | J156: 0 | K156: 0 | L156: 0 | M156: 0 | N156: 0
A157: Cost of buildings | B157: 50 ridge-tiles bought 6 shilling 3pence, at 1.5pence each. | C157: 0.31 | D157: 0 | E157: 6 | F157: 3 | H157: 0 | I157: 0 | J157: 0 | K157: 0 | L157: 0 | M157: 0 | N157: 0
A158: Cost of buildings | B158: sand bought and dug and quarried at Tadmarton 10pence. | C158: 0.04 | D158: 0 | E158: 0 | F158: 10 | H158: 0 | I158: 0 | J158: 0 | K158: 0 | L158: 0 | M158: 0 | N158: 0
A159: Cost of buildings | B159: stipend of 1 man going to Walton' to quarry lime there 2pence. | C159: 0.01 | D159: 0 | E159: 0 | F159: 2 | H159: 0 | I159: 0 | J159: 0 | K159: 0 | L159: 0 | M159: 0 | N159: 0
A160: Cost of buildings | B160: expenses of 12 men coming for a boon-work with 6 carts to quarry sand at Newotele and carry it to Adderbury, with the digging, 2 shilling 3pence. | C160: 0.11 | D160: 0 | E160: 2 | F160: 3 | H160: 0 | I160: 0 | J160: 0 | K160: 0 | L160: 0 | M160: 0 | N160: 0
A161: Cost of buildings | B161: hiring 1 man to carry sand and lime from the warrener's chamber to the barn by piece-work 4pence. | C161: 0.02 | D161: 0 | E161: 0 | F161: 4 | H161: 0 | I161: 0 | J161: 0 | K161: 0 | L161: 0 | M161: 0 | N161: 0
A162: Cost of buildings | B162: carrying the ridge-tiles bought above 8pence. | C162: 0.03 | D162: 0 | E162: 0 | F162: 8 | H162: 0 | I162: 0 | J162: 0 | K162: 0 | L162: 0 | M162: 0 | N162: 0
A163: Cost of buildings | B163: expenses of various men coming for a boon-work to buy slates at Aynho and carry them to Adderbury with the expenses of 1 man there mending the said slates 2d 1 shilling 9.5pence. | C163: 0.09 | D163: 0 | E163: 1 | F163: 9.5 | H163: 0 | I163: 0 | J163: 0 | K163: 0 | L163: 0 | M163: 0 | N163: 0
A164: Cost of buildings | B164: 1 tine bought 8pence. | C164: 0.03 | D164: 0 | E164: 0 | F164: 8 | H164: 0 | I164: 0 | J164: 0 | K164: 0 | L164: 0 | M164: 0 | N164: 0
... A181: Total of all allowances | B181: Total of all allowances and cash deliveries, £64 19 shilling 11.5pence He is quit. | C181: 65 | D181: 64 | E181: 19 | F181: 11.5 | H181: 0 | I181: 0 | J181: 0 | K181: 0 | L181: 0 | M181: 0 | N181: 0
A182: Wheat | B182: William Jakeman, reeve there, answers for 3 quarters of wheat remaining.. | C182: 0 | D182: 0 | E182: 0 | F182: 0 | G182: wheat | H182: 3 | I182: 0 | J182: 3 | K182: 3 | L182: 0 | M182: 3 | N182: 0
A183: Wheat | B183: Total, 3 quarters.. | C183: 0 | D183: 0 | E183: 0 | F183: 0 | H183: 3 | I183: 0 | J183: 3 | K183: 3 | L183: 0 | M183: 3 | N183: 0
A184: Wheat | B184: 3 quarters remain in the keeping of John Eadburbury, farmer there, to be handed back and restored at the end of his farm of 12 years, this year being the fifth. | C184: 0 | D184: 0 | E184: 0 | F184: 0 | H184: 3 | I184: 0 | J184: 3 | K184: 3 | L184: 0 | M184: 3 | N184: 0
A185: Rye | B185: And for 34 quarters of rye remaining.. | C185: 0 | D185: 0 | E185: 0 | F185: 0 | G185: rye | H185: 34 | I185: 0 | J185: 34 | K185: 34 | L185: 0 | M185: 34 | N185: 0
A186: Rye | B186: Total, 34 quarters.. | C186: 0 | D186: 0 | E186: 0 | F186: 0 | H186: 34 | I186: 0 | J186: 34 | K186: 34 | L186: 0 | M186: 34 | N186: 0
A187: Rye | B187: 34 quarters remain in the keeping of the said John Eadburbury, farmer there, to be handed back and restored at the end of his farm as before. | C187: 0 | D187: 0 | E187: 0 | F187: 0 | H187: 34 | I187: 0 | J187: 34 | K187: 34 | L187: 0 | M187: 34 | N187: 0
A188: Dredge | B188: And for 30 quarters of dredge remaining.. | C188: 0 | D188: 0 | E188: 0 | F188: 0 | G188: dredge | H188: 30 | I188: 0 | J188: 30 | K188: 30 | L188: 0 | M188: 30 | N188: 0
A189: Dredge | B189: Total, 30 quarters.. | C189: 0 | D189: 0 | E189: 0 | F189: 0 | H189: 30 | I189: 0 | J189: 30 | K189: 30 | L189: 0 | M189: 30 | N189: 0
A190: Dredge | B190: 30 quarters remain in the keeping of the said John Eadburbury, farmer there, to be handed back and restored as before. | C190: 0 | D190: 0 | E190: 0 | F190: 0 | H190: 30 | I190: 0 | J190: 30 | K190: 30 | L190: 0 | M190: 30 | N190: 0
A191: Pulses | B191: None remain. | C191: 0 | D191: 0 | E191: 0 | F191: 0 | H191: 0 | I191: 0 | J191: 0 | K191: 0 | L191: 0 | M191: 0 | N191: 0
...

Sheet Prices
A1: Meat & Dairy Prices
C2: 1301 | D2: 1302 | E2: Average
A3: Beef | B3: £ per lb | C3: 0.0033351854 | D3: 0.0032608538 | E3: =AVERAGE(C3:D3)
A4: Mutton | B4: £ per lb | C4: 0.0036593977 | D4: 0.0037125513 | E4: =AVERAGE(C4:D4)
A5: Pork | B5: £ per lb | C5: 0.0038431326 | D5: 0.0037574803 | E5: =AVERAGE(C5:D5)
A6: Cheese | B6: £ per lb | C6: 0.0055768754 | D6: 0.0056654898 | E6: =AVERAGE(C6:D6)
A7: Butter | B7: £ per lb | C7: 0.0036626221 | D7: 0.0035935077 | E7: =AVERAGE(C7:D7)
A8: Milk | B8: £ per gallon | C8: 0.0055768754 | D8: 0.0056654898 | E8: =AVERAGE(C8:D8)

Sheet Labour Rents

Sheet Merdon Overview
A1: MERDON OVERVIEW | B1: £ | C1: s | D1: d | G1: Total in £ | H1: Error
A3: CASH ACCOUNT
A4: RECEIPTS
A5: Arrears total | G5: =IF(INDEX('Merdon Receipts'!$A$4:$F$131,MATCH('Merdon Overview'!$A5,'Merdon Receipts'!$A$4:$A$131,0),6)=0,"",INDEX('Merdon Receipts'!$A$4:$F$131,MATCH('Merdon Overview'!$A5,'Merdon Receipts'!$A$4:$A$131,0),6))
A6: Rents of assize total | G6: =IF(INDEX('Merdon Receipts'!$A$4:$F$131,MATCH('Merdon Overview'!$A6,'Merdon Receipts'!$A$4:$A$131,0),6)=0,"",INDEX('Merdon Receipts'!$A$4:$F$131,MATCH('Merdon Overview'!$A6,'Merdon Receipts'!$A$4:$A$131,0),6))
A7: Quittances total | G7: =IF(INDEX('Merdon Receipts'!$A$4:$F$131,MATCH('Merdon Overview'!$A7,'Merdon Receipts'!$A$4:$A$131,0),6)=0,"",INDEX('Merdon Receipts'!$A$4:$F$131,MATCH('Merdon Overview'!$A7,'Merdon Receipts'!$A$4:$A$131,0),6))
A8: Defaults of rent total | G8: =IF(INDEX('Merdon Receipts'!$A$4:$F$131,MATCH('Merdon Overview'!$A8,'Merdon Receipts'!$A$4:$A$131,0),6)=0,"",INDEX('Merdon Receipts'!$A$4:$F$131,MATCH('Merdon Overview'!$A8,'Merdon Receipts'!$A$4:$A$131,0),6))
A9: Total rents remaining | G9: ='Merdon Receipts'!F30
A10: Annual recognizances total | G10: =IF(INDEX('Merdon Receipts'!$A$4:$F$131,MATCH('Merdon Overview'!$A10,'Merdon Receipts'!$A$4:$A$131,0),6)=0,"",INDEX('Merdon Receipts'!$A$4:$F$131,MATCH('Merdon Overview'!$A10,'Merdon Receipts'!$A$4:$A$131,0),6))
A11: Issues of the Manor total | G11: =IF(INDEX('Merdon Receipts'!$A$4:$F$131,MATCH('Merdon Overview'!$A11,'Merdon Receipts'!$A$4:$A$131,0),6)=0,"",INDEX('Merdon Receipts'!$A$4:$F$131,MATCH('Merdon Overview'!$A11,'Merdon Receipts'!$A$4:$A$131,0),6))
A12: Sale of corn total | G12: =IF(INDEX('Merdon Receipts'!$A$4:$F$131,MATCH('Merdon Overview'!$A12,'Merdon Receipts'!$A$4:$A$131,0),6)=0,"",INDEX('Merdon Receipts'!$A$4:$F$131,MATCH('Merdon Overview'!$A12,'Merdon Receipts'!$A$4:$A$131,0),6))
A13: Entry and marriage fines total | G13: =IF(INDEX('Merdon Receipts'!$A$4:$F$131,MATCH('Merdon Overview'!$A13,'Merdon Receipts'!$A$4:$A$131,0),6)=0,"",INDEX('Merdon Receipts'!$A$4:$F$131,MATCH('Merdon Overview'!$A13,'Merdon Receipts'!$A$4:$A$131,0),6))
A14: Pleas & perquisites total | G14: =IF(INDEX('Merdon Receipts'!$A$4:$F$131,MATCH('Merdon Overview'!$A14,'Merdon Receipts'!$A$4:$A$131,0),6)=0,"",INDEX('Merdon Receipts'!$A$4:$F$131,MATCH('Merdon Overview'!$A14,'Merdon Receipts'!$A$4:$A$131,0),6))
A15: Sum of the above (incl. arrears) | G15: =G5+G9+G10+G11+G12+G13+G14
A16: Total recorded in the accounts excl. arrears | G16: ='Merdon Receipts'!F130 | H16: =G15-G16
A17: Total recorded in the accounts incl. arrears | G17: ='Merdon Receipts'!F131
A20: EXPENSES
A21: Cost of ploughs total | G21: =IF(INDEX('Merdon Expenses'!$A$2:$F$170,MATCH('Merdon Overview'!$A21,'Merdon Expenses'!$A$2:$A$170,0),6)=0,"",INDEX('Merdon Expenses'!$A$2:$F$170,MATCH('Merdon Overview'!$A21,'Merdon Expenses'!$A$2:$A$170,0),6))
A22: Purchase of corn total | G22: =IF(INDEX('Merdon Expenses'!$A$2:$F$170,MATCH('Merdon Overview'!$A22,'Merdon Expenses'!$A$2:$A$170,0),6)=0,"",INDEX('Merdon Expenses'!$A$2:$F$170,MATCH('Merdon Overview'!$A22,'Merdon Expenses'!$A$2:$A$170,0),6))
A23: Cost of carts and wagons total | G23: =IF(INDEX('Merdon Expenses'!$A$2:$F$170,MATCH('Merdon Overview'!$A23,'Merdon Expenses'!$A$2:$A$170,0),6)=0,"",INDEX('Merdon Expenses'!$A$2:$F$170,MATCH('Merdon Overview'!$A23,'Merdon Expenses'!$A$2:$A$170,0),6))
A24: Cost of dairy total | G24: =IF(INDEX('Merdon Expenses'!$A$2:$F$170,MATCH('Merdon Overview'!$A24,'Merdon Expenses'!$A$2:$A$170,0),6)=0,"",INDEX('Merdon Expenses'!$A$2:$F$170,MATCH('Merdon Overview'!$A24,'Merdon Expenses'!$A$2:$A$170,0),6))
A25: Weeding total | G25: =IF(INDEX('Merdon Expenses'!$A$2:$F$170,MATCH('Merdon Overview'!$A25,'Merdon Expenses'!$A$2:$A$170,0),6)=0,"",INDEX('Merdon Expenses'!$A$2:$F$170,MATCH('Merdon Overview'!$A25,'Merdon Expenses'!$A$2:$A$170,0),6))
A26: Provision of household servants at harvest-time total | G26: =IF(INDEX('Merdon Expenses'!$A$2:$F$170,MATCH('Merdon Overview'!$A26,'Merdon Expenses'!$A$2:$A$170,0),6)=0,"",INDEX('Merdon Expenses'!$A$2:$F$170,MATCH('Merdon Overview'!$A26,'Merdon Expenses'!$A$2:$A$170,0),6))
A27: Cost of buildings total | G27: =IF(INDEX('Merdon Expenses'!$A$2:$F$170,MATCH('Merdon Overview'!$A27,'Merdon Expenses'!$A$2:$A$170,0),6)=0,"",INDEX('Merdon Expenses'!$A$2:$F$170,MATCH('Merdon Overview'!$A27,'Merdon Expenses'!$A$2:$A$170,0),6))
A28: Threshing total | G28: =IF(INDEX('Merdon Expenses'!$A$2:$F$170,MATCH('Merdon Overview'!$A28,'Merdon Expenses'!$A$2:$A$170,0),6)=0,"",INDEX('Merdon Expenses'!$A$2:$F$170,MATCH('Merdon Overview'!$A28,'Merdon Expenses'!$A$2:$A$170,0),6))
A29: Expenses of the harvest total | G29: =IF(INDEX('Merdon Expenses'!$A$2:$F$170,MATCH('Merdon Overview'!$A29,'Merdon Expenses'!$A$2:$A$170,0),6)=0,"",INDEX('Merdon Expenses'!$A$2:$F$170,MATCH('Merdon Overview'!$A29,'Merdon Expenses'!$A$2:$A$170,0),6))
A30: Payments for building repairs total | G30: =IF(INDEX('Merdon Expenses'!$A$2:$F$170,MATCH('Merdon Overview'!$A30,'Merdon Expenses'!$A$2:$A$170,0),6)=0,"",INDEX('Merdon Expenses'!$A$2:$F$170,MATCH('Merdon Overview'!$A30,'Merdon Expenses'!$A$2:$A$170,0),6))
A31: Cost of the park total | G31: =IF(INDEX('Merdon Expenses'!$A$2:$F$170,MATCH('Merdon Overview'!$A31,'Merdon Expenses'!$A$2:$A$170,0),6)=0,"",INDEX('Merdon Expenses'!$A$2:$F$170,MATCH('Merdon Overview'!$A31,'Merdon Expenses'!$A$2:$A$170,0),6))
A32: Steward's expenses total | G32: =IF(INDEX('Merdon Expenses'!$A$2:$F$170,MATCH('Merdon Overview'!$A32,'Merdon Expenses'!$A$2:$A$170,0),6)=0,"",INDEX('Merdon Expenses'!$A$2:$F$170,MATCH('Merdon Overview'!$A32,'Merdon Expenses'!$A$2:$A$170,0),6))
A33: Sum of the above | G33: =SUM(G21:G32)
A34: Total of all expenses | G34: ='Merdon Expenses'!F165 | H34: =G33-G34
A35: Capital Expenses | G35: ='Merdon Expenses'!F170
A37: Owed by the reeve | G37: =G15-G5-G33
A38: From accounts | G38: ='Merdon Expenses'!F166 | H38: =G38-G37
A40: Cash deliveries | G40: ='Merdon Expenses'!F168
A41: Total of all allowances and cash deliveries in accounts | B41: n/a | G41: =SUM(G40)
A43: Net amount owed | G43: =G38-G40
A44: Net amount owed in accounts | G44: ='Merdon Expenses'!F169 | H44: =G44-G43
A46: GRANGE ACCOUNT | B46: Net Production
A47: Grange | B47: qrs | G47: Value of net output (£) | H47: Value of total gross production in £ | I47: Note: Columns indexed are hardcoded, do not alter number of columns in issues of grange
...

Sheet Merdon Receipts
A1: MERDON RECEIPTS
B2: £ | C2: s | D2: d | F2: Total in £ | G2: Error | H2: Notes
A4: Arrears
A5: Arrears total | B5: 40 | C5: 7 | D5: 4.5 | F5: =B5+C5/20+D5/240
A6: of which delivered to treasurer of Wolvesey | B6: 40 | C6: 7 | D6: 4.5 | F6: =B6+C6/20+D6/240
A8: Rents of assize
A9: at Easter | B9: 18 | C9: 18 | D9: 1.75 | F9: =B9+C9/20+D9/240
A10: at Michaelmas | B10: 19 | C10: 19 | D10: 4.5 | F10: =B10+C10/20+D10/240
A11: Total recorded in accounts | B11: 38 | C11: 17 | D11: 6.25 | F11: =B11+C11/20+D11/240
A12: Rents of assize total | B12: =SUM(B9:B10) | C12: =SUM(C9:C10) | D12: =SUM(D9:D10) | F12: =B12+C12/20+D12/240 | G12: =F12-F11
A14: Quittances
A15: 1 reeve and 1 beadle | C15: 5 | F15: =B15+C15/20+D15/240
A16: 1 hayward | C16: 1 | D16: 3 | F16: =B16+C16/20+D16/240
A17: 1 swineherd | C17: 2 | D17: 6 | F17: =B17+C17/20+D17/240
A18: 10 ploughmen | C18: 12 | D18: 6 | F18: =B18+C18/20+D18/240
A19: 12 workers for the year | C19: 15 | F19: =B19+C19/20+D19/240
A20: 1 keeper of wethers | C20: 1 | D20: 3 | F20: =B20+C20/20+D20/240
A21: Total recorded in accounts | B21: 1 | C21: 17 | D21: 6 | F21: =B21+C21/20+D21/240
A22: Quittances total | B22: =SUM(B15:B20) | C22: =SUM(C15:C20) | D22: =SUM(D15:D20) | F22: =B22+C22/20+D22/240 | G22: =F22-F21
A24: Defaults of rent
A25: of William de Cruce | C25: 5 | F25: =B25+C25/20+D25/240
A26: 1 plot in the vill of Hursley which William Faber formerly encroached and buit upon pulled down because it was a nuisance | D26: 6 | F26: =B26+C26/20+D26/240
A27: Total recorded in accounts | C27: 5 | D27: 6 | F27: =B27+C27/20+D27/240
A28: Defaults of rent total | B28: =SUM(B25:B26) | C28: =SUM(C25:C26) | D28: =SUM(D25:D26) | F28: =B28+C28/20+D28/240 | G28: =F28-F27
A30: Total of rents remaining | B30: 36 | C30: 14 | D30: 6.25 | F30: =B30+C30/20+D30/240
A32: Annual recognizances
A33: from Adam | D33: 6 | F33: =B33+C33/20+D33/240
A34: from William | D34: 6 | F34: =B34+C34/20+D34/240
A35: from Walter | D35: 6 | F35: =B35+C35/20+D35/240
A36: from Ralph | D36: 3 | F36: =B36+C36/20+D36/240
A37: from Nicholas | D37: 3 | F37: =B37+C37/20+D37/240
A38: from John | D38: 3 | F38: =B38+C38/20+D38/240
A39: Total recorded in accounts | C39: 2 | D39: 3 | F39: =B39+C39/20+D39/240
A40: Annual recognizances total | B40: =SUM(B33:B38) | C40: =SUM(C33:C38) | D40: =SUM(D33:D38) | F40: =B40+C40/20+D40/240 | G40: =F40-F39
A42: Issues of the manor
A43: from panage of pigs at Martinmas | B43: 3 | C43: 2 | F43: =B43+C43/20+D43/240
A44: from the whole hudnred of Merdon to have heath and lords will | C44: 7 | F44: =B44+C44/20+D44/240
A45: from the pasturage next to Bouyat' sold for 36 yearlings | C45: 10 | D45: 6 | F45: =B45+C45/20+D45/240
A46: from honey found in the wood and sold | B46: 1 | C46: 6 | F46: =B46+C46/20+D46/240
A47: from the pasturage sold of 6 horses and mares, 11 oxen and cows, and 16 bullocks | C47: 14 | D47: 10 | F47: =B47+C47/20+D47/240
...

Sheet Merdon Expenses
A1: MERDON EXPENSES
B2: £ | C2: s | D2: d | F2: Total in £ | G2: Error | H2: Notes
A3: Cost of Ploughs
A4: iron and steel for 6 ploughs | B4: 1 | C4: 1 | D4: 7 | F4: =B4+C4/20+D4/240
A5: in 3 ploughshares bought | C5: 2 | F5: =B5+C5/20+D5/240
A6: in 1 coulter mended with iron | D6: 3 | F6: =B6+C6/20+D6/240
A7: in 10 plough feet | C7: 3 | D7: 4 | F7: =B7+C7/20+D7/240
A8: in fitting ploughs with iron tyres | D8: 6 | F8: =B8+C8/20+D8/240
A9: in 4 pairs of wheels | C9: 1 | D9: 4 | F9: =B9+C9/20+D9/240
A10: in 3 new harrows made | D10: 6 | F10: =B10+C10/20+D10/240
A11: in shoeing 12 plough-horses for the year | C11: 6 | F11: =B11+C11/20+D11/240
A12: in 8 halters made | D12: 2 | F12: =B12+C12/20+D12/240
A13: in boon-works of 50 ploughmen | C13: 16 | D13: 8 | F13: =B13+C13/20+D13/240
A14: in boonworks of 9 ploughmen of slackstead | C14: 1 | D14: 1.5 | F14: =B14+C14/20+D14/240
A15: in boon-works of 2 free men ploughing 2 acres of land | D15: 3 | F15: =B15+C15/20+D15/240
A16: in stipend of 10 ploughmen for 221 Saturday ploughings | B16: 2 | C16: 2 | D16: 11.5 | F16: =B16+C16/20+D16/240
A17: in stipend of the smith making the ironwork | C17: 4 | D17: 4.75 | F17: =B17+C17/20+D17/240
A18: in stipend of 2 ploughmen for the year | C18: 6 | F18: =B18+C18/20+D18/240
A19: in 2 plough-horses bought | C19: 15 | F19: =B19+C19/20+D19/240
A20: in 5 oxen bought | B20: 2 | C20: 10 | D20: 1.25 | F20: =B20+C20/20+D20/240
A21: in forage bought from the parson of Hursley | B21: 1 | F21: =B21+C21/20+D21/240
A22: Total recorded in accounts | B22: 9 | C22: 12 | D22: 11 | F22: =B22+C22/20+D22/240
A23: Cost of ploughs total | B23: =SUM(B4:B21) | C23: =SUM(C4:C21) | D23: =SUM(D4:D21) | F23: =B23+C23/20+D23/240 | G23: =F23-F22
A24: Total capital expenses | B24: =SUM(B4:B12) | C24: =SUM(C4:C12) | D24: =SUM(D4:D12) | F24: =B24+C24/20+D24/240
A26: Purchase of Corn
A27: in 29 qrs 1 bus of wheat bought for sowing | B27: 8 | C27: 6 | D27: 10.25
A28: in 11 qrs of barley bought for sowing | B28: 2 | C28: 4
A29: in 15 qrs of oats bought for sowing | B29: 1 | C29: 10 | F29: =B29+C29/20+D29/240
A30: Total recorded in accounts | B30: 12 | D30: 10.25 | F30: =B30+C30/20+D30/240
A31: Purchase of corn total | B31: =SUM(B27:B29) | C31: =SUM(C27:C29) | D31: =SUM(D27:D29) | F31: =B31+C31/20+D31/240 | G31: =F31-F30
A33: Cost of Carts and Wagons
A34: in a pair of wheels bought | C34: 3 | D34: 1 | F34: =B34+C34/20+D34/240
A35: in 1 new binding bought and fitted | C35: 9 | D35: 11 | F35: =B35+C35/20+D35/240
A36: in fitting the cart with axles | D36: 10 | F36: =B36+C36/20+D36/240
A37: in clouts and nails and grease | C37: 2 | D37: 6 | F37: =B37+C37/20+D37/240
A38: in collar bought and and 1 pair of saddle pads | C38: 1 | D38: 2 | F38: =B38+C38/20+D38/240
A39: in 1 saddle bought | D39: 4 | F39: =B39+C39/20+D39/240
A40: in 1 cart rope | C40: 1 | D40: 4 | F40: =B40+C40/20+D40/240
A41: in 1 pair of traces | D41: 7 | F41: =B41+C41/20+D41/240
A42: in 1 pair of wheels for clearing dung | C42: 2 | F42: =B42+C42/20+D42/240
...

Sheet Issues of the Grange
B1: The issue of the grange account gives the total "yield" at the top of each heading in curly brackets, measurements used: fold, qrs, bus
B2: In "Issues of the grange" (p.xx) | G2: In "Sale of Corn" (p.x) | P2: Value of Total Production
A3: Gross output | B3: Quantity | D3: Additional bought-in | F3: Quantity | G3: Quantity noted as sold | J3: Difference Produced vs. Sold | K3: Price 1 | L3: Quantity 1 | M3: Price 2 | N3: Quantity 2 | O3: Unit price | P3: Value
B4: qrs | C4: bus | D4: qrs | E4: bus | F4: qrs | G4: qrs | H4: bus | I4: qrs | K4: £ | L4: qrs | M4: £ | N4: qrs | O4: £ per qr | P4: £
A5: Wheat | B5: 338.5 | D5: 29 | E5: 1 | F5: =B5+D5+C5/8+E5/8 | G5: 308 | H5: 3 | I5: =G5+H5/8 | J5: =F5-I5 | K5: ='Merdon Receipts'!F80 | L5: =I5 | O5: =IFERROR((K5+M5)/(L5+N5),0) | P5: =O5*F5
A6: Curall | B6: 19 | C6: 2 | F6: =B6+D6+C6/8+E6/8 | G6: 16 | H6: 5 | I6: =G6+H6/8 | J6: =F6-I6 | K6: ='Merdon Receipts'!F81 | L6: =I6 | O6: =IFERROR((K6+M6)/(L6+N6),0) | P6: =O6*F6
A7: Barley | B7: 61 | D7: 19 | E7: 1 | F7: =B7+D7+C7/8+E7/8 | G7: 9 | H7: 7 | I7: =G7+H7/8 | J7: =F7-I7 | K7: ='Merdon Receipts'!F82 | L7: =8+5/8 | M7: ='Merdon Receipts'!F87 | N7: =1+2/8 | O7: =IFERROR((K7+M7)/(L7+N7),0) | P7: =O7*F7
A8: Oats | B8: 290 | D8: 15 | F8: =B8+D8+C8/8+E8/8 | G8: 42 | I8: =G8+H8/8 | J8: =F8-I8 | K8: ='Merdon Receipts'!F83 | L8: =I8 | O8: =IFERROR((K8+M8)/(L8+N8),0) | P8: =O8*F8
A9: Beans | C9: 6 | F9: =B9+D9+C9/8+E9/8 | H9: 4 | I9: =G9+H9/8 | J9: =F9-I9 | K9: ='Merdon Receipts'!F84 | L9: =I9 | O9: =IFERROR((K9+M9)/(L9+N9),0) | P9: =O9*F9
A10: Peas | B10: 16 | C10: 5 | F10: =B10+D10+C10/8+E10/8 | G10: 12 | H10: 2 | I10: =G10+H10/8 | J10: =F10-I10 | K10: ='Merdon Receipts'!F85 | L10: =I10 | O10: =IFERROR((K10+M10)/(L10+N10),0) | P10: =O10*F10
A11: Vetches | B11: 22 | C11: 2 | F11: =B11+D11+C11/8+E11/8 | G11: 16 | H11: 7 | I11: =G11+H11/8 | J11: =F11-I11 | K11: ='Merdon Receipts'!F86 | L11: =I11 | O11: =IFERROR((K11+M11)/(L11+N11),0) | P11: =O11*F11
A13: Total Production | F13: =SUM(F5:F11) | P13: =SUM(P5:P11) | Q13: Production value is significantly more, as much less was sold than what was produced
A14: Sales of corn (as recorded in accounts) | F14: =SUM(I5:I11) | P14: =SUM(K5:K11,M5:M11)
A17: Net output | B17: Gross output | C17: Seed | F17: tithe | G17: to manorial servants & livestock | J17: Output net of tithe & seed & liveries to manorial servants | K17: in stock from last year | L17: Price | M17: Value of net output | N17: Value of sales (in "Sale of Corn")
B18: qrs | C18: qrs | D18: bus | E18: qrs | F18: qrs | G18: qrs | H18: bus | I18: qrs | J18: qrs | K18: qrs | L18: £ per qr | M18: £ | N18: £
A19: Net wheat | B19: =F5 | C19: 54.5 | E19: =C19+D19/8 | G19: 4 | H19: 6 | I19: =G19+H19/8 | J19: =B19-(E19+F19+I19) | L19: =O5 | M19: =L19*J19 | N19: =O5*I5
A20: Net curall | B20: =F6 | E20: =C20+D20/8 | G20: 2 | H20: 5 | I20: =G20+H20/8 | J20: =B20-(E20+F20+I20) | L20: =O6 | M20: =L20*J20 | N20: =O6*I6
A21: Net barley | B21: =F7 | C21: 18 | D21: 5 | E21: =C21+D21/8 | G21: =31.5+5+3+0.5+7 | H21: =1+2+6+2+6 | I21: =G21+H21/8 | J21: =B21-(E21+F21+I21) | L21: =O7 | M21: =L21*J21 | N21: =O7*I7 | P21: Think about how to get avoid getting negative value of output by accounting for bought in here
A22: Net oats | B22: =F8 | C22: 97 | D22: 5 | E22: =C22+D22/8 | G22: =28+9+26+2 | H22: =1+2 | I22: =G22+H22/8 | J22: =B22-(E22+F22+I22) | L22: =O8 | M22: =L22*J22 | N22: =O8*I8
A23: Net peas | B23: =F9 | E23: =C23+D23/8 | I23: =G23+H23/8 | J23: =B23-(E23+F23+I23) | L23: =O10 | M23: =L23*J23 | N23: =O10*I10
A24: Net vetches | B24: =F10 | E24: =C24+D24/8 | I24: =G24+H24/8 | J24: =B24-(E24+F24+I24) | L24: =O11 | M24: =L24*J24 | N24: =O11*I11
A25: Total | B25: =SUM(B19:B24) | E25: =SUM(E19:E24) | J25: =SUM(J19:J24) | M25: =SUM(M19:M24) | N25: =SUM(N19:N24)

Sheet Stock
A1: EAST KNOYLE STOCK ACCOUNT
A3: Livestock | B3: Inherited stock | C3: Bought | D3: Produced | E3: strays | F3: herbage | G3: sold | H3: in murrain | I3: accounted for elsewhere | J3: End-period stock | K3: cross-check | L3: price 1 | M3: units 1 | N3: price 2 | O3: units 2 | P3: Weight (weys) | Q3: Unit price (£) | R3: Value of production (£) at sales prices | S3: Value of stock at sales prices | T3: Sales in (£) | U3: Details
A4: Cart-horses | B4: 4 | J4: 4 | K4: =B4+C4+D4+E4-F4-G4-H4-I4 | Q4: =IFERROR((L4+N4)/(M4+O4),"") | R4: =IFERROR(D4*Q4,"") | T4: =IFERROR(Q4*G4,"")
A5: Mares | K5: =B5+C5+D5+E5-F5-G5-H5-I5 | Q5: =IFERROR((L5+N5)/(M5+O5),"") | R5: =IFERROR(D5*Q5,"") | T5: =IFERROR(Q5*G5,"")
A6: Plough horses | B6: 11 | C6: 2 | D6: 1 | G6: 2 | J6: 12 | K6: =B6+C6+D6+E6-F6-G6-H6-I6 | L6: ='Merdon Receipts'!F51 | M6: 2 | Q6: =IFERROR((L6+N6)/(M6+O6),"") | R6: =IFERROR(D6*Q6,"") | S6: =Q6*K6 | T6: =IFERROR(Q6*G6,"")
A7: Colts (2 years) | K7: =B7+C7+D7+E7-F7-G7-H7-I7 | Q7: =IFERROR((L7+N7)/(M7+O7),"") | R7: =IFERROR(D7*Q7,"") | T7: =IFERROR(Q7*G7,"")
A8: Colts (2 years) | K8: =B8+C8+D8+E8-F8-G8-H8-I8 | Q8: =IFERROR((L8+N8)/(M8+O8),"") | R8: =IFERROR(D8*Q8,"") | T8: =IFERROR(Q8*G8,"")
A9: Colts (1 year) | K9: =B9+C9+D9+E9-F9-G9-H9-I9 | Q9: =IFERROR((L9+N9)/(M9+O9),"") | R9: =IFERROR(D9*Q9,"") | T9: =IFERROR(Q9*G9,"")
A10: Foals | K10: =B10+C10+D10+E10-F10-G10-H10-I10 | Q10: =IFERROR((L10+N10)/(M10+O10),"") | R10: =IFERROR(D10*Q10,"") | T10: =IFERROR(Q10*G10,"")
A11: Oxen | B11: 65 | C11: 5 | D11: 5 | G11: 13 | H11: 3 | J11: 59 | K11: =B11+C11+D11+E11-F11-G11-H11-I11 | L11: ='Merdon Receipts'!F52 | M11: 12 | N11: ='Merdon Receipts'!F62 | O11: 1 | Q11: =IFERROR((L11+N11)/(M11+O11),"") | R11: =IFERROR(D11*Q11,"") | S11: =Q11*K11 | T11: =IFERROR(Q11*G11,"")
A12: Bulls | B12: 1 | J12: 1 | K12: =B12+C12+D12+E12-F12-G12-H12-I12 | Q12: =IFERROR((L12+N12)/(M12+O12),"") | R12: =IFERROR(D12*Q12,"") | T12: =IFERROR(Q12*G12,"")
A13: Cows | B13: 23 | C13: 3 | D13: 5 | G13: 5 | J13: 26 | K13: =B13+C13+D13+E13-F13-G13-H13-I13 | L13: ='Merdon Receipts'!F53 | M13: 5 | Q13: =IFERROR((L13+N13)/(M13+O13),"") | R13: =IFERROR(D13*Q13,"") | S13: =Q13*K13 | T13: =IFERROR(Q13*G13,"")
A14: Steers | B14: 8 | I14: 8 | J14: 0 | K14: =B14+C14+D14+E14-F14-G14-H14-I14 | Q14: =IFERROR((L14+N14)/(M14+O14),"") | R14: =IFERROR(D14*Q14,"") | T14: =IFERROR(Q14*G14,"")
A15: Bullocks | B15: 9 | J15: 9 | K15: =B15+C15+D15+E15-F15-G15-H15-I15 | Q15: =IFERROR((L15+N15)/(M15+O15),"") | R15: =IFERROR(D15*Q15,"") | T15: =IFERROR(Q15*G15,"")
A16: Yearlings | B16: 9 | J16: 9 | K16: =B16+C16+D16+E16-F16-G16-H16-I16 | Q16: =IFERROR((L16+N16)/(M16+O16),"") | R16: =IFERROR(D16*Q16,"") | T16: =IFERROR(Q16*G16,"")
A17: Calves | C17: 2 | D17: 17 | G17: 5 | H17: 2 | I17: 2 | J17: 10 | K17: =B17+C17+D17+E17-F17-G17-H17-I17 | L17: ='Merdon Receipts'!F54 | M17: 5 | Q17: =IFERROR((L17+N17)/(M17+O17),"") | R17: =IFERROR(D17*Q17,"") | S17: =Q17*K17 | T17: =IFERROR(Q17*G17,"") | U17: accounted for elsewhere is tithe
A18: Wethers | B18: 166 | D18: 37 | G18: 21 | H18: 11 | J18: 171 | K18: =B18+C18+D18+E18-F18-G18-H18-I18 | L18: ='Merdon Receipts'!F55*(20/22) | M18: 21 | Q18: =IFERROR((L18+N18)/(M18+O18),"") | R18: =IFERROR(D18*Q18,"") | S18: =Q18*K18 | T18: =IFERROR(Q18*G18,"") | U18: price in receipts includes 1 ram excuded by assumign same price
A19: Rams | B19: 12 | D19: 5 | G19: 3 | J19: 14 | K19: =B19+C19+D19+E19-F19-G19-H19-I19 | L19: ='Merdon Receipts'!F56*(2/26) | M19: 2 | N19: ='Merdon Receipts'!F55*(1/22) | O19: 1 | Q19: =IFERROR((L19+N19)/(M19+O19),"") | R19: =IFERROR(D19*Q19,"") | S19: =Q19*K19 | T19: =IFERROR(Q19*G19,"") | U19: price in reciepts includes ewes which are excluded by assuming same unit price
A20: Ewes | B20: 238 | D20: 55 | G20: 24 | H20: 8 | J20: 261 | K20: =B20+C20+D20+E20-F20-G20-H20-I20 | L20: ='Merdon Receipts'!F56*(20/22) | M20: 24 | Q20: =IFERROR((L20+N20)/(M20+O20),"") | R20: =IFERROR(D20*Q20,"") | S20: =Q20*K20 | T20: =IFERROR(Q20*G20,"") | U20: price in reciepts includes rams which are excluded by assuming same unit price
A21: Hoggs | B21: 99 | H21: 3 | I21: 96 | J21: 0 | K21: =B21+C21+D21+E21-F21-G21-H21-I21 | Q21: =IFERROR((L21+N21)/(M21+O21),"") | R21: =IFERROR(D21*Q21,"") | T21: =IFERROR(Q21*G21,"")
A22: Lambs | D22: 202 | G22: 37 | H22: 18 | I22: 22 | J22: 125 | K22: =B22+C22+D22+E22-F22-G22-H22-I22 | L22: ='Merdon Receipts'!F57 | M22: 34 | Q22: =IFERROR((L22+N22)/(M22+O22),"") | R22: =IFERROR(D22*Q22,"") | S22: =Q22*K22 | T22: =IFERROR(Q22*G22,"") | U22: accounted for elsewhere is tithe; number of lambs sold in stock doesn't match receipts
A23: Boars | B23: 1 | D23: 1 | H23: 1 | J23: 1 | K23: =B23+C23+D23+E23-F23-G23-H23-I23 | Q23: =IFERROR((L23+N23)/(M23+O23),"") | R23: =IFERROR(D23*Q23,"") | T23: =IFERROR(Q23*G23,"")
A24: Sows | B24: 2 | D24: 1 | H24: 1 | J24: 2 | K24: =B24+C24+D24+E24-F24-G24-H24-I24 | Q24: =IFERROR((L24+N24)/(M24+O24),"") | R24: =IFERROR(D24*Q24,"") | T24: =IFERROR(Q24*G24,"")
A25: Pigs | B25: 21 | D25: 22 | E25: 1 | G25: 29 | J25: 15 | K25: =B25+C25+D25+E25-F25-G25-H25-I25 | L25: ='Merdon Receipts'!F58 | M25: 29 | Q25: =IFERROR((L25+N25)/(M25+O25),"") | R25: =IFERROR(D25*Q25,"") | S25: =Q25*K25 | T25: =IFERROR(Q25*G25,"")
A26: Hoggets | B26: 28 | H26: 4 | I26: 24 | J26: 0 | K26: =B26+C26+D26+E26-F26-G26-H26-I26 | Q26: =IFERROR((L26+N26)/(M26+O26),"") | R26: =IFERROR(D26*Q26,"") | T26: =IFERROR(Q26*G26,"")
A27: Piglets | D27: 40 | I27: 5 | J27: 35 | K27: =B27+C27+D27+E27-F27-G27-H27-I27 | Q27: =IFERROR((L27+N27)/(M27+O27),"") | R27: =IFERROR(D27*Q27,"") | T27: =IFERROR(Q27*G27,"") | U27: accounted for elsewhere is tithe
A28: Swans | K28: =B28+C28+D28+E28-F28-G28-H28-I28 | Q28: =IFERROR((L28+N28)/(M28+O28),"") | R28: =IFERROR(D28*Q28,"") | T28: =IFERROR(Q28*G28,"")
A29: Peacocks | K29: =B29+C29+D29+E29-F29-G29-H29-I29 | Q29: =IFERROR((L29+N29)/(M29+O29),"") | R29: =IFERROR(D29*Q29,"") | T29: =IFERROR(Q29*G29,"")
A30: Total | K30: =B30+C30+D30+E30-F30-G30-H30-I30 | Q30: =IFERROR((L30+N30)/(M30+O30),"") | R30: =IFERROR(D30*Q30,"") | T30: =SUM(T4:T29)
K31: =B31+C31+D31+E31-F31-G31-H31-I31 | Q31: =IFERROR((L31+N31)/(M31+O31),"") | R31: =IFERROR(D31*Q31,"") | T31: =IFERROR(Q31*G31,"")
A32: Wool | K32: =B32+C32+D32+E32-F32-G32-H32-I32 | Q32: =IFERROR((L32+N32)/(M32+O32),"") | R32: =IFERROR(D32*Q32,"") | T32: =IFERROR(Q32*G32,"")
A33: Fleeces | K33: =B33+C33+D33+E33-F33-G33-H33-I33 | Q33: =IFERROR((L33+N33)/(M33+O33),"") | R33: =IFERROR(D33*Q33,"") | T33: =IFERROR(Q33*G33,"")
A34: Coarse wool | D34: 451 | G34: 405 | I34: 46 | J34: 0 | K34: =B34+C34+D34+E34-F34-G34-H34-I34 | P34: =3+14*Assumptions!E5 | Q34: 0.02 | R34: =IFERROR(D34*Q34,"") | U34: unit price from overview sheet (UnitPricesStocks_averages)
A35: Lamb's wool | D35: 163 | G35: 163 | J35: 0 | K35: =B35+C35+D35+E35-F35-G35-H35-I35 | P35: =13*0.04 | Q35: 0.01 | R35: =IFERROR(D35*Q35,"") | T35: =IFERROR(Q35*G35,"") | U35: unit price from overview sheet (UnitPricesStocks_averages)
A36: Wool locks | D36: =2*0.04+4*Assumptions!E4 | G36: =D36 | K36: =B36+C36+D36+E36-F36-G36-H36-I36 | L36: ='Merdon Receipts'!F59 | M36: =P36 | P36: =G36 | Q36: =IFERROR((L36+N36)/(M36+O36),"") | R36: =IFERROR(D36*Q36,"") | S36: =Q36*K36 | T36: =IFERROR(Q36*G36,"")
A37: Wool sold at shearing | K37: =B37+C37+D37+E37-F37-G37-H37-I37 | Q37: =IFERROR((L37+N37)/(M37+O37),"") | R37: =IFERROR(D37*Q37,"") | T37: =IFERROR(Q37*G37,"")
A38: Total | K38: =B38+C38+D38+E38-F38-G38-H38-I38 | Q38: =IFERROR((L38+N38)/(M38+O38),"") | R38: =SUM(R34:R36) | T38: =SUM(T34:T37)
K39: =B39+C39+D39+E39-F39-G39-H39-I39 | Q39: =IFERROR((L39+N39)/(M39+O39),"") | R39: =IFERROR(D39*Q39,"") | T39: =IFERROR(Q39*G39,"")
K40: =B40+C40+D40+E40-F40-G40-H40-I40 | Q40: =IFERROR((L40+N40)/(M40+O40),"") | R40: =IFERROR(D40*Q40,"") | T40: =IFERROR(Q40*G40,"")
A41: Hides | K41: =B41+C41+D41+E41-F41-G41-H41-I41 | Q41: =IFERROR((L41+N41)/(M41+O41),"") | R41: =IFERROR(D41*Q41,"") | T41: =IFERROR(Q41*G41,"")
...

Sheet Assumptions
A1: ASSUMPTIONS
B3: Weights | C3: Value (in lbs) | D3: Value (in cloves) | E3: Value (in weys) | F3: Value (in stone)
B4: Lbs | C4: 1 | D4: =C4/C5 | E4: =C4/C6 | F4: =C4/C7
B5: Cloves | C5: 7 | D5: 1 | E5: =C5/C6 | F5: =C7/C5
B6: Wey | C6: 175 | D6: =C6/C5 | E6: =C6/C6 | F6: =C7/C6
B7: Stone | C7: =175/14 | D7: =C5/C7 | E7: =C7/C6 | F7: 1
