Workbook

Sheet Overton Overview - Completed
A1: OVERTON OVERVIEW - COMPLETED | B1: Total in £ | C1: Error | D1: Note
A2: CASH ACCOUNT
A3: RECEIPTS
A4: Arrears total | B4: 17.214583
A5: Rents of assize total | B5: 30.992708
A6: Quittances total | B6: 1.85
A7: Defaults of rent total | B7: 5.4625
A8: Defaults of rent through the pestilence total
A9: Cotlands defaults total
A10: Cotlands total
A11: Total of quittances and defaults of rent total
A12: Total of rents remaining clear total
A13: Farms total
A14: Annual recognizances total | B14: 0
A15: Issues of the Manor total | B15: 23.0125
A16: Issues of the tenements in the lord's hands total
A17: Sale of labour services total
A18: Sale of corn total | B18: 41.472917
A19: Entry and marriage fines total | B19: 4.8
A20: Pleas & perquisites total | B20: 4.9625
A21: Forfeited chattels total
A22: Farm of the demesne land total
A23: Total of all receipts (calculated here) | B23: =SUM(B5:B22)
A24: Total of all receipts (calculated here) incl arrears | B24: =SUM(B4:B22)
A25: Total recorded in the accounts excl. arrears | C25: =B23-B25
A26: Total recorded in the accounts incl. arrears | B26: =B25+B4
A29: EXPENSES
A30: Cost of ploughs total | B30: 6.2604167
A31: Purchase of corn total | B31: 0
A32: Cost of carts and wagons total | B32: 1.775
A33: Cost of dairy total | B33: 0.54583333
A34: Purchase of stock total | B34: 0
A35: Sheepcote total | B35: 7.2708333
A36: Cost of buildings total | B36: 2.4875
A37: Threshing total | B37: 1.5083333
A38: Barley expenses
A39: Expenses of the harvest total | B39: 1.2239583
A40: Necessary expenses
A41: Wages of the bailiff
A42: Steward's expenses total
...

Sheet Issues of the Mills
A1: No mill account for Adderbury

Sheet raw data
A1: Heading | B1: Sentence | C1: Total in Pounds | D1: Pounds | E1: Shillings | F1: Pence | G1: Corn | H1: Total Quarters Except 1 | I1: Total Bushels Except 1 | J1: Total Corn Cross-Check | K1: Total Corn Manorial Account | L1: Corn Quantity Error | M1: Quarters 1 | N1: Bushels 1 | O1: shilling a quarter 1 | P1: pence a quarter 1 | Q1: shilling a quarter 2 | R1: pence a quarter 2 | S1: shilling a quarter 3 | T1: pence a quarter 3 | U1: shilling a quarter 4 | V1: pence a quarter 4 | W1: shilling a bushel 1 | X1: pence a bushel 1 | Y1: shilling a bushel 2 | Z1: pence a bushel 2 | AA1: shilling a bushel 3 | AB1: pence a bushel 3 | AC1: shilling a bushel 4 | AD1: pence a bushel 4
A2: Adderbury | B2: The account2 of William Jakeman, reeve there, for the sixth year of the translation of Henry Beaufort', lord bishop of Winchester, and the eleventh year of the reign of King Henry the Fourth. | C2: 0 | D2: 0 | E2: 0 | F2: 0 | H2: 0 | I2: 0 | J2: 0 | K2: 0 | L2: 0 | M2: 0 | N2: 0
A3: Arrears | B3: None. | C3: 0 | D3: 0 | E3: 0 | F3: 0 | H3: 0 | I3: 0 | J3: 0 | K3: 0 | L3: 0 | M3: 0 | N3: 0
A4: Rents of assize | B4: And for £6 9 shilling 6.25pence for all rents of assize at St Thomas the Apostle (21 December). | C4: 6.48 | D4: 6 | E4: 9 | F4: 6.25 | H4: 0 | I4: 0 | J4: 0 | K4: 0 | L4: 0 | M4: 0 | N4: 0
A5: Rents of assize | B5: £6 9 shilling 8.5pence at Easter (23 March). | C5: 6.49 | D5: 6 | E5: 9 | F5: 8.5 | H5: 0 | I5: 0 | J5: 0 | K5: 0 | L5: 0 | M5: 0 | N5: 0
A6: Rents of assize | B6: £6 9 shilling 6.25pence at the Nativity of St John the Baptist (24 June). | C6: 6.48 | D6: 6 | E6: 9 | F6: 6.25 | H6: 0 | I6: 0 | J6: 0 | K6: 0 | L6: 0 | M6: 0 | N6: 0
A7: Rents of assize | B7: £6 10 shilling 1.5pence at Michaelmas (29 September). | C7: 6.51 | D7: 6 | E7: 10 | F7: 1.5 | H7: 0 | I7: 0 | J7: 0 | K7: 0 | L7: 0 | M7: 0 | N7: 0
A8: Rents of assize | B8: Total, £25 18 shilling 10.5pence. | C8: 25.94 | D8: 25 | E8: 18 | F8: 10.5 | H8: 0 | I8: 0 | J8: 0 | K8: 0 | L8: 0 | M8: 0 | N8: 0
A9: Quittances of rent | B9: In quittance of rent of 1 reeve for the year 5 shilling. | C9: 0.25 | D9: 0 | E9: 5 | F9: 0 | H9: 0 | I9: 0 | J9: 0 | K9: 0 | L9: 0 | M9: 0 | N9: 0
A10: Quittances of rent | B10: nothing this year of the 4 shilling for 1 smith forging the ironwork of 2 ploughs for the year. | C10: 0.2 | D10: 0 | E10: 4 | F10: 0 | H10: 0 | I10: 0 | J10: 0 | K10: 0 | L10: 0 | M10: 0 | N10: 0
A11: Quittances of rent | B11: nothing this year of the 4 shilling for 1 shepherd keeping the lord's wethers for the year. | C11: 0.2 | D11: 0 | E11: 4 | F11: 0 | H11: 0 | I11: 0 | J11: 0 | K11: 0 | L11: 0 | M11: 0 | N11: 0
A12: Quittances of rent | B12: nothing this year of the 4 shilling for 1 swineherd for the year. | C12: 0.2 | D12: 0 | E12: 4 | F12: 0 | H12: 0 | I12: 0 | J12: 0 | K12: 0 | L12: 0 | M12: 0 | N12: 0
A13: Quittances of rent | B13: nothing this year of the 4 shilling for 1 cowherd for the year. | C13: 0.2 | D13: 0 | E13: 4 | F13: 0 | H13: 0 | I13: 0 | J13: 0 | K13: 0 | L13: 0 | M13: 0 | N13: 0
... A149: Cost of buildings | B149: board-nails and clout-nails bought for the same 1 shilling 4pence. | C149: 0.07 | D149: 0 | E149: 1 | F149: 4 | H149: 0 | I149: 0 | J149: 0 | K149: 0 | L149: 0 | M149: 0 | N149: 0
A150: Cost of buildings | B150: 4 quarters 4 bushels of limestone bought at Walton' 5 shilling 3pence, at 1 shilling 2pence a quarters. | C150: 0.26 | D150: 0 | E150: 5 | F150: 3 | H150: 4 | I150: 4 | J150: 4.5 | K150: 4.5 | L150: 0 | M150: 4 | N150: 4 | O150: 1 | P150: 2
A151: Cost of buildings | B151: carrying the same 4pence. | C151: 0.02 | D151: 0 | E151: 0 | F151: 4 | H151: 0 | I151: 0 | J151: 0 | K151: 0 | L151: 0 | M151: 0 | N151: 0
A152: Cost of buildings | B152: 8 quarters of limestone bought at Witney 10 shilling 4pence, at 1 shilling 31 pence a quarters. | C152: 0.52 | D152: 0 | E152: 10 | F152: 4 | H152: 8 | I152: 0 | J152: 8 | K152: 8 | L152: 0 | M152: 8 | N152: 0 | O152: 1 | P152: 31
A153: Cost of buildings | B153: carrying the same from Witney to Adderbury 3 shilling 8pence. | C153: 0.18 | D153: 0 | E153: 3 | F153: 8 | H153: 0 | I153: 0 | J153: 0 | K153: 0 | L153: 0 | M153: 0 | N153: 0
A154: Cost of buildings | B154: 1,500 stone slates bought 6 shilling, at 4 shilling a 1,000.. | C154: 0.3 | D154: 0 | E154: 6 | F154: 0 | H154: 0 | I154: 0 | J154: 0 | K154: 0 | L154: 0 | M154: 0 | N154: 0
A155: Cost of buildings | B155: 500 eaves-stones bought 2 shilling 6pence, at 6pence a 100.. | C155: 0.12 | D155: 0 | E155: 2 | F155: 6 | H155: 0 | I155: 0 | J155: 0 | K155: 0 | L155: 0 | M155: 0 | N155: 0
A156: Cost of buildings | B156: 6,000 pins bought 2 shilling, at 4pence a 1,000.. | C156: 0.12 | D156: 0 | E156: 2 | F156: 4 | H156: 0 | I156: 0 | J156: 0 | K156: 0 | L156: 0 | M156: 0 | N156: 0
A157: Cost of buildings | B157: 50 ridge-tiles bought 6 shilling 3pence, at 1.5pence each. | C157: 0.31 | D157: 0 | E157: 6 | F157: 3 | H157: 0 | I157: 0 | J157: 0 | K157: 0 | L157: 0 | M157: 0 | N157: 0
A158: Cost of buildings | B158: sand bought and dug and quarried at Tadmarton 10pence. | C158: 0.04 | D158: 0 | E158: 0 | F158: 10 | H158: 0 | I158: 0 | J158: 0 | K158: 0 | L158: 0 | M158: 0 | N158: 0
A159: Cost of buildings | B159: stipend of 1 man going to Walton' to quarry lime there 2pence. | C159: 0.01 | D159: 0 | E159: 0 | F159: 2 | H159: 0 | I159: 0 | J159: 0 | K159: 0 | L159: 0 | M159: 0 | N159: 0
A160: Cost of buildings | B160: expenses of 12 men coming for a boon-work with 6 carts to quarry sand at Newotele and carry it to Adderbury, with the digging, 2 shilling 3pence. | C160: 0.11 | D160: 0 | E160: 2 | F160: 3 | H160: 0 | I160: 0 | J160: 0 | K160: 0 | L160: 0 | M160: 0 | N160: 0
A161: Cost of buildings | B161: hiring 1 man to carry sand and lime from the warrener's chamber to the barn by piece-work 4pence. | C161: 0.02 | D161: 0 | E161: 0 | F161: 4 | H161: 0 | I161: 0 | J161: 0 | K161: 0 | L161: 0 | M161: 0 | N161: 0
A162: Cost of buildings | B162: carrying the ridge-tiles bought above 8pence. | C162: 0.03 | D162: 0 | E162: 0 | F162: 8 | H162: 0 | I162: 0 | J162: 0 | K162: 0 | L162: 0 | M162: 0 | N162: 0
A163: Cost of buildings | B163: expenses of various men coming for a boon-work to buy slates at Aynho and carry them to Adderbury with the expenses of 1 man there mending the said slates 2d 1 shilling 9.5pence. | C163: 0.09 | D163: 0 | E163: 1 | F163: 9.5 | H163: 0 | I163: 0 | J163: 0 | K163: 0 | L163: 0 | M163: 0 | N163: 0
A164: Cost of buildings | B164: 1 tine bought 8pence. | C164: 0.03 | D164: 0 | E164: 0 | F164: 8 | H164: 0 | I164: 0 | J164: 0 | K164: 0 | L164: 0 | M164: 0 | N164: 0
... A181: Total of all allowances | B181: Total of all allowances and cash deliveries, £64 19 shilling 11.5pence He is quit. | C181: 65 | D181: 64 | E181: 19 | F181: 11.5 | H181: 0 | I181: 0 | J181: 0 | K181: 0 | L181: 0 | M181: 0 | N181: 0
A182: Wheat | B182: William Jakeman, reeve there, answers for 3 quarters of wheat remaining.. | C182: 0 | D182: 0 | E182: 0 | F182: 0 | G182: wheat | H182: 3 | I182: 0 | J182: 3 | K182: 3 | L182: 0 | M182: 3 | N182: 0
A183: Wheat | B183: Total, 3 quarters.. | C183: 0 | D183: 0 | E183: 0 | F183: 0 | H183: 3 | I183: 0 | J183: 3 | K183: 3 | L183: 0 | M183: 3 | N183: 0
A184: Wheat | B184: 3 quarters remain in the keeping of John Eadburbury, farmer there, to be handed back and restored at the end of his farm of 12 years, this year being the fifth. | C184: 0 | D184: 0 | E184: 0 | F184: 0 | H184: 3 | I184: 0 | J184: 3 | K184: 3 | L184: 0 | M184: 3 | N184: 0
A185: Rye | B185: And for 34 quarters of rye remaining.. | C185: 0 | D185: 0 | E185: 0 | F185: 0 | G185: rye | H185: 34 | I185: 0 | J185: 34 | K185: 34 | L185: 0 | M185: 34 | N185: 0
A186: Rye | B186: Total, 34 quarters.. | C186: 0 | D186: 0 | E186: 0 | F186: 0 | H186: 34 | I186: 0 | J186: 34 | K186: 34 | L186: 0 | M186: 34 | N186: 0
A187: Rye | B187: 34 quarters remain in the keeping of the said John Eadburbury, farmer there, to be handed back and restored at the end of his farm as before. | C187: 0 | D187: 0 | E187: 0 | F187: 0 | H187: 34 | I187: 0 | J187: 34 | K187: 34 | L187: 0 | M187: 34 | N187: 0
A188: Dredge | B188: And for 30 quarters of dredge remaining.. | C188: 0 | D188: 0 | E188: 0 | F188: 0 | G188: dredge | H188: 30 | I188: 0 | J188: 30 | K188: 30 | L188: 0 | M188: 30 | N188: 0
A189: Dredge | B189: Total, 30 quarters.. | C189: 0 | D189: 0 | E189: 0 | F189: 0 | H189: 30 | I189: 0 | J189: 30 | K189: 30 | L189: 0 | M189: 30 | N189: 0
A190: Dredge | B190: 30 quarters remain in the keeping of the said John Eadburbury, farmer there, to be handed back and restored as before. | C190: 0 | D190: 0 | E190: 0 | F190: 0 | H190: 30 | I190: 0 | J190: 30 | K190: 30 | L190: 0 | M190: 30 | N190: 0
A191: Pulses | B191: None remain. | C191: 0 | D191: 0 | E191: 0 | F191: 0 | H191: 0 | I191: 0 | J191: 0 | K191: 0 | L191: 0 | M191: 0 | N191: 0
...

Sheet Prices
A1: Meat & Dairy Prices
C2: 1301 | D2: 1302 | E2: Average
A3: Beef | B3: £ per lb | C3: 0.0033351854 | D3: 0.0032608538 | E3: =AVERAGE(C3:D3)
A4: Mutton | B4: £ per lb | C4: 0.0036593977 | D4: 0.0037125513 | E4: =AVERAGE(C4:D4)
A5: Pork | B5: £ per lb | C5: 0.0038431326 | D5: 0.0037574803 | E5: =AVERAGE(C5:D5)
A6: Cheese | B6: £ per lb | C6: 0.0055768754 | D6: 0.0056654898 | E6: =AVERAGE(C6:D6)
A7: Butter | B7: £ per lb | C7: 0.0036626221 | D7: 0.0035935077 | E7: =AVERAGE(C7:D7)
A8: Milk | B8: £ per gallon | C8: 0.0055768754 | D8: 0.0056654898 | E8: =AVERAGE(C8:D8)

Sheet Labour Rents

Sheet Overton Overview
A1: OVERTON OVERVIEW | B1: £ | C1: s | D1: d | G1: Total in £ | H1: Error
A2: CASH ACCOUNT
A3: RECEIPTS
A4: Arrears total | G4: =IF(INDEX('Overton Receipts'!$A$4:$F$171,MATCH('Overton Overview'!$A4,'Overton Receipts'!$A$4:$A$171,0),6)=0,"",INDEX('Overton Receipts'!$A$4:$F$171,MATCH('Overton Overview'!$A4,'Overton Receipts'!$A$4:$A$171,0),6))
A5: Rents of assize total | G5: =IF(INDEX('Overton Receipts'!$A$4:$F$171,MATCH('Overton Overview'!$A5,'Overton Receipts'!$A$4:$A$171,0),6)=0,"",INDEX('Overton Receipts'!$A$4:$F$171,MATCH('Overton Overview'!$A5,'Overton Receipts'!$A$4:$A$171,0),6))
A6: Quittances total | G6: =IF(INDEX('Overton Receipts'!$A$4:$F$171,MATCH('Overton Overview'!$A6,'Overton Receipts'!$A$4:$A$171,0),6)=0,"",INDEX('Overton Receipts'!$A$4:$F$171,MATCH('Overton Overview'!$A6,'Overton Receipts'!$A$4:$A$171,0),6))
A7: Defaults of rent total | G7: =IF(INDEX('Overton Receipts'!$A$4:$F$171,MATCH('Overton Overview'!$A7,'Overton Receipts'!$A$4:$A$171,0),6)=0,"",INDEX('Overton Receipts'!$A$4:$F$171,MATCH('Overton Overview'!$A7,'Overton Receipts'!$A$4:$A$171,0),6))
A8: Annual recognizances total | G8: =IF(INDEX('Overton Receipts'!$A$4:$F$171,MATCH('Overton Overview'!$A8,'Overton Receipts'!$A$4:$A$171,0),6)=0,"",INDEX('Overton Receipts'!$A$4:$F$171,MATCH('Overton Overview'!$A8,'Overton Receipts'!$A$4:$A$171,0),6))
A9: Issues of the Manor total | G9: =IF(INDEX('Overton Receipts'!$A$4:$F$171,MATCH('Overton Overview'!$A9,'Overton Receipts'!$A$4:$A$171,0),6)=0,"",INDEX('Overton Receipts'!$A$4:$F$171,MATCH('Overton Overview'!$A9,'Overton Receipts'!$A$4:$A$171,0),6))
A10: Sale of corn total | G10: =IF(INDEX('Overton Receipts'!$A$4:$F$171,MATCH('Overton Overview'!$A10,'Overton Receipts'!$A$4:$A$171,0),6)=0,"",INDEX('Overton Receipts'!$A$4:$F$171,MATCH('Overton Overview'!$A10,'Overton Receipts'!$A$4:$A$171,0),6))
A11: Entry and marriage fines total | G11: =IF(INDEX('Overton Receipts'!$A$4:$F$171,MATCH('Overton Overview'!$A11,'Overton Receipts'!$A$4:$A$171,0),6)=0,"",INDEX('Overton Receipts'!$A$4:$F$171,MATCH('Overton Overview'!$A11,'Overton Receipts'!$A$4:$A$171,0),6))
A12: Pleas & perquisites total | G12: =IF(INDEX('Overton Receipts'!$A$4:$F$171,MATCH('Overton Overview'!$A12,'Overton Receipts'!$A$4:$A$171,0),6)=0,"",INDEX('Overton Receipts'!$A$4:$F$171,MATCH('Overton Overview'!$A12,'Overton Receipts'!$A$4:$A$171,0),6))
A13: Sum of the above (incl. arrears) | G13: ='Overton Receipts'!F169
A14: Total recorded in the accounts excl. arrears | G14: ='Overton Receipts'!F170 | H14: =G13-G14 | I14: difference is arrears
A15: Total recorded in the accounts incl. arrears | G15: ='Overton Receipts'!F171 | I15: not recorded
A18: EXPENSES
A19: Cost of ploughs total | G19: =IF(INDEX('Overton Expenses'!$A$2:$F$156,MATCH('Overton Overview'!$A19,'Overton Expenses'!$A$2:$A$156,0),6)=0,"",INDEX('Overton Expenses'!$A$2:$F$156,MATCH('Overton Overview'!$A19,'Overton Expenses'!$A$2:$A$156,0),6))
A20: Purchase of corn total | G20: =IF(INDEX('Overton Expenses'!$A$2:$F$156,MATCH('Overton Overview'!$A20,'Overton Expenses'!$A$2:$A$156,0),6)=0,"",INDEX('Overton Expenses'!$A$2:$F$156,MATCH('Overton Overview'!$A20,'Overton Expenses'!$A$2:$A$156,0),6))
A21: Cost of carts and wagons total | G21: =IF(INDEX('Overton Expenses'!$A$2:$F$156,MATCH('Overton Overview'!$A21,'Overton Expenses'!$A$2:$A$156,0),6)=0,"",INDEX('Overton Expenses'!$A$2:$F$156,MATCH('Overton Overview'!$A21,'Overton Expenses'!$A$2:$A$156,0),6))
A22: Cost of dairy total | G22: =IF(INDEX('Overton Expenses'!$A$2:$F$156,MATCH('Overton Overview'!$A22,'Overton Expenses'!$A$2:$A$156,0),6)=0,"",INDEX('Overton Expenses'!$A$2:$F$156,MATCH('Overton Overview'!$A22,'Overton Expenses'!$A$2:$A$156,0),6))
A23: Purchase of stock total | G23: =IF(INDEX('Overton Expenses'!$A$2:$F$156,MATCH('Overton Overview'!$A23,'Overton Expenses'!$A$2:$A$156,0),6)=0,"",INDEX('Overton Expenses'!$A$2:$F$156,MATCH('Overton Overview'!$A23,'Overton Expenses'!$A$2:$A$156,0),6))
A24: Sheepcote total | G24: =IF(INDEX('Overton Expenses'!$A$2:$F$156,MATCH('Overton Overview'!$A24,'Overton Expenses'!$A$2:$A$156,0),6)=0,"",INDEX('Overton Expenses'!$A$2:$F$156,MATCH('Overton Overview'!$A24,'Overton Expenses'!$A$2:$A$156,0),6))
A25: Cost of buildings total | G25: =IF(INDEX('Overton Expenses'!$A$2:$F$156,MATCH('Overton Overview'!$A25,'Overton Expenses'!$A$2:$A$156,0),6)=0,"",INDEX('Overton Expenses'!$A$2:$F$156,MATCH('Overton Overview'!$A25,'Overton Expenses'!$A$2:$A$156,0),6))
A26: Threshing total | G26: =IF(INDEX('Overton Expenses'!$A$2:$F$156,MATCH('Overton Overview'!$A26,'Overton Expenses'!$A$2:$A$156,0),6)=0,"",INDEX('Overton Expenses'!$A$2:$F$156,MATCH('Overton Overview'!$A26,'Overton Expenses'!$A$2:$A$156,0),6))
A27: Expenses of the harvest total | G27: =IF(INDEX('Overton Expenses'!$A$2:$F$156,MATCH('Overton Overview'!$A27,'Overton Expenses'!$A$2:$A$156,0),6)=0,"",INDEX('Overton Expenses'!$A$2:$F$156,MATCH('Overton Overview'!$A27,'Overton Expenses'!$A$2:$A$156,0),6))
A28: Steward's expenses total | G28: =IF(INDEX('Overton Expenses'!$A$2:$F$156,MATCH('Overton Overview'!$A28,'Overton Expenses'!$A$2:$A$156,0),6)=0,"",INDEX('Overton Expenses'!$A$2:$F$156,MATCH('Overton Overview'!$A28,'Overton Expenses'!$A$2:$A$156,0),6))
A29: Sum of the above | G29: ='Overton Expenses'!F149
A30: Total of all expenses | G30: ='Overton Expenses'!F148 | H30: =G29-G30
A31: Capital Expenses | G31: ='Overton Expenses'!F157
A33: Owed by the reeve | G33: =G13-G29-G4
A34: From accounts | G34: ='Overton Expenses'!F151 | H34: =G34-G33
A36: Cash deliveries | G36: ='Overton Expenses'!F153
A37: Total of all allowances and cash deliveries in accounts | B37: n/a | G37: =G36
A39: Net amount owed | G39: =G34-G37
A40: Net amount owed in accounts | G40: ='Overton Expenses'!F154 | H40: =G39-G40
A42: GRANGE ACCOUNT | B42: Net Production | G42: Value of net production | H42: Value of total gross production in £
A43: Grange | B43: qrs | G43: £ | H43: £ | I43: Note: Columns indexed are hardcoded, do not alter number of columns in issues of grange
A44: Net wheat | B44: ='Issues of the Grange'!L19 | G44: ='Issues of the Grange'!O19 | H44: ='Issues of the Grange'!T5
A45: Net curall | B45: ='Issues of the Grange'!L20 | G45: ='Issues of the Grange'!O20 | H45: ='Issues of the Grange'!T6
A46: Net barley | B46: ='Issues of the Grange'!L21 | G46: ='Issues of the Grange'!O21 | H46: ='Issues of the Grange'!T7
...

Sheet Overton Receipts
A1: Overton RECEIPTS
B2: £ | C2: s | D2: d | F2: Total in £ | G2: Error | H2: Notes
A4: Arrears
A5: Arrears total | B5: 17 | C5: 4 | D5: 3.5 | F5: =B5+C5/20+D5/240
A6: of which delivered to treasurer of Wolvesey | B6: 17 | C6: 4 | D6: 3.5 | F6: =B6+C6/20+D6/240
A8: Rents of assize
A9: rents of assize Christmas | B9: 6 | C9: 6 | F9: =B9+C9/20+D9/240
A10: Easter | B10: 6 | C10: 11 | D10: 4 | F10: =B10+C10/20+D10/240
A11: Nativity | B11: 6 | C11: 3 | D11: 4 | F11: =B11+C11/20+D11/240
A12: Michaelmas | B12: 11 | C12: 19 | D12: 2.25 | F12: =B12+C12/20+D12/240
A13: Total recorded in accounts | B13: 30 | C13: 19 | D13: 10.25 | F13: =B13+C13/20+D13/240
A14: Rents of assize total | B14: =SUM(B9:B12) | C14: =SUM(C9:C12) | D14: =SUM(D9:D12) | F14: =B14+C14/20+D14/240 | G14: =F14-F13
A16: Quittances
A17: quittance for 1 reeve for the year | C17: 5 | F17: =B17+C17/20+D17/240
A18: 1 bartoner for the year | C18: 3 | F18: =B18+C18/20+D18/240
A19: 2 haywards | C19: 6 | F19: =B19+C19/20+D19/240
A20: 3 ploughmen for the year | C20: 9 | F20: =B20+C20/20+D20/240
A21: 1 ploughman | C21: 1 | D21: 6 | F21: =B21+C21/20+D21/240
A22: 1 smith for the year | C22: 3 | F22: =B22+C22/20+D22/240
A23: 2 shepherds for the year | C23: 6 | F23: =B23+C23/20+D23/240
A24: 1 keeper of hoggs | D24: 6 | F24: =B24+C24/20+D24/240
A25: 1 cowherd | C25: 3 | F25: =B25+C25/20+D25/240
F26: =B26+C26/20+D26/240
A27: Total recorded in accounts | B27: 1 | C27: 17 | F27: =B27+C27/20+D27/240
A28: Quittances total | B28: =SUM(B17:B26) | C28: =SUM(C17:C26) | D28: =SUM(D17:D26) | F28: =B28+C28/20+D28/240 | G28: =F28-F27
A30: Defaults of rent
A31: default of the mill of Lynch | B31: 1 | F31: =B31+C31/20+D31/240
A32: the land of Bascon drawn | C32: 3 | F32: =B32+C32/20+D32/240
A33: land of Strockyng drawn | C33: 3 | F33: =B33+C33/20+D33/240
A34: ... | C34: 3 | F34: =B34+C34/20+D34/240
A35: ... | C35: 1 | F35: =B35+C35/20+D35/240
A36: ... | C36: 1 | D36: 6 | F36: =B36+C36/20+D36/240
A37: ... | C37: 1 | D37: 6 | F37: =B37+C37/20+D37/240
A38: the land of le Cran | C38: 2 | F38: =B38+C38/20+D38/240
A39: ... | C39: 2 | F39: =B39+C39/20+D39/240
A40: land of William | C40: 1 | D40: 6 | F40: =B40+C40/20+D40/240
A41: ... | C41: 2 | F41: =B41+C41/20+D41/240
A42: land of Codeboye | C42: 2 | F42: =B42+C42/20+D42/240
A43: ... | C43: 2 | F43: =B43+C43/20+D43/240
A44: ... | C44: 1 | D44: 10 | F44: =B44+C44/20+D44/240
...

Sheet Overton Expenses
A1: OVERTON EXPENSES
B2: £ | C2: s | D2: d | F2: Total in £ | G2: Error | H2: Notes | J2: fixed investment | K2: demesne investment
A3: Cost of Ploughs
A4: iron and steel | C4: 10 | D4: 6 | F4: =B4+C4/20+D4/240 | J4: =F4 | K4: =J4
A5: 2 plougshares | C5: 1 | D5: 8 | F5: =B5+C5/20+D5/240 | J5: =F5 | K5: =J5
A6: plough feet | C6: 1 | D6: 9 | F6: =B6+C6/20+D6/240 | J6: =F6 | K6: =J6
A7: 2 ploughs made anew | D7: 6 | F7: =B7+C7/20+D7/240 | J7: =F7 | K7: =J7
A8: fitting the same and others with iron tyres | D8: 6.5 | F8: =B8+C8/20+D8/240 | J8: =F8 | K8: =J8
A9: 7 pairs of wheels | D9: 7 | F9: =B9+C9/20+D9/240 | J9: =F9 | K9: =J9
A10: old ploughs fitted with share-beams | D10: 6 | F10: =B10+C10/20+D10/240 | J10: =F10 | K10: =J10
A11: 14 halters made | D11: 3.5 | F11: =B11+C11/20+D11/240 | J11: =F11 | K11: =J11
A12: shoeing 9 plough-horses | C12: 9 | F12: =B12+C12/20+D12/240 | J12: =F12 | K12: =J12
A13: shoeing horses | D13: 11 | F13: =B13+C13/20+D13/240 | J13: =F13 | K13: =J13
A14: in ale and relish for boon-works | C14: 6 | D14: 8 | F14: =B14+C14/20+D14/240
A15: stipend of 3 oxherds | C15: 9 | F15: =B15+C15/20+D15/240
A16: 2 oxen bought | B16: 1 | C16: 2 | D16: 8 | F16: =B16+C16/20+D16/240
A17: wheat bought | C17: 6 | D17: 3 | F17: =B17+C17/20+D17/240
A18: bere bought | B18: 1 | C18: 4 | D18: 8.5 | F18: =B18+C18/20+D18/240
A19: barly bought | B19: 1 | C19: 6 | D19: 1.5 | F19: =B19+C19/20+D19/240
A20: peas bought | C20: 1 | D20: 8 | F20: =B20+C20/20+D20/240
A21: vetches bought | C21: 1 | D21: 10.5 | F21: =B21+C21/20+D21/240
A22: Total recorded in accounts | B22: 6 | C22: 5 | D22: 2.5 | F22: =B22+C22/20+D22/240
A23: Cost of ploughs total | B23: =SUM(B3:B21) | C23: =SUM(C3:C21) | D23: =SUM(D3:D21) | F23: =B23+C23/20+D23/240 | G23: =F23-F22
A25: Purchase of Corn
A26: nothing | F26: =B26+C26/20+D26/240
A27: Total recorded in accounts | F27: =B27+C27/20+D27/240
A28: Purchase of corn total | B28: =SUM(B26) | C28: =SUM(C26) | D28: =SUM(D26) | F28: =B28+C28/20+D28/240 | G28: =F28-F27
A30: Cost of Carts and Wagons
A31: 1 pair of wheels | C31: 2 | F31: =B31+C31/20+D31/240 | J31: =F31 | K31: =J31
A32: fitting an old binding incl. stipend of smith | C32: 3 | D32: 4 | F32: =B32+C32/20+D32/240 | J32: =F32 | K32: =J32
A33: in hooping the felloes of the cart | D33: 3 | F33: =B33+C33/20+D33/240 | J33: =F33 | K33: =J33
A34: clouts, nails, grease and white leather | C34: 1 | D34: 0.5 | F34: =B34+C34/20+D34/240 | J34: =F34 | K34: =J34
A35: fitting the cart with axles | D35: 6 | F35: =B35+C35/20+D35/240 | J35: =F35 | K35: =J35
A36: mending the old cart | D36: 9 | F36: =B36+C36/20+D36/240 | J36: =F36 | K36: =J36
A37: 1 pair of traces bought | D37: 4 | F37: =B37+C37/20+D37/240 | J37: =F37 | K37: =J37
A38: in 1 collar and 1 pair of tie-beams | C38: 1 | F38: =B38+C38/20+D38/240 | J38: =F38 | K38: =J38
A39: in 1 halter bought | D39: 0.5 | F39: =B39+C39/20+D39/240 | J39: =F39 | K39: =J39
A40: in 1 pair of wheels made for dung | D40: 9 | F40: =B40+C40/20+D40/240 | J40: =F40 | K40: =J40
A41: in shoeing 2 cart-horses | C41: 2 | D41: 6 | F41: =B41+C41/20+D41/240 | J41: =F41 | K41: =J41
A42: in 1 cart-horse bought | B42: 1 | F42: =B42+C42/20+D42/240
...

Sheet Issues of the Grange
B1: The issue of the grange account gives the total "yield" at the top of each heading in curly brackets, measurements used: fold, qrs, bus
B2: In "Issues of the grange" (p.96ff) | I2: In "Sale of Corn" (p.93) | T2: Value of Total Production
A3: Gross output | B3: Quantity | D3: Additional bought-in | F3: from previous year | H3: Quantity | I3: Quantity noted as sold | L3: Difference Produced vs. Sold | M3: Price 1 | N3: Quantity 1 | O3: Price 2 | P3: Quantity 2 | Q3: Price 3 | R3: Quantity 3 | S3: Unit price | T3: Value
B4: qrs | C4: bus | D4: qrs | E4: bus | F4: qrs | G4: bus | H4: qrs | I4: qrs | J4: bus | K4: qrs | M4: £ | N4: qrs | O4: £ | P4: qrs | Q4: £ | R4: qrs | S4: £ per qr | T4: £
A5: Wheat | B5: 64 | C5: 7 | D5: 1 | E5: 2 | H5: =B5+D5+F5+C5/8+E5/8+G5/8 | I5: 50.5 | K5: =I5+J5/8 | L5: =H5-K5 | M5: =5/20+6/240 | N5: 1 | O5: =5/20+4/240 | P5: 1 | Q5: =6/20 | R5: 1 | S5: =IFERROR((M5+O5)/(N5+P5),0) | T5: =S5*H5
A6: Curall | B6: 2 | C6: 2 | H6: =B6+D6+F6+C6/8+E6/8+G6/8 | I6: 2 | J6: 2 | K6: =I6+J6/8 | L6: =H6-K6 | M6: =4/20 | N6: 1 | S6: =IFERROR((M6+O6)/(N6+P6),0) | T6: =S6*H6
A7: Bere | B7: =83+2+1+2 | C7: 3 | D7: 12 | E7: 2 | F7: 13.5 | H7: =B7+D7+F7+C7/8+E7/8+G7/8 | I7: 48 | J7: 2 | K7: =I7+J7/8 | L7: =H7-K7 | M7: =3/20 | N7: 1 | S7: =IFERROR((M7+O7)/(N7+P7),0) | T7: =S7*H7
A8: Barley | B8: 81.5 | D8: 7 | E8: 1 | H8: =B8+D8+F8+C8/8+E8/8+G8/8 | I8: 75 | J8: 5 | K8: =I8+J8/8 | L8: =H8-K8 | M8: =3/20 | N8: 1 | O8: =4/20 | P8: 1 | S8: =IFERROR((M8+O8)/(N8+P8),0) | T8: =S8*H8
A9: Oats | B9: 144 | C9: 3.5 | H9: =B9+D9+F9+C9/8+E9/8+G9/8 | I9: 37 | K9: =I9+J9/8 | L9: =H9-K9 | M9: =2/20 | N9: 1 | O9: =2/20+6/240 | P9: 1 | S9: =IFERROR((M9+O9)/(N9+P9),0) | T9: =S9*H9
A10: Peas | B10: 1 | C10: 5 | H10: =B10+D10+F10+C10/8+E10/8+G10/8 | I10: 1 | J10: 1 | K10: =I10+J10/8 | L10: =H10-K10 | M10: =3/20 | N10: 1 | S10: =IFERROR((M10+O10)/(N10+P10),0) | T10: =S10*H10
A11: Vetches | B11: 3 | C11: 3 | D11: 1 | E11: 1 | F11: 1 | H11: =B11+D11+F11+C11/8+E11/8+G11/8 | I11: 4 | J11: 3 | K11: =I11+J11/8 | L11: =H11-K11 | M11: =1/20 | N11: 1 | S11: =IFERROR((M11+O11)/(N11+P11),0) | T11: =S11*H11
A13: Total Production | H13: =SUM(H5:H11) | T13: =SUM(T5:T11) | U13: Production value is significantly more, as much less was sold than what was produced
A14: Sales of corn (as recorded in accounts) | H14: =SUM(K5:K11) | T14: =41+9/20+5.5/240
A17: Net output | B17: Gross output | C17: Seed | H17: tithe | I17: to manorial servants & livestock | L17: Output net of tithe & seed & liveries to manorial servants | M17: in stock from last year | N17: Price | O17: Value of net output | P17: Value of sales (in "Sale of Corn")
B18: qrs | C18: qrs | D18: bus | E18: qrs | H18: qrs | I18: qrs | J18: bus | K18: qrs | L18: qrs | M18: qrs | N18: £ per qr | O18: £ | P18: £
A19: Net wheat | B19: =B5 | C19: 11 | D19: 2 | E19: =C19+D19/8 | I19: =3+4 | K19: =I19+J19/8 | L19: =B19-(E19+H19+K19) | N19: =S5 | O19: =N19*L19 | P19: =S5*K5
A20: Net curall | B20: =B6 | E20: =C20+D20/8 | K20: =I20+J20/8 | L20: =B20-(E20+H20+K20) | N20: =S6 | O20: =N20*L20 | P20: =S6*K6
A21: Net barley | B21: =B8 | C21: 20 | D21: 1 | E21: =C21+D21/8 | I21: =26+4+4+1.5+3+2+1+2 | J21: =7 | K21: =I21+J21/8 | L21: =B21-(E21+H21+K21) | N21: =S8 | O21: =N21*L21 | P21: =S8*K8
A22: Net oats | B22: =B9 | C22: 65 | E22: =C22+D22/8 | I22: =15+12+10+1+4 | J22: =2+1.5 | K22: =I22+J22/8 | L22: =B22-(E22+H22+K22) | N22: =S9 | O22: =N22*L22 | P22: =S9*K9
A23: Net peas | B23: =B10 | D23: 4 | E23: =C23+D23/8 | K23: =I23+J23/8 | L23: =B23-(E23+H23+K23) | N23: =S10 | O23: =N23*L23 | P23: =S10*K10
A24: Net vetches | B24: =B11 | C24: 1 | D24: 1 | E24: =C24+D24/8 | K24: =I24+J24/8 | L24: =B24-(E24+H24+K24) | N24: =S11 | O24: =N24*L24 | P24: =S11*K11
A25: Total | B25: =SUM(B19:B24) | E25: =SUM(E19:E24) | L25: =SUM(L19:L24) | O25: =SUM(O19:O24) | P25: =SUM(P19:P24)

Sheet Issues of the Mill
A1: OVERTON MILL ACCOUNT
B2: In "Issue of the Mill" (p.98) | F2: In "Mills" (p.95) | P2: Value of Total Production
B3: Quantity | D3: Quantity (produced) | E3: Quantity (produced) | F3: Prices per qr | H3: Prices per bus | J3: Quantities (noted as sold) | M3: Difference produced vs. sold | N3: Price | O3: Price | P3: Value avg price | Q3: Value avg price (busel) | R3: Value of production
B4: qrs | C4: bus | D4: qrs | E4: bus | F4: s | G4: d | H4: s | I4: d | J4: qrs | K4: bus | L4: qrs | M4: qrs | N4: £ per qr | O4: £ per bus | P4: £
A5: Wheat - Town Mill | B5: 3 | D5: =B5+C5/8 | F5: 5 | G5: 4 | J5: 3 | L5: =J5+K5/8 | M5: =D5-L5 | N5: =F5/20+G5/240 | P5: =N5 | R5: =P5*D5
A6: Maslin - Town Mill | B6: 4 | C6: 5 | D6: =B6+C6/8 | E6: =C6+B6*8 | I6: 6 | K6: 5 | L6: =J6+K6/8 | M6: =D6-L6 | O6: =H6/20+I6/240 | Q6: =O6 | R6: =Q6*E6
A7: Coarse-ground corn - Town Mill | B7: 5 | C7: 7 | D7: =B7+C7/8 | F7: 6 | J7: 5 | K7: 7 | L7: =J7+K7/8 | M7: =D7-L7 | N7: =F7/20+G7/240 | P7: =N7 | R7: =P7*D7
A8: Malt - Town Hill | B8: 24 | C8: 1 | D8: =B8+C8/8 | F8: 2 | G8: 4 | J8: 24 | K8: 1 | L8: =J8+K8/8 | M8: =D8-L8 | N8: =F8/20+G8/240 | P8: =N8 | R8: =P8*D8
A9: Mills of Lynch & Subhurn | B9: nothing because at farm
A11: Total production value - average | R11: =SUM(R5:R8)
A12: Sale of mill corn (as noted in Mill Account) | R12: =5+10/20+0.5/240

Sheet Stock
A1: EAST KNOYLE STOCK ACCOUNT
A3: Livestock | B3: Inherited stock | C3: Bought | D3: Produced | E3: strays | F3: herbage | G3: sold | H3: in murrain | I3: accounted for elsewhere | J3: End-period stock | K3: cross-check | L3: price 1 | M3: units 1 | N3: price 2 | O3: units 2 | P3: Weight (weys) | Q3: Unit price (£) | R3: Value of production (£) at sales prices | S3: Sales in (£) | T3: Details
A4: Cart-horses | B4: 2 | C4: 1 | G4: 1 | J4: 2 | K4: =B4+C4+D4+E4-F4-G4-H4-I4 | L4: =S4/G4 | Q4: =L4 | R4: =D4*Q4 | S4: ='Overton Receipts'!F81
A5: Mares | K5: =B5+C5+D5+E5-F5-G5-H5-I5 | Q5: =IFERROR((L5+N5)/(M5+O5),"") | S5: =IFERROR(Q5*G5,"")
A6: Plough horses | B6: 9 | E6: 1 | J6: 10 | K6: =B6+C6+D6+E6-F6-G6-H6-I6 | Q6: =IFERROR((L6+N6)/(M6+O6),"") | S6: =IFERROR(Q6*G6,"")
A7: Colts (2 years) | K7: =B7+C7+D7+E7-F7-G7-H7-I7 | Q7: =IFERROR((L7+N7)/(M7+O7),"") | S7: =IFERROR(Q7*G7,"")
A8: Colts (2 years) | K8: =B8+C8+D8+E8-F8-G8-H8-I8 | Q8: =IFERROR((L8+N8)/(M8+O8),"") | S8: =IFERROR(Q8*G8,"")
A9: Colts (1 year) | K9: =B9+C9+D9+E9-F9-G9-H9-I9 | Q9: =IFERROR((L9+N9)/(M9+O9),"") | S9: =IFERROR(Q9*G9,"")
A10: Foals | K10: =B10+C10+D10+E10-F10-G10-H10-I10 | Q10: =IFERROR((L10+N10)/(M10+O10),"") | S10: =IFERROR(Q10*G10,"")
A11: Oxen | B11: 20 | C11: 2 | G11: 2 | J11: 20 | K11: =B11+C11+D11+E11-F11-G11-H11-I11 | L11: =S11/G11 | Q11: =L11 | R11: =D11*Q11 | S11: ='Overton Receipts'!F82
A12: Bulls | B12: 1 | D12: 1 | G12: 1 | J12: 1 | K12: =B12+C12+D12+E12-F12-G12-H12-I12 | L12: =S12/G12 | Q12: =L12 | R12: =D12*Q12 | S12: ='Overton Receipts'!F83
A13: Cows | B13: 25 | D13: 3 | E13: 1 | G13: 2 | H13: 1 | J13: 26 | K13: =B13+C13+D13+E13-F13-G13-H13-I13 | L13: =S13/G13 | Q13: =L13 | R13: =D13*Q13 | S13: ='Overton Receipts'!F84
A14: Steers | B14: 5 | G14: 1 | I14: 4 | J14: 0 | K14: =B14+C14+D14+E14-F14-G14-H14-I14 | L14: =S14/G14 | Q14: =L14 | R14: =D14*Q14 | S14: ='Overton Receipts'!F85
A15: Bullocks | B15: 9 | J15: 9 | K15: =B15+C15+D15+E15-F15-G15-H15-I15
A16: Yearlings | B16: 10 | H16: 1 | J16: 9 | K16: =B16+C16+D16+E16-F16-G16-H16-I16
A17: Calves | B17: 25 | G17: 11 | H17: 3 | I17: 2 | J17: 9 | K17: =B17+C17+D17+E17-F17-G17-H17-I17 | L17: =S17/G17 | Q17: =L17 | R17: =D17*Q17 | S17: ='Overton Receipts'!F86
A18: Wethers | K18: =B18+C18+D18+E18-F18-G18-H18-I18
A19: Rams | B19: 20 | C19: 1 | D19: 7 | I19: 11 | J19: 17 | K19: =B19+C19+D19+E19-F19-G19-H19-I19
A20: Ewes | B20: 495 | C20: 106 | D20: 102 | G20: 39 | H20: =7+14+12 | J20: 631 | K20: =B20+C20+D20+E20-F20-G20-H20-I20 | L20: =S20/G20 | Q20: =L20 | R20: =D20*Q20 | S20: ='Overton Receipts'!F87 | T20: issues of the manor only records sale of 29 ewes
A21: Hoggs | B21: 234 | G21: 12 | H21: 12 | I21: =102+7+101 | J21: 0 | K21: =B21+C21+D21+E21-F21-G21-H21-I21 | L21: =S21/G21 | Q21: =L21 | R21: =D21*Q21 | S21: ='Overton Receipts'!F89
A22: Lambs | B22: 401 | H22: =61+12+14 | I22: =34 | J22: 280 | K22: =B22+C22+D22+E22-F22-G22-H22-I22
A23: Boars | K23: =B23+C23+D23+E23-F23-G23-H23-I23
A24: Sows | K24: =B24+C24+D24+E24-F24-G24-H24-I24
A25: Pigs | C25: 2 | G25: 2 | K25: =B25+C25+D25+E25-F25-G25-H25-I25 | L25: =S25/G25 | Q25: =L25 | R25: =D25*Q25 | S25: ='Overton Receipts'!F90
A26: Hoggets | K26: =B26+C26+D26+E26-F26-G26-H26-I26 | Q26: =IFERROR((L26+N26)/(M26+O26),"") | R26: =IFERROR(D26*Q26,"") | S26: =IFERROR(Q26*G26,"")
A27: Piglets | K27: =B27+C27+D27+E27-F27-G27-H27-I27 | Q27: =IFERROR((L27+N27)/(M27+O27),"") | R27: =IFERROR(D27*Q27,"") | S27: =IFERROR(Q27*G27,"")
A28: Swans | K28: =B28+C28+D28+E28-F28-G28-H28-I28 | Q28: =IFERROR((L28+N28)/(M28+O28),"") | R28: =IFERROR(D28*Q28,"") | S28: =IFERROR(Q28*G28,"")
A29: Peacocks | B29: 10 | D29: 2 | H29: 1 | J29: 11 | K29: =B29+C29+D29+E29-F29-G29-H29-I29 | Q29: =IFERROR((L29+N29)/(M29+O29),"") | R29: =IFERROR(D29*Q29,"") | S29: =IFERROR(Q29*G29,"")
A30: Total | S30: =SUM(S4:S29)
A33: Wool | K33: =B33+C33+D33+E33-F33-G33-H33-I33 | Q33: =IFERROR((L33+N33)/(M33+O33),"") | R33: =IFERROR(D33*Q33,"") | S33: =IFERROR(Q33*G33,"")
A34: Fleeces | D34: 1013 | I34: =101+2+910 | K34: =B34+C34+D34+E34-F34-G34-H34-I34 | Q34: 0.02 | R34: =IFERROR(D34*Q34,"") | S34: =IFERROR(Q34*G34,"")
A35: Coarse wool | K35: =B35+C35+D35+E35-F35-G35-H35-I35 | Q35: =IFERROR((L35+N35)/(M35+O35),"") | R35: =IFERROR(D35*Q35,"") | S35: =IFERROR(Q35*G35,"")
A36: Lamb's wool | D36: 294 | I36: 294 | K36: =B36+C36+D36+E36-F36-G36-H36-I36 | Q36: 0.01 | R36: =IFERROR(D36*Q36,"") | S36: =IFERROR(Q36*G36,"")
A37: Wool locks | K37: =B37+C37+D37+E37-F37-G37-H37-I37 | Q37: =IFERROR((L37+N37)/(M37+O37),"") | R37: =IFERROR(D37*Q37,"") | S37: ='Overton Receipts'!F91 | T37: in issues of manor woollocks sold
A38: Wool sold at shearing | K38: =B38+C38+D38+E38-F38-G38-H38-I38 | Q38: =IFERROR((L38+N38)/(M38+O38),"") | R38: =IFERROR(D38*Q38,"") | S38: =IFERROR(Q38*G38,"")
A39: Total | R39: =SUM(R34:R38)+S37
A42: Hides | Q42: =IFERROR((L42+N42)/(M42+O42),"") | R42: =IFERROR(D42*Q42,"") | S42: =IFERROR(Q42*G42,"")
A43: Ox hides | K43: =B43+C43+D43+E43-F43-G43-H43-I43 | Q43: =IFERROR((L43+N43)/(M43+O43),"") | R43: =IFERROR(D43*Q43,"") | S43: =IFERROR(Q43*G43,"")
A44: Cow hides | K44: =B44+C44+D44+E44-F44-G44-H44-I44 | Q44: =IFERROR((L44+N44)/(M44+O44),"") | R44: =IFERROR(D44*Q44,"") | S44: =IFERROR(Q44*G44,"")
A45: Mare hides | K45: =B45+C45+D45+E45-F45-G45-H45-I45 | Q45: =IFERROR((L45+N45)/(M45+O45),"") | R45: =IFERROR(D45*Q45,"") | S45: =IFERROR(Q45*G45,"")
...

Sheet Assumptions
A1: ASSUMPTIONS
B3: Weights | C3: Value (in lbs) | D3: Value (in cloves) | E3: Value (in weys) | F3: Value (in stone)
B4: Lbs | C4: 1 | D4: =C4/C5 | E4: =C4/C6 | F4: =C4/C7
B5: Cloves | C5: 7 | D5: 1 | E5: =C5/C6 | F5: =C7/C5
B6: Wey | C6: 175 | D6: =C6/C5 | E6: =C6/C6 | F6: =C7/C6
B7: Stone | C7: =175/14 | D7: =C5/C7 | E7: =C7/C6 | F7: 1
