Workbook

Sheet OvertonBorough Overview - Completed
A1: OVERTONBOROUGH OVERVIEW - COMPLETED | B1: Total in £ | C1: Error | D1: Note
A2: CASH ACCOUNT
A3: RECEIPTS
A4: Arrears total | B4: 2.0604167
A5: Rents of assize total | B5: 8.2145833
A6: Quittances total | B6: 0.1
A7: Defaults of rent total | B7: 0.025
A8: Defaults of rent through the pestilence total
A9: Cotlands defaults total
A10: Cotlands total
A11: Total of quittances and defaults of rent total
A12: Total of rents remaining clear total
A13: Farms total
A14: Annual recognizances total | B14: 0.025
A15: Issues of the Manor total | B15: 0.8
A16: Issues of the tenements in the lord's hands total
A17: Sale of labour services total
A18: Sale of corn total | B18: 0
A19: Entry and marriage fines total | B19: 0.5
A20: Pleas & perquisites total | B20: 3.2625
A21: Forfeited chattels total
A22: Farm of the demesne land total
A23: Total of all receipts (calculated here) | B23: =SUM(B5:B22)
A24: Total of all receipts (calculated here) incl arrears | B24: =SUM(B4:B22)
A25: Total recorded in the accounts excl. arrears | C25: =B23-B25
A26: Total recorded in the accounts incl. arrears | B26: =B25+B4
A29: EXPENSES
A30: Cost of ploughs total | B30: 0
A31: Purchase of corn total | B31: 0
A32: Cost of carts and wagons total | B32: 0
A33: Cost of dairy total | B33: 0
A34: Purchase of stock total | B34: 0
A35: Sheepcote total | B35: 0
A36: Cost of buildings total | B36: 0.25833333
A37: Threshing total | B37: 0
A38: Barley expenses
A39: Expenses of the harvest total | B39: 0
A40: Necessary expenses
A41: Wages of the bailiff
A42: Steward's expenses total
...

Sheet Issues of the Mills
A1: No mill account for Adderbury

Sheet raw data
A1: Heading | B1: Sentence | C1: Total in Pounds | D1: Pounds | E1: Shillings | F1: Pence | G1: Corn | H1: Total Quarters Except 1 | I1: Total Bushels Except 1 | J1: Total Corn Cross-Check | K1: Total Corn Manorial Account | L1: Corn Quantity Error | M1: Quarters 1 | N1: Bushels 1 | O1: shilling a quarter 1 | P1: pence a quarter 1 | Q1: shilling a quarter 2 | R1: pence a quarter 2 | S1: shilling a quarter 3 | T1: pence a quarter 3 | U1: shilling a quarter 4 | V1: pence a quarter 4 | W1: shilling a bushel 1 | X1: pence a bushel 1 | Y1: shilling a bushel 2 | Z1: pence a bushel 2 | AA1: shilling a bushel 3 | AB1: pence a bushel 3 | AC1: shilling a bushel 4 | AD1: pence a bushel 4
A2: Adderbury | B2: The account2 of William Jakeman, reeve there, for the sixth year of the translation of Henry Beaufort', lord bishop of Winchester, and the eleventh year of the reign of King Henry the Fourth. | C2: 0 | D2: 0 | E2: 0 | F2: 0 | H2: 0 | I2: 0 | J2: 0 | K2: 0 | L2: 0 | M2: 0 | N2: 0
A3: Arrears | B3: None. | C3: 0 | D3: 0 | E3: 0 | F3: 0 | H3: 0 | I3: 0 | J3: 0 | K3: 0 | L3: 0 | M3: 0 | N3: 0
A4: Rents of assize | B4: And for £6 9 shilling 6.25pence for all rents of assize at St Thomas the Apostle (21 December). | C4: 6.48 | D4: 6 | E4: 9 | F4: 6.25 | H4: 0 | I4: 0 | J4: 0 | K4: 0 | L4: 0 | M4: 0 | N4: 0
A5: Rents of assize | B5: £6 9 shilling 8.5pence at Easter (23 March). | C5: 6.49 | D5: 6 | E5: 9 | F5: 8.5 | H5: 0 | I5: 0 | J5: 0 | K5: 0 | L5: 0 | M5: 0 | N5: 0
A6: Rents of assize | B6: £6 9 shilling 6.25pence at the Nativity of St John the Baptist (24 June). | C6: 6.48 | D6: 6 | E6: 9 | F6: 6.25 | H6: 0 | I6: 0 | J6: 0 | K6: 0 | L6: 0 | M6: 0 | N6: 0
A7: Rents of assize | B7: £6 10 shilling 1.5pence at Michaelmas (29 September). | C7: 6.51 | D7: 6 | E7: 10 | F7: 1.5 | H7: 0 | I7: 0 | J7: 0 | K7: 0 | L7: 0 | M7: 0 | N7: 0
A8: Rents of assize | B8: Total, £25 18 shilling 10.5pence. | C8: 25.94 | D8: 25 | E8: 18 | F8: 10.5 | H8: 0 | I8: 0 | J8: 0 | K8: 0 | L8: 0 | M8: 0 | N8: 0
A9: Quittances of rent | B9: In quittance of rent of 1 reeve for the year 5 shilling. | C9: 0.25 | D9: 0 | E9: 5 | F9: 0 | H9: 0 | I9: 0 | J9: 0 | K9: 0 | L9: 0 | M9: 0 | N9: 0
A10: Quittances of rent | B10: nothing this year of the 4 shilling for 1 smith forging the ironwork of 2 ploughs for the year. | C10: 0.2 | D10: 0 | E10: 4 | F10: 0 | H10: 0 | I10: 0 | J10: 0 | K10: 0 | L10: 0 | M10: 0 | N10: 0
A11: Quittances of rent | B11: nothing this year of the 4 shilling for 1 shepherd keeping the lord's wethers for the year. | C11: 0.2 | D11: 0 | E11: 4 | F11: 0 | H11: 0 | I11: 0 | J11: 0 | K11: 0 | L11: 0 | M11: 0 | N11: 0
A12: Quittances of rent | B12: nothing this year of the 4 shilling for 1 swineherd for the year. | C12: 0.2 | D12: 0 | E12: 4 | F12: 0 | H12: 0 | I12: 0 | J12: 0 | K12: 0 | L12: 0 | M12: 0 | N12: 0
A13: Quittances of rent | B13: nothing this year of the 4 shilling for 1 cowherd for the year. | C13: 0.2 | D13: 0 | E13: 4 | F13: 0 | H13: 0 | I13: 0 | J13: 0 | K13: 0 | L13: 0 | M13: 0 | N13: 0
... A149: Cost of buildings | B149: board-nails and clout-nails bought for the same 1 shilling 4pence. | C149: 0.07 | D149: 0 | E149: 1 | F149: 4 | H149: 0 | I149: 0 | J149: 0 | K149: 0 | L149: 0 | M149: 0 | N149: 0
A150: Cost of buildings | B150: 4 quarters 4 bushels of limestone bought at Walton' 5 shilling 3pence, at 1 shilling 2pence a quarters. | C150: 0.26 | D150: 0 | E150: 5 | F150: 3 | H150: 4 | I150: 4 | J150: 4.5 | K150: 4.5 | L150: 0 | M150: 4 | N150: 4 | O150: 1 | P150: 2
A151: Cost of buildings | B151: carrying the same 4pence. | C151: 0.02 | D151: 0 | E151: 0 | F151: 4 | H151: 0 | I151: 0 | J151: 0 | K151: 0 | L151: 0 | M151: 0 | N151: 0
A152: Cost of buildings | B152: 8 quarters of limestone bought at Witney 10 shilling 4pence, at 1 shilling 31 pence a quarters. | C152: 0.52 | D152: 0 | E152: 10 | F152: 4 | H152: 8 | I152: 0 | J152: 8 | K152: 8 | L152: 0 | M152: 8 | N152: 0 | O152: 1 | P152: 31
A153: Cost of buildings | B153: carrying the same from Witney to Adderbury 3 shilling 8pence. | C153: 0.18 | D153: 0 | E153: 3 | F153: 8 | H153: 0 | I153: 0 | J153: 0 | K153: 0 | L153: 0 | M153: 0 | N153: 0
A154: Cost of buildings | B154: 1,500 stone slates bought 6 shilling, at 4 shilling a 1,000.. | C154: 0.3 | D154: 0 | E154: 6 | F154: 0 | H154: 0 | I154: 0 | J154: 0 | K154: 0 | L154: 0 | M154: 0 | N154: 0
A155: Cost of buildings | B155: 500 eaves-stones bought 2 shilling 6pence, at 6pence a 100.. | C155: 0.12 | D155: 0 | E155: 2 | F155: 6 | H155: 0 | I155: 0 | J155: 0 | K155: 0 | L155: 0 | M155: 0 | N155: 0
A156: Cost of buildings | B156: 6,000 pins bought 2 shilling, at 4pence a 1,000.. | C156: 0.12 | D156: 0 | E156: 2 | F156: 4 | H156: 0 | I156: 0 | J156: 0 | K156: 0 | L156: 0 | M156: 0 | N156: 0
A157: Cost of buildings | B157: 50 ridge-tiles bought 6 shilling 3pence, at 1.5pence each. | C157: 0.31 | D157: 0 | E157: 6 | F157: 3 | H157: 0 | I157: 0 | J157: 0 | K157: 0 | L157: 0 | M157: 0 | N157: 0
A158: Cost of buildings | B158: sand bought and dug and quarried at Tadmarton 10pence. | C158: 0.04 | D158: 0 | E158: 0 | F158: 10 | H158: 0 | I158: 0 | J158: 0 | K158: 0 | L158: 0 | M158: 0 | N158: 0
A159: Cost of buildings | B159: stipend of 1 man going to Walton' to quarry lime there 2pence. | C159: 0.01 | D159: 0 | E159: 0 | F159: 2 | H159: 0 | I159: 0 | J159: 0 | K159: 0 | L159: 0 | M159: 0 | N159: 0
A160: Cost of buildings | B160: expenses of 12 men coming for a boon-work with 6 carts to quarry sand at Newotele and carry it to Adderbury, with the digging, 2 shilling 3pence. | C160: 0.11 | D160: 0 | E160: 2 | F160: 3 | H160: 0 | I160: 0 | J160: 0 | K160: 0 | L160: 0 | M160: 0 | N160: 0
A161: Cost of buildings | B161: hiring 1 man to carry sand and lime from the warrener's chamber to the barn by piece-work 4pence. | C161: 0.02 | D161: 0 | E161: 0 | F161: 4 | H161: 0 | I161: 0 | J161: 0 | K161: 0 | L161: 0 | M161: 0 | N161: 0
A162: Cost of buildings | B162: carrying the ridge-tiles bought above 8pence. | C162: 0.03 | D162: 0 | E162: 0 | F162: 8 | H162: 0 | I162: 0 | J162: 0 | K162: 0 | L162: 0 | M162: 0 | N162: 0
A163: Cost of buildings | B163: expenses of various men coming for a boon-work to buy slates at Aynho and carry them to Adderbury with the expenses of 1 man there mending the said slates 2d 1 shilling 9.5pence. | C163: 0.09 | D163: 0 | E163: 1 | F163: 9.5 | H163: 0 | I163: 0 | J163: 0 | K163: 0 | L163: 0 | M163: 0 | N163: 0
A164: Cost of buildings | B164: 1 tine bought 8pence. | C164: 0.03 | D164: 0 | E164: 0 | F164: 8 | H164: 0 | I164: 0 | J164: 0 | K164: 0 | L164: 0 | M164: 0 | N164: 0
... A181: Total of all allowances | B181: Total of all allowances and cash deliveries, £64 19 shilling 11.5pence He is quit. | C181: 65 | D181: 64 | E181: 19 | F181: 11.5 | H181: 0 | I181: 0 | J181: 0 | K181: 0 | L181: 0 | M181: 0 | N181: 0
A182: Wheat | B182: William Jakeman, reeve there, answers for 3 quarters of wheat remaining.. | C182: 0 | D182: 0 | E182: 0 | F182: 0 | G182: wheat | H182: 3 | I182: 0 | J182: 3 | K182: 3 | L182: 0 | M182: 3 | N182: 0
A183: Wheat | B183: Total, 3 quarters.. | C183: 0 | D183: 0 | E183: 0 | F183: 0 | H183: 3 | I183: 0 | J183: 3 | K183: 3 | L183: 0 | M183: 3 | N183: 0
A184: Wheat | B184: 3 quarters remain in the keeping of John Eadburbury, farmer there, to be handed back and restored at the end of his farm of 12 years, this year being the fifth. | C184: 0 | D184: 0 | E184: 0 | F184: 0 | H184: 3 | I184: 0 | J184: 3 | K184: 3 | L184: 0 | M184: 3 | N184: 0
A185: Rye | B185: And for 34 quarters of rye remaining.. | C185: 0 | D185: 0 | E185: 0 | F185: 0 | G185: rye | H185: 34 | I185: 0 | J185: 34 | K185: 34 | L185: 0 | M185: 34 | N185: 0
A186: Rye | B186: Total, 34 quarters.. | C186: 0 | D186: 0 | E186: 0 | F186: 0 | H186: 34 | I186: 0 | J186: 34 | K186: 34 | L186: 0 | M186: 34 | N186: 0
A187: Rye | B187: 34 quarters remain in the keeping of the said John Eadburbury, farmer there, to be handed back and restored at the end of his farm as before. | C187: 0 | D187: 0 | E187: 0 | F187: 0 | H187: 34 | I187: 0 | J187: 34 | K187: 34 | L187: 0 | M187: 34 | N187: 0
A188: Dredge | B188: And for 30 quarters of dredge remaining.. | C188: 0 | D188: 0 | E188: 0 | F188: 0 | G188: dredge | H188: 30 | I188: 0 | J188: 30 | K188: 30 | L188: 0 | M188: 30 | N188: 0
A189: Dredge | B189: Total, 30 quarters.. | C189: 0 | D189: 0 | E189: 0 | F189: 0 | H189: 30 | I189: 0 | J189: 30 | K189: 30 | L189: 0 | M189: 30 | N189: 0
A190: Dredge | B190: 30 quarters remain in the keeping of the said John Eadburbury, farmer there, to be handed back and restored as before. | C190: 0 | D190: 0 | E190: 0 | F190: 0 | H190: 30 | I190: 0 | J190: 30 | K190: 30 | L190: 0 | M190: 30 | N190: 0
A191: Pulses | B191: None remain. | C191: 0 | D191: 0 | E191: 0 | F191: 0 | H191: 0 | I191: 0 | J191: 0 | K191: 0 | L191: 0 | M191: 0 | N191: 0
...

Sheet Prices
A1: Meat & Dairy Prices
C2: 1301 | D2: 1302 | E2: Average
A3: Beef | B3: £ per lb | C3: 0.0033351854 | D3: 0.0032608538 | E3: =AVERAGE(C3:D3)
A4: Mutton | B4: £ per lb | C4: 0.0036593977 | D4: 0.0037125513 | E4: =AVERAGE(C4:D4)
A5: Pork | B5: £ per lb | C5: 0.0038431326 | D5: 0.0037574803 | E5: =AVERAGE(C5:D5)
A6: Cheese | B6: £ per lb | C6: 0.0055768754 | D6: 0.0056654898 | E6: =AVERAGE(C6:D6)
A7: Butter | B7: £ per lb | C7: 0.0036626221 | D7: 0.0035935077 | E7: =AVERAGE(C7:D7)
A8: Milk | B8: £ per gallon | C8: 0.0055768754 | D8: 0.0056654898 | E8: =AVERAGE(C8:D8)

Sheet Labour Rents

Sheet Overton Borough Overview
A1: OVERTON BOROUGH | B1: £ | C1: s | D1: d | G1: Total in £ | H1: Error
A3: CASH ACCOUNT
A4: RECEIPTS
A5: Arrears total | G5: =IF(INDEX('Overton Borough Receipts'!$A$4:$F$70,MATCH('Overton Borough Overview'!$A5,'Overton Borough Receipts'!$A$4:$A$70,0),6)=0,"",INDEX('Overton Borough Receipts'!$A$4:$F$70,MATCH('Overton Borough Overview'!$A5,'Overton Borough Receipts'!$A$4:$A$70,0),6))
A6: Rents of assize total | G6: =IF(INDEX('Overton Borough Receipts'!$A$4:$F$70,MATCH('Overton Borough Overview'!$A6,'Overton Borough Receipts'!$A$4:$A$70,0),6)=0,"",INDEX('Overton Borough Receipts'!$A$4:$F$70,MATCH('Overton Borough Overview'!$A6,'Overton Borough Receipts'!$A$4:$A$70,0),6))
A7: Quittances total | G7: =IF(INDEX('Overton Borough Receipts'!$A$4:$F$70,MATCH('Overton Borough Overview'!$A7,'Overton Borough Receipts'!$A$4:$A$70,0),6)=0,"",INDEX('Overton Borough Receipts'!$A$4:$F$70,MATCH('Overton Borough Overview'!$A7,'Overton Borough Receipts'!$A$4:$A$70,0),6))
A8: Defaults of rent total | G8: =IF(INDEX('Overton Borough Receipts'!$A$4:$F$70,MATCH('Overton Borough Overview'!$A8,'Overton Borough Receipts'!$A$4:$A$70,0),6)=0,"",INDEX('Overton Borough Receipts'!$A$4:$F$70,MATCH('Overton Borough Overview'!$A8,'Overton Borough Receipts'!$A$4:$A$70,0),6))
A9: Annual recognizances total | G9: =IF(INDEX('Overton Borough Receipts'!$A$4:$F$70,MATCH('Overton Borough Overview'!$A9,'Overton Borough Receipts'!$A$4:$A$70,0),6)=0,"",INDEX('Overton Borough Receipts'!$A$4:$F$70,MATCH('Overton Borough Overview'!$A9,'Overton Borough Receipts'!$A$4:$A$70,0),6))
A10: Issues of the Manor total | G10: =IF(INDEX('Overton Borough Receipts'!$A$4:$F$70,MATCH('Overton Borough Overview'!$A10,'Overton Borough Receipts'!$A$4:$A$70,0),6)=0,"",INDEX('Overton Borough Receipts'!$A$4:$F$70,MATCH('Overton Borough Overview'!$A10,'Overton Borough Receipts'!$A$4:$A$70,0),6))
A11: Sale of corn total | G11: ='Overton Borough Receipts'!F44
A12: Entry and marriage fines total | G12: =IF(INDEX('Overton Borough Receipts'!$A$4:$F$70,MATCH('Overton Borough Overview'!$A12,'Overton Borough Receipts'!$A$4:$A$70,0),6)=0,"",INDEX('Overton Borough Receipts'!$A$4:$F$70,MATCH('Overton Borough Overview'!$A12,'Overton Borough Receipts'!$A$4:$A$70,0),6))
A13: Pleas & perquisites total | G13: =IF(INDEX('Overton Borough Receipts'!$A$4:$F$70,MATCH('Overton Borough Overview'!$A13,'Overton Borough Receipts'!$A$4:$A$70,0),6)=0,"",INDEX('Overton Borough Receipts'!$A$4:$F$70,MATCH('Overton Borough Overview'!$A13,'Overton Borough Receipts'!$A$4:$A$70,0),6))
A14: Sum of the above (incl. arrears) | G14: =SUM(G5:G13)-SUM(G7:G8)
A15: Total recorded in the accounts excl. arrears | G15: ='Overton Borough Receipts'!F69 | H15: =G14-G15
A16: Total recorded in the accounts incl. arrears | G16: ='Overton Borough Receipts'!F70
A19: EXPENSES
A20: Cost of ploughs total | G20: =IF(INDEX('Overton Borough Expenses'!$A$2:$F$120,MATCH('Overton Borough Overview'!$A20,'Overton Borough Expenses'!$A$2:$A$120,0),6)=0,"",INDEX('Overton Borough Expenses'!$A$2:$F$120,MATCH('Overton Borough Overview'!$A20,'Overton Borough Expenses'!$A$2:$A$120,0),6))
A21: Purchase of corn total | G21: =IF(INDEX('Overton Borough Expenses'!$A$2:$F$120,MATCH('Overton Borough Overview'!$A21,'Overton Borough Expenses'!$A$2:$A$120,0),6)=0,"",INDEX('Overton Borough Expenses'!$A$2:$F$120,MATCH('Overton Borough Overview'!$A21,'Overton Borough Expenses'!$A$2:$A$120,0),6))
A22: Cost of carts and wagons total | G22: =IF(INDEX('Overton Borough Expenses'!$A$2:$F$120,MATCH('Overton Borough Overview'!$A22,'Overton Borough Expenses'!$A$2:$A$120,0),6)=0,"",INDEX('Overton Borough Expenses'!$A$2:$F$120,MATCH('Overton Borough Overview'!$A22,'Overton Borough Expenses'!$A$2:$A$120,0),6))
A23: Cost of dairy total | G23: =IF(INDEX('Overton Borough Expenses'!$A$2:$F$120,MATCH('Overton Borough Overview'!$A23,'Overton Borough Expenses'!$A$2:$A$120,0),6)=0,"",INDEX('Overton Borough Expenses'!$A$2:$F$120,MATCH('Overton Borough Overview'!$A23,'Overton Borough Expenses'!$A$2:$A$120,0),6))
A24: Purchase of stock total | G24: =IF(INDEX('Overton Borough Expenses'!$A$2:$F$120,MATCH('Overton Borough Overview'!$A24,'Overton Borough Expenses'!$A$2:$A$120,0),6)=0,"",INDEX('Overton Borough Expenses'!$A$2:$F$120,MATCH('Overton Borough Overview'!$A24,'Overton Borough Expenses'!$A$2:$A$120,0),6))
A25: Sheepcote total | G25: =IF(INDEX('Overton Borough Expenses'!$A$2:$F$120,MATCH('Overton Borough Overview'!$A25,'Overton Borough Expenses'!$A$2:$A$120,0),6)=0,"",INDEX('Overton Borough Expenses'!$A$2:$F$120,MATCH('Overton Borough Overview'!$A25,'Overton Borough Expenses'!$A$2:$A$120,0),6))
A26: Cost of buildings total | G26: =IF(INDEX('Overton Borough Expenses'!$A$2:$F$120,MATCH('Overton Borough Overview'!$A26,'Overton Borough Expenses'!$A$2:$A$120,0),6)=0,"",INDEX('Overton Borough Expenses'!$A$2:$F$120,MATCH('Overton Borough Overview'!$A26,'Overton Borough Expenses'!$A$2:$A$120,0),6))
A27: Threshing total | G27: =IF(INDEX('Overton Borough Expenses'!$A$2:$F$120,MATCH('Overton Borough Overview'!$A27,'Overton Borough Expenses'!$A$2:$A$120,0),6)=0,"",INDEX('Overton Borough Expenses'!$A$2:$F$120,MATCH('Overton Borough Overview'!$A27,'Overton Borough Expenses'!$A$2:$A$120,0),6))
A28: Expenses of the harvest total | G28: =IF(INDEX('Overton Borough Expenses'!$A$2:$F$120,MATCH('Overton Borough Overview'!$A28,'Overton Borough Expenses'!$A$2:$A$120,0),6)=0,"",INDEX('Overton Borough Expenses'!$A$2:$F$120,MATCH('Overton Borough Overview'!$A28,'Overton Borough Expenses'!$A$2:$A$120,0),6))
A29: Steward's expenses total | G29: =IF(INDEX('Overton Borough Expenses'!$A$2:$F$120,MATCH('Overton Borough Overview'!$A29,'Overton Borough Expenses'!$A$2:$A$120,0),6)=0,"",INDEX('Overton Borough Expenses'!$A$2:$F$120,MATCH('Overton Borough Overview'!$A29,'Overton Borough Expenses'!$A$2:$A$120,0),6))
A30: Sum of the above | G30: =SUM(G20:G29)
A31: Total of all expenses | G31: ='Overton Borough Expenses'!F115 | H31: =G30-G31
A32: Capital Expenses | G32: ='Overton Borough Expenses'!F120
A34: Owed by the reeve
A35: From accounts
A37: Cash deliveries
A38: Total of all allowances and cash deliveries in accounts | B38: n/a
A40: Net amount owed
A41: Net amount owed in accounts | H41: =G40-G41
A43: GRANGE ACCOUNT | B43: Net Production
A44: Grange | B44: qrs | G44: £ | I44: Note: Columns indexed are hardcoded, do not alter number of columns in issues of grange
A45: Net wheat | B45: =IF(INDEX('Issues of the Grange'!$A$2:$P$24,MATCH('Overton Borough Overview'!$A45,'Issues of the Grange'!$A$2:$A$24,0),10)=0,"",INDEX('Issues of the Grange'!$A$2:$P$24,MATCH('Overton Borough Overview'!$A45,'Issues of the Grange'!$A$2:$A$24,0),10)) | G45: =IF(INDEX('Issues of the Grange'!$A$2:$P$24,MATCH('Overton Borough Overview'!$A45,'Issues of the Grange'!$A$2:$A$24,0),13)=0,"",INDEX('Issues of the Grange'!$A$2:$P$24,MATCH('Overton Borough Overview'!$A45,'Issues of the Grange'!$A$2:$A$24,0),13))
A46: Net curall | B46: =IF(INDEX('Issues of the Grange'!$A$2:$P$24,MATCH('Overton Borough Overview'!$A46,'Issues of the Grange'!$A$2:$A$24,0),10)=0,"",INDEX('Issues of the Grange'!$A$2:$P$24,MATCH('Overton Borough Overview'!$A46,'Issues of the Grange'!$A$2:$A$24,0),10)) | G46: =IF(INDEX('Issues of the Grange'!$A$2:$P$24,MATCH('Overton Borough Overview'!$A46,'Issues of the Grange'!$A$2:$A$24,0),13)=0,"",INDEX('Issues of the Grange'!$A$2:$P$24,MATCH('Overton Borough Overview'!$A46,'Issues of the Grange'!$A$2:$A$24,0),13))
A47: Net barley | B47: =IF(INDEX('Issues of the Grange'!$A$2:$P$24,MATCH('Overton Borough Overview'!$A47,'Issues of the Grange'!$A$2:$A$24,0),10)=0,"",INDEX('Issues of the Grange'!$A$2:$P$24,MATCH('Overton Borough Overview'!$A47,'Issues of the Grange'!$A$2:$A$24,0),10)) | G47: =IF(INDEX('Issues of the Grange'!$A$2:$P$24,MATCH('Overton Borough Overview'!$A47,'Issues of the Grange'!$A$2:$A$24,0),13)=0,"",INDEX('Issues of the Grange'!$A$2:$P$24,MATCH('Overton Borough Overview'!$A47,'Issues of the Grange'!$A$2:$A$24,0),13))
...

Sheet Overton Borough Receipts
A1: OVERTON BOROUGH RECEIPTS
B2: £ | C2: s | D2: d | F2: Total in £ | G2: Error | H2: Notes
A4: Arrears
A5: Arrears total | B5: 2 | C5: 1 | D5: 2.5 | F5: =B5+C5/20+D5/240
A6: of which delivered to treasurer of Wolvesey | B6: 2 | C6: 1 | D6: 2.5 | F6: =B6+C6/20+D6/240
A8: Rents of assize
A9: renst of assize for the year all paid at Michaelmas | B9: 8 | C9: 4 | D9: 3.5 | F9: =B9+C9/20+D9/240
A10: Total recorded in accounts | B10: 8 | C10: 4 | D10: 3.5 | F10: =B10+C10/20+D10/240
A11: Rents of assize total | B11: =SUM(B9:B9) | C11: =SUM(C9:C9) | D11: =SUM(D9:D9) | F11: =B11+C11/20+D11/240 | G11: =F11-F10
A13: Quittances
A14: one reeve for the year | C14: 2 | F14: =B14+C14/20+D14/240
A15: Total recorded in accounts | C15: 2 | F15: =B15+C15/20+D15/240
A16: Quittances total | B16: =SUM(B14:B14) | C16: =SUM(C14:C14) | D16: =SUM(D14:D14) | F16: =B16+C16/20+D16/240 | G16: =F16-F15
A18: Defaults of rent
A19: default of the house of Gilbert le Pynk | D19: 6 | F19: =B19+C19/20+D19/240
A20: Total recorded in accounts | D20: 6 | F20: =B20+C20/20+D20/240
A21: Defaults of rent total | B21: =SUM(B19:B19) | C21: =SUM(C19:C19) | D21: =SUM(D19:D19) | F21: =B21+C21/20+D21/240 | G21: =F21-F20
A23: Total of rents remaining | B23: 8 | C23: 1 | D23: 9.5 | F23: =B23+C23/20+D23/240 | H23: not included in receipts
A25: Wax
F26: =B26+C26/20+D26/240
A27: Total recorded in accounts | F27: =B27+C27/20+D27/240
A28: Wax total | B28: =SUM(B26) | C28: =SUM(C26) | D28: =SUM(D26) | F28: =B28+C28/20+D28/240 | G28: =F28-F27
A30: Annual recognizances
A31: from Richard Hayward | D31: 6 | F31: =B31+C31/20+D31/240
A32: Total recorded in accounts | D32: 6 | F32: =B32+C32/20+D32/240
A33: Annual recognizances total | B33: =SUM(B31:B31) | C33: =SUM(C31:C31) | D33: =SUM(D31:D31) | F33: =B33+C33/20+D33/240 | G33: =F33-F32
A35: Selds and stalls (no issue of the manor)
A36: 16 selds hired in the borough | C36: 10 | D36: 8 | F36: =B36+C36/20+D36/240
A37: 32 stalls | C37: 5 | D37: 4 | F37: =B37+C37/20+D37/240
A38: Total recorded in accounts | C38: 16 | F38: =B38+C38/20+D38/240
A39: Issues of the manor total | B39: =SUM(B36:B37) | C39: =SUM(C36:C37) | D39: =SUM(D36:D37) | F39: =B39+C39/20+D39/240 | G39: =F39-F38
A41: Sale of corn
A42: nothing | F42: =B42+C42/20+D42/240
A43: Total recorded in accounts | F43: =B43+C43/20+D43/240
A44: Sale of corn total | B44: =SUM(B42:B42) | C44: =SUM(C42:C42) | D44: =SUM(D42:D42) | F44: =B44+C44/20+D44/240 | G44: =F44-F43
A46: Entry and marriage fines
A47: nothing | F47: =B47+C47/20+D47/240
A48: Total recorded in accounts | F48: =B48+C48/20+D48/240
A49: Entry and marriage fines total | B49: =SUM(B47:B47) | C49: =SUM(C47:C47) | D49: =SUM(D47:D47) | F49: =B49+C49/20+D49/240 | G49: =F49-F48
A52: Farm of Freefolk
...

Sheet Overton Borough Expenses
A1: OVERTON BOROUGH EXPENSES
B2: £ | C2: s | D2: d | F2: Total in £ | G2: Error | H2: Notes
A3: Cost of Ploughs
F4: =B4+C4/20+D4/240
F5: =B5+C5/20+D5/240
F6: =B6+C6/20+D6/240
F7: =B7+C7/20+D7/240
F8: =B8+C8/20+D8/240
F9: =B9+C9/20+D9/240
F10: =B10+C10/20+D10/240
F11: =B11+C11/20+D11/240
F12: =B12+C12/20+D12/240
F13: =B13+C13/20+D13/240
F14: =B14+C14/20+D14/240
F15: =B15+C15/20+D15/240
A16: Total recorded in accounts | F16: =B16+C16/20+D16/240
A17: Cost of ploughs total | B17: =SUM(B3:B15) | C17: =SUM(C3:C15) | D17: =SUM(D3:D15) | F17: =B17+C17/20+D17/240 | G17: =F17-F16
A18: Total capital expenses | B18: =SUM(B4:B7,B9,B10:B11,B13,B15) | C18: =SUM(C4:C7,C9,C10:C11,C13,C15) | D18: =SUM(D4:D7,D9,D10:D11,D13,D15) | F18: =B18+C18/20+D18/240
A20: Purchase of Corn
F21: =B21+C21/20+D21/240
A22: Total recorded in accounts | F22: =B22+C22/20+D22/240
A23: Purchase of corn total | B23: =SUM(B21) | C23: =SUM(C21) | D23: =SUM(D21) | F23: =B23+C23/20+D23/240 | G23: =F23-F22
A25: Cost of Carts and Wagons
F26: =B26+C26/20+D26/240
F27: =B27+C27/20+D27/240
F28: =B28+C28/20+D28/240
F29: =B29+C29/20+D29/240
F30: =B30+C30/20+D30/240
F31: =B31+C31/20+D31/240
F32: =B32+C32/20+D32/240
F33: =B33+C33/20+D33/240
F34: =B34+C34/20+D34/240
F35: =B35+C35/20+D35/240
F36: =B36+C36/20+D36/240
F37: =B37+C37/20+D37/240
... F40: =B40+C40/20+D40/240
A41: Total recorded in accounts | F41: =B41+C41/20+D41/240
A42: Cost of carts and wagons total | B42: =SUM(B26:B40) | C42: =SUM(C26:C40) | D42: =SUM(D26:D40) | F42: =B42+C42/20+D42/240 | G42: =F42-F41
A43: Total capital expenses | B43: =SUM(B26:B39) | C43: =SUM(C26:C39) | D43: =SUM(D26:D39) | F43: =B43+C43/20+D43/240
A45: Cost of Dairy
...

Sheet Issues of the Grange
A1: no grange

Sheet Stock
A2: no stock account

Sheet Assumptions
A1: ASSUMPTIONS
B3: Weights | C3: Value (in lbs) | D3: Value (in cloves) | E3: Value (in weys) | F3: Value (in stone)
B4: Lbs | C4: 1 | D4: =C4/C5 | E4: =C4/C6 | F4: =C4/C7
B5: Cloves | C5: 7 | D5: 1 | E5: =C5/C6 | F5: =C7/C5
B6: Wey | C6: 175 | D6: =C6/C5 | E6: =C6/C6 | F6: =C7/C6
B7: Stone | C7: =175/14 | D7: =C5/C7 | E7: =C7/C6 | F7: 1
