Workbook

Sheet Rimpton Overview - Completed
A1: RIMPTON OVERVIEW - COMPLETED | B1: Total in £ | C1: Error | D1: Note
A2: CASH ACCOUNT
A3: RECEIPTS
A4: Arrears total
A5: Rents of assize total | B5: 4.885
A6: Quittances total | B6: 2.55
A7: Defaults of rent total | B7: 0.05
A8: Defaults of rent through the pestilence total
A9: Cotlands defaults total
A10: Cotlands total
A11: Total of quittances and defaults of rent total | B11: 2.6
A12: Total of rents remaining clear total
A13: Farms total
A14: Annual recognizances total
A15: Issues of the Manor total | B15: 16.64
A16: Issues of the tenements in the lord's hands total
A17: Sale of labour services total
A18: Sale of corn total | B18: 46.025
A19: Entry and marriage fines total | B19: 11.37
A20: Pleas & perquisites total
A21: Forfeited chattels total
A22: Farm of the demesne land total
A23: Total of all receipts (calculated here) | B23: =SUM(B5:B22)
A24: Total of all receipts (calculated here) incl arrears | B24: =SUM(B4:B22)
A25: Total recorded in the accounts excl. arrears | C25: =B23-B25
A26: Total recorded in the accounts incl. arrears | B26: =B25+B4
A29: EXPENSES
A30: Cost of ploughs total | B30: 8.11
A31: Purchase of corn total
A32: Cost of carts and wagons total
A33: Cost of dairy total
A34: Purchase of stock total
A35: Sheepcote total
A36: Cost of buildings total
A37: Threshing total
A38: Barley expenses
A39: Expenses of the harvest total
A40: Necessary expenses
A41: Wages of the bailiff
A42: Steward's expenses total
...

Sheet Prices
A1: Meat & Dairy Prices
C2: 1301 | D2: 1302 | E2: Average
A3: Beef | B3: £ per lb | C3: 0.0033351854 | D3: 0.0032608538 | E3: =AVERAGE(C3:D3)
A4: Mutton | B4: £ per lb | C4: 0.0036593977 | D4: 0.0037125513 | E4: =AVERAGE(C4:D4)
A5: Pork | B5: £ per lb | C5: 0.0038431326 | D5: 0.0037574803 | E5: =AVERAGE(C5:D5)
A6: Cheese | B6: £ per lb | C6: 0.0055768754 | D6: 0.0056654898 | E6: =AVERAGE(C6:D6)
A7: Butter | B7: £ per lb | C7: 0.0036626221 | D7: 0.0035935077 | E7: =AVERAGE(C7:D7)
A8: Milk | B8: £ per gallon | C8: 0.0055768754 | D8: 0.0056654898 | E8: =AVERAGE(C8:D8)

Sheet Labour Rents

Sheet Overview
A1: RIMPTON | B1: Total in £ | C1: Error | D1: Note
A2: CASH ACCOUNT
A3: RECEIPTS
A4: Arrears total
A5: Rents of assize total
A6: Quittances total
A7: Defaults of rent total
A8: Defaults of rent through the pestilence total
A9: Cotlands defaults total
A10: Cotlands total
A11: Total of quittances and defaults of rent total
A12: Total of rents remaining clear total
A13: Farms total
... A183: % of capital expenses as calculated previously

Sheet Receipts
A1: RIMPTON RECEIPTS
A2: Heading | B2: £ | C2: s | D2: d | F2: Total in £ | G2: Error | H2: Notes
A3: Rents of assize | B3: 1 | C3: 4 | D3: 6 | F3: =B3+C3/20+D3/240 | H3: Henry le Whyte and Robert Boye, reeve of Rimpton, render account for £1 4shilling 6pence for rents at Christmas.
A4: Rents of assize | B4: 1 | C4: 4 | D4: 6 | F4: 1.22 | H4: £1 4 shilling 6pence at Easter (22 April).
A5: Rents of assize | B5: 1 | C5: 4 | D5: 6 | F5: 1.22 | H5: £1 4 shilling 6pence at the Nativity of the blessed John the Baptist (24 June).
A6: Rents of assize | B6: 1 | C6: 4 | D6: 6 | F6: 1.22 | H6: £1 4 shilling 6pence at Michaelmas (29 September).
A7: Rents of assize | B7: 4 | C7: 18 | D7: 0 | F7: 4.9 | H7: Total, £4 18 shilling
A8: Rents of assize | F8: =SUM(F3:F6) | G8: =F8-F7 | H8: Total
A10: Quittances | B10: 0 | C10: 3 | D10: 0 | F10: 0.15 | H10: In quittance of 1 reeve for the year 3 shilling.
A11: Quittances | B11: 0 | C11: 12 | D11: 0 | F11: 0.6 | H11: 4 ploughmen, 2 ox-drovers for the year 12 shilling.
A12: Quittances | B12: 1 | C12: 16 | D12: 0 | F12: 1.8 | H12: 18 workers who harrowed, gripped, dug, threshed corn, mowed meadows, tossed and carried hay, reaped and carried corn at harvest-time, and did other necessary work, £1 16 shilling for the year, or 2 shilling each.
A13: Quittances | B13: 2 | C13: 11 | D13: 0 | F13: 2.55 | H13: Total, £2 11 shilling
A14: Quittances | F14: 2.55 | G14: 0 | H14: Total
A16: Defaults of rent | B16: 0 | C16: 1 | D16: 0 | F16: 0.05 | H16: In default of the house and curtilage of John de Molendino because it is in demesne 1 shilling
A17: Defaults of rent | B17: 0 | C17: 1 | D17: 0 | F17: =B17+C17/20+D17/240 | H17: Total, 1 shilling
A18: Defaults of rent | F18: 0.05 | G18: 0 | H18: Total
A20: Total of quittances and defaults of rent | B20: 2 | C20: 12 | D20: 0 | F20: 2.6 | H20: Total of quittances and defaults of rent, £2 12 shilling
A21: Total of quittances and defaults of rent | F21: 2.6 | G21: =F21-F20 | H21: Total
A23: Total of rents remaining | B23: 2 | C23: 6 | D23: 0 | F23: 2.3 | H23: Total of rents remaining, £2 6 shilling
A24: Total of rents remaining | F24: 2.3 | G24: =F24-F23 | H24: Total
A26: Issues of the manor | B26: 0 | C26: 4 | D26: 9.5 | F26: 0.24 | H26: The same render account for 4 shilling 9.5pence from pannage of 48 pigs and 19 hoggets this year, at 1pence a pig and 0.5pence a hogget.
A27: Issues of the manor | B27: 0 | C27: 3 | D27: 0 | F27: 0.15 | H27: 3 shilling from churchscot at Martinmas (11 November).
A28: Issues of the manor | B28: 0 | C28: 8 | D28: 6 | F28: 0.43 | H28: 8 shilling 6pence from the pasturage of 17 oxen sold in winter.
A29: Issues of the manor | B29: 0 | C29: 9 | D29: 4 | F29: 0.47 | H29: 9 shilling 4pence from the pasturage of 24 plough-horses and 8 colts sold after Martinmas, at 4pence a plough-horse and 2pence a colt.
A30: Issues of the manor | B30: 0 | C30: 0 | D30: 0 | F30: 0 | H30: nothing from the pasturage of la Grutte for the lord's stock.
A31: Issues of the manor | B31: 0 | C31: 2 | D31: 0 | F31: 0.1 | H31: 2 shilling from the pasturage of Alsyesham sold in summer.
A32: Issues of the manor | B32: 0 | C32: 0 | D32: 6 | F32: 0.03 | H32: 6pence from the pasturage sold at Oclefurlong and not more because the field was sown with summer corn (tremes') this year.
A33: Issues of the manor | B33: 0 | C33: 1 | D33: 2 | F33: 0.06 | H33: 1 shilling 2pence from the pasturage of la Portweye this year.
A34: Issues of the manor | B34: 0 | C34: 1 | D34: 6 | F34: 0.08 | H34: 1 shilling 6pence from the pasturage of Wetenegarston'.
A35: Issues of the manor | B35: 0 | C35: 0 | D35: 10 | F35: 0.04 | H35: 10pence from the pasturage of Parva Sterte sold this year.
A36: Issues of the manor | B36: 0 | C36: 1 | D36: 2 | F36: 0.06 | H36: 1 shilling 2pence from the pasturage of Magna Sterte.
A37: Issues of the manor | B37: 0 | C37: 0 | D37: 0 | F37: 0 | H37: nothing from the pasturage beside la Marlygputte this year because it is fallow.
... A63: Issues of the manor | B63: 16 | C63: 11 | D63: 9.5 | F63: 16.59 | H63: Total, £16 11 shilling 9.5pence
A64: Issues of the manor | F64: 16.64 | G64: 0.05 | H64: Total
A66: Sale of corn | B66: =32+1 | C66: =7+3 | D66: 5.75 | F66: =B66+C66/12+D66/20 | H66: The same render account for £32 7 shilling from 121 quarters 2.5 bushels of wheat sold, at 5 shilling 4pence a qr, £1 3 shilling 5.75pence from 6 quarters 1 bushels of curall sold, at 3 shilling 10pence a qr.
A67: Sale of corn | B67: 3 | C67: 0 | D67: 1 | F67: 3 | H67: £3 1pence from 12 quarters 7 bushels of maslin sold, at 4 shilling 8pence a qr.
A68: Sale of corn | B68: 0 | C68: 4 | D68: 7 | F68: =B68+C68/20+D68/240 | H68: 4 shilling 7pence from 1 qr 3 bushels of barley sold, at 3 shilling 4pence a qr.
A69: Sale of corn | B69: 1 | C69: 12 | D69: 6 | F69: =B69+C69/20+D69/240 | H69: £1 12 shilling 6pence from 16 quarters 2 bushels of beans sold, at 2 shilling a qr.
A70: Sale of corn | B70: 0 | C70: 11 | D70: 9 | F70: 0.59 | H70: 11 shilling 9pence from 5 quarters 7 bushels of peas sold, at 2 shilling a qr.
A71: Sale of corn | B71: 0 | C71: 1 | D71: 10 | F71: 0.09 | H71: 1 shilling 10pence from 1 qr 3 bushels of vetches sold, at 2pence a bushels.
...

Sheet Expenses
A1: RIMPTON EXPENSES
A2: Heading | B2: £ | C2: s | D2: d | F2: Total in £ | G2: Error | H2: Notes
A3: Cost of ploughs | B3: 0 | C3: 4 | D3: 1.75 | F3: 0.21 | H3: In iron bought to maintain the ironwork of 4 ploughs for the year 4 shilling 1.75pence.
A4: Cost of ploughs | B4: 0 | C4: 3 | D4: 6.5 | F4: 0.18 | H4: stipend of the smith repairing and restoring the ironwork of the said ploughs for the year 3 shilling 6.5pence.
A5: Cost of ploughs | B5: 0 | C5: 0 | D5: 5.5 | F5: 0.02 | H5: 8 yokes bought for ploughs 5.5pence.
A6: Cost of ploughs | B6: 0 | C6: 0 | D6: 9 | F6: 0.04 | H6: 5 yokes bought 9pence.
A7: Cost of ploughs | B7: 0 | C7: 2 | D7: 2 | F7: 0.11 | H7: expenses of 1 boon-work of 36 ploughmen and 24 harrowers, ploughing and harrowing 37 acres for the winter sowing, besides bread from stock: ale bought 2 shilling 2pence.
A8: Cost of ploughs | B8: 0 | C8: 2 | D8: 3 | F8: 0.11 | H8: meat bought 2 shilling 3pence.
A9: Cost of ploughs | B9: 0 | C9: 0 | D9: 3 | F9: 0.01 | H9: cheese bought 3pence.
A10: Cost of ploughs | B10: 0 | C10: 0 | D10: 11 | F10: 0.05 | H10: 1 boon-work of 11 ploughmen working on the fallow according to custom 11pence.
A11: Cost of ploughs | B11: 2 | C11: 9 | D11: 2 | F11: 2.46 | H11: 4 oxen bought £2 9 shilling 2pence, at 12 shilling 3.5pence each.
A12: Cost of ploughs | B12: 1 | C12: 13 | D12: 0.75 | F12: 1.65 | H12: 3 oxen bought £1 13 shilling 0.75pence, at 11 shilling 0.25pence each.
A13: Cost of ploughs | B13: 2 | C13: 14 | D13: 7 | F13: 2.73 | H13: 5 oxen bought £2 14 shilling 7pence, at 10 shilling 11pence each.
A14: Cost of ploughs | B14: 0 | C14: 0 | D14: 3 | F14: 0.01 | H14: blood-letting of oxen 3pence.
A15: Cost of ploughs | B15: 0 | C15: 0 | D15: 6 | F15: 0.03 | H15: hiring 2 men for 6 days to hold the ploughs whilst the ploughmen of the vii mow the meadows 6pence.
A16: Cost of ploughs | B16: 0 | C16: 10 | D16: 0 | F16: =B16+C16/20+D16/240 | H16: stipend of 2 ox-drovers for the year 10 shilling
A17: Cost of ploughs | B17: 8 | C17: 2 | D17: 0.5 | F17: 8.1 | H17: Total, £8 2 shilling 0.5pence
A18: Cost of ploughs | F18: =SUM(F3:F16) | G18: =F18-F17 | H18: Total
A20: Cost of the mill | B20: 0 | C20: 8 | D20: 3 | F20: 0.41 | H20: In one stone millstone bought for the mill 8 shilling 3pence.
A21: Cost of the mill | B21: 0 | C21: 0 | D21: 5 | F21: 0.02 | H21: making one mill-spindle 5pence.
A22: Cost of the mill | B22: 0 | C22: 0 | D22: 2.5 | F22: 0.01 | H22: nails bought for the mill-wheel 2.5pence.
A23: Cost of the mill | B23: 0 | C23: 5 | D23: 0 | F23: 0.25 | H23: stipend of the miller for the year 5 shilling.
A24: Cost of the mill | B24: 0 | C24: 2 | D24: 0 | F24: =B24+C24/20+D24/240 | H24: quittance of the tithe of the mill 2 shilling
A25: Cost of the mill | B25: 0 | C25: 15 | D25: 10.5 | F25: =B25+C25/20+D25/240 | H25: Total, 15 shilling 10.5pence
A26: Cost of the mill | F26: =SUM(F20:F24) | G26: =F26-F25 | H26: Total
A28: Steward's expenses | B28: 0 | C28: 8 | D28: 8 | F28: 0.43 | H28: In expenses of the steward and his clerk for their visits to view the state of the manor, to hold court, and to expedite other business of the lord, 8 shilling 8pence by 2 tallies.
A29: Steward's expenses | B29: 0 | C29: 8 | D29: 8 | F29: 0.43 | H29: Total, 8 shilling 8pence
A30: Steward's expenses | F30: 0.43 | G30: 0 | H30: Total
A32: Bailiff's expenses | B32: 3 | C32: 0 | D32: 10 | F32: 3.04 | H32: In expenses of the bailiff for the year £3 10pence, at 2pence a day.
A33: Bailiff's expenses | B33: 3 | C33: 0 | D33: 10 | F33: 3.04 | H33: Total, £3 10pence
A34: Bailiff's expenses | F34: 3.04 | G34: 0 | H34: Total
A36: Total of all expenses | B36: 14 | C36: 0 | D36: 0 | F36: 14 | H36: Total of all expenses, £14 1 1 shilling 9.5pence
A37: Total of all expenses | B37: 63 | C37: 0 | D37: 11.75 | F37: 63.05 | H37: And thus he owes, £63 11.75pence
A38: Total of all expenses | F38: 63.05 | G38: 0 | H38: Total
A41: Cash deliveries | B41: 38 | C41: 0 | D41: 0 | F41: 38 | H41: Delivered to Sir Geoffrey, treasurer of Wolvesey, by 1 tally, £38. Total, £38.
A43: Cash deliveries | B43: 25 | C43: 0 | D43: 11.75 | F43: 25.05 | H43: And thus he owes clear, £25 11.75pence

Sheet Issues of the Grange
A1: Gross Output | B1: Total Quantity | C1: Account Total Quarters | D1: Bought in Total Quarters | E1: Received from churchscot | F1: Sold Total Quarters | G1: Difference Produced+Bought-Sold | H1: Weighted Average Price per Quarter | I1: Value of Total Production weighted
A2: wheat | B2: 144.5 | C2: 144.5 | D2: 0 | F2: 121.3125 | G2: =B2-F2 | H2: 0.26666667 | I2: =H2*B2
A3: curall | B3: 20.125 | C3: 20.125 | D3: 0 | F3: 6.125 | G3: =B3-F3 | H3: 0.19166667 | I3: =H3*B3
A4: maslin | B4: 12.875 | C4: 12.875 | D4: 0 | F4: 12.875 | G4: =B4-F4 | H4: 0.23333333 | I4: =H4*B4
A5: barley | B5: 10 | C5: 10 | D5: 0 | F5: 4 | G5: =B5-F5 | H5: 0.16666667 | I5: =H5*B5
A6: beans | B6: 28.25 | C6: 28.25 | D6: 0 | F6: 16.25 | G6: =B6-F6 | H6: 0.1 | I6: =H6*B6
A7: peas | B7: 7.625 | C7: 7.625 | D7: 0 | F7: 5.875 | G7: =B7-F7 | H7: 0.1 | I7: =H7*B7
A8: vetches | B8: 1.75 | C8: 1.75 | D8: 0 | F8: 1.375 | G8: =B8-F8 | H8: 0.066666667 | I8: =H8*B8
A9: oats | B9: 107.875 | C9: 107.875 | D9: 0 | F9: 54.75 | G9: =B9-F9 | H9: 0.10833333 | I9: =H9*B9
A11: Total Production
A12: Sales of corn (as recorded in accounts)
A14: Net output | B14: Gross output | C14: Seed quarters | D14: Seed bushels | E14: Seed total quarters | F14: tithe quarters | G14: tithe bushels | H14: tithe total | I14: manorial servants quarters | J14: manorial servants bushels | K14: manorial servants total quarters | L14: output net of tithe, seed, liveries | M14: in stock from last year | N14: Price in £ | O14: Value of net output in £ | P14: Value of sales (in "Sale of Corn") in £
A15: wheat | B15: =B2 | C15: 22 | D15: 0.5 | E15: =C15+D15/8 | J15: 3 | K15: =I15+J15/8 | L15: =B15-E15-H15-K15 | N15: =H2 | O15: =N15*L15
A16: curall | B16: =B3 | E16: =C16+D16/8 | I16: 14 | K16: =I16+J16/8 | L16: =B16-E16-H16-K16 | N16: =H3 | O16: =N16*L16
A17: maslin | B17: =B4 | E17: =C17+D17/8 | K17: =I17+J17/8 | L17: =B17-E17-H17-K17 | N17: =H4 | O17: =N17*L17
A18: barley | B18: =B5 | D18: 7.5 | E18: =C18+D18/8 | I18: 4 | J18: =5+3.5 | K18: =I18+J18/8 | L18: =B18-E18-H18-K18 | N18: =H5 | O18: =N18*L18
A19: beans | B19: =B6 | C19: 7 | D19: 2 | E19: =C19+D19/8 | I19: =2.5+2 | J19: =2 | K19: =I19+J19/8 | L19: =B19-E19-H19-K19 | N19: =H6 | O19: =N19*L19
A20: peas | B20: =B7 | D20: 2 | E20: =C20+D20/8 | I20: =1.5 | K20: =I20+J20/8 | L20: =B20-E20-H20-K20 | N20: =H7 | O20: =N20*L20
A21: vetches | B21: =B8 | D21: 3 | E21: =C21+D21/8 | K21: =I21+J21/8 | L21: =B21-E21-H21-K21 | N21: =H8 | O21: =N21*L21
A22: oats | B22: =B9 | C22: 48 | E22: =C22+D22/8 | I22: =1+1.5+1+1 | K22: =I22+J22/8 | L22: =B22-E22-H22-K22 | N22: =H9 | O22: =N22*L22
A24: Total

Sheet Issues of the Mills

Sheet Stock
A1: RIMPTON STOCK ACCOUNT
C3: added | G3: subtracted
A4: Livestock | B4: Inherited stock | C4: added | D4: strays | E4: herbage | F4: churchscot | G4: of which in default | H4: sold | I4: in murrain | J4: accounted for elsewhere | K4: End-period stock | L4: cross-check | M4: stock building | N4: raw production | O4: Unit price (£) | P4: Value of stock (£) at given value | Q4: Value of stock (£) at sales prices | R4: Sales in (£) | S4: Value of stock building (£) | T4: Value of production (£) at sales prices | U4: Details
A5: Cart-horses
A6: Mares
A7: Plough horses | B7: 2 | C7: 1 | H7: 1 | K7: 2 | O7: =R7/H7 | R7: =Receipts!F44
A8: Colts (unspecified years) | B8: 2 | C8: 1 | H8: 1 | K8: 2 | O8: =R8/H8 | R8: =Receipts!F43
A9: Colts (2 years)
A10: Colts (1 year)
A11: Foals
A12: Oxen | B12: 36 | C12: =2+1+12 | H12: 13 | I12: 3 | K12: 35 | O12: =R12/H12 | R12: =Receipts!F45+Receipts!F46+Receipts!F47
A13: Bulls | B13: 1 | K13: 1
A14: Cows | B14: 18 | I14: =2+2 | K14: 14
A15: Steers | B15: 5 | I15: 3 | J15: 2 | K15: 5
A16: Bullocks | B16: 6 | H16: 1 | I16: 2 | K16: 3 | O16: =R16/H16 | R16: =Receipts!F48
A17: Yearlings | B17: 9 | K17: 9
A18: Calves | B18: 14 | I18: 7 | J18: 1 | K18: 6
A19: Wethers
A20: Rams
A21: Ewes
A22: Hoggs
A23: Lambs
A24: Boars
A25: Sows
A26: Pigs | B26: 16 | C26: 38 | H26: 25 | I26: 2 | K26: 27 | O26: =R26/H26 | R26: =Receipts!F50+Receipts!F49
A27: Hoggets | B27: 38 | J27: 38 | K27: 0
A28: Piglets | C28: =14+13+17 | I28: 8 | J28: 4 | K28: 32
A29: Swans
A30: Peacocks
A31: Total Value | R31: =SUM(R6:R30)
A34: Wool
A35: Coarse wool
A36: Lamb's wool
A37: Wool locks
A38: Wool sold at shearing
A39: Total wool
A42: Hides
A43: Ox hides | C43: 3 | H43: 3 | K43: 0 | O43: =R43/H43 | R43: =Receipts!F51
A44: cows | C44: 4 | H44: 4 | K44: 0 | O44: =R44/H44 | R44: =Receipts!F52
A45: heifer | C45: 3 | H45: 3 | K45: 0 | O45: =R45/H45 | R45: =Receipts!F53
...

Sheet raw data
A1: Heading | B1: Sentence | C1: Total in Pounds | D1: Pounds | E1: Shillings | F1: Pence | G1: Corn | H1: Total Quarters Except 1 | I1: Total Bushels Except 1 | J1: Total Corn Cross-Check | K1: Total Corn Manorial Account | L1: Corn Quantity Error | M1: Quarters 1 | N1: Bushels 1 | O1: Quarters 2 | P1: Bushels 2 | Q1: Quarters 3 | R1: Bushels 3 | S1: Quarters 4 | T1: Bushels 4 | U1: shilling a quarter 1 | V1: pence a quarter 1 | W1: shilling a quarter 2 | X1: pence a quarter 2 | Y1: shilling a quarter 3 | Z1: pence a quarter 3 | AA1: shilling a quarter 4 | AB1: pence a quarter 4 | AC1: shilling a bushel 1 | AD1: pence a bushel 1 | AE1: shilling a bushel 2 | AF1: pence a bushel 2 | AG1: shilling a bushel 3 | AH1: pence a bushel 3 | AI1: shilling a bushel 4 | AJ1: pence a bushel 4
A2: Rents of assize | B2: Henry le Whyte and Robert Boye, reeve of Rimpton, render account for £14 shilling 6pence for rents at Christmas. | C2: 14 | D2: 14 | E2: 0 | F2: 0 | H2: 0 | I2: 0 | J2: 0 | K2: 0 | L2: 0 | M2: 0 | N2: 0
A3: Rents of assize | B3: £1 4 shilling 6pence at Easter (22 April). | C3: 1.22 | D3: 1 | E3: 4 | F3: 6 | H3: 0 | I3: 0 | J3: 0 | K3: 0 | L3: 0 | M3: 0 | N3: 0
A4: Rents of assize | B4: £1 4 shilling 6pence at the Nativity of the blessed John the Baptist (24 June). | C4: 1.22 | D4: 1 | E4: 4 | F4: 6 | H4: 0 | I4: 0 | J4: 0 | K4: 0 | L4: 0 | M4: 0 | N4: 0
A5: Rents of assize | B5: £1 4 shilling 6pence at Michaelmas (29 September). | C5: 1.22 | D5: 1 | E5: 4 | F5: 6 | H5: 0 | I5: 0 | J5: 0 | K5: 0 | L5: 0 | M5: 0 | N5: 0
A6: Rents of assize | B6: Total, £4 18 shilling | C6: 4.9 | D6: 4 | E6: 18 | F6: 0 | H6: 0 | I6: 0 | J6: 0 | K6: 0 | L6: 0 | M6: 0 | N6: 0
A7: Quittances | B7: In quittance of 1 reeve for the year 3 shilling. | C7: 0.15 | D7: 0 | E7: 3 | F7: 0 | H7: 0 | I7: 0 | J7: 0 | K7: 0 | L7: 0 | M7: 0 | N7: 0
A8: Quittances | B8: 4 ploughmen, 2 ox-drovers for the year 12 shilling. | C8: 0.6 | D8: 0 | E8: 12 | F8: 0 | H8: 0 | I8: 0 | J8: 0 | K8: 0 | L8: 0 | M8: 0 | N8: 0
A9: Quittances | B9: 18 workers who harrowed, gripped, dug, threshed corn, mowed meadows, tossed and carried hay, reaped and carried corn at harvest-time, and did other necessary work, £1 16 shilling for the year, or 2 shilling each. | C9: 1.8 | D9: 1 | E9: 16 | F9: 0 | H9: 0 | I9: 0 | J9: 0 | K9: 0 | L9: 0 | M9: 0 | N9: 0
A10: Quittances | B10: Total, £2 11 shilling | C10: 2.55 | D10: 2 | E10: 11 | F10: 0 | H10: 0 | I10: 0 | J10: 0 | K10: 0 | L10: 0 | M10: 0 | N10: 0
A11: Defaults of rent | B11: In default of the house and curtilage of John de Molendino because it is in demesne 1 shilling Total, 1 shilling | C11: 0.05 | D11: 0 | E11: 1 | F11: 0 | H11: 0 | I11: 0 | J11: 0 | K11: 0 | L11: 0 | M11: 0 | N11: 0
A12: Total of quittances and defaults of rent | B12: Total of quittances and defaults of rent, £2 12 shilling | C12: 2.6 | D12: 2 | E12: 12 | F12: 0 | H12: 0 | I12: 0 | J12: 0 | K12: 0 | L12: 0 | M12: 0 | N12: 0
A13: Total of rents remaining | B13: Total of rents remaining, £2 6 shilling | C13: 2.3 | D13: 2 | E13: 6 | F13: 0 | H13: 0 | I13: 0 | J13: 0 | K13: 0 | L13: 0 | M13: 0 | N13: 0
... A51: Issues of the manor | B51: Total, £16 11 shilling 9.5pence | C51: 16.59 | D51: 16 | E51: 11 | F51: 9.5 | H51: 0 | I51: 0 | J51: 0 | K51: 0 | L51: 0 | M51: 0 | N51: 0
A52: Sale of corn | B52: The same render account for £32 7 shilling from 121 quarters 2.5 bushels of wheat sold, at 5 shilling 4pence a quarters, £1 3 shilling 5.75pence from 6 quarters 1 bushels of curall sold, at 3 shilling 10pence a quarters. | C52: 32.35 | D52: 32 | E52: 7 | F52: 0 | G52: curall, wheat | H52: 6 | I52: 1 | J52: 6.125 | K52: 121.3125 | L52: -115.1875 | M52: 121 | N52: 2.5 | O52: 6 | P52: 1 | U52: 5 | V52: 4 | W52: 3 | X52: 10
A53: Sale of corn | B53: £3 1pence from 12 quarters 7 bushels of maslin sold, at 4 shilling 8pence a quarters. | C53: 3 | D53: 3 | E53: 0 | F53: 1 | G53: maslin | H53: 12 | I53: 7 | J53: 12.875 | K53: 12.875 | L53: 0 | M53: 12 | N53: 7 | U53: 4 | V53: 8
A54: Sale of corn | B54: 4 shilling 7pence from 1 quarters 3 bushels of barley sold, at 3 shilling 4pence a quarters, £1 12 shilling 6pence from 16 quarters 2 bushels of beans sold, at 2 shilling a quarters. | C54: 1.62 | D54: 1 | E54: 12 | F54: 6 | G54: barley, beans | H54: 16 | I54: 2 | J54: 16.25 | K54: 1.375 | L54: 14.875 | M54: 1 | N54: 3 | O54: 16 | P54: 2 | U54: 3 | V54: 4 | W54: 2 | X54: 0
A55: Sale of corn | B55: 11 shilling 9pence from 5 quarters 7 bushels of peas sold, at 2 shilling a quarters. | C55: 0.59 | D55: 0 | E55: 11 | F55: 9 | G55: peas | H55: 5 | I55: 7 | J55: 5.875 | K55: 5.875 | L55: 0 | M55: 5 | N55: 7 | U55: 2 | V55: 0
A56: Sale of corn | B56: 1 shilling 10pence from 1 quarters 3 bushels of vetches sold, at 2pence a bushels. | C56: 0.09 | D56: 0 | E56: 1 | F56: 10 | G56: vetches | H56: 1 | I56: 3 | J56: 1.375 | K56: 1.375 | L56: 0 | M56: 1 | N56: 3 | AC56: 0 | AD56: 2
A57: Sale of corn | B57: £5 18 shilling 7.5pence from 54 quarters 6 bushels of oats sold, at 2 shilling 2pence a quarters. | C57: 5.93 | D57: 5 | E57: 18 | F57: 7.5 | G57: oats | H57: 54 | I57: 6 | J57: 54.75 | K57: 54.75 | L57: 0 | M57: 54 | N57: 6 | U57: 2 | V57: 2
A58: Sale of corn | B58: 8 shilling 9pence from 2 quarters 5 bushels of barley sold at the audit. | C58: 0.44 | D58: 0 | E58: 8 | F58: 9 | G58: barley | H58: 2 | I58: 5 | J58: 2.625 | K58: 2.625 | L58: 0 | M58: 2 | N58: 5
A59: Sale of corn | B59: Total, £45 8 shilling 7.25pence | C59: 45.43 | D59: 45 | E59: 8 | F59: 7.25 | H59: 0 | I59: 0 | J59: 0 | K59: 0 | L59: 0 | M59: 0 | N59: 0
A60: From the issue of the mill | B60: The same render account for 8 shilling 1.5pence from 1 quarters 5 bushels of wheat from the issue of the mill sold, at 55. a quarters. | C60: 0.41 | D60: 0 | E60: 8 | F60: 1.5 | G60: wheat | H60: 1 | I60: 5 | J60: 1.625 | K60: 1.625 | L60: 0 | M60: 1 | N60: 5
A61: From the issue of the mill | B61: 10 shilling 5.5pence from 3 quarters 5.5 bushels of first-grade and second-grade malt from the issue of the mill sold, at 2 shilling 10pence a quarters. | C61: 0.52 | D61: 0 | E61: 10 | F61: 5.5 | G61: second-grade malt | H61: 3 | I61: 5.5 | J61: 3.6875 | K61: 3.6875 | L61: 0 | M61: 3 | N61: 5.5 | U61: 2 | V61: 10
A62: From the issue of the mill | B62: Total, 18 shilling 7pence | C62: 0.93 | D62: 0 | E62: 18 | F62: 7 | H62: 0 | I62: 0 | J62: 0 | K62: 0 | L62: 0 | M62: 0 | N62: 0
A63: Entry and marriage fines | B63: The same render account for 8 shilling from the whole tithing of Rimpton for tithingpenny at the two hundred-courts. | C63: 0.4 | D63: 0 | E63: 8 | F63: 0 | H63: 0 | I63: 0 | J63: 0 | K63: 0 | L63: 0 | M63: 0 | N63: 0
A64: Entry and marriage fines | B64: 13 shilling 4pence from the fine of William le Nottey to have Joan Kage with 1 ferling of land. | C64: 0.67 | D64: 0 | E64: 13 | F64: 4 | H64: 0 | I64: 0 | J64: 0 | K64: 0 | L64: 0 | M64: 0 | N64: 0
A65: Entry and marriage fines | B65: £5 6 shilling 8pence from the fine of William le Denays to have 1 virgate of land with Aibreda, relict of Richard de Bosco. | C65: 5.33 | D65: 5 | E65: 6 | F65: 8 | H65: 0 | I65: 0 | J65: 0 | K65: 0 | L65: 0 | M65: 0 | N65: 0
A66: Entry and marriage fines | B66: £4 13 shilling 4pence from John de Woltnynton' to have Alice, relict of Henry Alayn, with 1 virgate of land. | C66: 4.67 | D66: 4 | E66: 13 | F66: 4 | H66: 0 | I66: 0 | J66: 0 | K66: 0 | L66: 0 | M66: 0 | N66: 0
A67: Entry and marriage fines | B67: 6 shilling from Albreda, the relict of de Bosco, to retain 1 virgate of her husband's lanpence Total, £11 7 shilling 4pence | C67: 11.37 | D67: 11 | E67: 7 | F67: 4 | H67: 0 | I67: 0 | J67: 0 | K67: 0 | L67: 0 | M67: 0 | N67: 0
A68: Perquisites | B68: The same render account for 8pence from William de Staford and Richard de Holeweye for trespass (transgressione) of pasture. | C68: 0.03 | D68: 0 | E68: 0 | F68: 8 | H68: 0 | I68: 0 | J68: 0 | K68: 0 | L68: 0 | M68: 0 | N68: 0
A69: Perquisites | B69: 6pence from John de Crawthorn' for the same. | C69: 0.03 | D69: 0 | E69: 0 | F69: 6 | H69: 0 | I69: 0 | J69: 0 | K69: 0 | L69: 0 | M69: 0 | N69: 0
A70: Perquisites | B70: 3.5pence from Roger Puphorn and his fellow for the same. | C70: 0.01 | D70: 0 | E70: 0 | F70: 3.5 | H70: 0 | I70: 0 | J70: 0 | K70: 0 | L70: 0 | M70: 0 | N70: 0
A71: Perquisites | B71: 1 shilling 9pence from Henry le Takeler', Henry Petyr, John Nob' and Robert Blakesol' for breaking the assize of ale. | C71: 0.09 | D71: 0 | E71: 1 | F71: 9 | H71: 0 | I71: 0 | J71: 0 | K71: 0 | L71: 0 | M71: 0 | N71: 0
A72: Perquisites | B72: 1 shilling from Robert de Quercu, Henry Gille, Henry Takeler' and John Nob' for the same. | C72: 0.05 | D72: 0 | E72: 1 | F72: 0 | H72: 0 | I72: 0 | J72: 0 | K72: 0 | L72: 0 | M72: 0 | N72: 0
A73: Perquisites | B73: 2 shilling from Henry Gill', John Nob', Jordan Burrich and Agnes Petra for the same. | C73: 0.1 | D73: 0 | E73: 2 | F73: 0 | H73: 0 | I73: 0 | J73: 0 | K73: 0 | L73: 0 | M73: 0 | N73: 0
... A143: Weeding corn and mowing the meadow | B143: stipend of the same 2 shilling. | C143: 0.1 | D143: 0 | E143: 2 | F143: 0 | H143: 0 | I143: 0 | J143: 0 | K143: 0 | L143: 0 | M143: 0 | N143: 0
A144: Weeding corn and mowing the meadow | B144: covering 1 stack of beans by piece-work 4pence Total, 9 shilling 7pence | C144: 0.47 | D144: 0 | E144: 9 | F144: 4 | G144: beans | H144: 0 | I144: 0 | J144: 0 | K144: 0 | L144: 0 | M144: 0 | N144: 0
A145: Steward's expenses | B145: In expenses of the steward and his clerk for their visits to view the state of the manor, to hold court, and to expedite other business of the lord, 8 shilling 8pence by 2 tallies. | C145: 0.43 | D145: 0 | E145: 8 | F145: 8 | H145: 0 | I145: 0 | J145: 0 | K145: 0 | L145: 0 | M145: 0 | N145: 0
A146: Steward's expenses | B146: Total, 8 shilling 8pence | C146: 0.43 | D146: 0 | E146: 8 | F146: 8 | H146: 0 | I146: 0 | J146: 0 | K146: 0 | L146: 0 | M146: 0 | N146: 0
...

Sheet Issues of the Grange raw
A1: Heading | B1: Sentence | C1: Quarters 1_x | D1: Bushels 1_x | E1: Sown Quarters | F1: Sown Bushels | G1: Sown Total Quarters | H1: Bought in Quarters | I1: Bought in Bushels | J1: Bought in Total Quarters | K1: Tithe Quarters | L1: Tithe Bushels | M1: Tithe Total Quarters | N1: Manorial servants & livestock Quarters | O1: Manorial servants & livestock Bushels | P1: Manorial servants & livestock Total Quarters | Q1: Sold Quarters | R1: Sold Bushels | S1: Sold Total Quarters | T1: Account Quarters | U1: Account Bushels | V1: Account Total Quarters | W1: bought only | X1: Total Quarters Except 1 | Y1: Total Bushels Except 1 | Z1: Total Corn Cross-Check | AA1: Total Corn Manorial Account | AB1: Corn Quantity Error | AC1: Quarters 1_y | AD1: Bushels 1_y | AE1: Quarters 2 | AF1: Bushels 2 | AG1: Quarters 3 | AH1: Bushels 3 | AI1: Quarters 4 | AJ1: Bushels 4
A2: Cash deliveries | B2: Total | C2: 0 | D2: 0 | E2: 0 | F2: 0 | G2: 0 | H2: 0 | I2: 0 | J2: 0 | K2: 0 | L2: 0 | M2: 0 | N2: 0 | O2: 0 | P2: 0 | Q2: 0 | R2: 0 | S2: 0 | T2: 0 | U2: 0 | V2: 0 | W2: 0
A3: Wheat | B3: {yield: 5.5-fold plus 6.5 bushels in all with the issue of maslin below) | C3: 0 | D3: 0 | E3: 0 | F3: 0 | G3: 0 | H3: 0 | I3: 0 | J3: 0 | K3: 0 | L3: 0 | M3: 0 | N3: 0 | O3: 0 | P3: 0 | Q3: 0 | R3: 0 | S3: 0 | T3: 0 | U3: 0 | V3: 0 | W3: 0 | X3: 0 | Y3: 6.5 | Z3: 0.8125 | AA3: 0.8125 | AB3: 0 | AC3: 0 | AD3: 6.5
A4: Wheat | B4: The same render account for 144.5 quarters of wheat from the issue of the grange threshed by the customary tenants of the vill by struck measure. | C4: 0 | D4: 0 | E4: 0 | F4: 0 | G4: 0 | H4: 0 | I4: 0 | J4: 0 | K4: 0 | L4: 0 | M4: 0 | N4: 0 | O4: 0 | P4: 0 | Q4: 0 | R4: 0 | S4: 0 | T4: 144.5 | U4: 0 | V4: 144.5 | W4: 0 | X4: 144.5 | Y4: 0 | Z4: 144.5 | AA4: 144.5 | AB4: 0 | AC4: 144.5 | AD4: 0
A5: Wheat | B5: Total, 144.5 quarters. | C5: 0 | D5: 0 | E5: 0 | F5: 0 | G5: 0 | H5: 0 | I5: 0 | J5: 0 | K5: 0 | L5: 0 | M5: 0 | N5: 0 | O5: 0 | P5: 0 | Q5: 0 | R5: 0 | S5: 0 | T5: 0 | U5: 0 | V5: 0 | W5: 0 | X5: 144.5 | Y5: 0 | Z5: 144.5 | AA5: 144.5 | AB5: 0 | AC5: 144.5 | AD5: 0
A6: Wheat | B6: Sown over 117 acres, 22 quarters .5 bushels. | C6: 0 | D6: 0 | E6: 22 | F6: 0 | G6: 22 | H6: 0 | I6: 0 | J6: 0 | K6: 0 | L6: 0 | M6: 0 | N6: 0 | O6: 0 | P6: 0 | Q6: 0 | R6: 0 | S6: 0 | T6: 0 | U6: 0 | V6: 0 | W6: 0 | X6: 22 | Y6: 5 | Z6: 22.625 | AA6: 22 | AB6: 0.625 | AC6: 22 | AD6: 0 | AE6: 0 | AF6: 5
A7: Wheat | B7: that is, 1.5 bushels an acre, plus 1 bushels in all. | C7: 0 | D7: 0 | E7: 0 | F7: 0 | G7: 0 | H7: 0 | I7: 0 | J7: 0 | K7: 0 | L7: 0 | M7: 0 | N7: 0 | O7: 0 | P7: 0 | Q7: 0 | R7: 0 | S7: 0 | T7: 0 | U7: 0 | V7: 0 | W7: 0 | X7: 0 | Y7: 1 | Z7: 0.125 | AA7: 0.1875 | AB7: -0.0625 | AC7: 0 | AD7: 1.5 | AE7: 0 | AF7: 1
A8: Wheat | B8: . | C8: 0 | D8: 0 | E8: 0 | F8: 0 | G8: 0 | H8: 0 | I8: 0 | J8: 0 | K8: 0 | L8: 0 | M8: 0 | N8: 0 | O8: 0 | P8: 0 | Q8: 0 | R8: 0 | S8: 0 | T8: 0 | U8: 0 | V8: 0 | W8: 0 | X8: 0 | Y8: 0 | Z8: 0 | AA8: 0 | AB8: 0 | AC8: 0 | AD8: 0
A9: Wheat | B9: bread baked for the provision of one boon-work for winter sowing, 6 bushels. | C9: 0 | D9: 0 | E9: 0 | F9: 0 | G9: 0 | H9: 0 | I9: 0 | J9: 0 | K9: 0 | L9: 0 | M9: 0 | N9: 0 | O9: 0 | P9: 0 | Q9: 0 | R9: 0 | S9: 0 | T9: 0 | U9: 0 | V9: 0 | W9: 0 | X9: 0 | Y9: 6 | Z9: 0.75 | AA9: 0.75 | AB9: 0 | AC9: 0 | AD9: 6
A10: Wheat | B10: provision of the steward for his visits, 3 bushels Sold within, 121 quarters 2.5 bushels Total as made clear. | C10: 0 | D10: 0 | E10: 0 | F10: 0 | G10: 0 | H10: 0 | I10: 0 | J10: 0 | K10: 0 | L10: 0 | M10: 0 | N10: 121 | O10: 2.5 | P10: 121.3125 | Q10: 121 | R10: 2.5 | S10: 121.3125 | T10: 0 | U10: 0 | V10: 0 | W10: 0 | X10: 121 | Y10: 2.5 | Z10: 121.3125 | AA10: 0.375 | AB10: 120.9375 | AC10: 0 | AD10: 3 | AE10: 121 | AF10: 2.5
A11: Wheat | B11: It balances. | C11: 0 | D11: 0 | E11: 0 | F11: 0 | G11: 0 | H11: 0 | I11: 0 | J11: 0 | K11: 0 | L11: 0 | M11: 0 | N11: 0 | O11: 0 | P11: 0 | Q11: 0 | R11: 0 | S11: 0 | T11: 0 | U11: 0 | V11: 0 | W11: 0 | X11: 0 | Y11: 0 | Z11: 0 | AA11: 0 | AB11: 0 | AC11: 0 | AD11: 0
A12: Wheat | B12: Total | C12: 0 | D12: 0 | E12: 0 | F12: 0 | G12: 0 | H12: 0 | I12: 0 | J12: 0 | K12: 0 | L12: 0 | M12: 0 | N12: 0 | O12: 0 | P12: 0 | Q12: 0 | R12: 0 | S12: 0 | T12: 0 | U12: 0 | V12: 0 | W12: 0
A13: Curall | B13: The same render account for 20 quarters 1 bushels of curall from the issue of the grange threshed like wheat above. | C13: 0 | D13: 0 | E13: 0 | F13: 0 | G13: 0 | H13: 0 | I13: 0 | J13: 0 | K13: 0 | L13: 0 | M13: 0 | N13: 0 | O13: 0 | P13: 0 | Q13: 0 | R13: 0 | S13: 0 | T13: 20 | U13: 1 | V13: 20.125 | W13: 0 | X13: 20 | Y13: 1 | Z13: 20.125 | AA13: 20.125 | AB13: 0 | AC13: 20 | AD13: 1
A14: Curall | B14: Total, 20 quarters 1 bushels | C14: 0 | D14: 0 | E14: 0 | F14: 0 | G14: 0 | H14: 0 | I14: 0 | J14: 0 | K14: 0 | L14: 0 | M14: 0 | N14: 0 | O14: 0 | P14: 0 | Q14: 0 | R14: 0 | S14: 0 | T14: 0 | U14: 0 | V14: 0 | W14: 0 | X14: 20 | Y14: 1 | Z14: 20.125 | AA14: 20.125 | AB14: 0 | AC14: 20 | AD14: 1
A15: Curall | B15: Mixed for the liveries of the manorial servants, 14 quarters. | C15: 0 | D15: 0 | E15: 0 | F15: 0 | G15: 0 | H15: 0 | I15: 0 | J15: 0 | K15: 0 | L15: 0 | M15: 0 | N15: 14 | O15: 0 | P15: 14 | Q15: 0 | R15: 0 | S15: 0 | T15: 0 | U15: 0 | V15: 0 | W15: 0 | X15: 14 | Y15: 0 | Z15: 14 | AA15: 14 | AB15: 0 | AC15: 14 | AD15: 0
A16: Curall | B16: Sold within, 6 quarters 1 bushels It balances. | C16: 0 | D16: 0 | E16: 0 | F16: 0 | G16: 0 | H16: 0 | I16: 0 | J16: 0 | K16: 0 | L16: 0 | M16: 0 | N16: 0 | O16: 0 | P16: 0 | Q16: 6 | R16: 1 | S16: 6.125 | T16: 0 | U16: 0 | V16: 0 | W16: 0 | X16: 6 | Y16: 1 | Z16: 6.125 | AA16: 6.125 | AB16: 0 | AC16: 6 | AD16: 1
A17: Curall | B17: Total | C17: 0 | D17: 0 | E17: 0 | F17: 0 | G17: 0 | H17: 0 | I17: 0 | J17: 0 | K17: 0 | L17: 0 | M17: 0 | N17: 0 | O17: 0 | P17: 0 | Q17: 0 | R17: 0 | S17: 0 | T17: 0 | U17: 0 | V17: 0 | W17: 0
A18: Maslin | B18: {yield: 5.5-fold with wheat above} | C18: 0 | D18: 0 | E18: 0 | F18: 0 | G18: 0 | H18: 0 | I18: 0 | J18: 0 | K18: 0 | L18: 0 | M18: 0 | N18: 0 | O18: 0 | P18: 0 | Q18: 0 | R18: 0 | S18: 0 | T18: 0 | U18: 0 | V18: 0 | W18: 0 | X18: 0 | Y18: 0 | Z18: 0 | AA18: 0 | AB18: 0 | AC18: 0 | AD18: 0
A19: Maslin | B19: The same render account for 12 quarters 7 bushels of maslin from the issue of the grange threshed as above. | C19: 0 | D19: 0 | E19: 0 | F19: 0 | G19: 0 | H19: 0 | I19: 0 | J19: 0 | K19: 0 | L19: 0 | M19: 0 | N19: 0 | O19: 0 | P19: 0 | Q19: 0 | R19: 0 | S19: 0 | T19: 12 | U19: 7 | V19: 12.875 | W19: 0 | X19: 12 | Y19: 7 | Z19: 12.875 | AA19: 12.875 | AB19: 0 | AC19: 12 | AD19: 7
A20: Maslin | B20: Total, 12 quarters 7 bushels Sold within. | C20: 0 | D20: 0 | E20: 0 | F20: 0 | G20: 0 | H20: 0 | I20: 0 | J20: 0 | K20: 0 | L20: 0 | M20: 0 | N20: 0 | O20: 0 | P20: 0 | Q20: 12 | R20: 7 | S20: 12.875 | T20: 0 | U20: 0 | V20: 0 | W20: 0 | X20: 12 | Y20: 7 | Z20: 12.875 | AA20: 12.875 | AB20: 0 | AC20: 12 | AD20: 7
A21: Maslin | B21: It balances. | C21: 0 | D21: 0 | E21: 0 | F21: 0 | G21: 0 | H21: 0 | I21: 0 | J21: 0 | K21: 0 | L21: 0 | M21: 0 | N21: 0 | O21: 0 | P21: 0 | Q21: 0 | R21: 0 | S21: 0 | T21: 0 | U21: 0 | V21: 0 | W21: 0 | X21: 0 | Y21: 0 | Z21: 0 | AA21: 0 | AB21: 0 | AC21: 0 | AD21: 0
A22: Maslin | B22: Total | C22: 0 | D22: 0 | E22: 0 | F22: 0 | G22: 0 | H22: 0 | I22: 0 | J22: 0 | K22: 0 | L22: 0 | M22: 0 | N22: 0 | O22: 0 | P22: 0 | Q22: 0 | R22: 0 | S22: 0 | T22: 0 | U22: 0 | V22: 0 | W22: 0
A23: Barley | B23: {yield: seven-fold less .5 qr} | C23: 0 | D23: 0 | E23: 0 | F23: 0 | G23: 0 | H23: 0 | I23: 0 | J23: 0 | K23: 0 | L23: 0 | M23: 0 | N23: 0 | O23: 0 | P23: 0 | Q23: 0 | R23: 0 | S23: 0 | T23: 0 | U23: 0 | V23: 0 | W23: 0
A24: Barley | B24: The same render account for 10 quarters of barley from the issue of the grange. | C24: 0 | D24: 0 | E24: 0 | F24: 0 | G24: 0 | H24: 0 | I24: 0 | J24: 0 | K24: 0 | L24: 0 | M24: 0 | N24: 0 | O24: 0 | P24: 0 | Q24: 0 | R24: 0 | S24: 0 | T24: 10 | U24: 0 | V24: 10 | W24: 0 | X24: 10 | Y24: 0 | Z24: 10 | AA24: 10 | AB24: 0 | AC24: 10 | AD24: 0
A25: Barley | B25: Total, 10 quarters. | C25: 0 | D25: 0 | E25: 0 | F25: 0 | G25: 0 | H25: 0 | I25: 0 | J25: 0 | K25: 0 | L25: 0 | M25: 0 | N25: 0 | O25: 0 | P25: 0 | Q25: 0 | R25: 0 | S25: 0 | T25: 0 | U25: 0 | V25: 0 | W25: 0 | X25: 10 | Y25: 0 | Z25: 10 | AA25: 10 | AB25: 0 | AC25: 10 | AD25: 0
A26: Barley | B26: Sown over 3 acres, 7.5 bushels. | C26: 0 | D26: 0 | E26: 0 | F26: 0 | G26: 0 | H26: 0 | I26: 0 | J26: 0 | K26: 0 | L26: 0 | M26: 0 | N26: 0 | O26: 0 | P26: 0 | Q26: 0 | R26: 0 | S26: 0 | T26: 0 | U26: 0 | V26: 0 | W26: 0 | X26: 0 | Y26: 7.5 | Z26: 0.9375 | AA26: 0.9375 | AB26: 0 | AC26: 0 | AD26: 7.5
A27: Barley | B27: that is, 2.5 bushels an acre. | C27: 0 | D27: 0 | E27: 0 | F27: 0 | G27: 0 | H27: 0 | I27: 0 | J27: 0 | K27: 0 | L27: 0 | M27: 0 | N27: 0 | O27: 0 | P27: 0 | Q27: 0 | R27: 0 | S27: 0 | T27: 0 | U27: 0 | V27: 0 | W27: 0 | X27: 0 | Y27: 2.5 | Z27: 0.3125 | AA27: 0.3125 | AB27: 0 | AC27: 0 | AD27: 2.5
A28: Barley | B28: . | C28: 0 | D28: 0 | E28: 0 | F28: 0 | G28: 0 | H28: 0 | I28: 0 | J28: 0 | K28: 0 | L28: 0 | M28: 0 | N28: 0 | O28: 0 | P28: 0 | Q28: 0 | R28: 0 | S28: 0 | T28: 0 | U28: 0 | V28: 0 | W28: 0 | X28: 0 | Y28: 0 | Z28: 0 | AA28: 0 | AB28: 0 | AC28: 0 | AD28: 0
A29: Barley | B29: supporting piglets, 5 bushels Mixed for the liveries of the manorial servants, 4 quarters 3.5 bushels Sold within, 1 qr 3 bushels Sold at the audit, 2 quarters 5 bushels It balances. | C29: 0 | D29: 0 | E29: 0 | F29: 0 | G29: 0 | H29: 0 | I29: 0 | J29: 0 | K29: 0 | L29: 0 | M29: 0 | N29: 6 | O29: 8.5 | P29: 7.0625 | Q29: 6 | R29: 8.5 | S29: 7.0625 | T29: 0 | U29: 0 | V29: 0 | W29: 0
A30: Barley | B30: Total | C30: 0 | D30: 0 | E30: 0 | F30: 0 | G30: 0 | H30: 0 | I30: 0 | J30: 0 | K30: 0 | L30: 0 | M30: 0 | N30: 0 | O30: 0 | P30: 0 | Q30: 0 | R30: 0 | S30: 0 | T30: 0 | U30: 0 | V30: 0 | W30: 0
A31: Beans | B31: {yield: seven-fold less 1 qr with 35 quarters by estimation remaining in the stack} The same render account for 1 qr 2 bushels of beans remaining from the previous account. | C31: 0 | D31: 0 | E31: 0 | F31: 0 | G31: 0 | H31: 0 | I31: 0 | J31: 0 | K31: 0 | L31: 0 | M31: 0 | N31: 0 | O31: 0 | P31: 0 | Q31: 0 | R31: 0 | S31: 0 | T31: 35 | U31: 0 | V31: 35 | W31: 0
A32: Beans | B32: 27 quarters from this year's issue. | C32: 0 | D32: 0 | E32: 0 | F32: 0 | G32: 0 | H32: 0 | I32: 0 | J32: 0 | K32: 0 | L32: 0 | M32: 0 | N32: 0 | O32: 0 | P32: 0 | Q32: 0 | R32: 0 | S32: 0 | T32: 0 | U32: 0 | V32: 0 | W32: 0 | X32: 27 | Y32: 0 | Z32: 27 | AA32: 27 | AB32: 0 | AC32: 27 | AD32: 0
A33: Beans | B33: Total, 28 quarters 2 bushels | C33: 0 | D33: 0 | E33: 0 | F33: 0 | G33: 0 | H33: 0 | I33: 0 | J33: 0 | K33: 0 | L33: 0 | M33: 0 | N33: 0 | O33: 0 | P33: 0 | Q33: 0 | R33: 0 | S33: 0 | T33: 0 | U33: 0 | V33: 0 | W33: 0 | X33: 28 | Y33: 2 | Z33: 28.25 | AA33: 28.25 | AB33: 0 | AC33: 28 | AD33: 2
A34: Beans | B34: Sown over 15 acres, 7 quarters 2 bushels. | C34: 0 | D34: 0 | E34: 7 | F34: 2 | G34: 7.25 | H34: 0 | I34: 0 | J34: 0 | K34: 0 | L34: 0 | M34: 0 | N34: 0 | O34: 0 | P34: 0 | Q34: 0 | R34: 0 | S34: 0 | T34: 0 | U34: 0 | V34: 0 | W34: 0 | X34: 7 | Y34: 2 | Z34: 7.25 | AA34: 7.25 | AB34: 0 | AC34: 7 | AD34: 2
A35: Beans | B35: that is, .5 qr an acre, less 2 bushels in all. | C35: 0 | D35: 0 | E35: 0 | F35: 0 | G35: 0 | H35: 0 | I35: 0 | J35: 0 | K35: 0 | L35: 0 | M35: 0 | N35: 0 | O35: 0 | P35: 0 | Q35: 0 | R35: 0 | S35: 0 | T35: 0 | U35: 0 | V35: 0 | W35: 0
A36: Beans | B36: . | C36: 0 | D36: 0 | E36: 0 | F36: 0 | G36: 0 | H36: 0 | I36: 0 | J36: 0 | K36: 0 | L36: 0 | M36: 0 | N36: 0 | O36: 0 | P36: 0 | Q36: 0 | R36: 0 | S36: 0 | T36: 0 | U36: 0 | V36: 0 | W36: 0 | X36: 0 | Y36: 0 | Z36: 0 | AA36: 0 | AB36: 0 | AC36: 0 | AD36: 0
A37: Beans | B37: feeding pigs, 2.5 quarters. | C37: 0 | D37: 0 | E37: 0 | F37: 0 | G37: 0 | H37: 0 | I37: 0 | J37: 0 | K37: 0 | L37: 0 | M37: 0 | N37: 0 | O37: 0 | P37: 0 | Q37: 0 | R37: 0 | S37: 0 | T37: 0 | U37: 0 | V37: 0 | W37: 0 | X37: 2.5 | Y37: 0 | Z37: 2.5 | AA37: 2.5 | AB37: 0 | AC37: 2.5 | AD37: 0
A38: Beans | B38: Mixed for the liveries of the manorial servants, 2 quarters 2 bushels Sold within, 16 quarters 2 bushels Total as above. 35 quarters by estimation remain in a certain stack. | C38: 0 | D38: 0 | E38: 0 | F38: 0 | G38: 0 | H38: 0 | I38: 0 | J38: 0 | K38: 0 | L38: 0 | M38: 0 | N38: 53 | O38: 4 | P38: 53.5 | Q38: 53 | R38: 4 | S38: 53.5 | T38: 0 | U38: 0 | V38: 0 | W38: 0 | X38: 51 | Y38: 2 | Z38: 51.25 | AA38: 2.25 | AB38: 49 | AC38: 2 | AD38: 2 | AE38: 16 | AF38: 2 | AG38: 35 | AH38: 0
A39: Beans | B39: Total | C39: 0 | D39: 0 | E39: 0 | F39: 0 | G39: 0 | H39: 0 | I39: 0 | J39: 0 | K39: 0 | L39: 0 | M39: 0 | N39: 0 | O39: 0 | P39: 0 | Q39: 0 | R39: 0 | S39: 0 | T39: 0 | U39: 0 | V39: 0 | W39: 0
A40: Peas | B40: {yield: 7.5-fold less % bushels with the remainder in the stack} | C40: 0 | D40: 0 | E40: 0 | F40: 0 | G40: 0 | H40: 0 | I40: 0 | J40: 0 | K40: 0 | L40: 0 | M40: 0 | N40: 0 | O40: 0 | P40: 0 | Q40: 0 | R40: 0 | S40: 0 | T40: 0 | U40: 0 | V40: 0 | W40: 0 | X40: 0 | Y40: 0 | Z40: 0 | AA40: 0 | AB40: 0 | AC40: 0 | AD40: 0
...

Sheet Sale of Corn Prices
A1: Heading | B1: Sentence | C1: Total in Pounds | D1: Pounds | E1: Shillings | F1: Pence | G1: Corn | H1: Total Quarters Except 1 | I1: Total Bushels Except 1 | J1: Total Corn Cross-Check | K1: Total Corn Manorial Account | L1: Corn Quantity Error | M1: Quarters 0 | N1: Bushels 0 | O1: shilling a quarter 1 | P1: pence a quarter 1 | Q1: Quarters 1 | R1: Bushels 1 | S1: shilling a quarter 2 | T1: pence a quarter 2 | U1: Quarters 2 | V1: Bushels 2 | W1: shilling a quarter 3 | X1: pence a quarter 3 | Y1: Quarters 3 | Z1: Bushels 3 | AA1: shilling a quarter 4 | AB1: pence a quarter 4 | AC1: £ a quarter 1 | AD1: £ a quarter 2 | AE1: £ a quarter 3 | AF1: £ a quarter 4 | AG1: Quarters Sold | AH1: Weighted Average Price per Quarter | AI1: Non-Weighted Average Price per Quarter | AJ1: Corn lowercase
A2: Sale of corn | B2: The same render account for £32 7 shilling from 121 quarters 2.5 bushels of wheat sold, at 5 shilling 4pence a quarters, £1 3 shilling 5.75pence from 6 quarters 1 bushels of curall sold, at 3 shilling 10pence a quarters. | C2: 32.35 | D2: 32 | E2: 7 | F2: 0 | G2: curall, wheat | H2: 6 | I2: 1 | J2: 6.125 | K2: 121.3125 | L2: -115.1875 | M2: 121 | N2: 2.5 | O2: 5 | P2: 4 | Q2: 6 | R2: 1 | S2: 3 | T2: 10 | AC2: 0.26666667 | AD2: 0.19166667 | AG2: 121.3125 | AI2: 0.22916667 | AJ2: curall, wheat
A3: Sale of corn | B3: £3 1pence from 12 quarters 7 bushels of maslin sold, at 4 shilling 8pence a quarters. | C3: 3 | D3: 3 | E3: 0 | F3: 1 | G3: maslin | H3: 12 | I3: 7 | J3: 12.875 | K3: 12.875 | L3: 0 | M3: 12 | N3: 7 | O3: 4 | P3: 8 | AC3: 0.23333333 | AG3: 12.875 | AH3: 0.23333333 | AI3: 0.23333333 | AJ3: maslin
A4: Sale of corn | B4: 4 shilling 7pence from 1 quarters 3 bushels of barley sold, at 3 shilling 4pence a quarters, £1 12 shilling 6pence from 16 quarters 2 bushels of beans sold, at 2 shilling a quarters. | C4: 1.62 | D4: 1 | E4: 12 | F4: 6 | G4: barley, beans | H4: 16 | I4: 2 | J4: 16.25 | K4: 1.375 | L4: 14.875 | M4: 1 | N4: 3 | O4: 3 | P4: 4 | Q4: 16 | R4: 2 | S4: 2 | T4: 0 | AC4: 0.16666667 | AD4: 0.1 | AG4: 1.375 | AI4: 0.13333333 | AJ4: barley, beans
A5: Sale of corn | B5: 11 shilling 9pence from 5 quarters 7 bushels of peas sold, at 2 shilling a quarters. | C5: 0.59 | D5: 0 | E5: 11 | F5: 9 | G5: peas | H5: 5 | I5: 7 | J5: 5.875 | K5: 5.875 | L5: 0 | M5: 5 | N5: 7 | O5: 2 | P5: 0 | AC5: 0.1 | AG5: 5.875 | AH5: 0.1 | AI5: 0.1 | AJ5: peas
A6: Sale of corn | B6: 1 shilling 10pence from 1 quarters 3 bushels of vetches sold, at 2pence a bushels. | C6: 0.09 | D6: 0 | E6: 1 | F6: 10 | G6: vetches | H6: 1 | I6: 3 | J6: 1.375 | K6: 1.375 | L6: 0 | M6: 1 | N6: 3 | AC6: 0.065454545 | AG6: 1.375 | AH6: 0.065454545 | AI6: 0.065454545 | AJ6: vetches
A7: Sale of corn | B7: £5 18 shilling 7.5pence from 54 quarters 6 bushels of oats sold, at 2 shilling 2pence a quarters. | C7: 5.93 | D7: 5 | E7: 18 | F7: 7.5 | G7: oats | H7: 54 | I7: 6 | J7: 54.75 | K7: 54.75 | L7: 0 | M7: 54 | N7: 6 | O7: 2 | P7: 2 | AC7: 0.10833333 | AG7: 54.75 | AH7: 0.10833333 | AI7: 0.10833333 | AJ7: oats
A8: Sale of corn | B8: 8 shilling 9pence from 2 quarters 5 bushels of barley sold at the audit. | C8: 0.44 | D8: 0 | E8: 8 | F8: 9 | G8: barley | H8: 2 | I8: 5 | J8: 2.625 | K8: 2.625 | L8: 0 | M8: 2 | N8: 5 | AC8: 0.16761905 | AG8: 2.625 | AH8: 0.16761905 | AI8: 0.16761905 | AJ8: barley
A9: Sale of corn | B9: Total, £45 8 shilling 7.25pence | C9: 45.43 | D9: 45 | E9: 8 | F9: 7.25 | H9: 0 | I9: 0 | J9: 0 | K9: 0 | L9: 0 | M9: 0 | N9: 0 | AC9: inf | AG9: 0 | AH9: inf | AI9: inf
