Workbook

Sheet Southwark Overview - Completed
A1: SOUTHWARK OVERVIEW - COMPLETED | B1: Total in £ | C1: Error | D1: Note
A2: CASH ACCOUNT
A3: RECEIPTS
A4: Arrears total | B4: 8.2
A5: Rents of assize total | B5: 16.18
A6: Quittances total
A7: Defaults of rent total
A8: Defaults of rent through the pestilence total
A9: Cotlands defaults total
A10: Cotlands total
A11: Total of quittances and defaults of rent total
A12: Total of rents remaining clear total | B12: 14.9
A13: Farms total
A14: Annual recognizances total
A15: Issues of the Manor total | B15: 4.58
A16: Issues of the tenements in the lord's hands total
A17: Sale of labour services total
A18: Sale of corn total | B18: 6.92
A19: Entry and marriage fines total
A20: Pleas & perquisites total
A21: Forfeited chattels total
A22: Farm of the demesne land total
A23: Total of all receipts (calculated here) | B23: =SUM(B5:B22)
A24: Total of all receipts (calculated here) incl arrears | B24: =SUM(B4:B22)
A25: Total recorded in the accounts excl. arrears | C25: =B23-B25
A26: Total recorded in the accounts incl. arrears | B26: =B25+B4
A29: EXPENSES
A30: Cost of ploughs total
A31: Purchase of corn total
A32: Cost of carts and wagons total
A33: Cost of dairy total
A34: Purchase of stock total
A35: Sheepcote total
A36: Cost of buildings total
A37: Threshing total
A38: Barley expenses
A39: Expenses of the harvest total
A40: Necessary expenses
... A47: Total Demesne fixed investment
A49: Owed by the reeve | B49: =B23-B45
...

Sheet Prices
A1: Meat & Dairy Prices
C2: 1301 | D2: 1302 | E2: Average
A3: Beef | B3: £ per lb | C3: 0.0033351854 | D3: 0.0032608538 | E3: =AVERAGE(C3:D3)
A4: Mutton | B4: £ per lb | C4: 0.0036593977 | D4: 0.0037125513 | E4: =AVERAGE(C4:D4)
A5: Pork | B5: £ per lb | C5: 0.0038431326 | D5: 0.0037574803 | E5: =AVERAGE(C5:D5)
A6: Cheese | B6: £ per lb | C6: 0.0055768754 | D6: 0.0056654898 | E6: =AVERAGE(C6:D6)
A7: Butter | B7: £ per lb | C7: 0.0036626221 | D7: 0.0035935077 | E7: =AVERAGE(C7:D7)
A8: Milk | B8: £ per gallon | C8: 0.0055768754 | D8: 0.0056654898 | E8: =AVERAGE(C8:D8)

Sheet Labour Rents

Sheet Overview
A1: SOUTHWARK | B1: Total in £ | C1: Error | D1: Note
A2: CASH ACCOUNT
A3: RECEIPTS
A4: Arrears total
A5: Rents of assize total
A6: Quittances total
A7: Defaults of rent total
A8: Defaults of rent through the pestilence total
A9: Cotlands defaults total
A10: Cotlands total
A11: Total of quittances and defaults of rent total
A12: Total of rents remaining clear total
A13: Farms total
... A183: % of capital expenses as calculated previously

Sheet Receipts
A1: SOUTHWARK RECEIPTS
A2: Heading | B2: £ | C2: s | D2: d | F2: Total in £ | G2: Error | H2: Notes
A3: Arrears | B3: 8 | C3: 4 | D3: 0.75 | F3: 8.2 | H3: The same render account for £8 4 shilling 0.75pence of arrears from the previous year.
A4: Arrears | B4: 0 | C4: 0 | D4: 0 | F4: 0 | H4: Delivered to Sir Geoffrey by 1 tally.
A5: Arrears | B5: 0 | C5: 0 | D5: 0 | F5: 0 | H5: They are quit.
A6: Arrears | F6: 8.2 | G6: 8.2 | H6: Total
A8: Rents of assize | B8: 8 | C8: 1 | D8: 10.5 | F8: 8.09 | H8: The same render account for £8 1 shilling 10.5pence for all rents of assize in London and Southwark at Easter (22 April).
A9: Rents of assize | B9: 8 | C9: 1 | D9: 10.5 | F9: 8.09 | H9: £8 1 shilling 10.5pence at Michaelmas (29 September).
A10: Rents of assize | B10: 16 | C10: 3 | D10: 9 | F10: 16.19 | H10: Total, £16 3 shilling 9pence
A11: Rents of assize | F11: 16.18 | G11: -0.01 | H11: Total
A13: Total of rents remaining clear | B13: 14 | C13: 18 | D13: 1 | F13: 14.9 | H13: Total of rents remaining clear, £14 18 shilling 1 pence
A14: Total of rents remaining clear | F14: 14.9 | G14: =F14-E13 | H14: Total
A16: Pepper | B16: 0 | C16: 0 | D16: 0 | F16: 0 | H16: The same render account for 1 lb of pepper from the rent of 1 seld in Eldefhystrate this year.
A17: Pepper | B17: 0 | C17: 0 | D17: 0 | F17: 0 | H17: Total, 1 lb.
A18: Pepper | B18: 0 | C18: 0 | D18: 0 | F18: 0 | H18: All delivered to Sir Geoffrey by 1 tally.
A19: Pepper | B19: 0 | C19: 0 | D19: 0 | F19: 0 | H19: They are quit.
A20: Pepper | F20: 0 | G20: 0 | H20: Total
A22: Issues of the manor | B22: 3 | C22: 6 | D22: 8 | F22: 3.33 | H22: The same render account for £3 6 shilling 8pence from the herbage in the great field sold.
A23: Issues of the manor | B23: 0 | C23: 8 | D23: 0 | F23: 0.4 | H23: 8 shilling from nettles in la Wild' sold.
A24: Issues of the manor | B24: 0 | C24: 5 | D24: 0 | F24: 0.25 | H24: 5 shilling from 1 garden hired this year to make a curtilage.
A25: Issues of the manor | B25: 0 | C25: 9 | D25: 0 | F25: 0.45 | H25: 9 shilling from fruit sold this year.
A26: Issues of the manor | B26: 0 | C26: 3 | D26: 0 | F26: 0.15 | H26: 3 shilling from 1 plot behind the kitchen, and not more this year because part of the bishops hay was stacked there which it was not possible to stack in other buildings because of the sojourn of the count of Savoy there.
A27: Issues of the manor | B27: 0 | C27: 0 | D27: 0 | F27: 0 | H27: nothing from hay this year because all was in provision of the bishop's horses.
A28: Issues of the manor | B28: 0 | C28: 0 | D28: 0 | F28: 0 | H28: nothing from the pinfold this year because it is submergepence
A29: Issues of the manor | B29: 4 | C29: 11 | D29: 8 | F29: 4.58 | H29: Total, £4 11 shilling 8pence
A30: Issues of the manor | F30: =SUM(F22:F28) | G30: =F30-F29 | H30: Total
A32: Sale of corn | B32: 2 | C32: 16 | D32: 8 | F32: 2.83 | H32: The same render account for £2 16 shilling 8pence from 10 quarters of wheat sold from the issue of the mill, at 5 shilling 8pence a qr.
A33: Sale of corn | B33: 2 | C33: 13 | D33: 4 | F33: 2.67 | H33: £2 13 shilling 4pence from 10 quarters of wheat sold from the same issue, at 5 shilling 4pence a qr.
A34: Sale of corn | B34: 1 | C34: 8 | D34: 4 | F34: 1.42 | H34: £1 8 shilling 4pence from 8.5 quarters of maslin sold from the issue of the mill, at 3 shilling 4pence a qr.
A35: Sale of corn | B35: 6 | C35: 18 | D35: 4 | F35: 6.92 | H35: Total, £6 18 shilling 4pence
A36: Sale of corn | F36: 6.92 | G36: 0 | H36: Total
A38: Perquisites | B38: 0 | C38: 0 | D38: 6 | F38: 0.03 | H38: The same render account for 6pence from John Baldewyn' and his pledges.
A39: Perquisites | B39: 0 | C39: 0 | D39: 6 | F39: 0.03 | H39: 6pence from Emma, wife of Roginald Pistor'.
A40: Perquisites | B40: 0 | C40: 0 | D40: 3 | F40: 0.01 | H40: 3pence from John de Wynton' for many transgressions.
A41: Perquisites | B41: 0 | C41: 0 | D41: 3 | F41: 0.01 | H41: 3pence from Simon de Merton' for the same.
A42: Perquisites | B42: 0 | C42: 1 | D42: 0 | F42: 0.05 | H42: 1 shilling from the whole tithing for concealment.
A43: Perquisites | B43: 0 | C43: 0 | D43: 3 | F43: 0.01 | H43: 3pence from William le Lech' for breaking the assize of ale.
A44: Perquisites | B44: 0 | C44: 0 | D44: 3 | F44: 0.01 | H44: 3pence from John le Sthalou' for the same.
A45: Perquisites | B45: 0 | C45: 0 | D45: 3 | F45: 0.01 | H45: 3pence from Roger le Horsdrivare for the same.
A46: Perquisites | B46: 0 | C46: 0 | D46: 3 | F46: 0.01 | H46: 3pence from Stephen Bost for the same.
...

Sheet Expenses
A1: SOUTHWARK EXPENSES
A2: Heading | B2: £ | C2: s | D2: d | F2: Total in £ | G2: Error | H2: Notes
A3: Cost of the mill | B3: 0 | C3: 1 | D3: 0 | F3: 0.05 | H3: In 1 measure of steel bought for the mill bills 1 shilling.
A4: Cost of the mill | B4: 0 | C4: 1 | D4: 0 | F4: 0.05 | H4: forging the same 1 shilling.
A5: Cost of the mill | B5: 0 | C5: 2 | D5: 0 | F5: 0.1 | H5: sharpening the bills for the year 2 shilling.
A6: Cost of the mill | B6: 0 | C6: 5 | D6: 0 | F6: 0.25 | H6: repairing the mill spindle this year 5 shilling.
A7: Cost of the mill | B7: 0 | C7: 0 | D7: 6 | F7: 0.03 | H7: shoeing 1 horse for the year 6pence.
A8: Cost of the mill | B8: 0 | C8: 0 | D8: 8 | F8: 0.03 | H8: mending 1 saddle-pad and surcingle 8pence.
A9: Cost of the mill | B9: 0 | C9: 4 | D9: 0 | F9: 0.2 | H9: cogs and rungs bought 4 shilling.
A10: Cost of the mill | B10: 0 | C10: 1 | D10: 4 | F10: 0.07 | H10: tallow for the same 1 shilling 4pence.
A11: Cost of the mill | B11: 0 | C11: 4 | D11: 8 | F11: 0.23 | H11: carrying 224 quarters of corn from London to the mill by boat and from the mill to London 4 shilling 8pence.
A12: Cost of the mill | B12: 0 | C12: 8 | D12: 0 | F12: 0.4 | H12: stipend of 1 miller for the year 8 shilling.
A13: Cost of the mill | B13: 0 | C13: 6 | D13: 0 | F13: 0.3 | H13: stipend of 1 man driving 1 mill-horse for the year 6 shilling.
A14: Cost of the mill | B14: 0 | C14: 16 | D14: 0 | F14: =B14+C14/20+D14/240 | H14: 12 quarters of oats bought for the fodder of the mill-horse 16 shilling, at 1 shilling 4pence a qr.
A15: Cost of the mill | B15: 0 | C15: 16 | D15: 1.5 | F15: 0.81 | H15: 10 quarters 6 bushels of oats bought for the same 16 shilling 1.5pence, at 1 shilling 6pence a qr.
A16: Cost of the mill | B16: 3 | C16: 12 | D16: 5.5 | F16: 3.62 | H16: Total, £3 12 shilling 5.5pence
A17: Cost of the mill | F17: =SUM(F3:F15) | G17: =F17-F16 | H17: Total
A19: Cost of hay | B19: 0 | C19: 16 | D19: 6 | F19: 0.83 | H19: In mowing 32 acres of meadow by piece-work this year 16 shilling, at 6pence an acre.
A20: Cost of hay | B20: 0 | C20: 1 | D20: 6 | F20: 0.08 | H20: spreading the said hay 1 shilling 6pence.
A21: Cost of hay | B21: 0 | C21: 8 | D21: 6 | F21: 0.43 | H21: haulage and porterage from the water to the land 8 shilling 6pence.
A22: Cost of hay | B22: 0 | C22: 16 | D22: 0 | F22: 0.8 | H22: tossing the said hay and making haycocks therefrom 16 shilling.
A23: Cost of hay | B23: 2 | C23: 2 | D23: 6 | F23: 2.12 | H23: carrying the said hay to the curia this year £2 2 shilling 6pence.
A24: Cost of hay | B24: 0 | C24: 7 | D24: 6 | F24: 0.38 | H24: mowing 18 acres of rowen meadow 7 shilling 6pence, at 5pence an acre.
A25: Cost of hay | B25: 0 | C25: 0 | D25: 9 | F25: 0.04 | H25: tedding 9pence.
A26: Cost of hay | B26: 0 | C26: 7 | D26: 6 | F26: 0.38 | H26: the haulage and porterage of the aforesaid hay 7 shilling 6pence.
A27: Cost of hay | B27: 0 | C27: 14 | D27: 0 | F27: =B27+C27/20+D27/240 | H27: tossing the said hay and making haycocks therefrom 14 shilling
A28: Cost of hay | B28: 5 | C28: 14 | D28: 6 | F28: 5.73 | H28: Total, £5 14 shilling 6pence
A29: Cost of hay | F29: =SUM(F19:F27) | G29: =F29-F28 | H29: Total
A31: Small expenses | B31: 0 | C31: 6 | D31: 8 | F31: 0.33 | H31: In quittance of tithe of the said meadow next to the chapel of the blessed Margaret 6 shilling 8pence.
A32: Small expenses | B32: 0 | C32: 2 | D32: 0 | F32: 0.1 | H32: tithe for the garden 2 shilling.
A33: Small expenses | B33: 0 | C33: 9 | D33: 0 | F33: 0.45 | H33: removing hay from behind the hall to the palfreys' stable by order of the bishop 9 shilling.
A34: Small expenses | B34: 0 | C34: 8 | D34: 0 | F34: 0.4 | H34: 2 weys of lead bought for the guttering of the bishop's chamber 8 shilling.
A35: Small expenses | B35: 0 | C35: 3 | D35: 0 | F35: 0.15 | H35: 1 man making the aforesaid gutters for 6 days 3 shilling, and for his mate 2 shilling.
A36: Small expenses | B36: 0 | C36: 1 | D36: 6 | F36: 0.08 | H36: tin for the same 1 shilling 6pence.
A37: Small expenses | B37: 0 | C37: 0 | D37: 6 | F37: 0.03 | H37: 3 bushels of charcoal for the same 6pence.
A38: Small expenses | B38: 0 | C38: 0 | D38: 1.5 | F38: 0.01 | H38: tallow 1.5pence.
A39: Small expenses | B39: 0 | C39: 1 | D39: 6 | F39: 0.08 | H39: 1 beam (jupa) bought for the hall 1 shilling 6pence.
A40: Small expenses | B40: 0 | C40: 0 | D40: 8 | F40: 0.03 | H40: 1 iron gudgeon for the same 8pence.
A41: Small expenses | B41: 0 | C41: 0 | D41: 8 | F41: 0.03 | H41: iron for the same 8pence.
A42: Small expenses | B42: 0 | C42: 1 | D42: 0 | F42: 0.05 | H42: carpentry for the same 1 shilling.
...

Sheet Issues of the Grange
A1: no grange - all in mill account

Sheet Issues of the Mills
A1: Gross Output | B1: Total Quantity | C1: Account Total Quarters | D1: Bought in Total Quarters | E1: Received from churchscot | F1: Sold Total Quarters | G1: Difference Produced+Bought-Sold | H1: Weighted Average Price per Quarter | I1: Value of Total Production weighted
A2: wheat | B2: 36.625 | C2: 36.625 | D2: 0 | F2: 20 | G2: =B2-F2 | H2: 0.275 | I2: =H2*B2
A3: maslin | B3: 9.375 | C3: 9.375 | D3: 0 | F3: 8.5 | G3: =B3-F3 | H3: 0.16666667 | I3: =H3*B3
A4: oats | B4: 22.75 | C4: 0 | D4: 22.75 | F4: 0 | G4: =B4-F4 | I4: =H4*B4
A6: Total Production
A7: Sales of corn (as recorded in accounts)
A10: Net output | B10: Gross output | C10: Seed quarters | D10: Seed bushels | E10: Seed total quarters | F10: tithe quarters | G10: tithe bushels | H10: tithe total | I10: manorial servants quarters | J10: manorial servants bushels | K10: manorial servants total quarters | L10: output net of tithe, seed, liveries | M10: in stock from last year | N10: Price in £ | O10: Value of net output in £ | P10: Value of sales (in "Sale of Corn") in £
A11: wheat | B11: =B2 | F11: 3 | G11: 5 | H11: =F11+G11/8 | I11: 13 | K11: =I11+J11/8 | L11: =B11-E11-H11-K11 | N11: =H2 | O11: =L11*N11
A12: maslin | B12: =B3 | G12: 7 | H12: =F12+G12/8 | K12: =I12+J12/8 | L12: =B12-E12-H12-K12 | N12: =H3 | O12: =L12*N12
A13: oats | B13: =B4 | H13: =F13+G13/8 | I13: 22 | J13: 6 | K13: =I13+J13/8 | L13: =B13-E13-H13-K13 | N13: =H4 | O13: =L13*N13
A15: Total

Sheet Stock
A1: SOUTHWARK STOCK ACCOUNT
C3: added | G3: subtracted
A4: Livestock | B4: Inherited stock | C4: added | D4: strays | E4: herbage | F4: churchscot | G4: of which in default | H4: sold | I4: in murrain | J4: accounted for elsewhere | K4: End-period stock | L4: cross-check | M4: stock building | N4: raw production | O4: Unit price (£) | P4: Value of stock (£) at given value | Q4: Value of stock (£) at sales prices | R4: Sales in (£) | S4: Value of stock building (£) | T4: Value of production (£) at sales prices | U4: Details
A5: Cart-horses | B5: 1 | K5: 1
A6: Mares
A7: Plough horses
A8: Colts (unspecified years)
A9: Colts (2 years)
A10: Colts (1 year)
A11: Foals
A12: Oxen
A13: Bulls
A14: Cows
A15: Steers
A16: Bullocks
A17: Yearlings
... A128: brass posnets

Sheet raw data
A1: Heading | B1: Sentence | C1: Total in Pounds | D1: Pounds | E1: Shillings | F1: Pence | G1: Corn | H1: Total Quarters Except 1 | I1: Total Bushels Except 1 | J1: Total Corn Cross-Check | K1: Total Corn Manorial Account | L1: Corn Quantity Error | M1: Quarters 1 | N1: Bushels 1 | O1: Quarters 2 | P1: Bushels 2 | Q1: shilling a quarter 1 | R1: pence a quarter 1 | S1: shilling a quarter 2 | T1: pence a quarter 2 | U1: shilling a quarter 3 | V1: pence a quarter 3 | W1: shilling a quarter 4 | X1: pence a quarter 4 | Y1: shilling a bushel 1 | Z1: pence a bushel 1 | AA1: shilling a bushel 2 | AB1: pence a bushel 2 | AC1: shilling a bushel 3 | AD1: pence a bushel 3 | AE1: shilling a bushel 4 | AF1: pence a bushel 4
A2: Arrears | B2: The same render account for £8 4 shilling 0.75pence of arrears from the previous year. | C2: 8.2 | D2: 8 | E2: 4 | F2: 0.75 | H2: 0 | I2: 0 | J2: 0 | K2: 0 | L2: 0 | M2: 0 | N2: 0
A3: Arrears | B3: Delivered | C3: 0 | D3: 0 | E3: 0 | F3: 0 | H3: 0 | I3: 0 | J3: 0 | K3: 0 | L3: 0 | M3: 0 | N3: 0
A4: Arrears | B4: to Sir Geoffrey by 1 tally. | C4: 0 | D4: 0 | E4: 0 | F4: 0 | H4: 0 | I4: 0 | J4: 0 | K4: 0 | L4: 0 | M4: 0 | N4: 0
A5: Arrears | B5: They are quit. | C5: 0 | D5: 0 | E5: 0 | F5: 0 | H5: 0 | I5: 0 | J5: 0 | K5: 0 | L5: 0 | M5: 0 | N5: 0
A6: Rents of assize | B6: The same render account for £8 1 shilling 10.5pence for all rents of assize in London and Southwark at Easter (22 April). | C6: 8.09 | D6: 8 | E6: 1 | F6: 10.5 | H6: 0 | I6: 0 | J6: 0 | K6: 0 | L6: 0 | M6: 0 | N6: 0
A7: Rents of assize | B7: £8 1 shilling 10.5pence at Michaelmas (29 September). | C7: 8.09 | D7: 8 | E7: 1 | F7: 10.5 | H7: 0 | I7: 0 | J7: 0 | K7: 0 | L7: 0 | M7: 0 | N7: 0
A8: Rents of assize | B8: Total, £16 3 shilling 9pence | C8: 16.19 | D8: 16 | E8: 3 | F8: 9 | H8: 0 | I8: 0 | J8: 0 | K8: 0 | L8: 0 | M8: 0 | N8: 0
A9: Decayed rents | B9: In default of the rent of the tenement of Richard de Holebrok', because it is not built upon, nor enclosed, nor is there anything growing on it from which it would be possible to levy a rent, 10 shilling 2pence. | C9: 0.51 | D9: 0 | E9: 10 | F9: 2 | H9: 0 | I9: 0 | J9: 0 | K9: 0 | L9: 0 | M9: 0 | N9: 0
A10: Decayed rents | B10: the tenement which belonged to William Wellyng', 2 shilling this year, because it is not possible to levy a rent. | C10: 0.1 | D10: 0 | E10: 2 | F10: 0 | H10: 0 | I10: 0 | J10: 0 | K10: 0 | L10: 0 | M10: 0 | N10: 0
A11: Decayed rents | B11: the queen's garden 10 shilling 6pence. | C11: 0.53 | D11: 0 | E11: 10 | F11: 6 | H11: 0 | I11: 0 | J11: 0 | K11: 0 | L11: 0 | M11: 0 | N11: 0
A12: Decayed rents | B12: the tenement of the earl of Lancaster 2 shilling. | C12: 0.1 | D12: 0 | E12: 2 | F12: 0 | H12: 0 | I12: 0 | J12: 0 | K12: 0 | L12: 0 | M12: 0 | N12: 0
A13: Decayed rents | B13: the tenement of Laurence Hardel 1 shilling, because it is not possible to levy a rent this year. | C13: 0.05 | D13: 0 | E13: 1 | F13: 0 | H13: 0 | I13: 0 | J13: 0 | K13: 0 | L13: 0 | M13: 0 | N13: 0
... A28: Issues of the manor | B28: nothing from the pinfold this year because it is submergepence Total, £4 11 shilling 8pence | C28: 4.58 | D28: 4 | E28: 11 | F28: 8 | H28: 0 | I28: 0 | J28: 0 | K28: 0 | L28: 0 | M28: 0 | N28: 0
A29: Sale of corn | B29: The same render account for £2 16 shilling 8pence from 10 quarters of wheat sold from the issue of the mill, at 5 shilling 8pence a quarters. | C29: 2.83 | D29: 2 | E29: 16 | F29: 8 | G29: wheat | H29: 10 | I29: 0 | J29: 10 | K29: 10 | L29: 0 | M29: 10 | N29: 0 | Q29: 5 | R29: 8
A30: Sale of corn | B30: £2 13 shilling 4pence from 10 quarters of wheat sold from the same issue, at 5 shilling 4pence a quarters. | C30: 2.67 | D30: 2 | E30: 13 | F30: 4 | G30: wheat | H30: 10 | I30: 0 | J30: 10 | K30: 10 | L30: 0 | M30: 10 | N30: 0 | Q30: 5 | R30: 4
A31: Sale of corn | B31: £1 8 shilling 4pence from 8.5 quarters of maslin sold from the issue of the mill, at 3 shilling 4pence a quarters. | C31: 1.42 | D31: 1 | E31: 8 | F31: 4 | G31: maslin | H31: 8.5 | I31: 0 | J31: 8.5 | K31: 8.5 | L31: 0 | M31: 8.5 | N31: 0 | Q31: 3 | R31: 4
A32: Sale of corn | B32: Total, £6 18 shilling 4pence | C32: 6.92 | D32: 6 | E32: 18 | F32: 4 | H32: 0 | I32: 0 | J32: 0 | K32: 0 | L32: 0 | M32: 0 | N32: 0
A33: Perquisites | B33: The same render account for 6pence from John Baldewyn' and his pledges. | C33: 0.03 | D33: 0 | E33: 0 | F33: 6 | H33: 0 | I33: 0 | J33: 0 | K33: 0 | L33: 0 | M33: 0 | N33: 0
A34: Perquisites | B34: 6pence from Emma, wife of Roginald Pistor'. | C34: 0.03 | D34: 0 | E34: 0 | F34: 6 | H34: 0 | I34: 0 | J34: 0 | K34: 0 | L34: 0 | M34: 0 | N34: 0
A35: Perquisites | B35: 3pence from John de Wynton' for many transgressions. | C35: 0.01 | D35: 0 | E35: 0 | F35: 3 | H35: 0 | I35: 0 | J35: 0 | K35: 0 | L35: 0 | M35: 0 | N35: 0
A36: Perquisites | B36: 3pence from Simon de Merton' for the same. | C36: 0.01 | D36: 0 | E36: 0 | F36: 3 | H36: 0 | I36: 0 | J36: 0 | K36: 0 | L36: 0 | M36: 0 | N36: 0
A37: Perquisites | B37: 1 shilling from the whole tithing for concealment. | C37: 0.05 | D37: 0 | E37: 1 | F37: 0 | H37: 0 | I37: 0 | J37: 0 | K37: 0 | L37: 0 | M37: 0 | N37: 0
A38: Perquisites | B38: 3pence from William le Lech' for breaking the assize of ale. | C38: 0.01 | D38: 0 | E38: 0 | F38: 3 | H38: 0 | I38: 0 | J38: 0 | K38: 0 | L38: 0 | M38: 0 | N38: 0
A39: Perquisites | B39: 3pence from John le Sthalou' for the same. | C39: 0.01 | D39: 0 | E39: 0 | F39: 3 | H39: 0 | I39: 0 | J39: 0 | K39: 0 | L39: 0 | M39: 0 | N39: 0
A40: Perquisites | B40: 3pence from Roger le Horsdrivare for the same. | C40: 0.01 | D40: 0 | E40: 0 | F40: 3 | H40: 0 | I40: 0 | J40: 0 | K40: 0 | L40: 0 | M40: 0 | N40: 0
A41: Perquisites | B41: 3pence from Stephen Bost for the same. | C41: 0.01 | D41: 0 | E41: 0 | F41: 3 | H41: 0 | I41: 0 | J41: 0 | K41: 0 | L41: 0 | M41: 0 | N41: 0
A42: Perquisites | B42: 3pence from John Wynterman. | C42: 0.01 | D42: 0 | E42: 0 | F42: 3 | H42: 0 | I42: 0 | J42: 0 | K42: 0 | L42: 0 | M42: 0 | N42: 0
A43: Perquisites | B43: 2 shilling from the whole tithing. | C43: 0.1 | D43: 0 | E43: 2 | F43: 0 | H43: 0 | I43: 0 | J43: 0 | K43: 0 | L43: 0 | M43: 0 | N43: 0
... A64: Cost of the mill | B64: stipend of 1 man driving 1 mill-horse for the year 6 shilling. | C64: 0.3 | D64: 0 | E64: 6 | F64: 0 | H64: 0 | I64: 0 | J64: 0 | K64: 0 | L64: 0 | M64: 0 | N64: 0
A65: Cost of the mill | B65: 12 quarters of oats bought for the fodder of the mill-horse 16 shilling, at 1 shilling 4pence a quarters. | C65: 0.82 | D65: 0 | E65: 16 | F65: 4 | G65: oats | H65: 12 | I65: 0 | J65: 12 | K65: 12 | L65: 0 | M65: 12 | N65: 0 | Q65: 1 | R65: 4
A66: Cost of the mill | B66: . | C66: 0 | D66: 0 | E66: 0 | F66: 0 | H66: 0 | I66: 0 | J66: 0 | K66: 0 | L66: 0 | M66: 0 | N66: 0
A67: Cost of the mill | B67: 10 quarters 6 bushels of oats bought for the same 16 shilling 1.5pence, at 1 shilling 6pence a quarters. | C67: 0.81 | D67: 0 | E67: 16 | F67: 1.5 | G67: oats | H67: 10 | I67: 6 | J67: 10.75 | K67: 10.75 | L67: 0 | M67: 10 | N67: 6 | Q67: 1 | R67: 6
A68: Cost of the mill | B68: Total, £3 12 shilling 5.5pence | C68: 3.62 | D68: 3 | E68: 12 | F68: 5.5 | H68: 0 | I68: 0 | J68: 0 | K68: 0 | L68: 0 | M68: 0 | N68: 0
A69: Cost of hay | B69: In mowing 32 acres of meadow by piece-work this year 16 shilling, at 6pence an acre. | C69: 0.83 | D69: 0 | E69: 16 | F69: 6 | H69: 0 | I69: 0 | J69: 0 | K69: 0 | L69: 0 | M69: 0 | N69: 0
A70: Cost of hay | B70: . | C70: 0 | D70: 0 | E70: 0 | F70: 0 | H70: 0 | I70: 0 | J70: 0 | K70: 0 | L70: 0 | M70: 0 | N70: 0
A71: Cost of hay | B71: spreading the said hay 1 shilling 6pence. | C71: 0.08 | D71: 0 | E71: 1 | F71: 6 | H71: 0 | I71: 0 | J71: 0 | K71: 0 | L71: 0 | M71: 0 | N71: 0
A72: Cost of hay | B72: haulage and porterage from the water to the land 8 shilling 6pence. | C72: 0.43 | D72: 0 | E72: 8 | F72: 6 | H72: 0 | I72: 0 | J72: 0 | K72: 0 | L72: 0 | M72: 0 | N72: 0
A73: Cost of hay | B73: tossing the said hay and making haycocks therefrom 16 shilling. | C73: 0.8 | D73: 0 | E73: 16 | F73: 0 | H73: 0 | I73: 0 | J73: 0 | K73: 0 | L73: 0 | M73: 0 | N73: 0
A74: Cost of hay | B74: carrying the said hay to the curia this year £2 2 shilling 6pence. | C74: 2.12 | D74: 2 | E74: 2 | F74: 6 | H74: 0 | I74: 0 | J74: 0 | K74: 0 | L74: 0 | M74: 0 | N74: 0
...

Sheet Issues of the Grange raw
A1: Heading | B1: Sentence | C1: Quarters 1_x | D1: Bushels 1_x | E1: Sown Quarters | F1: Sown Bushels | G1: Sown Total Quarters | H1: Bought in Quarters | I1: Bought in Bushels | J1: Bought in Total Quarters | K1: Tithe Quarters | L1: Tithe Bushels | M1: Tithe Total Quarters | N1: Manorial servants & livestock Quarters | O1: Manorial servants & livestock Bushels | P1: Manorial servants & livestock Total Quarters | Q1: Sold Quarters | R1: Sold Bushels | S1: Sold Total Quarters | T1: Account Quarters | U1: Account Bushels | V1: Account Total Quarters | W1: bought only | X1: Total Quarters Except 1 | Y1: Total Bushels Except 1 | Z1: Total Corn Cross-Check | AA1: Total Corn Manorial Account | AB1: Corn Quantity Error | AC1: Quarters 1_y | AD1: Bushels 1_y | AE1: Quarters 2 | AF1: Bushels 2
A2: Total of all expenses | B2: Total | C2: 0 | D2: 0 | E2: 0 | F2: 0 | G2: 0 | H2: 0 | I2: 0 | J2: 0 | K2: 0 | L2: 0 | M2: 0 | N2: 0 | O2: 0 | P2: 0 | Q2: 0 | R2: 0 | S2: 0 | T2: 0 | U2: 0 | V2: 0 | W2: 0
A3: Wheat | B3: The same render account for.36 quarters 5 bushels of wheat from the issue of the mill by 1 tally against John le Fennere and John Molendinarius. | C3: 0 | D3: 0 | E3: 0 | F3: 0 | G3: 0 | H3: 0 | I3: 0 | J3: 0 | K3: 0 | L3: 0 | M3: 0 | N3: 0 | O3: 0 | P3: 0 | Q3: 0 | R3: 0 | S3: 0 | T3: 36 | U3: 5 | V3: 36.625 | W3: 0 | X3: 36 | Y3: 5 | Z3: 36.625 | AA3: 36.625 | AB3: 0 | AC3: 36 | AD3: 5
A4: Wheat | B4: Total, 36 quarters 5 bushels. | C4: 0 | D4: 0 | E4: 0 | F4: 0 | G4: 0 | H4: 0 | I4: 0 | J4: 0 | K4: 0 | L4: 0 | M4: 0 | N4: 0 | O4: 0 | P4: 0 | Q4: 0 | R4: 0 | S4: 0 | T4: 0 | U4: 0 | V4: 0 | W4: 0 | X4: 36 | Y4: 5 | Z4: 36.625 | AA4: 36.625 | AB4: 0 | AC4: 36 | AD4: 5
A5: Wheat | B5: tithe, 3 quarters 5 bushels Delivered to 1 miller and 1 man driving 1 mill-horse for the year, 13 quarters. | C5: 0 | D5: 0 | E5: 0 | F5: 0 | G5: 0 | H5: 0 | I5: 0 | J5: 0 | K5: 16 | L5: 5 | M5: 16.625 | N5: 0 | O5: 0 | P5: 0 | Q5: 0 | R5: 0 | S5: 0 | T5: 0 | U5: 0 | V5: 0 | W5: 0 | X5: 13 | Y5: 5 | Z5: 13.625 | AA5: 3.625 | AB5: 10 | AC5: 3 | AD5: 5 | AE5: 13 | AF5: 0
A6: Wheat | B6: Sold as noted within (ut infra), 20 quarters. | C6: 0 | D6: 0 | E6: 0 | F6: 0 | G6: 0 | H6: 0 | I6: 0 | J6: 0 | K6: 0 | L6: 0 | M6: 0 | N6: 0 | O6: 0 | P6: 0 | Q6: 20 | R6: 0 | S6: 20 | T6: 0 | U6: 0 | V6: 0 | W6: 0 | X6: 20 | Y6: 0 | Z6: 20 | AA6: 20 | AB6: 0 | AC6: 20 | AD6: 0
A7: Wheat | B7: Total as above. | C7: 0 | D7: 0 | E7: 0 | F7: 0 | G7: 0 | H7: 0 | I7: 0 | J7: 0 | K7: 0 | L7: 0 | M7: 0 | N7: 0 | O7: 0 | P7: 0 | Q7: 0 | R7: 0 | S7: 0 | T7: 0 | U7: 0 | V7: 0 | W7: 0 | X7: 0 | Y7: 0 | Z7: 0 | AA7: 0 | AB7: 0 | AC7: 0 | AD7: 0
A8: Wheat | B8: It balances. | C8: 0 | D8: 0 | E8: 0 | F8: 0 | G8: 0 | H8: 0 | I8: 0 | J8: 0 | K8: 0 | L8: 0 | M8: 0 | N8: 0 | O8: 0 | P8: 0 | Q8: 0 | R8: 0 | S8: 0 | T8: 0 | U8: 0 | V8: 0 | W8: 0 | X8: 0 | Y8: 0 | Z8: 0 | AA8: 0 | AB8: 0 | AC8: 0 | AD8: 0
A9: Wheat | B9: Total | C9: 0 | D9: 0 | E9: 0 | F9: 0 | G9: 0 | H9: 0 | I9: 0 | J9: 0 | K9: 0 | L9: 0 | M9: 0 | N9: 0 | O9: 0 | P9: 0 | Q9: 0 | R9: 0 | S9: 0 | T9: 0 | U9: 0 | V9: 0 | W9: 0
A10: Maslin | B10: The same render account for 9 quarters 3 bushels of marlin from the issue of the mill by tally against the aforesaipence Total, 9 quarters 3 bushels | C10: 0 | D10: 0 | E10: 0 | F10: 0 | G10: 0 | H10: 0 | I10: 0 | J10: 0 | K10: 0 | L10: 0 | M10: 0 | N10: 0 | O10: 0 | P10: 0 | Q10: 0 | R10: 0 | S10: 0 | T10: 18 | U10: 6 | V10: 18.75 | W10: 0 | X10: 9 | Y10: 3 | Z10: 9.375 | AA10: 9.375 | AB10: 0 | AC10: 9 | AD10: 3 | AE10: 9 | AF10: 3
A11: Maslin | B11: In tithe, 7 bushels Sold as noted within, 8 quarters 4 bushels Total as above. | C11: 0 | D11: 0 | E11: 0 | F11: 0 | G11: 0 | H11: 0 | I11: 0 | J11: 0 | K11: 8 | L11: 4 | M11: 8.5 | N11: 0 | O11: 0 | P11: 0 | Q11: 8 | R11: 4 | S11: 8.5 | T11: 0 | U11: 0 | V11: 0 | W11: 0 | X11: 8 | Y11: 4 | Z11: 8.5 | AA11: 0.875 | AB11: 7.625 | AC11: 0 | AD11: 7 | AE11: 8 | AF11: 4
A12: Maslin | B12: It balances. | C12: 0 | D12: 0 | E12: 0 | F12: 0 | G12: 0 | H12: 0 | I12: 0 | J12: 0 | K12: 0 | L12: 0 | M12: 0 | N12: 0 | O12: 0 | P12: 0 | Q12: 0 | R12: 0 | S12: 0 | T12: 0 | U12: 0 | V12: 0 | W12: 0 | X12: 0 | Y12: 0 | Z12: 0 | AA12: 0 | AB12: 0 | AC12: 0 | AD12: 0
A13: Maslin | B13: Total | C13: 0 | D13: 0 | E13: 0 | F13: 0 | G13: 0 | H13: 0 | I13: 0 | J13: 0 | K13: 0 | L13: 0 | M13: 0 | N13: 0 | O13: 0 | P13: 0 | Q13: 0 | R13: 0 | S13: 0 | T13: 0 | U13: 0 | V13: 0 | W13: 0
A14: Oats | B14: The same render account for 22 quarters 6 bushels of oats bought as noted within. | C14: 0 | D14: 0 | E14: 0 | F14: 0 | G14: 0 | H14: 22 | I14: 6 | J14: 22.75 | K14: 0 | L14: 0 | M14: 0 | N14: 0 | O14: 0 | P14: 0 | Q14: 0 | R14: 0 | S14: 0 | T14: 22 | U14: 6 | V14: 22.75 | W14: 1 | X14: 22 | Y14: 6 | Z14: 22.75 | AA14: 22.75 | AB14: 0 | AC14: 22 | AD14: 6
A15: Oats | B15: Total, 22 quarters 6 bushels All in fodder of the mill-horse. | C15: 0 | D15: 0 | E15: 0 | F15: 0 | G15: 0 | H15: 0 | I15: 0 | J15: 0 | K15: 0 | L15: 0 | M15: 0 | N15: 22 | O15: 6 | P15: 22.75 | Q15: 0 | R15: 0 | S15: 0 | T15: 0 | U15: 0 | V15: 0 | W15: 0 | X15: 22 | Y15: 6 | Z15: 22.75 | AA15: 22.75 | AB15: 0 | AC15: 22 | AD15: 6
A16: Oats | B16: None remains. | C16: 0 | D16: 0 | E16: 0 | F16: 0 | G16: 0 | H16: 0 | I16: 0 | J16: 0 | K16: 0 | L16: 0 | M16: 0 | N16: 0 | O16: 0 | P16: 0 | Q16: 0 | R16: 0 | S16: 0 | T16: 0 | U16: 0 | V16: 0 | W16: 0 | X16: 0 | Y16: 0 | Z16: 0 | AA16: 0 | AB16: 0 | AC16: 0 | AD16: 0
A17: Oats | B17: Horses: 1 remains. | C17: 0 | D17: 0 | E17: 0 | F17: 0 | G17: 0 | H17: 0 | I17: 0 | J17: 0 | K17: 0 | L17: 0 | M17: 0 | N17: 0 | O17: 0 | P17: 0 | Q17: 0 | R17: 0 | S17: 0 | T17: 0 | U17: 0 | V17: 0 | W17: 0 | X17: 0 | Y17: 0 | Z17: 0 | AA17: 0 | AB17: 0 | AC17: 0 | AD17: 0
A18: Oats | B18: Total, 1. 1 remains. | C18: 0 | D18: 0 | E18: 0 | F18: 0 | G18: 0 | H18: 0 | I18: 0 | J18: 0 | K18: 0 | L18: 0 | M18: 0 | N18: 0 | O18: 0 | P18: 0 | Q18: 0 | R18: 0 | S18: 0 | T18: 0 | U18: 0 | V18: 0 | W18: 0 | X18: 0 | Y18: 0 | Z18: 0 | AA18: 0 | AB18: 0 | AC18: 0 | AD18: 0
A19: Oats | B19: Total | C19: 0 | D19: 0 | E19: 0 | F19: 0 | G19: 0 | H19: 0 | I19: 0 | J19: 0 | K19: 0 | L19: 0 | M19: 0 | N19: 0 | O19: 0 | P19: 0 | Q19: 0 | R19: 0 | S19: 0 | T19: 0 | U19: 0 | V19: 0 | W19: 0

Sheet Sale of Corn Prices
A1: Heading | B1: Sentence | C1: Total in Pounds | D1: Pounds | E1: Shillings | F1: Pence | G1: Corn | H1: Total Quarters Except 1 | I1: Total Bushels Except 1 | J1: Total Corn Cross-Check | K1: Total Corn Manorial Account | L1: Corn Quantity Error | M1: Quarters 0 | N1: Bushels 0 | O1: shilling a quarter 1 | P1: pence a quarter 1 | Q1: Quarters 1 | R1: Bushels 1 | S1: shilling a quarter 2 | T1: pence a quarter 2 | U1: shilling a quarter 3 | V1: pence a quarter 3 | W1: shilling a quarter 4 | X1: pence a quarter 4 | Y1: £ a quarter 1 | Z1: £ a quarter 2 | AA1: £ a quarter 3 | AB1: £ a quarter 4 | AC1: Quarters Sold | AD1: Weighted Average Price per Quarter | AE1: Non-Weighted Average Price per Quarter | AF1: Corn lowercase
A2: Sale of corn | B2: The same render account for £2 16 shilling 8pence from 10 quarters of wheat sold from the issue of the mill, at 5 shilling 8pence a quarters. | C2: 2.83 | D2: 2 | E2: 16 | F2: 8 | G2: wheat | H2: 10 | I2: 0 | J2: 10 | K2: 10 | L2: 0 | M2: 10 | N2: 0 | O2: 5 | P2: 8 | Y2: 0.28333333 | AC2: 10 | AD2: 0.28333333 | AE2: 0.28333333 | AF2: wheat
A3: Sale of corn | B3: £2 13 shilling 4pence from 10 quarters of wheat sold from the same issue, at 5 shilling 4pence a quarters. | C3: 2.67 | D3: 2 | E3: 13 | F3: 4 | G3: wheat | H3: 10 | I3: 0 | J3: 10 | K3: 10 | L3: 0 | M3: 10 | N3: 0 | O3: 5 | P3: 4 | Y3: 0.26666667 | AC3: 10 | AD3: 0.26666667 | AE3: 0.26666667 | AF3: wheat
A4: Sale of corn | B4: £1 8 shilling 4pence from 8.5 quarters of maslin sold from the issue of the mill, at 3 shilling 4pence a quarters. | C4: 1.42 | D4: 1 | E4: 8 | F4: 4 | G4: maslin | H4: 8.5 | I4: 0 | J4: 8.5 | K4: 8.5 | L4: 0 | M4: 8.5 | N4: 0 | O4: 3 | P4: 4 | Y4: 0.16666667 | AC4: 8.5 | AD4: 0.16666667 | AE4: 0.16666667 | AF4: maslin
A5: Sale of corn | B5: Total, £6 18 shilling 4pence | C5: 6.92 | D5: 6 | E5: 18 | F5: 4 | H5: 0 | I5: 0 | J5: 0 | K5: 0 | L5: 0 | M5: 0 | N5: 0 | Y5: inf | AC5: 0 | AD5: inf | AE5: inf
