Workbook

Sheet StGilesFair Overview - Completed
A1: STGILESFAIR OVERVIEW - COMPLETED | B1: Total in £ | C1: Error | D1: Note
A2: CASH ACCOUNT
A3: RECEIPTS
A4: Arrears total
A5: Rents of assize total
A6: Quittances total
A7: Defaults of rent total
A8: Defaults of rent through the pestilence total
A9: Cotlands defaults total
A10: Cotlands total
A11: Total of quittances and defaults of rent total
A12: Total of rents remaining clear total
A13: Farms total
... A22: Farm of the demesne land total
A23: Total of all receipts (calculated here) | B23: =SUM(B5:B22)
A24: Total of all receipts (calculated here) incl arrears | B24: =SUM(B4:B22)
A25: Total recorded in the accounts excl. arrears | C25: =B23-B25
A26: Total recorded in the accounts incl. arrears | B26: =B25+B4
A29: EXPENSES
A30: Cost of ploughs total
A31: Purchase of corn total
A32: Cost of carts and wagons total
A33: Cost of dairy total
A34: Purchase of stock total
A35: Sheepcote total
A36: Cost of buildings total
A37: Threshing total
A38: Barley expenses
A39: Expenses of the harvest total
A40: Necessary expenses
... A47: Total Demesne fixed investment
A49: Owed by the reeve | B49: =B23-B45
A50: From accounts
A52: Allowances
A53: Cash deliveries
A54: Sum of the above | B54: =SUM(B52:B53)
A55: Total of all allowances and cash deliveries in accounts
A57: Net amount owed | B57: =B50-B54
A58: Net amount owed in accounts
A60: GRANGE ACCOUNT | B60: Total Production | D60: Value of total gross production in £ | E60: Value of total net production in £
...

Sheet Prices
A1: Meat & Dairy Prices
C2: 1301 | D2: 1302 | E2: Average
A3: Beef | B3: £ per lb | C3: 0.0033351854 | D3: 0.0032608538 | E3: =AVERAGE(C3:D3)
A4: Mutton | B4: £ per lb | C4: 0.0036593977 | D4: 0.0037125513 | E4: =AVERAGE(C4:D4)
A5: Pork | B5: £ per lb | C5: 0.0038431326 | D5: 0.0037574803 | E5: =AVERAGE(C5:D5)
A6: Cheese | B6: £ per lb | C6: 0.0055768754 | D6: 0.0056654898 | E6: =AVERAGE(C6:D6)
A7: Butter | B7: £ per lb | C7: 0.0036626221 | D7: 0.0035935077 | E7: =AVERAGE(C7:D7)
A8: Milk | B8: £ per gallon | C8: 0.0055768754 | D8: 0.0056654898 | E8: =AVERAGE(C8:D8)

Sheet Labour Rents

Sheet Overview
A1: ST GILES FAIR | B1: Total in £ | C1: Error | D1: Note
A2: CASH ACCOUNT
A3: RECEIPTS
A4: Arrears total
A5: Rents of assize total
A6: Quittances total
A7: Defaults of rent total
A8: Defaults of rent through the pestilence total
A9: Cotlands defaults total
A10: Cotlands total
A11: Total of quittances and defaults of rent total
A12: Total of rents remaining clear total
A13: Farms total
... A183: % of capital expenses as calculated previously

Sheet Receipts
A1: ST GILES FAIR RECEIPTS
A2: Heading | B2: £ | C2: s | D2: d | F2: Total in £ | G2: Error | H2: Notes
A3: South Gate | B3: 0 | C3: 1 | D3: 2 | F3: 0.06 | H3: The first, second, third and fourth day, 1 shilling 2pence.
A4: South Gate | B4: 0 | C4: 3 | D4: 0 | F4: 0.15 | H4: the fifth day, 3 shilling.
A5: South Gate | B5: 0 | C5: 5 | D5: 7 | F5: 0.28 | H5: the sixth day, 5 shilling 7pence.
A6: South Gate | B6: 0 | C6: 17 | D6: 4 | F6: 0.87 | H6: the seventh day, 17 shilling 4pence.
A7: South Gate | B7: 0 | C7: 12 | D7: 4 | F7: 0.62 | H7: the eighth day, 12 shilling 4pence.
A8: South Gate | B8: 0 | C8: 1 | D8: 1 | F8: 0.05 | H8: the ninth day, 1 shilling 1pence.
A9: South Gate | B9: 0 | C9: 2 | D9: 6 | F9: 0.12 | H9: the tenth day, 2 shilling 6pence.
A10: South Gate | B10: 0 | C10: 2 | D10: 3 | F10: 0.11 | H10: the eleventh day, 2 shilling 3pence.
A11: South Gate | B11: 0 | C11: 2 | D11: 7 | F11: 0.13 | H11: the twelfth day, 2 shilling 7pence.
A12: South Gate | B12: 0 | C12: 3 | D12: 2 | F12: 0.16 | H12: the thirteenth day, 3 shilling 2pence.
A13: South Gate | B13: 0 | C13: 1 | D13: 1 | F13: 0.05 | H13: the fourteenth day, 1 shilling 1pence.
A14: South Gate | B14: 0 | C14: 4 | D14: 5 | F14: 0.22 | H14: the fifteenth day, 4 shilling 5pence.
A15: South Gate | B15: 0 | C15: 3 | D15: 0 | F15: =B15+C15/20+D15/240 | H15: the sixteenth day, 3 shilling
A16: South Gate | B16: 2 | C16: 19 | D16: 6 | F16: 2.98 | H16: Total, £2 19 shilling 6pence
A17: South Gate | F17: =SUM(F3:F15) | G17: =F17-F16 | H17: Total
A19: East gate | B19: 0 | C19: 0 | D19: 0 | F19: 0 | H19: The first, second, third and fourth day, nothing.
A20: East gate | B20: 0 | C20: 0 | D20: 0 | F20: 0 | H20: the fifth day, nothing.
A21: East gate | B21: 0 | C21: 1 | D21: 4 | F21: 0.07 | H21: the sixth day, 1 shilling 4pence.
A22: East gate | B22: 0 | C22: 0 | D22: 6 | F22: 0.03 | H22: the seventh day, 6pence.
A23: East gate | B23: 0 | C23: 1 | D23: 2 | F23: 0.06 | H23: the eighth day, 1 shilling 2pence.
A24: East gate | B24: 0 | C24: 2 | D24: 6 | F24: 0.12 | H24: the ninth day, 2 shilling 6pence.
A25: East gate | B25: 0 | C25: 0 | D25: 6 | F25: 0.03 | H25: the tenth day, 6pence.
A26: East gate | B26: 0 | C26: 3 | D26: 7 | F26: 0.18 | H26: the eleventh day, 3 shilling 7pence.
A27: East gate | B27: 0 | C27: 1 | D27: 9 | F27: 0.09 | H27: the twelfth day, 1 shilling 9pence.
A28: East gate | B28: 0 | C28: 0 | D28: 6 | F28: 0.03 | H28: the thirteenth day, 6pence.
A29: East gate | B29: 0 | C29: 0 | D29: 9 | F29: 0.04 | H29: the fourteenth day, 9pence.
A30: East gate | B30: 0 | C30: 0 | D30: 6 | F30: 0.03 | H30: the fifteenth day, 6pence.
A31: East gate | B31: 0 | C31: 0 | D31: 11 | F31: =B31+C31/20+D31/240 | H31: the sixteenth day, 11pence
A32: East gate | B32: 0 | C32: 14 | D32: 0 | F32: =B32+C32/20+D32/240 | H32: Total, 14 shilling
F33: =SUM(F19:F31) | G33: =F33-F32 | H33: Total
A35: West gate | B35: 0 | C35: 0 | D35: 6 | F35: 0.03 | H35: The first, second, third and fourth day, 6pence.
A36: West gate | B36: 0 | C36: 0 | D36: 2 | F36: 0.01 | H36: the fifth day, 2pence.
A37: West gate | B37: 0 | C37: 1 | D37: 0 | F37: 0.05 | H37: the sixth day, 1 shilling.
A38: West gate | B38: 0 | C38: 2 | D38: 11 | F38: 0.15 | H38: the seventh day, 2 shilling 11pence.
A39: West gate | B39: 0 | C39: 3 | D39: 3 | F39: 0.16 | H39: the eighth day, 3 shilling 3pence.
A40: West gate | B40: 0 | C40: 1 | D40: 3 | F40: 0.06 | H40: the ninth day, 1 shilling 3pence.
A41: West gate | B41: 0 | C41: 0 | D41: 4 | F41: 0.02 | H41: the tenth day, 4pence.
A42: West gate | B42: 0 | C42: 1 | D42: 1 | F42: 0.05 | H42: the eleventh day, 1 shilling 1pence.
...

Sheet Expenses
A1: ST GILES FAIR RECEIPTS
A2: Heading | B2: Pounds | C2: Shillings | D2: Pence | F2: Total in Pounds | G2: Error | H2: Sentence
A3: Expenses | B3: 0 | C3: 2 | D3: 8 | F3: 0.13 | H3: Keeper of the East Gate from the first day for 16 days, William in the Den' of Chidden, 2 shilling 8pence
A4: Expenses | B4: 0 | C4: 2 | D4: 8 | F4: 0.13 | H4: Keeper of the South Gate for 8 days, Hugh de Hursley and William Kyrie, 2 shilling 8pence
A5: Expenses | B5: 0 | C5: 2 | D5: 8 | F5: 0.13 | H5: Keeper of the West Gate from the first day for 16 days, Richard de Frylend', 2 shilling 8pence
A6: Expenses | B6: 0 | C6: 0 | D6: 0 | F6: 0 | H6: Keeper of saddles and ladders, fanned out to John Gentyl and John, sergeant of the Soke
A7: Expenses | B7: 0 | C7: 0 | D7: 0 | F7: 0 | H7: Keeper of animals at the fair, farmed out to Walter Crude.
A8: Expenses | B8: 0 | C8: 0 | D8: 0 | F8: 0 | H8: Keeper of animals in the meadows, farmed out to Hugh Balehorn.
A9: Expenses | B9: 0 | C9: 0 | D9: 0 | F9: 0 | H9: Keeper of the office of reeve of the city, farmed out to Peter de Portesmuth' and Walter de Tysted'; the minor reeve, John Jackemyson'.
A10: Expenses | B10: 0 | C10: 0 | D10: 0 | F10: 0 | H10: Keeper of the Romsey, Redbridge, Hursley and Crawley roads, farmed out to [John Tothull']
A11: Expenses | B11: 0 | C11: 0 | D11: 0 | F11: 0 | H11: [Keeper of the' Cheriton and Alresford roadsl, Hugh le Forster.
A12: Expenses | B12: 0 | C12: 0 | D12: 0 | F12: 0 | H12: Keeper of the traders in burel, William Sarr' and William de Colbrok'.
A13: Expenses | B13: 0 | C13: 0 | D13: 0 | F13: 0 | H13: Teasels, John Masseday, Laurence de Wilehal', Walter ate Yate.
A14: Expenses | B14: 0 | C14: 0 | D14: 0 | F14: 0 | H14: Wheels, Richard Canon, Adam Burgeys.
... A21: Expenses | B21: 1 | C21: 4 | D21: 4 | F21: 1.22 | H21: Total, £1 4 shilling 4pence
A22: Expenses | F22: =SUM(F3:F19) | G22: =F22-F21 | H22: Total

Sheet Issues of the Grange
A1: no grange

Sheet Issues of the Mills

Sheet Stock
A1: no stock account

Sheet raw data
A1: Heading | B1: Sentence | C1: Total in Pounds | D1: Pounds | E1: Shillings | F1: Pence | G1: Corn | H1: Total Quarters Except 1 | I1: Total Bushels Except 1 | J1: Total Corn Cross-Check | K1: Total Corn Manorial Account | L1: Corn Quantity Error | M1: Quarters 1 | N1: Bushels 1 | O1: shilling a quarter 1 | P1: pence a quarter 1 | Q1: shilling a quarter 2 | R1: pence a quarter 2 | S1: shilling a quarter 3 | T1: pence a quarter 3 | U1: shilling a quarter 4 | V1: pence a quarter 4 | W1: shilling a bushel 1 | X1: pence a bushel 1 | Y1: shilling a bushel 2 | Z1: pence a bushel 2 | AA1: shilling a bushel 3 | AB1: pence a bushel 3 | AC1: shilling a bushel 4 | AD1: pence a bushel 4
A2: South Gate | B2: The first, second, third and fourth day, 1 shilling 2pence. | C2: 0.06 | D2: 0 | E2: 1 | F2: 2 | H2: 0 | I2: 0 | J2: 0 | K2: 0 | L2: 0 | M2: 0 | N2: 0
A3: South Gate | B3: the fifth day, 3 shilling. | C3: 0.15 | D3: 0 | E3: 3 | F3: 0 | H3: 0 | I3: 0 | J3: 0 | K3: 0 | L3: 0 | M3: 0 | N3: 0
A4: South Gate | B4: the sixth day, 5 shilling 7pence. | C4: 0.28 | D4: 0 | E4: 5 | F4: 7 | H4: 0 | I4: 0 | J4: 0 | K4: 0 | L4: 0 | M4: 0 | N4: 0
A5: South Gate | B5: the seventh day, 17 shilling 4pence. | C5: 0.87 | D5: 0 | E5: 17 | F5: 4 | H5: 0 | I5: 0 | J5: 0 | K5: 0 | L5: 0 | M5: 0 | N5: 0
A6: South Gate | B6: the eighth day, 12 shilling 4pence. | C6: 0.62 | D6: 0 | E6: 12 | F6: 4 | H6: 0 | I6: 0 | J6: 0 | K6: 0 | L6: 0 | M6: 0 | N6: 0
A7: South Gate | B7: the ninth day, 1 shilling 1pence. | C7: 0.05 | D7: 0 | E7: 1 | F7: 1 | H7: 0 | I7: 0 | J7: 0 | K7: 0 | L7: 0 | M7: 0 | N7: 0
A8: South Gate | B8: the tenth day, 2 shilling 6pence. | C8: 0.12 | D8: 0 | E8: 2 | F8: 6 | H8: 0 | I8: 0 | J8: 0 | K8: 0 | L8: 0 | M8: 0 | N8: 0
A9: South Gate | B9: the eleventh day, 2 shilling 3pence. | C9: 0.11 | D9: 0 | E9: 2 | F9: 3 | H9: 0 | I9: 0 | J9: 0 | K9: 0 | L9: 0 | M9: 0 | N9: 0
A10: South Gate | B10: the twelfth day, 2 shilling 7pence. | C10: 0.13 | D10: 0 | E10: 2 | F10: 7 | H10: 0 | I10: 0 | J10: 0 | K10: 0 | L10: 0 | M10: 0 | N10: 0
A11: South Gate | B11: the thirteenth day, 3 shilling 2pence. | C11: 0.16 | D11: 0 | E11: 3 | F11: 2 | H11: 0 | I11: 0 | J11: 0 | K11: 0 | L11: 0 | M11: 0 | N11: 0
A12: South Gate | B12: the fourteenth day, 1 shilling 1pence. | C12: 0.05 | D12: 0 | E12: 1 | F12: 1 | H12: 0 | I12: 0 | J12: 0 | K12: 0 | L12: 0 | M12: 0 | N12: 0
A13: South Gate | B13: the fifteenth day, 4 shilling 5pence. | C13: 0.22 | D13: 0 | E13: 4 | F13: 5 | H13: 0 | I13: 0 | J13: 0 | K13: 0 | L13: 0 | M13: 0 | N13: 0
... A109: Minor sergeants | B109: Total of all expenses, £13 9 shilling 2.5pence | C109: 13.46 | D109: 13 | E109: 9 | F109: 2.5 | H109: 0 | I109: 0 | J109: 0 | K109: 0 | L109: 0 | M109: 0 | N109: 0
