Workbook

Sheet Upton Overview - Completed
A1: UPTON OVERVIEW - COMPLETED | B1: Total in £ | C1: Error | D1: Note
A2: CASH ACCOUNT
A3: RECEIPTS
A4: Arrears total
A5: Rents of assize total
A6: Quittances total
A7: Defaults of rent total
A8: Defaults of rent through the pestilence total
A9: Cotlands defaults total
A10: Cotlands total
A11: Total of quittances and defaults of rent total
A12: Total of rents remaining clear total
A13: Farms total
... A22: Farm of the demesne land total
A23: Total of all receipts (calculated here) | B23: =SUM(B5:B22)
A24: Total of all receipts (calculated here) incl arrears | B24: =SUM(B4:B22)
A25: Total recorded in the accounts excl. arrears | C25: =B23-B25
A26: Total recorded in the accounts incl. arrears | B26: =B25+B4
A29: EXPENSES
A30: Cost of ploughs total
A31: Purchase of corn total
A32: Cost of carts and wagons total
A33: Cost of dairy total
A34: Purchase of stock total
A35: Sheepcote total
A36: Cost of buildings total
A37: Threshing total
A38: Barley expenses
A39: Expenses of the harvest total
A40: Necessary expenses
... A47: Total Demesne fixed investment
A49: Owed by the reeve | B49: =B23-B45
A50: From accounts | B50: 5.1541667
A52: Allowances
A53: Cash deliveries
A54: Sum of the above | B54: =SUM(B52:B53)
A55: Total of all allowances and cash deliveries in accounts
A57: Net amount owed | B57: =B50-B54
A58: Net amount owed in accounts
A60: GRANGE ACCOUNT | B60: Total Production | D60: Value of total gross production in £ | E60: Value of total net production in £
...

Sheet Issues of the Mills
A1: No mill account for Adderbury

Sheet raw data
A1: Heading | B1: Sentence | C1: Total in Pounds | D1: Pounds | E1: Shillings | F1: Pence | G1: Corn | H1: Total Quarters Except 1 | I1: Total Bushels Except 1 | J1: Total Corn Cross-Check | K1: Total Corn Manorial Account | L1: Corn Quantity Error | M1: Quarters 1 | N1: Bushels 1 | O1: shilling a quarter 1 | P1: pence a quarter 1 | Q1: shilling a quarter 2 | R1: pence a quarter 2 | S1: shilling a quarter 3 | T1: pence a quarter 3 | U1: shilling a quarter 4 | V1: pence a quarter 4 | W1: shilling a bushel 1 | X1: pence a bushel 1 | Y1: shilling a bushel 2 | Z1: pence a bushel 2 | AA1: shilling a bushel 3 | AB1: pence a bushel 3 | AC1: shilling a bushel 4 | AD1: pence a bushel 4
A2: Adderbury | B2: The account2 of William Jakeman, reeve there, for the sixth year of the translation of Henry Beaufort', lord bishop of Winchester, and the eleventh year of the reign of King Henry the Fourth. | C2: 0 | D2: 0 | E2: 0 | F2: 0 | H2: 0 | I2: 0 | J2: 0 | K2: 0 | L2: 0 | M2: 0 | N2: 0
A3: Arrears | B3: None. | C3: 0 | D3: 0 | E3: 0 | F3: 0 | H3: 0 | I3: 0 | J3: 0 | K3: 0 | L3: 0 | M3: 0 | N3: 0
A4: Rents of assize | B4: And for £6 9 shilling 6.25pence for all rents of assize at St Thomas the Apostle (21 December). | C4: 6.48 | D4: 6 | E4: 9 | F4: 6.25 | H4: 0 | I4: 0 | J4: 0 | K4: 0 | L4: 0 | M4: 0 | N4: 0
A5: Rents of assize | B5: £6 9 shilling 8.5pence at Easter (23 March). | C5: 6.49 | D5: 6 | E5: 9 | F5: 8.5 | H5: 0 | I5: 0 | J5: 0 | K5: 0 | L5: 0 | M5: 0 | N5: 0
A6: Rents of assize | B6: £6 9 shilling 6.25pence at the Nativity of St John the Baptist (24 June). | C6: 6.48 | D6: 6 | E6: 9 | F6: 6.25 | H6: 0 | I6: 0 | J6: 0 | K6: 0 | L6: 0 | M6: 0 | N6: 0
A7: Rents of assize | B7: £6 10 shilling 1.5pence at Michaelmas (29 September). | C7: 6.51 | D7: 6 | E7: 10 | F7: 1.5 | H7: 0 | I7: 0 | J7: 0 | K7: 0 | L7: 0 | M7: 0 | N7: 0
A8: Rents of assize | B8: Total, £25 18 shilling 10.5pence. | C8: 25.94 | D8: 25 | E8: 18 | F8: 10.5 | H8: 0 | I8: 0 | J8: 0 | K8: 0 | L8: 0 | M8: 0 | N8: 0
A9: Quittances of rent | B9: In quittance of rent of 1 reeve for the year 5 shilling. | C9: 0.25 | D9: 0 | E9: 5 | F9: 0 | H9: 0 | I9: 0 | J9: 0 | K9: 0 | L9: 0 | M9: 0 | N9: 0
A10: Quittances of rent | B10: nothing this year of the 4 shilling for 1 smith forging the ironwork of 2 ploughs for the year. | C10: 0.2 | D10: 0 | E10: 4 | F10: 0 | H10: 0 | I10: 0 | J10: 0 | K10: 0 | L10: 0 | M10: 0 | N10: 0
A11: Quittances of rent | B11: nothing this year of the 4 shilling for 1 shepherd keeping the lord's wethers for the year. | C11: 0.2 | D11: 0 | E11: 4 | F11: 0 | H11: 0 | I11: 0 | J11: 0 | K11: 0 | L11: 0 | M11: 0 | N11: 0
A12: Quittances of rent | B12: nothing this year of the 4 shilling for 1 swineherd for the year. | C12: 0.2 | D12: 0 | E12: 4 | F12: 0 | H12: 0 | I12: 0 | J12: 0 | K12: 0 | L12: 0 | M12: 0 | N12: 0
A13: Quittances of rent | B13: nothing this year of the 4 shilling for 1 cowherd for the year. | C13: 0.2 | D13: 0 | E13: 4 | F13: 0 | H13: 0 | I13: 0 | J13: 0 | K13: 0 | L13: 0 | M13: 0 | N13: 0
... A149: Cost of buildings | B149: board-nails and clout-nails bought for the same 1 shilling 4pence. | C149: 0.07 | D149: 0 | E149: 1 | F149: 4 | H149: 0 | I149: 0 | J149: 0 | K149: 0 | L149: 0 | M149: 0 | N149: 0
A150: Cost of buildings | B150: 4 quarters 4 bushels of limestone bought at Walton' 5 shilling 3pence, at 1 shilling 2pence a quarters. | C150: 0.26 | D150: 0 | E150: 5 | F150: 3 | H150: 4 | I150: 4 | J150: 4.5 | K150: 4.5 | L150: 0 | M150: 4 | N150: 4 | O150: 1 | P150: 2
A151: Cost of buildings | B151: carrying the same 4pence. | C151: 0.02 | D151: 0 | E151: 0 | F151: 4 | H151: 0 | I151: 0 | J151: 0 | K151: 0 | L151: 0 | M151: 0 | N151: 0
A152: Cost of buildings | B152: 8 quarters of limestone bought at Witney 10 shilling 4pence, at 1 shilling 31 pence a quarters. | C152: 0.52 | D152: 0 | E152: 10 | F152: 4 | H152: 8 | I152: 0 | J152: 8 | K152: 8 | L152: 0 | M152: 8 | N152: 0 | O152: 1 | P152: 31
A153: Cost of buildings | B153: carrying the same from Witney to Adderbury 3 shilling 8pence. | C153: 0.18 | D153: 0 | E153: 3 | F153: 8 | H153: 0 | I153: 0 | J153: 0 | K153: 0 | L153: 0 | M153: 0 | N153: 0
A154: Cost of buildings | B154: 1,500 stone slates bought 6 shilling, at 4 shilling a 1,000.. | C154: 0.3 | D154: 0 | E154: 6 | F154: 0 | H154: 0 | I154: 0 | J154: 0 | K154: 0 | L154: 0 | M154: 0 | N154: 0
A155: Cost of buildings | B155: 500 eaves-stones bought 2 shilling 6pence, at 6pence a 100.. | C155: 0.12 | D155: 0 | E155: 2 | F155: 6 | H155: 0 | I155: 0 | J155: 0 | K155: 0 | L155: 0 | M155: 0 | N155: 0
A156: Cost of buildings | B156: 6,000 pins bought 2 shilling, at 4pence a 1,000.. | C156: 0.12 | D156: 0 | E156: 2 | F156: 4 | H156: 0 | I156: 0 | J156: 0 | K156: 0 | L156: 0 | M156: 0 | N156: 0
A157: Cost of buildings | B157: 50 ridge-tiles bought 6 shilling 3pence, at 1.5pence each. | C157: 0.31 | D157: 0 | E157: 6 | F157: 3 | H157: 0 | I157: 0 | J157: 0 | K157: 0 | L157: 0 | M157: 0 | N157: 0
A158: Cost of buildings | B158: sand bought and dug and quarried at Tadmarton 10pence. | C158: 0.04 | D158: 0 | E158: 0 | F158: 10 | H158: 0 | I158: 0 | J158: 0 | K158: 0 | L158: 0 | M158: 0 | N158: 0
A159: Cost of buildings | B159: stipend of 1 man going to Walton' to quarry lime there 2pence. | C159: 0.01 | D159: 0 | E159: 0 | F159: 2 | H159: 0 | I159: 0 | J159: 0 | K159: 0 | L159: 0 | M159: 0 | N159: 0
A160: Cost of buildings | B160: expenses of 12 men coming for a boon-work with 6 carts to quarry sand at Newotele and carry it to Adderbury, with the digging, 2 shilling 3pence. | C160: 0.11 | D160: 0 | E160: 2 | F160: 3 | H160: 0 | I160: 0 | J160: 0 | K160: 0 | L160: 0 | M160: 0 | N160: 0
A161: Cost of buildings | B161: hiring 1 man to carry sand and lime from the warrener's chamber to the barn by piece-work 4pence. | C161: 0.02 | D161: 0 | E161: 0 | F161: 4 | H161: 0 | I161: 0 | J161: 0 | K161: 0 | L161: 0 | M161: 0 | N161: 0
A162: Cost of buildings | B162: carrying the ridge-tiles bought above 8pence. | C162: 0.03 | D162: 0 | E162: 0 | F162: 8 | H162: 0 | I162: 0 | J162: 0 | K162: 0 | L162: 0 | M162: 0 | N162: 0
A163: Cost of buildings | B163: expenses of various men coming for a boon-work to buy slates at Aynho and carry them to Adderbury with the expenses of 1 man there mending the said slates 2d 1 shilling 9.5pence. | C163: 0.09 | D163: 0 | E163: 1 | F163: 9.5 | H163: 0 | I163: 0 | J163: 0 | K163: 0 | L163: 0 | M163: 0 | N163: 0
A164: Cost of buildings | B164: 1 tine bought 8pence. | C164: 0.03 | D164: 0 | E164: 0 | F164: 8 | H164: 0 | I164: 0 | J164: 0 | K164: 0 | L164: 0 | M164: 0 | N164: 0
... A181: Total of all allowances | B181: Total of all allowances and cash deliveries, £64 19 shilling 11.5pence He is quit. | C181: 65 | D181: 64 | E181: 19 | F181: 11.5 | H181: 0 | I181: 0 | J181: 0 | K181: 0 | L181: 0 | M181: 0 | N181: 0
A182: Wheat | B182: William Jakeman, reeve there, answers for 3 quarters of wheat remaining.. | C182: 0 | D182: 0 | E182: 0 | F182: 0 | G182: wheat | H182: 3 | I182: 0 | J182: 3 | K182: 3 | L182: 0 | M182: 3 | N182: 0
A183: Wheat | B183: Total, 3 quarters.. | C183: 0 | D183: 0 | E183: 0 | F183: 0 | H183: 3 | I183: 0 | J183: 3 | K183: 3 | L183: 0 | M183: 3 | N183: 0
A184: Wheat | B184: 3 quarters remain in the keeping of John Eadburbury, farmer there, to be handed back and restored at the end of his farm of 12 years, this year being the fifth. | C184: 0 | D184: 0 | E184: 0 | F184: 0 | H184: 3 | I184: 0 | J184: 3 | K184: 3 | L184: 0 | M184: 3 | N184: 0
A185: Rye | B185: And for 34 quarters of rye remaining.. | C185: 0 | D185: 0 | E185: 0 | F185: 0 | G185: rye | H185: 34 | I185: 0 | J185: 34 | K185: 34 | L185: 0 | M185: 34 | N185: 0
A186: Rye | B186: Total, 34 quarters.. | C186: 0 | D186: 0 | E186: 0 | F186: 0 | H186: 34 | I186: 0 | J186: 34 | K186: 34 | L186: 0 | M186: 34 | N186: 0
A187: Rye | B187: 34 quarters remain in the keeping of the said John Eadburbury, farmer there, to be handed back and restored at the end of his farm as before. | C187: 0 | D187: 0 | E187: 0 | F187: 0 | H187: 34 | I187: 0 | J187: 34 | K187: 34 | L187: 0 | M187: 34 | N187: 0
A188: Dredge | B188: And for 30 quarters of dredge remaining.. | C188: 0 | D188: 0 | E188: 0 | F188: 0 | G188: dredge | H188: 30 | I188: 0 | J188: 30 | K188: 30 | L188: 0 | M188: 30 | N188: 0
A189: Dredge | B189: Total, 30 quarters.. | C189: 0 | D189: 0 | E189: 0 | F189: 0 | H189: 30 | I189: 0 | J189: 30 | K189: 30 | L189: 0 | M189: 30 | N189: 0
A190: Dredge | B190: 30 quarters remain in the keeping of the said John Eadburbury, farmer there, to be handed back and restored as before. | C190: 0 | D190: 0 | E190: 0 | F190: 0 | H190: 30 | I190: 0 | J190: 30 | K190: 30 | L190: 0 | M190: 30 | N190: 0
A191: Pulses | B191: None remain. | C191: 0 | D191: 0 | E191: 0 | F191: 0 | H191: 0 | I191: 0 | J191: 0 | K191: 0 | L191: 0 | M191: 0 | N191: 0
...

Sheet Prices
A1: Meat & Dairy Prices
C2: 1301 | D2: 1302 | E2: Average
A3: Beef | B3: £ per lb | C3: 0.0033351854 | D3: 0.0032608538 | E3: =AVERAGE(C3:D3)
A4: Mutton | B4: £ per lb | C4: 0.0036593977 | D4: 0.0037125513 | E4: =AVERAGE(C4:D4)
A5: Pork | B5: £ per lb | C5: 0.0038431326 | D5: 0.0037574803 | E5: =AVERAGE(C5:D5)
A6: Cheese | B6: £ per lb | C6: 0.0055768754 | D6: 0.0056654898 | E6: =AVERAGE(C6:D6)
A7: Butter | B7: £ per lb | C7: 0.0036626221 | D7: 0.0035935077 | E7: =AVERAGE(C7:D7)
A8: Milk | B8: £ per gallon | C8: 0.0055768754 | D8: 0.0056654898 | E8: =AVERAGE(C8:D8)

Sheet Labour Rents

Sheet Upton Overview
A1: UPTON OVERVIEW | B1: £ | C1: s | D1: d | G1: Total in £ | H1: Error
A3: CASH ACCOUNT
A4: RECEIPTS
A5: Arrears | G5: ='Upton Receipts'!F5
A6: Rents of assize | G6: ='Upton Receipts'!F14
A7: Quittances | G7: ='Upton Receipts'!F22
A8: Defaults of rent | G8: ='Upton Receipts'!F27
A9: Annual reconizances
A10: Issues of the Manor | G10: ='Upton Receipts'!F39
A11: Sale of corn | G11: ='Upton Receipts'!F48
A12: Entry and marriage fines
A13: Pleas & Perquisites | G13: ='Upton Receipts'!F51
A14: Sum of the above (incl. arrears) | G14: =SUM(G5:G13)
A15: Total recorded in the accounts excl. arrears? (p.10) | G15: ='Upton Receipts'!F55 | H15: =G14-G15
A16: Total recorded in the accounts incl. arrears? (p.10) | G16: n/a
A18: EXPENSES
A19: Cost of ploughs | G19: ='Upton Expenses'!F14
A20: Purchase of corn
A21: Cost of carts and wagons | G21: ='Upton Expenses'!F25
A22: Cost of dairy
A23: Purchase of stock
A24: Sheepcote | G24: ='Upton Expenses'!F32
A25: Cost of buildings | G25: ='Upton Expenses'!F44
A26: Threshing | G26: ='Upton Expenses'!F53
A27: Expenses of the harvest | G27: ='Upton Expenses'!F63
A28: Stewards expenses
A29: Sum of the above | G29: =SUM(G19:G28)
A30: Total of all expenses | G30: ='Upton Expenses'!F65 | H30: =G29-G30
A31: Capital Expenses | G31: ='Upton Expenses'!F69
A33: Owed by the reeve | G33: ='Upton Expenses'!F67
A34: From accounts
A36: Cash deliveries | G36: ='Upton Expenses'!F68
A37: Cash delivers (Hindon Borough)
A38: Sum of the above | B38: =SUM(B36:B37) | C38: =SUM(C36:C37) | D38: =SUM(D36:D37) | E38: =SUM(E36:E37) | G38: =SUM(G36:G37)
A39: Total of all allowances and cash deliveries in accounts | B39: n/a
A41: Net amount owed | G41: ='Upton Expenses'!F67
A42: Net amount owed in accounts | H42: =G41-G42
A44: GRANGE ACCOUNT | B44: Total Production
A45: Grange | B45: qrs | C45: bus | G45: Value of total gross production in £ | H45: Value of total net production in £
A46: Wheat | B46: ='Issues of the Grange'!B5 | C46: ='Issues of the Grange'!C5 | G46: ='Issues of the Grange'!P5 | H46: ='Issues of the Grange'!M18
...

Sheet Upton Receipts
A1: UPTON RECEIPTS
B2: £ | C2: s | D2: d | F2: Total in £ | G2: Error | H2: Notes
A4: Arrears
A5: arrears from previous year | B5: 5 | C5: 19 | D5: 2.75 | F5: =B5+C5/20+D5/240
A6: of which delivered to treasurer of Wolvesey | B6: 1 | C6: 9 | F6: =B6+C6/20+D6/240
A8: Rents of assize
A9: Feast of St. Andrew | C9: 7 | D9: 4 | F9: =B9+C9/20+D9/240
A10: Palm Sunday | C10: 7 | D10: 4 | F10: =B10+C10/20+D10/240
A11: Lammas | C11: 7 | D11: 4 | F11: =B11+C11/20+D11/240
A12: Michaelmas | C12: 1 | D12: 2.75 | F12: =B12+C12/20+D12/240
A13: Total recorded in accounts | B13: 1 | C13: 3 | D13: 2.75 | F13: =B13+C13/20+D13/240
A14: Total | B14: =SUM(B9:B12) | C14: =SUM(C9:C12) | D14: =SUM(D9:D12) | F14: =B14+C14/20+D14/240 | G14: =F14-F13
A16: Quittances
A17: in quittance of 1 reeve for the year | C17: 2 | F17: =B17+C17/20+D17/240
A18: 3 ploughmen for the year | C18: 6 | F18: =B18+C18/20+D18/240
A19: 1 shepherd for the year | C19: 2 | F19: =B19+C19/20+D19/240
A20: 2 workers for the year | C20: 4 | F20: =B20+C20/20+D20/240
A21: Total recorded in accounts | C21: 14 | F21: =B21+C21/20+D21/240
A22: Total | B22: =SUM(B17:B20) | C22: =SUM(C17:C20) | D22: =SUM(D17:D20) | F22: =B22+C22/20+D22/240 | G22: =F22-F21
A24: Defaults of rent
A25: 1 acre of land which John held dawn into demense | D25: 2.25 | F25: =B25+C25/20+D25/240
A26: Total recorded in accounts | D26: 2.25 | F26: =B26+C26/20+D26/240
A27: Total | B27: =SUM(B25:B25) | C27: =SUM(C25:C25) | D27: =SUM(D25:D25) | F27: =B27+C27/20+D27/240 | G27: =F27-F26
A29: Total of rents remaining | C29: 9 | D29: 0.5 | F29: =B29+C29/20+D29/240
A31: Issues of the manor
A32: from 29 wethers sold | B32: 1 | C32: 14 | D32: 10.5 | F32: =B32+C32/20+D32/240
A33: from 3 feeble and sick oxen sold | C33: 14 | D33: 10 | F33: =B33+C33/20+D33/240
A34: from hides of 7 oxen in murrain | C34: 18 | D34: 2 | F34: =B34+C34/20+D34/240
A35: from skins of 13 wethers in murrain before shearing | C35: 3 | D35: 3 | F35: =B35+C35/20+D35/240
A36: from skins of 10 wethers after shearing | D36: 10 | F36: =B36+C36/20+D36/240
A37: from 44 hens sold | C37: 3 | D37: 8 | F37: =B37+C37/20+D37/240
A38: Total recorded in accounts | B38: 3 | C38: 15 | D38: 7.5 | F38: =B38+C38/20+D38/240
A39: Total | B39: =SUM(B32:B37) | C39: =SUM(C32:C37) | D39: =SUM(D32:D37) | F39: =B39+C39/20+D39/240 | G39: =F39-F38
A41: Sale of corn
A42: from 11qrs 1 bus of wheat sold | B42: 2 | C42: 14 | D42: 5.5 | F42: =B42+C42/20+D42/240
A43: from 6 qrs of curall sold | C43: 12 | F43: =B43+C43/20+D43/240
A44: from 10 qrs wrs 3 bus of barley sold | B44: 1 | C44: 11 | D44: 1.5 | F44: =B44+C44/20+D44/240
A45: from 14 qrs 2 bus of oats sold | B45: 1 | C45: 13 | D45: 3 | F45: =B45+C45/20+D45/240
A46: from 4 qrs and 7 bus of vetches sold | C46: 9 | D46: 6 | F46: =B46+C46/20+D46/240
A47: Total recorded in accounts | B47: 7 | D47: 4 | F47: =B47+C47/20+D47/240
...

Sheet Upton Expenses
A1: UPTON EXPENSES
B2: £ | C2: s | D2: d | F2: Total in £ | G2: Error | H2: Notes
A3: Cost of Ploughs
A4: iron and steel bought for 2 ploughs | C4: 4 | D4: 9.5 | F4: =B4+C4/20+D4/240
A5: 1 ploughshare | D5: 9 | F5: =B5+C5/20+D5/240
A6: 2 plough feet bought | D6: 6 | F6: =B6+C6/20+D6/240
A7: 1 pair of wheels bought | D7: 2 | F7: =B7+C7/20+D7/240
A8: 2 yokes | D8: 2 | F8: =B8+C8/20+D8/240
A9: stipend of smith for ironwork of 2 ploughs | C9: 4 | F9: =B9+C9/20+D9/240
A10: stipend of 1 oxherd | C10: 5 | F10: =B10+C10/20+D10/240
A11: making 2 ploughs from lords timber | D11: 5 | F11: =B11+C11/20+D11/240
A12: in 7 oxen bought due to others dying | B12: 2 | C12: 12 | D12: 10.75 | F12: =B12+C12/20+D12/240
A13: Total recorded in accounts | B13: 3 | C13: 8 | D13: 8.25 | F13: =B13+C13/20+D13/240
A14: Total | B14: =SUM(B3:B12) | C14: =SUM(C3:C12) | D14: =SUM(D3:D12) | F14: =B14+C14/20+D14/240 | G14: =F14-F13
A15: Total capital expenses | B15: =SUM(B4:B9,B11) | C15: =SUM(C4:C9,C11) | D15: =SUM(D4:D9,D11) | F15: =B15+C15/20+D15/240
A17: Cost of Carts
A18: 4 tacks bought | D18: 3 | F18: =B18+C18/20+D18/240
A19: in 1 saddle pad | D19: 9 | F19: =B19+C19/20+D19/240
A20: in grease | D20: 1 | F20: =B20+C20/20+D20/240
A21: in shoeing 2 plough-horses | C21: 1 | D21: 5 | F21: =B21+C21/20+D21/240
A22: in fitting cart with axels | D22: 1.5 | F22: =B22+C22/20+D22/240
A23: stipend of 1 carter | C23: 5 | F23: =B23+C23/20+D23/240
A24: Total recorded in accounts | C24: 7 | D24: 7.5 | F24: =B24+C24/20+D24/240
A25: Total | B25: =SUM(B18:B23) | C25: =SUM(C18:C23) | D25: =SUM(D18:D23) | F25: =B25+C25/20+D25/240 | G25: =F25-F24
A26: Total capital expenses | B26: =SUM(B18:B22) | C26: =SUM(C18:C22) | D26: =SUM(D18:D22) | F26: =B26+C26/20+D26/240
A28: Sheepcote
A29: washing and shearing sheep | D29: 6 | F29: =B29+C29/20+D29/240
A30: grease bought | C30: 4 | F30: =B30+C30/20+D30/240
A31: Total recorded in accounts | C31: 4 | D31: 6 | F31: =B31+C31/20+D31/240
A32: Total | B32: =SUM(B29:B30) | C32: =SUM(C29:C30) | D32: =SUM(D29:D30) | F32: =B32+C32/20+D32/240 | G32: =F32-F31
A33: Total capital expenses | B33: =SUM(B30) | C33: =SUM(C30) | D33: =SUM(D30) | F33: =B33+C33/20+D33/240
A35: Cost of Buildings
A36: roofing and mending hall and byre | D36: 7.5 | F36: =B36+C36/20+D36/240
A37: stipend of 1 man repairing wall around garden | C37: 2 | D37: 1 | F37: =B37+C37/20+D37/240
A38: mending garden gate | D38: 2 | F38: =B38+C38/20+D38/240
A39: nails for same | D39: 1.5 | F39: =B39+C39/20+D39/240
A40: 1 lock bought | D40: 1.5 | F40: =B40+C40/20+D40/240
A41: stipend of 1 man re-roofing hay-barn and cart-house | C41: 1 | D41: 4 | F41: =B41+C41/20+D41/240
A42: 2 casks bought for cider | C42: 6 | D42: 10 | F42: =B42+C42/20+D42/240
A43: Total recorded in accounts | C43: 11 | D43: 3 | F43: =B43+C43/20+D43/240
...

Sheet Issues of the Grange
B1: The issue of the grange account gives the total "yield" at the top of each heading in curly brackets, measurements used: fold, qrs, bus
B2: In "Issues of the grange" (p.12-13) | G2: In "Sale of Corn" (p.7) | P2: Value of Total Production
A3: Gross output | B3: Quantity | D3: Additional bought-in | F3: Quantity | G3: Quantity noted as sold | J3: Difference Produced vs. Sold | K3: Price 1 | L3: Quantity 1 | M3: Price 2 | N3: Quantity 2 | O3: Unit price | P3: Value
B4: qrs | C4: bus | D4: qrs | E4: bus | F4: qrs | G4: qrs | H4: bus | I4: qrs | K4: £ | L4: qrs | M4: £ | N4: qrs | O4: £ per qr | P4: £
A5: Wheat | B5: 23 | C5: 1 | F5: =B5+D5+C5/8+E5/8 | G5: 11 | H5: 1 | I5: =G5+H5/8 | J5: =F5-I5 | K5: =2+14/20+5.5/240 | L5: =I5 | O5: =IFERROR((K5+M5)/(L5+N5),0) | P5: =O5*F5
A6: Curall | B6: 6 | F6: =B6+D6+C6/8+E6/8 | G6: 6 | I6: =G6+H6/8 | J6: =F6-I6 | K6: =12/20 | L6: =I6 | O6: =IFERROR((K6+M6)/(L6+N6),0) | P6: =O6*F6
A7: Barley | B7: 34.5 | F7: =B7+D7+C7/8+E7/8 | G7: 10 | H7: 3 | I7: =G7+H7/8 | J7: =F7-I7 | K7: ='Upton Receipts'!F44 | L7: =I7 | O7: =IFERROR((K7+M7)/(L7+N7),0) | P7: =O7*F7
A8: Oats | B8: 32 | C8: 6 | F8: =B8+D8+C8/8+E8/8 | G8: 14 | H8: 2 | I8: =G8+H8/8 | J8: =F8-I8 | K8: ='Upton Receipts'!F45 | L8: =I8 | O8: =IFERROR((K8+M8)/(L8+N8),0) | P8: =O8*F8
A9: Peas | F9: =B9+D9+C9/8+E9/8 | I9: =G9+H9/8 | J9: =F9-I9 | L9: =I9 | O9: =IFERROR((K9+M9)/(L9+N9),0) | P9: =O9*F9
A10: Vetches | B10: 7 | C10: 6 | F10: =B10+D10+C10/8+E10/8 | G10: 4 | H10: 7 | I10: =G10+H10/8 | J10: =F10-I10 | K10: ='Upton Receipts'!F46 | L10: =I10 | O10: =IFERROR((K10+M10)/(L10+N10),0) | P10: =O10*F10
A12: Total Production | F12: =SUM(F5:F10) | P12: =SUM(P5:P10) | Q12: Production value is significantly more, as much less was sold than what was produced
A13: Sales of corn (as recorded in accounts) | F13: =SUM(I5:I10)
A16: Net output | B16: Gross output | C16: Seed | F16: tithe | G16: to manorial servants & livestock | J16: Output net of tithe & seed & liveries to manorial servants | K16: in stock from last year | L16: Price | M16: Value of net output | N16: Value of sales (in "Sale of Corn")
B17: qrs | C17: qrs | D17: bus | E17: qrs | F17: qrs | G17: qrs | H17: bus | I17: qrs | J17: qrs | K17: qrs | L17: £ per qr | M17: £ | N17: £
A18: Wheat | B18: =F5 | C18: 11 | E18: =C18+D18/8 | G18: 1 | H18: 3 | I18: =G18+H18/8 | J18: =B18-(E18+F18+I18) | L18: =O5 | M18: =L18*J18 | N18: ='Upton Receipts'!F42
A19: Curall | B19: =F6 | E19: =C19+D19/8 | I19: =G19+H19/8 | J19: =B19-(E19+F19+I19) | L19: =O6 | M19: =L19*J19 | N19: ='Upton Receipts'!F43
A20: Barley | B20: =F7 | C20: 11 | D20: 6 | E20: =C20+D20/8 | G20: 11.5 | H20: 6 | I20: =G20+H20/8 | J20: =B20-(E20+F20+I20) | L20: =O7 | M20: =L20*J20 | N20: ='Upton Receipts'!F44
A21: Oats | B21: =F8 | C21: 15 | E21: =C21+D21/8 | G21: 3.5 | I21: =G21+H21/8 | J21: =B21-(E21+F21+I21) | L21: =O8 | M21: =L21*J21 | N21: ='Upton Receipts'!F45
A22: Peas | B22: =F9 | E22: =C22+D22/8 | I22: =G22+H22/8 | J22: =B22-(E22+F22+I22) | L22: =O9 | M22: =L22*J22
A23: Vetches | B23: =F10 | C23: 1 | D23: 7 | E23: =C23+D23/8 | G23: 1 | I23: =G23+H23/8 | J23: =B23-(E23+F23+I23) | L23: =O10 | M23: =L23*J23 | N23: ='Upton Receipts'!F46
A24: Total | B24: =SUM(B18:B23) | E24: =SUM(E18:E23) | J24: =SUM(J18:J23) | M24: =SUM(M18:M23) | N24: =SUM(N18:N23)

Sheet Stock
A1: EAST KNOYLE STOCK ACCOUNT
A3: Livestock | B3: Inherited stock | C3: added | D3: strays | E3: herbage | F3: sold | G3: in murrain | H3: accounted for elsewhere | I3: End-period stock | J3: cross-check | K3: price 1 | L3: units 1 | M3: price 2 | N3: units 2 | O3: Weight (weys) | P3: Unit price (£) | Q3: Value of production (£) at sales prices | R3: Sales in (£) | S3: Details
A4: Cart-horses | J4: =B4+C4-D4-E4-F4-G4-H4 | P4: =IFERROR((K4+M4)/(L4+N4),"") | Q4: =IFERROR(C4*P4,"") | R4: =IFERROR(P4*F4,"")
A5: Mares | B5: 16 | C5: 7 | F5: 3 | G5: 7 | I5: 13 | J5: =B5+C5-D5-E5-F5-G5-H5 | K5: ='Upton Receipts'!F33 | L5: 3 | P5: =IFERROR((K5+M5)/(L5+N5),"") | Q5: =IFERROR(C5*P5,"") | R5: =IFERROR(P5*F5,"")
A6: Plough horses | B6: 2 | I6: 2 | J6: =B6+C6-D6-E6-F6-G6-H6 | P6: =IFERROR((K6+M6)/(L6+N6),"") | Q6: =IFERROR(C6*P6,"") | R6: =IFERROR(P6*F6,"")
A7: Colts (2 years) | J7: =B7+C7-D7-E7-F7-G7-H7 | P7: =IFERROR((K7+M7)/(L7+N7),"") | Q7: =IFERROR(C7*P7,"") | R7: =IFERROR(P7*F7,"")
A8: Colts (2 years) | J8: =B8+C8-D8-E8-F8-G8-H8 | P8: =IFERROR((K8+M8)/(L8+N8),"") | Q8: =IFERROR(C8*P8,"") | R8: =IFERROR(P8*F8,"")
A9: Colts (1 year) | J9: =B9+C9-D9-E9-F9-G9-H9 | P9: =IFERROR((K9+M9)/(L9+N9),"") | Q9: =IFERROR(C9*P9,"") | R9: =IFERROR(P9*F9,"")
A10: Foals | J10: =B10+C10-D10-E10-F10-G10-H10 | P10: =IFERROR((K10+M10)/(L10+N10),"") | Q10: =IFERROR(C10*P10,"") | R10: =IFERROR(P10*F10,"")
A11: Oxen | J11: =B11+C11-D11-E11-F11-G11-H11 | P11: =IFERROR((K11+M11)/(L11+N11),"") | Q11: =IFERROR(C11*P11,"") | R11: =IFERROR(P11*F11,"")
A12: Bulls | J12: =B12+C12-D12-E12-F12-G12-H12 | P12: =IFERROR((K12+M12)/(L12+N12),"") | Q12: =IFERROR(C12*P12,"") | R12: =IFERROR(P12*F12,"")
A13: Cows | J13: =B13+C13-D13-E13-F13-G13-H13 | P13: =IFERROR((K13+M13)/(L13+N13),"") | Q13: =IFERROR(C13*P13,"") | R13: =IFERROR(P13*F13,"")
A14: Steers | J14: =B14+C14-D14-E14-F14-G14-H14 | P14: =IFERROR((K14+M14)/(L14+N14),"") | Q14: =IFERROR(C14*P14,"") | R14: =IFERROR(P14*F14,"")
A15: Bullocks | J15: =B15+C15-D15-E15-F15-G15-H15 | P15: =IFERROR((K15+M15)/(L15+N15),"") | Q15: =IFERROR(C15*P15,"") | R15: =IFERROR(P15*F15,"")
A16: Yearlings | J16: =B16+C16-D16-E16-F16-G16-H16 | P16: =IFERROR((K16+M16)/(L16+N16),"") | Q16: =IFERROR(C16*P16,"") | R16: =IFERROR(P16*F16,"")
A17: Calves | J17: =B17+C17-D17-E17-F17-G17-H17 | P17: =IFERROR((K17+M17)/(L17+N17),"") | Q17: =IFERROR(C17*P17,"") | R17: =IFERROR(P17*F17,"")
A18: Wethers | B18: 313 | F18: 29 | G18: 26 | I18: 261 | J18: =B18+C18-D18-E18-F18-G18-H18 | K18: ='Upton Receipts'!F32 | L18: 29 | P18: =IFERROR((K18+M18)/(L18+N18),"") | Q18: =IFERROR(C18*P18,"") | R18: =IFERROR(P18*F18,"")
A19: Rams | J19: =B19+C19-D19-E19-F19-G19-H19 | P19: =IFERROR((K19+M19)/(L19+N19),"") | Q19: =IFERROR(C19*P19,"") | R19: =IFERROR(P19*F19,"")
A20: Ewes | J20: =B20+C20-D20-E20-F20-G20-H20 | P20: =IFERROR((K20+M20)/(L20+N20),"") | Q20: =IFERROR(C20*P20,"") | R20: =IFERROR(P20*F20,"")
A21: Hoggs | J21: =B21+C21-D21-E21-F21-G21-H21 | P21: =IFERROR((K21+M21)/(L21+N21),"") | Q21: =IFERROR(C21*P21,"") | R21: =IFERROR(P21*F21,"")
A22: Lambs | J22: =B22+C22-D22-E22-F22-G22-H22 | P22: =IFERROR((K22+M22)/(L22+N22),"") | Q22: =IFERROR(C22*P22,"") | R22: =IFERROR(P22*F22,"")
A23: Boars | J23: =B23+C23-D23-E23-F23-G23-H23 | P23: =IFERROR((K23+M23)/(L23+N23),"") | Q23: =IFERROR(C23*P23,"") | R23: =IFERROR(P23*F23,"")
A24: Sows | J24: =B24+C24-D24-E24-F24-G24-H24 | P24: =IFERROR((K24+M24)/(L24+N24),"") | Q24: =IFERROR(C24*P24,"") | R24: =IFERROR(P24*F24,"")
A25: Pigs | J25: =B25+C25-D25-E25-F25-G25-H25 | P25: =IFERROR((K25+M25)/(L25+N25),"") | Q25: =IFERROR(C25*P25,"") | R25: =IFERROR(P25*F25,"")
A26: Hoggets | J26: =B26+C26-D26-E26-F26-G26-H26 | P26: =IFERROR((K26+M26)/(L26+N26),"") | Q26: =IFERROR(C26*P26,"") | R26: =IFERROR(P26*F26,"")
A27: Piglets | J27: =B27+C27-D27-E27-F27-G27-H27 | P27: =IFERROR((K27+M27)/(L27+N27),"") | Q27: =IFERROR(C27*P27,"") | R27: =IFERROR(P27*F27,"")
A28: Swans | J28: =B28+C28-D28-E28-F28-G28-H28 | P28: =IFERROR((K28+M28)/(L28+N28),"") | Q28: =IFERROR(C28*P28,"") | R28: =IFERROR(P28*F28,"")
A29: Peacocks | J29: =B29+C29-D29-E29-F29-G29-H29 | P29: =IFERROR((K29+M29)/(L29+N29),"") | Q29: =IFERROR(C29*P29,"") | R29: =IFERROR(P29*F29,"")
A30: Total | R30: =SUM(R4:R29)
P31: =IFERROR((K31+M31)/(L31+N31),"") | Q31: =IFERROR(C31*P31,"") | R31: =IFERROR(P31*F31,"")
P32: =IFERROR((K32+M32)/(L32+N32),"") | Q32: =IFERROR(C32*P32,"") | R32: =IFERROR(P32*F32,"")
A33: Wool | P33: =IFERROR((K33+M33)/(L33+N33),"") | Q33: =IFERROR(C33*P33,"") | R33: =IFERROR(P33*F33,"")
A34: Fleeces | C34: 287 | H34: 287 | I34: 0 | J34: =B34+C34-D34-E34-F34-G34-H34 | P34: 0.02 | Q34: =IFERROR(C34*P34,"") | R34: =IFERROR(P34*F34,"") | S34: 286 Given to the Reeve of East Knoyle, one given to shepherd
A35: Coarse wool | J35: =B35+C37-D37-E37-F37-G37-H37 | P35: =IFERROR((K35+M35)/(L35+N35),"") | Q35: =IFERROR(C35*P35,"") | R35: =IFERROR(P35*F35,"")
A36: Lamb's wool | J36: =B36+C36-D36-E36-F36-G36-H36 | P36: =IFERROR((K36+M36)/(L36+N36),"") | Q36: =IFERROR(C36*P36,"") | R36: =IFERROR(P36*F36,"")
A37: Wool locks | C37: =O37 | H37: =O37 | I37: 0 | O37: =2*Assumptions!E7 | P37: =IFERROR((K37+M37)/(L37+N37),"") | Q37: =IFERROR(C37*P37,"") | S37: given to East Knoyle
A38: Wool sold at shearing | J38: =B38+C38-D38-E38-F38-G38-H38 | P38: =IFERROR((K38+M38)/(L38+N38),"") | Q38: =IFERROR(C38*P38,"") | R38: =IFERROR(P38*F38,"")
A39: Total | J39: =B39+C39-D39-E39-F39-G39-H39 | P39: =IFERROR((K39+M39)/(L39+N39),"") | Q39: =SUM(Q34:Q38) | R39: =IFERROR(P39*F39,"")
P40: =IFERROR((K40+M40)/(L40+N40),"") | Q40: =IFERROR(C40*P40,"") | R40: =IFERROR(P40*F40,"")
P41: =IFERROR((K41+M41)/(L41+N41),"") | Q41: =IFERROR(C41*P41,"") | R41: =IFERROR(P41*F41,"")
...

Sheet Assumptions
A1: ASSUMPTIONS
B3: Weights | C3: Value (in lbs) | D3: Value (in cloves) | E3: Value (in weys) | F3: Value (in stone)
B4: Lbs | C4: 1 | D4: =C4/C5 | E4: =C4/C6 | F4: =C4/C7
B5: Cloves | C5: 7 | D5: 1 | E5: =C5/C6 | F5: =C7/C5
B6: Wey | C6: 175 | D6: =C6/C5 | E6: =C6/C6 | F6: =C7/C6
B7: Stone | C7: =175/14 | D7: =C5/C7 | E7: =C7/C6 | F7: 1
